package com.github.revival.server.gen.feature;

import java.util.Random;

import com.github.revival.server.block.FABlockRegistry;
import com.github.revival.server.item.FAItemRegistry;

import net.minecraft.block.Block;
import net.minecraft.block.material.Material;
import net.minecraft.init.Blocks;
import net.minecraft.init.Items;
import net.minecraft.item.Item;
import net.minecraft.tileentity.TileEntityChest;
import net.minecraft.util.WeightedRandomChestContent;
import net.minecraft.world.World;
import net.minecraft.world.gen.feature.WorldGenerator;

public class AztecWeaponsShopWorldGen extends WorldGenerator {
	protected static final WeightedRandomChestContent[] treasure = new WeightedRandomChestContent[]{
		new WeightedRandomChestContent(FAItemRegistry.INSTANCE.relic, 0, 1, 2, 76),
		new WeightedRandomChestContent(FAItemRegistry.INSTANCE.woodjavelin, 0, 1, 8, 50),
		new WeightedRandomChestContent(FAItemRegistry.INSTANCE.stonejavelin, 0, 1, 8, 50),
		new WeightedRandomChestContent(FAItemRegistry.INSTANCE.ironjavelin, 0, 1, 8, 25),
		new WeightedRandomChestContent(FAItemRegistry.INSTANCE.goldjavelin, 0, 1, 8, 25),
		new WeightedRandomChestContent(Items.wooden_sword, 0, 1, 1, 25),
		new WeightedRandomChestContent(Items.stone_sword, 0, 1, 1, 25),
		new WeightedRandomChestContent(Items.golden_sword, 0, 1, 1, 25),
		new WeightedRandomChestContent(Item.getItemFromBlock(FABlockRegistry.INSTANCE.blockSkull), 0, 1, 2, 70),
		new WeightedRandomChestContent(Item.getItemFromBlock(FABlockRegistry.INSTANCE.skullLantern), 0, 1, 2, 55),
		new WeightedRandomChestContent(Item.getItemFromBlock(FABlockRegistry.INSTANCE.drum), 0, 1, 1, 38),
		new WeightedRandomChestContent(FAItemRegistry.INSTANCE.potteryShards, 0, 1, 3, 80),
		new WeightedRandomChestContent(FAItemRegistry.INSTANCE.goldjavelin, 0, 1, 1, 33),
		new WeightedRandomChestContent(FAItemRegistry.INSTANCE.ironjavelin, 0, 1, 1, 56),
		new WeightedRandomChestContent(FAItemRegistry.INSTANCE.stoneboard, 0, 1, 3, 75),
		new WeightedRandomChestContent(Items.bone, 0, 1, 3, 85),
		new WeightedRandomChestContent(Items.gold_ingot, 0, 1, 3, 90),
		new WeightedRandomChestContent(Items.emerald, 0, 1, 3, 25),
		new WeightedRandomChestContent(Items.coal, 0, 1, 7, 55),
		new WeightedRandomChestContent(Item.getItemFromBlock(Blocks.bookshelf), 0, 1, 5, 55),
		new WeightedRandomChestContent(Item.getItemFromBlock(Blocks.glowstone), 0, 1, 4, 65),
		new WeightedRandomChestContent(Item.getItemFromBlock(Blocks.obsidian), 0, 1, 6, 55),
		new WeightedRandomChestContent(FAItemRegistry.INSTANCE.recordNano_Discovering, 0, 1, 1, 6),
		new WeightedRandomChestContent(Items.bowl, 0, 1, 8, 25),
		new WeightedRandomChestContent(Item.getItemFromBlock(Blocks.tnt), 0, 1, 6, 45)

	};
	public boolean generate(World world, Random rand, int x, int y, int z) {
		generate_r0(world, rand, x, y, z);
		return true;

	}

	public boolean generate_r0(World world, Random rand, int x, int y, int z) {

		world.setBlock(x + 0, y + 1, z + 0, Blocks.dirt, 0, 3);
		world.setBlock(x + 1, y + 1, z + 0, Blocks.dirt, 0, 3);
		world.setBlock(x + 2, y + 1, z + 0, Blocks.dirt, 0, 3);
		world.setBlock(x + 3, y + 1, z + 0, Blocks.dirt, 0, 3);
		world.setBlock(x + 4, y + 1, z + 0, Blocks.dirt, 0, 3);
		world.setBlock(x + 5, y + 1, z + 0, Blocks.dirt, 0, 3);
		world.setBlock(x + 6, y + 1, z + 0, Blocks.dirt, 0, 3);
		world.setBlock(x + 7, y + 1, z + 0, Blocks.dirt, 0, 3);
		world.setBlock(x + 8, y + 1, z + 0, Blocks.dirt, 0, 3);
		world.setBlock(x + 9, y + 1, z + 0, Blocks.dirt, 0, 3);
		world.setBlock(x + 10, y + 1, z + 0, Blocks.dirt, 0, 3);
		world.setBlock(x + 11, y + 1, z + 0, Blocks.dirt, 0, 3);
		world.setBlock(x + 12, y + 1, z + 0, Blocks.dirt, 0, 3);
		world.setBlock(x + 13, y + 1, z + 0, Blocks.dirt, 0, 3);
		world.setBlock(x + 14, y + 1, z + 0, Blocks.dirt, 0, 3);
		world.setBlock(x + 15, y + 1, z + 0, Blocks.dirt, 0, 3);
		world.setBlock(x + 16, y + 1, z + 0, Blocks.dirt, 0, 3);
		world.setBlock(x + 17, y + 1, z + 0, Blocks.dirt, 0, 3);
		world.setBlock(x + 18, y + 1, z + 0, Blocks.dirt, 0, 3);
		world.setBlock(x + 0, y + 1, z + 1, Blocks.dirt, 0, 3);
		world.setBlock(x + 1, y + 1, z + 1, Blocks.dirt, 0, 3);
		world.setBlock(x + 2, y + 1, z + 1, Blocks.dirt, 0, 3);
		world.setBlock(x + 3, y + 1, z + 1, Blocks.dirt, 0, 3);
		world.setBlock(x + 4, y + 1, z + 1, Blocks.dirt, 0, 3);
		world.setBlock(x + 5, y + 1, z + 1, Blocks.dirt, 0, 3);
		world.setBlock(x + 6, y + 1, z + 1, Blocks.dirt, 0, 3);
		world.setBlock(x + 7, y + 1, z + 1, Blocks.dirt, 0, 3);
		world.setBlock(x + 8, y + 1, z + 1, Blocks.dirt, 0, 3);
		world.setBlock(x + 9, y + 1, z + 1, Blocks.dirt, 0, 3);
		world.setBlock(x + 10, y + 1, z + 1, Blocks.dirt, 0, 3);
		world.setBlock(x + 11, y + 1, z + 1, Blocks.dirt, 0, 3);
		world.setBlock(x + 12, y + 1, z + 1, Blocks.dirt, 0, 3);
		world.setBlock(x + 13, y + 1, z + 1, Blocks.dirt, 0, 3);
		world.setBlock(x + 14, y + 1, z + 1, Blocks.dirt, 0, 3);
		world.setBlock(x + 15, y + 1, z + 1, Blocks.dirt, 0, 3);
		world.setBlock(x + 16, y + 1, z + 1, Blocks.dirt, 0, 3);
		world.setBlock(x + 17, y + 1, z + 1, Blocks.dirt, 0, 3);
		world.setBlock(x + 18, y + 1, z + 1, Blocks.dirt, 0, 3);
		world.setBlock(x + 0, y + 1, z + 2, Blocks.dirt, 0, 3);
		world.setBlock(x + 1, y + 1, z + 2, Blocks.dirt, 0, 3);
		world.setBlock(x + 2, y + 1, z + 2, Blocks.dirt, 0, 3);
		world.setBlock(x + 3, y + 1, z + 2, Blocks.dirt, 0, 3);
		world.setBlock(x + 4, y + 1, z + 2, Blocks.dirt, 0, 3);
		world.setBlock(x + 5, y + 1, z + 2, Blocks.dirt, 0, 3);
		world.setBlock(x + 6, y + 1, z + 2, Blocks.dirt, 0, 3);
		world.setBlock(x + 7, y + 1, z + 2, Blocks.dirt, 0, 3);
		world.setBlock(x + 8, y + 1, z + 2, Blocks.dirt, 0, 3);
		world.setBlock(x + 9, y + 1, z + 2, Blocks.dirt, 0, 3);
		world.setBlock(x + 10, y + 1, z + 2, Blocks.dirt, 0, 3);
		world.setBlock(x + 11, y + 1, z + 2, Blocks.dirt, 0, 3);
		world.setBlock(x + 12, y + 1, z + 2, Blocks.dirt, 0, 3);
		world.setBlock(x + 13, y + 1, z + 2, Blocks.dirt, 0, 3);
		world.setBlock(x + 14, y + 1, z + 2, Blocks.dirt, 0, 3);
		world.setBlock(x + 15, y + 1, z + 2, Blocks.dirt, 0, 3);
		world.setBlock(x + 16, y + 1, z + 2, Blocks.dirt, 0, 3);
		world.setBlock(x + 17, y + 1, z + 2, Blocks.dirt, 0, 3);
		world.setBlock(x + 18, y + 1, z + 2, Blocks.dirt, 0, 3);
		world.setBlock(x + 0, y + 1, z + 3, Blocks.dirt, 0, 3);
		world.setBlock(x + 1, y + 1, z + 3, Blocks.dirt, 0, 3);
		world.setBlock(x + 2, y + 1, z + 3, Blocks.dirt, 0, 3);
		world.setBlock(x + 3, y + 1, z + 3, Blocks.dirt, 0, 3);
		world.setBlock(x + 4, y + 1, z + 3, Blocks.dirt, 0, 3);
		world.setBlock(x + 5, y + 1, z + 3, Blocks.dirt, 0, 3);
		world.setBlock(x + 6, y + 1, z + 3, Blocks.dirt, 0, 3);
		world.setBlock(x + 7, y + 1, z + 3, Blocks.dirt, 0, 3);
		world.setBlock(x + 8, y + 1, z + 3, Blocks.dirt, 0, 3);
		world.setBlock(x + 9, y + 1, z + 3, Blocks.dirt, 0, 3);
		world.setBlock(x + 10, y + 1, z + 3, Blocks.dirt, 0, 3);
		world.setBlock(x + 11, y + 1, z + 3, Blocks.dirt, 0, 3);
		world.setBlock(x + 12, y + 1, z + 3, Blocks.dirt, 0, 3);
		world.setBlock(x + 13, y + 1, z + 3, Blocks.dirt, 0, 3);
		world.setBlock(x + 14, y + 1, z + 3, Blocks.dirt, 0, 3);
		world.setBlock(x + 15, y + 1, z + 3, Blocks.dirt, 0, 3);
		world.setBlock(x + 16, y + 1, z + 3, Blocks.dirt, 0, 3);
		world.setBlock(x + 17, y + 1, z + 3, Blocks.dirt, 0, 3);
		world.setBlock(x + 18, y + 1, z + 3, Blocks.dirt, 0, 3);
		world.setBlock(x + 0, y + 1, z + 4, Blocks.dirt, 0, 3);
		world.setBlock(x + 1, y + 1, z + 4, Blocks.dirt, 0, 3);
		world.setBlock(x + 2, y + 1, z + 4, Blocks.dirt, 0, 3);
		world.setBlock(x + 3, y + 1, z + 4, Blocks.dirt, 0, 3);
		world.setBlock(x + 4, y + 1, z + 4, Blocks.dirt, 0, 3);
		world.setBlock(x + 5, y + 1, z + 4, Blocks.dirt, 0, 3);
		world.setBlock(x + 6, y + 1, z + 4, Blocks.dirt, 0, 3);
		world.setBlock(x + 7, y + 1, z + 4, Blocks.dirt, 0, 3);
		world.setBlock(x + 8, y + 1, z + 4, Blocks.dirt, 0, 3);
		world.setBlock(x + 9, y + 1, z + 4, Blocks.dirt, 0, 3);
		world.setBlock(x + 10, y + 1, z + 4, Blocks.dirt, 0, 3);
		world.setBlock(x + 11, y + 1, z + 4, Blocks.dirt, 0, 3);
		world.setBlock(x + 12, y + 1, z + 4, Blocks.dirt, 0, 3);
		world.setBlock(x + 13, y + 1, z + 4, Blocks.dirt, 0, 3);
		world.setBlock(x + 14, y + 1, z + 4, Blocks.dirt, 0, 3);
		world.setBlock(x + 15, y + 1, z + 4, Blocks.dirt, 0, 3);
		world.setBlock(x + 16, y + 1, z + 4, Blocks.dirt, 0, 3);
		world.setBlock(x + 17, y + 1, z + 4, Blocks.dirt, 0, 3);
		world.setBlock(x + 18, y + 1, z + 4, Blocks.dirt, 0, 3);
		world.setBlock(x + 0, y + 1, z + 5, Blocks.dirt, 0, 3);
		world.setBlock(x + 1, y + 1, z + 5, Blocks.dirt, 0, 3);
		world.setBlock(x + 2, y + 1, z + 5, Blocks.dirt, 0, 3);
		world.setBlock(x + 3, y + 1, z + 5, Blocks.dirt, 0, 3);
		world.setBlock(x + 4, y + 1, z + 5, Blocks.dirt, 0, 3);
		world.setBlock(x + 5, y + 1, z + 5, Blocks.dirt, 0, 3);
		world.setBlock(x + 6, y + 1, z + 5, Blocks.dirt, 0, 3);
		world.setBlock(x + 7, y + 1, z + 5, Blocks.dirt, 0, 3);
		world.setBlock(x + 8, y + 1, z + 5, Blocks.dirt, 0, 3);
		world.setBlock(x + 9, y + 1, z + 5, Blocks.dirt, 0, 3);
		world.setBlock(x + 10, y + 1, z + 5, Blocks.dirt, 0, 3);
		world.setBlock(x + 11, y + 1, z + 5, Blocks.dirt, 0, 3);
		world.setBlock(x + 12, y + 1, z + 5, Blocks.dirt, 0, 3);
		world.setBlock(x + 13, y + 1, z + 5, Blocks.dirt, 0, 3);
		world.setBlock(x + 14, y + 1, z + 5, Blocks.dirt, 0, 3);
		world.setBlock(x + 15, y + 1, z + 5, Blocks.dirt, 0, 3);
		world.setBlock(x + 16, y + 1, z + 5, Blocks.dirt, 0, 3);
		world.setBlock(x + 17, y + 1, z + 5, Blocks.dirt, 0, 3);
		world.setBlock(x + 18, y + 1, z + 5, Blocks.dirt, 0, 3);
		world.setBlock(x + 0, y + 1, z + 6, Blocks.dirt, 0, 3);
		world.setBlock(x + 1, y + 1, z + 6, Blocks.dirt, 0, 3);
		world.setBlock(x + 2, y + 1, z + 6, Blocks.dirt, 0, 3);
		world.setBlock(x + 3, y + 1, z + 6, Blocks.dirt, 0, 3);
		world.setBlock(x + 4, y + 1, z + 6, Blocks.dirt, 0, 3);
		world.setBlock(x + 5, y + 1, z + 6, Blocks.dirt, 0, 3);
		world.setBlock(x + 6, y + 1, z + 6, Blocks.dirt, 0, 3);
		world.setBlock(x + 7, y + 1, z + 6, Blocks.dirt, 0, 3);
		world.setBlock(x + 8, y + 1, z + 6, Blocks.dirt, 0, 3);
		world.setBlock(x + 9, y + 1, z + 6, Blocks.dirt, 0, 3);
		world.setBlock(x + 10, y + 1, z + 6, Blocks.dirt, 0, 3);
		world.setBlock(x + 11, y + 1, z + 6, Blocks.dirt, 0, 3);
		world.setBlock(x + 12, y + 1, z + 6, Blocks.dirt, 0, 3);
		world.setBlock(x + 13, y + 1, z + 6, Blocks.dirt, 0, 3);
		world.setBlock(x + 14, y + 1, z + 6, Blocks.dirt, 0, 3);
		world.setBlock(x + 15, y + 1, z + 6, Blocks.dirt, 0, 3);
		world.setBlock(x + 16, y + 1, z + 6, Blocks.dirt, 0, 3);
		world.setBlock(x + 17, y + 1, z + 6, Blocks.dirt, 0, 3);
		world.setBlock(x + 18, y + 1, z + 6, Blocks.dirt, 0, 3);
		world.setBlock(x + 0, y + 1, z + 7, Blocks.dirt, 0, 3);
		world.setBlock(x + 1, y + 1, z + 7, Blocks.dirt, 0, 3);
		world.setBlock(x + 2, y + 1, z + 7, Blocks.dirt, 0, 3);
		world.setBlock(x + 3, y + 1, z + 7, Blocks.dirt, 0, 3);
		world.setBlock(x + 4, y + 1, z + 7, Blocks.dirt, 0, 3);
		world.setBlock(x + 5, y + 1, z + 7, Blocks.dirt, 0, 3);
		world.setBlock(x + 6, y + 1, z + 7, Blocks.dirt, 0, 3);
		world.setBlock(x + 7, y + 1, z + 7, Blocks.dirt, 0, 3);
		world.setBlock(x + 8, y + 1, z + 7, Blocks.dirt, 0, 3);
		world.setBlock(x + 9, y + 1, z + 7, Blocks.dirt, 0, 3);
		world.setBlock(x + 10, y + 1, z + 7, Blocks.dirt, 0, 3);
		world.setBlock(x + 11, y + 1, z + 7, Blocks.dirt, 0, 3);
		world.setBlock(x + 12, y + 1, z + 7, Blocks.dirt, 0, 3);
		world.setBlock(x + 13, y + 1, z + 7, Blocks.dirt, 0, 3);
		world.setBlock(x + 14, y + 1, z + 7, Blocks.dirt, 0, 3);
		world.setBlock(x + 15, y + 1, z + 7, Blocks.dirt, 0, 3);
		world.setBlock(x + 16, y + 1, z + 7, Blocks.dirt, 0, 3);
		world.setBlock(x + 17, y + 1, z + 7, Blocks.dirt, 0, 3);
		world.setBlock(x + 18, y + 1, z + 7, Blocks.dirt, 0, 3);
		world.setBlock(x + 0, y + 1, z + 8, Blocks.dirt, 0, 3);
		world.setBlock(x + 1, y + 1, z + 8, Blocks.dirt, 0, 3);
		world.setBlock(x + 2, y + 1, z + 8, Blocks.dirt, 0, 3);
		world.setBlock(x + 3, y + 1, z + 8, Blocks.dirt, 0, 3);
		world.setBlock(x + 4, y + 1, z + 8, Blocks.dirt, 0, 3);
		world.setBlock(x + 5, y + 1, z + 8, Blocks.dirt, 0, 3);
		world.setBlock(x + 6, y + 1, z + 8, Blocks.dirt, 0, 3);
		world.setBlock(x + 7, y + 1, z + 8, Blocks.dirt, 0, 3);
		world.setBlock(x + 8, y + 1, z + 8, Blocks.dirt, 0, 3);
		world.setBlock(x + 9, y + 1, z + 8, Blocks.dirt, 0, 3);
		world.setBlock(x + 10, y + 1, z + 8, Blocks.dirt, 0, 3);
		world.setBlock(x + 11, y + 1, z + 8, Blocks.dirt, 0, 3);
		world.setBlock(x + 12, y + 1, z + 8, Blocks.dirt, 0, 3);
		world.setBlock(x + 13, y + 1, z + 8, Blocks.dirt, 0, 3);
		world.setBlock(x + 14, y + 1, z + 8, Blocks.dirt, 0, 3);
		world.setBlock(x + 15, y + 1, z + 8, Blocks.dirt, 0, 3);
		world.setBlock(x + 16, y + 1, z + 8, Blocks.dirt, 0, 3);
		world.setBlock(x + 17, y + 1, z + 8, Blocks.dirt, 0, 3);
		world.setBlock(x + 18, y + 1, z + 8, Blocks.dirt, 0, 3);
		world.setBlock(x + 0, y + 1, z + 9, Blocks.dirt, 0, 3);
		world.setBlock(x + 1, y + 1, z + 9, Blocks.dirt, 0, 3);
		world.setBlock(x + 2, y + 1, z + 9, Blocks.dirt, 0, 3);
		world.setBlock(x + 3, y + 1, z + 9, Blocks.dirt, 0, 3);
		world.setBlock(x + 4, y + 1, z + 9, Blocks.dirt, 0, 3);
		world.setBlock(x + 5, y + 1, z + 9, Blocks.dirt, 0, 3);
		world.setBlock(x + 6, y + 1, z + 9, Blocks.dirt, 0, 3);
		world.setBlock(x + 7, y + 1, z + 9, Blocks.dirt, 0, 3);
		world.setBlock(x + 8, y + 1, z + 9, Blocks.dirt, 0, 3);
		world.setBlock(x + 9, y + 1, z + 9, Blocks.dirt, 0, 3);
		world.setBlock(x + 10, y + 1, z + 9, Blocks.dirt, 0, 3);
		world.setBlock(x + 11, y + 1, z + 9, Blocks.dirt, 0, 3);
		world.setBlock(x + 12, y + 1, z + 9, Blocks.dirt, 0, 3);
		world.setBlock(x + 13, y + 1, z + 9, Blocks.dirt, 0, 3);
		world.setBlock(x + 14, y + 1, z + 9, Blocks.dirt, 0, 3);
		world.setBlock(x + 15, y + 1, z + 9, Blocks.dirt, 0, 3);
		world.setBlock(x + 16, y + 1, z + 9, Blocks.dirt, 0, 3);
		world.setBlock(x + 17, y + 1, z + 9, Blocks.dirt, 0, 3);
		world.setBlock(x + 18, y + 1, z + 9, Blocks.dirt, 0, 3);
		world.setBlock(x + 0, y + 1, z + 10, Blocks.dirt, 0, 3);
		world.setBlock(x + 1, y + 1, z + 10, Blocks.dirt, 0, 3);
		world.setBlock(x + 2, y + 1, z + 10, Blocks.dirt, 0, 3);
		world.setBlock(x + 3, y + 1, z + 10, Blocks.dirt, 0, 3);
		world.setBlock(x + 4, y + 1, z + 10, Blocks.dirt, 0, 3);
		world.setBlock(x + 5, y + 1, z + 10, Blocks.dirt, 0, 3);
		world.setBlock(x + 6, y + 1, z + 10, Blocks.dirt, 0, 3);
		world.setBlock(x + 7, y + 1, z + 10, Blocks.dirt, 0, 3);
		world.setBlock(x + 8, y + 1, z + 10, Blocks.dirt, 0, 3);
		world.setBlock(x + 9, y + 1, z + 10, Blocks.dirt, 0, 3);
		world.setBlock(x + 10, y + 1, z + 10, Blocks.dirt, 0, 3);
		world.setBlock(x + 11, y + 1, z + 10, Blocks.dirt, 0, 3);
		world.setBlock(x + 12, y + 1, z + 10, Blocks.dirt, 0, 3);
		world.setBlock(x + 13, y + 1, z + 10, Blocks.dirt, 0, 3);
		world.setBlock(x + 14, y + 1, z + 10, Blocks.dirt, 0, 3);
		world.setBlock(x + 15, y + 1, z + 10, Blocks.dirt, 0, 3);
		world.setBlock(x + 16, y + 1, z + 10, Blocks.dirt, 0, 3);
		world.setBlock(x + 17, y + 1, z + 10, Blocks.dirt, 0, 3);
		world.setBlock(x + 18, y + 1, z + 10, Blocks.dirt, 0, 3);
		world.setBlock(x + 0, y + 1, z + 11, Blocks.dirt, 0, 3);
		world.setBlock(x + 1, y + 1, z + 11, Blocks.dirt, 0, 3);
		world.setBlock(x + 2, y + 1, z + 11, Blocks.dirt, 0, 3);
		world.setBlock(x + 3, y + 1, z + 11, Blocks.dirt, 0, 3);
		world.setBlock(x + 4, y + 1, z + 11, Blocks.dirt, 0, 3);
		world.setBlock(x + 5, y + 1, z + 11, Blocks.dirt, 0, 3);
		world.setBlock(x + 6, y + 1, z + 11, Blocks.dirt, 0, 3);
		world.setBlock(x + 7, y + 1, z + 11, Blocks.dirt, 0, 3);
		world.setBlock(x + 8, y + 1, z + 11, Blocks.dirt, 0, 3);
		world.setBlock(x + 9, y + 1, z + 11, Blocks.dirt, 0, 3);
		world.setBlock(x + 10, y + 1, z + 11, Blocks.dirt, 0, 3);
		world.setBlock(x + 11, y + 1, z + 11, Blocks.dirt, 0, 3);
		world.setBlock(x + 12, y + 1, z + 11, Blocks.dirt, 0, 3);
		world.setBlock(x + 13, y + 1, z + 11, Blocks.dirt, 0, 3);
		world.setBlock(x + 14, y + 1, z + 11, Blocks.dirt, 0, 3);
		world.setBlock(x + 15, y + 1, z + 11, Blocks.dirt, 0, 3);
		world.setBlock(x + 16, y + 1, z + 11, Blocks.dirt, 0, 3);
		world.setBlock(x + 17, y + 1, z + 11, Blocks.dirt, 0, 3);
		world.setBlock(x + 18, y + 1, z + 11, Blocks.dirt, 0, 3);
		world.setBlock(x + 0, y + 1, z + 12, Blocks.dirt, 0, 3);
		world.setBlock(x + 1, y + 1, z + 12, Blocks.dirt, 0, 3);
		world.setBlock(x + 2, y + 1, z + 12, Blocks.dirt, 0, 3);
		world.setBlock(x + 3, y + 1, z + 12, Blocks.dirt, 0, 3);
		world.setBlock(x + 4, y + 1, z + 12, Blocks.dirt, 0, 3);
		world.setBlock(x + 5, y + 1, z + 12, Blocks.dirt, 0, 3);
		world.setBlock(x + 6, y + 1, z + 12, Blocks.dirt, 0, 3);
		world.setBlock(x + 7, y + 1, z + 12, Blocks.dirt, 0, 3);
		world.setBlock(x + 8, y + 1, z + 12, Blocks.dirt, 0, 3);
		world.setBlock(x + 9, y + 1, z + 12, Blocks.dirt, 0, 3);
		world.setBlock(x + 10, y + 1, z + 12, Blocks.dirt, 0, 3);
		world.setBlock(x + 11, y + 1, z + 12, Blocks.dirt, 0, 3);
		world.setBlock(x + 12, y + 1, z + 12, Blocks.dirt, 0, 3);
		world.setBlock(x + 13, y + 1, z + 12, Blocks.dirt, 0, 3);
		world.setBlock(x + 14, y + 1, z + 12, Blocks.dirt, 0, 3);
		world.setBlock(x + 15, y + 1, z + 12, Blocks.dirt, 0, 3);
		world.setBlock(x + 16, y + 1, z + 12, Blocks.dirt, 0, 3);
		world.setBlock(x + 17, y + 1, z + 12, Blocks.dirt, 0, 3);
		world.setBlock(x + 18, y + 1, z + 12, Blocks.dirt, 0, 3);
		world.setBlock(x + 0, y + 1, z + 13, Blocks.dirt, 0, 3);
		world.setBlock(x + 1, y + 1, z + 13, Blocks.dirt, 0, 3);
		world.setBlock(x + 2, y + 1, z + 13, Blocks.dirt, 0, 3);
		world.setBlock(x + 3, y + 1, z + 13, Blocks.dirt, 0, 3);
		world.setBlock(x + 4, y + 1, z + 13, Blocks.dirt, 0, 3);
		world.setBlock(x + 5, y + 1, z + 13, Blocks.dirt, 0, 3);
		world.setBlock(x + 6, y + 1, z + 13, Blocks.dirt, 0, 3);
		world.setBlock(x + 7, y + 1, z + 13, Blocks.dirt, 0, 3);
		world.setBlock(x + 8, y + 1, z + 13, Blocks.dirt, 0, 3);
		world.setBlock(x + 9, y + 1, z + 13, Blocks.dirt, 0, 3);
		world.setBlock(x + 10, y + 1, z + 13, Blocks.dirt, 0, 3);
		world.setBlock(x + 11, y + 1, z + 13, Blocks.dirt, 0, 3);
		world.setBlock(x + 12, y + 1, z + 13, Blocks.dirt, 0, 3);
		world.setBlock(x + 13, y + 1, z + 13, Blocks.dirt, 0, 3);
		world.setBlock(x + 14, y + 1, z + 13, Blocks.dirt, 0, 3);
		world.setBlock(x + 15, y + 1, z + 13, Blocks.dirt, 0, 3);
		world.setBlock(x + 16, y + 1, z + 13, Blocks.dirt, 0, 3);
		world.setBlock(x + 17, y + 1, z + 13, Blocks.dirt, 0, 3);
		world.setBlock(x + 18, y + 1, z + 13, Blocks.dirt, 0, 3);
		world.setBlock(x + 0, y + 1, z + 14, Blocks.dirt, 0, 3);
		world.setBlock(x + 1, y + 1, z + 14, Blocks.dirt, 0, 3);
		world.setBlock(x + 2, y + 1, z + 14, Blocks.dirt, 0, 3);
		world.setBlock(x + 3, y + 1, z + 14, Blocks.dirt, 0, 3);
		world.setBlock(x + 4, y + 1, z + 14, Blocks.dirt, 0, 3);
		world.setBlock(x + 5, y + 1, z + 14, Blocks.dirt, 0, 3);
		world.setBlock(x + 6, y + 1, z + 14, Blocks.dirt, 0, 3);
		world.setBlock(x + 7, y + 1, z + 14, Blocks.dirt, 0, 3);
		world.setBlock(x + 8, y + 1, z + 14, Blocks.dirt, 0, 3);
		world.setBlock(x + 9, y + 1, z + 14, Blocks.dirt, 0, 3);
		world.setBlock(x + 10, y + 1, z + 14, Blocks.dirt, 0, 3);
		world.setBlock(x + 11, y + 1, z + 14, Blocks.dirt, 0, 3);
		world.setBlock(x + 12, y + 1, z + 14, Blocks.dirt, 0, 3);
		world.setBlock(x + 13, y + 1, z + 14, Blocks.dirt, 0, 3);
		world.setBlock(x + 14, y + 1, z + 14, Blocks.dirt, 0, 3);
		world.setBlock(x + 15, y + 1, z + 14, Blocks.dirt, 0, 3);
		world.setBlock(x + 16, y + 1, z + 14, Blocks.dirt, 0, 3);
		world.setBlock(x + 17, y + 1, z + 14, Blocks.dirt, 0, 3);
		world.setBlock(x + 18, y + 1, z + 14, Blocks.dirt, 0, 3);
		world.setBlock(x + 0, y + 1, z + 15, Blocks.dirt, 0, 3);
		world.setBlock(x + 1, y + 1, z + 15, Blocks.dirt, 0, 3);
		world.setBlock(x + 2, y + 1, z + 15, Blocks.dirt, 0, 3);
		world.setBlock(x + 3, y + 1, z + 15, Blocks.dirt, 0, 3);
		world.setBlock(x + 4, y + 1, z + 15, Blocks.dirt, 0, 3);
		world.setBlock(x + 5, y + 1, z + 15, Blocks.dirt, 0, 3);
		world.setBlock(x + 6, y + 1, z + 15, Blocks.dirt, 0, 3);
		world.setBlock(x + 7, y + 1, z + 15, Blocks.dirt, 0, 3);
		world.setBlock(x + 8, y + 1, z + 15, Blocks.dirt, 0, 3);
		world.setBlock(x + 9, y + 1, z + 15, Blocks.dirt, 0, 3);
		world.setBlock(x + 10, y + 1, z + 15, Blocks.dirt, 0, 3);
		world.setBlock(x + 11, y + 1, z + 15, Blocks.dirt, 0, 3);
		world.setBlock(x + 12, y + 1, z + 15, Blocks.dirt, 0, 3);
		world.setBlock(x + 13, y + 1, z + 15, Blocks.dirt, 0, 3);
		world.setBlock(x + 14, y + 1, z + 15, Blocks.dirt, 0, 3);
		world.setBlock(x + 15, y + 1, z + 15, Blocks.dirt, 0, 3);
		world.setBlock(x + 16, y + 1, z + 15, Blocks.dirt, 0, 3);
		world.setBlock(x + 17, y + 1, z + 15, Blocks.dirt, 0, 3);
		world.setBlock(x + 18, y + 1, z + 15, Blocks.dirt, 0, 3);
		world.setBlock(x + 0, y + 1, z + 16, Blocks.dirt, 0, 3);
		world.setBlock(x + 1, y + 1, z + 16, Blocks.dirt, 0, 3);
		world.setBlock(x + 2, y + 1, z + 16, Blocks.dirt, 0, 3);
		world.setBlock(x + 3, y + 1, z + 16, Blocks.dirt, 0, 3);
		world.setBlock(x + 4, y + 1, z + 16, Blocks.dirt, 0, 3);
		world.setBlock(x + 5, y + 1, z + 16, Blocks.dirt, 0, 3);
		world.setBlock(x + 6, y + 1, z + 16, Blocks.dirt, 0, 3);
		world.setBlock(x + 7, y + 1, z + 16, Blocks.dirt, 0, 3);
		world.setBlock(x + 8, y + 1, z + 16, Blocks.dirt, 0, 3);
		world.setBlock(x + 9, y + 1, z + 16, Blocks.dirt, 0, 3);
		world.setBlock(x + 10, y + 1, z + 16, Blocks.dirt, 0, 3);
		world.setBlock(x + 11, y + 1, z + 16, Blocks.dirt, 0, 3);
		world.setBlock(x + 12, y + 1, z + 16, Blocks.dirt, 0, 3);
		world.setBlock(x + 13, y + 1, z + 16, Blocks.dirt, 0, 3);
		world.setBlock(x + 14, y + 1, z + 16, Blocks.dirt, 0, 3);
		world.setBlock(x + 15, y + 1, z + 16, Blocks.dirt, 0, 3);
		world.setBlock(x + 16, y + 1, z + 16, Blocks.dirt, 0, 3);
		world.setBlock(x + 17, y + 1, z + 16, Blocks.dirt, 0, 3);
		world.setBlock(x + 18, y + 1, z + 16, Blocks.dirt, 0, 3);
		world.setBlock(x + 0, y + 1, z + 17, Blocks.dirt, 0, 3);
		world.setBlock(x + 1, y + 1, z + 17, Blocks.dirt, 0, 3);
		world.setBlock(x + 2, y + 1, z + 17, Blocks.dirt, 0, 3);
		world.setBlock(x + 3, y + 1, z + 17, Blocks.dirt, 0, 3);
		world.setBlock(x + 4, y + 1, z + 17, Blocks.dirt, 0, 3);
		world.setBlock(x + 5, y + 1, z + 17, Blocks.dirt, 0, 3);
		world.setBlock(x + 6, y + 1, z + 17, Blocks.dirt, 0, 3);
		world.setBlock(x + 7, y + 1, z + 17, Blocks.dirt, 0, 3);
		world.setBlock(x + 8, y + 1, z + 17, Blocks.dirt, 0, 3);
		world.setBlock(x + 9, y + 1, z + 17, Blocks.dirt, 0, 3);
		world.setBlock(x + 10, y + 1, z + 17, Blocks.dirt, 0, 3);
		world.setBlock(x + 11, y + 1, z + 17, Blocks.dirt, 0, 3);
		world.setBlock(x + 12, y + 1, z + 17, Blocks.dirt, 0, 3);
		world.setBlock(x + 13, y + 1, z + 17, Blocks.dirt, 0, 3);
		world.setBlock(x + 14, y + 1, z + 17, Blocks.dirt, 0, 3);
		world.setBlock(x + 15, y + 1, z + 17, Blocks.dirt, 0, 3);
		world.setBlock(x + 16, y + 1, z + 17, Blocks.dirt, 0, 3);
		world.setBlock(x + 17, y + 1, z + 17, Blocks.dirt, 0, 3);
		world.setBlock(x + 18, y + 1, z + 17, Blocks.dirt, 0, 3);
		world.setBlock(x + 0, y + 2, z + 0, Blocks.dirt, 0, 3);
		world.setBlock(x + 1, y + 2, z + 0, Blocks.dirt, 0, 3);
		world.setBlock(x + 2, y + 2, z + 0, Blocks.dirt, 0, 3);
		world.setBlock(x + 3, y + 2, z + 0, Blocks.dirt, 0, 3);
		world.setBlock(x + 4, y + 2, z + 0, Blocks.dirt, 0, 3);
		world.setBlock(x + 5, y + 2, z + 0, Blocks.dirt, 0, 3);
		world.setBlock(x + 6, y + 2, z + 0, Blocks.dirt, 0, 3);
		world.setBlock(x + 7, y + 2, z + 0, Blocks.dirt, 0, 3);
		world.setBlock(x + 8, y + 2, z + 0, Blocks.dirt, 0, 3);
		world.setBlock(x + 9, y + 2, z + 0, Blocks.dirt, 0, 3);
		world.setBlock(x + 10, y + 2, z + 0, Blocks.dirt, 0, 3);
		world.setBlock(x + 11, y + 2, z + 0, Blocks.dirt, 0, 3);
		world.setBlock(x + 12, y + 2, z + 0, Blocks.dirt, 0, 3);
		world.setBlock(x + 13, y + 2, z + 0, Blocks.dirt, 0, 3);
		world.setBlock(x + 14, y + 2, z + 0, Blocks.dirt, 0, 3);
		world.setBlock(x + 15, y + 2, z + 0, Blocks.dirt, 0, 3);
		world.setBlock(x + 16, y + 2, z + 0, Blocks.dirt, 0, 3);
		world.setBlock(x + 17, y + 2, z + 0, Blocks.dirt, 0, 3);
		world.setBlock(x + 18, y + 2, z + 0, Blocks.dirt, 0, 3);
		world.setBlock(x + 0, y + 2, z + 1, Blocks.dirt, 0, 3);
		world.setBlock(x + 1, y + 2, z + 1, Blocks.dirt, 0, 3);
		world.setBlock(x + 2, y + 2, z + 1, Blocks.dirt, 0, 3);
		world.setBlock(x + 3, y + 2, z + 1, Blocks.dirt, 0, 3);
		world.setBlock(x + 4, y + 2, z + 1, Blocks.dirt, 0, 3);
		world.setBlock(x + 5, y + 2, z + 1, Blocks.dirt, 0, 3);
		world.setBlock(x + 6, y + 2, z + 1, Blocks.dirt, 0, 3);
		world.setBlock(x + 7, y + 2, z + 1, Blocks.dirt, 0, 3);
		world.setBlock(x + 8, y + 2, z + 1, Blocks.dirt, 0, 3);
		world.setBlock(x + 9, y + 2, z + 1, Blocks.dirt, 0, 3);
		world.setBlock(x + 10, y + 2, z + 1, Blocks.dirt, 0, 3);
		world.setBlock(x + 11, y + 2, z + 1, Blocks.dirt, 0, 3);
		world.setBlock(x + 12, y + 2, z + 1, Blocks.dirt, 0, 3);
		world.setBlock(x + 13, y + 2, z + 1, Blocks.dirt, 0, 3);
		world.setBlock(x + 14, y + 2, z + 1, Blocks.dirt, 0, 3);
		world.setBlock(x + 15, y + 2, z + 1, Blocks.dirt, 0, 3);
		world.setBlock(x + 16, y + 2, z + 1, Blocks.dirt, 0, 3);
		world.setBlock(x + 17, y + 2, z + 1, Blocks.dirt, 0, 3);
		world.setBlock(x + 18, y + 2, z + 1, Blocks.dirt, 0, 3);
		world.setBlock(x + 0, y + 2, z + 2, Blocks.dirt, 0, 3);
		world.setBlock(x + 1, y + 2, z + 2, Blocks.dirt, 0, 3);
		world.setBlock(x + 2, y + 2, z + 2, Blocks.dirt, 0, 3);
		world.setBlock(x + 3, y + 2, z + 2, Blocks.dirt, 0, 3);
		world.setBlock(x + 4, y + 2, z + 2, Blocks.dirt, 0, 3);
		world.setBlock(x + 5, y + 2, z + 2, Blocks.dirt, 0, 3);
		world.setBlock(x + 6, y + 2, z + 2, Blocks.dirt, 0, 3);
		world.setBlock(x + 7, y + 2, z + 2, Blocks.dirt, 0, 3);
		world.setBlock(x + 8, y + 2, z + 2, Blocks.dirt, 0, 3);
		world.setBlock(x + 9, y + 2, z + 2, Blocks.dirt, 0, 3);
		world.setBlock(x + 10, y + 2, z + 2, Blocks.dirt, 0, 3);
		world.setBlock(x + 11, y + 2, z + 2, Blocks.dirt, 0, 3);
		world.setBlock(x + 12, y + 2, z + 2, Blocks.dirt, 0, 3);
		world.setBlock(x + 13, y + 2, z + 2, Blocks.dirt, 0, 3);
		world.setBlock(x + 14, y + 2, z + 2, Blocks.dirt, 0, 3);
		world.setBlock(x + 15, y + 2, z + 2, Blocks.dirt, 0, 3);
		world.setBlock(x + 16, y + 2, z + 2, Blocks.dirt, 0, 3);
		world.setBlock(x + 17, y + 2, z + 2, Blocks.dirt, 0, 3);
		world.setBlock(x + 18, y + 2, z + 2, Blocks.dirt, 0, 3);
		world.setBlock(x + 0, y + 2, z + 3, Blocks.dirt, 0, 3);
		world.setBlock(x + 1, y + 2, z + 3, Blocks.dirt, 0, 3);
		world.setBlock(x + 2, y + 2, z + 3, Blocks.dirt, 0, 3);
		world.setBlock(x + 3, y + 2, z + 3, Blocks.dirt, 0, 3);
		world.setBlock(x + 4, y + 2, z + 3, Blocks.dirt, 0, 3);
		world.setBlock(x + 5, y + 2, z + 3, Blocks.dirt, 0, 3);
		world.setBlock(x + 6, y + 2, z + 3, Blocks.dirt, 0, 3);
		world.setBlock(x + 7, y + 2, z + 3, Blocks.dirt, 0, 3);
		world.setBlock(x + 8, y + 2, z + 3, Blocks.dirt, 0, 3);
		world.setBlock(x + 9, y + 2, z + 3, Blocks.dirt, 0, 3);
		world.setBlock(x + 10, y + 2, z + 3, Blocks.dirt, 0, 3);
		world.setBlock(x + 11, y + 2, z + 3, Blocks.dirt, 0, 3);
		world.setBlock(x + 12, y + 2, z + 3, Blocks.dirt, 0, 3);
		world.setBlock(x + 13, y + 2, z + 3, Blocks.dirt, 0, 3);
		world.setBlock(x + 14, y + 2, z + 3, Blocks.dirt, 0, 3);
		world.setBlock(x + 15, y + 2, z + 3, Blocks.dirt, 0, 3);
		world.setBlock(x + 16, y + 2, z + 3, Blocks.dirt, 0, 3);
		world.setBlock(x + 17, y + 2, z + 3, Blocks.dirt, 0, 3);
		world.setBlock(x + 18, y + 2, z + 3, Blocks.dirt, 0, 3);
		world.setBlock(x + 0, y + 2, z + 4, Blocks.dirt, 0, 3);
		world.setBlock(x + 1, y + 2, z + 4, Blocks.dirt, 0, 3);
		world.setBlock(x + 2, y + 2, z + 4, Blocks.dirt, 0, 3);
		world.setBlock(x + 3, y + 2, z + 4, Blocks.dirt, 0, 3);
		world.setBlock(x + 4, y + 2, z + 4, Blocks.dirt, 0, 3);
		world.setBlock(x + 5, y + 2, z + 4, Blocks.dirt, 0, 3);
		world.setBlock(x + 6, y + 2, z + 4, Blocks.dirt, 0, 3);
		world.setBlock(x + 7, y + 2, z + 4, Blocks.dirt, 0, 3);
		world.setBlock(x + 8, y + 2, z + 4, Blocks.dirt, 0, 3);
		world.setBlock(x + 9, y + 2, z + 4, Blocks.dirt, 0, 3);
		world.setBlock(x + 10, y + 2, z + 4, Blocks.dirt, 0, 3);
		world.setBlock(x + 11, y + 2, z + 4, Blocks.dirt, 0, 3);
		world.setBlock(x + 12, y + 2, z + 4, Blocks.dirt, 0, 3);
		world.setBlock(x + 13, y + 2, z + 4, Blocks.dirt, 0, 3);
		world.setBlock(x + 14, y + 2, z + 4, Blocks.dirt, 0, 3);
		world.setBlock(x + 15, y + 2, z + 4, Blocks.dirt, 0, 3);
		world.setBlock(x + 16, y + 2, z + 4, Blocks.dirt, 0, 3);
		world.setBlock(x + 17, y + 2, z + 4, Blocks.dirt, 0, 3);
		world.setBlock(x + 18, y + 2, z + 4, Blocks.dirt, 0, 3);
		world.setBlock(x + 0, y + 2, z + 5, Blocks.dirt, 0, 3);
		world.setBlock(x + 1, y + 2, z + 5, Blocks.dirt, 0, 3);
		world.setBlock(x + 2, y + 2, z + 5, Blocks.dirt, 0, 3);
		world.setBlock(x + 3, y + 2, z + 5, Blocks.dirt, 0, 3);
		world.setBlock(x + 4, y + 2, z + 5, Blocks.dirt, 0, 3);
		world.setBlock(x + 5, y + 2, z + 5, Blocks.dirt, 0, 3);
		world.setBlock(x + 6, y + 2, z + 5, Blocks.dirt, 0, 3);
		world.setBlock(x + 7, y + 2, z + 5, Blocks.dirt, 0, 3);
		world.setBlock(x + 8, y + 2, z + 5, Blocks.dirt, 0, 3);
		world.setBlock(x + 9, y + 2, z + 5, Blocks.stonebrick, 0, 3);
		world.setBlock(x + 10, y + 2, z + 5, Blocks.dirt, 0, 3);
		world.setBlock(x + 11, y + 2, z + 5, Blocks.dirt, 0, 3);
		world.setBlock(x + 12, y + 2, z + 5, Blocks.dirt, 0, 3);
		world.setBlock(x + 13, y + 2, z + 5, Blocks.dirt, 0, 3);
		world.setBlock(x + 14, y + 2, z + 5, Blocks.dirt, 0, 3);
		world.setBlock(x + 15, y + 2, z + 5, Blocks.dirt, 0, 3);
		world.setBlock(x + 16, y + 2, z + 5, Blocks.dirt, 0, 3);
		world.setBlock(x + 17, y + 2, z + 5, Blocks.dirt, 0, 3);
		world.setBlock(x + 18, y + 2, z + 5, Blocks.dirt, 0, 3);
		world.setBlock(x + 0, y + 2, z + 6, Blocks.dirt, 0, 3);
		world.setBlock(x + 1, y + 2, z + 6, Blocks.dirt, 0, 3);
		world.setBlock(x + 2, y + 2, z + 6, Blocks.dirt, 0, 3);
		world.setBlock(x + 3, y + 2, z + 6, Blocks.dirt, 0, 3);
		world.setBlock(x + 4, y + 2, z + 6, Blocks.dirt, 0, 3);
		world.setBlock(x + 5, y + 2, z + 6, Blocks.dirt, 0, 3);
		world.setBlock(x + 6, y + 2, z + 6, Blocks.dirt, 0, 3);
		world.setBlock(x + 7, y + 2, z + 6, Blocks.dirt, 0, 3);
		world.setBlock(x + 8, y + 2, z + 6, Blocks.stonebrick, 0, 3);
		world.setBlock(x + 9, y + 2, z + 6, Blocks.stonebrick, 0, 3);
		world.setBlock(x + 10, y + 2, z + 6, Blocks.stonebrick, 0, 3);
		world.setBlock(x + 11, y + 2, z + 6, Blocks.dirt, 0, 3);
		world.setBlock(x + 12, y + 2, z + 6, Blocks.dirt, 0, 3);
		world.setBlock(x + 13, y + 2, z + 6, Blocks.dirt, 0, 3);
		world.setBlock(x + 14, y + 2, z + 6, Blocks.dirt, 0, 3);
		world.setBlock(x + 15, y + 2, z + 6, Blocks.dirt, 0, 3);
		world.setBlock(x + 16, y + 2, z + 6, Blocks.dirt, 0, 3);
		world.setBlock(x + 17, y + 2, z + 6, Blocks.dirt, 0, 3);
		world.setBlock(x + 18, y + 2, z + 6, Blocks.dirt, 0, 3);
		world.setBlock(x + 0, y + 2, z + 7, Blocks.dirt, 0, 3);
		world.setBlock(x + 1, y + 2, z + 7, Blocks.dirt, 0, 3);
		world.setBlock(x + 2, y + 2, z + 7, Blocks.dirt, 0, 3);
		world.setBlock(x + 3, y + 2, z + 7, Blocks.dirt, 0, 3);
		world.setBlock(x + 4, y + 2, z + 7, Blocks.dirt, 0, 3);
		world.setBlock(x + 5, y + 2, z + 7, Blocks.dirt, 0, 3);
		world.setBlock(x + 6, y + 2, z + 7, Blocks.dirt, 0, 3);
		world.setBlock(x + 7, y + 2, z + 7, Blocks.stonebrick, 0, 3);
		world.setBlock(x + 8, y + 2, z + 7, Blocks.stonebrick, 0, 3);
		world.setBlock(x + 9, y + 2, z + 7, Blocks.gold_block, 0, 3);
		world.setBlock(x + 10, y + 2, z + 7, Blocks.stonebrick, 0, 3);
		world.setBlock(x + 11, y + 2, z + 7, Blocks.stonebrick, 0, 3);
		world.setBlock(x + 12, y + 2, z + 7, Blocks.dirt, 0, 3);
		world.setBlock(x + 13, y + 2, z + 7, Blocks.dirt, 0, 3);
		world.setBlock(x + 14, y + 2, z + 7, Blocks.dirt, 0, 3);
		world.setBlock(x + 15, y + 2, z + 7, Blocks.dirt, 0, 3);
		world.setBlock(x + 16, y + 2, z + 7, Blocks.dirt, 0, 3);
		world.setBlock(x + 17, y + 2, z + 7, Blocks.dirt, 0, 3);
		world.setBlock(x + 18, y + 2, z + 7, Blocks.dirt, 0, 3);
		world.setBlock(x + 0, y + 2, z + 8, Blocks.dirt, 0, 3);
		world.setBlock(x + 1, y + 2, z + 8, Blocks.dirt, 0, 3);
		world.setBlock(x + 2, y + 2, z + 8, Blocks.dirt, 0, 3);
		world.setBlock(x + 3, y + 2, z + 8, Blocks.dirt, 0, 3);
		world.setBlock(x + 4, y + 2, z + 8, Blocks.dirt, 0, 3);
		world.setBlock(x + 5, y + 2, z + 8, Blocks.dirt, 0, 3);
		world.setBlock(x + 6, y + 2, z + 8, Blocks.stonebrick, 0, 3);
		world.setBlock(x + 7, y + 2, z + 8, Blocks.stonebrick, 0, 3);
		world.setBlock(x + 8, y + 2, z + 8, Blocks.gold_block, 0, 3);
		world.setBlock(x + 9, y + 2, z + 8, Blocks.emerald_block, 0, 3);
		world.setBlock(x + 10, y + 2, z + 8, Blocks.gold_block, 0, 3);
		world.setBlock(x + 11, y + 2, z + 8, Blocks.stonebrick, 0, 3);
		world.setBlock(x + 12, y + 2, z + 8, Blocks.stonebrick, 0, 3);
		world.setBlock(x + 13, y + 2, z + 8, Blocks.dirt, 0, 3);
		world.setBlock(x + 14, y + 2, z + 8, Blocks.dirt, 0, 3);
		world.setBlock(x + 15, y + 2, z + 8, Blocks.dirt, 0, 3);
		world.setBlock(x + 16, y + 2, z + 8, Blocks.dirt, 0, 3);
		world.setBlock(x + 17, y + 2, z + 8, Blocks.dirt, 0, 3);
		world.setBlock(x + 18, y + 2, z + 8, Blocks.dirt, 0, 3);
		world.setBlock(x + 0, y + 2, z + 9, Blocks.dirt, 0, 3);
		world.setBlock(x + 1, y + 2, z + 9, Blocks.dirt, 0, 3);
		world.setBlock(x + 2, y + 2, z + 9, Blocks.dirt, 0, 3);
		world.setBlock(x + 3, y + 2, z + 9, Blocks.dirt, 0, 3);
		world.setBlock(x + 4, y + 2, z + 9, Blocks.dirt, 0, 3);
		world.setBlock(x + 5, y + 2, z + 9, Blocks.dirt, 0, 3);
		world.setBlock(x + 6, y + 2, z + 9, Blocks.dirt, 0, 3);
		world.setBlock(x + 7, y + 2, z + 9, Blocks.stonebrick, 0, 3);
		world.setBlock(x + 8, y + 2, z + 9, Blocks.stonebrick, 0, 3);
		world.setBlock(x + 9, y + 2, z + 9, Blocks.gold_block, 0, 3);
		world.setBlock(x + 10, y + 2, z + 9, Blocks.stonebrick, 0, 3);
		world.setBlock(x + 11, y + 2, z + 9, Blocks.stonebrick, 0, 3);
		world.setBlock(x + 12, y + 2, z + 9, Blocks.dirt, 0, 3);
		world.setBlock(x + 13, y + 2, z + 9, Blocks.dirt, 0, 3);
		world.setBlock(x + 14, y + 2, z + 9, Blocks.dirt, 0, 3);
		world.setBlock(x + 15, y + 2, z + 9, Blocks.dirt, 0, 3);
		world.setBlock(x + 16, y + 2, z + 9, Blocks.dirt, 0, 3);
		world.setBlock(x + 17, y + 2, z + 9, Blocks.dirt, 0, 3);
		world.setBlock(x + 18, y + 2, z + 9, Blocks.dirt, 0, 3);
		world.setBlock(x + 0, y + 2, z + 10, Blocks.dirt, 0, 3);
		world.setBlock(x + 1, y + 2, z + 10, Blocks.dirt, 0, 3);
		world.setBlock(x + 2, y + 2, z + 10, Blocks.dirt, 0, 3);
		world.setBlock(x + 3, y + 2, z + 10, Blocks.dirt, 0, 3);
		world.setBlock(x + 4, y + 2, z + 10, Blocks.dirt, 0, 3);
		world.setBlock(x + 5, y + 2, z + 10, Blocks.dirt, 0, 3);
		world.setBlock(x + 6, y + 2, z + 10, Blocks.dirt, 0, 3);
		world.setBlock(x + 7, y + 2, z + 10, Blocks.dirt, 0, 3);
		world.setBlock(x + 8, y + 2, z + 10, Blocks.stonebrick, 0, 3);
		world.setBlock(x + 9, y + 2, z + 10, Blocks.stonebrick, 0, 3);
		world.setBlock(x + 10, y + 2, z + 10, Blocks.stonebrick, 0, 3);
		world.setBlock(x + 11, y + 2, z + 10, Blocks.dirt, 0, 3);
		world.setBlock(x + 12, y + 2, z + 10, Blocks.dirt, 0, 3);
		world.setBlock(x + 13, y + 2, z + 10, Blocks.dirt, 0, 3);
		world.setBlock(x + 14, y + 2, z + 10, Blocks.dirt, 0, 3);
		world.setBlock(x + 15, y + 2, z + 10, Blocks.dirt, 0, 3);
		world.setBlock(x + 16, y + 2, z + 10, Blocks.dirt, 0, 3);
		world.setBlock(x + 17, y + 2, z + 10, Blocks.dirt, 0, 3);
		world.setBlock(x + 18, y + 2, z + 10, Blocks.dirt, 0, 3);
		world.setBlock(x + 0, y + 2, z + 11, Blocks.dirt, 0, 3);
		world.setBlock(x + 1, y + 2, z + 11, Blocks.dirt, 0, 3);
		world.setBlock(x + 2, y + 2, z + 11, Blocks.dirt, 0, 3);
		world.setBlock(x + 3, y + 2, z + 11, Blocks.dirt, 0, 3);
		world.setBlock(x + 4, y + 2, z + 11, Blocks.dirt, 0, 3);
		world.setBlock(x + 5, y + 2, z + 11, Blocks.dirt, 0, 3);
		world.setBlock(x + 6, y + 2, z + 11, Blocks.dirt, 0, 3);
		world.setBlock(x + 7, y + 2, z + 11, Blocks.dirt, 0, 3);
		world.setBlock(x + 8, y + 2, z + 11, Blocks.dirt, 0, 3);
		world.setBlock(x + 9, y + 2, z + 11, Blocks.stonebrick, 0, 3);
		world.setBlock(x + 10, y + 2, z + 11, Blocks.dirt, 0, 3);
		world.setBlock(x + 11, y + 2, z + 11, Blocks.dirt, 0, 3);
		world.setBlock(x + 12, y + 2, z + 11, Blocks.dirt, 0, 3);
		world.setBlock(x + 13, y + 2, z + 11, Blocks.dirt, 0, 3);
		world.setBlock(x + 14, y + 2, z + 11, Blocks.dirt, 0, 3);
		world.setBlock(x + 15, y + 2, z + 11, Blocks.dirt, 0, 3);
		world.setBlock(x + 16, y + 2, z + 11, Blocks.dirt, 0, 3);
		world.setBlock(x + 17, y + 2, z + 11, Blocks.dirt, 0, 3);
		world.setBlock(x + 18, y + 2, z + 11, Blocks.dirt, 0, 3);
		world.setBlock(x + 0, y + 2, z + 12, Blocks.dirt, 0, 3);
		world.setBlock(x + 1, y + 2, z + 12, Blocks.dirt, 0, 3);
		world.setBlock(x + 2, y + 2, z + 12, Blocks.dirt, 0, 3);
		world.setBlock(x + 3, y + 2, z + 12, Blocks.dirt, 0, 3);
		world.setBlock(x + 4, y + 2, z + 12, Blocks.dirt, 0, 3);
		world.setBlock(x + 5, y + 2, z + 12, Blocks.dirt, 0, 3);
		world.setBlock(x + 6, y + 2, z + 12, Blocks.dirt, 0, 3);
		world.setBlock(x + 7, y + 2, z + 12, Blocks.dirt, 0, 3);
		world.setBlock(x + 8, y + 2, z + 12, Blocks.dirt, 0, 3);
		world.setBlock(x + 9, y + 2, z + 12, Blocks.dirt, 0, 3);
		world.setBlock(x + 10, y + 2, z + 12, Blocks.dirt, 0, 3);
		world.setBlock(x + 11, y + 2, z + 12, Blocks.dirt, 0, 3);
		world.setBlock(x + 12, y + 2, z + 12, Blocks.dirt, 0, 3);
		world.setBlock(x + 13, y + 2, z + 12, Blocks.dirt, 0, 3);
		world.setBlock(x + 14, y + 2, z + 12, Blocks.dirt, 0, 3);
		world.setBlock(x + 15, y + 2, z + 12, Blocks.dirt, 0, 3);
		world.setBlock(x + 16, y + 2, z + 12, Blocks.dirt, 0, 3);
		world.setBlock(x + 17, y + 2, z + 12, Blocks.dirt, 0, 3);
		world.setBlock(x + 18, y + 2, z + 12, Blocks.dirt, 0, 3);
		world.setBlock(x + 0, y + 2, z + 13, Blocks.dirt, 0, 3);
		world.setBlock(x + 1, y + 2, z + 13, Blocks.dirt, 0, 3);
		world.setBlock(x + 2, y + 2, z + 13, Blocks.dirt, 0, 3);
		world.setBlock(x + 3, y + 2, z + 13, Blocks.dirt, 0, 3);
		world.setBlock(x + 4, y + 2, z + 13, Blocks.dirt, 0, 3);
		world.setBlock(x + 5, y + 2, z + 13, Blocks.dirt, 0, 3);
		world.setBlock(x + 6, y + 2, z + 13, Blocks.dirt, 0, 3);
		world.setBlock(x + 7, y + 2, z + 13, Blocks.dirt, 0, 3);
		world.setBlock(x + 8, y + 2, z + 13, Blocks.dirt, 0, 3);
		world.setBlock(x + 9, y + 2, z + 13, Blocks.dirt, 0, 3);
		world.setBlock(x + 10, y + 2, z + 13, Blocks.dirt, 0, 3);
		world.setBlock(x + 11, y + 2, z + 13, Blocks.dirt, 0, 3);
		world.setBlock(x + 12, y + 2, z + 13, Blocks.dirt, 0, 3);
		world.setBlock(x + 13, y + 2, z + 13, Blocks.dirt, 0, 3);
		world.setBlock(x + 14, y + 2, z + 13, Blocks.dirt, 0, 3);
		world.setBlock(x + 15, y + 2, z + 13, Blocks.dirt, 0, 3);
		world.setBlock(x + 16, y + 2, z + 13, Blocks.dirt, 0, 3);
		world.setBlock(x + 17, y + 2, z + 13, Blocks.dirt, 0, 3);
		world.setBlock(x + 18, y + 2, z + 13, Blocks.dirt, 0, 3);
		world.setBlock(x + 0, y + 2, z + 14, Blocks.dirt, 0, 3);
		world.setBlock(x + 1, y + 2, z + 14, Blocks.dirt, 0, 3);
		world.setBlock(x + 2, y + 2, z + 14, Blocks.dirt, 0, 3);
		world.setBlock(x + 3, y + 2, z + 14, Blocks.dirt, 0, 3);
		world.setBlock(x + 4, y + 2, z + 14, Blocks.dirt, 0, 3);
		world.setBlock(x + 5, y + 2, z + 14, Blocks.dirt, 0, 3);
		world.setBlock(x + 6, y + 2, z + 14, Blocks.dirt, 0, 3);
		world.setBlock(x + 7, y + 2, z + 14, Blocks.dirt, 0, 3);
		world.setBlock(x + 8, y + 2, z + 14, Blocks.dirt, 0, 3);
		world.setBlock(x + 9, y + 2, z + 14, Blocks.dirt, 0, 3);
		world.setBlock(x + 10, y + 2, z + 14, Blocks.dirt, 0, 3);
		world.setBlock(x + 11, y + 2, z + 14, Blocks.dirt, 0, 3);
		world.setBlock(x + 12, y + 2, z + 14, Blocks.dirt, 0, 3);
		world.setBlock(x + 13, y + 2, z + 14, Blocks.dirt, 0, 3);
		world.setBlock(x + 14, y + 2, z + 14, Blocks.dirt, 0, 3);
		world.setBlock(x + 15, y + 2, z + 14, Blocks.dirt, 0, 3);
		world.setBlock(x + 16, y + 2, z + 14, Blocks.dirt, 0, 3);
		world.setBlock(x + 17, y + 2, z + 14, Blocks.dirt, 0, 3);
		world.setBlock(x + 18, y + 2, z + 14, Blocks.dirt, 0, 3);
		world.setBlock(x + 0, y + 2, z + 15, Blocks.dirt, 0, 3);
		world.setBlock(x + 1, y + 2, z + 15, Blocks.dirt, 0, 3);
		world.setBlock(x + 2, y + 2, z + 15, Blocks.dirt, 0, 3);
		world.setBlock(x + 3, y + 2, z + 15, Blocks.dirt, 0, 3);
		world.setBlock(x + 4, y + 2, z + 15, Blocks.dirt, 0, 3);
		world.setBlock(x + 5, y + 2, z + 15, Blocks.dirt, 0, 3);
		world.setBlock(x + 6, y + 2, z + 15, Blocks.dirt, 0, 3);
		world.setBlock(x + 7, y + 2, z + 15, Blocks.dirt, 0, 3);
		world.setBlock(x + 8, y + 2, z + 15, Blocks.dirt, 0, 3);
		world.setBlock(x + 9, y + 2, z + 15, Blocks.dirt, 0, 3);
		world.setBlock(x + 10, y + 2, z + 15, Blocks.dirt, 0, 3);
		world.setBlock(x + 11, y + 2, z + 15, Blocks.dirt, 0, 3);
		world.setBlock(x + 12, y + 2, z + 15, Blocks.dirt, 0, 3);
		world.setBlock(x + 13, y + 2, z + 15, Blocks.dirt, 0, 3);
		world.setBlock(x + 14, y + 2, z + 15, Blocks.dirt, 0, 3);
		world.setBlock(x + 15, y + 2, z + 15, Blocks.dirt, 0, 3);
		world.setBlock(x + 16, y + 2, z + 15, Blocks.dirt, 0, 3);
		world.setBlock(x + 17, y + 2, z + 15, Blocks.dirt, 0, 3);
		world.setBlock(x + 18, y + 2, z + 15, Blocks.dirt, 0, 3);
		world.setBlock(x + 0, y + 2, z + 16, Blocks.dirt, 0, 3);
		world.setBlock(x + 1, y + 2, z + 16, Blocks.dirt, 0, 3);
		world.setBlock(x + 2, y + 2, z + 16, Blocks.dirt, 0, 3);
		world.setBlock(x + 3, y + 2, z + 16, Blocks.dirt, 0, 3);
		world.setBlock(x + 4, y + 2, z + 16, Blocks.dirt, 0, 3);
		world.setBlock(x + 5, y + 2, z + 16, Blocks.dirt, 0, 3);
		world.setBlock(x + 6, y + 2, z + 16, Blocks.dirt, 0, 3);
		world.setBlock(x + 7, y + 2, z + 16, Blocks.dirt, 0, 3);
		world.setBlock(x + 8, y + 2, z + 16, Blocks.dirt, 0, 3);
		world.setBlock(x + 9, y + 2, z + 16, Blocks.dirt, 0, 3);
		world.setBlock(x + 10, y + 2, z + 16, Blocks.dirt, 0, 3);
		world.setBlock(x + 11, y + 2, z + 16, Blocks.dirt, 0, 3);
		world.setBlock(x + 12, y + 2, z + 16, Blocks.dirt, 0, 3);
		world.setBlock(x + 13, y + 2, z + 16, Blocks.dirt, 0, 3);
		world.setBlock(x + 14, y + 2, z + 16, Blocks.dirt, 0, 3);
		world.setBlock(x + 15, y + 2, z + 16, Blocks.dirt, 0, 3);
		world.setBlock(x + 16, y + 2, z + 16, Blocks.dirt, 0, 3);
		world.setBlock(x + 17, y + 2, z + 16, Blocks.dirt, 0, 3);
		world.setBlock(x + 18, y + 2, z + 16, Blocks.dirt, 0, 3);
		world.setBlock(x + 0, y + 2, z + 17, Blocks.dirt, 0, 3);
		world.setBlock(x + 1, y + 2, z + 17, Blocks.dirt, 0, 3);
		world.setBlock(x + 2, y + 2, z + 17, Blocks.dirt, 0, 3);
		world.setBlock(x + 3, y + 2, z + 17, Blocks.dirt, 0, 3);
		world.setBlock(x + 4, y + 2, z + 17, Blocks.dirt, 0, 3);
		world.setBlock(x + 5, y + 2, z + 17, Blocks.dirt, 0, 3);
		world.setBlock(x + 6, y + 2, z + 17, Blocks.dirt, 0, 3);
		world.setBlock(x + 7, y + 2, z + 17, Blocks.dirt, 0, 3);
		world.setBlock(x + 8, y + 2, z + 17, Blocks.dirt, 0, 3);
		world.setBlock(x + 9, y + 2, z + 17, Blocks.dirt, 0, 3);
		world.setBlock(x + 10, y + 2, z + 17, Blocks.dirt, 0, 3);
		world.setBlock(x + 11, y + 2, z + 17, Blocks.dirt, 0, 3);
		world.setBlock(x + 12, y + 2, z + 17, Blocks.dirt, 0, 3);
		world.setBlock(x + 13, y + 2, z + 17, Blocks.dirt, 0, 3);
		world.setBlock(x + 14, y + 2, z + 17, Blocks.dirt, 0, 3);
		world.setBlock(x + 15, y + 2, z + 17, Blocks.dirt, 0, 3);
		world.setBlock(x + 16, y + 2, z + 17, Blocks.dirt, 0, 3);
		world.setBlock(x + 17, y + 2, z + 17, Blocks.dirt, 0, 3);
		world.setBlock(x + 18, y + 2, z + 17, Blocks.dirt, 0, 3);
		world.setBlock(x + 0, y + 3, z + 0, Blocks.grass, 0, 3);
		world.setBlock(x + 1, y + 3, z + 0, Blocks.grass, 0, 3);
		world.setBlock(x + 2, y + 3, z + 0, Blocks.grass, 0, 3);
		world.setBlock(x + 3, y + 3, z + 0, Blocks.grass, 0, 3);
		world.setBlock(x + 4, y + 3, z + 0, Blocks.grass, 0, 3);
		world.setBlock(x + 5, y + 3, z + 0, Blocks.grass, 0, 3);
		world.setBlock(x + 6, y + 3, z + 0, Blocks.grass, 0, 3);
		world.setBlock(x + 7, y + 3, z + 0, Blocks.grass, 0, 3);
		world.setBlock(x + 8, y + 3, z + 0, Blocks.grass, 0, 3);
		world.setBlock(x + 9, y + 3, z + 0, Blocks.grass, 0, 3);
		world.setBlock(x + 10, y + 3, z + 0, Blocks.grass, 0, 3);
		world.setBlock(x + 11, y + 3, z + 0, Blocks.grass, 0, 3);
		world.setBlock(x + 12, y + 3, z + 0, Blocks.grass, 0, 3);
		world.setBlock(x + 13, y + 3, z + 0, Blocks.grass, 0, 3);
		world.setBlock(x + 14, y + 3, z + 0, Blocks.grass, 0, 3);
		world.setBlock(x + 15, y + 3, z + 0, Blocks.grass, 0, 3);
		world.setBlock(x + 16, y + 3, z + 0, Blocks.grass, 0, 3);
		world.setBlock(x + 17, y + 3, z + 0, Blocks.grass, 0, 3);
		world.setBlock(x + 18, y + 3, z + 0, Blocks.grass, 0, 3);
		world.setBlock(x + 0, y + 3, z + 1, Blocks.grass, 0, 3);
		world.setBlock(x + 1, y + 3, z + 1, Blocks.grass, 0, 3);
		world.setBlock(x + 2, y + 3, z + 1, Blocks.grass, 0, 3);
		world.setBlock(x + 3, y + 3, z + 1, Blocks.grass, 0, 3);
		world.setBlock(x + 4, y + 3, z + 1, Blocks.grass, 0, 3);
		world.setBlock(x + 5, y + 3, z + 1, Blocks.grass, 0, 3);
		world.setBlock(x + 6, y + 3, z + 1, Blocks.grass, 0, 3);
		world.setBlock(x + 7, y + 3, z + 1, Blocks.grass, 0, 3);
		world.setBlock(x + 8, y + 3, z + 1, Blocks.grass, 0, 3);
		world.setBlock(x + 9, y + 3, z + 1, Blocks.grass, 0, 3);
		world.setBlock(x + 10, y + 3, z + 1, Blocks.grass, 0, 3);
		world.setBlock(x + 11, y + 3, z + 1, Blocks.grass, 0, 3);
		world.setBlock(x + 12, y + 3, z + 1, Blocks.grass, 0, 3);
		world.setBlock(x + 13, y + 3, z + 1, Blocks.grass, 0, 3);
		world.setBlock(x + 14, y + 3, z + 1, Blocks.grass, 0, 3);
		world.setBlock(x + 15, y + 3, z + 1, Blocks.grass, 0, 3);
		world.setBlock(x + 16, y + 3, z + 1, Blocks.grass, 0, 3);
		world.setBlock(x + 17, y + 3, z + 1, Blocks.grass, 0, 3);
		world.setBlock(x + 18, y + 3, z + 1, Blocks.grass, 0, 3);
		world.setBlock(x + 0, y + 3, z + 2, Blocks.grass, 0, 3);
		world.setBlock(x + 1, y + 3, z + 2, Blocks.grass, 0, 3);
		world.setBlock(x + 2, y + 3, z + 2, Blocks.dirt, 0, 3);
		world.setBlock(x + 3, y + 3, z + 2, Blocks.dirt, 0, 3);
		world.setBlock(x + 4, y + 3, z + 2, Blocks.dirt, 0, 3);
		world.setBlock(x + 5, y + 3, z + 2, Blocks.dirt, 0, 3);
		world.setBlock(x + 6, y + 3, z + 2, Blocks.dirt, 0, 3);
		world.setBlock(x + 7, y + 3, z + 2, Blocks.dirt, 0, 3);
		world.setBlock(x + 8, y + 3, z + 2, Blocks.dirt, 0, 3);
		world.setBlock(x + 9, y + 3, z + 2, Blocks.dirt, 0, 3);
		world.setBlock(x + 10, y + 3, z + 2, Blocks.dirt, 0, 3);
		world.setBlock(x + 11, y + 3, z + 2, Blocks.dirt, 0, 3);
		world.setBlock(x + 12, y + 3, z + 2, Blocks.dirt, 0, 3);
		world.setBlock(x + 13, y + 3, z + 2, Blocks.dirt, 0, 3);
		world.setBlock(x + 14, y + 3, z + 2, Blocks.dirt, 0, 3);
		world.setBlock(x + 15, y + 3, z + 2, Blocks.dirt, 0, 3);
		world.setBlock(x + 16, y + 3, z + 2, Blocks.dirt, 0, 3);
		world.setBlock(x + 17, y + 3, z + 2, Blocks.grass, 0, 3);
		world.setBlock(x + 18, y + 3, z + 2, Blocks.grass, 0, 3);
		world.setBlock(x + 0, y + 3, z + 3, Blocks.grass, 0, 3);
		world.setBlock(x + 1, y + 3, z + 3, Blocks.grass, 0, 3);
		world.setBlock(x + 2, y + 3, z + 3, Blocks.dirt, 0, 3);
		world.setBlock(x + 3, y + 3, z + 3, Blocks.dirt, 0, 3);
		world.setBlock(x + 4, y + 3, z + 3, Blocks.dirt, 0, 3);
		world.setBlock(x + 5, y + 3, z + 3, Blocks.dirt, 0, 3);
		world.setBlock(x + 6, y + 3, z + 3, Blocks.dirt, 0, 3);
		world.setBlock(x + 7, y + 3, z + 3, Blocks.dirt, 0, 3);
		world.setBlock(x + 8, y + 3, z + 3, Blocks.dirt, 0, 3);
		world.setBlock(x + 9, y + 3, z + 3, Blocks.dirt, 0, 3);
		world.setBlock(x + 10, y + 3, z + 3, Blocks.dirt, 0, 3);
		world.setBlock(x + 11, y + 3, z + 3, Blocks.dirt, 0, 3);
		world.setBlock(x + 12, y + 3, z + 3, Blocks.dirt, 0, 3);
		world.setBlock(x + 13, y + 3, z + 3, Blocks.dirt, 0, 3);
		world.setBlock(x + 14, y + 3, z + 3, Blocks.dirt, 0, 3);
		world.setBlock(x + 15, y + 3, z + 3, Blocks.dirt, 0, 3);
		world.setBlock(x + 16, y + 3, z + 3, Blocks.dirt, 0, 3);
		world.setBlock(x + 17, y + 3, z + 3, Blocks.grass, 0, 3);
		world.setBlock(x + 18, y + 3, z + 3, Blocks.grass, 0, 3);
		world.setBlock(x + 0, y + 3, z + 4, Blocks.grass, 0, 3);
		world.setBlock(x + 1, y + 3, z + 4, Blocks.grass, 0, 3);
		world.setBlock(x + 2, y + 3, z + 4, Blocks.dirt, 0, 3);
		world.setBlock(x + 3, y + 3, z + 4, Blocks.dirt, 0, 3);
		world.setBlock(x + 4, y + 3, z + 4, Blocks.dirt, 0, 3);
		world.setBlock(x + 5, y + 3, z + 4, Blocks.dirt, 0, 3);
		world.setBlock(x + 6, y + 3, z + 4, Blocks.dirt, 0, 3);
		world.setBlock(x + 7, y + 3, z + 4, Blocks.dirt, 0, 3);
		world.setBlock(x + 8, y + 3, z + 4, Blocks.dirt, 0, 3);
		world.setBlock(x + 9, y + 3, z + 4, Blocks.stonebrick, 0, 3);
		world.setBlock(x + 10, y + 3, z + 4, Blocks.dirt, 0, 3);
		world.setBlock(x + 11, y + 3, z + 4, Blocks.dirt, 0, 3);
		world.setBlock(x + 12, y + 3, z + 4, Blocks.dirt, 0, 3);
		world.setBlock(x + 13, y + 3, z + 4, Blocks.dirt, 0, 3);
		world.setBlock(x + 14, y + 3, z + 4, Blocks.dirt, 0, 3);
		world.setBlock(x + 15, y + 3, z + 4, Blocks.dirt, 0, 3);
		world.setBlock(x + 16, y + 3, z + 4, Blocks.dirt, 0, 3);
		world.setBlock(x + 17, y + 3, z + 4, Blocks.grass, 0, 3);
		world.setBlock(x + 18, y + 3, z + 4, Blocks.grass, 0, 3);
		world.setBlock(x + 0, y + 3, z + 5, Blocks.grass, 0, 3);
		world.setBlock(x + 1, y + 3, z + 5, Blocks.grass, 0, 3);
		world.setBlock(x + 2, y + 3, z + 5, Blocks.dirt, 0, 3);
		world.setBlock(x + 3, y + 3, z + 5, Blocks.dirt, 0, 3);
		world.setBlock(x + 4, y + 3, z + 5, Blocks.dirt, 0, 3);
		world.setBlock(x + 5, y + 3, z + 5, Blocks.dirt, 0, 3);
		world.setBlock(x + 6, y + 3, z + 5, Blocks.dirt, 0, 3);
		world.setBlock(x + 7, y + 3, z + 5, Blocks.dirt, 0, 3);
		world.setBlock(x + 8, y + 3, z + 5, Blocks.stonebrick, 0, 3);
		//world.setBlock(x + 9, y + 3, z + 5, Blocks.furnace, 3, 3);
		world.setBlock(x + 10, y + 3, z + 5, Blocks.stonebrick, 0, 3);
		world.setBlock(x + 11, y + 3, z + 5, Blocks.dirt, 0, 3);
		world.setBlock(x + 12, y + 3, z + 5, Blocks.dirt, 0, 3);
		world.setBlock(x + 13, y + 3, z + 5, Blocks.dirt, 0, 3);
		world.setBlock(x + 14, y + 3, z + 5, Blocks.dirt, 0, 3);
		world.setBlock(x + 15, y + 3, z + 5, Blocks.dirt, 0, 3);
		world.setBlock(x + 16, y + 3, z + 5, Blocks.dirt, 0, 3);
		world.setBlock(x + 17, y + 3, z + 5, Blocks.grass, 0, 3);
		world.setBlock(x + 18, y + 3, z + 5, Blocks.grass, 0, 3);
		world.setBlock(x + 0, y + 3, z + 6, Blocks.grass, 0, 3);
		world.setBlock(x + 1, y + 3, z + 6, Blocks.grass, 0, 3);
		world.setBlock(x + 2, y + 3, z + 6, Blocks.dirt, 0, 3);
		world.setBlock(x + 3, y + 3, z + 6, Blocks.dirt, 0, 3);
		world.setBlock(x + 4, y + 3, z + 6, Blocks.dirt, 0, 3);
		world.setBlock(x + 5, y + 3, z + 6, Blocks.dirt, 0, 3);
		world.setBlock(x + 6, y + 3, z + 6, Blocks.dirt, 0, 3);
		world.setBlock(x + 7, y + 3, z + 6, Blocks.stonebrick, 3, 3);
		world.setBlock(x + 8, y + 3, z + 6, Blocks.cobblestone_wall, 0, 3);
		world.setBlock(x + 9, y + 3, z + 6, Blocks.air, 0, 3);
		world.setBlock(x + 10, y + 3, z + 6, Blocks.cobblestone_wall, 0, 3);
		world.setBlock(x + 11, y + 3, z + 6, Blocks.stonebrick, 3, 3);
		world.setBlock(x + 12, y + 3, z + 6, Blocks.dirt, 0, 3);
		world.setBlock(x + 13, y + 3, z + 6, Blocks.dirt, 0, 3);
		world.setBlock(x + 14, y + 3, z + 6, Blocks.dirt, 0, 3);
		world.setBlock(x + 15, y + 3, z + 6, Blocks.dirt, 0, 3);
		world.setBlock(x + 16, y + 3, z + 6, Blocks.dirt, 0, 3);
		world.setBlock(x + 17, y + 3, z + 6, Blocks.grass, 0, 3);
		world.setBlock(x + 18, y + 3, z + 6, Blocks.grass, 0, 3);
		world.setBlock(x + 0, y + 3, z + 7, Blocks.grass, 0, 3);
		world.setBlock(x + 1, y + 3, z + 7, Blocks.grass, 0, 3);
		world.setBlock(x + 2, y + 3, z + 7, Blocks.dirt, 0, 3);
		world.setBlock(x + 3, y + 3, z + 7, Blocks.dirt, 0, 3);
		world.setBlock(x + 4, y + 3, z + 7, Blocks.dirt, 0, 3);
		world.setBlock(x + 5, y + 3, z + 7, Blocks.dirt, 0, 3);
		world.setBlock(x + 6, y + 3, z + 7, Blocks.stonebrick, 0, 3);
		world.setBlock(x + 7, y + 3, z + 7, Blocks.cobblestone_wall, 0, 3);
		world.setBlock(x + 8, y + 3, z + 7, Blocks.air, 0, 3);
		world.setBlock(x + 9, y + 3, z + 7, Blocks.air, 0, 3);
		world.setBlock(x + 10, y + 3, z + 7, Blocks.air, 0, 3);
		world.setBlock(x + 11, y + 3, z + 7, Blocks.cobblestone_wall, 0, 3);
		world.setBlock(x + 12, y + 3, z + 7, Blocks.stonebrick, 0, 3);
		world.setBlock(x + 13, y + 3, z + 7, Blocks.dirt, 0, 3);
		world.setBlock(x + 14, y + 3, z + 7, Blocks.dirt, 0, 3);
		world.setBlock(x + 15, y + 3, z + 7, Blocks.dirt, 0, 3);
		world.setBlock(x + 16, y + 3, z + 7, Blocks.dirt, 0, 3);
		world.setBlock(x + 17, y + 3, z + 7, Blocks.grass, 0, 3);
		world.setBlock(x + 18, y + 3, z + 7, Blocks.grass, 0, 3);
		world.setBlock(x + 0, y + 3, z + 8, Blocks.grass, 0, 3);
		world.setBlock(x + 1, y + 3, z + 8, Blocks.grass, 0, 3);
		world.setBlock(x + 2, y + 3, z + 8, Blocks.dirt, 0, 3);
		world.setBlock(x + 3, y + 3, z + 8, Blocks.dirt, 0, 3);
		world.setBlock(x + 4, y + 3, z + 8, Blocks.dirt, 0, 3);
		world.setBlock(x + 5, y + 3, z + 8, Blocks.stonebrick, 0, 3);
		//world.setBlock(x + 6, y + 3, z + 8, Blocks.furnace, 3, 3);
		world.setBlock(x + 7, y + 3, z + 8, Blocks.air, 0, 3);
		world.setBlock(x + 8, y + 3, z + 8, Blocks.air, 0, 3);
		world.setBlock(x + 9, y + 3, z + 8, Blocks.obsidian, 0, 3);
		world.setBlock(x + 10, y + 3, z + 8, Blocks.air, 0, 3);
		world.setBlock(x + 11, y + 3, z + 8, Blocks.air, 0, 3);
		//world.setBlock(x + 12, y + 3, z + 8, Blocks.furnace, 4, 3);
		world.setBlock(x + 13, y + 3, z + 8, Blocks.stonebrick, 0, 3);
		world.setBlock(x + 14, y + 3, z + 8, Blocks.dirt, 0, 3);
		world.setBlock(x + 15, y + 3, z + 8, Blocks.dirt, 0, 3);
		world.setBlock(x + 16, y + 3, z + 8, Blocks.dirt, 0, 3);
		world.setBlock(x + 17, y + 3, z + 8, Blocks.dirt, 0, 3);
		world.setBlock(x + 18, y + 3, z + 8, Blocks.grass, 0, 3);
		world.setBlock(x + 0, y + 3, z + 9, Blocks.grass, 0, 3);
		world.setBlock(x + 1, y + 3, z + 9, Blocks.grass, 0, 3);
		world.setBlock(x + 2, y + 3, z + 9, Blocks.dirt, 0, 3);
		world.setBlock(x + 3, y + 3, z + 9, Blocks.dirt, 0, 3);
		world.setBlock(x + 4, y + 3, z + 9, Blocks.dirt, 0, 3);
		world.setBlock(x + 5, y + 3, z + 9, Blocks.dirt, 0, 3);
		world.setBlock(x + 6, y + 3, z + 9, Blocks.stonebrick, 0, 3);
		world.setBlock(x + 7, y + 3, z + 9, Blocks.cobblestone_wall, 0, 3);
		world.setBlock(x + 8, y + 3, z + 9, Blocks.air, 0, 3);
		world.setBlock(x + 9, y + 3, z + 9, Blocks.air, 0, 3);
		world.setBlock(x + 10, y + 3, z + 9, Blocks.air, 0, 3);
		world.setBlock(x + 11, y + 3, z + 9, Blocks.cobblestone_wall, 0, 3);
		world.setBlock(x + 12, y + 3, z + 9, Blocks.stonebrick, 0, 3);
		world.setBlock(x + 13, y + 3, z + 9, Blocks.dirt, 0, 3);
		world.setBlock(x + 14, y + 3, z + 9, Blocks.dirt, 0, 3);
		world.setBlock(x + 15, y + 3, z + 9, Blocks.dirt, 0, 3);
		world.setBlock(x + 16, y + 3, z + 9, Blocks.dirt, 0, 3);
		world.setBlock(x + 17, y + 3, z + 9, Blocks.grass, 0, 3);
		world.setBlock(x + 18, y + 3, z + 9, Blocks.grass, 0, 3);
		world.setBlock(x + 0, y + 3, z + 10, Blocks.grass, 0, 3);
		world.setBlock(x + 1, y + 3, z + 10, Blocks.grass, 0, 3);
		world.setBlock(x + 2, y + 3, z + 10, Blocks.dirt, 0, 3);
		world.setBlock(x + 3, y + 3, z + 10, Blocks.dirt, 0, 3);
		world.setBlock(x + 4, y + 3, z + 10, Blocks.dirt, 0, 3);
		world.setBlock(x + 5, y + 3, z + 10, Blocks.dirt, 0, 3);
		world.setBlock(x + 6, y + 3, z + 10, Blocks.dirt, 0, 3);
		world.setBlock(x + 7, y + 3, z + 10, Blocks.stonebrick, 3, 3);
		world.setBlock(x + 8, y + 3, z + 10, Blocks.cobblestone_wall, 0, 3);
		world.setBlock(x + 9, y + 3, z + 10, Blocks.air, 0, 3);
		world.setBlock(x + 10, y + 3, z + 10, Blocks.cobblestone_wall, 0, 3);
		world.setBlock(x + 11, y + 3, z + 10, Blocks.stonebrick, 3, 3);
		world.setBlock(x + 12, y + 3, z + 10, Blocks.dirt, 0, 3);
		world.setBlock(x + 13, y + 3, z + 10, Blocks.dirt, 0, 3);
		world.setBlock(x + 14, y + 3, z + 10, Blocks.dirt, 0, 3);
		world.setBlock(x + 15, y + 3, z + 10, Blocks.dirt, 0, 3);
		world.setBlock(x + 16, y + 3, z + 10, Blocks.dirt, 0, 3);
		world.setBlock(x + 17, y + 3, z + 10, Blocks.grass, 0, 3);
		world.setBlock(x + 18, y + 3, z + 10, Blocks.grass, 0, 3);
		world.setBlock(x + 0, y + 3, z + 11, Blocks.grass, 0, 3);
		world.setBlock(x + 1, y + 3, z + 11, Blocks.grass, 0, 3);
		world.setBlock(x + 2, y + 3, z + 11, Blocks.dirt, 0, 3);
		world.setBlock(x + 3, y + 3, z + 11, Blocks.dirt, 0, 3);
		world.setBlock(x + 4, y + 3, z + 11, Blocks.dirt, 0, 3);
		world.setBlock(x + 5, y + 3, z + 11, Blocks.dirt, 0, 3);
		world.setBlock(x + 6, y + 3, z + 11, Blocks.dirt, 0, 3);
		world.setBlock(x + 7, y + 3, z + 11, Blocks.dirt, 0, 3);
		world.setBlock(x + 8, y + 3, z + 11, Blocks.stonebrick, 0, 3);
		world.setBlock(x + 9, y + 3, z + 11, Blocks.chest, 2, 3);
		world.setBlock(x + 10, y + 3, z + 11, Blocks.stonebrick, 0, 3);
		world.setBlock(x + 11, y + 3, z + 11, Blocks.dirt, 0, 3);
		world.setBlock(x + 12, y + 3, z + 11, Blocks.dirt, 0, 3);
		world.setBlock(x + 13, y + 3, z + 11, Blocks.dirt, 0, 3);
		world.setBlock(x + 14, y + 3, z + 11, Blocks.dirt, 0, 3);
		world.setBlock(x + 15, y + 3, z + 11, Blocks.dirt, 0, 3);
		world.setBlock(x + 16, y + 3, z + 11, Blocks.dirt, 0, 3);
		world.setBlock(x + 17, y + 3, z + 11, Blocks.grass, 0, 3);
		world.setBlock(x + 18, y + 3, z + 11, Blocks.grass, 0, 3);
		world.setBlock(x + 0, y + 3, z + 12, Blocks.grass, 0, 3);
		world.setBlock(x + 1, y + 3, z + 12, Blocks.grass, 0, 3);
		world.setBlock(x + 2, y + 3, z + 12, Blocks.dirt, 0, 3);
		world.setBlock(x + 3, y + 3, z + 12, Blocks.dirt, 0, 3);
		world.setBlock(x + 4, y + 3, z + 12, Blocks.dirt, 0, 3);
		world.setBlock(x + 5, y + 3, z + 12, Blocks.dirt, 0, 3);
		world.setBlock(x + 6, y + 3, z + 12, Blocks.dirt, 0, 3);
		world.setBlock(x + 7, y + 3, z + 12, Blocks.dirt, 0, 3);
		world.setBlock(x + 8, y + 3, z + 12, Blocks.dirt, 0, 3);
		world.setBlock(x + 9, y + 3, z + 12, Blocks.stonebrick, 0, 3);
		world.setBlock(x + 10, y + 3, z + 12, Blocks.dirt, 0, 3);
		world.setBlock(x + 11, y + 3, z + 12, Blocks.dirt, 0, 3);
		world.setBlock(x + 12, y + 3, z + 12, Blocks.dirt, 0, 3);
		world.setBlock(x + 13, y + 3, z + 12, Blocks.dirt, 0, 3);
		world.setBlock(x + 14, y + 3, z + 12, Blocks.dirt, 0, 3);
		world.setBlock(x + 15, y + 3, z + 12, Blocks.dirt, 0, 3);
		world.setBlock(x + 16, y + 3, z + 12, Blocks.dirt, 0, 3);
		world.setBlock(x + 17, y + 3, z + 12, Blocks.grass, 0, 3);
		world.setBlock(x + 18, y + 3, z + 12, Blocks.grass, 0, 3);
		world.setBlock(x + 0, y + 3, z + 13, Blocks.grass, 0, 3);
		world.setBlock(x + 1, y + 3, z + 13, Blocks.grass, 0, 3);
		world.setBlock(x + 2, y + 3, z + 13, Blocks.dirt, 0, 3);
		world.setBlock(x + 3, y + 3, z + 13, Blocks.dirt, 0, 3);
		world.setBlock(x + 4, y + 3, z + 13, Blocks.dirt, 0, 3);
		world.setBlock(x + 5, y + 3, z + 13, Blocks.dirt, 0, 3);
		world.setBlock(x + 6, y + 3, z + 13, Blocks.dirt, 0, 3);
		world.setBlock(x + 7, y + 3, z + 13, Blocks.dirt, 0, 3);
		world.setBlock(x + 8, y + 3, z + 13, Blocks.dirt, 0, 3);
		world.setBlock(x + 9, y + 3, z + 13, Blocks.dirt, 0, 3);
		world.setBlock(x + 10, y + 3, z + 13, Blocks.dirt, 0, 3);
		world.setBlock(x + 11, y + 3, z + 13, Blocks.dirt, 0, 3);
		world.setBlock(x + 12, y + 3, z + 13, Blocks.dirt, 0, 3);
		world.setBlock(x + 13, y + 3, z + 13, Blocks.dirt, 0, 3);
		world.setBlock(x + 14, y + 3, z + 13, Blocks.dirt, 0, 3);
		world.setBlock(x + 15, y + 3, z + 13, Blocks.dirt, 0, 3);
		world.setBlock(x + 16, y + 3, z + 13, Blocks.dirt, 0, 3);
		world.setBlock(x + 17, y + 3, z + 13, Blocks.grass, 0, 3);
		world.setBlock(x + 18, y + 3, z + 13, Blocks.grass, 0, 3);
		world.setBlock(x + 0, y + 3, z + 14, Blocks.grass, 0, 3);
		world.setBlock(x + 1, y + 3, z + 14, Blocks.grass, 0, 3);
		world.setBlock(x + 2, y + 3, z + 14, Blocks.dirt, 0, 3);
		world.setBlock(x + 3, y + 3, z + 14, Blocks.dirt, 0, 3);
		world.setBlock(x + 4, y + 3, z + 14, Blocks.dirt, 0, 3);
		world.setBlock(x + 5, y + 3, z + 14, Blocks.dirt, 0, 3);
		world.setBlock(x + 6, y + 3, z + 14, Blocks.dirt, 0, 3);
		world.setBlock(x + 7, y + 3, z + 14, Blocks.dirt, 0, 3);
		world.setBlock(x + 8, y + 3, z + 14, Blocks.dirt, 0, 3);
		world.setBlock(x + 9, y + 3, z + 14, Blocks.dirt, 0, 3);
		world.setBlock(x + 10, y + 3, z + 14, Blocks.dirt, 0, 3);
		world.setBlock(x + 11, y + 3, z + 14, Blocks.dirt, 0, 3);
		world.setBlock(x + 12, y + 3, z + 14, Blocks.dirt, 0, 3);
		world.setBlock(x + 13, y + 3, z + 14, Blocks.dirt, 0, 3);
		world.setBlock(x + 14, y + 3, z + 14, Blocks.dirt, 0, 3);
		world.setBlock(x + 15, y + 3, z + 14, Blocks.dirt, 0, 3);
		world.setBlock(x + 16, y + 3, z + 14, Blocks.dirt, 0, 3);
		world.setBlock(x + 17, y + 3, z + 14, Blocks.grass, 0, 3);
		world.setBlock(x + 18, y + 3, z + 14, Blocks.grass, 0, 3);
		world.setBlock(x + 0, y + 3, z + 15, Blocks.grass, 0, 3);
		world.setBlock(x + 1, y + 3, z + 15, Blocks.grass, 0, 3);
		world.setBlock(x + 2, y + 3, z + 15, Blocks.grass, 0, 3);
		world.setBlock(x + 3, y + 3, z + 15, Blocks.grass, 0, 3);
		world.setBlock(x + 4, y + 3, z + 15, Blocks.grass, 0, 3);
		world.setBlock(x + 5, y + 3, z + 15, Blocks.grass, 0, 3);
		world.setBlock(x + 6, y + 3, z + 15, Blocks.dirt, 0, 3);
		world.setBlock(x + 7, y + 3, z + 15, Blocks.dirt, 0, 3);
		world.setBlock(x + 8, y + 3, z + 15, Blocks.dirt, 0, 3);
		world.setBlock(x + 9, y + 3, z + 15, Blocks.grass, 0, 3);
		world.setBlock(x + 10, y + 3, z + 15, Blocks.grass, 0, 3);
		world.setBlock(x + 11, y + 3, z + 15, Blocks.dirt, 0, 3);
		world.setBlock(x + 12, y + 3, z + 15, Blocks.grass, 0, 3);
		world.setBlock(x + 13, y + 3, z + 15, Blocks.grass, 0, 3);
		world.setBlock(x + 14, y + 3, z + 15, Blocks.grass, 0, 3);
		world.setBlock(x + 15, y + 3, z + 15, Blocks.grass, 0, 3);
		world.setBlock(x + 16, y + 3, z + 15, Blocks.grass, 0, 3);
		world.setBlock(x + 17, y + 3, z + 15, Blocks.grass, 0, 3);
		world.setBlock(x + 18, y + 3, z + 15, Blocks.grass, 0, 3);
		world.setBlock(x + 0, y + 3, z + 16, Blocks.grass, 0, 3);
		world.setBlock(x + 1, y + 3, z + 16, Blocks.grass, 0, 3);
		world.setBlock(x + 2, y + 3, z + 16, Blocks.grass, 0, 3);
		world.setBlock(x + 3, y + 3, z + 16, Blocks.grass, 0, 3);
		world.setBlock(x + 4, y + 3, z + 16, Blocks.grass, 0, 3);
		world.setBlock(x + 5, y + 3, z + 16, Blocks.grass, 0, 3);
		world.setBlock(x + 6, y + 3, z + 16, Blocks.grass, 0, 3);
		world.setBlock(x + 7, y + 3, z + 16, Blocks.dirt, 0, 3);
		world.setBlock(x + 8, y + 3, z + 16, Blocks.gravel, 0, 3);
		world.setBlock(x + 9, y + 3, z + 16, Blocks.gravel, 0, 3);
		world.setBlock(x + 10, y + 3, z + 16, Blocks.gravel, 0, 3);
		world.setBlock(x + 11, y + 3, z + 16, Blocks.grass, 0, 3);
		world.setBlock(x + 12, y + 3, z + 16, Blocks.grass, 0, 3);
		world.setBlock(x + 13, y + 3, z + 16, Blocks.grass, 0, 3);
		world.setBlock(x + 14, y + 3, z + 16, Blocks.grass, 0, 3);
		world.setBlock(x + 15, y + 3, z + 16, Blocks.grass, 0, 3);
		world.setBlock(x + 16, y + 3, z + 16, Blocks.grass, 0, 3);
		world.setBlock(x + 17, y + 3, z + 16, Blocks.grass, 0, 3);
		world.setBlock(x + 18, y + 3, z + 16, Blocks.grass, 0, 3);
		world.setBlock(x + 0, y + 3, z + 17, Blocks.grass, 0, 3);
		world.setBlock(x + 1, y + 3, z + 17, Blocks.grass, 0, 3);
		world.setBlock(x + 2, y + 3, z + 17, Blocks.grass, 0, 3);
		world.setBlock(x + 3, y + 3, z + 17, Blocks.grass, 0, 3);
		world.setBlock(x + 4, y + 3, z + 17, Blocks.grass, 0, 3);
		world.setBlock(x + 5, y + 3, z + 17, Blocks.grass, 0, 3);
		world.setBlock(x + 6, y + 3, z + 17, Blocks.grass, 0, 3);
		world.setBlock(x + 7, y + 3, z + 17, Blocks.grass, 0, 3);
		world.setBlock(x + 8, y + 3, z + 17, Blocks.gravel, 0, 3);
		world.setBlock(x + 9, y + 3, z + 17, Blocks.gravel, 0, 3);
		world.setBlock(x + 10, y + 3, z + 17, Blocks.gravel, 0, 3);
		world.setBlock(x + 11, y + 3, z + 17, Blocks.grass, 0, 3);
		world.setBlock(x + 12, y + 3, z + 17, Blocks.grass, 0, 3);
		world.setBlock(x + 13, y + 3, z + 17, Blocks.grass, 0, 3);
		world.setBlock(x + 14, y + 3, z + 17, Blocks.grass, 0, 3);
		world.setBlock(x + 15, y + 3, z + 17, Blocks.grass, 0, 3);
		world.setBlock(x + 16, y + 3, z + 17, Blocks.grass, 0, 3);
		world.setBlock(x + 17, y + 3, z + 17, Blocks.grass, 0, 3);
		world.setBlock(x + 18, y + 3, z + 17, Blocks.grass, 0, 3);
		world.setBlock(x + 9, y + 4, z + 0, Blocks.leaves, 7, 3);
		world.setBlock(x + 10, y + 4, z + 0, Blocks.leaves, 7, 3);
		world.setBlock(x + 1, y + 4, z + 1, Blocks.tallgrass, 1, 3);
		world.setBlock(x + 3, y + 4, z + 1, Blocks.vine, 1, 3);
		world.setBlock(x + 4, y + 4, z + 1, Blocks.vine, 1, 3);
		world.setBlock(x + 6, y + 4, z + 1, Blocks.tallgrass, 1, 3);
		world.setBlock(x + 7, y + 4, z + 1, Blocks.vine, 1, 3);
		world.setBlock(x + 8, y + 4, z + 1, Blocks.leaves, 15, 3);
		world.setBlock(x + 9, y + 4, z + 1, Blocks.leaves, 15, 3);
		world.setBlock(x + 10, y + 4, z + 1, Blocks.leaves, 15, 3);
		world.setBlock(x + 11, y + 4, z + 1, Blocks.leaves, 15, 3);
		world.setBlock(x + 12, y + 4, z + 1, Blocks.vine, 1, 3);
		world.setBlock(x + 13, y + 4, z + 1, Blocks.tallgrass, 2, 3);
		world.setBlock(x + 14, y + 4, z + 1, Blocks.tallgrass, 1, 3);
		world.setBlock(x + 16, y + 4, z + 1, Blocks.tallgrass, 1, 3);
		world.setBlock(x + 1, y + 4, z + 2, Blocks.tallgrass, 2, 3);
		world.setBlock(x + 2, y + 4, z + 2, Blocks.stonebrick, 0, 3);
		world.setBlock(x + 3, y + 4, z + 2, Blocks.stonebrick, 0, 3);
		world.setBlock(x + 4, y + 4, z + 2, Blocks.stonebrick, 0, 3);
		world.setBlock(x + 5, y + 4, z + 2, Blocks.stonebrick, 0, 3);
		world.setBlock(x + 6, y + 4, z + 2, Blocks.stonebrick, 0, 3);
		world.setBlock(x + 7, y + 4, z + 2, Blocks.stonebrick, 0, 3);
		world.setBlock(x + 8, y + 4, z + 2, Blocks.stonebrick, 0, 3);
		world.setBlock(x + 9, y + 4, z + 2, Blocks.stonebrick, 0, 3);
		world.setBlock(x + 10, y + 4, z + 2, Blocks.stonebrick, 0, 3);
		world.setBlock(x + 11, y + 4, z + 2, Blocks.stonebrick, 0, 3);
		world.setBlock(x + 12, y + 4, z + 2, Blocks.stonebrick, 0, 3);
		world.setBlock(x + 13, y + 4, z + 2, Blocks.stonebrick, 0, 3);
		world.setBlock(x + 14, y + 4, z + 2, Blocks.stonebrick, 0, 3);
		world.setBlock(x + 15, y + 4, z + 2, Blocks.stonebrick, 0, 3);
		world.setBlock(x + 16, y + 4, z + 2, Blocks.stonebrick, 0, 3);
		world.setBlock(x + 1, y + 4, z + 3, Blocks.double_plant, 3, 3);
		world.setBlock(x + 2, y + 4, z + 3, Blocks.stonebrick, 0, 3);
		world.setBlock(x + 3, y + 4, z + 3, Blocks.dirt, 0, 3);
		world.setBlock(x + 4, y + 4, z + 3, Blocks.dirt, 0, 3);
		world.setBlock(x + 5, y + 4, z + 3, Blocks.dirt, 0, 3);
		world.setBlock(x + 6, y + 4, z + 3, Blocks.dirt, 0, 3);
		world.setBlock(x + 7, y + 4, z + 3, Blocks.dirt, 0, 3);
		world.setBlock(x + 8, y + 4, z + 3, Blocks.dirt, 0, 3);
		world.setBlock(x + 9, y + 4, z + 3, Blocks.dirt, 0, 3);
		world.setBlock(x + 10, y + 4, z + 3, Blocks.dirt, 0, 3);
		world.setBlock(x + 11, y + 4, z + 3, Blocks.dirt, 0, 3);
		world.setBlock(x + 12, y + 4, z + 3, Blocks.dirt, 0, 3);
		world.setBlock(x + 13, y + 4, z + 3, Blocks.dirt, 0, 3);
		world.setBlock(x + 14, y + 4, z + 3, Blocks.dirt, 0, 3);
		world.setBlock(x + 15, y + 4, z + 3, Blocks.dirt, 0, 3);
		world.setBlock(x + 16, y + 4, z + 3, Blocks.stonebrick, 0, 3);
		world.setBlock(x + 17, y + 4, z + 3, Blocks.vine, 2, 3);
		world.setBlock(x + 2, y + 4, z + 4, Blocks.stonebrick, 0, 3);
		world.setBlock(x + 3, y + 4, z + 4, Blocks.dirt, 0, 3);
		world.setBlock(x + 4, y + 4, z + 4, Blocks.dirt, 0, 3);
		world.setBlock(x + 5, y + 4, z + 4, Blocks.dirt, 0, 3);
		world.setBlock(x + 6, y + 4, z + 4, Blocks.dirt, 0, 3);
		world.setBlock(x + 7, y + 4, z + 4, Blocks.dirt, 0, 3);
		world.setBlock(x + 8, y + 4, z + 4, Blocks.dirt, 0, 3);
		world.setBlock(x + 9, y + 4, z + 4, Blocks.stonebrick, 0, 3);
		world.setBlock(x + 10, y + 4, z + 4, Blocks.dirt, 0, 3);
		world.setBlock(x + 11, y + 4, z + 4, Blocks.dirt, 0, 3);
		world.setBlock(x + 12, y + 4, z + 4, Blocks.dirt, 0, 3);
		world.setBlock(x + 13, y + 4, z + 4, Blocks.dirt, 0, 3);
		world.setBlock(x + 14, y + 4, z + 4, Blocks.dirt, 0, 3);
		world.setBlock(x + 15, y + 4, z + 4, Blocks.dirt, 0, 3);
		world.setBlock(x + 16, y + 4, z + 4, Blocks.stonebrick, 0, 3);
		world.setBlock(x + 17, y + 4, z + 4, Blocks.vine, 2, 3);
		world.setBlock(x + 1, y + 4, z + 5, Blocks.vine, 8, 3);
		world.setBlock(x + 2, y + 4, z + 5, Blocks.stonebrick, 0, 3);
		world.setBlock(x + 3, y + 4, z + 5, Blocks.dirt, 0, 3);
		world.setBlock(x + 4, y + 4, z + 5, Blocks.dirt, 0, 3);
		world.setBlock(x + 5, y + 4, z + 5, Blocks.dirt, 0, 3);
		world.setBlock(x + 6, y + 4, z + 5, Blocks.dirt, 0, 3);
		world.setBlock(x + 7, y + 4, z + 5, Blocks.dirt, 0, 3);
		world.setBlock(x + 8, y + 4, z + 5, Blocks.stonebrick, 0, 3);
		world.setBlock(x + 9, y + 4, z + 5, Blocks.air, 0, 3);
		world.setBlock(x + 10, y + 4, z + 5, Blocks.stonebrick, 0, 3);
		world.setBlock(x + 11, y + 4, z + 5, Blocks.dirt, 0, 3);
		world.setBlock(x + 12, y + 4, z + 5, Blocks.dirt, 0, 3);
		world.setBlock(x + 13, y + 4, z + 5, Blocks.dirt, 0, 3);
		world.setBlock(x + 14, y + 4, z + 5, Blocks.dirt, 0, 3);
		world.setBlock(x + 15, y + 4, z + 5, Blocks.dirt, 0, 3);
		world.setBlock(x + 16, y + 4, z + 5, Blocks.stonebrick, 0, 3);
		world.setBlock(x + 17, y + 4, z + 5, Blocks.tallgrass, 1, 3);
		world.setBlock(x + 2, y + 4, z + 6, Blocks.stonebrick, 0, 3);
		world.setBlock(x + 3, y + 4, z + 6, Blocks.dirt, 0, 3);
		world.setBlock(x + 4, y + 4, z + 6, Blocks.dirt, 0, 3);
		world.setBlock(x + 5, y + 4, z + 6, Blocks.dirt, 0, 3);
		world.setBlock(x + 6, y + 4, z + 6, Blocks.dirt, 0, 3);
		world.setBlock(x + 7, y + 4, z + 6, Blocks.glowstone, 0, 3);
		world.setBlock(x + 8, y + 4, z + 6, Blocks.cobblestone_wall, 0, 3);
		world.setBlock(x + 9, y + 4, z + 6, Blocks.air, 0, 3);
		world.setBlock(x + 10, y + 4, z + 6, Blocks.cobblestone_wall, 0, 3);
		world.setBlock(x + 11, y + 4, z + 6, Blocks.glowstone, 0, 3);
		world.setBlock(x + 12, y + 4, z + 6, Blocks.dirt, 0, 3);
		world.setBlock(x + 13, y + 4, z + 6, Blocks.dirt, 0, 3);
		world.setBlock(x + 14, y + 4, z + 6, Blocks.dirt, 0, 3);
		world.setBlock(x + 15, y + 4, z + 6, Blocks.dirt, 0, 3);
		world.setBlock(x + 16, y + 4, z + 6, Blocks.stonebrick, 0, 3);
		world.setBlock(x + 1, y + 4, z + 7, Blocks.tallgrass, 2, 3);
		world.setBlock(x + 2, y + 4, z + 7, Blocks.stonebrick, 0, 3);
		world.setBlock(x + 3, y + 4, z + 7, Blocks.dirt, 0, 3);
		world.setBlock(x + 4, y + 4, z + 7, Blocks.dirt, 0, 3);
		world.setBlock(x + 5, y + 4, z + 7, Blocks.dirt, 0, 3);
		world.setBlock(x + 6, y + 4, z + 7, Blocks.stonebrick, 0, 3);
		world.setBlock(x + 7, y + 4, z + 7, Blocks.cobblestone_wall, 0, 3);
		world.setBlock(x + 8, y + 4, z + 7, Blocks.air, 0, 3);
		world.setBlock(x + 9, y + 4, z + 7, Blocks.air, 0, 3);
		world.setBlock(x + 10, y + 4, z + 7, Blocks.air, 0, 3);
		world.setBlock(x + 11, y + 4, z + 7, Blocks.cobblestone_wall, 0, 3);
		world.setBlock(x + 12, y + 4, z + 7, Blocks.stonebrick, 0, 3);
		world.setBlock(x + 13, y + 4, z + 7, Blocks.dirt, 0, 3);
		world.setBlock(x + 14, y + 4, z + 7, Blocks.dirt, 0, 3);
		world.setBlock(x + 15, y + 4, z + 7, Blocks.dirt, 0, 3);
		world.setBlock(x + 16, y + 4, z + 7, Blocks.stonebrick, 0, 3);
		world.setBlock(x + 17, y + 4, z + 7, Blocks.leaves, 7, 3);
		world.setBlock(x + 1, y + 4, z + 8, Blocks.leaves, 7, 3);
		world.setBlock(x + 2, y + 4, z + 8, Blocks.stonebrick, 0, 3);
		world.setBlock(x + 3, y + 4, z + 8, Blocks.dirt, 0, 3);
		world.setBlock(x + 4, y + 4, z + 8, Blocks.dirt, 0, 3);
		world.setBlock(x + 5, y + 4, z + 8, Blocks.stonebrick, 0, 3);
		world.setBlock(x + 6, y + 4, z + 8, Blocks.air, 0, 3);
		world.setBlock(x + 7, y + 4, z + 8, Blocks.air, 0, 3);
		world.setBlock(x + 8, y + 4, z + 8, Blocks.air, 0, 3);
		world.setBlock(x + 9, y + 4, z + 8, Blocks.air, 0, 3);
		world.setBlock(x + 10, y + 4, z + 8, Blocks.air, 0, 3);
		world.setBlock(x + 11, y + 4, z + 8, Blocks.air, 0, 3);
		world.setBlock(x + 12, y + 4, z + 8, Blocks.air, 0, 3);
		world.setBlock(x + 13, y + 4, z + 8, Blocks.stonebrick, 0, 3);
		world.setBlock(x + 14, y + 4, z + 8, Blocks.dirt, 0, 3);
		world.setBlock(x + 15, y + 4, z + 8, Blocks.dirt, 0, 3);
		world.setBlock(x + 16, y + 4, z + 8, Blocks.stonebrick, 0, 3);
		world.setBlock(x + 17, y + 4, z + 8, Blocks.log, 3, 3);
		world.setBlock(x + 18, y + 4, z + 8, Blocks.leaves, 7, 3);
		world.setBlock(x + 0, y + 4, z + 9, Blocks.leaves, 7, 3);

		generate_r02(world, rand, x, y, z);
		return true;

	}

	public boolean generate_r02(World world, Random rand, int x, int y, int z) {

		world.setBlock(x + 1, y + 4, z + 9, Blocks.leaves, 7, 3);
		world.setBlock(x + 2, y + 4, z + 9, Blocks.stonebrick, 0, 3);
		world.setBlock(x + 3, y + 4, z + 9, Blocks.dirt, 0, 3);
		world.setBlock(x + 4, y + 4, z + 9, Blocks.dirt, 0, 3);
		world.setBlock(x + 5, y + 4, z + 9, Blocks.dirt, 0, 3);
		world.setBlock(x + 6, y + 4, z + 9, Blocks.stonebrick, 0, 3);
		world.setBlock(x + 7, y + 4, z + 9, Blocks.cobblestone_wall, 0, 3);
		world.setBlock(x + 8, y + 4, z + 9, Blocks.air, 0, 3);
		world.setBlock(x + 9, y + 4, z + 9, Blocks.air, 0, 3);
		world.setBlock(x + 10, y + 4, z + 9, Blocks.air, 0, 3);
		world.setBlock(x + 11, y + 4, z + 9, Blocks.cobblestone_wall, 0, 3);
		world.setBlock(x + 12, y + 4, z + 9, Blocks.stonebrick, 0, 3);
		world.setBlock(x + 13, y + 4, z + 9, Blocks.dirt, 0, 3);
		world.setBlock(x + 14, y + 4, z + 9, Blocks.dirt, 0, 3);
		world.setBlock(x + 15, y + 4, z + 9, Blocks.dirt, 0, 3);
		world.setBlock(x + 16, y + 4, z + 9, Blocks.stonebrick, 0, 3);
		world.setBlock(x + 17, y + 4, z + 9, Blocks.leaves, 7, 3);
		world.setBlock(x + 1, y + 4, z + 10, Blocks.leaves, 7, 3);
		world.setBlock(x + 2, y + 4, z + 10, Blocks.stonebrick, 0, 3);
		world.setBlock(x + 3, y + 4, z + 10, Blocks.dirt, 0, 3);
		world.setBlock(x + 4, y + 4, z + 10, Blocks.dirt, 0, 3);
		world.setBlock(x + 5, y + 4, z + 10, Blocks.dirt, 0, 3);
		world.setBlock(x + 6, y + 4, z + 10, Blocks.dirt, 0, 3);
		world.setBlock(x + 7, y + 4, z + 10, Blocks.glowstone, 0, 3);
		world.setBlock(x + 8, y + 4, z + 10, Blocks.cobblestone_wall, 0, 3);
		world.setBlock(x + 9, y + 4, z + 10, Blocks.air, 0, 3);
		world.setBlock(x + 10, y + 4, z + 10, Blocks.cobblestone_wall, 0, 3);
		world.setBlock(x + 11, y + 4, z + 10, Blocks.glowstone, 0, 3);
		world.setBlock(x + 12, y + 4, z + 10, Blocks.dirt, 0, 3);
		world.setBlock(x + 13, y + 4, z + 10, Blocks.dirt, 0, 3);
		world.setBlock(x + 14, y + 4, z + 10, Blocks.dirt, 0, 3);
		world.setBlock(x + 15, y + 4, z + 10, Blocks.dirt, 0, 3);
		world.setBlock(x + 16, y + 4, z + 10, Blocks.stonebrick, 0, 3);
		world.setBlock(x + 17, y + 4, z + 10, Blocks.tallgrass, 1, 3);
		world.setBlock(x + 1, y + 4, z + 11, Blocks.vine, 8, 3);
		world.setBlock(x + 2, y + 4, z + 11, Blocks.stonebrick, 0, 3);
		world.setBlock(x + 3, y + 4, z + 11, Blocks.dirt, 0, 3);
		world.setBlock(x + 4, y + 4, z + 11, Blocks.dirt, 0, 3);
		world.setBlock(x + 5, y + 4, z + 11, Blocks.dirt, 0, 3);
		world.setBlock(x + 6, y + 4, z + 11, Blocks.dirt, 0, 3);
		world.setBlock(x + 7, y + 4, z + 11, Blocks.dirt, 0, 3);
		world.setBlock(x + 8, y + 4, z + 11, Blocks.stonebrick, 0, 3);
		world.setBlock(x + 9, y + 4, z + 11, Blocks.air, 0, 3);
		world.setBlock(x + 10, y + 4, z + 11, Blocks.stonebrick, 0, 3);
		world.setBlock(x + 11, y + 4, z + 11, Blocks.dirt, 0, 3);
		world.setBlock(x + 12, y + 4, z + 11, Blocks.dirt, 0, 3);
		world.setBlock(x + 13, y + 4, z + 11, Blocks.dirt, 0, 3);
		world.setBlock(x + 14, y + 4, z + 11, Blocks.dirt, 0, 3);
		world.setBlock(x + 15, y + 4, z + 11, Blocks.dirt, 0, 3);
		world.setBlock(x + 16, y + 4, z + 11, Blocks.stonebrick, 0, 3);
		world.setBlock(x + 17, y + 4, z + 11, Blocks.vine, 2, 3);
		world.setBlock(x + 2, y + 4, z + 12, Blocks.stonebrick, 0, 3);
		world.setBlock(x + 3, y + 4, z + 12, Blocks.dirt, 0, 3);
		world.setBlock(x + 4, y + 4, z + 12, Blocks.dirt, 0, 3);
		world.setBlock(x + 5, y + 4, z + 12, Blocks.dirt, 0, 3);
		world.setBlock(x + 6, y + 4, z + 12, Blocks.dirt, 0, 3);
		world.setBlock(x + 7, y + 4, z + 12, Blocks.dirt, 0, 3);
		world.setBlock(x + 8, y + 4, z + 12, Blocks.dirt, 0, 3);
		world.setBlock(x + 9, y + 4, z + 12, Blocks.stonebrick, 0, 3);
		world.setBlock(x + 10, y + 4, z + 12, Blocks.dirt, 0, 3);
		world.setBlock(x + 11, y + 4, z + 12, Blocks.dirt, 0, 3);
		world.setBlock(x + 12, y + 4, z + 12, Blocks.dirt, 0, 3);
		world.setBlock(x + 13, y + 4, z + 12, Blocks.dirt, 0, 3);
		world.setBlock(x + 14, y + 4, z + 12, Blocks.dirt, 0, 3);
		world.setBlock(x + 15, y + 4, z + 12, Blocks.dirt, 0, 3);
		world.setBlock(x + 16, y + 4, z + 12, Blocks.stonebrick, 0, 3);
		world.setBlock(x + 17, y + 4, z + 12, Blocks.tallgrass, 1, 3);
		world.setBlock(x + 2, y + 4, z + 13, Blocks.stonebrick, 0, 3);
		world.setBlock(x + 3, y + 4, z + 13, Blocks.dirt, 0, 3);
		world.setBlock(x + 4, y + 4, z + 13, Blocks.dirt, 0, 3);
		world.setBlock(x + 5, y + 4, z + 13, Blocks.dirt, 0, 3);
		world.setBlock(x + 6, y + 4, z + 13, Blocks.dirt, 0, 3);
		world.setBlock(x + 7, y + 4, z + 13, Blocks.dirt, 0, 3);
		world.setBlock(x + 8, y + 4, z + 13, Blocks.dirt, 0, 3);
		world.setBlock(x + 9, y + 4, z + 13, Blocks.dirt, 0, 3);
		world.setBlock(x + 10, y + 4, z + 13, Blocks.dirt, 0, 3);
		world.setBlock(x + 11, y + 4, z + 13, Blocks.dirt, 0, 3);
		world.setBlock(x + 12, y + 4, z + 13, Blocks.dirt, 0, 3);
		world.setBlock(x + 13, y + 4, z + 13, Blocks.dirt, 0, 3);
		world.setBlock(x + 14, y + 4, z + 13, Blocks.dirt, 0, 3);
		world.setBlock(x + 15, y + 4, z + 13, Blocks.dirt, 0, 3);
		world.setBlock(x + 16, y + 4, z + 13, Blocks.stonebrick, 0, 3);
		world.setBlock(x + 17, y + 4, z + 13, Blocks.vine, 2, 3);
		world.setBlock(x + 1, y + 4, z + 14, Blocks.vine, 8, 3);
		world.setBlock(x + 2, y + 4, z + 14, Blocks.stonebrick, 0, 3);
		world.setBlock(x + 3, y + 4, z + 14, Blocks.stonebrick, 0, 3);
		world.setBlock(x + 4, y + 4, z + 14, Blocks.stonebrick, 0, 3);
		world.setBlock(x + 5, y + 4, z + 14, Blocks.stonebrick, 0, 3);
		world.setBlock(x + 6, y + 4, z + 14, Blocks.stonebrick, 0, 3);
		world.setBlock(x + 7, y + 4, z + 14, Blocks.stonebrick, 0, 3);
		world.setBlock(x + 8, y + 4, z + 14, Blocks.stonebrick, 0, 3);
		world.setBlock(x + 9, y + 4, z + 14, Blocks.stonebrick, 0, 3);
		world.setBlock(x + 10, y + 4, z + 14, Blocks.stonebrick, 0, 3);
		world.setBlock(x + 11, y + 4, z + 14, Blocks.stonebrick, 0, 3);
		world.setBlock(x + 12, y + 4, z + 14, Blocks.stonebrick, 0, 3);
		world.setBlock(x + 13, y + 4, z + 14, Blocks.stonebrick, 0, 3);
		world.setBlock(x + 14, y + 4, z + 14, Blocks.stonebrick, 0, 3);
		world.setBlock(x + 15, y + 4, z + 14, Blocks.stonebrick, 0, 3);
		world.setBlock(x + 16, y + 4, z + 14, Blocks.stonebrick, 0, 3);
		world.setBlock(x + 1, y + 4, z + 15, Blocks.tallgrass, 1, 3);
		world.setBlock(x + 2, y + 4, z + 15, Blocks.tallgrass, 2, 3);
		world.setBlock(x + 3, y + 4, z + 15, Blocks.vine, 4, 3);
		world.setBlock(x + 4, y + 4, z + 15, Blocks.tallgrass, 1, 3);
		world.setBlock(x + 5, y + 4, z + 15, Blocks.leaves, 7, 3);
		world.setBlock(x + 6, y + 4, z + 15, Blocks.log, 3, 3);
		world.setBlock(x + 7, y + 4, z + 15, Blocks.stonebrick, 0, 3);
		world.setBlock(x + 8, y + 4, z + 15, Blocks.stone_brick_stairs, 3, 3);
		world.setBlock(x + 9, y + 4, z + 15, Blocks.stone_brick_stairs, 3, 3);
		world.setBlock(x + 10, y + 4, z + 15, Blocks.stone_brick_stairs, 3, 3);
		world.setBlock(x + 11, y + 4, z + 15, Blocks.stonebrick, 0, 3);
		world.setBlock(x + 12, y + 4, z + 15, Blocks.tallgrass, 2, 3);
		world.setBlock(x + 13, y + 4, z + 15, Blocks.tallgrass, 1, 3);
		world.setBlock(x + 15, y + 4, z + 15, Blocks.double_plant, 3, 3);
		world.setBlock(x + 16, y + 4, z + 15, Blocks.tallgrass, 2, 3);
		world.setBlock(x + 17, y + 4, z + 15, Blocks.tallgrass, 1, 3);
		world.setBlock(x + 4, y + 4, z + 16, Blocks.tallgrass, 1, 3);
		world.setBlock(x + 5, y + 4, z + 16, Blocks.leaves, 7, 3);
		world.setBlock(x + 6, y + 4, z + 16, Blocks.leaves, 15, 3);
		world.setBlock(x + 7, y + 4, z + 16, Blocks.stone_brick_stairs, 3, 3);
		world.setBlock(x + 8, y + 4, z + 16, Blocks.leaves, 7, 3);
		world.setBlock(x + 11, y + 4, z + 16, Blocks.stone_brick_stairs, 3, 3);
		world.setBlock(x + 12, y + 4, z + 16, Blocks.tallgrass, 1, 3);
		world.setBlock(x + 13, y + 4, z + 16, Blocks.double_plant, 2, 3);
		world.setBlock(x + 6, y + 4, z + 17, Blocks.double_plant, 2, 3);
		world.setBlock(x + 7, y + 4, z + 17, Blocks.leaves, 7, 3);
		world.setBlock(x + 2, y + 5, z + 1, Blocks.double_plant, 9, 3);
		world.setBlock(x + 4, y + 5, z + 1, Blocks.vine, 1, 3);
		world.setBlock(x + 6, y + 5, z + 1, Blocks.vine, 1, 3);
		world.setBlock(x + 7, y + 5, z + 1, Blocks.vine, 1, 3);
		world.setBlock(x + 9, y + 5, z + 1, Blocks.leaves, 15, 3);
		world.setBlock(x + 10, y + 5, z + 1, Blocks.leaves, 15, 3);
		world.setBlock(x + 11, y + 5, z + 1, Blocks.vine, 1, 3);
		world.setBlock(x + 12, y + 5, z + 1, Blocks.vine, 1, 3);
		world.setBlock(x + 15, y + 5, z + 1, Blocks.double_plant, 10, 3);
		world.setBlock(x + 16, y + 5, z + 1, Blocks.vine, 1, 3);
		world.setBlock(x + 2, y + 5, z + 2, Blocks.stonebrick, 0, 3);
		world.setBlock(x + 3, y + 5, z + 2, Blocks.stonebrick, 0, 3);
		world.setBlock(x + 4, y + 5, z + 2, Blocks.stonebrick, 0, 3);
		world.setBlock(x + 5, y + 5, z + 2, Blocks.stonebrick, 0, 3);
		world.setBlock(x + 6, y + 5, z + 2, Blocks.stonebrick, 0, 3);
		world.setBlock(x + 7, y + 5, z + 2, Blocks.stonebrick, 0, 3);
		world.setBlock(x + 8, y + 5, z + 2, Blocks.stonebrick, 0, 3);
		world.setBlock(x + 9, y + 5, z + 2, Blocks.stonebrick, 0, 3);
		world.setBlock(x + 10, y + 5, z + 2, Blocks.stonebrick, 0, 3);
		world.setBlock(x + 11, y + 5, z + 2, Blocks.stonebrick, 0, 3);
		world.setBlock(x + 12, y + 5, z + 2, Blocks.stonebrick, 0, 3);
		world.setBlock(x + 13, y + 5, z + 2, Blocks.stonebrick, 0, 3);
		world.setBlock(x + 14, y + 5, z + 2, Blocks.stonebrick, 0, 3);
		world.setBlock(x + 15, y + 5, z + 2, Blocks.stonebrick, 0, 3);
		world.setBlock(x + 16, y + 5, z + 2, Blocks.stonebrick, 0, 3);
		world.setBlock(x + 1, y + 5, z + 3, Blocks.double_plant, 9, 3);
		world.setBlock(x + 2, y + 5, z + 3, Blocks.stonebrick, 0, 3);
		world.setBlock(x + 3, y + 5, z + 3, Blocks.grass, 0, 3);
		world.setBlock(x + 4, y + 5, z + 3, Blocks.grass, 0, 3);
		world.setBlock(x + 5, y + 5, z + 3, Blocks.grass, 0, 3);
		world.setBlock(x + 6, y + 5, z + 3, Blocks.grass, 0, 3);
		world.setBlock(x + 7, y + 5, z + 3, Blocks.grass, 0, 3);
		world.setBlock(x + 8, y + 5, z + 3, Blocks.grass, 0, 3);
		world.setBlock(x + 9, y + 5, z + 3, Blocks.dirt, 0, 3);
		world.setBlock(x + 10, y + 5, z + 3, Blocks.grass, 0, 3);
		world.setBlock(x + 11, y + 5, z + 3, Blocks.grass, 0, 3);
		world.setBlock(x + 12, y + 5, z + 3, Blocks.grass, 0, 3);
		world.setBlock(x + 13, y + 5, z + 3, Blocks.grass, 0, 3);
		world.setBlock(x + 14, y + 5, z + 3, Blocks.grass, 0, 3);
		world.setBlock(x + 15, y + 5, z + 3, Blocks.grass, 0, 3);
		world.setBlock(x + 16, y + 5, z + 3, Blocks.stonebrick, 0, 3);
		world.setBlock(x + 17, y + 5, z + 3, Blocks.vine, 2, 3);
		world.setBlock(x + 2, y + 5, z + 4, Blocks.stonebrick, 0, 3);
		world.setBlock(x + 3, y + 5, z + 4, Blocks.grass, 0, 3);
		world.setBlock(x + 4, y + 5, z + 4, Blocks.dirt, 0, 3);
		world.setBlock(x + 5, y + 5, z + 4, Blocks.dirt, 0, 3);
		world.setBlock(x + 6, y + 5, z + 4, Blocks.dirt, 0, 3);
		world.setBlock(x + 7, y + 5, z + 4, Blocks.dirt, 0, 3);
		world.setBlock(x + 8, y + 5, z + 4, Blocks.dirt, 0, 3);
		world.setBlock(x + 9, y + 5, z + 4, Blocks.dirt, 0, 3);
		world.setBlock(x + 10, y + 5, z + 4, Blocks.dirt, 0, 3);
		world.setBlock(x + 11, y + 5, z + 4, Blocks.dirt, 0, 3);
		world.setBlock(x + 12, y + 5, z + 4, Blocks.dirt, 0, 3);
		world.setBlock(x + 13, y + 5, z + 4, Blocks.dirt, 0, 3);
		world.setBlock(x + 14, y + 5, z + 4, Blocks.dirt, 0, 3);
		world.setBlock(x + 15, y + 5, z + 4, Blocks.grass, 0, 3);
		world.setBlock(x + 16, y + 5, z + 4, Blocks.stonebrick, 0, 3);
		world.setBlock(x + 17, y + 5, z + 4, Blocks.vine, 2, 3);
		world.setBlock(x + 1, y + 5, z + 5, Blocks.vine, 8, 3);
		world.setBlock(x + 2, y + 5, z + 5, Blocks.stonebrick, 0, 3);
		world.setBlock(x + 3, y + 5, z + 5, Blocks.grass, 0, 3);
		world.setBlock(x + 4, y + 5, z + 5, Blocks.dirt, 0, 3);
		world.setBlock(x + 5, y + 5, z + 5, Blocks.dirt, 0, 3);
		world.setBlock(x + 6, y + 5, z + 5, Blocks.dirt, 0, 3);
		world.setBlock(x + 7, y + 5, z + 5, Blocks.dirt, 0, 3);
		world.setBlock(x + 8, y + 5, z + 5, Blocks.stonebrick, 0, 3);
		world.setBlock(x + 9, y + 5, z + 5, Blocks.stone_brick_stairs, 7, 3);
		world.setBlock(x + 10, y + 5, z + 5, Blocks.stonebrick, 0, 3);
		world.setBlock(x + 11, y + 5, z + 5, Blocks.dirt, 0, 3);
		world.setBlock(x + 12, y + 5, z + 5, Blocks.dirt, 0, 3);
		world.setBlock(x + 13, y + 5, z + 5, Blocks.dirt, 0, 3);
		world.setBlock(x + 14, y + 5, z + 5, Blocks.dirt, 0, 3);
		world.setBlock(x + 15, y + 5, z + 5, Blocks.grass, 0, 3);
		world.setBlock(x + 16, y + 5, z + 5, Blocks.stonebrick, 0, 3);
		world.setBlock(x + 1, y + 5, z + 6, Blocks.double_plant, 9, 3);
		world.setBlock(x + 2, y + 5, z + 6, Blocks.stonebrick, 0, 3);
		world.setBlock(x + 3, y + 5, z + 6, Blocks.grass, 0, 3);
		world.setBlock(x + 4, y + 5, z + 6, Blocks.dirt, 0, 3);
		world.setBlock(x + 5, y + 5, z + 6, Blocks.dirt, 0, 3);
		world.setBlock(x + 6, y + 5, z + 6, Blocks.dirt, 0, 3);
		world.setBlock(x + 7, y + 5, z + 6, Blocks.stonebrick, 3, 3);
		world.setBlock(x + 8, y + 5, z + 6, Blocks.cobblestone_wall, 0, 3);
		world.setBlock(x + 9, y + 5, z + 6, Blocks.air, 0, 3);
		world.setBlock(x + 10, y + 5, z + 6, Blocks.cobblestone_wall, 0, 3);
		world.setBlock(x + 11, y + 5, z + 6, Blocks.stonebrick, 3, 3);
		world.setBlock(x + 12, y + 5, z + 6, Blocks.dirt, 0, 3);
		world.setBlock(x + 13, y + 5, z + 6, Blocks.dirt, 0, 3);
		world.setBlock(x + 14, y + 5, z + 6, Blocks.dirt, 0, 3);
		world.setBlock(x + 15, y + 5, z + 6, Blocks.grass, 0, 3);
		world.setBlock(x + 16, y + 5, z + 6, Blocks.stonebrick, 0, 3);
		world.setBlock(x + 17, y + 5, z + 6, Blocks.double_plant, 11, 3);
		world.setBlock(x + 2, y + 5, z + 7, Blocks.stonebrick, 0, 3);
		world.setBlock(x + 3, y + 5, z + 7, Blocks.grass, 0, 3);
		world.setBlock(x + 4, y + 5, z + 7, Blocks.dirt, 0, 3);
		world.setBlock(x + 5, y + 5, z + 7, Blocks.dirt, 0, 3);
		world.setBlock(x + 6, y + 5, z + 7, Blocks.stonebrick, 0, 3);
		world.setBlock(x + 7, y + 5, z + 7, Blocks.cobblestone_wall, 0, 3);
		world.setBlock(x + 8, y + 5, z + 7, Blocks.air, 0, 3);
		world.setBlock(x + 9, y + 5, z + 7, Blocks.air, 0, 3);
		world.setBlock(x + 10, y + 5, z + 7, Blocks.air, 0, 3);
		world.setBlock(x + 11, y + 5, z + 7, Blocks.cobblestone_wall, 0, 3);
		world.setBlock(x + 12, y + 5, z + 7, Blocks.stonebrick, 0, 3);
		world.setBlock(x + 13, y + 5, z + 7, Blocks.dirt, 0, 3);
		world.setBlock(x + 14, y + 5, z + 7, Blocks.dirt, 0, 3);
		world.setBlock(x + 15, y + 5, z + 7, Blocks.grass, 0, 3);
		world.setBlock(x + 16, y + 5, z + 7, Blocks.stonebrick, 0, 3);
		world.setBlock(x + 17, y + 5, z + 7, Blocks.vine, 2, 3);
		world.setBlock(x + 1, y + 5, z + 8, Blocks.leaves, 7, 3);
		world.setBlock(x + 2, y + 5, z + 8, Blocks.stonebrick, 0, 3);
		world.setBlock(x + 3, y + 5, z + 8, Blocks.grass, 0, 3);
		world.setBlock(x + 4, y + 5, z + 8, Blocks.dirt, 0, 3);
		world.setBlock(x + 5, y + 5, z + 8, Blocks.dirt, 0, 3);
		world.setBlock(x + 6, y + 5, z + 8, Blocks.stone_brick_stairs, 5, 3);
		world.setBlock(x + 7, y + 5, z + 8, Blocks.air, 0, 3);
		world.setBlock(x + 8, y + 5, z + 8, Blocks.air, 0, 3);
		world.setBlock(x + 9, y + 5, z + 8, Blocks.air, 0, 3);
		world.setBlock(x + 10, y + 5, z + 8, Blocks.air, 0, 3);
		world.setBlock(x + 11, y + 5, z + 8, Blocks.air, 0, 3);
		world.setBlock(x + 12, y + 5, z + 8, Blocks.stone_brick_stairs, 4, 3);
		world.setBlock(x + 13, y + 5, z + 8, Blocks.stonebrick, 0, 3);
		world.setBlock(x + 14, y + 5, z + 8, Blocks.dirt, 0, 3);
		world.setBlock(x + 15, y + 5, z + 8, Blocks.grass, 0, 3);
		world.setBlock(x + 16, y + 5, z + 8, Blocks.stonebrick, 0, 3);
		world.setBlock(x + 17, y + 5, z + 8, Blocks.leaves, 15, 3);
		world.setBlock(x + 1, y + 5, z + 9, Blocks.leaves, 15, 3);
		world.setBlock(x + 2, y + 5, z + 9, Blocks.stonebrick, 0, 3);
		world.setBlock(x + 3, y + 5, z + 9, Blocks.dirt, 0, 3);
		world.setBlock(x + 4, y + 5, z + 9, Blocks.dirt, 0, 3);
		world.setBlock(x + 5, y + 5, z + 9, Blocks.dirt, 0, 3);
		world.setBlock(x + 6, y + 5, z + 9, Blocks.stonebrick, 0, 3);
		world.setBlock(x + 7, y + 5, z + 9, Blocks.cobblestone_wall, 0, 3);
		world.setBlock(x + 8, y + 5, z + 9, Blocks.air, 0, 3);
		world.setBlock(x + 9, y + 5, z + 9, Blocks.air, 0, 3);
		world.setBlock(x + 10, y + 5, z + 9, Blocks.air, 0, 3);
		world.setBlock(x + 11, y + 5, z + 9, Blocks.cobblestone_wall, 0, 3);
		world.setBlock(x + 12, y + 5, z + 9, Blocks.stonebrick, 0, 3);
		world.setBlock(x + 13, y + 5, z + 9, Blocks.dirt, 0, 3);
		world.setBlock(x + 14, y + 5, z + 9, Blocks.dirt, 0, 3);
		world.setBlock(x + 15, y + 5, z + 9, Blocks.grass, 0, 3);
		world.setBlock(x + 16, y + 5, z + 9, Blocks.stonebrick, 0, 3);
		world.setBlock(x + 17, y + 5, z + 9, Blocks.vine, 2, 3);
		world.setBlock(x + 1, y + 5, z + 10, Blocks.vine, 8, 3);
		world.setBlock(x + 2, y + 5, z + 10, Blocks.stonebrick, 0, 3);
		world.setBlock(x + 3, y + 5, z + 10, Blocks.grass, 0, 3);
		world.setBlock(x + 4, y + 5, z + 10, Blocks.dirt, 0, 3);
		world.setBlock(x + 5, y + 5, z + 10, Blocks.dirt, 0, 3);
		world.setBlock(x + 6, y + 5, z + 10, Blocks.dirt, 0, 3);
		world.setBlock(x + 7, y + 5, z + 10, Blocks.stonebrick, 3, 3);
		world.setBlock(x + 8, y + 5, z + 10, Blocks.cobblestone_wall, 0, 3);
		world.setBlock(x + 9, y + 5, z + 10, Blocks.air, 0, 3);
		world.setBlock(x + 10, y + 5, z + 10, Blocks.cobblestone_wall, 0, 3);
		world.setBlock(x + 11, y + 5, z + 10, Blocks.stonebrick, 3, 3);
		world.setBlock(x + 12, y + 5, z + 10, Blocks.dirt, 0, 3);
		world.setBlock(x + 13, y + 5, z + 10, Blocks.dirt, 0, 3);
		world.setBlock(x + 14, y + 5, z + 10, Blocks.dirt, 0, 3);
		world.setBlock(x + 15, y + 5, z + 10, Blocks.grass, 0, 3);
		world.setBlock(x + 16, y + 5, z + 10, Blocks.stonebrick, 0, 3);
		world.setBlock(x + 2, y + 5, z + 11, Blocks.stonebrick, 0, 3);
		world.setBlock(x + 3, y + 5, z + 11, Blocks.grass, 0, 3);
		world.setBlock(x + 4, y + 5, z + 11, Blocks.dirt, 0, 3);
		world.setBlock(x + 5, y + 5, z + 11, Blocks.dirt, 0, 3);
		world.setBlock(x + 6, y + 5, z + 11, Blocks.dirt, 0, 3);
		world.setBlock(x + 7, y + 5, z + 11, Blocks.dirt, 0, 3);
		world.setBlock(x + 8, y + 5, z + 11, Blocks.stonebrick, 0, 3);
		world.setBlock(x + 9, y + 5, z + 11, Blocks.stone_brick_stairs, 6, 3);
		world.setBlock(x + 10, y + 5, z + 11, Blocks.stonebrick, 0, 3);
		world.setBlock(x + 11, y + 5, z + 11, Blocks.dirt, 0, 3);
		world.setBlock(x + 12, y + 5, z + 11, Blocks.dirt, 0, 3);
		world.setBlock(x + 13, y + 5, z + 11, Blocks.dirt, 0, 3);
		world.setBlock(x + 14, y + 5, z + 11, Blocks.dirt, 0, 3);
		world.setBlock(x + 15, y + 5, z + 11, Blocks.grass, 0, 3);
		world.setBlock(x + 16, y + 5, z + 11, Blocks.stonebrick, 0, 3);
		world.setBlock(x + 2, y + 5, z + 12, Blocks.stonebrick, 0, 3);
		world.setBlock(x + 3, y + 5, z + 12, Blocks.grass, 0, 3);
		world.setBlock(x + 4, y + 5, z + 12, Blocks.dirt, 0, 3);
		world.setBlock(x + 5, y + 5, z + 12, Blocks.dirt, 0, 3);
		world.setBlock(x + 6, y + 5, z + 12, Blocks.dirt, 0, 3);
		world.setBlock(x + 7, y + 5, z + 12, Blocks.dirt, 0, 3);
		world.setBlock(x + 8, y + 5, z + 12, Blocks.dirt, 0, 3);
		world.setBlock(x + 9, y + 5, z + 12, Blocks.stonebrick, 0, 3);
		world.setBlock(x + 10, y + 5, z + 12, Blocks.dirt, 0, 3);
		world.setBlock(x + 11, y + 5, z + 12, Blocks.dirt, 0, 3);
		world.setBlock(x + 12, y + 5, z + 12, Blocks.dirt, 0, 3);
		world.setBlock(x + 13, y + 5, z + 12, Blocks.dirt, 0, 3);
		world.setBlock(x + 14, y + 5, z + 12, Blocks.dirt, 0, 3);
		world.setBlock(x + 15, y + 5, z + 12, Blocks.grass, 0, 3);
		world.setBlock(x + 16, y + 5, z + 12, Blocks.stonebrick, 0, 3);
		world.setBlock(x + 17, y + 5, z + 12, Blocks.vine, 2, 3);
		world.setBlock(x + 1, y + 5, z + 13, Blocks.double_plant, 9, 3);
		world.setBlock(x + 2, y + 5, z + 13, Blocks.stonebrick, 0, 3);
		world.setBlock(x + 3, y + 5, z + 13, Blocks.grass, 0, 3);
		world.setBlock(x + 4, y + 5, z + 13, Blocks.grass, 0, 3);
		world.setBlock(x + 5, y + 5, z + 13, Blocks.grass, 0, 3);
		world.setBlock(x + 6, y + 5, z + 13, Blocks.grass, 0, 3);
		world.setBlock(x + 7, y + 5, z + 13, Blocks.dirt, 0, 3);
		world.setBlock(x + 8, y + 5, z + 13, Blocks.grass, 0, 3);
		world.setBlock(x + 9, y + 5, z + 13, Blocks.grass, 0, 3);
		world.setBlock(x + 10, y + 5, z + 13, Blocks.grass, 0, 3);
		world.setBlock(x + 11, y + 5, z + 13, Blocks.dirt, 0, 3);
		world.setBlock(x + 12, y + 5, z + 13, Blocks.grass, 0, 3);
		world.setBlock(x + 13, y + 5, z + 13, Blocks.grass, 0, 3);
		world.setBlock(x + 14, y + 5, z + 13, Blocks.grass, 0, 3);
		world.setBlock(x + 15, y + 5, z + 13, Blocks.grass, 0, 3);
		world.setBlock(x + 16, y + 5, z + 13, Blocks.stonebrick, 0, 3);
		world.setBlock(x + 17, y + 5, z + 13, Blocks.vine, 2, 3);
		world.setBlock(x + 1, y + 5, z + 14, Blocks.vine, 8, 3);
		world.setBlock(x + 2, y + 5, z + 14, Blocks.stonebrick, 0, 3);
		world.setBlock(x + 3, y + 5, z + 14, Blocks.stonebrick, 0, 3);
		world.setBlock(x + 4, y + 5, z + 14, Blocks.stonebrick, 0, 3);
		world.setBlock(x + 5, y + 5, z + 14, Blocks.stonebrick, 0, 3);
		world.setBlock(x + 6, y + 5, z + 14, Blocks.stonebrick, 0, 3);
		world.setBlock(x + 7, y + 5, z + 14, Blocks.stonebrick, 0, 3);
		world.setBlock(x + 8, y + 5, z + 14, Blocks.stone_brick_stairs, 3, 3);
		world.setBlock(x + 9, y + 5, z + 14, Blocks.stone_brick_stairs, 3, 3);
		world.setBlock(x + 10, y + 5, z + 14, Blocks.stone_brick_stairs, 3, 3);
		world.setBlock(x + 11, y + 5, z + 14, Blocks.stonebrick, 0, 3);
		world.setBlock(x + 12, y + 5, z + 14, Blocks.stonebrick, 0, 3);
		world.setBlock(x + 13, y + 5, z + 14, Blocks.stonebrick, 0, 3);
		world.setBlock(x + 14, y + 5, z + 14, Blocks.stonebrick, 0, 3);
		world.setBlock(x + 15, y + 5, z + 14, Blocks.stonebrick, 0, 3);
		world.setBlock(x + 16, y + 5, z + 14, Blocks.stonebrick, 0, 3);
		world.setBlock(x + 17, y + 5, z + 14, Blocks.double_plant, 11, 3);
		world.setBlock(x + 3, y + 5, z + 15, Blocks.vine, 4, 3);
		world.setBlock(x + 5, y + 5, z + 15, Blocks.leaves, 7, 3);
		world.setBlock(x + 6, y + 5, z + 15, Blocks.leaves, 7, 3);
		world.setBlock(x + 7, y + 5, z + 15, Blocks.stone_brick_stairs, 3, 3);
		world.setBlock(x + 11, y + 5, z + 15, Blocks.stone_brick_stairs, 3, 3);
		world.setBlock(x + 13, y + 5, z + 15, Blocks.vine, 4, 3);
		world.setBlock(x + 15, y + 5, z + 15, Blocks.double_plant, 8, 3);
		world.setBlock(x + 16, y + 5, z + 15, Blocks.vine, 4, 3);
		world.setBlock(x + 6, y + 5, z + 16, Blocks.leaves, 15, 3);
		world.setBlock(x + 7, y + 5, z + 16, Blocks.leaves, 15, 3);
		world.setBlock(x + 13, y + 5, z + 16, Blocks.double_plant, 8, 3);
		world.setBlock(x + 6, y + 5, z + 17, Blocks.double_plant, 8, 3);
		world.setBlock(x + 9, y + 6, z + 1, Blocks.leaves, 15, 3);
		world.setBlock(x + 8, y + 6, z + 2, Blocks.leaves, 15, 3);
		world.setBlock(x + 9, y + 6, z + 2, Blocks.leaves, 15, 3);
		world.setBlock(x + 10, y + 6, z + 2, Blocks.leaves, 15, 3);
		world.setBlock(x + 4, y + 6, z + 3, Blocks.tallgrass, 2, 3);
		world.setBlock(x + 6, y + 6, z + 3, Blocks.vine, 1, 3);
		world.setBlock(x + 7, y + 6, z + 3, Blocks.vine, 1, 3);
		world.setBlock(x + 8, y + 6, z + 3, Blocks.leaves, 15, 3);
		world.setBlock(x + 9, y + 6, z + 3, Blocks.log, 3, 3);
		world.setBlock(x + 10, y + 6, z + 3, Blocks.leaves, 15, 3);
		world.setBlock(x + 11, y + 6, z + 3, Blocks.leaves, 15, 3);
		world.setBlock(x + 12, y + 6, z + 3, Blocks.vine, 1, 3);
		world.setBlock(x + 14, y + 6, z + 3, Blocks.tallgrass, 1, 3);
		world.setBlock(x + 3, y + 6, z + 4, Blocks.tallgrass, 1, 3);
		world.setBlock(x + 4, y + 6, z + 4, Blocks.stonebrick, 0, 3);
		world.setBlock(x + 5, y + 6, z + 4, Blocks.stonebrick, 0, 3);
		world.setBlock(x + 6, y + 6, z + 4, Blocks.stonebrick, 0, 3);
		world.setBlock(x + 7, y + 6, z + 4, Blocks.stonebrick, 0, 3);
		world.setBlock(x + 8, y + 6, z + 4, Blocks.stonebrick, 0, 3);
		world.setBlock(x + 9, y + 6, z + 4, Blocks.stonebrick, 0, 3);
		world.setBlock(x + 10, y + 6, z + 4, Blocks.stonebrick, 0, 3);
		world.setBlock(x + 11, y + 6, z + 4, Blocks.stonebrick, 0, 3);
		world.setBlock(x + 12, y + 6, z + 4, Blocks.stonebrick, 0, 3);
		world.setBlock(x + 13, y + 6, z + 4, Blocks.stonebrick, 0, 3);
		world.setBlock(x + 14, y + 6, z + 4, Blocks.stonebrick, 0, 3);
		world.setBlock(x + 15, y + 6, z + 4, Blocks.vine, 2, 3);
		world.setBlock(x + 3, y + 6, z + 5, Blocks.vine, 8, 3);
		world.setBlock(x + 4, y + 6, z + 5, Blocks.stonebrick, 0, 3);
		world.setBlock(x + 5, y + 6, z + 5, Blocks.dirt, 0, 3);
		world.setBlock(x + 6, y + 6, z + 5, Blocks.dirt, 0, 3);
		world.setBlock(x + 7, y + 6, z + 5, Blocks.dirt, 0, 3);
		world.setBlock(x + 8, y + 6, z + 5, Blocks.dirt, 0, 3);
		world.setBlock(x + 9, y + 6, z + 5, Blocks.dirt, 0, 3);
		world.setBlock(x + 10, y + 6, z + 5, Blocks.dirt, 0, 3);
		world.setBlock(x + 11, y + 6, z + 5, Blocks.dirt, 0, 3);
		world.setBlock(x + 12, y + 6, z + 5, Blocks.dirt, 0, 3);
		world.setBlock(x + 13, y + 6, z + 5, Blocks.dirt, 0, 3);
		world.setBlock(x + 14, y + 6, z + 5, Blocks.stonebrick, 0, 3);
		world.setBlock(x + 3, y + 6, z + 6, Blocks.vine, 8, 3);
		world.setBlock(x + 4, y + 6, z + 6, Blocks.stonebrick, 0, 3);
		world.setBlock(x + 5, y + 6, z + 6, Blocks.dirt, 0, 3);
		world.setBlock(x + 6, y + 6, z + 6, Blocks.dirt, 0, 3);
		world.setBlock(x + 7, y + 6, z + 6, Blocks.stonebrick, 3, 3);
		world.setBlock(x + 8, y + 6, z + 6, Blocks.stonebrick, 0, 3);
		world.setBlock(x + 9, y + 6, z + 6, Blocks.stone_brick_stairs, 7, 3);
		world.setBlock(x + 10, y + 6, z + 6, Blocks.stonebrick, 0, 3);
		world.setBlock(x + 11, y + 6, z + 6, Blocks.stonebrick, 3, 3);
		world.setBlock(x + 12, y + 6, z + 6, Blocks.dirt, 0, 3);
		world.setBlock(x + 13, y + 6, z + 6, Blocks.dirt, 0, 3);
		world.setBlock(x + 14, y + 6, z + 6, Blocks.stonebrick, 0, 3);
		world.setBlock(x + 3, y + 6, z + 7, Blocks.double_plant, 3, 3);
		world.setBlock(x + 4, y + 6, z + 7, Blocks.stonebrick, 0, 3);
		world.setBlock(x + 5, y + 6, z + 7, Blocks.dirt, 0, 3);
		world.setBlock(x + 6, y + 6, z + 7, Blocks.dirt, 0, 3);
		world.setBlock(x + 7, y + 6, z + 7, Blocks.stonebrick, 0, 3);
		world.setBlock(x + 8, y + 6, z + 7, Blocks.stone_slab, 13, 3);
		world.setBlock(x + 9, y + 6, z + 7, Blocks.stone_slab, 13, 3);
		world.setBlock(x + 10, y + 6, z + 7, Blocks.stone_slab, 13, 3);
		world.setBlock(x + 11, y + 6, z + 7, Blocks.stonebrick, 0, 3);
		world.setBlock(x + 12, y + 6, z + 7, Blocks.dirt, 0, 3);
		world.setBlock(x + 13, y + 6, z + 7, Blocks.dirt, 0, 3);
		world.setBlock(x + 14, y + 6, z + 7, Blocks.stonebrick, 0, 3);
		world.setBlock(x + 15, y + 6, z + 7, Blocks.vine, 2, 3);
		world.setBlock(x + 2, y + 6, z + 8, Blocks.leaves, 15, 3);
		world.setBlock(x + 3, y + 6, z + 8, Blocks.leaves, 7, 3);
		world.setBlock(x + 4, y + 6, z + 8, Blocks.stonebrick, 0, 3);
		world.setBlock(x + 5, y + 6, z + 8, Blocks.dirt, 0, 3);
		world.setBlock(x + 6, y + 6, z + 8, Blocks.dirt, 0, 3);
		world.setBlock(x + 7, y + 6, z + 8, Blocks.stone_brick_stairs, 5, 3);
		world.setBlock(x + 8, y + 6, z + 8, Blocks.stone_slab, 13, 3);
		world.setBlock(x + 9, y + 6, z + 8, Blocks.stone_slab, 13, 3);
		world.setBlock(x + 10, y + 6, z + 8, Blocks.stone_slab, 13, 3);
		world.setBlock(x + 11, y + 6, z + 8, Blocks.stone_brick_stairs, 4, 3);
		world.setBlock(x + 12, y + 6, z + 8, Blocks.dirt, 0, 3);
		world.setBlock(x + 13, y + 6, z + 8, Blocks.dirt, 0, 3);
		world.setBlock(x + 14, y + 6, z + 8, Blocks.stonebrick, 0, 3);
		world.setBlock(x + 15, y + 6, z + 8, Blocks.vine, 2, 3);
		world.setBlock(x + 1, y + 6, z + 9, Blocks.leaves, 15, 3);
		world.setBlock(x + 2, y + 6, z + 9, Blocks.leaves, 15, 3);
		world.setBlock(x + 3, y + 6, z + 9, Blocks.log, 3, 3);
		world.setBlock(x + 4, y + 6, z + 9, Blocks.stonebrick, 0, 3);
		world.setBlock(x + 5, y + 6, z + 9, Blocks.dirt, 0, 3);
		world.setBlock(x + 6, y + 6, z + 9, Blocks.dirt, 0, 3);
		world.setBlock(x + 7, y + 6, z + 9, Blocks.stonebrick, 0, 3);
		world.setBlock(x + 8, y + 6, z + 9, Blocks.stone_slab, 13, 3);
		world.setBlock(x + 9, y + 6, z + 9, Blocks.stone_slab, 13, 3);
		world.setBlock(x + 10, y + 6, z + 9, Blocks.stone_slab, 13, 3);
		world.setBlock(x + 11, y + 6, z + 9, Blocks.stonebrick, 0, 3);
		world.setBlock(x + 12, y + 6, z + 9, Blocks.dirt, 0, 3);
		world.setBlock(x + 13, y + 6, z + 9, Blocks.dirt, 0, 3);
