package com.github.revival.server.gen.feature;

import com.github.revival.server.block.FABlockRegistry;
import com.github.revival.server.item.FAItemRegistry;
import net.minecraft.block.Block;
import net.minecraft.block.material.Material;
import net.minecraft.init.Blocks;
import net.minecraft.init.Items;
import net.minecraft.item.Item;
import net.minecraft.item.ItemDoor;
import net.minecraft.tileentity.TileEntityChest;
import net.minecraft.util.WeightedRandomChestContent;
import net.minecraft.world.World;
import net.minecraft.world.gen.feature.WorldGenerator;

import java.util.Random;

public class HellBoatWorldGen extends WorldGenerator {
    protected static final WeightedRandomChestContent[] field_111019_a = new WeightedRandomChestContent[]{
            new WeightedRandomChestContent(Item.getItemFromBlock(FABlockRegistry.ancientGlass), 0, 2, 5, 25),
            new WeightedRandomChestContent(FAItemRegistry.relic, 0, 1, 2, 76),
            new WeightedRandomChestContent(FAItemRegistry.ancientSword, 0, 1, 3, 15),
            new WeightedRandomChestContent(Item.getItemFromBlock(FABlockRegistry.blockSkull), 0, 1, 2, 60),
            new WeightedRandomChestContent(Item.getItemFromBlock(FABlockRegistry.skullLantern), 0, 1, 2, 45),
            new WeightedRandomChestContent(Item.getItemFromBlock(FABlockRegistry.drum), 0, 1, 1, 28),
            new WeightedRandomChestContent(FAItemRegistry.potteryShards, 0, 1, 3, 70),
            new WeightedRandomChestContent(FAItemRegistry.goldjavelin, 0, 1, 1, 33),
            new WeightedRandomChestContent(FAItemRegistry.ironjavelin, 0, 1, 1, 46),
            new WeightedRandomChestContent(FAItemRegistry.stoneboard, 0, 1, 3, 25),
            new WeightedRandomChestContent(Items.bone, 0, 1, 3, 85),
            new WeightedRandomChestContent(Items.emerald, 0, 1, 3, 25),
            new WeightedRandomChestContent(Items.flint, 0, 1, 3, 35),
            new WeightedRandomChestContent(Items.blaze_rod, 0, 1, 3, 30),
            new WeightedRandomChestContent(Items.ghast_tear, 0, 1, 2, 25),
            new WeightedRandomChestContent(Item.getItemFromBlock(Blocks.bookshelf), 0, 1, 5, 35),
            new WeightedRandomChestContent(Item.getItemFromBlock(Blocks.glowstone), 0, 1, 4, 35),
            new WeightedRandomChestContent(Item.getItemFromBlock(Blocks.obsidian), 0, 1, 6, 25),
            new WeightedRandomChestContent(Items.netherbrick, 0, 1, 12, 65),
            new WeightedRandomChestContent(Item.getItemFromBlock(Blocks.tnt), 0, 1, 6, 25)
    };

    protected Block[] GetValidSpawnBlocks() {
        return new Block[]
                {
                        Blocks.lava,
                };
    }

    public boolean LocationIsValidSpawn(World world, int x, int y, int z) {
        int distanceToAir = 0;
        Block checkBlock = world.getBlock(x, y, z);

        while (checkBlock != Blocks.air) {
            distanceToAir++;
            checkBlock = world.getBlock(x, y + distanceToAir, z);
        }

        if (distanceToAir > 1) {
            return false;
        }

        y += distanceToAir - 1;

        Block block = world.getBlock(x, y, z);
        Block blockAbove = world.getBlock(x, y + 1, z);
        Block blockBelow = world.getBlock(x, y - 1, z);

        for (Block i : GetValidSpawnBlocks()) {
            if (blockAbove != Blocks.air) {
                return false;
            }
            if (block == i) {
                return true;
            } else if (block == Blocks.snow_layer && blockBelow == i) {
                return true;
            } else if (block.getMaterial() == Material.plants && blockBelow == i) {
                return true;
            }
        }
        return false;
    }

    public boolean generate(World world, Random rand, int x, int y, int z) {
        generate_r0(world, rand, x, y, z);
        return true;

    }

    public boolean generate_r0(World world, Random rand, int x, int y, int z) {
        if (!LocationIsValidSpawn(world, x + 16, y, z + 5)) {
            return false;
        }

        world.setBlock(x + 4, y + -2, z + 5, Blocks.nether_brick, 0, 3);
        world.setBlock(x + 5, y + -2, z + 5, Blocks.nether_brick, 0, 3);
        world.setBlock(x + 6, y + -2, z + 5, Blocks.nether_brick, 0, 3);
        world.setBlock(x + 7, y + -2, z + 5, Blocks.nether_brick, 0, 3);
        world.setBlock(x + 8, y + -2, z + 5, Blocks.nether_brick, 0, 3);
        world.setBlock(x + 9, y + -2, z + 5, Blocks.nether_brick, 0, 3);
        world.setBlock(x + 10, y + -2, z + 5, Blocks.nether_brick, 0, 3);
        world.setBlock(x + 11, y + -2, z + 5, Blocks.nether_brick, 0, 3);
        world.setBlock(x + 12, y + -2, z + 5, Blocks.nether_brick, 0, 3);
        world.setBlock(x + 13, y + -2, z + 5, Blocks.nether_brick, 0, 3);
        world.setBlock(x + 14, y + -2, z + 5, Blocks.nether_brick, 0, 3);
        world.setBlock(x + 15, y + -2, z + 5, Blocks.nether_brick, 0, 3);
        world.setBlock(x + 16, y + -2, z + 5, Blocks.nether_brick, 0, 3);
        world.setBlock(x + 17, y + -2, z + 5, Blocks.nether_brick, 0, 3);
        world.setBlock(x + 18, y + -2, z + 5, Blocks.nether_brick, 0, 3);
        world.setBlock(x + 19, y + -2, z + 5, Blocks.nether_brick, 0, 3);
        world.setBlock(x + 20, y + -2, z + 5, Blocks.nether_brick, 0, 3);
        world.setBlock(x + 4, y + -1, z + 3, Blocks.nether_brick, 0, 3);
        world.setBlock(x + 5, y + -1, z + 3, Blocks.nether_brick, 0, 3);
        world.setBlock(x + 6, y + -1, z + 3, Blocks.nether_brick, 0, 3);
        world.setBlock(x + 7, y + -1, z + 3, Blocks.nether_brick, 0, 3);
        world.setBlock(x + 8, y + -1, z + 3, Blocks.nether_brick, 0, 3);
        world.setBlock(x + 9, y + -1, z + 3, Blocks.nether_brick, 0, 3);
        world.setBlock(x + 10, y + -1, z + 3, Blocks.nether_brick, 0, 3);
        world.setBlock(x + 11, y + -1, z + 3, Blocks.nether_brick, 0, 3);
        world.setBlock(x + 12, y + -1, z + 3, Blocks.nether_brick, 0, 3);
        world.setBlock(x + 13, y + -1, z + 3, Blocks.nether_brick, 0, 3);
        world.setBlock(x + 14, y + -1, z + 3, Blocks.nether_brick, 0, 3);
        world.setBlock(x + 15, y + -1, z + 3, Blocks.nether_brick, 0, 3);
        world.setBlock(x + 16, y + -1, z + 3, Blocks.nether_brick, 0, 3);
        world.setBlock(x + 17, y + -1, z + 3, Blocks.nether_brick, 0, 3);
        world.setBlock(x + 18, y + -1, z + 3, Blocks.nether_brick, 0, 3);
        world.setBlock(x + 19, y + -1, z + 3, Blocks.nether_brick, 0, 3);
        world.setBlock(x + 20, y + -1, z + 3, Blocks.nether_brick, 0, 3);
        world.setBlock(x + 4, y + -1, z + 4, Blocks.nether_brick, 0, 3);
        world.setBlock(x + 5, y + -1, z + 4, Blocks.nether_brick, 0, 3);
        world.setBlock(x + 6, y + -1, z + 4, Blocks.nether_brick, 0, 3);
        world.setBlock(x + 7, y + -1, z + 4, Blocks.nether_brick, 0, 3);
        world.setBlock(x + 8, y + -1, z + 4, Blocks.nether_brick, 0, 3);
        world.setBlock(x + 9, y + -1, z + 4, Blocks.nether_brick, 0, 3);
        world.setBlock(x + 10, y + -1, z + 4, Blocks.nether_brick, 0, 3);
        world.setBlock(x + 11, y + -1, z + 4, Blocks.nether_brick, 0, 3);
        world.setBlock(x + 12, y + -1, z + 4, Blocks.nether_brick, 0, 3);
        world.setBlock(x + 13, y + -1, z + 4, Blocks.nether_brick, 0, 3);
        world.setBlock(x + 14, y + -1, z + 4, Blocks.nether_brick, 0, 3);
        world.setBlock(x + 15, y + -1, z + 4, Blocks.nether_brick, 0, 3);
        world.setBlock(x + 16, y + -1, z + 4, Blocks.nether_brick, 0, 3);
        world.setBlock(x + 17, y + -1, z + 4, Blocks.nether_brick, 0, 3);
        world.setBlock(x + 18, y + -1, z + 4, Blocks.nether_brick, 0, 3);
        world.setBlock(x + 19, y + -1, z + 4, Blocks.nether_brick, 0, 3);
        world.setBlock(x + 20, y + -1, z + 4, Blocks.nether_brick, 0, 3);
        world.setBlock(x + 2, y + -1, z + 5, Blocks.nether_brick, 0, 3);
        world.setBlock(x + 3, y + -1, z + 5, Blocks.nether_brick, 0, 3);
        world.setBlock(x + 21, y + -1, z + 5, Blocks.nether_brick, 0, 3);
        world.setBlock(x + 22, y + -1, z + 5, Blocks.nether_brick, 0, 3);
        world.setBlock(x + 4, y + -1, z + 6, Blocks.nether_brick, 0, 3);
        world.setBlock(x + 5, y + -1, z + 6, Blocks.nether_brick, 0, 3);
        world.setBlock(x + 6, y + -1, z + 6, Blocks.nether_brick, 0, 3);
        world.setBlock(x + 7, y + -1, z + 6, Blocks.nether_brick, 0, 3);
        world.setBlock(x + 8, y + -1, z + 6, Blocks.nether_brick, 0, 3);
        world.setBlock(x + 9, y + -1, z + 6, Blocks.nether_brick, 0, 3);
        world.setBlock(x + 10, y + -1, z + 6, Blocks.nether_brick, 0, 3);
        world.setBlock(x + 11, y + -1, z + 6, Blocks.nether_brick, 0, 3);
        world.setBlock(x + 12, y + -1, z + 6, Blocks.nether_brick, 0, 3);
        world.setBlock(x + 13, y + -1, z + 6, Blocks.nether_brick, 0, 3);
        world.setBlock(x + 14, y + -1, z + 6, Blocks.nether_brick, 0, 3);
        world.setBlock(x + 15, y + -1, z + 6, Blocks.nether_brick, 0, 3);
        world.setBlock(x + 16, y + -1, z + 6, Blocks.nether_brick, 0, 3);
        world.setBlock(x + 17, y + -1, z + 6, Blocks.nether_brick, 0, 3);
        world.setBlock(x + 18, y + -1, z + 6, Blocks.nether_brick, 0, 3);
        world.setBlock(x + 19, y + -1, z + 6, Blocks.nether_brick, 0, 3);
        world.setBlock(x + 20, y + -1, z + 6, Blocks.nether_brick, 0, 3);
        world.setBlock(x + 4, y + -1, z + 7, Blocks.nether_brick, 0, 3);
        world.setBlock(x + 5, y + -1, z + 7, Blocks.nether_brick, 0, 3);
        world.setBlock(x + 6, y + -1, z + 7, Blocks.nether_brick, 0, 3);
        world.setBlock(x + 7, y + -1, z + 7, Blocks.nether_brick, 0, 3);
        world.setBlock(x + 8, y + -1, z + 7, Blocks.nether_brick, 0, 3);
        world.setBlock(x + 9, y + -1, z + 7, Blocks.nether_brick, 0, 3);
        world.setBlock(x + 10, y + -1, z + 7, Blocks.nether_brick, 0, 3);
        world.setBlock(x + 11, y + -1, z + 7, Blocks.nether_brick, 0, 3);
        world.setBlock(x + 12, y + -1, z + 7, Blocks.nether_brick, 0, 3);
        world.setBlock(x + 13, y + -1, z + 7, Blocks.nether_brick, 0, 3);
        world.setBlock(x + 14, y + -1, z + 7, Blocks.nether_brick, 0, 3);
        world.setBlock(x + 15, y + -1, z + 7, Blocks.nether_brick, 0, 3);
        world.setBlock(x + 16, y + -1, z + 7, Blocks.nether_brick, 0, 3);
        world.setBlock(x + 17, y + -1, z + 7, Blocks.nether_brick, 0, 3);
        world.setBlock(x + 18, y + -1, z + 7, Blocks.nether_brick, 0, 3);
        world.setBlock(x + 19, y + -1, z + 7, Blocks.nether_brick, 0, 3);
        world.setBlock(x + 20, y + -1, z + 7, Blocks.nether_brick, 0, 3);
        world.setBlock(x + 4, y + 0, z + 2, Blocks.nether_brick, 0, 3);
        world.setBlock(x + 5, y + 0, z + 2, Blocks.nether_brick, 0, 3);
        world.setBlock(x + 6, y + 0, z + 2, Blocks.nether_brick, 0, 3);
        world.setBlock(x + 7, y + 0, z + 2, Blocks.nether_brick, 0, 3);
        world.setBlock(x + 8, y + 0, z + 2, Blocks.nether_brick, 0, 3);
        world.setBlock(x + 9, y + 0, z + 2, Blocks.nether_brick, 0, 3);
        world.setBlock(x + 10, y + 0, z + 2, Blocks.nether_brick, 0, 3);
        world.setBlock(x + 11, y + 0, z + 2, Blocks.nether_brick, 0, 3);
        world.setBlock(x + 12, y + 0, z + 2, Blocks.nether_brick, 0, 3);
        world.setBlock(x + 13, y + 0, z + 2, Blocks.nether_brick, 0, 3);
        world.setBlock(x + 14, y + 0, z + 2, Blocks.nether_brick, 0, 3);
        world.setBlock(x + 15, y + 0, z + 2, Blocks.nether_brick, 0, 3);
        world.setBlock(x + 16, y + 0, z + 2, Blocks.nether_brick, 0, 3);
        world.setBlock(x + 17, y + 0, z + 2, Blocks.nether_brick, 0, 3);
        world.setBlock(x + 18, y + 0, z + 2, Blocks.nether_brick, 0, 3);
        world.setBlock(x + 19, y + 0, z + 2, Blocks.nether_brick, 0, 3);
        world.setBlock(x + 20, y + 0, z + 2, Blocks.nether_brick, 0, 3);
        world.setBlock(x + 3, y + 0, z + 3, Blocks.nether_brick, 0, 3);
        world.setBlock(x + 4, y + 0, z + 3, Blocks.obsidian, 0, 3);
        world.setBlock(x + 5, y + 0, z + 3, Blocks.obsidian, 0, 3);
        world.setBlock(x + 6, y + 0, z + 3, Blocks.obsidian, 0, 3);
        world.setBlock(x + 7, y + 0, z + 3, Blocks.obsidian, 0, 3);
        world.setBlock(x + 8, y + 0, z + 3, Blocks.obsidian, 0, 3);
        world.setBlock(x + 9, y + 0, z + 3, Blocks.obsidian, 0, 3);
        world.setBlock(x + 10, y + 0, z + 3, Blocks.obsidian, 0, 3);
        world.setBlock(x + 11, y + 0, z + 3, Blocks.obsidian, 0, 3);
        world.setBlock(x + 12, y + 0, z + 3, Blocks.obsidian, 0, 3);
        world.setBlock(x + 13, y + 0, z + 3, Blocks.obsidian, 0, 3);
        world.setBlock(x + 14, y + 0, z + 3, Blocks.obsidian, 0, 3);
        world.setBlock(x + 15, y + 0, z + 3, Blocks.obsidian, 0, 3);
        world.setBlock(x + 16, y + 0, z + 3, Blocks.obsidian, 0, 3);
        world.setBlock(x + 17, y + 0, z + 3, Blocks.obsidian, 0, 3);
        world.setBlock(x + 18, y + 0, z + 3, Blocks.obsidian, 0, 3);
        world.setBlock(x + 19, y + 0, z + 3, Blocks.obsidian, 0, 3);
        world.setBlock(x + 20, y + 0, z + 3, Blocks.obsidian, 0, 3);
        world.setBlock(x + 21, y + 0, z + 3, Blocks.nether_brick, 0, 3);
        world.setBlock(x + 2, y + 0, z + 4, Blocks.nether_brick, 0, 3);
        world.setBlock(x + 3, y + 0, z + 4, Blocks.nether_brick, 0, 3);
        world.setBlock(x + 4, y + 0, z + 4, Blocks.obsidian, 0, 3);
        world.setBlock(x + 5, y + 0, z + 4, Blocks.obsidian, 0, 3);
        world.setBlock(x + 6, y + 0, z + 4, Blocks.obsidian, 0, 3);
        world.setBlock(x + 7, y + 0, z + 4, Blocks.obsidian, 0, 3);
        world.setBlock(x + 8, y + 0, z + 4, Blocks.obsidian, 0, 3);
        world.setBlock(x + 9, y + 0, z + 4, Blocks.obsidian, 0, 3);
        world.setBlock(x + 10, y + 0, z + 4, Blocks.obsidian, 0, 3);
        world.setBlock(x + 11, y + 0, z + 4, Blocks.obsidian, 0, 3);
        world.setBlock(x + 12, y + 0, z + 4, Blocks.obsidian, 0, 3);
        world.setBlock(x + 13, y + 0, z + 4, Blocks.obsidian, 0, 3);
        world.setBlock(x + 14, y + 0, z + 4, Blocks.obsidian, 0, 3);
        world.setBlock(x + 15, y + 0, z + 4, Blocks.obsidian, 0, 3);
        world.setBlock(x + 16, y + 0, z + 4, Blocks.obsidian, 0, 3);
        world.setBlock(x + 17, y + 0, z + 4, Blocks.obsidian, 0, 3);
        world.setBlock(x + 18, y + 0, z + 4, Blocks.obsidian, 0, 3);
        world.setBlock(x + 19, y + 0, z + 4, Blocks.obsidian, 0, 3);
        world.setBlock(x + 20, y + 0, z + 4, Blocks.obsidian, 0, 3);
        world.setBlock(x + 21, y + 0, z + 4, Blocks.nether_brick, 0, 3);
        world.setBlock(x + 22, y + 0, z + 4, Blocks.nether_brick, 0, 3);
        world.setBlock(x + 1, y + 0, z + 5, Blocks.nether_brick, 0, 3);
        world.setBlock(x + 2, y + 0, z + 5, Blocks.obsidian, 0, 3);
        world.setBlock(x + 3, y + 0, z + 5, Blocks.obsidian, 0, 3);
        world.setBlock(x + 4, y + 0, z + 5, Blocks.obsidian, 0, 3);
        world.setBlock(x + 5, y + 0, z + 5, Blocks.obsidian, 0, 3);
        world.setBlock(x + 6, y + 0, z + 5, Blocks.obsidian, 0, 3);
        world.setBlock(x + 7, y + 0, z + 5, Blocks.obsidian, 0, 3);
        world.setBlock(x + 8, y + 0, z + 5, Blocks.obsidian, 0, 3);
        world.setBlock(x + 9, y + 0, z + 5, Blocks.obsidian, 0, 3);
        world.setBlock(x + 10, y + 0, z + 5, Blocks.obsidian, 0, 3);
        world.setBlock(x + 11, y + 0, z + 5, Blocks.obsidian, 0, 3);
        world.setBlock(x + 12, y + 0, z + 5, Blocks.obsidian, 0, 3);
        world.setBlock(x + 13, y + 0, z + 5, Blocks.obsidian, 0, 3);
        world.setBlock(x + 14, y + 0, z + 5, Blocks.obsidian, 0, 3);
        world.setBlock(x + 15, y + 0, z + 5, Blocks.obsidian, 0, 3);
        world.setBlock(x + 16, y + 0, z + 5, Blocks.obsidian, 0, 3);
        world.setBlock(x + 17, y + 0, z + 5, Blocks.obsidian, 0, 3);
        world.setBlock(x + 18, y + 0, z + 5, Blocks.obsidian, 0, 3);
        world.setBlock(x + 19, y + 0, z + 5, Blocks.obsidian, 0, 3);
        world.setBlock(x + 20, y + 0, z + 5, Blocks.obsidian, 0, 3);
        world.setBlock(x + 21, y + 0, z + 5, Blocks.obsidian, 0, 3);
        world.setBlock(x + 22, y + 0, z + 5, Blocks.obsidian, 0, 3);
        world.setBlock(x + 23, y + 0, z + 5, Blocks.nether_brick, 0, 3);
        world.setBlock(x + 24, y + 0, z + 5, Blocks.nether_brick, 0, 3);
        world.setBlock(x + 2, y + 0, z + 6, Blocks.nether_brick, 0, 3);
        world.setBlock(x + 3, y + 0, z + 6, Blocks.nether_brick, 0, 3);
        world.setBlock(x + 4, y + 0, z + 6, Blocks.obsidian, 0, 3);
        world.setBlock(x + 5, y + 0, z + 6, Blocks.obsidian, 0, 3);
        world.setBlock(x + 6, y + 0, z + 6, Blocks.obsidian, 0, 3);
        world.setBlock(x + 7, y + 0, z + 6, Blocks.obsidian, 0, 3);
        world.setBlock(x + 8, y + 0, z + 6, Blocks.obsidian, 0, 3);
        world.setBlock(x + 9, y + 0, z + 6, Blocks.obsidian, 0, 3);
        world.setBlock(x + 10, y + 0, z + 6, Blocks.obsidian, 0, 3);
        world.setBlock(x + 11, y + 0, z + 6, Blocks.obsidian, 0, 3);
        world.setBlock(x + 12, y + 0, z + 6, Blocks.obsidian, 0, 3);
        world.setBlock(x + 13, y + 0, z + 6, Blocks.obsidian, 0, 3);
        world.setBlock(x + 14, y + 0, z + 6, Blocks.obsidian, 0, 3);
        world.setBlock(x + 15, y + 0, z + 6, Blocks.obsidian, 0, 3);
        world.setBlock(x + 16, y + 0, z + 6, Blocks.obsidian, 0, 3);
        world.setBlock(x + 17, y + 0, z + 6, Blocks.obsidian, 0, 3);
        world.setBlock(x + 18, y + 0, z + 6, Blocks.obsidian, 0, 3);
        world.setBlock(x + 19, y + 0, z + 6, Blocks.obsidian, 0, 3);
        world.setBlock(x + 20, y + 0, z + 6, Blocks.obsidian, 0, 3);
        world.setBlock(x + 21, y + 0, z + 6, Blocks.nether_brick, 0, 3);
        world.setBlock(x + 22, y + 0, z + 6, Blocks.nether_brick, 0, 3);
        world.setBlock(x + 3, y + 0, z + 7, Blocks.nether_brick, 0, 3);
        world.setBlock(x + 4, y + 0, z + 7, Blocks.obsidian, 0, 3);
        world.setBlock(x + 5, y + 0, z + 7, Blocks.obsidian, 0, 3);
        world.setBlock(x + 6, y + 0, z + 7, Blocks.obsidian, 0, 3);
        world.setBlock(x + 7, y + 0, z + 7, Blocks.obsidian, 0, 3);
        world.setBlock(x + 8, y + 0, z + 7, Blocks.obsidian, 0, 3);
        world.setBlock(x + 9, y + 0, z + 7, Blocks.obsidian, 0, 3);
        world.setBlock(x + 10, y + 0, z + 7, Blocks.obsidian, 0, 3);
        world.setBlock(x + 11, y + 0, z + 7, Blocks.obsidian, 0, 3);
        world.setBlock(x + 12, y + 0, z + 7, Blocks.obsidian, 0, 3);
        world.setBlock(x + 13, y + 0, z + 7, Blocks.obsidian, 0, 3);
        world.setBlock(x + 14, y + 0, z + 7, Blocks.obsidian, 0, 3);
        world.setBlock(x + 15, y + 0, z + 7, Blocks.obsidian, 0, 3);
        world.setBlock(x + 16, y + 0, z + 7, Blocks.obsidian, 0, 3);
        world.setBlock(x + 17, y + 0, z + 7, Blocks.obsidian, 0, 3);
        world.setBlock(x + 18, y + 0, z + 7, Blocks.obsidian, 0, 3);
        world.setBlock(x + 19, y + 0, z + 7, Blocks.obsidian, 0, 3);
        world.setBlock(x + 20, y + 0, z + 7, Blocks.obsidian, 0, 3);
        world.setBlock(x + 21, y + 0, z + 7, Blocks.nether_brick, 0, 3);
        world.setBlock(x + 4, y + 0, z + 8, Blocks.nether_brick, 0, 3);
        world.setBlock(x + 5, y + 0, z + 8, Blocks.nether_brick, 0, 3);
        world.setBlock(x + 6, y + 0, z + 8, Blocks.nether_brick, 0, 3);
        world.setBlock(x + 7, y + 0, z + 8, Blocks.nether_brick, 0, 3);
        world.setBlock(x + 8, y + 0, z + 8, Blocks.nether_brick, 0, 3);
        world.setBlock(x + 9, y + 0, z + 8, Blocks.nether_brick, 0, 3);
        world.setBlock(x + 10, y + 0, z + 8, Blocks.nether_brick, 0, 3);
        world.setBlock(x + 11, y + 0, z + 8, Blocks.nether_brick, 0, 3);
        world.setBlock(x + 12, y + 0, z + 8, Blocks.nether_brick, 0, 3);
        world.setBlock(x + 13, y + 0, z + 8, Blocks.nether_brick, 0, 3);
        world.setBlock(x + 14, y + 0, z + 8, Blocks.nether_brick, 0, 3);
        world.setBlock(x + 15, y + 0, z + 8, Blocks.nether_brick, 0, 3);
        world.setBlock(x + 16, y + 0, z + 8, Blocks.nether_brick, 0, 3);
        world.setBlock(x + 17, y + 0, z + 8, Blocks.nether_brick, 0, 3);
        world.setBlock(x + 18, y + 0, z + 8, Blocks.nether_brick, 0, 3);
        world.setBlock(x + 19, y + 0, z + 8, Blocks.nether_brick, 0, 3);
        world.setBlock(x + 20, y + 0, z + 8, Blocks.nether_brick, 0, 3);
        world.setBlock(x + 4, y + 1, z + 1, Blocks.nether_brick, 0, 3);
        world.setBlock(x + 5, y + 1, z + 1, Blocks.nether_brick, 0, 3);
        world.setBlock(x + 6, y + 1, z + 1, Blocks.nether_brick, 0, 3);
        world.setBlock(x + 7, y + 1, z + 1, Blocks.nether_brick, 0, 3);
        world.setBlock(x + 8, y + 1, z + 1, Blocks.nether_brick, 0, 3);
        world.setBlock(x + 9, y + 1, z + 1, Blocks.nether_brick, 0, 3);
        world.setBlock(x + 10, y + 1, z + 1, Blocks.nether_brick, 0, 3);
        world.setBlock(x + 11, y + 1, z + 1, Blocks.nether_brick, 0, 3);
        world.setBlock(x + 12, y + 1, z + 1, Blocks.nether_brick, 0, 3);
        world.setBlock(x + 13, y + 1, z + 1, Blocks.nether_brick, 0, 3);
        world.setBlock(x + 14, y + 1, z + 1, Blocks.nether_brick, 0, 3);
        world.setBlock(x + 15, y + 1, z + 1, Blocks.nether_brick, 0, 3);
        world.setBlock(x + 16, y + 1, z + 1, Blocks.nether_brick, 0, 3);
        world.setBlock(x + 17, y + 1, z + 1, Blocks.nether_brick, 0, 3);
        world.setBlock(x + 18, y + 1, z + 1, Blocks.nether_brick, 0, 3);
        world.setBlock(x + 19, y + 1, z + 1, Blocks.nether_brick, 0, 3);
        world.setBlock(x + 20, y + 1, z + 1, Blocks.nether_brick, 0, 3);
        world.setBlock(x + 3, y + 1, z + 2, Blocks.nether_brick, 0, 3);
        world.setBlock(x + 4, y + 1, z + 2, FABlockRegistry.blockSkull, 0, 3);
        world.setBlock(x + 5, y + 1, z + 2, Blocks.air, 0, 3);
        world.setBlock(x + 6, y + 1, z + 2, Blocks.air, 0, 3);
        world.setBlock(x + 7, y + 1, z + 2, Blocks.air, 0, 3);
        world.setBlock(x + 8, y + 1, z + 2, Blocks.air, 0, 3);
        world.setBlock(x + 9, y + 1, z + 2, Blocks.furnace, 3, 3);
        world.setBlock(x + 10, y + 1, z + 2, Blocks.furnace, 3, 3);
        world.setBlock(x + 11, y + 1, z + 2, Blocks.jukebox, 0, 3);
        world.setBlock(x + 12, y + 1, z + 2, Blocks.air, 0, 3);
        world.setBlock(x + 13, y + 1, z + 2, Blocks.air, 0, 3);
        world.setBlock(x + 14, y + 1, z + 2, Blocks.web, 0, 3);
        world.setBlock(x + 15, y + 1, z + 2, Blocks.iron_bars, 0, 3);
        world.setBlock(x + 16, y + 1, z + 2, Blocks.air, 0, 3);
        world.setBlock(x + 17, y + 1, z + 2, Blocks.air, 0, 3);
        world.setBlock(x + 18, y + 1, z + 2, Blocks.chest, 4, 3);
        this.generateStructureChestContents(world, rand, x + 18, y + 1, z + 2, field_111019_a, 2 + rand.nextInt(1));
        world.setBlock(x + 19, y + 1, z + 2, Blocks.iron_bars, 0, 3);
        world.setBlock(x + 20, y + 1, z + 2, Blocks.air, 0, 3);
        world.setBlock(x + 21, y + 1, z + 2, Blocks.nether_brick, 0, 3);
        world.setBlock(x + 2, y + 1, z + 3, Blocks.nether_brick, 0, 3);
        world.setBlock(x + 3, y + 1, z + 3, Blocks.air, 0, 3);
        world.setBlock(x + 4, y + 1, z + 3, Blocks.air, 0, 3);
        world.setBlock(x + 5, y + 1, z + 3, Blocks.air, 0, 3);
        world.setBlock(x + 6, y + 1, z + 3, Blocks.air, 0, 3);
        world.setBlock(x + 7, y + 1, z + 3, Blocks.air, 0, 3);
        world.setBlock(x + 8, y + 1, z + 3, Blocks.air, 0, 3);
        world.setBlock(x + 9, y + 1, z + 3, Blocks.air, 0, 3);
        world.setBlock(x + 10, y + 1, z + 3, Blocks.air, 0, 3);
        world.setBlock(x + 11, y + 1, z + 3, Blocks.air, 0, 3);
        world.setBlock(x + 12, y + 1, z + 3, Blocks.nether_brick_fence, 0, 3);
        world.setBlock(x + 13, y + 1, z + 3, Blocks.air, 0, 3);
        world.setBlock(x + 14, y + 1, z + 3, Blocks.air, 0, 3);
        world.setBlock(x + 15, y + 1, z + 3, Blocks.iron_bars, 0, 3);
        world.setBlock(x + 16, y + 1, z + 3, Blocks.air, 0, 3);
        world.setBlock(x + 17, y + 1, z + 3, Blocks.air, 0, 3);
        world.setBlock(x + 18, y + 1, z + 3, Blocks.chest, 4, 3);
        this.generateStructureChestContents(world, rand, x + 18, y + 1, z + 3, field_111019_a, 2 + rand.nextInt(1));
        world.setBlock(x + 19, y + 1, z + 3, Blocks.iron_bars, 0, 3);
        world.setBlock(x + 20, y + 1, z + 3, Blocks.air, 0, 3);
        world.setBlock(x + 21, y + 1, z + 3, Blocks.air, 0, 3);
        world.setBlock(x + 22, y + 1, z + 3, Blocks.nether_brick, 0, 3);
        world.setBlock(x + 1, y + 1, z + 4, Blocks.nether_brick, 0, 3);
        world.setBlock(x + 2, y + 1, z + 4, Blocks.air, 0, 3);
        world.setBlock(x + 3, y + 1, z + 4, Blocks.air, 0, 3);
        world.setBlock(x + 4, y + 1, z + 4, Blocks.air, 0, 3);
        world.setBlock(x + 5, y + 1, z + 4, Blocks.air, 0, 3);
        world.setBlock(x + 6, y + 1, z + 4, Blocks.chest, 4, 3);
        this.generateStructureChestContents(world, rand, x + 6, y + 1, z + 4, field_111019_a, 2 + rand.nextInt(1));
        world.setBlock(x + 7, y + 1, z + 4, Blocks.nether_brick_stairs, 1, 3);
        world.setBlock(x + 8, y + 1, z + 4, Blocks.air, 0, 3);
        world.setBlock(x + 9, y + 1, z + 4, Blocks.air, 0, 3);
        world.setBlock(x + 10, y + 1, z + 4, Blocks.air, 0, 3);
        world.setBlock(x + 11, y + 1, z + 4, Blocks.air, 0, 3);
        world.setBlock(x + 12, y + 1, z + 4, Blocks.air, 0, 3);
        world.setBlock(x + 13, y + 1, z + 4, Blocks.air, 0, 3);
        world.setBlock(x + 14, y + 1, z + 4, Blocks.air, 0, 3);
        world.setBlock(x + 15, y + 1, z + 4, Blocks.double_stone_slab, 0, 3);
        //world.setBlock(x + 16, y + 1, z + 4, Blocks.iron_door, 3, 3);
        ItemDoor.placeDoorBlock(world, x + 16, y + 1, z + 4, 3, Blocks.iron_door);
        world.setBlock(x + 17, y + 1, z + 4, Blocks.double_stone_slab, 0, 3);
        world.setBlock(x + 18, y + 1, z + 4, Blocks.iron_bars, 0, 3);
        world.setBlock(x + 19, y + 1, z + 4, Blocks.iron_bars, 0, 3);
        world.setBlock(x + 20, y + 1, z + 4, Blocks.air, 0, 3);
        world.setBlock(x + 21, y + 1, z + 4, Blocks.air, 0, 3);
        world.setBlock(x + 22, y + 1, z + 4, Blocks.air, 0, 3);
        world.setBlock(x + 23, y + 1, z + 4, Blocks.nether_brick, 0, 3);
        world.setBlock(x + 1, y + 1, z + 5, Blocks.nether_brick, 0, 3);
        world.setBlock(x + 2, y + 1, z + 5, Blocks.air, 0, 3);
        world.setBlock(x + 3, y + 1, z + 5, Blocks.air, 0, 3);
        world.setBlock(x + 4, y + 1, z + 5, Blocks.air, 0, 3);
        world.setBlock(x + 5, y + 1, z + 5, Blocks.air, 0, 3);
        world.setBlock(x + 6, y + 1, z + 5, Blocks.nether_brick_stairs, 4, 3);
        world.setBlock(x + 7, y + 1, z + 5, Blocks.nether_brick_stairs, 1, 3);
        world.setBlock(x + 8, y + 1, z + 5, Blocks.air, 0, 3);
        world.setBlock(x + 9, y + 1, z + 5, Blocks.air, 0, 3);
        world.setBlock(x + 10, y + 1, z + 5, Blocks.air, 0, 3);
        world.setBlock(x + 11, y + 1, z + 5, Blocks.air, 0, 3);
        world.setBlock(x + 12, y + 1, z + 5, Blocks.air, 0, 3);
        world.setBlock(x + 13, y + 1, z + 5, Blocks.air, 0, 3);
        world.setBlock(x + 14, y + 1, z + 5, Blocks.air, 0, 3);
        world.setBlock(x + 15, y + 1, z + 5, Blocks.air, 0, 3);
        world.setBlock(x + 16, y + 1, z + 5, Blocks.air, 0, 3);
        world.setBlock(x + 17, y + 1, z + 5, Blocks.air, 0, 3);
        world.setBlock(x + 18, y + 1, z + 5, Blocks.air, 0, 3);
        world.setBlock(x + 19, y + 1, z + 5, Blocks.air, 0, 3);
        world.setBlock(x + 20, y + 1, z + 5, Blocks.air, 0, 3);
        world.setBlock(x + 21, y + 1, z + 5, Blocks.air, 0, 3);
        world.setBlock(x + 22, y + 1, z + 5, Blocks.air, 0, 3);
        world.setBlock(x + 23, y + 1, z + 5, Blocks.nether_brick_fence, 0, 3);
        world.setBlock(x + 24, y + 1, z + 5, Blocks.nether_brick, 0, 3);
        world.setBlock(x + 25, y + 1, z + 5, Blocks.nether_brick, 0, 3);
        world.setBlock(x + 1, y + 1, z + 6, Blocks.nether_brick, 0, 3);
        world.setBlock(x + 2, y + 1, z + 6, Blocks.web, 0, 3);
        world.setBlock(x + 3, y + 1, z + 6, Blocks.air, 0, 3);
        world.setBlock(x + 4, y + 1, z + 6, Blocks.air, 0, 3);
        world.setBlock(x + 5, y + 1, z + 6, Blocks.air, 0, 3);
        world.setBlock(x + 6, y + 1, z + 6, Blocks.chest, 4, 3);
        this.generateStructureChestContents(world, rand, x + 6, y + 1, z + 6, field_111019_a, 2 + rand.nextInt(1));
        world.setBlock(x + 7, y + 1, z + 6, Blocks.nether_brick_stairs, 1, 3);
        world.setBlock(x + 8, y + 1, z + 6, Blocks.air, 0, 3);
        world.setBlock(x + 9, y + 1, z + 6, Blocks.air, 0, 3);
        world.setBlock(x + 10, y + 1, z + 6, Blocks.air, 0, 3);
        world.setBlock(x + 11, y + 1, z + 6, Blocks.air, 0, 3);
        world.setBlock(x + 12, y + 1, z + 6, Blocks.nether_brick_fence, 0, 3);
        world.setBlock(x + 13, y + 1, z + 6, Blocks.air, 0, 3);
        world.setBlock(x + 14, y + 1, z + 6, Blocks.air, 0, 3);
        world.setBlock(x + 15, y + 1, z + 6, Blocks.double_stone_slab, 0, 3);
        //world.setBlock(x + 16, y + 1, z + 6, Blocks.iron_door, 1, 3);
        ItemDoor.placeDoorBlock(world, x + 16, y + 1, z + 6, 3, Blocks.iron_door);
        world.setBlock(x + 17, y + 1, z + 6, Blocks.double_stone_slab, 0, 3);
        world.setBlock(x + 18, y + 1, z + 6, Blocks.iron_bars, 0, 3);
        world.setBlock(x + 19, y + 1, z + 6, Blocks.iron_bars, 0, 3);
        world.setBlock(x + 20, y + 1, z + 6, Blocks.air, 0, 3);
        world.setBlock(x + 21, y + 1, z + 6, Blocks.air, 0, 3);
        world.setBlock(x + 22, y + 1, z + 6, Blocks.chest, 4, 3);//
        this.generateStructureChestContents(world, rand, x + 22, y + 1, z + 6, field_111019_a, 2 + rand.nextInt(1));
        world.setBlock(x + 23, y + 1, z + 6, Blocks.nether_brick, 0, 3);
        world.setBlock(x + 2, y + 1, z + 7, Blocks.nether_brick, 0, 3);
        world.setBlock(x + 3, y + 1, z + 7, Blocks.air, 0, 3);
        world.setBlock(x + 4, y + 1, z + 7, Blocks.air, 0, 3);
        world.setBlock(x + 5, y + 1, z + 7, Blocks.air, 0, 3);
        world.setBlock(x + 6, y + 1, z + 7, Blocks.air, 0, 3);
        world.setBlock(x + 7, y + 1, z + 7, Blocks.air, 0, 3);
        world.setBlock(x + 8, y + 1, z + 7, Blocks.air, 0, 3);
        world.setBlock(x + 9, y + 1, z + 7, Blocks.air, 0, 3);
        world.setBlock(x + 10, y + 1, z + 7, Blocks.air, 0, 3);
        world.setBlock(x + 12, y + 1, z + 7, Blocks.air, 0, 3);
        world.setBlock(x + 13, y + 1, z + 7, Blocks.air, 0, 3);
        world.setBlock(x + 14, y + 1, z + 7, Blocks.air, 0, 3);
        world.setBlock(x + 15, y + 1, z + 7, Blocks.iron_bars, 0, 3);
        world.setBlock(x + 16, y + 1, z + 7, Blocks.air, 0, 3);
        world.setBlock(x + 17, y + 1, z + 7, Blocks.air, 0, 3);
        world.setBlock(x + 19, y + 1, z + 7, Blocks.iron_bars, 0, 3);
        world.setBlock(x + 20, y + 1, z + 7, Blocks.air, 0, 3);
        world.setBlock(x + 21, y + 1, z + 7, Blocks.air, 0, 3);
        world.setBlock(x + 22, y + 1, z + 7, Blocks.nether_brick, 0, 3);
        world.setBlock(x + 3, y + 1, z + 8, Blocks.nether_brick, 0, 3);
        world.setBlock(x + 4, y + 1, z + 8, Blocks.anvil, 4, 3);
        world.setBlock(x + 5, y + 1, z + 8, Blocks.air, 0, 3);
        world.setBlock(x + 6, y + 1, z + 8, Blocks.air, 0, 3);
        world.setBlock(x + 7, y + 1, z + 8, Blocks.air, 0, 3);
        world.setBlock(x + 8, y + 1, z + 8, Blocks.air, 0, 3);
        world.setBlock(x + 9, y + 1, z + 8, Blocks.furnace, 2, 3);
        world.setBlock(x + 10, y + 1, z + 8, Blocks.furnace, 2, 3);
        world.setBlock(x + 11, y + 1, z + 8, Blocks.chest, 2, 3);//
        this.generateStructureChestContents(world, rand, x + 11, y + 1, z + 8, field_111019_a, 2 + rand.nextInt(1));
        world.setBlock(x + 11, y + 1, z + 7, Blocks.air, 2, 3);
        world.setBlock(x + 12, y + 1, z + 8, Blocks.air, 0, 3);
        world.setBlock(x + 13, y + 1, z + 8, Blocks.air, 0, 3);
        world.setBlock(x + 14, y + 1, z + 8, Blocks.air, 0, 3);
        world.setBlock(x + 15, y + 1, z + 8, Blocks.iron_bars, 0, 3);
        world.setBlock(x + 16, y + 1, z + 8, Blocks.air, 0, 3);
        world.setBlock(x + 17, y + 1, z + 8, Blocks.air, 0, 3);
        world.setBlock(x + 18, y + 1, z + 8, Blocks.chest, 2, 3);
        this.generateStructureChestContents(world, rand, x + 18, y + 1, z + 8, field_111019_a, 2 + rand.nextInt(1));
        world.setBlock(x + 18, y + 1, z + 7, Blocks.air, 2, 3);
        world.setBlock(x + 19, y + 1, z + 8, Blocks.iron_bars, 0, 3);
        world.setBlock(x + 20, y + 1, z + 8, Blocks.web, 0, 3);
        world.setBlock(x + 21, y + 1, z + 8, Blocks.nether_brick, 0, 3);
        world.setBlock(x + 4, y + 1, z + 9, Blocks.nether_brick, 0, 3);
        world.setBlock(x + 5, y + 1, z + 9, Blocks.nether_brick, 0, 3);
        world.setBlock(x + 6, y + 1, z + 9, Blocks.nether_brick, 0, 3);
        world.setBlock(x + 7, y + 1, z + 9, Blocks.nether_brick, 0, 3);
        world.setBlock(x + 8, y + 1, z + 9, Blocks.nether_brick, 0, 3);
        world.setBlock(x + 9, y + 1, z + 9, Blocks.nether_brick, 0, 3);
        world.setBlock(x + 10, y + 1, z + 9, Blocks.nether_brick, 0, 3);
        world.setBlock(x + 11, y + 1, z + 9, Blocks.nether_brick, 0, 3);
        world.setBlock(x + 12, y + 1, z + 9, Blocks.nether_brick, 0, 3);
        world.setBlock(x + 13, y + 1, z + 9, Blocks.nether_brick, 0, 3);
        world.setBlock(x + 14, y + 1, z + 9, Blocks.nether_brick, 0, 3);
        world.setBlock(x + 15, y + 1, z + 9, Blocks.nether_brick, 0, 3);
        world.setBlock(x + 16, y + 1, z + 9, Blocks.nether_brick, 0, 3);
        world.setBlock(x + 17, y + 1, z + 9, Blocks.nether_brick, 0, 3);
        world.setBlock(x + 18, y + 1, z + 9, Blocks.nether_brick, 0, 3);
        world.setBlock(x + 19, y + 1, z + 9, Blocks.nether_brick, 0, 3);
        world.setBlock(x + 20, y + 1, z + 9, Blocks.nether_brick, 0, 3);
        world.setBlock(x + 3, y + 2, z + 1, Blocks.nether_brick_stairs, 4, 3);
        world.setBlock(x + 4, y + 2, z + 1, Blocks.nether_brick, 0, 3);
        world.setBlock(x + 5, y + 2, z + 1, Blocks.nether_brick, 0, 3);
        world.setBlock(x + 6, y + 2, z + 1, Blocks.nether_brick, 0, 3);
        world.setBlock(x + 7, y + 2, z + 1, Blocks.nether_brick, 0, 3);
        world.setBlock(x + 8, y + 2, z + 1, Blocks.nether_brick, 0, 3);
        world.setBlock(x + 9, y + 2, z + 1, FABlockRegistry.ancientGlass, 0, 3);
        world.setBlock(x + 10, y + 2, z + 1, FABlockRegistry.ancientGlass, 0, 3);
        world.setBlock(x + 11, y + 2, z + 1, FABlockRegistry.ancientGlass, 0, 3);
        world.setBlock(x + 12, y + 2, z + 1, FABlockRegistry.ancientGlass, 0, 3);
        world.setBlock(x + 13, y + 2, z + 1, Blocks.nether_brick, 0, 3);
        world.setBlock(x + 14, y + 2, z + 1, Blocks.nether_brick, 0, 3);
        world.setBlock(x + 15, y + 2, z + 1, Blocks.nether_brick, 0, 3);
        world.setBlock(x + 16, y + 2, z + 1, Blocks.nether_brick, 0, 3);
        world.setBlock(x + 17, y + 2, z + 1, Blocks.nether_brick, 0, 3);
        world.setBlock(x + 18, y + 2, z + 1, Blocks.nether_brick, 0, 3);
        world.setBlock(x + 19, y + 2, z + 1, Blocks.nether_brick, 0, 3);
        world.setBlock(x + 20, y + 2, z + 1, Blocks.nether_brick, 0, 3);
        world.setBlock(x + 21, y + 2, z + 1, Blocks.nether_brick_stairs, 5, 3);
        world.setBlock(x + 2, y + 2, z + 2, Blocks.nether_brick_stairs, 4, 3);
        world.setBlock(x + 3, y + 2, z + 2, Blocks.nether_brick, 0, 3);
        world.setBlock(x + 4, y + 2, z + 2, Blocks.air, 0, 3);
        world.setBlock(x + 5, y + 2, z + 2, Blocks.air, 0, 3);
        world.setBlock(x + 6, y + 2, z + 2, Blocks.air, 0, 3);
        world.setBlock(x + 7, y + 2, z + 2, Blocks.air, 0, 3);
        world.setBlock(x + 8, y + 2, z + 2, Blocks.air, 0, 3);
        world.setBlock(x + 9, y + 2, z + 2, Blocks.air, 0, 3);
        world.setBlock(x + 10, y + 2, z + 2, Blocks.air, 0, 3);
        world.setBlock(x + 11, y + 2, z + 2, Blocks.air, 0, 3);
        world.setBlock(x + 12, y + 2, z + 2, Blocks.air, 0, 3);
        world.setBlock(x + 13, y + 2, z + 2, Blocks.air, 0, 3);
        world.setBlock(x + 14, y + 2, z + 2, Blocks.air, 0, 3);
        world.setBlock(x + 15, y + 2, z + 2, Blocks.iron_bars, 0, 3);
        world.setBlock(x + 16, y + 2, z + 2, Blocks.air, 0, 3);
        world.setBlock(x + 17, y + 2, z + 2, Blocks.air, 0, 3);
        world.setBlock(x + 18, y + 2, z + 2, Blocks.air, 0, 3);
        world.setBlock(x + 19, y + 2, z + 2, Blocks.iron_bars, 0, 3);
        world.setBlock(x + 20, y + 2, z + 2, Blocks.air, 0, 3);
        world.setBlock(x + 21, y + 2, z + 2, Blocks.nether_brick, 0, 3);
        world.setBlock(x + 22, y + 2, z + 2, Blocks.nether_brick_stairs, 5, 3);
        world.setBlock(x + 1, y + 2, z + 3, Blocks.nether_brick_stairs, 4, 3);
        world.setBlock(x + 2, y + 2, z + 3, Blocks.nether_brick, 0, 3);
        world.setBlock(x + 3, y + 2, z + 3, Blocks.air, 0, 3);
        world.setBlock(x + 4, y + 2, z + 3, Blocks.air, 0, 3);
        world.setBlock(x + 5, y + 2, z + 3, Blocks.air, 0, 3);
        world.setBlock(x + 6, y + 2, z + 3, Blocks.air, 0, 3);
        world.setBlock(x + 7, y + 2, z + 3, Blocks.air, 0, 3);
        world.setBlock(x + 8, y + 2, z + 3, Blocks.air, 0, 3);
        world.setBlock(x + 9, y + 2, z + 3, Blocks.air, 0, 3);
        world.setBlock(x + 10, y + 2, z + 3, Blocks.air, 0, 3);
        world.setBlock(x + 11, y + 2, z + 3, Blocks.air, 0, 3);
        world.setBlock(x + 12, y + 2, z + 3, FABlockRegistry.skullLantern, 1, 3);
        world.setBlock(x + 13, y + 2, z + 3, Blocks.air, 0, 3);
        world.setBlock(x + 14, y + 2, z + 3, Blocks.air, 0, 3);
        world.setBlock(x + 15, y + 2, z + 3, Blocks.iron_bars, 0, 3);
        world.setBlock(x + 16, y + 2, z + 3, Blocks.air, 0, 3);
        world.setBlock(x + 17, y + 2, z + 3, Blocks.air, 0, 3);
        world.setBlock(x + 18, y + 2, z + 3, Blocks.air, 0, 3);
        world.setBlock(x + 19, y + 2, z + 3, Blocks.iron_bars, 0, 3);
        world.setBlock(x + 20, y + 2, z + 3, Blocks.air, 0, 3);
        world.setBlock(x + 21, y + 2, z + 3, Blocks.air, 0, 3);
        world.setBlock(x + 22, y + 2, z + 3, Blocks.nether_brick, 0, 3);
        world.setBlock(x + 23, y + 2, z + 3, Blocks.nether_brick_stairs, 5, 3);
        world.setBlock(x + 1, y + 2, z + 4, Blocks.nether_brick, 0, 3);
        world.setBlock(x + 3, y + 2, z + 4, Blocks.air, 0, 3);
        world.setBlock(x + 4, y + 2, z + 4, Blocks.air, 0, 3);
        world.setBlock(x + 5, y + 2, z + 4, Blocks.nether_brick_stairs, 4, 3);
        world.setBlock(x + 6, y + 2, z + 4, Blocks.nether_brick_stairs, 1, 3);
        world.setBlock(x + 7, y + 2, z + 4, Blocks.air, 0, 3);
        world.setBlock(x + 8, y + 2, z + 4, Blocks.air, 0, 3);
        world.setBlock(x + 9, y + 2, z + 4, Blocks.air, 0, 3);
        world.setBlock(x + 10, y + 2, z + 4, Blocks.air, 0, 3);
        world.setBlock(x + 11, y + 2, z + 4, Blocks.air, 0, 3);
        world.setBlock(x + 12, y + 2, z + 4, Blocks.air, 0, 3);
        world.setBlock(x + 13, y + 2, z + 4, Blocks.air, 0, 3);
        world.setBlock(x + 14, y + 2, z + 4, Blocks.air, 0, 3);
        world.setBlock(x + 15, y + 2, z + 4, Blocks.double_stone_slab, 0, 3);
        world.setBlock(x + 17, y + 2, z + 4, Blocks.double_stone_slab, 0, 3);
        world.setBlock(x + 18, y + 2, z + 4, Blocks.iron_bars, 0, 3);
        world.setBlock(x + 19, y + 2, z + 4, Blocks.iron_bars, 0, 3);
        world.setBlock(x + 20, y + 2, z + 4, Blocks.air, 0, 3);
        world.setBlock(x + 21, y + 2, z + 4, Blocks.air, 0, 3);
        world.setBlock(x + 22, y + 2, z + 4, Blocks.air, 0, 3);
        world.setBlock(x + 23, y + 2, z + 4, Blocks.nether_brick, 0, 3);
        world.setBlock(x + 24, y + 2, z + 4, Blocks.nether_brick_stairs, 5, 3);
        world.setBlock(x + 1, y + 2, z + 5, Blocks.nether_brick, 0, 3);
        world.setBlock(x + 2, y + 2, z + 5, Blocks.air, 0, 3);
        world.setBlock(x + 3, y + 2, z + 5, Blocks.air, 0, 3);
        world.setBlock(x + 4, y + 2, z + 5, Blocks.air, 0, 3);
        world.setBlock(x + 5, y + 2, z + 5, Blocks.nether_brick_stairs, 4, 3);
        world.setBlock(x + 6, y + 2, z + 5, Blocks.nether_brick_stairs, 1, 3);
        world.setBlock(x + 7, y + 2, z + 5, Blocks.air, 0, 3);
        world.setBlock(x + 8, y + 2, z + 5, Blocks.air, 0, 3);
        world.setBlock(x + 9, y + 2, z + 5, Blocks.air, 0, 3);
        world.setBlock(x + 10, y + 2, z + 5, Blocks.air, 0, 3);
        world.setBlock(x + 11, y + 2, z + 5, Blocks.air, 0, 3);
        world.setBlock(x + 12, y + 2, z + 5, Blocks.air, 0, 3);
        world.setBlock(x + 13, y + 2, z + 5, Blocks.air, 0, 3);
        world.setBlock(x + 14, y + 2, z + 5, Blocks.air, 0, 3);
        world.setBlock(x + 15, y + 2, z + 5, Blocks.air, 0, 3);
        world.setBlock(x + 16, y + 2, z + 5, Blocks.air, 0, 3);
        world.setBlock(x + 17, y + 2, z + 5, Blocks.air, 0, 3);
        world.setBlock(x + 18, y + 2, z + 5, Blocks.air, 0, 3);
        world.setBlock(x + 19, y + 2, z + 5, Blocks.air, 0, 3);
        world.setBlock(x + 20, y + 2, z + 5, Blocks.air, 0, 3);
        world.setBlock(x + 21, y + 2, z + 5, Blocks.air, 0, 3);
        world.setBlock(x + 22, y + 2, z + 5, Blocks.air, 0, 3);
        world.setBlock(x + 23, y + 2, z + 5, FABlockRegistry.skullLantern, 1, 3);
        world.setBlock(x + 24, y + 2, z + 5, Blocks.nether_brick, 0, 3);
        world.setBlock(x + 25, y + 2, z + 5, Blocks.nether_brick, 0, 3);
        world.setBlock(x + 26, y + 2, z + 5, Blocks.nether_brick, 0, 3);
        world.setBlock(x + 27, y + 2, z + 5, Blocks.nether_brick, 0, 3);
        world.setBlock(x + 1, y + 2, z + 6, Blocks.nether_brick, 0, 3);
        world.setBlock(x + 3, y + 2, z + 6, Blocks.air, 0, 3);
        world.setBlock(x + 4, y + 2, z + 6, Blocks.air, 0, 3);
        world.setBlock(x + 5, y + 2, z + 6, Blocks.nether_brick_stairs, 4, 3);
        world.setBlock(x + 6, y + 2, z + 6, Blocks.nether_brick_stairs, 1, 3);
        world.setBlock(x + 7, y + 2, z + 6, Blocks.air, 0, 3);
        world.setBlock(x + 8, y + 2, z + 6, Blocks.air, 0, 3);
        world.setBlock(x + 9, y + 2, z + 6, Blocks.air, 0, 3);
        world.setBlock(x + 10, y + 2, z + 6, Blocks.air, 0, 3);
        world.setBlock(x + 11, y + 2, z + 6, Blocks.air, 0, 3);
        world.setBlock(x + 12, y + 2, z + 6, FABlockRegistry.skullLantern, 1, 3);
        world.setBlock(x + 13, y + 2, z + 6, Blocks.air, 0, 3);
        world.setBlock(x + 14, y + 2, z + 6, Blocks.air, 0, 3);
        world.setBlock(x + 15, y + 2, z + 6, Blocks.double_stone_slab, 0, 3);
        world.setBlock(x + 17, y + 2, z + 6, Blocks.double_stone_slab, 0, 3);
        world.setBlock(x + 18, y + 2, z + 6, Blocks.iron_bars, 0, 3);
        world.setBlock(x + 19, y + 2, z + 6, Blocks.iron_bars, 0, 3);
        world.setBlock(x + 20, y + 2, z + 6, Blocks.air, 0, 3);
        world.setBlock(x + 21, y + 2, z + 6, Blocks.air, 0, 3);
        world.setBlock(x + 22, y + 2, z + 6, Blocks.air, 0, 3);
        world.setBlock(x + 23, y + 2, z + 6, Blocks.nether_brick, 0, 3);
        world.setBlock(x + 24, y + 2, z + 6, Blocks.nether_brick_stairs, 5, 3);
        world.setBlock(x + 1, y + 2, z + 7, Blocks.nether_brick_stairs, 4, 3);
        world.setBlock(x + 2, y + 2, z + 7, Blocks.nether_brick, 0, 3);
        world.setBlock(x + 3, y + 2, z + 7, Blocks.air, 0, 3);
        world.setBlock(x + 4, y + 2, z + 7, Blocks.air, 0, 3);
        world.setBlock(x + 5, y + 2, z + 7, Blocks.air, 0, 3);
        world.setBlock(x + 6, y + 2, z + 7, Blocks.air, 0, 3);
        world.setBlock(x + 7, y + 2, z + 7, Blocks.air, 0, 3);
        world.setBlock(x + 8, y + 2, z + 7, Blocks.air, 0, 3);
        world.setBlock(x + 9, y + 2, z + 7, Blocks.air, 0, 3);
        world.setBlock(x + 10, y + 2, z + 7, Blocks.air, 0, 3);
        world.setBlock(x + 11, y + 2, z + 7, Blocks.air, 0, 3);
        world.setBlock(x + 12, y + 2, z + 7, Blocks.air, 0, 3);
        world.setBlock(x + 13, y + 2, z + 7, Blocks.air, 0, 3);
        world.setBlock(x + 14, y + 2, z + 7, Blocks.air, 0, 3);
        world.setBlock(x + 15, y + 2, z + 7, Blocks.iron_bars, 0, 3);
        world.setBlock(x + 16, y + 2, z + 7, Blocks.air, 0, 3);
        world.setBlock(x + 17, y + 2, z + 7, Blocks.air, 0, 3);
        world.setBlock(x + 18, y + 2, z + 7, Blocks.air, 0, 3);
        world.setBlock(x + 19, y + 2, z + 7, Blocks.iron_bars, 0, 3);
        world.setBlock(x + 20, y + 2, z + 7, Blocks.air, 0, 3);
        world.setBlock(x + 21, y + 2, z + 7, Blocks.air, 0, 3);
        world.setBlock(x + 22, y + 2, z + 7, Blocks.nether_brick, 0, 3);
        world.setBlock(x + 23, y + 2, z + 7, Blocks.nether_brick_stairs, 5, 3);
        world.setBlock(x + 2, y + 2, z + 8, Blocks.nether_brick_stairs, 4, 3);
        world.setBlock(x + 3, y + 2, z + 8, Blocks.nether_brick, 0, 3);
        world.setBlock(x + 4, y + 2, z + 8, Blocks.air, 0, 3);
        world.setBlock(x + 5, y + 2, z + 8, Blocks.air, 0, 3);
        world.setBlock(x + 6, y + 2, z + 8, Blocks.air, 0, 3);
        world.setBlock(x + 7, y + 2, z + 8, Blocks.air, 0, 3);
        world.setBlock(x + 8, y + 2, z + 8, Blocks.air, 0, 3);
        world.setBlock(x + 9, y + 2, z + 8, Blocks.air, 0, 3);
        world.setBlock(x + 10, y + 2, z + 8, Blocks.air, 0, 3);
        world.setBlock(x + 11, y + 2, z + 8, Blocks.air, 0, 3);
        world.setBlock(x + 12, y + 2, z + 8, Blocks.air, 0, 3);
        world.setBlock(x + 13, y + 2, z + 8, Blocks.air, 0, 3);
        world.setBlock(x + 14, y + 2, z + 8, Blocks.air, 0, 3);
        world.setBlock(x + 15, y + 2, z + 8, Blocks.iron_bars, 0, 3);
        world.setBlock(x + 16, y + 2, z + 8, Blocks.air, 0, 3);
        world.setBlock(x + 17, y + 2, z + 8, Blocks.air, 0, 3);
        world.setBlock(x + 18, y + 2, z + 8, Blocks.air, 0, 3);
        world.setBlock(x + 19, y + 2, z + 8, Blocks.iron_bars, 0, 3);
        world.setBlock(x + 20, y + 2, z + 8, Blocks.air, 0, 3);
        world.setBlock(x + 21, y + 2, z + 8, Blocks.nether_brick, 0, 3);
        world.setBlock(x + 22, y + 2, z + 8, Blocks.nether_brick_stairs, 5, 3);
        world.setBlock(x + 3, y + 2, z + 9, Blocks.nether_brick_stairs, 4, 3);
        world.setBlock(x + 4, y + 2, z + 9, Blocks.nether_brick, 0, 3);
        world.setBlock(x + 5, y + 2, z + 9, Blocks.nether_brick, 0, 3);
        world.setBlock(x + 6, y + 2, z + 9, Blocks.nether_brick, 0, 3);
        world.setBlock(x + 7, y + 2, z + 9, Blocks.nether_brick, 0, 3);
        world.setBlock(x + 8, y + 2, z + 9, Blocks.nether_brick, 0, 3);
        world.setBlock(x + 9, y + 2, z + 9, FABlockRegistry.ancientGlass, 0, 3);
        world.setBlock(x + 10, y + 2, z + 9, FABlockRegistry.ancientGlass, 0, 3);
        world.setBlock(x + 11, y + 2, z + 9, FABlockRegistry.ancientGlass, 0, 3);
        world.setBlock(x + 12, y + 2, z + 9, FABlockRegistry.ancientGlass, 0, 3);
        world.setBlock(x + 13, y + 2, z + 9, Blocks.nether_brick, 0, 3);
        world.setBlock(x + 14, y + 2, z + 9, Blocks.nether_brick, 0, 3);
        world.setBlock(x + 15, y + 2, z + 9, Blocks.nether_brick, 0, 3);
        world.setBlock(x + 16, y + 2, z + 9, Blocks.nether_brick, 0, 3);
        world.setBlock(x + 17, y + 2, z + 9, Blocks.nether_brick, 0, 3);
        world.setBlock(x + 18, y + 2, z + 9, Blocks.nether_brick, 0, 3);
        world.setBlock(x + 19, y + 2, z + 9, Blocks.nether_brick, 0, 3);
        world.setBlock(x + 20, y + 2, z + 9, Blocks.nether_brick, 0, 3);
        world.setBlock(x + 21, y + 2, z + 9, Blocks.nether_brick_stairs, 5, 3);
        world.setBlock(x + 3, y + 3, z + 1, Blocks.nether_brick_stairs, 0, 3);
        world.setBlock(x + 4, y + 3, z + 1, Blocks.nether_brick_stairs, 2, 3);
        world.setBlock(x + 5, y + 3, z + 1, Blocks.nether_brick_stairs, 2, 3);
        world.setBlock(x + 6, y + 3, z + 1, Blocks.nether_brick_stairs, 2, 3);
        world.setBlock(x + 7, y + 3, z + 1, Blocks.nether_brick_stairs, 2, 3);
        world.setBlock(x + 8, y + 3, z + 1, Blocks.nether_brick_stairs, 2, 3);
        world.setBlock(x + 9, y + 3, z + 1, Blocks.nether_brick_stairs, 2, 3);
        world.setBlock(x + 10, y + 3, z + 1, Blocks.nether_brick_stairs, 2, 3);
        world.setBlock(x + 11, y + 3, z + 1, Blocks.nether_brick_stairs, 2, 3);
        world.setBlock(x + 12, y + 3, z + 1, Blocks.nether_brick_stairs, 2, 3);
        world.setBlock(x + 13, y + 3, z + 1, Blocks.nether_brick_stairs, 2, 3);
        world.setBlock(x + 14, y + 3, z + 1, Blocks.nether_brick_stairs, 2, 3);
        world.setBlock(x + 15, y + 3, z + 1, Blocks.nether_brick_stairs, 2, 3);
        world.setBlock(x + 16, y + 3, z + 1, Blocks.nether_brick_stairs, 2, 3);
        world.setBlock(x + 17, y + 3, z + 1, Blocks.nether_brick_stairs, 2, 3);
        world.setBlock(x + 18, y + 3, z + 1, Blocks.nether_brick_stairs, 2, 3);
        world.setBlock(x + 19, y + 3, z + 1, Blocks.nether_brick_stairs, 2, 3);
        world.setBlock(x + 20, y + 3, z + 1, Blocks.nether_brick_stairs, 2, 3);
        world.setBlock(x + 21, y + 3, z + 1, Blocks.nether_brick_stairs, 2, 3);
        world.setBlock(x + 2, y + 3, z + 2, Blocks.nether_brick_stairs, 0, 3);
        world.setBlock(x + 3, y + 3, z + 2, Blocks.nether_brick_stairs, 2, 3);
        world.setBlock(x + 4, y + 3, z + 2, Blocks.stone_slab, 14, 3);
        world.setBlock(x + 5, y + 3, z + 2, Blocks.stone_slab, 14, 3);
        world.setBlock(x + 6, y + 3, z + 2, Blocks.stone_slab, 14, 3);
        world.setBlock(x + 7, y + 3, z + 2, Blocks.stone_slab, 14, 3);
        world.setBlock(x + 8, y + 3, z + 2, Blocks.stone_slab, 14, 3);
        world.setBlock(x + 9, y + 3, z + 2, Blocks.stone_slab, 14, 3);
        world.setBlock(x + 10, y + 3, z + 2, Blocks.stone_slab, 14, 3);
        world.setBlock(x + 11, y + 3, z + 2, Blocks.stone_slab, 14, 3);
        world.setBlock(x + 12, y + 3, z + 2, Blocks.stone_slab, 14, 3);
        world.setBlock(x + 13, y + 3, z + 2, Blocks.stone_slab, 14, 3);
        world.setBlock(x + 14, y + 3, z + 2, Blocks.stone_slab, 14, 3);
        world.setBlock(x + 15, y + 3, z + 2, Blocks.nether_brick, 0, 3);
        world.setBlock(x + 16, y + 3, z + 2, Blocks.stone_slab, 14, 3);
        world.setBlock(x + 17, y + 3, z + 2, Blocks.stone_slab, 14, 3);
        world.setBlock(x + 18, y + 3, z + 2, Blocks.stone_slab, 14, 3);
        world.setBlock(x + 19, y + 3, z + 2, Blocks.nether_brick, 0, 3);
        world.setBlock(x + 20, y + 3, z + 2, Blocks.stone_slab, 14, 3);
        world.setBlock(x + 21, y + 3, z + 2, Blocks.nether_brick_stairs, 1, 3);
        world.setBlock(x + 22, y + 3, z + 2, Blocks.nether_brick_stairs, 2, 3);
        world.setBlock(x + 1, y + 3, z + 3, Blocks.nether_brick_stairs, 0, 3);
        world.setBlock(x + 2, y + 3, z + 3, Blocks.nether_brick_stairs, 2, 3);
        world.setBlock(x + 3, y + 3, z + 3, Blocks.stone_slab, 14, 3);
        world.setBlock(x + 4, y + 3, z + 3, Blocks.stone_slab, 14, 3);
        world.setBlock(x + 5, y + 3, z + 3, Blocks.stone_slab, 14, 3);
        world.setBlock(x + 6, y + 3, z + 3, Blocks.stone_slab, 14, 3);
        world.setBlock(x + 7, y + 3, z + 3, Blocks.stone_slab, 14, 3);
        world.setBlock(x + 8, y + 3, z + 3, Blocks.stone_slab, 14, 3);
        world.setBlock(x + 9, y + 3, z + 3, Blocks.stone_slab, 14, 3);
        world.setBlock(x + 10, y + 3, z + 3, Blocks.stone_slab, 14, 3);
        world.setBlock(x + 11, y + 3, z + 3, Blocks.stone_slab, 14, 3);
        world.setBlock(x + 12, y + 3, z + 3, Blocks.stone_slab, 14, 3);
        world.setBlock(x + 13, y + 3, z + 3, Blocks.stone_slab, 14, 3);
        world.setBlock(x + 14, y + 3, z + 3, Blocks.stone_slab, 14, 3);
        world.setBlock(x + 15, y + 3, z + 3, Blocks.nether_brick, 0, 3);
        world.setBlock(x + 16, y + 3, z + 3, Blocks.stone_slab, 14, 3);
        world.setBlock(x + 17, y + 3, z + 3, Blocks.stone_slab, 14, 3);
        world.setBlock(x + 18, y + 3, z + 3, Blocks.stone_slab, 14, 3);
        world.setBlock(x + 19, y + 3, z + 3, Blocks.nether_brick, 0, 3);
        world.setBlock(x + 20, y + 3, z + 3, Blocks.stone_slab, 14, 3);
        world.setBlock(x + 21, y + 3, z + 3, Blocks.stone_slab, 14, 3);
        world.setBlock(x + 22, y + 3, z + 3, Blocks.nether_brick_stairs, 1, 3);
        world.setBlock(x + 23, y + 3, z + 3, Blocks.nether_brick_stairs, 2, 3);
        world.setBlock(x + 1, y + 3, z + 4, Blocks.nether_brick_stairs, 0, 3);
        world.setBlock(x + 2, y + 3, z + 4, Blocks.stone_slab, 14, 3);
        world.setBlock(x + 3, y + 3, z + 4, Blocks.stone_slab, 14, 3);
        world.setBlock(x + 4, y + 3, z + 4, Blocks.stone_slab, 14, 3);
        world.setBlock(x + 5, y + 3, z + 4, Blocks.nether_brick_stairs, 1, 3);
        world.setBlock(x + 6, y + 3, z + 4, Blocks.air, 0, 3);
        world.setBlock(x + 7, y + 3, z + 4, Blocks.air, 0, 3);
        world.setBlock(x + 8, y + 3, z + 4, Blocks.air, 0, 3);
        world.setBlock(x + 9, y + 3, z + 4, Blocks.stone_slab, 14, 3);
        world.setBlock(x + 10, y + 3, z + 4, Blocks.stone_slab, 14, 3);
        world.setBlock(x + 11, y + 3, z + 4, Blocks.stone_slab, 14, 3);
        world.setBlock(x + 12, y + 3, z + 4, Blocks.stone_slab, 14, 3);
        world.setBlock(x + 13, y + 3, z + 4, Blocks.stone_slab, 14, 3);
        world.setBlock(x + 14, y + 3, z + 4, Blocks.stone_slab, 14, 3);
        world.setBlock(x + 15, y + 3, z + 4, Blocks.nether_brick, 0, 3);
        world.setBlock(x + 16, y + 3, z + 4, Blocks.nether_brick, 0, 3);
        world.setBlock(x + 17, y + 3, z + 4, Blocks.nether_brick, 0, 3);
        world.setBlock(x + 18, y + 3, z + 4, Blocks.nether_brick, 0, 3);
        world.setBlock(x + 19, y + 3, z + 4, Blocks.nether_brick, 0, 3);
        world.setBlock(x + 20, y + 3, z + 4, Blocks.stone_slab, 14, 3);
        world.setBlock(x + 21, y + 3, z + 4, Blocks.stone_slab, 14, 3);
        world.setBlock(x + 22, y + 3, z + 4, Blocks.stone_slab, 14, 3);
        world.setBlock(x + 23, y + 3, z + 4, Blocks.nether_brick_stairs, 1, 3);
        world.setBlock(x + 24, y + 3, z + 4, Blocks.nether_brick_stairs, 2, 3);
        world.setBlock(x + 1, y + 3, z + 5, Blocks.nether_brick_stairs, 0, 3);
        world.setBlock(x + 2, y + 3, z + 5, Blocks.stone_slab, 14, 3);
        world.setBlock(x + 3, y + 3, z + 5, Blocks.stone_slab, 14, 3);
        world.setBlock(x + 4, y + 3, z + 5, Blocks.stone_slab, 14, 3);
        world.setBlock(x + 5, y + 3, z + 5, Blocks.nether_brick_stairs, 1, 3);
        world.setBlock(x + 6, y + 3, z + 5, Blocks.air, 0, 3);
        world.setBlock(x + 7, y + 3, z + 5, Blocks.air, 0, 3);
        world.setBlock(x + 8, y + 3, z + 5, Blocks.air, 0, 3);
        world.setBlock(x + 9, y + 3, z + 5, Blocks.stone_slab, 14, 3);
        world.setBlock(x + 10, y + 3, z + 5, Blocks.stone_slab, 14, 3);
        world.setBlock(x + 11, y + 3, z + 5, Blocks.stone_slab, 14, 3);
        world.setBlock(x + 12, y + 3, z + 5, Blocks.stone_slab, 14, 3);
        world.setBlock(x + 13, y + 3, z + 5, Blocks.stone_slab, 14, 3);
        world.setBlock(x + 14, y + 3, z + 5, Blocks.stone_slab, 14, 3);
        world.setBlock(x + 15, y + 3, z + 5, Blocks.stone_slab, 14, 3);
        world.setBlock(x + 16, y + 3, z + 5, Blocks.stone_slab, 14, 3);
        world.setBlock(x + 17, y + 3, z + 5, Blocks.stone_slab, 14, 3);
        world.setBlock(x + 18, y + 3, z + 5, Blocks.stone_slab, 14, 3);
        world.setBlock(x + 19, y + 3, z + 5, Blocks.stone_slab, 14, 3);
        world.setBlock(x + 20, y + 3, z + 5, Blocks.stone_slab, 14, 3);
        world.setBlock(x + 21, y + 3, z + 5, Blocks.stone_slab, 14, 3);
        world.setBlock(x + 22, y + 3, z + 5, Blocks.stone_slab, 14, 3);
        world.setBlock(x + 23, y + 3, z + 5, Blocks.nether_brick, 0, 3);
        world.setBlock(x + 24, y + 3, z + 5, Blocks.nether_brick, 0, 3);
        world.setBlock(x + 25, y + 3, z + 5, Blocks.nether_brick, 0, 3);
        world.setBlock(x + 26, y + 3, z + 5, Blocks.nether_brick, 0, 3);
        world.setBlock(x + 27, y + 3, z + 5, Blocks.nether_brick, 0, 3);
        world.setBlock(x + 28, y + 3, z + 5, Blocks.nether_brick, 0, 3);
        world.setBlock(x + 29, y + 3, z + 5, Blocks.nether_brick, 0, 3);
        world.setBlock(x + 30, y + 3, z + 5, Blocks.nether_brick, 0, 3);
        world.setBlock(x + 31, y + 3, z + 5, Blocks.nether_brick_stairs, 5, 3);
        world.setBlock(x + 1, y + 3, z + 6, Blocks.nether_brick_stairs, 0, 3);
        world.setBlock(x + 2, y + 3, z + 6, Blocks.stone_slab, 14, 3);
        world.setBlock(x + 3, y + 3, z + 6, Blocks.stone_slab, 14, 3);
        world.setBlock(x + 4, y + 3, z + 6, Blocks.stone_slab, 14, 3);
        world.setBlock(x + 5, y + 3, z + 6, Blocks.nether_brick_stairs, 1, 3);
        world.setBlock(x + 6, y + 3, z + 6, Blocks.air, 0, 3);
        world.setBlock(x + 7, y + 3, z + 6, Blocks.air, 0, 3);
        world.setBlock(x + 8, y + 3, z + 6, Blocks.air, 0, 3);
        world.setBlock(x + 9, y + 3, z + 6, Blocks.stone_slab, 14, 3);
        world.setBlock(x + 10, y + 3, z + 6, Blocks.stone_slab, 14, 3);
        world.setBlock(x + 11, y + 3, z + 6, Blocks.stone_slab, 14, 3);
        world.setBlock(x + 12, y + 3, z + 6, Blocks.stone_slab, 14, 3);
        world.setBlock(x + 13, y + 3, z + 6, Blocks.stone_slab, 14, 3);
        world.setBlock(x + 14, y + 3, z + 6, Blocks.stone_slab, 14, 3);
        world.setBlock(x + 15, y + 3, z + 6, Blocks.nether_brick, 0, 3);
        world.setBlock(x + 16, y + 3, z + 6, Blocks.nether_brick, 0, 3);
        world.setBlock(x + 17, y + 3, z + 6, Blocks.nether_brick, 0, 3);
        world.setBlock(x + 18, y + 3, z + 6, Blocks.nether_brick, 0, 3);
        world.setBlock(x + 19, y + 3, z + 6, Blocks.nether_brick, 0, 3);
        world.setBlock(x + 20, y + 3, z + 6, Blocks.stone_slab, 14, 3);
        world.setBlock(x + 21, y + 3, z + 6, Blocks.stone_slab, 14, 3);
        world.setBlock(x + 22, y + 3, z + 6, Blocks.stone_slab, 14, 3);
        world.setBlock(x + 23, y + 3, z + 6, Blocks.nether_brick_stairs, 3, 3);
        world.setBlock(x + 24, y + 3, z + 6, Blocks.nether_brick_stairs, 3, 3);
        world.setBlock(x + 1, y + 3, z + 7, Blocks.nether_brick_stairs, 3, 3);
        world.setBlock(x + 2, y + 3, z + 7, Blocks.nether_brick_stairs, 0, 3);
        world.setBlock(x + 3, y + 3, z + 7, Blocks.stone_slab, 14, 3);
        world.setBlock(x + 4, y + 3, z + 7, Blocks.stone_slab, 14, 3);
        world.setBlock(x + 5, y + 3, z + 7, Blocks.stone_slab, 14, 3);
        world.setBlock(x + 6, y + 3, z + 7, Blocks.stone_slab, 14, 3);
        world.setBlock(x + 7, y + 3, z + 7, Blocks.stone_slab, 14, 3);
        world.setBlock(x + 8, y + 3, z + 7, Blocks.stone_slab, 14, 3);
        world.setBlock(x + 9, y + 3, z + 7, Blocks.stone_slab, 14, 3);
        world.setBlock(x + 10, y + 3, z + 7, Blocks.stone_slab, 14, 3);
        world.setBlock(x + 11, y + 3, z + 7, Blocks.stone_slab, 14, 3);
        world.setBlock(x + 12, y + 3, z + 7, Blocks.stone_slab, 14, 3);
        world.setBlock(x + 13, y + 3, z + 7, Blocks.stone_slab, 14, 3);
        world.setBlock(x + 14, y + 3, z + 7, Blocks.stone_slab, 14, 3);
        world.setBlock(x + 15, y + 3, z + 7, Blocks.nether_brick, 0, 3);
        world.setBlock(x + 16, y + 3, z + 7, Blocks.stone_slab, 14, 3);
        world.setBlock(x + 17, y + 3, z + 7, Blocks.stone_slab, 14, 3);
        world.setBlock(x + 18, y + 3, z + 7, Blocks.stone_slab, 14, 3);
        world.setBlock(x + 19, y + 3, z + 7, Blocks.nether_brick, 0, 3);
        world.setBlock(x + 20, y + 3, z + 7, Blocks.stone_slab, 14, 3);
        world.setBlock(x + 21, y + 3, z + 7, Blocks.stone_slab, 14, 3);
        world.setBlock(x + 22, y + 3, z + 7, Blocks.nether_brick_stairs, 3, 3);
        world.setBlock(x + 23, y + 3, z + 7, Blocks.nether_brick_stairs, 1, 3);
        world.setBlock(x + 2, y + 3, z + 8, Blocks.nether_brick_stairs, 3, 3);
        world.setBlock(x + 3, y + 3, z + 8, Blocks.nether_brick_stairs, 3, 3);
        world.setBlock(x + 4, y + 3, z + 8, Blocks.stone_slab, 14, 3);
        world.setBlock(x + 5, y + 3, z + 8, Blocks.stone_slab, 14, 3);
        world.setBlock(x + 6, y + 3, z + 8, Blocks.stone_slab, 14, 3);
        world.setBlock(x + 7, y + 3, z + 8, Blocks.stone_slab, 14, 3);
        world.setBlock(x + 8, y + 3, z + 8, Blocks.stone_slab, 14, 3);
        world.setBlock(x + 9, y + 3, z + 8, Blocks.stone_slab, 14, 3);
        world.setBlock(x + 10, y + 3, z + 8, Blocks.stone_slab, 14, 3);
        world.setBlock(x + 11, y + 3, z + 8, Blocks.stone_slab, 14, 3);
        world.setBlock(x + 12, y + 3, z + 8, Blocks.stone_slab, 14, 3);
        world.setBlock(x + 13, y + 3, z + 8, Blocks.stone_slab, 14, 3);
        world.setBlock(x + 14, y + 3, z + 8, Blocks.stone_slab, 14, 3);
        world.setBlock(x + 15, y + 3, z + 8, Blocks.nether_brick, 0, 3);
        world.setBlock(x + 16, y + 3, z + 8, Blocks.stone_slab, 14, 3);
        world.setBlock(x + 17, y + 3, z + 8, Blocks.stone_slab, 14, 3);
        world.setBlock(x + 18, y + 3, z + 8, Blocks.stone_slab, 14, 3);
        world.setBlock(x + 19, y + 3, z + 8, Blocks.nether_brick, 0, 3);
        world.setBlock(x + 20, y + 3, z + 8, Blocks.stone_slab, 14, 3);
        world.setBlock(x + 21, y + 3, z + 8, Blocks.nether_brick_stairs, 3, 3);
        world.setBlock(x + 22, y + 3, z + 8, Blocks.nether_brick_stairs, 1, 3);
        world.setBlock(x + 3, y + 3, z + 9, Blocks.nether_brick_stairs, 0, 3);
        world.setBlock(x + 4, y + 3, z + 9, Blocks.nether_brick_stairs, 3, 3);
        world.setBlock(x + 5, y + 3, z + 9, Blocks.nether_brick_stairs, 3, 3);
        world.setBlock(x + 6, y + 3, z + 9, Blocks.nether_brick_stairs, 3, 3);
        world.setBlock(x + 7, y + 3, z + 9, Blocks.nether_brick_stairs, 3, 3);
        world.setBlock(x + 8, y + 3, z + 9, Blocks.nether_brick_stairs, 3, 3);
        world.setBlock(x + 9, y + 3, z + 9, Blocks.nether_brick_stairs, 3, 3);
        world.setBlock(x + 10, y + 3, z + 9, Blocks.nether_brick_stairs, 3, 3);
        world.setBlock(x + 11, y + 3, z + 9, Blocks.nether_brick_stairs, 3, 3);
        world.setBlock(x + 12, y + 3, z + 9, Blocks.nether_brick_stairs, 3, 3);
        world.setBlock(x + 13, y + 3, z + 9, Blocks.nether_brick_stairs, 3, 3);
        world.setBlock(x + 14, y + 3, z + 9, Blocks.nether_brick_stairs, 3, 3);
        world.setBlock(x + 15, y + 3, z + 9, Blocks.nether_brick_stairs, 3, 3);
        world.setBlock(x + 16, y + 3, z + 9, Blocks.nether_brick_stairs, 3, 3);
        world.setBlock(x + 17, y + 3, z + 9, Blocks.nether_brick_stairs, 3, 3);
        world.setBlock(x + 18, y + 3, z + 9, Blocks.nether_brick_stairs, 3, 3);
        world.setBlock(x + 19, y + 3, z + 9, Blocks.nether_brick_stairs, 3, 3);
        world.setBlock(x + 20, y + 3, z + 9, Blocks.nether_brick_stairs, 3, 3);
        world.setBlock(x + 21, y + 3, z + 9, Blocks.nether_brick_stairs, 1, 3);
        world.setBlock(x + 4, y + 4, z + 2, Blocks.obsidian, 0, 3);
        world.setBlock(x + 5, y + 4, z + 2, Blocks.obsidian, 0, 3);
        world.setBlock(x + 6, y + 4, z + 2, Blocks.obsidian, 0, 3);
        world.setBlock(x + 7, y + 4, z + 2, Blocks.obsidian, 0, 3);
        world.setBlock(x + 8, y + 4, z + 2, Blocks.obsidian, 0, 3);
        world.setBlock(x + 9, y + 4, z + 2, Blocks.obsidian, 0, 3);
        world.setBlock(x + 10, y + 4, z + 2, Blocks.obsidian, 0, 3);
        world.setBlock(x + 11, y + 4, z + 2, Blocks.obsidian, 0, 3);
        world.setBlock(x + 12, y + 4, z + 2, Blocks.obsidian, 0, 3);
        world.setBlock(x + 13, y + 4, z + 2, Blocks.obsidian, 0, 3);
        world.setBlock(x + 14, y + 4, z + 2, Blocks.obsidian, 0, 3);
        world.setBlock(x + 15, y + 4, z + 2, Blocks.obsidian, 0, 3);
        world.setBlock(x + 16, y + 4, z + 2, Blocks.obsidian, 0, 3);
        world.setBlock(x + 17, y + 4, z + 2, Blocks.obsidian, 0, 3);
        world.setBlock(x + 18, y + 4, z + 2, Blocks.obsidian, 0, 3);
        world.setBlock(x + 19, y + 4, z + 2, Blocks.obsidian, 0, 3);
        world.setBlock(x + 20, y + 4, z + 2, Blocks.obsidian, 0, 3);
        world.setBlock(x + 3, y + 4, z + 3, Blocks.obsidian, 0, 3);
        world.setBlock(x + 4, y + 4, z + 3, Blocks.obsidian, 0, 3);
        world.setBlock(x + 20, y + 4, z + 3, Blocks.obsidian, 0, 3);
        world.setBlock(x + 21, y + 4, z + 3, Blocks.obsidian, 0, 3);
        world.setBlock(x + 2, y + 4, z + 4, Blocks.obsidian, 0, 3);
        world.setBlock(x + 3, y + 4, z + 4, Blocks.obsidian, 0, 3);
        world.setBlock(x + 21, y + 4, z + 4, Blocks.obsidian, 0, 3);
        world.setBlock(x + 22, y + 4, z + 4, Blocks.obsidian, 0, 3);
        world.setBlock(x + 2, y + 4, z + 5, Blocks.obsidian, 0, 3);
        world.setBlock(x + 3, y + 4, z + 5, Blocks.obsidian, 0, 3);
        world.setBlock(x + 11, y + 4, z + 5, FABlockRegistry.anuTotem, 5, 3);
        world.setBlock(x + 15, y + 4, z + 5, Blocks.obsidian, 0, 3);
        world.setBlock(x + 22, y + 4, z + 5, Blocks.obsidian, 0, 3);
        world.setBlock(x + 23, y + 4, z + 5, Blocks.obsidian, 0, 3);
        world.setBlock(x + 2, y + 4, z + 6, Blocks.obsidian, 0, 3);
        world.setBlock(x + 3, y + 4, z + 6, Blocks.obsidian, 0, 3);
        world.setBlock(x + 21, y + 4, z + 6, Blocks.obsidian, 0, 3);
        world.setBlock(x + 22, y + 4, z + 6, Blocks.obsidian, 0, 3);
        world.setBlock(x + 3, y + 4, z + 7, Blocks.obsidian, 0, 3);
        world.setBlock(x + 4, y + 4, z + 7, Blocks.obsidian, 0, 3);
        world.setBlock(x + 20, y + 4, z + 7, Blocks.obsidian, 0, 3);
        world.setBlock(x + 21, y + 4, z + 7, Blocks.obsidian, 0, 3);
        world.setBlock(x + 4, y + 4, z + 8, Blocks.obsidian, 0, 3);
        world.setBlock(x + 5, y + 4, z + 8, Blocks.obsidian, 0, 3);
        world.setBlock(x + 6, y + 4, z + 8, Blocks.obsidian, 0, 3);
        world.setBlock(x + 7, y + 4, z + 8, Blocks.obsidian, 0, 3);
        world.setBlock(x + 8, y + 4, z + 8, Blocks.obsidian, 0, 3);
        world.setBlock(x + 9, y + 4, z + 8, Blocks.obsidian, 0, 3);
        world.setBlock(x + 10, y + 4, z + 8, Blocks.obsidian, 0, 3);
        world.setBlock(x + 11, y + 4, z + 8, Blocks.obsidian, 0, 3);
        world.setBlock(x + 12, y + 4, z + 8, Blocks.obsidian, 0, 3);
        world.setBlock(x + 13, y + 4, z + 8, Blocks.obsidian, 0, 3);
        world.setBlock(x + 14, y + 4, z + 8, Blocks.obsidian, 0, 3);
        world.setBlock(x + 15, y + 4, z + 8, Blocks.obsidian, 0, 3);
        world.setBlock(x + 16, y + 4, z + 8, Blocks.obsidian, 0, 3);
        world.setBlock(x + 17, y + 4, z + 8, Blocks.obsidian, 0, 3);
        world.setBlock(x + 18, y + 4, z + 8, Blocks.obsidian, 0, 3);
        world.setBlock(x + 19, y + 4, z + 8, Blocks.obsidian, 0, 3);
        world.setBlock(x + 20, y + 4, z + 8, Blocks.obsidian, 0, 3);
        world.setBlock(x + 4, y + 5, z + 2, Blocks.nether_brick_fence, 0, 3);
        world.setBlock(x + 5, y + 5, z + 2, Blocks.nether_brick_fence, 0, 3);
        world.setBlock(x + 6, y + 5, z + 2, Blocks.nether_brick_fence, 0, 3);
        world.setBlock(x + 7, y + 5, z + 2, Blocks.nether_brick_fence, 0, 3);
        world.setBlock(x + 8, y + 5, z + 2, Blocks.nether_brick_fence, 0, 3);
        world.setBlock(x + 9, y + 5, z + 2, Blocks.nether_brick_fence, 0, 3);
        world.setBlock(x + 10, y + 5, z + 2, Blocks.nether_brick_fence, 0, 3);
        world.setBlock(x + 11, y + 5, z + 2, Blocks.nether_brick_fence, 0, 3);
        world.setBlock(x + 12, y + 5, z + 2, Blocks.nether_brick_fence, 0, 3);
        world.setBlock(x + 13, y + 5, z + 2, Blocks.nether_brick_fence, 0, 3);
        world.setBlock(x + 14, y + 5, z + 2, Blocks.nether_brick_fence, 0, 3);
        world.setBlock(x + 15, y + 5, z + 2, Blocks.nether_brick_fence, 0, 3);
        world.setBlock(x + 16, y + 5, z + 2, Blocks.nether_brick_fence, 0, 3);
        world.setBlock(x + 17, y + 5, z + 2, Blocks.nether_brick_fence, 0, 3);
        world.setBlock(x + 18, y + 5, z + 2, Blocks.nether_brick_fence, 0, 3);
        world.setBlock(x + 19, y + 5, z + 2, Blocks.nether_brick_fence, 0, 3);
        world.setBlock(x + 20, y + 5, z + 2, Blocks.nether_brick_fence, 0, 3);
        world.setBlock(x + 3, y + 5, z + 3, Blocks.nether_brick_fence, 0, 3);
        world.setBlock(x + 4, y + 5, z + 3, Blocks.nether_brick_fence, 0, 3);
        world.setBlock(x + 20, y + 5, z + 3, Blocks.nether_brick_fence, 0, 3);
        world.setBlock(x + 21, y + 5, z + 3, Blocks.nether_brick_fence, 0, 3);
        world.setBlock(x + 2, y + 5, z + 4, Blocks.nether_brick_fence, 0, 3);
        world.setBlock(x + 3, y + 5, z + 4, Blocks.nether_brick_fence, 0, 3);
        world.setBlock(x + 21, y + 5, z + 4, Blocks.nether_brick_fence, 0, 3);
        world.setBlock(x + 22, y + 5, z + 4, Blocks.nether_brick_fence, 0, 3);
        world.setBlock(x + 2, y + 5, z + 5, Blocks.nether_brick_fence, 0, 3);
        world.setBlock(x + 3, y + 5, z + 5, Blocks.obsidian, 0, 3);
        world.setBlock(x + 15, y + 5, z + 5, Blocks.obsidian, 0, 3);
        world.setBlock(x + 22, y + 5, z + 5, Blocks.nether_brick_fence, 0, 3);
        world.setBlock(x + 23, y + 5, z + 5, Blocks.nether_brick_fence, 0, 3);
        world.setBlock(x + 2, y + 5, z + 6, Blocks.nether_brick_fence, 0, 3);
        world.setBlock(x + 3, y + 5, z + 6, Blocks.nether_brick_fence, 0, 3);
        world.setBlock(x + 21, y + 5, z + 6, Blocks.nether_brick_fence, 0, 3);
        world.setBlock(x + 22, y + 5, z + 6, Blocks.nether_brick_fence, 0, 3);
        world.setBlock(x + 3, y + 5, z + 7, Blocks.nether_brick_fence, 0, 3);
        world.setBlock(x + 4, y + 5, z + 7, Blocks.nether_brick_fence, 0, 3);
        world.setBlock(x + 20, y + 5, z + 7, Blocks.nether_brick_fence, 0, 3);
        world.setBlock(x + 21, y + 5, z + 7, Blocks.nether_brick_fence, 0, 3);
        world.setBlock(x + 4, y + 5, z + 8, Blocks.nether_brick_fence, 0, 3);
        world.setBlock(x + 5, y + 5, z + 8, Blocks.nether_brick_fence, 0, 3);
        world.setBlock(x + 6, y + 5, z + 8, Blocks.nether_brick_fence, 0, 3);
        world.setBlock(x + 7, y + 5, z + 8, Blocks.nether_brick_fence, 0, 3);
        world.setBlock(x + 8, y + 5, z + 8, Blocks.nether_brick_fence, 0, 3);
        world.setBlock(x + 9, y + 5, z + 8, Blocks.nether_brick_fence, 0, 3);
        world.setBlock(x + 10, y + 5, z + 8, Blocks.nether_brick_fence, 0, 3);
        world.setBlock(x + 11, y + 5, z + 8, Blocks.nether_brick_fence, 0, 3);
        world.setBlock(x + 12, y + 5, z + 8, Blocks.nether_brick_fence, 0, 3);
        world.setBlock(x + 13, y + 5, z + 8, Blocks.nether_brick_fence, 0, 3);
        world.setBlock(x + 14, y + 5, z + 8, Blocks.nether_brick_fence, 0, 3);
        world.setBlock(x + 15, y + 5, z + 8, Blocks.nether_brick_fence, 0, 3);
        world.setBlock(x + 16, y + 5, z + 8, Blocks.nether_brick_fence, 0, 3);
        world.setBlock(x + 17, y + 5, z + 8, Blocks.nether_brick_fence, 0, 3);
        world.setBlock(x + 18, y + 5, z + 8, Blocks.nether_brick_fence, 0, 3);
        world.setBlock(x + 19, y + 5, z + 8, Blocks.nether_brick_fence, 0, 3);
        world.setBlock(x + 20, y + 5, z + 8, Blocks.nether_brick_fence, 0, 3);
        world.setBlock(x + 3, y + 6, z + 5, Blocks.obsidian, 0, 3);
        world.setBlock(x + 15, y + 6, z + 5, Blocks.obsidian, 0, 3);
        world.setBlock(x + 3, y + 7, z + 5, Blocks.obsidian, 0, 3);
        world.setBlock(x + 15, y + 7, z + 5, Blocks.obsidian, 0, 3);
        world.setBlock(x + 3, y + 8, z + 5, Blocks.obsidian, 0, 3);
        world.setBlock(x + 15, y + 8, z + 5, Blocks.obsidian, 0, 3);
        world.setBlock(x + 15, y + 9, z + 3, Blocks.obsidian, 0, 3);
        world.setBlock(x + 3, y + 9, z + 4, Blocks.obsidian, 0, 3);
        world.setBlock(x + 15, y + 9, z + 4, Blocks.obsidian, 0, 3);
        world.setBlock(x + 3, y + 9, z + 5, Blocks.obsidian, 0, 3);
        world.setBlock(x + 15, y + 9, z + 5, Blocks.obsidian, 0, 3);
        world.setBlock(x + 3, y + 9, z + 6, Blocks.obsidian, 0, 3);
        world.setBlock(x + 15, y + 9, z + 6, Blocks.obsidian, 0, 3);
        world.setBlock(x + 15, y + 9, z + 7, Blocks.obsidian, 0, 3);
        world.setBlock(x + 3, y + 10, z + 5, Blocks.obsidian, 0, 3);
        world.setBlock(x + 15, y + 10, z + 5, Blocks.obsidian, 0, 3);
        world.setBlock(x + 3, y + 11, z + 5, Blocks.obsidian, 0, 3);
        world.setBlock(x + 15, y + 11, z + 5, Blocks.obsidian, 0, 3);
        world.setBlock(x + 3, y + 12, z + 5, Blocks.obsidian, 0, 3);
        world.setBlock(x + 15, y + 12, z + 5, Blocks.obsidian, 0, 3);
        world.setBlock(x + 3, y + 13, z + 5, Blocks.obsidian, 0, 3);
        world.setBlock(x + 15, y + 13, z + 5, Blocks.obsidian, 0, 3);
        world.setBlock(x + 15, y + 14, z + 0, Blocks.obsidian, 0, 3);
        world.setBlock(x + 3, y + 14, z + 1, Blocks.obsidian, 0, 3);
        world.setBlock(x + 15, y + 14, z + 1, Blocks.obsidian, 0, 3);
        world.setBlock(x + 3, y + 14, z + 2, Blocks.obsidian, 0, 3);
        world.setBlock(x + 15, y + 14, z + 2, Blocks.obsidian, 0, 3);
        world.setBlock(x + 3, y + 14, z + 3, Blocks.obsidian, 0, 3);
        world.setBlock(x + 15, y + 14, z + 3, Blocks.obsidian, 0, 3);
        world.setBlock(x + 3, y + 14, z + 4, Blocks.obsidian, 0, 3);
        world.setBlock(x + 15, y + 14, z + 4, Blocks.obsidian, 0, 3);
        world.setBlock(x + 3, y + 14, z + 5, Blocks.obsidian, 0, 3);
        world.setBlock(x + 15, y + 14, z + 5, Blocks.obsidian, 0, 3);
        world.setBlock(x + 3, y + 14, z + 6, Blocks.obsidian, 0, 3);
        world.setBlock(x + 15, y + 14, z + 6, Blocks.obsidian, 0, 3);
        world.setBlock(x + 3, y + 14, z + 7, Blocks.obsidian, 0, 3);
        world.setBlock(x + 15, y + 14, z + 7, Blocks.obsidian, 0, 3);
        world.setBlock(x + 3, y + 14, z + 8, Blocks.obsidian, 0, 3);
        world.setBlock(x + 15, y + 14, z + 8, Blocks.obsidian, 0, 3);
        world.setBlock(x + 3, y + 14, z + 9, Blocks.obsidian, 0, 3);
        world.setBlock(x + 15, y + 14, z + 9, Blocks.obsidian, 0, 3);
        world.setBlock(x + 15, y + 14, z + 10, Blocks.obsidian, 0, 3);
        world.setBlock(x + 3, y + 15, z + 5, Blocks.obsidian, 0, 3);
        world.setBlock(x + 15, y + 15, z + 5, Blocks.obsidian, 0, 3);
        world.setBlock(x + 3, y + 16, z + 5, Blocks.obsidian, 0, 3);
        world.setBlock(x + 15, y + 16, z + 5, Blocks.obsidian, 0, 3);
        world.setBlock(x + 15, y + 17, z + 5, Blocks.obsidian, 0, 3);
        world.setBlock(x + 15, y + 18, z + 5, Blocks.obsidian, 0, 3);
        world.setBlock(x + 15, y + 19, z + 5, Blocks.obsidian, 0, 3);
        world.setBlock(x + 14, y + 20, z + 4, Blocks.nether_brick_stairs, 4, 3);
        world.setBlock(x + 15, y + 20, z + 4, Blocks.nether_brick_stairs, 6, 3);
        world.setBlock(x + 16, y + 20, z + 4, Blocks.nether_brick_stairs, 6, 3);
        world.setBlock(x + 15, y + 20, z + 5, Blocks.nether_brick, 0, 3);
        world.setBlock(x + 16, y + 20, z + 5, Blocks.nether_brick_stairs, 5, 3);
        world.setBlock(x + 14, y + 20, z + 6, Blocks.nether_brick_stairs, 4, 3);
        world.setBlock(x + 15, y + 20, z + 6, Blocks.nether_brick_stairs, 7, 3);
        world.setBlock(x + 16, y + 20, z + 6, Blocks.nether_brick_stairs, 7, 3);
        world.setBlock(x + 14, y + 21, z + 4, Blocks.nether_brick_fence, 0, 3);
        world.setBlock(x + 15, y + 21, z + 4, Blocks.nether_brick_fence, 0, 3);
        world.setBlock(x + 16, y + 21, z + 4, Blocks.nether_brick_fence, 0, 3);
        world.setBlock(x + 16, y + 21, z + 5, Blocks.nether_brick_fence, 0, 3);
        world.setBlock(x + 14, y + 21, z + 6, Blocks.nether_brick_fence, 0, 3);
        world.setBlock(x + 15, y + 21, z + 6, Blocks.nether_brick_fence, 0, 3);
        world.setBlock(x + 16, y + 21, z + 6, Blocks.nether_brick_fence, 0, 3);

        generate_r02_last(world, rand, x, y, z);
        return true;

    }

    public boolean generate_r02_last(World world, Random rand, int x, int y, int z) {

        world.setBlock(x + 2, y + 2, z + 4, Blocks.redstone_torch, 1, 3);
        world.setBlock(x + 2, y + 2, z + 6, Blocks.redstone_torch, 1, 3);
        world.setBlock(x + 14, y + 4, z + 5, Blocks.ladder, 4, 3);
        world.setBlock(x + 14, y + 5, z + 5, Blocks.ladder, 4, 3);
        world.setBlock(x + 14, y + 6, z + 5, Blocks.ladder, 4, 3);
        world.setBlock(x + 14, y + 7, z + 5, Blocks.ladder, 4, 3);
        world.setBlock(x + 14, y + 8, z + 5, Blocks.ladder, 4, 3);
        world.setBlock(x + 14, y + 9, z + 5, Blocks.ladder, 4, 3);
        world.setBlock(x + 14, y + 10, z + 5, Blocks.ladder, 4, 3);
        world.setBlock(x + 14, y + 11, z + 5, Blocks.ladder, 4, 3);
        world.setBlock(x + 14, y + 12, z + 5, Blocks.ladder, 4, 3);
        world.setBlock(x + 14, y + 13, z + 5, Blocks.ladder, 4, 3);
        world.setBlock(x + 14, y + 14, z + 5, Blocks.ladder, 4, 3);
        world.setBlock(x + 14, y + 15, z + 5, Blocks.ladder, 4, 3);
        world.setBlock(x + 14, y + 16, z + 5, Blocks.ladder, 4, 3);
        world.setBlock(x + 14, y + 17, z + 5, Blocks.ladder, 4, 3);
        world.setBlock(x + 14, y + 18, z + 5, Blocks.ladder, 4, 3);
        world.setBlock(x + 14, y + 19, z + 5, Blocks.ladder, 4, 3);
        world.setBlock(x + 14, y + 20, z + 5, Blocks.ladder, 4, 3);
        return true;

    }

    protected void generateStructureChestContents(World world, Random rand, int i1, int j1, int k1, WeightedRandomChestContent[] content, int i) {

        world.setBlock(i1, j1, k1, Blocks.chest, 0, 2);
        TileEntityChest tileentitychest = (TileEntityChest) world.getTileEntity(i1, j1, k1);

        if (tileentitychest != null) {
            WeightedRandomChestContent.generateChestContents(rand, content, tileentitychest, i);
        }

    }
}