package com.github.revival.server.gen.feature;

import java.util.Random;

import com.github.revival.Revival;
import com.github.revival.server.block.FABlockRegistry;

import net.minecraft.block.Block;
import net.minecraft.block.material.Material;
import net.minecraft.entity.passive.EntityVillager;
import net.minecraft.init.Blocks;
import net.minecraft.world.World;
import net.minecraft.world.gen.feature.WorldGenerator;

public class WorldGenTarSite extends WorldGenerator {

	public boolean generate(World world, Random rand, int x, int y, int z) {
		int i = rand.nextInt(4);
			generate_r0(world, rand, x, y, z);
		
		return true;

	}

	public boolean generate_r0(World world, Random rand, int x, int y, int z) {
		world.setBlock(x + 0, y + 0, z + 0, Blocks.dirt, 0, 3);
		world.setBlock(x + 1, y + 0, z + 0, Blocks.dirt, 0, 3);
		world.setBlock(x + 2, y + 0, z + 0, Blocks.dirt, 0, 3);
		world.setBlock(x + 3, y + 0, z + 0, Blocks.dirt, 0, 3);
		world.setBlock(x + 4, y + 0, z + 0, Blocks.dirt, 0, 3);
		world.setBlock(x + 5, y + 0, z + 0, Blocks.dirt, 0, 3);
		world.setBlock(x + 6, y + 0, z + 0, Blocks.dirt, 0, 3);
		world.setBlock(x + 7, y + 0, z + 0, Blocks.dirt, 0, 3);
		world.setBlock(x + 8, y + 0, z + 0, Blocks.dirt, 0, 3);
		world.setBlock(x + 9, y + 0, z + 0, Blocks.dirt, 0, 3);
		world.setBlock(x + 10, y + 0, z + 0, Blocks.dirt, 0, 3);
		world.setBlock(x + 11, y + 0, z + 0, Blocks.dirt, 0, 3);
		world.setBlock(x + 0, y + 0, z + 1, Blocks.dirt, 0, 3);
		world.setBlock(x + 1, y + 0, z + 1, Blocks.dirt, 0, 3);
		world.setBlock(x + 2, y + 0, z + 1, Blocks.dirt, 0, 3);
		world.setBlock(x + 3, y + 0, z + 1, Blocks.dirt, 0, 3);
		world.setBlock(x + 4, y + 0, z + 1, Blocks.dirt, 0, 3);
		world.setBlock(x + 5, y + 0, z + 1, Blocks.dirt, 0, 3);
		world.setBlock(x + 6, y + 0, z + 1, Blocks.dirt, 0, 3);
		world.setBlock(x + 7, y + 0, z + 1, Blocks.dirt, 0, 3);
		world.setBlock(x + 8, y + 0, z + 1, Blocks.dirt, 0, 3);
		world.setBlock(x + 9, y + 0, z + 1, Blocks.dirt, 0, 3);
		world.setBlock(x + 10, y + 0, z + 1, Blocks.dirt, 0, 3);
		world.setBlock(x + 11, y + 0, z + 1, Blocks.dirt, 0, 3);
		world.setBlock(x + 0, y + 0, z + 2, Blocks.dirt, 0, 3);
		world.setBlock(x + 1, y + 0, z + 2, Blocks.dirt, 0, 3);
		world.setBlock(x + 2, y + 0, z + 2, Blocks.dirt, 0, 3);
		world.setBlock(x + 3, y + 0, z + 2, Blocks.dirt, 0, 3);
		world.setBlock(x + 4, y + 0, z + 2, Blocks.dirt, 0, 3);
		world.setBlock(x + 5, y + 0, z + 2, Blocks.dirt, 0, 3);
		world.setBlock(x + 6, y + 0, z + 2, Blocks.dirt, 0, 3);
		world.setBlock(x + 7, y + 0, z + 2, Blocks.dirt, 0, 3);
		world.setBlock(x + 8, y + 0, z + 2, Blocks.dirt, 0, 3);
		world.setBlock(x + 9, y + 0, z + 2, Blocks.dirt, 0, 3);
		world.setBlock(x + 10, y + 0, z + 2, Blocks.dirt, 0, 3);
		world.setBlock(x + 11, y + 0, z + 2, Blocks.dirt, 0, 3);
		world.setBlock(x + 0, y + 0, z + 3, Blocks.dirt, 0, 3);
		world.setBlock(x + 1, y + 0, z + 3, Blocks.dirt, 0, 3);
		world.setBlock(x + 2, y + 0, z + 3, Blocks.dirt, 0, 3);
		world.setBlock(x + 3, y + 0, z + 3, Blocks.dirt, 0, 3);
		world.setBlock(x + 4, y + 0, z + 3, Blocks.dirt, 0, 3);
		world.setBlock(x + 5, y + 0, z + 3, Blocks.dirt, 0, 3);
		world.setBlock(x + 6, y + 0, z + 3, Blocks.dirt, 0, 3);
		world.setBlock(x + 7, y + 0, z + 3, Blocks.dirt, 0, 3);
		world.setBlock(x + 8, y + 0, z + 3, Blocks.dirt, 0, 3);
		world.setBlock(x + 9, y + 0, z + 3, Blocks.dirt, 0, 3);
		world.setBlock(x + 10, y + 0, z + 3, Blocks.dirt, 0, 3);
		world.setBlock(x + 11, y + 0, z + 3, Blocks.dirt, 0, 3);
		world.setBlock(x + 0, y + 0, z + 4, Blocks.dirt, 0, 3);
		world.setBlock(x + 1, y + 0, z + 4, Blocks.dirt, 0, 3);
		world.setBlock(x + 2, y + 0, z + 4, Blocks.dirt, 0, 3);
		world.setBlock(x + 3, y + 0, z + 4, Blocks.dirt, 0, 3);
		world.setBlock(x + 4, y + 0, z + 4, Blocks.dirt, 0, 3);
		world.setBlock(x + 5, y + 0, z + 4, Blocks.dirt, 0, 3);
		world.setBlock(x + 6, y + 0, z + 4, Blocks.dirt, 0, 3);
		world.setBlock(x + 7, y + 0, z + 4, Blocks.dirt, 0, 3);
		world.setBlock(x + 8, y + 0, z + 4, Blocks.dirt, 0, 3);
		world.setBlock(x + 9, y + 0, z + 4, Blocks.dirt, 0, 3);
		world.setBlock(x + 10, y + 0, z + 4, Blocks.dirt, 0, 3);
		world.setBlock(x + 11, y + 0, z + 4, Blocks.dirt, 0, 3);
		world.setBlock(x + 0, y + 0, z + 5, Blocks.dirt, 0, 3);
		world.setBlock(x + 1, y + 0, z + 5, Blocks.dirt, 0, 3);
		world.setBlock(x + 2, y + 0, z + 5, Blocks.dirt, 0, 3);
		world.setBlock(x + 3, y + 0, z + 5, Blocks.dirt, 0, 3);
		world.setBlock(x + 4, y + 0, z + 5, Blocks.dirt, 0, 3);
		world.setBlock(x + 5, y + 0, z + 5, Blocks.dirt, 0, 3);
		world.setBlock(x + 6, y + 0, z + 5, Blocks.dirt, 0, 3);
		world.setBlock(x + 7, y + 0, z + 5, Blocks.dirt, 0, 3);
		world.setBlock(x + 8, y + 0, z + 5, Blocks.dirt, 0, 3);
		world.setBlock(x + 9, y + 0, z + 5, Blocks.dirt, 0, 3);
		world.setBlock(x + 10, y + 0, z + 5, Blocks.dirt, 0, 3);
		world.setBlock(x + 11, y + 0, z + 5, Blocks.dirt, 0, 3);
		world.setBlock(x + 0, y + 0, z + 6, Blocks.dirt, 0, 3);
		world.setBlock(x + 1, y + 0, z + 6, Blocks.dirt, 0, 3);
		world.setBlock(x + 2, y + 0, z + 6, Blocks.dirt, 0, 3);
		world.setBlock(x + 3, y + 0, z + 6, Blocks.dirt, 0, 3);
		world.setBlock(x + 4, y + 0, z + 6, Blocks.dirt, 0, 3);
		world.setBlock(x + 5, y + 0, z + 6, Blocks.dirt, 0, 3);
		world.setBlock(x + 6, y + 0, z + 6, Blocks.dirt, 0, 3);
		world.setBlock(x + 7, y + 0, z + 6, Blocks.dirt, 0, 3);
		world.setBlock(x + 8, y + 0, z + 6, Blocks.dirt, 0, 3);
		world.setBlock(x + 9, y + 0, z + 6, Blocks.dirt, 0, 3);
		world.setBlock(x + 10, y + 0, z + 6, Blocks.dirt, 0, 3);
		world.setBlock(x + 11, y + 0, z + 6, Blocks.dirt, 0, 3);
		world.setBlock(x + 0, y + 0, z + 7, Blocks.dirt, 0, 3);
		world.setBlock(x + 1, y + 0, z + 7, Blocks.dirt, 0, 3);
		world.setBlock(x + 2, y + 0, z + 7, Blocks.dirt, 0, 3);
		world.setBlock(x + 3, y + 0, z + 7, Blocks.dirt, 0, 3);
		world.setBlock(x + 4, y + 0, z + 7, Blocks.dirt, 0, 3);
		world.setBlock(x + 5, y + 0, z + 7, Blocks.dirt, 0, 3);
		world.setBlock(x + 6, y + 0, z + 7, Blocks.dirt, 0, 3);
		world.setBlock(x + 7, y + 0, z + 7, Blocks.dirt, 0, 3);
		world.setBlock(x + 8, y + 0, z + 7, Blocks.dirt, 0, 3);
		world.setBlock(x + 9, y + 0, z + 7, Blocks.dirt, 0, 3);
		world.setBlock(x + 10, y + 0, z + 7, Blocks.dirt, 0, 3);
		world.setBlock(x + 11, y + 0, z + 7, Blocks.dirt, 0, 3);
		world.setBlock(x + 0, y + 0, z + 8, Blocks.dirt, 0, 3);
		world.setBlock(x + 1, y + 0, z + 8, Blocks.dirt, 0, 3);
		world.setBlock(x + 2, y + 0, z + 8, Blocks.dirt, 0, 3);
		world.setBlock(x + 3, y + 0, z + 8, Blocks.dirt, 0, 3);
		world.setBlock(x + 4, y + 0, z + 8, Blocks.dirt, 0, 3);
		world.setBlock(x + 5, y + 0, z + 8, Blocks.dirt, 0, 3);
		world.setBlock(x + 6, y + 0, z + 8, Blocks.dirt, 0, 3);
		world.setBlock(x + 7, y + 0, z + 8, Blocks.dirt, 0, 3);
		world.setBlock(x + 8, y + 0, z + 8, Blocks.dirt, 0, 3);
		world.setBlock(x + 9, y + 0, z + 8, Blocks.dirt, 0, 3);
		world.setBlock(x + 10, y + 0, z + 8, Blocks.dirt, 0, 3);
		world.setBlock(x + 11, y + 0, z + 8, Blocks.dirt, 0, 3);
		world.setBlock(x + 0, y + 0, z + 9, Blocks.dirt, 0, 3);
		world.setBlock(x + 1, y + 0, z + 9, Blocks.dirt, 0, 3);
		world.setBlock(x + 2, y + 0, z + 9, Blocks.dirt, 0, 3);
		world.setBlock(x + 3, y + 0, z + 9, Blocks.dirt, 0, 3);
		world.setBlock(x + 4, y + 0, z + 9, Blocks.dirt, 0, 3);
		world.setBlock(x + 5, y + 0, z + 9, Blocks.dirt, 0, 3);
		world.setBlock(x + 6, y + 0, z + 9, Blocks.dirt, 0, 3);
		world.setBlock(x + 7, y + 0, z + 9, Blocks.dirt, 0, 3);
		world.setBlock(x + 8, y + 0, z + 9, Blocks.dirt, 0, 3);
		world.setBlock(x + 9, y + 0, z + 9, Blocks.dirt, 0, 3);
		world.setBlock(x + 10, y + 0, z + 9, Blocks.dirt, 0, 3);
		world.setBlock(x + 11, y + 0, z + 9, Blocks.dirt, 0, 3);
		world.setBlock(x + 0, y + 0, z + 10, Blocks.dirt, 0, 3);
		world.setBlock(x + 1, y + 0, z + 10, Blocks.dirt, 0, 3);
		world.setBlock(x + 2, y + 0, z + 10, Blocks.dirt, 0, 3);
		world.setBlock(x + 3, y + 0, z + 10, Blocks.dirt, 0, 3);
		world.setBlock(x + 4, y + 0, z + 10, Blocks.dirt, 0, 3);
		world.setBlock(x + 5, y + 0, z + 10, Blocks.dirt, 0, 3);
		world.setBlock(x + 6, y + 0, z + 10, Blocks.dirt, 0, 3);
		world.setBlock(x + 7, y + 0, z + 10, Blocks.dirt, 0, 3);
		world.setBlock(x + 8, y + 0, z + 10, Blocks.dirt, 0, 3);
		world.setBlock(x + 9, y + 0, z + 10, Blocks.dirt, 0, 3);
		world.setBlock(x + 10, y + 0, z + 10, Blocks.dirt, 0, 3);
		world.setBlock(x + 11, y + 0, z + 10, Blocks.dirt, 0, 3);
		world.setBlock(x + 0, y + 0, z + 11, Blocks.dirt, 0, 3);
		world.setBlock(x + 1, y + 0, z + 11, Blocks.dirt, 0, 3);
		world.setBlock(x + 2, y + 0, z + 11, Blocks.dirt, 0, 3);
		world.setBlock(x + 3, y + 0, z + 11, Blocks.dirt, 0, 3);
		world.setBlock(x + 4, y + 0, z + 11, Blocks.dirt, 0, 3);
		world.setBlock(x + 5, y + 0, z + 11, Blocks.dirt, 0, 3);
		world.setBlock(x + 6, y + 0, z + 11, Blocks.dirt, 0, 3);
		world.setBlock(x + 7, y + 0, z + 11, Blocks.dirt, 0, 3);
		world.setBlock(x + 8, y + 0, z + 11, Blocks.dirt, 0, 3);
		world.setBlock(x + 9, y + 0, z + 11, Blocks.dirt, 0, 3);
		world.setBlock(x + 10, y + 0, z + 11, Blocks.dirt, 0, 3);
		world.setBlock(x + 11, y + 0, z + 11, Blocks.dirt, 0, 3);
		world.setBlock(x + 0, y + 0, z + 12, Blocks.dirt, 0, 3);
		world.setBlock(x + 1, y + 0, z + 12, Blocks.dirt, 0, 3);
		world.setBlock(x + 2, y + 0, z + 12, Blocks.dirt, 0, 3);
		world.setBlock(x + 3, y + 0, z + 12, Blocks.dirt, 0, 3);
		world.setBlock(x + 4, y + 0, z + 12, Blocks.dirt, 0, 3);
		world.setBlock(x + 5, y + 0, z + 12, Blocks.dirt, 0, 3);
		world.setBlock(x + 6, y + 0, z + 12, Blocks.dirt, 0, 3);
		world.setBlock(x + 7, y + 0, z + 12, Blocks.dirt, 0, 3);
		world.setBlock(x + 8, y + 0, z + 12, Blocks.dirt, 0, 3);
		world.setBlock(x + 9, y + 0, z + 12, Blocks.dirt, 0, 3);
		world.setBlock(x + 10, y + 0, z + 12, Blocks.dirt, 0, 3);
		world.setBlock(x + 11, y + 0, z + 12, Blocks.dirt, 0, 3);
		world.setBlock(x + 0, y + 0, z + 13, Blocks.dirt, 0, 3);
		world.setBlock(x + 1, y + 0, z + 13, Blocks.dirt, 0, 3);
		world.setBlock(x + 2, y + 0, z + 13, Blocks.dirt, 0, 3);
		world.setBlock(x + 3, y + 0, z + 13, Blocks.dirt, 0, 3);
		world.setBlock(x + 4, y + 0, z + 13, Blocks.dirt, 0, 3);
		world.setBlock(x + 5, y + 0, z + 13, Blocks.dirt, 0, 3);
		world.setBlock(x + 6, y + 0, z + 13, Blocks.dirt, 0, 3);
		world.setBlock(x + 7, y + 0, z + 13, Blocks.dirt, 0, 3);
		world.setBlock(x + 8, y + 0, z + 13, Blocks.dirt, 0, 3);
		world.setBlock(x + 9, y + 0, z + 13, Blocks.dirt, 0, 3);
		world.setBlock(x + 10, y + 0, z + 13, Blocks.dirt, 0, 3);
		world.setBlock(x + 11, y + 0, z + 13, Blocks.dirt, 0, 3);
		world.setBlock(x + 0, y + 0, z + 14, Blocks.dirt, 0, 3);
		world.setBlock(x + 1, y + 0, z + 14, Blocks.dirt, 0, 3);
		world.setBlock(x + 2, y + 0, z + 14, Blocks.dirt, 0, 3);
		world.setBlock(x + 3, y + 0, z + 14, Blocks.dirt, 0, 3);
		world.setBlock(x + 4, y + 0, z + 14, Blocks.dirt, 0, 3);
		world.setBlock(x + 5, y + 0, z + 14, Blocks.dirt, 0, 3);
		world.setBlock(x + 6, y + 0, z + 14, Blocks.dirt, 0, 3);
		world.setBlock(x + 7, y + 0, z + 14, Blocks.dirt, 0, 3);
		world.setBlock(x + 8, y + 0, z + 14, Blocks.dirt, 0, 3);
		world.setBlock(x + 9, y + 0, z + 14, Blocks.dirt, 0, 3);
		world.setBlock(x + 10, y + 0, z + 14, Blocks.dirt, 0, 3);
		world.setBlock(x + 11, y + 0, z + 14, Blocks.dirt, 0, 3);
		world.setBlock(x + 0, y + 0, z + 15, Blocks.dirt, 0, 3);
		world.setBlock(x + 1, y + 0, z + 15, Blocks.dirt, 0, 3);
		world.setBlock(x + 2, y + 0, z + 15, Blocks.dirt, 0, 3);
		world.setBlock(x + 3, y + 0, z + 15, Blocks.dirt, 0, 3);
		world.setBlock(x + 4, y + 0, z + 15, Blocks.dirt, 0, 3);
		world.setBlock(x + 5, y + 0, z + 15, Blocks.dirt, 0, 3);
		world.setBlock(x + 6, y + 0, z + 15, Blocks.dirt, 0, 3);
		world.setBlock(x + 7, y + 0, z + 15, Blocks.dirt, 0, 3);
		world.setBlock(x + 8, y + 0, z + 15, Blocks.dirt, 0, 3);
		world.setBlock(x + 9, y + 0, z + 15, Blocks.dirt, 0, 3);
		world.setBlock(x + 10, y + 0, z + 15, Blocks.dirt, 0, 3);
		world.setBlock(x + 11, y + 0, z + 15, Blocks.dirt, 0, 3);
		world.setBlock(x + 0, y + 0, z + 16, Blocks.dirt, 0, 3);
		world.setBlock(x + 1, y + 0, z + 16, Blocks.dirt, 0, 3);
		world.setBlock(x + 2, y + 0, z + 16, Blocks.dirt, 0, 3);
		world.setBlock(x + 3, y + 0, z + 16, Blocks.dirt, 0, 3);
		world.setBlock(x + 4, y + 0, z + 16, Blocks.dirt, 0, 3);
		world.setBlock(x + 5, y + 0, z + 16, Blocks.dirt, 0, 3);
		world.setBlock(x + 6, y + 0, z + 16, Blocks.dirt, 0, 3);
		world.setBlock(x + 7, y + 0, z + 16, Blocks.dirt, 0, 3);
		world.setBlock(x + 8, y + 0, z + 16, Blocks.dirt, 0, 3);
		world.setBlock(x + 9, y + 0, z + 16, Blocks.dirt, 0, 3);
		world.setBlock(x + 10, y + 0, z + 16, Blocks.dirt, 0, 3);
		world.setBlock(x + 11, y + 0, z + 16, Blocks.dirt, 0, 3);
		world.setBlock(x + 0, y + 0, z + 17, Blocks.dirt, 0, 3);
		world.setBlock(x + 1, y + 0, z + 17, Blocks.dirt, 0, 3);
		world.setBlock(x + 2, y + 0, z + 17, Blocks.dirt, 0, 3);
		world.setBlock(x + 3, y + 0, z + 17, Blocks.dirt, 0, 3);
		world.setBlock(x + 4, y + 0, z + 17, Blocks.dirt, 0, 3);
		world.setBlock(x + 5, y + 0, z + 17, Blocks.dirt, 0, 3);
		world.setBlock(x + 6, y + 0, z + 17, Blocks.dirt, 0, 3);
		world.setBlock(x + 7, y + 0, z + 17, Blocks.dirt, 0, 3);
		world.setBlock(x + 8, y + 0, z + 17, Blocks.dirt, 0, 3);
		world.setBlock(x + 9, y + 0, z + 17, Blocks.dirt, 0, 3);
		world.setBlock(x + 10, y + 0, z + 17, Blocks.dirt, 0, 3);
		world.setBlock(x + 11, y + 0, z + 17, Blocks.dirt, 0, 3);
		world.setBlock(x + 0, y + 1, z + 0, Blocks.dirt, 0, 3);
		world.setBlock(x + 1, y + 1, z + 0, Blocks.dirt, 0, 3);
		world.setBlock(x + 2, y + 1, z + 0, Blocks.dirt, 0, 3);
		world.setBlock(x + 3, y + 1, z + 0, Blocks.dirt, 0, 3);
		world.setBlock(x + 4, y + 1, z + 0, Blocks.dirt, 0, 3);
		world.setBlock(x + 5, y + 1, z + 0, Blocks.dirt, 0, 3);
		world.setBlock(x + 6, y + 1, z + 0, Blocks.dirt, 0, 3);
		world.setBlock(x + 7, y + 1, z + 0, Blocks.dirt, 0, 3);
		world.setBlock(x + 8, y + 1, z + 0, Blocks.dirt, 0, 3);
		world.setBlock(x + 9, y + 1, z + 0, Blocks.dirt, 0, 3);
		world.setBlock(x + 10, y + 1, z + 0, Blocks.dirt, 0, 3);
		world.setBlock(x + 11, y + 1, z + 0, Blocks.dirt, 0, 3);
		world.setBlock(x + 0, y + 1, z + 1, Blocks.dirt, 0, 3);
		world.setBlock(x + 1, y + 1, z + 1, Blocks.dirt, 0, 3);
		world.setBlock(x + 2, y + 1, z + 1, Blocks.dirt, 0, 3);
		world.setBlock(x + 3, y + 1, z + 1, Blocks.dirt, 0, 3);
		world.setBlock(x + 4, y + 1, z + 1, Blocks.dirt, 0, 3);
		world.setBlock(x + 5, y + 1, z + 1, Blocks.dirt, 0, 3);
		world.setBlock(x + 6, y + 1, z + 1, Blocks.dirt, 0, 3);
		world.setBlock(x + 7, y + 1, z + 1, Blocks.dirt, 0, 3);
		world.setBlock(x + 8, y + 1, z + 1, Blocks.dirt, 0, 3);
		world.setBlock(x + 9, y + 1, z + 1, Blocks.dirt, 0, 3);
		world.setBlock(x + 10, y + 1, z + 1, Blocks.dirt, 0, 3);
		world.setBlock(x + 11, y + 1, z + 1, Blocks.dirt, 0, 3);
		world.setBlock(x + 0, y + 1, z + 2, Blocks.dirt, 0, 3);
		world.setBlock(x + 1, y + 1, z + 2, Blocks.dirt, 0, 3);
		world.setBlock(x + 2, y + 1, z + 2, Blocks.dirt, 0, 3);
		world.setBlock(x + 3, y + 1, z + 2, Blocks.dirt, 0, 3);
		world.setBlock(x + 4, y + 1, z + 2, Blocks.dirt, 0, 3);
		world.setBlock(x + 5, y + 1, z + 2, Blocks.dirt, 0, 3);
		world.setBlock(x + 6, y + 1, z + 2, Blocks.dirt, 0, 3);
		world.setBlock(x + 7, y + 1, z + 2, Blocks.dirt, 0, 3);
		world.setBlock(x + 8, y + 1, z + 2, Blocks.dirt, 0, 3);
		world.setBlock(x + 9, y + 1, z + 2, Blocks.dirt, 0, 3);
		world.setBlock(x + 10, y + 1, z + 2, Blocks.dirt, 0, 3);
		world.setBlock(x + 11, y + 1, z + 2, Blocks.dirt, 0, 3);
		world.setBlock(x + 0, y + 1, z + 3, Blocks.dirt, 0, 3);
		world.setBlock(x + 1, y + 1, z + 3, Blocks.dirt, 0, 3);
		world.setBlock(x + 2, y + 1, z + 3, Blocks.dirt, 0, 3);
		world.setBlock(x + 3, y + 1, z + 3, Blocks.dirt, 0, 3);
		world.setBlock(x + 4, y + 1, z + 3, Blocks.dirt, 0, 3);
		world.setBlock(x + 5, y + 1, z + 3, Blocks.dirt, 0, 3);
		world.setBlock(x + 6, y + 1, z + 3, Blocks.dirt, 0, 3);
		world.setBlock(x + 7, y + 1, z + 3, Blocks.dirt, 0, 3);
		world.setBlock(x + 8, y + 1, z + 3, Blocks.dirt, 0, 3);
		world.setBlock(x + 9, y + 1, z + 3, Blocks.dirt, 0, 3);
		world.setBlock(x + 10, y + 1, z + 3, Blocks.dirt, 0, 3);
		world.setBlock(x + 11, y + 1, z + 3, Blocks.dirt, 0, 3);
		world.setBlock(x + 0, y + 1, z + 4, Blocks.dirt, 0, 3);
		world.setBlock(x + 1, y + 1, z + 4, Blocks.dirt, 0, 3);
		world.setBlock(x + 2, y + 1, z + 4, Blocks.dirt, 0, 3);
		world.setBlock(x + 3, y + 1, z + 4, Blocks.dirt, 0, 3);
		world.setBlock(x + 4, y + 1, z + 4, Blocks.dirt, 0, 3);
		world.setBlock(x + 5, y + 1, z + 4, Blocks.dirt, 0, 3);
		world.setBlock(x + 6, y + 1, z + 4, Blocks.dirt, 0, 3);
		world.setBlock(x + 7, y + 1, z + 4, Blocks.dirt, 0, 3);
		world.setBlock(x + 8, y + 1, z + 4, Blocks.dirt, 0, 3);
		world.setBlock(x + 9, y + 1, z + 4, Blocks.dirt, 0, 3);
		world.setBlock(x + 10, y + 1, z + 4, Blocks.dirt, 0, 3);
		world.setBlock(x + 11, y + 1, z + 4, Blocks.dirt, 0, 3);
		world.setBlock(x + 0, y + 1, z + 5, Blocks.dirt, 0, 3);
		world.setBlock(x + 1, y + 1, z + 5, Blocks.dirt, 0, 3);
		world.setBlock(x + 2, y + 1, z + 5, Blocks.dirt, 0, 3);
		world.setBlock(x + 3, y + 1, z + 5, Blocks.dirt, 0, 3);
		world.setBlock(x + 4, y + 1, z + 5, Blocks.dirt, 0, 3);
		world.setBlock(x + 5, y + 1, z + 5, Blocks.dirt, 0, 3);
		world.setBlock(x + 6, y + 1, z + 5, Blocks.dirt, 0, 3);
		world.setBlock(x + 7, y + 1, z + 5, Blocks.dirt, 0, 3);
		world.setBlock(x + 8, y + 1, z + 5, Blocks.dirt, 0, 3);
		world.setBlock(x + 9, y + 1, z + 5, Blocks.dirt, 0, 3);
		world.setBlock(x + 10, y + 1, z + 5, Blocks.dirt, 0, 3);
		world.setBlock(x + 11, y + 1, z + 5, Blocks.dirt, 0, 3);
		world.setBlock(x + 0, y + 1, z + 6, Blocks.dirt, 0, 3);
		world.setBlock(x + 1, y + 1, z + 6, Blocks.dirt, 0, 3);
		world.setBlock(x + 2, y + 1, z + 6, Blocks.dirt, 0, 3);
		world.setBlock(x + 3, y + 1, z + 6, Blocks.dirt, 0, 3);
		world.setBlock(x + 4, y + 1, z + 6, Blocks.dirt, 0, 3);
		world.setBlock(x + 5, y + 1, z + 6, Blocks.dirt, 0, 3);
		world.setBlock(x + 6, y + 1, z + 6, Blocks.dirt, 0, 3);
		world.setBlock(x + 7, y + 1, z + 6, Blocks.dirt, 0, 3);
		world.setBlock(x + 8, y + 1, z + 6, Blocks.dirt, 0, 3);
		world.setBlock(x + 9, y + 1, z + 6, Blocks.dirt, 0, 3);
		world.setBlock(x + 10, y + 1, z + 6, Blocks.dirt, 0, 3);
		world.setBlock(x + 11, y + 1, z + 6, Blocks.dirt, 0, 3);
		world.setBlock(x + 0, y + 1, z + 7, Blocks.dirt, 0, 3);
		world.setBlock(x + 1, y + 1, z + 7, Blocks.dirt, 0, 3);
		world.setBlock(x + 2, y + 1, z + 7, Blocks.dirt, 0, 3);
		world.setBlock(x + 3, y + 1, z + 7, Blocks.dirt, 0, 3);
		world.setBlock(x + 4, y + 1, z + 7, Blocks.dirt, 0, 3);
		world.setBlock(x + 5, y + 1, z + 7, Blocks.dirt, 0, 3);
		world.setBlock(x + 6, y + 1, z + 7, Blocks.dirt, 0, 3);
		world.setBlock(x + 7, y + 1, z + 7, Blocks.dirt, 0, 3);
		world.setBlock(x + 8, y + 1, z + 7, Blocks.dirt, 0, 3);
		world.setBlock(x + 9, y + 1, z + 7, Blocks.dirt, 0, 3);
		world.setBlock(x + 10, y + 1, z + 7, Blocks.dirt, 0, 3);
		world.setBlock(x + 11, y + 1, z + 7, Blocks.dirt, 0, 3);
		world.setBlock(x + 0, y + 1, z + 8, Blocks.dirt, 0, 3);
		world.setBlock(x + 1, y + 1, z + 8, Blocks.dirt, 0, 3);
		world.setBlock(x + 2, y + 1, z + 8, Blocks.dirt, 0, 3);
		world.setBlock(x + 3, y + 1, z + 8, Blocks.dirt, 0, 3);
		world.setBlock(x + 4, y + 1, z + 8, Blocks.dirt, 0, 3);
		world.setBlock(x + 5, y + 1, z + 8, Blocks.dirt, 0, 3);
		world.setBlock(x + 6, y + 1, z + 8, Blocks.dirt, 0, 3);
		world.setBlock(x + 7, y + 1, z + 8, Blocks.dirt, 0, 3);
		world.setBlock(x + 8, y + 1, z + 8, Blocks.dirt, 0, 3);
		world.setBlock(x + 9, y + 1, z + 8, Blocks.dirt, 0, 3);
		world.setBlock(x + 10, y + 1, z + 8, Blocks.dirt, 0, 3);
		world.setBlock(x + 11, y + 1, z + 8, Blocks.dirt, 0, 3);
		world.setBlock(x + 0, y + 1, z + 9, Blocks.dirt, 0, 3);
		world.setBlock(x + 1, y + 1, z + 9, Blocks.dirt, 0, 3);
		world.setBlock(x + 2, y + 1, z + 9, Blocks.dirt, 0, 3);
		world.setBlock(x + 3, y + 1, z + 9, Blocks.dirt, 0, 3);
		world.setBlock(x + 4, y + 1, z + 9, Blocks.dirt, 0, 3);
		world.setBlock(x + 5, y + 1, z + 9, Blocks.dirt, 0, 3);
		world.setBlock(x + 6, y + 1, z + 9, Blocks.dirt, 0, 3);
		world.setBlock(x + 7, y + 1, z + 9, Blocks.dirt, 0, 3);
		world.setBlock(x + 8, y + 1, z + 9, Blocks.dirt, 0, 3);
		world.setBlock(x + 9, y + 1, z + 9, Blocks.dirt, 0, 3);
		world.setBlock(x + 10, y + 1, z + 9, Blocks.dirt, 0, 3);
		world.setBlock(x + 11, y + 1, z + 9, Blocks.dirt, 0, 3);
		world.setBlock(x + 0, y + 1, z + 10, Blocks.dirt, 0, 3);
		world.setBlock(x + 1, y + 1, z + 10, Blocks.dirt, 0, 3);
		world.setBlock(x + 2, y + 1, z + 10, Blocks.dirt, 0, 3);
		world.setBlock(x + 3, y + 1, z + 10, Blocks.dirt, 2, 3);
		world.setBlock(x + 4, y + 1, z + 10, Blocks.sand, 0, 3);
		world.setBlock(x + 5, y + 1, z + 10, Blocks.dirt, 0, 3);
		world.setBlock(x + 6, y + 1, z + 10, Blocks.dirt, 0, 3);
		world.setBlock(x + 7, y + 1, z + 10, Blocks.dirt, 0, 3);
		world.setBlock(x + 8, y + 1, z + 10, Blocks.dirt, 0, 3);
		world.setBlock(x + 9, y + 1, z + 10, Blocks.dirt, 0, 3);
		world.setBlock(x + 10, y + 1, z + 10, Blocks.dirt, 0, 3);
		world.setBlock(x + 11, y + 1, z + 10, Blocks.dirt, 0, 3);
		world.setBlock(x + 0, y + 1, z + 11, Blocks.dirt, 0, 3);
		world.setBlock(x + 1, y + 1, z + 11, Blocks.dirt, 0, 3);
		world.setBlock(x + 2, y + 1, z + 11, Blocks.dirt, 0, 3);
		world.setBlock(x + 3, y + 1, z + 11, Blocks.sand, 0, 3);
		world.setBlock(x + 4, y + 1, z + 11, FABlockRegistry.INSTANCE.tar, 0, 3);
		world.setBlock(x + 5, y + 1, z + 11, FABlockRegistry.INSTANCE.tar, 0, 3);
		world.setBlock(x + 6, y + 1, z + 11, Blocks.dirt, 2, 3);
		world.setBlock(x + 7, y + 1, z + 11, Blocks.dirt, 0, 3);
		world.setBlock(x + 8, y + 1, z + 11, Blocks.dirt, 0, 3);
		world.setBlock(x + 9, y + 1, z + 11, Blocks.dirt, 0, 3);
		world.setBlock(x + 10, y + 1, z + 11, Blocks.dirt, 0, 3);
		world.setBlock(x + 11, y + 1, z + 11, Blocks.dirt, 0, 3);
		world.setBlock(x + 0, y + 1, z + 12, Blocks.dirt, 0, 3);
		world.setBlock(x + 1, y + 1, z + 12, Blocks.dirt, 0, 3);
		world.setBlock(x + 2, y + 1, z + 12, Blocks.sand, 0, 3);
		world.setBlock(x + 3, y + 1, z + 12, FABlockRegistry.INSTANCE.tar, 0, 3);
		world.setBlock(x + 4, y + 1, z + 12, FABlockRegistry.INSTANCE.tar, 0, 3);
		world.setBlock(x + 5, y + 1, z + 12, FABlockRegistry.INSTANCE.tar, 0, 3);
		world.setBlock(x + 6, y + 1, z + 12, FABlockRegistry.INSTANCE.tar, 0, 3);
		world.setBlock(x + 7, y + 1, z + 12, Blocks.sand, 0, 3);
		world.setBlock(x + 8, y + 1, z + 12, Blocks.dirt, 0, 3);
		world.setBlock(x + 9, y + 1, z + 12, Blocks.dirt, 0, 3);
		world.setBlock(x + 10, y + 1, z + 12, Blocks.dirt, 0, 3);
		world.setBlock(x + 11, y + 1, z + 12, Blocks.dirt, 0, 3);
		world.setBlock(x + 0, y + 1, z + 13, Blocks.dirt, 0, 3);
		world.setBlock(x + 1, y + 1, z + 13, Blocks.dirt, 0, 3);
		world.setBlock(x + 2, y + 1, z + 13, Blocks.dirt, 0, 3);
		world.setBlock(x + 3, y + 1, z + 13, Blocks.sand, 0, 3);
		world.setBlock(x + 4, y + 1, z + 13, Blocks.sand, 0, 3);
		world.setBlock(x + 5, y + 1, z + 13, FABlockRegistry.INSTANCE.tar, 0, 3);
		world.setBlock(x + 6, y + 1, z + 13, FABlockRegistry.INSTANCE.tar, 0, 3);
		world.setBlock(x + 7, y + 1, z + 13, FABlockRegistry.INSTANCE.tar, 0, 3);
		world.setBlock(x + 8, y + 1, z + 13, Blocks.sand, 0, 3);
		world.setBlock(x + 9, y + 1, z + 13, Blocks.dirt, 0, 3);
		world.setBlock(x + 10, y + 1, z + 13, Blocks.dirt, 0, 3);
		world.setBlock(x + 11, y + 1, z + 13, Blocks.dirt, 0, 3);
		world.setBlock(x + 0, y + 1, z + 14, Blocks.dirt, 0, 3);
		world.setBlock(x + 1, y + 1, z + 14, Blocks.dirt, 0, 3);
		world.setBlock(x + 2, y + 1, z + 14, Blocks.dirt, 0, 3);
		world.setBlock(x + 3, y + 1, z + 14, Blocks.dirt, 0, 3);
		world.setBlock(x + 4, y + 1, z + 14, Blocks.dirt, 0, 3);
		world.setBlock(x + 5, y + 1, z + 14, Blocks.sand, 0, 3);
		world.setBlock(x + 6, y + 1, z + 14, FABlockRegistry.INSTANCE.tar, 0, 3);
		world.setBlock(x + 7, y + 1, z + 14, FABlockRegistry.INSTANCE.tar, 0, 3);
		world.setBlock(x + 8, y + 1, z + 14, Blocks.sand, 0, 3);
		world.setBlock(x + 9, y + 1, z + 14, Blocks.dirt, 0, 3);
		world.setBlock(x + 10, y + 1, z + 14, Blocks.dirt, 0, 3);
		world.setBlock(x + 11, y + 1, z + 14, Blocks.dirt, 0, 3);
		world.setBlock(x + 0, y + 1, z + 15, Blocks.dirt, 0, 3);
		world.setBlock(x + 1, y + 1, z + 15, Blocks.dirt, 0, 3);
		world.setBlock(x + 2, y + 1, z + 15, Blocks.dirt, 0, 3);
		world.setBlock(x + 3, y + 1, z + 15, Blocks.dirt, 0, 3);
		world.setBlock(x + 4, y + 1, z + 15, Blocks.sand, 0, 3);
		world.setBlock(x + 5, y + 1, z + 15, FABlockRegistry.INSTANCE.tar, 0, 3);
		world.setBlock(x + 6, y + 1, z + 15, FABlockRegistry.INSTANCE.tar, 0, 3);
		world.setBlock(x + 7, y + 1, z + 15, Blocks.sand, 0, 3);
		world.setBlock(x + 8, y + 1, z + 15, Blocks.dirt, 0, 3);
		world.setBlock(x + 9, y + 1, z + 15, Blocks.dirt, 0, 3);
		world.setBlock(x + 10, y + 1, z + 15, Blocks.dirt, 0, 3);
		world.setBlock(x + 11, y + 1, z + 15, Blocks.dirt, 0, 3);
		world.setBlock(x + 0, y + 1, z + 16, Blocks.dirt, 0, 3);
		world.setBlock(x + 1, y + 1, z + 16, Blocks.dirt, 0, 3);
		world.setBlock(x + 2, y + 1, z + 16, Blocks.dirt, 0, 3);
		world.setBlock(x + 3, y + 1, z + 16, Blocks.dirt, 0, 3);
		world.setBlock(x + 4, y + 1, z + 16, Blocks.dirt, 0, 3);
		world.setBlock(x + 5, y + 1, z + 16, Blocks.sand, 0, 3);
		world.setBlock(x + 6, y + 1, z + 16, Blocks.dirt, 2, 3);
		world.setBlock(x + 7, y + 1, z + 16, Blocks.dirt, 2, 3);
		world.setBlock(x + 8, y + 1, z + 16, Blocks.dirt, 0, 3);
		world.setBlock(x + 9, y + 1, z + 16, Blocks.dirt, 0, 3);
		world.setBlock(x + 10, y + 1, z + 16, Blocks.dirt, 0, 3);
		world.setBlock(x + 11, y + 1, z + 16, Blocks.dirt, 0, 3);
		world.setBlock(x + 0, y + 1, z + 17, Blocks.dirt, 0, 3);
		world.setBlock(x + 1, y + 1, z + 17, Blocks.dirt, 0, 3);
		world.setBlock(x + 2, y + 1, z + 17, Blocks.dirt, 0, 3);
		world.setBlock(x + 3, y + 1, z + 17, Blocks.dirt, 0, 3);
		world.setBlock(x + 4, y + 1, z + 17, Blocks.dirt, 0, 3);
		world.setBlock(x + 5, y + 1, z + 17, Blocks.dirt, 0, 3);
		world.setBlock(x + 6, y + 1, z + 17, Blocks.dirt, 0, 3);
		world.setBlock(x + 7, y + 1, z + 17, Blocks.dirt, 0, 3);
		world.setBlock(x + 8, y + 1, z + 17, Blocks.dirt, 0, 3);
		world.setBlock(x + 9, y + 1, z + 17, Blocks.dirt, 0, 3);
		world.setBlock(x + 10, y + 1, z + 17, Blocks.dirt, 0, 3);
		world.setBlock(x + 11, y + 1, z + 17, Blocks.dirt, 0, 3);
		world.setBlock(x + 0, y + 2, z + 0, Blocks.grass, 0, 3);
		world.setBlock(x + 1, y + 2, z + 0, Blocks.grass, 0, 3);
		world.setBlock(x + 2, y + 2, z + 0, Blocks.grass, 0, 3);
		world.setBlock(x + 3, y + 2, z + 0, Blocks.grass, 0, 3);
		world.setBlock(x + 4, y + 2, z + 0, Blocks.dirt, 0, 3);
		world.setBlock(x + 5, y + 2, z + 0, Blocks.dirt, 0, 3);
		world.setBlock(x + 6, y + 2, z + 0, Blocks.dirt, 0, 3);
		world.setBlock(x + 7, y + 2, z + 0, Blocks.grass, 0, 3);
		world.setBlock(x + 8, y + 2, z + 0, Blocks.grass, 0, 3);
		world.setBlock(x + 9, y + 2, z + 0, Blocks.grass, 0, 3);
		world.setBlock(x + 10, y + 2, z + 0, Blocks.grass, 0, 3);
		world.setBlock(x + 11, y + 2, z + 0, Blocks.grass, 0, 3);
		world.setBlock(x + 0, y + 2, z + 1, Blocks.grass, 0, 3);
		world.setBlock(x + 1, y + 2, z + 1, Blocks.grass, 0, 3);
		world.setBlock(x + 2, y + 2, z + 1, Blocks.grass, 0, 3);
		world.setBlock(x + 3, y + 2, z + 1, Blocks.dirt, 0, 3);
		world.setBlock(x + 4, y + 2, z + 1, Blocks.dirt, 1, 3);
		world.setBlock(x + 5, y + 2, z + 1, Blocks.dirt, 1, 3);
		world.setBlock(x + 6, y + 2, z + 1, Blocks.dirt, 1, 3);
		world.setBlock(x + 7, y + 2, z + 1, Blocks.dirt, 0, 3);
		world.setBlock(x + 8, y + 2, z + 1, Blocks.grass, 0, 3);
		world.setBlock(x + 9, y + 2, z + 1, Blocks.grass, 0, 3);
		world.setBlock(x + 10, y + 2, z + 1, Blocks.grass, 0, 3);
		world.setBlock(x + 11, y + 2, z + 1, Blocks.grass, 0, 3);
		world.setBlock(x + 0, y + 2, z + 2, Blocks.grass, 0, 3);
		world.setBlock(x + 1, y + 2, z + 2, Blocks.grass, 0, 3);
		world.setBlock(x + 2, y + 2, z + 2, Blocks.grass, 0, 3);
		world.setBlock(x + 3, y + 2, z + 2, Blocks.dirt, 0, 3);
		world.setBlock(x + 4, y + 2, z + 2, Blocks.dirt, 1, 3);
		world.setBlock(x + 5, y + 2, z + 2, Blocks.dirt, 1, 3);
		world.setBlock(x + 6, y + 2, z + 2, Blocks.dirt, 1, 3);
		world.setBlock(x + 7, y + 2, z + 2, Blocks.dirt, 0, 3);
		world.setBlock(x + 8, y + 2, z + 2, Blocks.grass, 0, 3);
		world.setBlock(x + 9, y + 2, z + 2, Blocks.grass, 0, 3);
		world.setBlock(x + 10, y + 2, z + 2, Blocks.grass, 0, 3);
		world.setBlock(x + 11, y + 2, z + 2, Blocks.grass, 0, 3);
		world.setBlock(x + 0, y + 2, z + 3, Blocks.grass, 0, 3);
		world.setBlock(x + 1, y + 2, z + 3, Blocks.grass, 0, 3);
		world.setBlock(x + 2, y + 2, z + 3, Blocks.grass, 0, 3);
		world.setBlock(x + 3, y + 2, z + 3, Blocks.dirt, 0, 3);
		world.setBlock(x + 4, y + 2, z + 3, Blocks.dirt, 1, 3);
		world.setBlock(x + 5, y + 2, z + 3, Blocks.dirt, 1, 3);
		world.setBlock(x + 6, y + 2, z + 3, Blocks.dirt, 1, 3);
		world.setBlock(x + 7, y + 2, z + 3, Blocks.dirt, 0, 3);
		world.setBlock(x + 8, y + 2, z + 3, Blocks.grass, 0, 3);
		world.setBlock(x + 9, y + 2, z + 3, Blocks.grass, 0, 3);
		world.setBlock(x + 10, y + 2, z + 3, Blocks.grass, 0, 3);
		world.setBlock(x + 11, y + 2, z + 3, Blocks.grass, 0, 3);
		world.setBlock(x + 0, y + 2, z + 4, Blocks.grass, 0, 3);
		world.setBlock(x + 1, y + 2, z + 4, Blocks.grass, 0, 3);
		world.setBlock(x + 2, y + 2, z + 4, Blocks.grass, 0, 3);
		world.setBlock(x + 3, y + 2, z + 4, Blocks.dirt, 0, 3);
		world.setBlock(x + 4, y + 2, z + 4, Blocks.dirt, 1, 3);
		world.setBlock(x + 5, y + 2, z + 4, Blocks.dirt, 1, 3);
		world.setBlock(x + 6, y + 2, z + 4, Blocks.dirt, 1, 3);
		world.setBlock(x + 7, y + 2, z + 4, Blocks.dirt, 0, 3);
		world.setBlock(x + 8, y + 2, z + 4, Blocks.grass, 0, 3);
		world.setBlock(x + 9, y + 2, z + 4, Blocks.grass, 0, 3);
		world.setBlock(x + 10, y + 2, z + 4, Blocks.grass, 0, 3);
		world.setBlock(x + 11, y + 2, z + 4, Blocks.grass, 0, 3);
		world.setBlock(x + 0, y + 2, z + 5, Blocks.grass, 0, 3);
		world.setBlock(x + 1, y + 2, z + 5, Blocks.grass, 0, 3);
		world.setBlock(x + 2, y + 2, z + 5, Blocks.grass, 0, 3);
		world.setBlock(x + 3, y + 2, z + 5, Blocks.grass, 0, 3);
		world.setBlock(x + 4, y + 2, z + 5, Blocks.dirt, 0, 3);
		world.setBlock(x + 5, y + 2, z + 5, Blocks.dirt, 1, 3);
		world.setBlock(x + 6, y + 2, z + 5, Blocks.dirt, 0, 3);
		world.setBlock(x + 7, y + 2, z + 5, Blocks.grass, 0, 3);
		world.setBlock(x + 8, y + 2, z + 5, Blocks.grass, 0, 3);
		world.setBlock(x + 9, y + 2, z + 5, Blocks.grass, 0, 3);
		world.setBlock(x + 10, y + 2, z + 5, Blocks.grass, 0, 3);
		world.setBlock(x + 11, y + 2, z + 5, Blocks.grass, 0, 3);
		world.setBlock(x + 0, y + 2, z + 6, Blocks.grass, 0, 3);
		world.setBlock(x + 1, y + 2, z + 6, Blocks.grass, 0, 3);
		world.setBlock(x + 2, y + 2, z + 6, Blocks.grass, 0, 3);
		world.setBlock(x + 3, y + 2, z + 6, Blocks.grass, 0, 3);
		world.setBlock(x + 4, y + 2, z + 6, Blocks.grass, 0, 3);
		world.setBlock(x + 5, y + 2, z + 6, Blocks.dirt, 2, 3);
		world.setBlock(x + 6, y + 2, z + 6, Blocks.grass, 0, 3);
		world.setBlock(x + 7, y + 2, z + 6, Blocks.grass, 0, 3);
		world.setBlock(x + 8, y + 2, z + 6, Blocks.grass, 0, 3);
		world.setBlock(x + 9, y + 2, z + 6, Blocks.grass, 0, 3);
		world.setBlock(x + 10, y + 2, z + 6, Blocks.grass, 0, 3);
		world.setBlock(x + 11, y + 2, z + 6, Blocks.grass, 0, 3);
		world.setBlock(x + 0, y + 2, z + 7, Blocks.grass, 0, 3);
		world.setBlock(x + 1, y + 2, z + 7, Blocks.grass, 0, 3);
		world.setBlock(x + 2, y + 2, z + 7, Blocks.grass, 0, 3);
		world.setBlock(x + 3, y + 2, z + 7, Blocks.grass, 0, 3);
		world.setBlock(x + 4, y + 2, z + 7, Blocks.dirt, 2, 3);
		world.setBlock(x + 5, y + 2, z + 7, Blocks.dirt, 2, 3);
		world.setBlock(x + 6, y + 2, z + 7, Blocks.dirt, 2, 3);
		world.setBlock(x + 7, y + 2, z + 7, Blocks.dirt, 2, 3);
		world.setBlock(x + 8, y + 2, z + 7, Blocks.dirt, 2, 3);
		world.setBlock(x + 9, y + 2, z + 7, Blocks.grass, 0, 3);
		world.setBlock(x + 10, y + 2, z + 7, Blocks.grass, 0, 3);
		world.setBlock(x + 11, y + 2, z + 7, Blocks.grass, 0, 3);
		world.setBlock(x + 0, y + 2, z + 8, Blocks.grass, 0, 3);
		world.setBlock(x + 1, y + 2, z + 8, Blocks.grass, 0, 3);
		world.setBlock(x + 2, y + 2, z + 8, Blocks.grass, 0, 3);
		world.setBlock(x + 3, y + 2, z + 8, Blocks.dirt, 2, 3);
		world.setBlock(x + 4, y + 2, z + 8, Blocks.grass, 0, 3);
		world.setBlock(x + 5, y + 2, z + 8, Blocks.dirt, 2, 3);
		world.setBlock(x + 6, y + 2, z + 8, Blocks.dirt, 2, 3);
		world.setBlock(x + 7, y + 2, z + 8, Blocks.soul_sand, 0, 3);
		world.setBlock(x + 8, y + 2, z + 8, Blocks.dirt, 2, 3);
		world.setBlock(x + 9, y + 2, z + 8, Blocks.dirt, 2, 3);
		world.setBlock(x + 10, y + 2, z + 8, Blocks.grass, 0, 3);
		world.setBlock(x + 11, y + 2, z + 8, Blocks.grass, 0, 3);
		world.setBlock(x + 0, y + 2, z + 9, Blocks.grass, 0, 3);
		world.setBlock(x + 1, y + 2, z + 9, Blocks.grass, 0, 3);
		world.setBlock(x + 2, y + 2, z + 9, Blocks.dirt, 2, 3);
		world.setBlock(x + 3, y + 2, z + 9, Blocks.dirt, 2, 3);
		world.setBlock(x + 4, y + 2, z + 9, Blocks.dirt, 2, 3);
		world.setBlock(x + 5, y + 2, z + 9, Blocks.dirt, 2, 3);
		world.setBlock(x + 6, y + 2, z + 9, Blocks.soul_sand, 0, 3);
		world.setBlock(x + 7, y + 2, z + 9, Blocks.soul_sand, 0, 3);
		world.setBlock(x + 8, y + 2, z + 9, Blocks.dirt, 2, 3);
		world.setBlock(x + 9, y + 2, z + 9, Blocks.dirt, 2, 3);
		world.setBlock(x + 10, y + 2, z + 9, Blocks.dirt, 2, 3);
		world.setBlock(x + 11, y + 2, z + 9, Blocks.grass, 0, 3);
		world.setBlock(x + 0, y + 2, z + 10, Blocks.grass, 0, 3);
		world.setBlock(x + 1, y + 2, z + 10, Blocks.grass, 0, 3);
		world.setBlock(x + 2, y + 2, z + 10, Blocks.dirt, 2, 3);
		world.setBlock(x + 5, y + 2, z + 10, Blocks.dirt, 2, 3);
		world.setBlock(x + 6, y + 2, z + 10, Blocks.dirt, 2, 3);
		world.setBlock(x + 7, y + 2, z + 10, Blocks.dirt, 2, 3);
		world.setBlock(x + 8, y + 2, z + 10, Blocks.soul_sand, 0, 3);
		world.setBlock(x + 9, y + 2, z + 10, Blocks.dirt, 2, 3);
		world.setBlock(x + 10, y + 2, z + 10, Blocks.dirt, 2, 3);
		world.setBlock(x + 11, y + 2, z + 10, Blocks.grass, 0, 3);
		world.setBlock(x + 0, y + 2, z + 11, Blocks.grass, 0, 3);
		world.setBlock(x + 1, y + 2, z + 11, Blocks.dirt, 2, 3);
		world.setBlock(x + 2, y + 2, z + 11, Blocks.dirt, 2, 3);
		world.setBlock(x + 7, y + 2, z + 11, Blocks.dirt, 2, 3);
		world.setBlock(x + 8, y + 2, z + 11, Blocks.dirt, 2, 3);
		world.setBlock(x + 9, y + 2, z + 11, Blocks.dirt, 2, 3);
		world.setBlock(x + 10, y + 2, z + 11, Blocks.dirt, 2, 3);
		world.setBlock(x + 11, y + 2, z + 11, Blocks.dirt, 2, 3);
		world.setBlock(x + 0, y + 2, z + 12, Blocks.grass, 0, 3);
		world.setBlock(x + 1, y + 2, z + 12, Blocks.dirt, 2, 3);
		world.setBlock(x + 8, y + 2, z + 12, Blocks.dirt, 2, 3);
		world.setBlock(x + 9, y + 2, z + 12, Blocks.sand, 0, 3);
		world.setBlock(x + 10, y + 2, z + 12, Blocks.grass, 0, 3);
		world.setBlock(x + 11, y + 2, z + 12, Blocks.dirt, 2, 3);
		world.setBlock(x + 0, y + 2, z + 13, Blocks.grass, 0, 3);
		world.setBlock(x + 1, y + 2, z + 13, Blocks.dirt, 2, 3);
		world.setBlock(x + 2, y + 2, z + 13, Blocks.dirt, 2, 3);
		world.setBlock(x + 9, y + 2, z + 13, Blocks.dirt, 2, 3);
		world.setBlock(x + 10, y + 2, z + 13, Blocks.grass, 0, 3);
		world.setBlock(x + 11, y + 2, z + 13, Blocks.dirt, 2, 3);
		world.setBlock(x + 0, y + 2, z + 14, Blocks.grass, 0, 3);
		world.setBlock(x + 1, y + 2, z + 14, Blocks.grass, 0, 3);
		world.setBlock(x + 2, y + 2, z + 14, Blocks.mycelium, 0, 3);
		world.setBlock(x + 3, y + 2, z + 14, Blocks.dirt, 2, 3);
		world.setBlock(x + 4, y + 2, z + 14, Blocks.dirt, 2, 3);
		world.setBlock(x + 9, y + 2, z + 14, Blocks.dirt, 2, 3);
		world.setBlock(x + 10, y + 2, z + 14, Blocks.sand, 0, 3);
		world.setBlock(x + 11, y + 2, z + 14, Blocks.dirt, 2, 3);
		world.setBlock(x + 0, y + 2, z + 15, Blocks.grass, 0, 3);
		world.setBlock(x + 1, y + 2, z + 15, Blocks.grass, 0, 3);
		world.setBlock(x + 2, y + 2, z + 15, Blocks.dirt, 2, 3);
		world.setBlock(x + 3, y + 2, z + 15, Blocks.dirt, 2, 3);
		world.setBlock(x + 8, y + 2, z + 15, Blocks.dirt, 2, 3);
		world.setBlock(x + 9, y + 2, z + 15, Blocks.dirt, 2, 3);
		world.setBlock(x + 10, y + 2, z + 15, Blocks.dirt, 2, 3);
		world.setBlock(x + 11, y + 2, z + 15, Blocks.grass, 0, 3);
		world.setBlock(x + 0, y + 2, z + 16, Blocks.grass, 0, 3);
		world.setBlock(x + 1, y + 2, z + 16, Blocks.grass, 0, 3);
		world.setBlock(x + 2, y + 2, z + 16, Blocks.dirt, 2, 3);
		world.setBlock(x + 3, y + 2, z + 16, Blocks.mycelium, 0, 3);
		world.setBlock(x + 4, y + 2, z + 16, Blocks.sand, 0, 3);
		world.setBlock(x + 8, y + 2, z + 16, Blocks.grass, 0, 3);
		world.setBlock(x + 9, y + 2, z + 16, Blocks.dirt, 2, 3);
		world.setBlock(x + 10, y + 2, z + 16, Blocks.grass, 0, 3);
		world.setBlock(x + 11, y + 2, z + 16, Blocks.grass, 0, 3);
		world.setBlock(x + 0, y + 2, z + 17, Blocks.grass, 0, 3);
		world.setBlock(x + 1, y + 2, z + 17, Blocks.grass, 0, 3);
		world.setBlock(x + 2, y + 2, z + 17, Blocks.grass, 0, 3);
		world.setBlock(x + 3, y + 2, z + 17, Blocks.dirt, 2, 3);
		world.setBlock(x + 4, y + 2, z + 17, Blocks.mycelium, 0, 3);
		world.setBlock(x + 5, y + 2, z + 17, Blocks.dirt, 2, 3);
		world.setBlock(x + 6, y + 2, z + 17, Blocks.dirt, 2, 3);
		world.setBlock(x + 7, y + 2, z + 17, Blocks.dirt, 2, 3);
		world.setBlock(x + 8, y + 2, z + 17, Blocks.dirt, 2, 3);
		world.setBlock(x + 9, y + 2, z + 17, Blocks.grass, 0, 3);
		world.setBlock(x + 10, y + 2, z + 17, Blocks.grass, 0, 3);
		world.setBlock(x + 11, y + 2, z + 17, Blocks.grass, 0, 3);
		world.setBlock(x + 3, y + 3, z + 0, Blocks.fence, 0, 3);
		world.setBlock(x + 4, y + 3, z + 0, Blocks.wool, 0, 3);
		world.setBlock(x + 5, y + 3, z + 0, Blocks.wool, 0, 3);
		world.setBlock(x + 6, y + 3, z + 0, Blocks.wool, 0, 3);
		world.setBlock(x + 7, y + 3, z + 0, Blocks.fence, 0, 3);
		world.setBlock(x + 3, y + 3, z + 1, Blocks.wool, 0, 3);
		world.setBlock(x + 4, y + 3, z + 1, Blocks.wool, 0, 3);
		world.setBlock(x + 5, y + 3, z + 1, Blocks.fence, 0, 3);
		world.setBlock(x + 6, y + 3, z + 1, Blocks.wool, 0, 3);
		world.setBlock(x + 7, y + 3, z + 1, Blocks.wool, 0, 3);
		world.setBlock(x + 3, y + 3, z + 2, Blocks.wool, 0, 3);
		world.setBlock(x + 4, y + 3, z + 2, Blocks.bed, 10, 3);
		world.setBlock(x + 6, y + 3, z + 2, Blocks.crafting_table, 0, 3);
		world.setBlock(x + 7, y + 3, z + 2, Blocks.wool, 0, 3);
		world.setBlock(x + 3, y + 3, z + 3, Blocks.wool, 0, 3);
		world.setBlock(x + 4, y + 3, z + 3, Blocks.bed, 2, 3);
		world.setBlock(x + 6, y + 3, z + 3, Blocks.bookshelf, 0, 3);
		world.setBlock(x + 7, y + 3, z + 3, Blocks.wool, 0, 3);
		world.setBlock(x + 3, y + 3, z + 4, Blocks.wool, 0, 3);
		world.setBlock(x + 4, y + 3, z + 4, Blocks.fence, 0, 3);
		world.setBlock(x + 6, y + 3, z + 4, Blocks.fence, 0, 3);
		world.setBlock(x + 7, y + 3, z + 4, Blocks.wool, 0, 3);
		world.setBlock(x + 3, y + 3, z + 5, Blocks.fence, 0, 3);
		world.setBlock(x + 4, y + 3, z + 5, Blocks.wool, 0, 3);
		world.setBlock(x + 5, y + 3, z + 5, Blocks.wooden_door, 3, 3);
		this.spawnVillager(world, x + 5, y + 3, z + 5);
		world.setBlock(x + 6, y + 3, z + 5, Blocks.wool, 0, 3);
		world.setBlock(x + 7, y + 3, z + 5, Blocks.fence, 0, 3);
		world.setBlock(x + 4, y + 3, z + 7, Blocks.cobblestone_wall, 0, 3);
		world.setBlock(x + 5, y + 3, z + 7, Blocks.cobblestone_wall, 0, 3);
		world.setBlock(x + 9, y + 3, z + 8, Blocks.cobblestone_wall, 1, 3);
		world.setBlock(x + 9, y + 3, z + 9, Blocks.cobblestone_wall, 0, 3);
		world.setBlock(x + 10, y + 3, z + 9, Blocks.cobblestone_wall, 0, 3);
		world.setBlock(x + 10, y + 3, z + 12, Blocks.tallgrass, 1, 3);
		world.setBlock(x + 1, y + 3, z + 14, Blocks.double_plant, 2, 3);
		world.setBlock(x + 10, y + 3, z + 15, Blocks.cobblestone_wall, 1, 3);
		world.setBlock(x + 8, y + 3, z + 16, Blocks.tallgrass, 1, 3);
		world.setBlock(x + 3, y + 3, z + 17, Blocks.cobblestone_wall, 0, 3);
		world.setBlock(x + 4, y + 4, z + 0, Blocks.wool, 0, 3);
		world.setBlock(x + 5, y + 4, z + 0, Blocks.wool, 0, 3);
		world.setBlock(x + 6, y + 4, z + 0, Blocks.wool, 0, 3);
		world.setBlock(x + 3, y + 4, z + 1, Blocks.wool, 0, 3);
		world.setBlock(x + 4, y + 4, z + 1, Blocks.wool, 0, 3);
		world.setBlock(x + 5, y + 4, z + 1, Blocks.fence, 0, 3);
		world.setBlock(x + 6, y + 4, z + 1, Blocks.wool, 0, 3);
		world.setBlock(x + 7, y + 4, z + 1, Blocks.wool, 0, 3);
		world.setBlock(x + 3, y + 4, z + 2, Blocks.wool, 0, 3);
		world.setBlock(x + 7, y + 4, z + 2, Blocks.wool, 0, 3);
		world.setBlock(x + 3, y + 4, z + 3, Blocks.wool, 0, 3);
		world.setBlock(x + 7, y + 4, z + 3, Blocks.wool, 0, 3);
		world.setBlock(x + 3, y + 4, z + 4, Blocks.wool, 0, 3);
		world.setBlock(x + 4, y + 4, z + 4, Blocks.fence, 0, 3);
		world.setBlock(x + 6, y + 4, z + 4, Blocks.fence, 0, 3);
		world.setBlock(x + 7, y + 4, z + 4, Blocks.wool, 0, 3);
		world.setBlock(x + 4, y + 4, z + 5, Blocks.wool, 0, 3);
		world.setBlock(x + 5, y + 4, z + 5, Blocks.wooden_door, 8, 3);
		world.setBlock(x + 6, y + 4, z + 5, Blocks.wool, 0, 3);
		world.setBlock(x + 4, y + 4, z + 8, Blocks.double_plant, 9, 3);
		world.setBlock(x + 9, y + 4, z + 8, Blocks.cobblestone_wall, 0, 3);
		world.setBlock(x + 10, y + 4, z + 13, Blocks.double_plant, 9, 3);
		world.setBlock(x + 1, y + 4, z + 14, Blocks.double_plant, 8, 3);
		world.setBlock(x + 10, y + 4, z + 15, Blocks.cobblestone_wall, 0, 3);
		world.setBlock(x + 5, y + 5, z + 0, Blocks.wool, 0, 3);
		world.setBlock(x + 4, y + 5, z + 1, Blocks.wool, 0, 3);
		world.setBlock(x + 5, y + 5, z + 1, Blocks.wool, 0, 3);
		world.setBlock(x + 6, y + 5, z + 1, Blocks.wool, 0, 3);
		world.setBlock(x + 4, y + 5, z + 2, Blocks.wool, 0, 3);
		world.setBlock(x + 6, y + 5, z + 2, Blocks.wool, 0, 3);
		world.setBlock(x + 4, y + 5, z + 3, Blocks.wool, 0, 3);
		world.setBlock(x + 6, y + 5, z + 3, Blocks.wool, 0, 3);
		world.setBlock(x + 4, y + 5, z + 4, Blocks.wool, 0, 3);
		world.setBlock(x + 6, y + 5, z + 4, Blocks.wool, 0, 3);
		world.setBlock(x + 5, y + 5, z + 5, Blocks.wool, 0, 3);
		world.setBlock(x + 9, y + 5, z + 8, Blocks.cobblestone_wall, 0, 3);
		world.setBlock(x + 5, y + 6, z + 1, Blocks.wool, 0, 3);
		world.setBlock(x + 5, y + 6, z + 2, Blocks.wool, 0, 3);
		world.setBlock(x + 5, y + 6, z + 3, Blocks.wool, 0, 3);
		world.setBlock(x + 5, y + 6, z + 4, Blocks.wool, 0, 3);
		return true;

	}

	public boolean generate_r1(World world, Random rand, int x, int y, int z) {
		world.setBlock(x + 0, y + 0, z + 11, Blocks.dirt, 0, 3);
		world.setBlock(x + 0, y + 0, z + 10, Blocks.dirt, 0, 3);
		world.setBlock(x + 0, y + 0, z + 9, Blocks.dirt, 0, 3);
		world.setBlock(x + 0, y + 0, z + 8, Blocks.dirt, 0, 3);
		world.setBlock(x + 0, y + 0, z + 7, Blocks.dirt, 0, 3);
		world.setBlock(x + 0, y + 0, z + 6, Blocks.dirt, 0, 3);
		world.setBlock(x + 0, y + 0, z + 5, Blocks.dirt, 0, 3);
		world.setBlock(x + 0, y + 0, z + 4, Blocks.dirt, 0, 3);
		world.setBlock(x + 0, y + 0, z + 3, Blocks.dirt, 0, 3);
		world.setBlock(x + 0, y + 0, z + 2, Blocks.dirt, 0, 3);
		world.setBlock(x + 0, y + 0, z + 1, Blocks.dirt, 0, 3);
		world.setBlock(x + 0, y + 0, z + 0, Blocks.dirt, 0, 3);
		world.setBlock(x + 1, y + 0, z + 11, Blocks.dirt, 0, 3);
		world.setBlock(x + 1, y + 0, z + 10, Blocks.dirt, 0, 3);
		world.setBlock(x + 1, y + 0, z + 9, Blocks.dirt, 0, 3);
		world.setBlock(x + 1, y + 0, z + 8, Blocks.dirt, 0, 3);
		world.setBlock(x + 1, y + 0, z + 7, Blocks.dirt, 0, 3);
		world.setBlock(x + 1, y + 0, z + 6, Blocks.dirt, 0, 3);
		world.setBlock(x + 1, y + 0, z + 5, Blocks.dirt, 0, 3);
		world.setBlock(x + 1, y + 0, z + 4, Blocks.dirt, 0, 3);
		world.setBlock(x + 1, y + 0, z + 3, Blocks.dirt, 0, 3);
		world.setBlock(x + 1, y + 0, z + 2, Blocks.dirt, 0, 3);
		world.setBlock(x + 1, y + 0, z + 1, Blocks.dirt, 0, 3);
		world.setBlock(x + 1, y + 0, z + 0, Blocks.dirt, 0, 3);
		world.setBlock(x + 2, y + 0, z + 11, Blocks.dirt, 0, 3);
		world.setBlock(x + 2, y + 0, z + 10, Blocks.dirt, 0, 3);
		world.setBlock(x + 2, y + 0, z + 9, Blocks.dirt, 0, 3);
		world.setBlock(x + 2, y + 0, z + 8, Blocks.dirt, 0, 3);
		world.setBlock(x + 2, y + 0, z + 7, Blocks.dirt, 0, 3);
		world.setBlock(x + 2, y + 0, z + 6, Blocks.dirt, 0, 3);
		world.setBlock(x + 2, y + 0, z + 5, Blocks.dirt, 0, 3);
		world.setBlock(x + 2, y + 0, z + 4, Blocks.dirt, 0, 3);
		world.setBlock(x + 2, y + 0, z + 3, Blocks.dirt, 0, 3);
		world.setBlock(x + 2, y + 0, z + 2, Blocks.dirt, 0, 3);
		world.setBlock(x + 2, y + 0, z + 1, Blocks.dirt, 0, 3);
		world.setBlock(x + 2, y + 0, z + 0, Blocks.dirt, 0, 3);
		world.setBlock(x + 3, y + 0, z + 11, Blocks.dirt, 0, 3);
		world.setBlock(x + 3, y + 0, z + 10, Blocks.dirt, 0, 3);
		world.setBlock(x + 3, y + 0, z + 9, Blocks.dirt, 0, 3);
		world.setBlock(x + 3, y + 0, z + 8, Blocks.dirt, 0, 3);
		world.setBlock(x + 3, y + 0, z + 7, Blocks.dirt, 0, 3);
		world.setBlock(x + 3, y + 0, z + 6, Blocks.dirt, 0, 3);
		world.setBlock(x + 3, y + 0, z + 5, Blocks.dirt, 0, 3);
		world.setBlock(x + 3, y + 0, z + 4, Blocks.dirt, 0, 3);
		world.setBlock(x + 3, y + 0, z + 3, Blocks.dirt, 0, 3);
		world.setBlock(x + 3, y + 0, z + 2, Blocks.dirt, 0, 3);
		world.setBlock(x + 3, y + 0, z + 1, Blocks.dirt, 0, 3);
		world.setBlock(x + 3, y + 0, z + 0, Blocks.dirt, 0, 3);
		world.setBlock(x + 4, y + 0, z + 11, Blocks.dirt, 0, 3);
		world.setBlock(x + 4, y + 0, z + 10, Blocks.dirt, 0, 3);
		world.setBlock(x + 4, y + 0, z + 9, Blocks.dirt, 0, 3);
		world.setBlock(x + 4, y + 0, z + 8, Blocks.dirt, 0, 3);
		world.setBlock(x + 4, y + 0, z + 7, Blocks.dirt, 0, 3);
		world.setBlock(x + 4, y + 0, z + 6, Blocks.dirt, 0, 3);
		world.setBlock(x + 4, y + 0, z + 5, Blocks.dirt, 0, 3);
		world.setBlock(x + 4, y + 0, z + 4, Blocks.dirt, 0, 3);
		world.setBlock(x + 4, y + 0, z + 3, Blocks.dirt, 0, 3);
		world.setBlock(x + 4, y + 0, z + 2, Blocks.dirt, 0, 3);
		world.setBlock(x + 4, y + 0, z + 1, Blocks.dirt, 0, 3);
		world.setBlock(x + 4, y + 0, z + 0, Blocks.dirt, 0, 3);
		world.setBlock(x + 5, y + 0, z + 11, Blocks.dirt, 0, 3);
		world.setBlock(x + 5, y + 0, z + 10, Blocks.dirt, 0, 3);
		world.setBlock(x + 5, y + 0, z + 9, Blocks.dirt, 0, 3);
		world.setBlock(x + 5, y + 0, z + 8, Blocks.dirt, 0, 3);
		world.setBlock(x + 5, y + 0, z + 7, Blocks.dirt, 0, 3);
		world.setBlock(x + 5, y + 0, z + 6, Blocks.dirt, 0, 3);
		world.setBlock(x + 5, y + 0, z + 5, Blocks.dirt, 0, 3);
		world.setBlock(x + 5, y + 0, z + 4, Blocks.dirt, 0, 3);
		world.setBlock(x + 5, y + 0, z + 3, Blocks.dirt, 0, 3);
		world.setBlock(x + 5, y + 0, z + 2, Blocks.dirt, 0, 3);
		world.setBlock(x + 5, y + 0, z + 1, Blocks.dirt, 0, 3);
		world.setBlock(x + 5, y + 0, z + 0, Blocks.dirt, 0, 3);
		world.setBlock(x + 6, y + 0, z + 11, Blocks.dirt, 0, 3);
		world.setBlock(x + 6, y + 0, z + 10, Blocks.dirt, 0, 3);
		world.setBlock(x + 6, y + 0, z + 9, Blocks.dirt, 0, 3);
		world.setBlock(x + 6, y + 0, z + 8, Blocks.dirt, 0, 3);
		world.setBlock(x + 6, y + 0, z + 7, Blocks.dirt, 0, 3);
		world.setBlock(x + 6, y + 0, z + 6, Blocks.dirt, 0, 3);
		world.setBlock(x + 6, y + 0, z + 5, Blocks.dirt, 0, 3);
		world.setBlock(x + 6, y + 0, z + 4, Blocks.dirt, 0, 3);
		world.setBlock(x + 6, y + 0, z + 3, Blocks.dirt, 0, 3);
		world.setBlock(x + 6, y + 0, z + 2, Blocks.dirt, 0, 3);
		world.setBlock(x + 6, y + 0, z + 1, Blocks.dirt, 0, 3);
		world.setBlock(x + 6, y + 0, z + 0, Blocks.dirt, 0, 3);
		world.setBlock(x + 7, y + 0, z + 11, Blocks.dirt, 0, 3);
		world.setBlock(x + 7, y + 0, z + 10, Blocks.dirt, 0, 3);
		world.setBlock(x + 7, y + 0, z + 9, Blocks.dirt, 0, 3);
		world.setBlock(x + 7, y + 0, z + 8, Blocks.dirt, 0, 3);
		world.setBlock(x + 7, y + 0, z + 7, Blocks.dirt, 0, 3);
		world.setBlock(x + 7, y + 0, z + 6, Blocks.dirt, 0, 3);
		world.setBlock(x + 7, y + 0, z + 5, Blocks.dirt, 0, 3);
		world.setBlock(x + 7, y + 0, z + 4, Blocks.dirt, 0, 3);
		world.setBlock(x + 7, y + 0, z + 3, Blocks.dirt, 0, 3);
		world.setBlock(x + 7, y + 0, z + 2, Blocks.dirt, 0, 3);
		world.setBlock(x + 7, y + 0, z + 1, Blocks.dirt, 0, 3);
		world.setBlock(x + 7, y + 0, z + 0, Blocks.dirt, 0, 3);
		world.setBlock(x + 8, y + 0, z + 11, Blocks.dirt, 0, 3);
		world.setBlock(x + 8, y + 0, z + 10, Blocks.dirt, 0, 3);
		world.setBlock(x + 8, y + 0, z + 9, Blocks.dirt, 0, 3);
		world.setBlock(x + 8, y + 0, z + 8, Blocks.dirt, 0, 3);
		world.setBlock(x + 8, y + 0, z + 7, Blocks.dirt, 0, 3);
		world.setBlock(x + 8, y + 0, z + 6, Blocks.dirt, 0, 3);
		world.setBlock(x + 8, y + 0, z + 5, Blocks.dirt, 0, 3);
		world.setBlock(x + 8, y + 0, z + 4, Blocks.dirt, 0, 3);
		world.setBlock(x + 8, y + 0, z + 3, Blocks.dirt, 0, 3);
		world.setBlock(x + 8, y + 0, z + 2, Blocks.dirt, 0, 3);
		world.setBlock(x + 8, y + 0, z + 1, Blocks.dirt, 0, 3);
		world.setBlock(x + 8, y + 0, z + 0, Blocks.dirt, 0, 3);
		world.setBlock(x + 9, y + 0, z + 11, Blocks.dirt, 0, 3);
		world.setBlock(x + 9, y + 0, z + 10, Blocks.dirt, 0, 3);
		world.setBlock(x + 9, y + 0, z + 9, Blocks.dirt, 0, 3);
		world.setBlock(x + 9, y + 0, z + 8, Blocks.dirt, 0, 3);
		world.setBlock(x + 9, y + 0, z + 7, Blocks.dirt, 0, 3);
		world.setBlock(x + 9, y + 0, z + 6, Blocks.dirt, 0, 3);
		world.setBlock(x + 9, y + 0, z + 5, Blocks.dirt, 0, 3);
		world.setBlock(x + 9, y + 0, z + 4, Blocks.dirt, 0, 3);
		world.setBlock(x + 9, y + 0, z + 3, Blocks.dirt, 0, 3);
		world.setBlock(x + 9, y + 0, z + 2, Blocks.dirt, 0, 3);
		world.setBlock(x + 9, y + 0, z + 1, Blocks.dirt, 0, 3);
		world.setBlock(x + 9, y + 0, z + 0, Blocks.dirt, 0, 3);
		world.setBlock(x + 10, y + 0, z + 11, Blocks.dirt, 0, 3);
		world.setBlock(x + 10, y + 0, z + 10, Blocks.dirt, 0, 3);
		world.setBlock(x + 10, y + 0, z + 9, Blocks.dirt, 0, 3);
		world.setBlock(x + 10, y + 0, z + 8, Blocks.dirt, 0, 3);
		world.setBlock(x + 10, y + 0, z + 7, Blocks.dirt, 0, 3);
		world.setBlock(x + 10, y + 0, z + 6, Blocks.dirt, 0, 3);
		world.setBlock(x + 10, y + 0, z + 5, Blocks.dirt, 0, 3);
		world.setBlock(x + 10, y + 0, z + 4, Blocks.dirt, 0, 3);
		world.setBlock(x + 10, y + 0, z + 3, Blocks.dirt, 0, 3);
		world.setBlock(x + 10, y + 0, z + 2, Blocks.dirt, 0, 3);
		world.setBlock(x + 10, y + 0, z + 1, Blocks.dirt, 0, 3);
		world.setBlock(x + 10, y + 0, z + 0, Blocks.dirt, 0, 3);
		world.setBlock(x + 11, y + 0, z + 11, Blocks.dirt, 0, 3);
		world.setBlock(x + 11, y + 0, z + 10, Blocks.dirt, 0, 3);
		world.setBlock(x + 11, y + 0, z + 9, Blocks.dirt, 0, 3);
		world.setBlock(x + 11, y + 0, z + 8, Blocks.dirt, 0, 3);
		world.setBlock(x + 11, y + 0, z + 7, Blocks.dirt, 0, 3);
		world.setBlock(x + 11, y + 0, z + 6, Blocks.dirt, 0, 3);
		world.setBlock(x + 11, y + 0, z + 5, Blocks.dirt, 0, 3);
		world.setBlock(x + 11, y + 0, z + 4, Blocks.dirt, 0, 3);
		world.setBlock(x + 11, y + 0, z + 3, Blocks.dirt, 0, 3);
		world.setBlock(x + 11, y + 0, z + 2, Blocks.dirt, 0, 3);
		world.setBlock(x + 11, y + 0, z + 1, Blocks.dirt, 0, 3);
		world.setBlock(x + 11, y + 0, z + 0, Blocks.dirt, 0, 3);
		world.setBlock(x + 12, y + 0, z + 11, Blocks.dirt, 0, 3);
		world.setBlock(x + 12, y + 0, z + 10, Blocks.dirt, 0, 3);
		world.setBlock(x + 12, y + 0, z + 9, Blocks.dirt, 0, 3);
		world.setBlock(x + 12, y + 0, z + 8, Blocks.dirt, 0, 3);
		world.setBlock(x + 12, y + 0, z + 7, Blocks.dirt, 0, 3);
		world.setBlock(x + 12, y + 0, z + 6, Blocks.dirt, 0, 3);
		world.setBlock(x + 12, y + 0, z + 5, Blocks.dirt, 0, 3);
		world.setBlock(x + 12, y + 0, z + 4, Blocks.dirt, 0, 3);
		world.setBlock(x + 12, y + 0, z + 3, Blocks.dirt, 0, 3);
		world.setBlock(x + 12, y + 0, z + 2, Blocks.dirt, 0, 3);
		world.setBlock(x + 12, y + 0, z + 1, Blocks.dirt, 0, 3);
		world.setBlock(x + 12, y + 0, z + 0, Blocks.dirt, 0, 3);
		world.setBlock(x + 13, y + 0, z + 11, Blocks.dirt, 0, 3);
		world.setBlock(x + 13, y + 0, z + 10, Blocks.dirt, 0, 3);
		world.setBlock(x + 13, y + 0, z + 9, Blocks.dirt, 0, 3);
		world.setBlock(x + 13, y + 0, z + 8, Blocks.dirt, 0, 3);
		world.setBlock(x + 13, y + 0, z + 7, Blocks.dirt, 0, 3);
		world.setBlock(x + 13, y + 0, z + 6, Blocks.dirt, 0, 3);
		world.setBlock(x + 13, y + 0, z + 5, Blocks.dirt, 0, 3);
		world.setBlock(x + 13, y + 0, z + 4, Blocks.dirt, 0, 3);
		world.setBlock(x + 13, y + 0, z + 3, Blocks.dirt, 0, 3);
		world.setBlock(x + 13, y + 0, z + 2, Blocks.dirt, 0, 3);
		world.setBlock(x + 13, y + 0, z + 1, Blocks.dirt, 0, 3);
		world.setBlock(x + 13, y + 0, z + 0, Blocks.dirt, 0, 3);
		world.setBlock(x + 14, y + 0, z + 11, Blocks.dirt, 0, 3);
		world.setBlock(x + 14, y + 0, z + 10, Blocks.dirt, 0, 3);
		world.setBlock(x + 14, y + 0, z + 9, Blocks.dirt, 0, 3);
		world.setBlock(x + 14, y + 0, z + 8, Blocks.dirt, 0, 3);
		world.setBlock(x + 14, y + 0, z + 7, Blocks.dirt, 0, 3);
		world.setBlock(x + 14, y + 0, z + 6, Blocks.dirt, 0, 3);
		world.setBlock(x + 14, y + 0, z + 5, Blocks.dirt, 0, 3);
		world.setBlock(x + 14, y + 0, z + 4, Blocks.dirt, 0, 3);
		world.setBlock(x + 14, y + 0, z + 3, Blocks.dirt, 0, 3);
		world.setBlock(x + 14, y + 0, z + 2, Blocks.dirt, 0, 3);
		world.setBlock(x + 14, y + 0, z + 1, Blocks.dirt, 0, 3);
		world.setBlock(x + 14, y + 0, z + 0, Blocks.dirt, 0, 3);
		world.setBlock(x + 15, y + 0, z + 11, Blocks.dirt, 0, 3);
		world.setBlock(x + 15, y + 0, z + 10, Blocks.dirt, 0, 3);
		world.setBlock(x + 15, y + 0, z + 9, Blocks.dirt, 0, 3);
		world.setBlock(x + 15, y + 0, z + 8, Blocks.dirt, 0, 3);
		world.setBlock(x + 15, y + 0, z + 7, Blocks.dirt, 0, 3);
		world.setBlock(x + 15, y + 0, z + 6, Blocks.dirt, 0, 3);
		world.setBlock(x + 15, y + 0, z + 5, Blocks.dirt, 0, 3);
		world.setBlock(x + 15, y + 0, z + 4, Blocks.dirt, 0, 3);
		world.setBlock(x + 15, y + 0, z + 3, Blocks.dirt, 0, 3);
		world.setBlock(x + 15, y + 0, z + 2, Blocks.dirt, 0, 3);
		world.setBlock(x + 15, y + 0, z + 1, Blocks.dirt, 0, 3);
		world.setBlock(x + 15, y + 0, z + 0, Blocks.dirt, 0, 3);
		world.setBlock(x + 16, y + 0, z + 11, Blocks.dirt, 0, 3);
		world.setBlock(x + 16, y + 0, z + 10, Blocks.dirt, 0, 3);
		world.setBlock(x + 16, y + 0, z + 9, Blocks.dirt, 0, 3);
		world.setBlock(x + 16, y + 0, z + 8, Blocks.dirt, 0, 3);
		world.setBlock(x + 16, y + 0, z + 7, Blocks.dirt, 0, 3);
		world.setBlock(x + 16, y + 0, z + 6, Blocks.dirt, 0, 3);
		world.setBlock(x + 16, y + 0, z + 5, Blocks.dirt, 0, 3);
		world.setBlock(x + 16, y + 0, z + 4, Blocks.dirt, 0, 3);
		world.setBlock(x + 16, y + 0, z + 3, Blocks.dirt, 0, 3);
		world.setBlock(x + 16, y + 0, z + 2, Blocks.dirt, 0, 3);
		world.setBlock(x + 16, y + 0, z + 1, Blocks.dirt, 0, 3);
		world.setBlock(x + 16, y + 0, z + 0, Blocks.dirt, 0, 3);
		world.setBlock(x + 17, y + 0, z + 11, Blocks.dirt, 0, 3);
		world.setBlock(x + 17, y + 0, z + 10, Blocks.dirt, 0, 3);
		world.setBlock(x + 17, y + 0, z + 9, Blocks.dirt, 0, 3);
		world.setBlock(x + 17, y + 0, z + 8, Blocks.dirt, 0, 3);
		world.setBlock(x + 17, y + 0, z + 7, Blocks.dirt, 0, 3);
		world.setBlock(x + 17, y + 0, z + 6, Blocks.dirt, 0, 3);
		world.setBlock(x + 17, y + 0, z + 5, Blocks.dirt, 0, 3);
		world.setBlock(x + 17, y + 0, z + 4, Blocks.dirt, 0, 3);
		world.setBlock(x + 17, y + 0, z + 3, Blocks.dirt, 0, 3);
		world.setBlock(x + 17, y + 0, z + 2, Blocks.dirt, 0, 3);
		world.setBlock(x + 17, y + 0, z + 1, Blocks.dirt, 0, 3);
		world.setBlock(x + 17, y + 0, z + 0, Blocks.dirt, 0, 3);
		world.setBlock(x + 0, y + 1, z + 11, Blocks.dirt, 0, 3);
		world.setBlock(x + 0, y + 1, z + 10, Blocks.dirt, 0, 3);
		world.setBlock(x + 0, y + 1, z + 9, Blocks.dirt, 0, 3);
		world.setBlock(x + 0, y + 1, z + 8, Blocks.dirt, 0, 3);
		world.setBlock(x + 0, y + 1, z + 7, Blocks.dirt, 0, 3);
		world.setBlock(x + 0, y + 1, z + 6, Blocks.dirt, 0, 3);
		world.setBlock(x + 0, y + 1, z + 5, Blocks.dirt, 0, 3);
		world.setBlock(x + 0, y + 1, z + 4, Blocks.dirt, 0, 3);
		world.setBlock(x + 0, y + 1, z + 3, Blocks.dirt, 0, 3);
		world.setBlock(x + 0, y + 1, z + 2, Blocks.dirt, 0, 3);
		world.setBlock(x + 0, y + 1, z + 1, Blocks.dirt, 0, 3);
		world.setBlock(x + 0, y + 1, z + 0, Blocks.dirt, 0, 3);
		world.setBlock(x + 1, y + 1, z + 11, Blocks.dirt, 0, 3);
		world.setBlock(x + 1, y + 1, z + 10, Blocks.dirt, 0, 3);
		world.setBlock(x + 1, y + 1, z + 9, Blocks.dirt, 0, 3);
		world.setBlock(x + 1, y + 1, z + 8, Blocks.dirt, 0, 3);
		world.setBlock(x + 1, y + 1, z + 7, Blocks.dirt, 0, 3);
		world.setBlock(x + 1, y + 1, z + 6, Blocks.dirt, 0, 3);
		world.setBlock(x + 1, y + 1, z + 5, Blocks.dirt, 0, 3);
		world.setBlock(x + 1, y + 1, z + 4, Blocks.dirt, 0, 3);
		world.setBlock(x + 1, y + 1, z + 3, Blocks.dirt, 0, 3);
		world.setBlock(x + 1, y + 1, z + 2, Blocks.dirt, 0, 3);
		world.setBlock(x + 1, y + 1, z + 1, Blocks.dirt, 0, 3);
		world.setBlock(x + 1, y + 1, z + 0, Blocks.dirt, 0, 3);
		world.setBlock(x + 2, y + 1, z + 11, Blocks.dirt, 0, 3);
		world.setBlock(x + 2, y + 1, z + 10, Blocks.dirt, 0, 3);
		world.setBlock(x + 2, y + 1, z + 9, Blocks.dirt, 0, 3);
		world.setBlock(x + 2, y + 1, z + 8, Blocks.dirt, 0, 3);
		world.setBlock(x + 2, y + 1, z + 7, Blocks.dirt, 0, 3);
		world.setBlock(x + 2, y + 1, z + 6, Blocks.dirt, 0, 3);
		world.setBlock(x + 2, y + 1, z + 5, Blocks.dirt, 0, 3);
		world.setBlock(x + 2, y + 1, z + 4, Blocks.dirt, 0, 3);
		world.setBlock(x + 2, y + 1, z + 3, Blocks.dirt, 0, 3);
		world.setBlock(x + 2, y + 1, z + 2, Blocks.dirt, 0, 3);
		world.setBlock(x + 2, y + 1, z + 1, Blocks.dirt, 0, 3);
		world.setBlock(x + 2, y + 1, z + 0, Blocks.dirt, 0, 3);
		world.setBlock(x + 3, y + 1, z + 11, Blocks.dirt, 0, 3);
		world.setBlock(x + 3, y + 1, z + 10, Blocks.dirt, 0, 3);
		world.setBlock(x + 3, y + 1, z + 9, Blocks.dirt, 0, 3);
		world.setBlock(x + 3, y + 1, z + 8, Blocks.dirt, 0, 3);
		world.setBlock(x + 3, y + 1, z + 7, Blocks.dirt, 0, 3);
		world.setBlock(x + 3, y + 1, z + 6, Blocks.dirt, 0, 3);
		world.setBlock(x + 3, y + 1, z + 5, Blocks.dirt, 0, 3);
		world.setBlock(x + 3, y + 1, z + 4, Blocks.dirt, 0, 3);
		world.setBlock(x + 3, y + 1, z + 3, Blocks.dirt, 0, 3);
		world.setBlock(x + 3, y + 1, z + 2, Blocks.dirt, 0, 3);
		world.setBlock(x + 3, y + 1, z + 1, Blocks.dirt, 0, 3);
		world.setBlock(x + 3, y + 1, z + 0, Blocks.dirt, 0, 3);
		world.setBlock(x + 4, y + 1, z + 11, Blocks.dirt, 0, 3);
		world.setBlock(x + 4, y + 1, z + 10, Blocks.dirt, 0, 3);
		world.setBlock(x + 4, y + 1, z + 9, Blocks.dirt, 0, 3);
		world.setBlock(x + 4, y + 1, z + 8, Blocks.dirt, 0, 3);
		world.setBlock(x + 4, y + 1, z + 7, Blocks.dirt, 0, 3);
		world.setBlock(x + 4, y + 1, z + 6, Blocks.dirt, 0, 3);
		world.setBlock(x + 4, y + 1, z + 5, Blocks.dirt, 0, 3);
		world.setBlock(x + 4, y + 1, z + 4, Blocks.dirt, 0, 3);
		world.setBlock(x + 4, y + 1, z + 3, Blocks.dirt, 0, 3);
		world.setBlock(x + 4, y + 1, z + 2, Blocks.dirt, 0, 3);
		world.setBlock(x + 4, y + 1, z + 1, Blocks.dirt, 0, 3);
		world.setBlock(x + 4, y + 1, z + 0, Blocks.dirt, 0, 3);
		world.setBlock(x + 5, y + 1, z + 11, Blocks.dirt, 0, 3);
		world.setBlock(x + 5, y + 1, z + 10, Blocks.dirt, 0, 3);
		world.setBlock(x + 5, y + 1, z + 9, Blocks.dirt, 0, 3);
		world.setBlock(x + 5, y + 1, z + 8, Blocks.dirt, 0, 3);
		world.setBlock(x + 5, y + 1, z + 7, Blocks.dirt, 0, 3);
		world.setBlock(x + 5, y + 1, z + 6, Blocks.dirt, 0, 3);
		world.setBlock(x + 5, y + 1, z + 5, Blocks.dirt, 0, 3);
		world.setBlock(x + 5, y + 1, z + 4, Blocks.dirt, 0, 3);
		world.setBlock(x + 5, y + 1, z + 3, Blocks.dirt, 0, 3);
		world.setBlock(x + 5, y + 1, z + 2, Blocks.dirt, 0, 3);
		world.setBlock(x + 5, y + 1, z + 1, Blocks.dirt, 0, 3);
		world.setBlock(x + 5, y + 1, z + 0, Blocks.dirt, 0, 3);
		world.setBlock(x + 6, y + 1, z + 11, Blocks.dirt, 0, 3);
		world.setBlock(x + 6, y + 1, z + 10, Blocks.dirt, 0, 3);
		world.setBlock(x + 6, y + 1, z + 9, Blocks.dirt, 0, 3);
		world.setBlock(x + 6, y + 1, z + 8, Blocks.dirt, 0, 3);
		world.setBlock(x + 6, y + 1, z + 7, Blocks.dirt, 0, 3);
		world.setBlock(x + 6, y + 1, z + 6, Blocks.dirt, 0, 3);
		world.setBlock(x + 6, y + 1, z + 5, Blocks.dirt, 0, 3);
		world.setBlock(x + 6, y + 1, z + 4, Blocks.dirt, 0, 3);
		world.setBlock(x + 6, y + 1, z + 3, Blocks.dirt, 0, 3);
		world.setBlock(x + 6, y + 1, z + 2, Blocks.dirt, 0, 3);
		world.setBlock(x + 6, y + 1, z + 1, Blocks.dirt, 0, 3);
		world.setBlock(x + 6, y + 1, z + 0, Blocks.dirt, 0, 3);
		world.setBlock(x + 7, y + 1, z + 11, Blocks.dirt, 0, 3);
		world.setBlock(x + 7, y + 1, z + 10, Blocks.dirt, 0, 3);
		world.setBlock(x + 7, y + 1, z + 9, Blocks.dirt, 0, 3);
		world.setBlock(x + 7, y + 1, z + 8, Blocks.dirt, 0, 3);
		world.setBlock(x + 7, y + 1, z + 7, Blocks.dirt, 0, 3);
		world.setBlock(x + 7, y + 1, z + 6, Blocks.dirt, 0, 3);
		world.setBlock(x + 7, y + 1, z + 5, Blocks.dirt, 0, 3);
		world.setBlock(x + 7, y + 1, z + 4, Blocks.dirt, 0, 3);
		world.setBlock(x + 7, y + 1, z + 3, Blocks.dirt, 0, 3);
		world.setBlock(x + 7, y + 1, z + 2, Blocks.dirt, 0, 3);
		world.setBlock(x + 7, y + 1, z + 1, Blocks.dirt, 0, 3);
		world.setBlock(x + 7, y + 1, z + 0, Blocks.dirt, 0, 3);
		world.setBlock(x + 8, y + 1, z + 11, Blocks.dirt, 0, 3);
		world.setBlock(x + 8, y + 1, z + 10, Blocks.dirt, 0, 3);
		world.setBlock(x + 8, y + 1, z + 9, Blocks.dirt, 0, 3);
		world.setBlock(x + 8, y + 1, z + 8, Blocks.dirt, 0, 3);
		world.setBlock(x + 8, y + 1, z + 7, Blocks.dirt, 0, 3);
		world.setBlock(x + 8, y + 1, z + 6, Blocks.dirt, 0, 3);
		world.setBlock(x + 8, y + 1, z + 5, Blocks.dirt, 0, 3);
		world.setBlock(x + 8, y + 1, z + 4, Blocks.dirt, 0, 3);
		world.setBlock(x + 8, y + 1, z + 3, Blocks.dirt, 0, 3);
		world.setBlock(x + 8, y + 1, z + 2, Blocks.dirt, 0, 3);
		world.setBlock(x + 8, y + 1, z + 1, Blocks.dirt, 0, 3);
		world.setBlock(x + 8, y + 1, z + 0, Blocks.dirt, 0, 3);
		world.setBlock(x + 9, y + 1, z + 11, Blocks.dirt, 0, 3);
		world.setBlock(x + 9, y + 1, z + 10, Blocks.dirt, 0, 3);
		world.setBlock(x + 9, y + 1, z + 9, Blocks.dirt, 0, 3);
		world.setBlock(x + 9, y + 1, z + 8, Blocks.dirt, 0, 3);
		world.setBlock(x + 9, y + 1, z + 7, Blocks.dirt, 0, 3);
		world.setBlock(x + 9, y + 1, z + 6, Blocks.dirt, 0, 3);
		world.setBlock(x + 9, y + 1, z + 5, Blocks.dirt, 0, 3);
		world.setBlock(x + 9, y + 1, z + 4, Blocks.dirt, 0, 3);
		world.setBlock(x + 9, y + 1, z + 3, Blocks.dirt, 0, 3);
		world.setBlock(x + 9, y + 1, z + 2, Blocks.dirt, 0, 3);
		world.setBlock(x + 9, y + 1, z + 1, Blocks.dirt, 0, 3);
		world.setBlock(x + 9, y + 1, z + 0, Blocks.dirt, 0, 3);
		world.setBlock(x + 10, y + 1, z + 11, Blocks.dirt, 0, 3);
		world.setBlock(x + 10, y + 1, z + 10, Blocks.dirt, 0, 3);
		world.setBlock(x + 10, y + 1, z + 9, Blocks.dirt, 0, 3);
		world.setBlock(x + 10, y + 1, z + 8, Blocks.dirt, 2, 3);
		world.setBlock(x + 10, y + 1, z + 7, Blocks.sand, 0, 3);
		world.setBlock(x + 10, y + 1, z + 6, Blocks.dirt, 0, 3);
		world.setBlock(x + 10, y + 1, z + 5, Blocks.dirt, 0, 3);
		world.setBlock(x + 10, y + 1, z + 4, Blocks.dirt, 0, 3);
		world.setBlock(x + 10, y + 1, z + 3, Blocks.dirt, 0, 3);
		world.setBlock(x + 10, y + 1, z + 2, Blocks.dirt, 0, 3);
		world.setBlock(x + 10, y + 1, z + 1, Blocks.dirt, 0, 3);
		world.setBlock(x + 10, y + 1, z + 0, Blocks.dirt, 0, 3);
		world.setBlock(x + 11, y + 1, z + 11, Blocks.dirt, 0, 3);
		world.setBlock(x + 11, y + 1, z + 10, Blocks.dirt, 0, 3);
		world.setBlock(x + 11, y + 1, z + 9, Blocks.dirt, 0, 3);
		world.setBlock(x + 11, y + 1, z + 8, Blocks.sand, 0, 3);
		world.setBlock(x + 11, y + 1, z + 7, FABlockRegistry.INSTANCE.tar, 0, 3);
		world.setBlock(x + 11, y + 1, z + 6, FABlockRegistry.INSTANCE.tar, 0, 3);
		world.setBlock(x + 11, y + 1, z + 5, Blocks.dirt, 2, 3);
		world.setBlock(x + 11, y + 1, z + 4, Blocks.dirt, 0, 3);
		world.setBlock(x + 11, y + 1, z + 3, Blocks.dirt, 0, 3);
		world.setBlock(x + 11, y + 1, z + 2, Blocks.dirt, 0, 3);
		world.setBlock(x + 11, y + 1, z + 1, Blocks.dirt, 0, 3);
		world.setBlock(x + 11, y + 1, z + 0, Blocks.dirt, 0, 3);
		world.setBlock(x + 12, y + 1, z + 11, Blocks.dirt, 0, 3);
		world.setBlock(x + 12, y + 1, z + 10, Blocks.dirt, 0, 3);
		world.setBlock(x + 12, y + 1, z + 9, Blocks.sand, 0, 3);
		world.setBlock(x + 12, y + 1, z + 8, FABlockRegistry.INSTANCE.tar, 0, 3);
		world.setBlock(x + 12, y + 1, z + 7, FABlockRegistry.INSTANCE.tar, 0, 3);
		world.setBlock(x + 12, y + 1, z + 6, FABlockRegistry.INSTANCE.tar, 0, 3);
		world.setBlock(x + 12, y + 1, z + 5, FABlockRegistry.INSTANCE.tar, 0, 3);
		world.setBlock(x + 12, y + 1, z + 4, Blocks.sand, 0, 3);
		world.setBlock(x + 12, y + 1, z + 3, Blocks.dirt, 0, 3);
		world.setBlock(x + 12, y + 1, z + 2, Blocks.dirt, 0, 3);
		world.setBlock(x + 12, y + 1, z + 1, Blocks.dirt, 0, 3);
		world.setBlock(x + 12, y + 1, z + 0, Blocks.dirt, 0, 3);
		world.setBlock(x + 13, y + 1, z + 11, Blocks.dirt, 0, 3);
		world.setBlock(x + 13, y + 1, z + 10, Blocks.dirt, 0, 3);
		world.setBlock(x + 13, y + 1, z + 9, Blocks.dirt, 0, 3);
		world.setBlock(x + 13, y + 1, z + 8, Blocks.sand, 0, 3);
		world.setBlock(x + 13, y + 1, z + 7, Blocks.sand, 0, 3);
		world.setBlock(x + 13, y + 1, z + 6, FABlockRegistry.INSTANCE.tar, 0, 3);
		world.setBlock(x + 13, y + 1, z + 5, FABlockRegistry.INSTANCE.tar, 0, 3);
		world.setBlock(x + 13, y + 1, z + 4, FABlockRegistry.INSTANCE.tar, 0, 3);
		world.setBlock(x + 13, y + 1, z + 3, Blocks.sand, 0, 3);
		world.setBlock(x + 13, y + 1, z + 2, Blocks.dirt, 0, 3);
		world.setBlock(x + 13, y + 1, z + 1, Blocks.dirt, 0, 3);
		world.setBlock(x + 13, y + 1, z + 0, Blocks.dirt, 0, 3);
		world.setBlock(x + 14, y + 1, z + 11, Blocks.dirt, 0, 3);
		world.setBlock(x + 14, y + 1, z + 10, Blocks.dirt, 0, 3);
		world.setBlock(x + 14, y + 1, z + 9, Blocks.dirt, 0, 3);
		world.setBlock(x + 14, y + 1, z + 8, Blocks.dirt, 0, 3);
		world.setBlock(x + 14, y + 1, z + 7, Blocks.dirt, 0, 3);
		world.setBlock(x + 14, y + 1, z + 6, Blocks.sand, 0, 3);
		world.setBlock(x + 14, y + 1, z + 5, FABlockRegistry.INSTANCE.tar, 0, 3);
		world.setBlock(x + 14, y + 1, z + 4, FABlockRegistry.INSTANCE.tar, 0, 3);
		world.setBlock(x + 14, y + 1, z + 3, Blocks.sand, 0, 3);
		world.setBlock(x + 14, y + 1, z + 2, Blocks.dirt, 0, 3);
		world.setBlock(x + 14, y + 1, z + 1, Blocks.dirt, 0, 3);
		world.setBlock(x + 14, y + 1, z + 0, Blocks.dirt, 0, 3);
		world.setBlock(x + 15, y + 1, z + 11, Blocks.dirt, 0, 3);
		world.setBlock(x + 15, y + 1, z + 10, Blocks.dirt, 0, 3);
		world.setBlock(x + 15, y + 1, z + 9, Blocks.dirt, 0, 3);
		world.setBlock(x + 15, y + 1, z + 8, Blocks.dirt, 0, 3);
		world.setBlock(x + 15, y + 1, z + 7, Blocks.sand, 0, 3);
		world.setBlock(x + 15, y + 1, z + 6, FABlockRegistry.INSTANCE.tar, 0, 3);
		world.setBlock(x + 15, y + 1, z + 5, FABlockRegistry.INSTANCE.tar, 0, 3);
		world.setBlock(x + 15, y + 1, z + 4, Blocks.sand, 0, 3);
		world.setBlock(x + 15, y + 1, z + 3, Blocks.dirt, 0, 3);
		world.setBlock(x + 15, y + 1, z + 2, Blocks.dirt, 0, 3);
		world.setBlock(x + 15, y + 1, z + 1, Blocks.dirt, 0, 3);
		world.setBlock(x + 15, y + 1, z + 0, Blocks.dirt, 0, 3);
		world.setBlock(x + 16, y + 1, z + 11, Blocks.dirt, 0, 3);
		world.setBlock(x + 16, y + 1, z + 10, Blocks.dirt, 0, 3);
		world.setBlock(x + 16, y + 1, z + 9, Blocks.dirt, 0, 3);
		world.setBlock(x + 16, y + 1, z + 8, Blocks.dirt, 0, 3);
		world.setBlock(x + 16, y + 1, z + 7, Blocks.dirt, 0, 3);
		world.setBlock(x + 16, y + 1, z + 6, Blocks.sand, 0, 3);
		world.setBlock(x + 16, y + 1, z + 5, Blocks.dirt, 2, 3);
		world.setBlock(x + 16, y + 1, z + 4, Blocks.dirt, 2, 3);
		world.setBlock(x + 16, y + 1, z + 3, Blocks.dirt, 0, 3);
		world.setBlock(x + 16, y + 1, z + 2, Blocks.dirt, 0, 3);
		world.setBlock(x + 16, y + 1, z + 1, Blocks.dirt, 0, 3);
		world.setBlock(x + 16, y + 1, z + 0, Blocks.dirt, 0, 3);
		world.setBlock(x + 17, y + 1, z + 11, Blocks.dirt, 0, 3);
		world.setBlock(x + 17, y + 1, z + 10, Blocks.dirt, 0, 3);
		world.setBlock(x + 17, y + 1, z + 9, Blocks.dirt, 0, 3);
		world.setBlock(x + 17, y + 1, z + 8, Blocks.dirt, 0, 3);
		world.setBlock(x + 17, y + 1, z + 7, Blocks.dirt, 0, 3);
		world.setBlock(x + 17, y + 1, z + 6, Blocks.dirt, 0, 3);
		world.setBlock(x + 17, y + 1, z + 5, Blocks.dirt, 0, 3);
		world.setBlock(x + 17, y + 1, z + 4, Blocks.dirt, 0, 3);
		world.setBlock(x + 17, y + 1, z + 3, Blocks.dirt, 0, 3);
		world.setBlock(x + 17, y + 1, z + 2, Blocks.dirt, 0, 3);
		world.setBlock(x + 17, y + 1, z + 1, Blocks.dirt, 0, 3);
		world.setBlock(x + 17, y + 1, z + 0, Blocks.dirt, 0, 3);
		world.setBlock(x + 0, y + 2, z + 11, Blocks.grass, 0, 3);
		world.setBlock(x + 0, y + 2, z + 10, Blocks.grass, 0, 3);
		world.setBlock(x + 0, y + 2, z + 9, Blocks.grass, 0, 3);
		world.setBlock(x + 0, y + 2, z + 8, Blocks.grass, 0, 3);
		world.setBlock(x + 0, y + 2, z + 7, Blocks.dirt, 0, 3);
		world.setBlock(x + 0, y + 2, z + 6, Blocks.dirt, 0, 3);
		world.setBlock(x + 0, y + 2, z + 5, Blocks.dirt, 0, 3);
		world.setBlock(x + 0, y + 2, z + 4, Blocks.grass, 0, 3);
		world.setBlock(x + 0, y + 2, z + 3, Blocks.grass, 0, 3);
		world.setBlock(x + 0, y + 2, z + 2, Blocks.grass, 0, 3);
		world.setBlock(x + 0, y + 2, z + 1, Blocks.grass, 0, 3);
		world.setBlock(x + 0, y + 2, z + 0, Blocks.grass, 0, 3);
		world.setBlock(x + 1, y + 2, z + 11, Blocks.grass, 0, 3);
		world.setBlock(x + 1, y + 2, z + 10, Blocks.grass, 0, 3);
		world.setBlock(x + 1, y + 2, z + 9, Blocks.grass, 0, 3);
		world.setBlock(x + 1, y + 2, z + 8, Blocks.dirt, 0, 3);
		world.setBlock(x + 1, y + 2, z + 7, Blocks.dirt, 1, 3);
		world.setBlock(x + 1, y + 2, z + 6, Blocks.dirt, 1, 3);
		world.setBlock(x + 1, y + 2, z + 5, Blocks.dirt, 1, 3);
		world.setBlock(x + 1, y + 2, z + 4, Blocks.dirt, 0, 3);
		world.setBlock(x + 1, y + 2, z + 3, Blocks.grass, 0, 3);
		world.setBlock(x + 1, y + 2, z + 2, Blocks.grass, 0, 3);
		world.setBlock(x + 1, y + 2, z + 1, Blocks.grass, 0, 3);
		world.setBlock(x + 1, y + 2, z + 0, Blocks.grass, 0, 3);
		world.setBlock(x + 2, y + 2, z + 11, Blocks.grass, 0, 3);
		world.setBlock(x + 2, y + 2, z + 10, Blocks.grass, 0, 3);
		world.setBlock(x + 2, y + 2, z + 9, Blocks.grass, 0, 3);
		world.setBlock(x + 2, y + 2, z + 8, Blocks.dirt, 0, 3);
		world.setBlock(x + 2, y + 2, z + 7, Blocks.dirt, 1, 3);
		world.setBlock(x + 2, y + 2, z + 6, Blocks.dirt, 1, 3);
		world.setBlock(x + 2, y + 2, z + 5, Blocks.dirt, 1, 3);
		world.setBlock(x + 2, y + 2, z + 4, Blocks.dirt, 0, 3);
		world.setBlock(x + 2, y + 2, z + 3, Blocks.grass, 0, 3);
		world.setBlock(x + 2, y + 2, z + 2, Blocks.grass, 0, 3);
		world.setBlock(x + 2, y + 2, z + 1, Blocks.grass, 0, 3);
		world.setBlock(x + 2, y + 2, z + 0, Blocks.grass, 0, 3);
		world.setBlock(x + 3, y + 2, z + 11, Blocks.grass, 0, 3);
		world.setBlock(x + 3, y + 2, z + 10, Blocks.grass, 0, 3);
		world.setBlock(x + 3, y + 2, z + 9, Blocks.grass, 0, 3);
		world.setBlock(x + 3, y + 2, z + 8, Blocks.dirt, 0, 3);
		world.setBlock(x + 3, y + 2, z + 7, Blocks.dirt, 1, 3);
		world.setBlock(x + 3, y + 2, z + 6, Blocks.dirt, 1, 3);
		world.setBlock(x + 3, y + 2, z + 5, Blocks.dirt, 1, 3);
		world.setBlock(x + 3, y + 2, z + 4, Blocks.dirt, 0, 3);
		world.setBlock(x + 3, y + 2, z + 3, Blocks.grass, 0, 3);
		world.setBlock(x + 3, y + 2, z + 2, Blocks.grass, 0, 3);
		world.setBlock(x + 3, y + 2, z + 1, Blocks.grass, 0, 3);
		world.setBlock(x + 3, y + 2, z + 0, Blocks.grass, 0, 3);
		world.setBlock(x + 4, y + 2, z + 11, Blocks.grass, 0, 3);
		world.setBlock(x + 4, y + 2, z + 10, Blocks.grass, 0, 3);
		world.setBlock(x + 4, y + 2, z + 9, Blocks.grass, 0, 3);
		world.setBlock(x + 4, y + 2, z + 8, Blocks.dirt, 0, 3);
		world.setBlock(x + 4, y + 2, z + 7, Blocks.dirt, 1, 3);
		world.setBlock(x + 4, y + 2, z + 6, Blocks.dirt, 1, 3);
		world.setBlock(x + 4, y + 2, z + 5, Blocks.dirt, 1, 3);
		world.setBlock(x + 4, y + 2, z + 4, Blocks.dirt, 0, 3);
		world.setBlock(x + 4, y + 2, z + 3, Blocks.grass, 0, 3);
		world.setBlock(x + 4, y + 2, z + 2, Blocks.grass, 0, 3);
		world.setBlock(x + 4, y + 2, z + 1, Blocks.grass, 0, 3);
		world.setBlock(x + 4, y + 2, z + 0, Blocks.grass, 0, 3);
		world.setBlock(x + 5, y + 2, z + 11, Blocks.grass, 0, 3);
		world.setBlock(x + 5, y + 2, z + 10, Blocks.grass, 0, 3);
		world.setBlock(x + 5, y + 2, z + 9, Blocks.grass, 0, 3);
		world.setBlock(x + 5, y + 2, z + 8, Blocks.grass, 0, 3);
		world.setBlock(x + 5, y + 2, z + 7, Blocks.dirt, 0, 3);
		world.setBlock(x + 5, y + 2, z + 6, Blocks.dirt, 1, 3);
		world.setBlock(x + 5, y + 2, z + 5, Blocks.dirt, 0, 3);
		world.setBlock(x + 5, y + 2, z + 4, Blocks.grass, 0, 3);
		world.setBlock(x + 5, y + 2, z + 3, Blocks.grass, 0, 3);
		world.setBlock(x + 5, y + 2, z + 2, Blocks.grass, 0, 3);
		world.setBlock(x + 5, y + 2, z + 1, Blocks.grass, 0, 3);
		world.setBlock(x + 5, y + 2, z + 0, Blocks.grass, 0, 3);
		world.setBlock(x + 6, y + 2, z + 11, Blocks.grass, 0, 3);
		world.setBlock(x + 6, y + 2, z + 10, Blocks.grass, 0, 3);
		world.setBlock(x + 6, y + 2, z + 9, Blocks.grass, 0, 3);
		world.setBlock(x + 6, y + 2, z + 8, Blocks.grass, 0, 3);
		world.setBlock(x + 6, y + 2, z + 7, Blocks.grass, 0, 3);
		world.setBlock(x + 6, y + 2, z + 6, Blocks.dirt, 2, 3);
		world.setBlock(x + 6, y + 2, z + 5, Blocks.grass, 0, 3);
		world.setBlock(x + 6, y + 2, z + 4, Blocks.grass, 0, 3);
		world.setBlock(x + 6, y + 2, z + 3, Blocks.grass, 0, 3);
		world.setBlock(x + 6, y + 2, z + 2, Blocks.grass, 0, 3);
		world.setBlock(x + 6, y + 2, z + 1, Blocks.grass, 0, 3);
		world.setBlock(x + 6, y + 2, z + 0, Blocks.grass, 0, 3);
		world.setBlock(x + 7, y + 2, z + 11, Blocks.grass, 0, 3);
		world.setBlock(x + 7, y + 2, z + 10, Blocks.grass, 0, 3);
		world.setBlock(x + 7, y + 2, z + 9, Blocks.grass, 0, 3);
		world.setBlock(x + 7, y + 2, z + 8, Blocks.grass, 0, 3);
		world.setBlock(x + 7, y + 2, z + 7, Blocks.dirt, 2, 3);
		world.setBlock(x + 7, y + 2, z + 6, Blocks.dirt, 2, 3);
		world.setBlock(x + 7, y + 2, z + 5, Blocks.dirt, 2, 3);
		world.setBlock(x + 7, y + 2, z + 4, Blocks.dirt, 2, 3);
		world.setBlock(x + 7, y + 2, z + 3, Blocks.dirt, 2, 3);
		world.setBlock(x + 7, y + 2, z + 2, Blocks.grass, 0, 3);
		world.setBlock(x + 7, y + 2, z + 1, Blocks.grass, 0, 3);
		world.setBlock(x + 7, y + 2, z + 0, Blocks.grass, 0, 3);
		world.setBlock(x + 8, y + 2, z + 11, Blocks.grass, 0, 3);
		world.setBlock(x + 8, y + 2, z + 10, Blocks.grass, 0, 3);
		world.setBlock(x + 8, y + 2, z + 9, Blocks.grass, 0, 3);
		world.setBlock(x + 8, y + 2, z + 8, Blocks.dirt, 2, 3);
		world.setBlock(x + 8, y + 2, z + 7, Blocks.grass, 0, 3);
		world.setBlock(x + 8, y + 2, z + 6, Blocks.dirt, 2, 3);
		world.setBlock(x + 8, y + 2, z + 5, Blocks.dirt, 2, 3);
		world.setBlock(x + 8, y + 2, z + 4, Blocks.soul_sand, 0, 3);
		world.setBlock(x + 8, y + 2, z + 3, Blocks.dirt, 2, 3);
		world.setBlock(x + 8, y + 2, z + 2, Blocks.dirt, 2, 3);
		world.setBlock(x + 8, y + 2, z + 1, Blocks.grass, 0, 3);
		world.setBlock(x + 8, y + 2, z + 0, Blocks.grass, 0, 3);
		world.setBlock(x + 9, y + 2, z + 11, Blocks.grass, 0, 3);
		world.setBlock(x + 9, y + 2, z + 10, Blocks.grass, 0, 3);
		world.setBlock(x + 9, y + 2, z + 9, Blocks.dirt, 2, 3);
		world.setBlock(x + 9, y + 2, z + 8, Blocks.dirt, 2, 3);
		world.setBlock(x + 9, y + 2, z + 7, Blocks.dirt, 2, 3);
		world.setBlock(x + 9, y + 2, z + 6, Blocks.dirt, 2, 3);
		world.setBlock(x + 9, y + 2, z + 5, Blocks.soul_sand, 0, 3);
		world.setBlock(x + 9, y + 2, z + 4, Blocks.soul_sand, 0, 3);
		world.setBlock(x + 9, y + 2, z + 3, Blocks.dirt, 2, 3);
		world.setBlock(x + 9, y + 2, z + 2, Blocks.dirt, 2, 3);
		world.setBlock(x + 9, y + 2, z + 1, Blocks.dirt, 2, 3);
		world.setBlock(x + 9, y + 2, z + 0, Blocks.grass, 0, 3);
		world.setBlock(x + 10, y + 2, z + 11, Blocks.grass, 0, 3);
		world.setBlock(x + 10, y + 2, z + 10, Blocks.grass, 0, 3);
		world.setBlock(x + 10, y + 2, z + 9, Blocks.dirt, 2, 3);
		world.setBlock(x + 10, y + 2, z + 6, Blocks.dirt, 2, 3);
		world.setBlock(x + 10, y + 2, z + 5, Blocks.dirt, 2, 3);
		world.setBlock(x + 10, y + 2, z + 4, Blocks.dirt, 2, 3);
		world.setBlock(x + 10, y + 2, z + 3, Blocks.soul_sand, 0, 3);
		world.setBlock(x + 10, y + 2, z + 2, Blocks.dirt, 2, 3);
		world.setBlock(x + 10, y + 2, z + 1, Blocks.dirt, 2, 3);
		world.setBlock(x + 10, y + 2, z + 0, Blocks.grass, 0, 3);
		world.setBlock(x + 11, y + 2, z + 11, Blocks.grass, 0, 3);
		world.setBlock(x + 11, y + 2, z + 10, Blocks.dirt, 2, 3);
		world.setBlock(x + 11, y + 2, z + 9, Blocks.dirt, 2, 3);
		world.setBlock(x + 11, y + 2, z + 4, Blocks.dirt, 2, 3);
		world.setBlock(x + 11, y + 2, z + 3, Blocks.dirt, 2, 3);
		world.setBlock(x + 11, y + 2, z + 2, Blocks.dirt, 2, 3);
		world.setBlock(x + 11, y + 2, z + 1, Blocks.dirt, 2, 3);
		world.setBlock(x + 11, y + 2, z + 0, Blocks.dirt, 2, 3);
		world.setBlock(x + 12, y + 2, z + 11, Blocks.grass, 0, 3);
		world.setBlock(x + 12, y + 2, z + 10, Blocks.dirt, 2, 3);
		world.setBlock(x + 12, y + 2, z + 3, Blocks.dirt, 2, 3);
		world.setBlock(x + 12, y + 2, z + 2, Blocks.sand, 0, 3);
		world.setBlock(x + 12, y + 2, z + 1, Blocks.grass, 0, 3);
		world.setBlock(x + 12, y + 2, z + 0, Blocks.dirt, 2, 3);
		world.setBlock(x + 13, y + 2, z + 11, Blocks.grass, 0, 3);
		world.setBlock(x + 13, y + 2, z + 10, Blocks.dirt, 2, 3);
		world.setBlock(x + 13, y + 2, z + 9, Blocks.dirt, 2, 3);
		world.setBlock(x + 13, y + 2, z + 2, Blocks.dirt, 2, 3);
		world.setBlock(x + 13, y + 2, z + 1, Blocks.grass, 0, 3);
		world.setBlock(x + 13, y + 2, z + 0, Blocks.dirt, 2, 3);
		world.setBlock(x + 14, y + 2, z + 11, Blocks.grass, 0, 3);
		world.setBlock(x + 14, y + 2, z + 10, Blocks.grass, 0, 3);
		world.setBlock(x + 14, y + 2, z + 9, Blocks.mycelium, 0, 3);
		world.setBlock(x + 14, y + 2, z + 8, Blocks.dirt, 2, 3);
		world.setBlock(x + 14, y + 2, z + 7, Blocks.dirt, 2, 3);
		world.setBlock(x + 14, y + 2, z + 2, Blocks.dirt, 2, 3);
		world.setBlock(x + 14, y + 2, z + 1, Blocks.sand, 0, 3);
		world.setBlock(x + 14, y + 2, z + 0, Blocks.dirt, 2, 3);
		world.setBlock(x + 15, y + 2, z + 11, Blocks.grass, 0, 3);
		world.setBlock(x + 15, y + 2, z + 10, Blocks.grass, 0, 3);
		world.setBlock(x + 15, y + 2, z + 9, Blocks.dirt, 2, 3);
		world.setBlock(x + 15, y + 2, z + 8, Blocks.dirt, 2, 3);
		world.setBlock(x + 15, y + 2, z + 3, Blocks.dirt, 2, 3);
		world.setBlock(x + 15, y + 2, z + 2, Blocks.dirt, 2, 3);
		world.setBlock(x + 15, y + 2, z + 1, Blocks.dirt, 2, 3);
		world.setBlock(x + 15, y + 2, z + 0, Blocks.grass, 0, 3);
		world.setBlock(x + 16, y + 2, z + 11, Blocks.grass, 0, 3);
		world.setBlock(x + 16, y + 2, z + 10, Blocks.grass, 0, 3);
		world.setBlock(x + 16, y + 2, z + 9, Blocks.dirt, 2, 3);
		world.setBlock(x + 16, y + 2, z + 8, Blocks.mycelium, 0, 3);
		world.setBlock(x + 16, y + 2, z + 7, Blocks.sand, 0, 3);
		world.setBlock(x + 16, y + 2, z + 3, Blocks.grass, 0, 3);
		world.setBlock(x + 16, y + 2, z + 2, Blocks.dirt, 2, 3);
		world.setBlock(x + 16, y + 2, z + 1, Blocks.grass, 0, 3);
		world.setBlock(x + 16, y + 2, z + 0, Blocks.grass, 0, 3);
		world.setBlock(x + 17, y + 2, z + 11, Blocks.grass, 0, 3);
		world.setBlock(x + 17, y + 2, z + 10, Blocks.grass, 0, 3);
		world.setBlock(x + 17, y + 2, z + 9, Blocks.grass, 0, 3);
		world.setBlock(x + 17, y + 2, z + 8, Blocks.dirt, 2, 3);
		world.setBlock(x + 17, y + 2, z + 7, Blocks.mycelium, 0, 3);
		world.setBlock(x + 17, y + 2, z + 6, Blocks.dirt, 2, 3);
		world.setBlock(x + 17, y + 2, z + 5, Blocks.dirt, 2, 3);
		world.setBlock(x + 17, y + 2, z + 4, Blocks.dirt, 2, 3);
		world.setBlock(x + 17, y + 2, z + 3, Blocks.dirt, 2, 3);
		world.setBlock(x + 17, y + 2, z + 2, Blocks.grass, 0, 3);
		world.setBlock(x + 17, y + 2, z + 1, Blocks.grass, 0, 3);
		world.setBlock(x + 17, y + 2, z + 0, Blocks.grass, 0, 3);
		world.setBlock(x + 0, y + 3, z + 8, Blocks.fence, 0, 3);
		world.setBlock(x + 0, y + 3, z + 7, Blocks.wool, 0, 3);
		world.setBlock(x + 0, y + 3, z + 6, Blocks.wool, 0, 3);
		world.setBlock(x + 0, y + 3, z + 5, Blocks.wool, 0, 3);
		world.setBlock(x + 0, y + 3, z + 4, Blocks.fence, 0, 3);
		world.setBlock(x + 1, y + 3, z + 8, Blocks.wool, 0, 3);
		world.setBlock(x + 1, y + 3, z + 7, Blocks.wool, 0, 3);
		world.setBlock(x + 1, y + 3, z + 6, Blocks.fence, 0, 3);
		world.setBlock(x + 1, y + 3, z + 5, Blocks.wool, 0, 3);
		world.setBlock(x + 1, y + 3, z + 4, Blocks.wool, 0, 3);
		world.setBlock(x + 2, y + 3, z + 8, Blocks.wool, 0, 3);
		world.setBlock(x + 2, y + 3, z + 7, Blocks.bed, 10, 3);
		world.setBlock(x + 2, y + 3, z + 5, Blocks.crafting_table, 0, 3);
		world.setBlock(x + 2, y + 3, z + 4, Blocks.wool, 0, 3);
		world.setBlock(x + 3, y + 3, z + 8, Blocks.wool, 0, 3);
		world.setBlock(x + 3, y + 3, z + 7, Blocks.bed, 2, 3);
		world.setBlock(x + 3, y + 3, z + 5, Blocks.bookshelf, 0, 3);
		world.setBlock(x + 3, y + 3, z + 4, Blocks.wool, 0, 3);
		world.setBlock(x + 4, y + 3, z + 8, Blocks.wool, 0, 3);
		world.setBlock(x + 4, y + 3, z + 7, Blocks.fence, 0, 3);
		world.setBlock(x + 4, y + 3, z + 5, Blocks.fence, 0, 3);
		world.setBlock(x + 4, y + 3, z + 4, Blocks.wool, 0, 3);
		world.setBlock(x + 5, y + 3, z + 8, Blocks.fence, 0, 3);
		world.setBlock(x + 5, y + 3, z + 7, Blocks.wool, 0, 3);
		world.setBlock(x + 5, y + 3, z + 6, Blocks.wooden_door, 3, 3);
		this.spawnVillager(world, x + 5, y + 3, z + 6);
		world.setBlock(x + 5, y + 3, z + 5, Blocks.wool, 0, 3);
		world.setBlock(x + 5, y + 3, z + 4, Blocks.fence, 0, 3);
		world.setBlock(x + 7, y + 3, z + 7, Blocks.cobblestone_wall, 0, 3);
		world.setBlock(x + 7, y + 3, z + 6, Blocks.cobblestone_wall, 0, 3);
		world.setBlock(x + 8, y + 3, z + 2, Blocks.cobblestone_wall, 1, 3);
		world.setBlock(x + 9, y + 3, z + 2, Blocks.cobblestone_wall, 0, 3);
		world.setBlock(x + 9, y + 3, z + 1, Blocks.cobblestone_wall, 0, 3);
		world.setBlock(x + 12, y + 3, z + 1, Blocks.tallgrass, 1, 3);
		world.setBlock(x + 14, y + 3, z + 10, Blocks.double_plant, 2, 3);
		world.setBlock(x + 15, y + 3, z + 1, Blocks.cobblestone_wall, 1, 3);
		world.setBlock(x + 16, y + 3, z + 3, Blocks.tallgrass, 1, 3);
		world.setBlock(x + 17, y + 3, z + 8, Blocks.cobblestone_wall, 0, 3);
		world.setBlock(x + 0, y + 4, z + 7, Blocks.wool, 0, 3);
		world.setBlock(x + 0, y + 4, z + 6, Blocks.wool, 0, 3);
		world.setBlock(x + 0, y + 4, z + 5, Blocks.wool, 0, 3);
		world.setBlock(x + 1, y + 4, z + 8, Blocks.wool, 0, 3);
		world.setBlock(x + 1, y + 4, z + 7, Blocks.wool, 0, 3);
		world.setBlock(x + 1, y + 4, z + 6, Blocks.fence, 0, 3);
		world.setBlock(x + 1, y + 4, z + 5, Blocks.wool, 0, 3);
		world.setBlock(x + 1, y + 4, z + 4, Blocks.wool, 0, 3);
		world.setBlock(x + 2, y + 4, z + 8, Blocks.wool, 0, 3);
		world.setBlock(x + 2, y + 4, z + 4, Blocks.wool, 0, 3);
		world.setBlock(x + 3, y + 4, z + 8, Blocks.wool, 0, 3);
		world.setBlock(x + 3, y + 4, z + 4, Blocks.wool, 0, 3);
		world.setBlock(x + 4, y + 4, z + 8, Blocks.wool, 0, 3);
		world.setBlock(x + 4, y + 4, z + 7, Blocks.fence, 0, 3);
		world.setBlock(x + 4, y + 4, z + 5, Blocks.fence, 0, 3);
		world.setBlock(x + 4, y + 4, z + 4, Blocks.wool, 0, 3);
		world.setBlock(x + 5, y + 4, z + 7, Blocks.wool, 0, 3);
		world.setBlock(x + 5, y + 4, z + 6, Blocks.wooden_door, 8, 3);
		world.setBlock(x + 5, y + 4, z + 5, Blocks.wool, 0, 3);
		world.setBlock(x + 8, y + 4, z + 7, Blocks.double_plant, 9, 3);
		world.setBlock(x + 8, y + 4, z + 2, Blocks.cobblestone_wall, 0, 3);
		world.setBlock(x + 13, y + 4, z + 1, Blocks.double_plant, 9, 3);
		world.setBlock(x + 14, y + 4, z + 10, Blocks.double_plant, 8, 3);
		world.setBlock(x + 15, y + 4, z + 1, Blocks.cobblestone_wall, 0, 3);
		world.setBlock(x + 0, y + 5, z + 6, Blocks.wool, 0, 3);
		world.setBlock(x + 1, y + 5, z + 7, Blocks.wool, 0, 3);
		world.setBlock(x + 1, y + 5, z + 6, Blocks.wool, 0, 3);
		world.setBlock(x + 1, y + 5, z + 5, Blocks.wool, 0, 3);
		world.setBlock(x + 2, y + 5, z + 7, Blocks.wool, 0, 3);
		world.setBlock(x + 2, y + 5, z + 5, Blocks.wool, 0, 3);
		world.setBlock(x + 3, y + 5, z + 7, Blocks.wool, 0, 3);
		world.setBlock(x + 3, y + 5, z + 5, Blocks.wool, 0, 3);
		world.setBlock(x + 4, y + 5, z + 7, Blocks.wool, 0, 3);
		world.setBlock(x + 4, y + 5, z + 5, Blocks.wool, 0, 3);
		world.setBlock(x + 5, y + 5, z + 6, Blocks.wool, 0, 3);
		world.setBlock(x + 8, y + 5, z + 2, Blocks.cobblestone_wall, 0, 3);
		world.setBlock(x + 1, y + 6, z + 6, Blocks.wool, 0, 3);
		world.setBlock(x + 2, y + 6, z + 6, Blocks.wool, 0, 3);
		world.setBlock(x + 3, y + 6, z + 6, Blocks.wool, 0, 3);
		world.setBlock(x + 4, y + 6, z + 6, Blocks.wool, 0, 3);
		return true;

	}

	public boolean generate_r2(World world, Random rand, int x, int y, int z) {
		world.setBlock(x + 11, y + 0, z + 17, Blocks.dirt, 0, 3);
		world.setBlock(x + 10, y + 0, z + 17, Blocks.dirt, 0, 3);
		world.setBlock(x + 9, y + 0, z + 17, Blocks.dirt, 0, 3);
		world.setBlock(x + 8, y + 0, z + 17, Blocks.dirt, 0, 3);
		world.setBlock(x + 7, y + 0, z + 17, Blocks.dirt, 0, 3);
		world.setBlock(x + 6, y + 0, z + 17, Blocks.dirt, 0, 3);
		world.setBlock(x + 5, y + 0, z + 17, Blocks.dirt, 0, 3);
		world.setBlock(x + 4, y + 0, z + 17, Blocks.dirt, 0, 3);
		world.setBlock(x + 3, y + 0, z + 17, Blocks.dirt, 0, 3);
		world.setBlock(x + 2, y + 0, z + 17, Blocks.dirt, 0, 3);
		world.setBlock(x + 1, y + 0, z + 17, Blocks.dirt, 0, 3);
		world.setBlock(x + 0, y + 0, z + 17, Blocks.dirt, 0, 3);
		world.setBlock(x + 11, y + 0, z + 16, Blocks.dirt, 0, 3);
		world.setBlock(x + 10, y + 0, z + 16, Blocks.dirt, 0, 3);
		world.setBlock(x + 9, y + 0, z + 16, Blocks.dirt, 0, 3);
		world.setBlock(x + 8, y + 0, z + 16, Blocks.dirt, 0, 3);
		world.setBlock(x + 7, y + 0, z + 16, Blocks.dirt, 0, 3);
		world.setBlock(x + 6, y + 0, z + 16, Blocks.dirt, 0, 3);
		world.setBlock(x + 5, y + 0, z + 16, Blocks.dirt, 0, 3);
		world.setBlock(x + 4, y + 0, z + 16, Blocks.dirt, 0, 3);
		world.setBlock(x + 3, y + 0, z + 16, Blocks.dirt, 0, 3);
		world.setBlock(x + 2, y + 0, z + 16, Blocks.dirt, 0, 3);
		world.setBlock(x + 1, y + 0, z + 16, Blocks.dirt, 0, 3);
		world.setBlock(x + 0, y + 0, z + 16, Blocks.dirt, 0, 3);
		world.setBlock(x + 11, y + 0, z + 15, Blocks.dirt, 0, 3);
		world.setBlock(x + 10, y + 0, z + 15, Blocks.dirt, 0, 3);
		world.setBlock(x + 9, y + 0, z + 15, Blocks.dirt, 0, 3);
		world.setBlock(x + 8, y + 0, z + 15, Blocks.dirt, 0, 3);
		world.setBlock(x + 7, y + 0, z + 15, Blocks.dirt, 0, 3);
		world.setBlock(x + 6, y + 0, z + 15, Blocks.dirt, 0, 3);
		world.setBlock(x + 5, y + 0, z + 15, Blocks.dirt, 0, 3);
		world.setBlock(x + 4, y + 0, z + 15, Blocks.dirt, 0, 3);
		world.setBlock(x + 3, y + 0, z + 15, Blocks.dirt, 0, 3);
		world.setBlock(x + 2, y + 0, z + 15, Blocks.dirt, 0, 3);
		world.setBlock(x + 1, y + 0, z + 15, Blocks.dirt, 0, 3);
		world.setBlock(x + 0, y + 0, z + 15, Blocks.dirt, 0, 3);
		world.setBlock(x + 11, y + 0, z + 14, Blocks.dirt, 0, 3);
		world.setBlock(x + 10, y + 0, z + 14, Blocks.dirt, 0, 3);
		world.setBlock(x + 9, y + 0, z + 14, Blocks.dirt, 0, 3);
		world.setBlock(x + 8, y + 0, z + 14, Blocks.dirt, 0, 3);
		world.setBlock(x + 7, y + 0, z + 14, Blocks.dirt, 0, 3);
		world.setBlock(x + 6, y + 0, z + 14, Blocks.dirt, 0, 3);
		world.setBlock(x + 5, y + 0, z + 14, Blocks.dirt, 0, 3);
		world.setBlock(x + 4, y + 0, z + 14, Blocks.dirt, 0, 3);
		world.setBlock(x + 3, y + 0, z + 14, Blocks.dirt, 0, 3);
		world.setBlock(x + 2, y + 0, z + 14, Blocks.dirt, 0, 3);
		world.setBlock(x + 1, y + 0, z + 14, Blocks.dirt, 0, 3);
		world.setBlock(x + 0, y + 0, z + 14, Blocks.dirt, 0, 3);
		world.setBlock(x + 11, y + 0, z + 13, Blocks.dirt, 0, 3);
		world.setBlock(x + 10, y + 0, z + 13, Blocks.dirt, 0, 3);
		world.setBlock(x + 9, y + 0, z + 13, Blocks.dirt, 0, 3);
		world.setBlock(x + 8, y + 0, z + 13, Blocks.dirt, 0, 3);
		world.setBlock(x + 7, y + 0, z + 13, Blocks.dirt, 0, 3);
		world.setBlock(x + 6, y + 0, z + 13, Blocks.dirt, 0, 3);
		world.setBlock(x + 5, y + 0, z + 13, Blocks.dirt, 0, 3);
		world.setBlock(x + 4, y + 0, z + 13, Blocks.dirt, 0, 3);
		world.setBlock(x + 3, y + 0, z + 13, Blocks.dirt, 0, 3);
		world.setBlock(x + 2, y + 0, z + 13, Blocks.dirt, 0, 3);
		world.setBlock(x + 1, y + 0, z + 13, Blocks.dirt, 0, 3);
		world.setBlock(x + 0, y + 0, z + 13, Blocks.dirt, 0, 3);
		world.setBlock(x + 11, y + 0, z + 12, Blocks.dirt, 0, 3);
		world.setBlock(x + 10, y + 0, z + 12, Blocks.dirt, 0, 3);
		world.setBlock(x + 9, y + 0, z + 12, Blocks.dirt, 0, 3);
		world.setBlock(x + 8, y + 0, z + 12, Blocks.dirt, 0, 3);
		world.setBlock(x + 7, y + 0, z + 12, Blocks.dirt, 0, 3);
		world.setBlock(x + 6, y + 0, z + 12, Blocks.dirt, 0, 3);
		world.setBlock(x + 5, y + 0, z + 12, Blocks.dirt, 0, 3);
		world.setBlock(x + 4, y + 0, z + 12, Blocks.dirt, 0, 3);
		world.setBlock(x + 3, y + 0, z + 12, Blocks.dirt, 0, 3);
		world.setBlock(x + 2, y + 0, z + 12, Blocks.dirt, 0, 3);
		world.setBlock(x + 1, y + 0, z + 12, Blocks.dirt, 0, 3);
		world.setBlock(x + 0, y + 0, z + 12, Blocks.dirt, 0, 3);
		world.setBlock(x + 11, y + 0, z + 11, Blocks.dirt, 0, 3);
		world.setBlock(x + 10, y + 0, z + 11, Blocks.dirt, 0, 3);
		world.setBlock(x + 9, y + 0, z + 11, Blocks.dirt, 0, 3);
		world.setBlock(x + 8, y + 0, z + 11, Blocks.dirt, 0, 3);
		world.setBlock(x + 7, y + 0, z + 11, Blocks.dirt, 0, 3);
		world.setBlock(x + 6, y + 0, z + 11, Blocks.dirt, 0, 3);
		world.setBlock(x + 5, y + 0, z + 11, Blocks.dirt, 0, 3);
		world.setBlock(x + 4, y + 0, z + 11, Blocks.dirt, 0, 3);
		world.setBlock(x + 3, y + 0, z + 11, Blocks.dirt, 0, 3);
		world.setBlock(x + 2, y + 0, z + 11, Blocks.dirt, 0, 3);
		world.setBlock(x + 1, y + 0, z + 11, Blocks.dirt, 0, 3);
		world.setBlock(x + 0, y + 0, z + 11, Blocks.dirt, 0, 3);
		world.setBlock(x + 11, y + 0, z + 10, Blocks.dirt, 0, 3);
		world.setBlock(x + 10, y + 0, z + 10, Blocks.dirt, 0, 3);
		world.setBlock(x + 9, y + 0, z + 10, Blocks.dirt, 0, 3);
		world.setBlock(x + 8, y + 0, z + 10, Blocks.dirt, 0, 3);
		world.setBlock(x + 7, y + 0, z + 10, Blocks.dirt, 0, 3);
		world.setBlock(x + 6, y + 0, z + 10, Blocks.dirt, 0, 3);
		world.setBlock(x + 5, y + 0, z + 10, Blocks.dirt, 0, 3);
		world.setBlock(x + 4, y + 0, z + 10, Blocks.dirt, 0, 3);
		world.setBlock(x + 3, y + 0, z + 10, Blocks.dirt, 0, 3);
		world.setBlock(x + 2, y + 0, z + 10, Blocks.dirt, 0, 3);
		world.setBlock(x + 1, y + 0, z + 10, Blocks.dirt, 0, 3);
		world.setBlock(x + 0, y + 0, z + 10, Blocks.dirt, 0, 3);
		world.setBlock(x + 11, y + 0, z + 9, Blocks.dirt, 0, 3);
		world.setBlock(x + 10, y + 0, z + 9, Blocks.dirt, 0, 3);
		world.setBlock(x + 9, y + 0, z + 9, Blocks.dirt, 0, 3);
		world.setBlock(x + 8, y + 0, z + 9, Blocks.dirt, 0, 3);
		world.setBlock(x + 7, y + 0, z + 9, Blocks.dirt, 0, 3);
		world.setBlock(x + 6, y + 0, z + 9, Blocks.dirt, 0, 3);
		world.setBlock(x + 5, y + 0, z + 9, Blocks.dirt, 0, 3);
		world.setBlock(x + 4, y + 0, z + 9, Blocks.dirt, 0, 3);
		world.setBlock(x + 3, y + 0, z + 9, Blocks.dirt, 0, 3);
		world.setBlock(x + 2, y + 0, z + 9, Blocks.dirt, 0, 3);
		world.setBlock(x + 1, y + 0, z + 9, Blocks.dirt, 0, 3);
		world.setBlock(x + 0, y + 0, z + 9, Blocks.dirt, 0, 3);

		generate_r22(world, rand, x, y, z);
		return true;

	}

	public boolean generate_r22(World world, Random rand, int x, int y, int z) {

		world.setBlock(x + 11, y + 0, z + 8, Blocks.dirt, 0, 3);
		world.setBlock(x + 10, y + 0, z + 8, Blocks.dirt, 0, 3);
		world.setBlock(x + 9, y + 0, z + 8, Blocks.dirt, 0, 3);
		world.setBlock(x + 8, y + 0, z + 8, Blocks.dirt, 0, 3);
		world.setBlock(x + 7, y + 0, z + 8, Blocks.dirt, 0, 3);
		world.setBlock(x + 6, y + 0, z + 8, Blocks.dirt, 0, 3);
		world.setBlock(x + 5, y + 0, z + 8, Blocks.dirt, 0, 3);
		world.setBlock(x + 4, y + 0, z + 8, Blocks.dirt, 0, 3);
		world.setBlock(x + 3, y + 0, z + 8, Blocks.dirt, 0, 3);
		world.setBlock(x + 2, y + 0, z + 8, Blocks.dirt, 0, 3);
		world.setBlock(x + 1, y + 0, z + 8, Blocks.dirt, 0, 3);
		world.setBlock(x + 0, y + 0, z + 8, Blocks.dirt, 0, 3);
		world.setBlock(x + 11, y + 0, z + 7, Blocks.dirt, 0, 3);
		world.setBlock(x + 10, y + 0, z + 7, Blocks.dirt, 0, 3);
		world.setBlock(x + 9, y + 0, z + 7, Blocks.dirt, 0, 3);
		world.setBlock(x + 8, y + 0, z + 7, Blocks.dirt, 0, 3);
		world.setBlock(x + 7, y + 0, z + 7, Blocks.dirt, 0, 3);
		world.setBlock(x + 6, y + 0, z + 7, Blocks.dirt, 0, 3);
		world.setBlock(x + 5, y + 0, z + 7, Blocks.dirt, 0, 3);
		world.setBlock(x + 4, y + 0, z + 7, Blocks.dirt, 0, 3);
		world.setBlock(x + 3, y + 0, z + 7, Blocks.dirt, 0, 3);
		world.setBlock(x + 2, y + 0, z + 7, Blocks.dirt, 0, 3);
		world.setBlock(x + 1, y + 0, z + 7, Blocks.dirt, 0, 3);
		world.setBlock(x + 0, y + 0, z + 7, Blocks.dirt, 0, 3);
		world.setBlock(x + 11, y + 0, z + 6, Blocks.dirt, 0, 3);
		world.setBlock(x + 10, y + 0, z + 6, Blocks.dirt, 0, 3);
		world.setBlock(x + 9, y + 0, z + 6, Blocks.dirt, 0, 3);
		world.setBlock(x + 8, y + 0, z + 6, Blocks.dirt, 0, 3);
		world.setBlock(x + 7, y + 0, z + 6, Blocks.dirt, 0, 3);
		world.setBlock(x + 6, y + 0, z + 6, Blocks.dirt, 0, 3);
		world.setBlock(x + 5, y + 0, z + 6, Blocks.dirt, 0, 3);
		world.setBlock(x + 4, y + 0, z + 6, Blocks.dirt, 0, 3);
		world.setBlock(x + 3, y + 0, z + 6, Blocks.dirt, 0, 3);
		world.setBlock(x + 2, y + 0, z + 6, Blocks.dirt, 0, 3);
		world.setBlock(x + 1, y + 0, z + 6, Blocks.dirt, 0, 3);
		world.setBlock(x + 0, y + 0, z + 6, Blocks.dirt, 0, 3);
		world.setBlock(x + 11, y + 0, z + 5, Blocks.dirt, 0, 3);
		world.setBlock(x + 10, y + 0, z + 5, Blocks.dirt, 0, 3);
		world.setBlock(x + 9, y + 0, z + 5, Blocks.dirt, 0, 3);
		world.setBlock(x + 8, y + 0, z + 5, Blocks.dirt, 0, 3);
		world.setBlock(x + 7, y + 0, z + 5, Blocks.dirt, 0, 3);
		world.setBlock(x + 6, y + 0, z + 5, Blocks.dirt, 0, 3);
		world.setBlock(x + 5, y + 0, z + 5, Blocks.dirt, 0, 3);
		world.setBlock(x + 4, y + 0, z + 5, Blocks.dirt, 0, 3);
		world.setBlock(x + 3, y + 0, z + 5, Blocks.dirt, 0, 3);
		world.setBlock(x + 2, y + 0, z + 5, Blocks.dirt, 0, 3);
		world.setBlock(x + 1, y + 0, z + 5, Blocks.dirt, 0, 3);
		world.setBlock(x + 0, y + 0, z + 5, Blocks.dirt, 0, 3);
		world.setBlock(x + 11, y + 0, z + 4, Blocks.dirt, 0, 3);
		world.setBlock(x + 10, y + 0, z + 4, Blocks.dirt, 0, 3);
		world.setBlock(x + 9, y + 0, z + 4, Blocks.dirt, 0, 3);
		world.setBlock(x + 8, y + 0, z + 4, Blocks.dirt, 0, 3);
		world.setBlock(x + 7, y + 0, z + 4, Blocks.dirt, 0, 3);
		world.setBlock(x + 6, y + 0, z + 4, Blocks.dirt, 0, 3);
		world.setBlock(x + 5, y + 0, z + 4, Blocks.dirt, 0, 3);
		world.setBlock(x + 4, y + 0, z + 4, Blocks.dirt, 0, 3);
		world.setBlock(x + 3, y + 0, z + 4, Blocks.dirt, 0, 3);
		world.setBlock(x + 2, y + 0, z + 4, Blocks.dirt, 0, 3);
		world.setBlock(x + 1, y + 0, z + 4, Blocks.dirt, 0, 3);
		world.setBlock(x + 0, y + 0, z + 4, Blocks.dirt, 0, 3);
		world.setBlock(x + 11, y + 0, z + 3, Blocks.dirt, 0, 3);
		world.setBlock(x + 10, y + 0, z + 3, Blocks.dirt, 0, 3);
		world.setBlock(x + 9, y + 0, z + 3, Blocks.dirt, 0, 3);
		world.setBlock(x + 8, y + 0, z + 3, Blocks.dirt, 0, 3);
		world.setBlock(x + 7, y + 0, z + 3, Blocks.dirt, 0, 3);
		world.setBlock(x + 6, y + 0, z + 3, Blocks.dirt, 0, 3);
		world.setBlock(x + 5, y + 0, z + 3, Blocks.dirt, 0, 3);
		world.setBlock(x + 4, y + 0, z + 3, Blocks.dirt, 0, 3);
		world.setBlock(x + 3, y + 0, z + 3, Blocks.dirt, 0, 3);
		world.setBlock(x + 2, y + 0, z + 3, Blocks.dirt, 0, 3);
		world.setBlock(x + 1, y + 0, z + 3, Blocks.dirt, 0, 3);
		world.setBlock(x + 0, y + 0, z + 3, Blocks.dirt, 0, 3);
		world.setBlock(x + 11, y + 0, z + 2, Blocks.dirt, 0, 3);
		world.setBlock(x + 10, y + 0, z + 2, Blocks.dirt, 0, 3);
		world.setBlock(x + 9, y + 0, z + 2, Blocks.dirt, 0, 3);
		world.setBlock(x + 8, y + 0, z + 2, Blocks.dirt, 0, 3);
		world.setBlock(x + 7, y + 0, z + 2, Blocks.dirt, 0, 3);
		world.setBlock(x + 6, y + 0, z + 2, Blocks.dirt, 0, 3);
		world.setBlock(x + 5, y + 0, z + 2, Blocks.dirt, 0, 3);
		world.setBlock(x + 4, y + 0, z + 2, Blocks.dirt, 0, 3);
		world.setBlock(x + 3, y + 0, z + 2, Blocks.dirt, 0, 3);
		world.setBlock(x + 2, y + 0, z + 2, Blocks.dirt, 0, 3);
		world.setBlock(x + 1, y + 0, z + 2, Blocks.dirt, 0, 3);
		world.setBlock(x + 0, y + 0, z + 2, Blocks.dirt, 0, 3);
		world.setBlock(x + 11, y + 0, z + 1, Blocks.dirt, 0, 3);
		world.setBlock(x + 10, y + 0, z + 1, Blocks.dirt, 0, 3);
		world.setBlock(x + 9, y + 0, z + 1, Blocks.dirt, 0, 3);
		world.setBlock(x + 8, y + 0, z + 1, Blocks.dirt, 0, 3);
		world.setBlock(x + 7, y + 0, z + 1, Blocks.dirt, 0, 3);
		world.setBlock(x + 6, y + 0, z + 1, Blocks.dirt, 0, 3);
		world.setBlock(x + 5, y + 0, z + 1, Blocks.dirt, 0, 3);
		world.setBlock(x + 4, y + 0, z + 1, Blocks.dirt, 0, 3);
		world.setBlock(x + 3, y + 0, z + 1, Blocks.dirt, 0, 3);
		world.setBlock(x + 2, y + 0, z + 1, Blocks.dirt, 0, 3);
		world.setBlock(x + 1, y + 0, z + 1, Blocks.dirt, 0, 3);
		world.setBlock(x + 0, y + 0, z + 1, Blocks.dirt, 0, 3);
		world.setBlock(x + 11, y + 0, z + 0, Blocks.dirt, 0, 3);
		world.setBlock(x + 10, y + 0, z + 0, Blocks.dirt, 0, 3);
		world.setBlock(x + 9, y + 0, z + 0, Blocks.dirt, 0, 3);
		world.setBlock(x + 8, y + 0, z + 0, Blocks.dirt, 0, 3);
		world.setBlock(x + 7, y + 0, z + 0, Blocks.dirt, 0, 3);
		world.setBlock(x + 6, y + 0, z + 0, Blocks.dirt, 0, 3);
		world.setBlock(x + 5, y + 0, z + 0, Blocks.dirt, 0, 3);
		world.setBlock(x + 4, y + 0, z + 0, Blocks.dirt, 0, 3);
		world.setBlock(x + 3, y + 0, z + 0, Blocks.dirt, 0, 3);
		world.setBlock(x + 2, y + 0, z + 0, Blocks.dirt, 0, 3);
		world.setBlock(x + 1, y + 0, z + 0, Blocks.dirt, 0, 3);
		world.setBlock(x + 0, y + 0, z + 0, Blocks.dirt, 0, 3);
		world.setBlock(x + 11, y + 1, z + 17, Blocks.dirt, 0, 3);
		world.setBlock(x + 10, y + 1, z + 17, Blocks.dirt, 0, 3);
		world.setBlock(x + 9, y + 1, z + 17, Blocks.dirt, 0, 3);
		world.setBlock(x + 8, y + 1, z + 17, Blocks.dirt, 0, 3);
		world.setBlock(x + 7, y + 1, z + 17, Blocks.dirt, 0, 3);
		world.setBlock(x + 6, y + 1, z + 17, Blocks.dirt, 0, 3);
		world.setBlock(x + 5, y + 1, z + 17, Blocks.dirt, 0, 3);
		world.setBlock(x + 4, y + 1, z + 17, Blocks.dirt, 0, 3);
		world.setBlock(x + 3, y + 1, z + 17, Blocks.dirt, 0, 3);
		world.setBlock(x + 2, y + 1, z + 17, Blocks.dirt, 0, 3);
		world.setBlock(x + 1, y + 1, z + 17, Blocks.dirt, 0, 3);
		world.setBlock(x + 0, y + 1, z + 17, Blocks.dirt, 0, 3);
		world.setBlock(x + 11, y + 1, z + 16, Blocks.dirt, 0, 3);
		world.setBlock(x + 10, y + 1, z + 16, Blocks.dirt, 0, 3);
		world.setBlock(x + 9, y + 1, z + 16, Blocks.dirt, 0, 3);
		world.setBlock(x + 8, y + 1, z + 16, Blocks.dirt, 0, 3);
		world.setBlock(x + 7, y + 1, z + 16, Blocks.dirt, 0, 3);
		world.setBlock(x + 6, y + 1, z + 16, Blocks.dirt, 0, 3);
		world.setBlock(x + 5, y + 1, z + 16, Blocks.dirt, 0, 3);
		world.setBlock(x + 4, y + 1, z + 16, Blocks.dirt, 0, 3);
		world.setBlock(x + 3, y + 1, z + 16, Blocks.dirt, 0, 3);
		world.setBlock(x + 2, y + 1, z + 16, Blocks.dirt, 0, 3);
		world.setBlock(x + 1, y + 1, z + 16, Blocks.dirt, 0, 3);
		world.setBlock(x + 0, y + 1, z + 16, Blocks.dirt, 0, 3);
		world.setBlock(x + 11, y + 1, z + 15, Blocks.dirt, 0, 3);
		world.setBlock(x + 10, y + 1, z + 15, Blocks.dirt, 0, 3);
		world.setBlock(x + 9, y + 1, z + 15, Blocks.dirt, 0, 3);
		world.setBlock(x + 8, y + 1, z + 15, Blocks.dirt, 0, 3);
		world.setBlock(x + 7, y + 1, z + 15, Blocks.dirt, 0, 3);
		world.setBlock(x + 6, y + 1, z + 15, Blocks.dirt, 0, 3);
		world.setBlock(x + 5, y + 1, z + 15, Blocks.dirt, 0, 3);
		world.setBlock(x + 4, y + 1, z + 15, Blocks.dirt, 0, 3);
		world.setBlock(x + 3, y + 1, z + 15, Blocks.dirt, 0, 3);
		world.setBlock(x + 2, y + 1, z + 15, Blocks.dirt, 0, 3);
		world.setBlock(x + 1, y + 1, z + 15, Blocks.dirt, 0, 3);
		world.setBlock(x + 0, y + 1, z + 15, Blocks.dirt, 0, 3);
		world.setBlock(x + 11, y + 1, z + 14, Blocks.dirt, 0, 3);
		world.setBlock(x + 10, y + 1, z + 14, Blocks.dirt, 0, 3);
		world.setBlock(x + 9, y + 1, z + 14, Blocks.dirt, 0, 3);
		world.setBlock(x + 8, y + 1, z + 14, Blocks.dirt, 0, 3);
		world.setBlock(x + 7, y + 1, z + 14, Blocks.dirt, 0, 3);
		world.setBlock(x + 6, y + 1, z + 14, Blocks.dirt, 0, 3);
		world.setBlock(x + 5, y + 1, z + 14, Blocks.dirt, 0, 3);
		world.setBlock(x + 4, y + 1, z + 14, Blocks.dirt, 0, 3);
		world.setBlock(x + 3, y + 1, z + 14, Blocks.dirt, 0, 3);
		world.setBlock(x + 2, y + 1, z + 14, Blocks.dirt, 0, 3);
		world.setBlock(x + 1, y + 1, z + 14, Blocks.dirt, 0, 3);
		world.setBlock(x + 0, y + 1, z + 14, Blocks.dirt, 0, 3);
		world.setBlock(x + 11, y + 1, z + 13, Blocks.dirt, 0, 3);
		world.setBlock(x + 10, y + 1, z + 13, Blocks.dirt, 0, 3);
		world.setBlock(x + 9, y + 1, z + 13, Blocks.dirt, 0, 3);
		world.setBlock(x + 8, y + 1, z + 13, Blocks.dirt, 0, 3);
		world.setBlock(x + 7, y + 1, z + 13, Blocks.dirt, 0, 3);
		world.setBlock(x + 6, y + 1, z + 13, Blocks.dirt, 0, 3);
		world.setBlock(x + 5, y + 1, z + 13, Blocks.dirt, 0, 3);
		world.setBlock(x + 4, y + 1, z + 13, Blocks.dirt, 0, 3);
		world.setBlock(x + 3, y + 1, z + 13, Blocks.dirt, 0, 3);
		world.setBlock(x + 2, y + 1, z + 13, Blocks.dirt, 0, 3);
		world.setBlock(x + 1, y + 1, z + 13, Blocks.dirt, 0, 3);
		world.setBlock(x + 0, y + 1, z + 13, Blocks.dirt, 0, 3);
