package fossilsarcheology.server.world.gen;

import fossilsarcheology.server.block.FABlockRegistry;
import fossilsarcheology.server.world.FALoot;
import net.minecraft.init.Blocks;
import net.minecraft.item.ItemDoor;
import net.minecraft.util.EnumFacing;
import net.minecraft.util.math.BlockPos;
import net.minecraft.world.World;
import net.minecraft.world.gen.feature.WorldGenerator;

import java.util.Random;

public class HellBoatWorldGen extends WorldGenerator {
//    protected static final WeightedRandomCHESTContent[] field_111019_a = new WeightedRandomCHESTContent[]{new WeightedRandomCHESTContent(Item.getItemFromBlock(FABlockRegistry.ANCIENT_GLASS), 0, 2, 5, 25), new WeightedRandomCHESTContent(FAItemRegistry.INSTANCE.relic, 0, 1, 2, 76), new WeightedRandomCHESTContent(FAItemRegistry.INSTANCE.ancientSword, 0, 1, 3, 15), new WeightedRandomCHESTContent(Item.getItemFromBlock(FABlockRegistry.INSTANCE.blockSkull), 0, 1, 2, 60), new WeightedRandomCHESTContent(Item.getItemFromBlock(FABlockRegistry.SKULL_LANTERN), 0, 1, 2, 45), new WeightedRandomCHESTContent(Item.getItemFromBlock(FABlockRegistry.INSTANCE.drum), 0, 1, 1, 28), new WeightedRandomCHESTContent(FAItemRegistry.INSTANCE.potteryShards, 0, 1, 3, 70), new WeightedRandomCHESTContent(FAItemRegistry.INSTANCE.goldjavelin, 0, 1, 1, 33), new WeightedRandomCHESTContent(FAItemRegistry.INSTANCE.ironjavelin, 0, 1, 1, 46), new WeightedRandomCHESTContent(FAItemRegistry.INSTANCE.stoneboard, 0, 1, 3, 25), new WeightedRandomCHESTContent(Items.bone, 0, 1, 3, 85), new WeightedRandomCHESTContent(Items.emerald, 0, 1, 3, 25), new WeightedRandomCHESTContent(Items.flint, 0, 1, 3, 35), new WeightedRandomCHESTContent(Items.blaze_rod, 0, 1, 3, 30), new WeightedRandomCHESTContent(Items.ghast_tear, 0, 1, 2, 25), new WeightedRandomCHESTContent(Item.getItemFromBlock(Blocks.bookshelf), 0, 1, 5, 35), new WeightedRandomCHESTContent(Item.getItemFromBlock(Blocks.glowstone), 0, 1, 4, 35), new WeightedRandomCHESTContent(Item.getItemFromBlock(Blocks.OBSIDIAN), 0, 1, 6, 25), new WeightedRandomCHESTContent(Items.netherbrick, 0, 1, 12, 65), new WeightedRandomCHESTContent(Item.getItemFromBlock(Blocks.tnt), 0, 1, 6, 25)};

    @SuppressWarnings("deprecation")
    @Override
    public boolean generate(World world, Random rand, BlockPos pos) {
        generate_r0(world, rand, pos.getX(), pos.getY(), pos.getZ());
        return true;

    }

    @SuppressWarnings("deprecation")
    public boolean generate_r0(World world, Random rand, int x, int y, int z) {
        BlockUtils.setBlock(world, x + 4, y + -2, z + 5, Blocks.NETHER_BRICK, 0, 3);
        BlockUtils.setBlock(world, x + 5, y + -2, z + 5, Blocks.NETHER_BRICK, 0, 3);
        BlockUtils.setBlock(world, x + 6, y + -2, z + 5, Blocks.NETHER_BRICK, 0, 3);
        BlockUtils.setBlock(world, x + 7, y + -2, z + 5, Blocks.NETHER_BRICK, 0, 3);
        BlockUtils.setBlock(world, x + 8, y + -2, z + 5, Blocks.NETHER_BRICK, 0, 3);
        BlockUtils.setBlock(world, x + 9, y + -2, z + 5, Blocks.NETHER_BRICK, 0, 3);
        BlockUtils.setBlock(world, x + 10, y + -2, z + 5, Blocks.NETHER_BRICK, 0, 3);
        BlockUtils.setBlock(world, x + 11, y + -2, z + 5, Blocks.NETHER_BRICK, 0, 3);
        BlockUtils.setBlock(world, x + 12, y + -2, z + 5, Blocks.NETHER_BRICK, 0, 3);
        BlockUtils.setBlock(world, x + 13, y + -2, z + 5, Blocks.NETHER_BRICK, 0, 3);
        BlockUtils.setBlock(world, x + 14, y + -2, z + 5, Blocks.NETHER_BRICK, 0, 3);
        BlockUtils.setBlock(world, x + 15, y + -2, z + 5, Blocks.NETHER_BRICK, 0, 3);
        BlockUtils.setBlock(world, x + 16, y + -2, z + 5, Blocks.NETHER_BRICK, 0, 3);
        BlockUtils.setBlock(world, x + 17, y + -2, z + 5, Blocks.NETHER_BRICK, 0, 3);
        BlockUtils.setBlock(world, x + 18, y + -2, z + 5, Blocks.NETHER_BRICK, 0, 3);
        BlockUtils.setBlock(world, x + 19, y + -2, z + 5, Blocks.NETHER_BRICK, 0, 3);
        BlockUtils.setBlock(world, x + 20, y + -2, z + 5, Blocks.NETHER_BRICK, 0, 3);
        BlockUtils.setBlock(world, x + 4, y + -1, z + 3, Blocks.NETHER_BRICK, 0, 3);
        BlockUtils.setBlock(world, x + 5, y + -1, z + 3, Blocks.NETHER_BRICK, 0, 3);
        BlockUtils.setBlock(world, x + 6, y + -1, z + 3, Blocks.NETHER_BRICK, 0, 3);
        BlockUtils.setBlock(world, x + 7, y + -1, z + 3, Blocks.NETHER_BRICK, 0, 3);
        BlockUtils.setBlock(world, x + 8, y + -1, z + 3, Blocks.NETHER_BRICK, 0, 3);
        BlockUtils.setBlock(world, x + 9, y + -1, z + 3, Blocks.NETHER_BRICK, 0, 3);
        BlockUtils.setBlock(world, x + 10, y + -1, z + 3, Blocks.NETHER_BRICK, 0, 3);
        BlockUtils.setBlock(world, x + 11, y + -1, z + 3, Blocks.NETHER_BRICK, 0, 3);
        BlockUtils.setBlock(world, x + 12, y + -1, z + 3, Blocks.NETHER_BRICK, 0, 3);
        BlockUtils.setBlock(world, x + 13, y + -1, z + 3, Blocks.NETHER_BRICK, 0, 3);
        BlockUtils.setBlock(world, x + 14, y + -1, z + 3, Blocks.NETHER_BRICK, 0, 3);
        BlockUtils.setBlock(world, x + 15, y + -1, z + 3, Blocks.NETHER_BRICK, 0, 3);
        BlockUtils.setBlock(world, x + 16, y + -1, z + 3, Blocks.NETHER_BRICK, 0, 3);
        BlockUtils.setBlock(world, x + 17, y + -1, z + 3, Blocks.NETHER_BRICK, 0, 3);
        BlockUtils.setBlock(world, x + 18, y + -1, z + 3, Blocks.NETHER_BRICK, 0, 3);
        BlockUtils.setBlock(world, x + 19, y + -1, z + 3, Blocks.NETHER_BRICK, 0, 3);
        BlockUtils.setBlock(world, x + 20, y + -1, z + 3, Blocks.NETHER_BRICK, 0, 3);
        BlockUtils.setBlock(world, x + 4, y + -1, z + 4, Blocks.NETHER_BRICK, 0, 3);
        BlockUtils.setBlock(world, x + 5, y + -1, z + 4, Blocks.NETHER_BRICK, 0, 3);
        BlockUtils.setBlock(world, x + 6, y + -1, z + 4, Blocks.NETHER_BRICK, 0, 3);
        BlockUtils.setBlock(world, x + 7, y + -1, z + 4, Blocks.NETHER_BRICK, 0, 3);
        BlockUtils.setBlock(world, x + 8, y + -1, z + 4, Blocks.NETHER_BRICK, 0, 3);
        BlockUtils.setBlock(world, x + 9, y + -1, z + 4, Blocks.NETHER_BRICK, 0, 3);
        BlockUtils.setBlock(world, x + 10, y + -1, z + 4, Blocks.NETHER_BRICK, 0, 3);
        BlockUtils.setBlock(world, x + 11, y + -1, z + 4, Blocks.NETHER_BRICK, 0, 3);
        BlockUtils.setBlock(world, x + 12, y + -1, z + 4, Blocks.NETHER_BRICK, 0, 3);
        BlockUtils.setBlock(world, x + 13, y + -1, z + 4, Blocks.NETHER_BRICK, 0, 3);
        BlockUtils.setBlock(world, x + 14, y + -1, z + 4, Blocks.NETHER_BRICK, 0, 3);
        BlockUtils.setBlock(world, x + 15, y + -1, z + 4, Blocks.NETHER_BRICK, 0, 3);
        BlockUtils.setBlock(world, x + 16, y + -1, z + 4, Blocks.NETHER_BRICK, 0, 3);
        BlockUtils.setBlock(world, x + 17, y + -1, z + 4, Blocks.NETHER_BRICK, 0, 3);
        BlockUtils.setBlock(world, x + 18, y + -1, z + 4, Blocks.NETHER_BRICK, 0, 3);
        BlockUtils.setBlock(world, x + 19, y + -1, z + 4, Blocks.NETHER_BRICK, 0, 3);
        BlockUtils.setBlock(world, x + 20, y + -1, z + 4, Blocks.NETHER_BRICK, 0, 3);
        BlockUtils.setBlock(world, x + 2, y + -1, z + 5, Blocks.NETHER_BRICK, 0, 3);
        BlockUtils.setBlock(world, x + 3, y + -1, z + 5, Blocks.NETHER_BRICK, 0, 3);
        BlockUtils.setBlock(world, x + 21, y + -1, z + 5, Blocks.NETHER_BRICK, 0, 3);
        BlockUtils.setBlock(world, x + 22, y + -1, z + 5, Blocks.NETHER_BRICK, 0, 3);
        BlockUtils.setBlock(world, x + 4, y + -1, z + 6, Blocks.NETHER_BRICK, 0, 3);
        BlockUtils.setBlock(world, x + 5, y + -1, z + 6, Blocks.NETHER_BRICK, 0, 3);
        BlockUtils.setBlock(world, x + 6, y + -1, z + 6, Blocks.NETHER_BRICK, 0, 3);
        BlockUtils.setBlock(world, x + 7, y + -1, z + 6, Blocks.NETHER_BRICK, 0, 3);
        BlockUtils.setBlock(world, x + 8, y + -1, z + 6, Blocks.NETHER_BRICK, 0, 3);
        BlockUtils.setBlock(world, x + 9, y + -1, z + 6, Blocks.NETHER_BRICK, 0, 3);
        BlockUtils.setBlock(world, x + 10, y + -1, z + 6, Blocks.NETHER_BRICK, 0, 3);
        BlockUtils.setBlock(world, x + 11, y + -1, z + 6, Blocks.NETHER_BRICK, 0, 3);
        BlockUtils.setBlock(world, x + 12, y + -1, z + 6, Blocks.NETHER_BRICK, 0, 3);
        BlockUtils.setBlock(world, x + 13, y + -1, z + 6, Blocks.NETHER_BRICK, 0, 3);
        BlockUtils.setBlock(world, x + 14, y + -1, z + 6, Blocks.NETHER_BRICK, 0, 3);
        BlockUtils.setBlock(world, x + 15, y + -1, z + 6, Blocks.NETHER_BRICK, 0, 3);
        BlockUtils.setBlock(world, x + 16, y + -1, z + 6, Blocks.NETHER_BRICK, 0, 3);
        BlockUtils.setBlock(world, x + 17, y + -1, z + 6, Blocks.NETHER_BRICK, 0, 3);
        BlockUtils.setBlock(world, x + 18, y + -1, z + 6, Blocks.NETHER_BRICK, 0, 3);
        BlockUtils.setBlock(world, x + 19, y + -1, z + 6, Blocks.NETHER_BRICK, 0, 3);
        BlockUtils.setBlock(world, x + 20, y + -1, z + 6, Blocks.NETHER_BRICK, 0, 3);
        BlockUtils.setBlock(world, x + 4, y + -1, z + 7, Blocks.NETHER_BRICK, 0, 3);
        BlockUtils.setBlock(world, x + 5, y + -1, z + 7, Blocks.NETHER_BRICK, 0, 3);
        BlockUtils.setBlock(world, x + 6, y + -1, z + 7, Blocks.NETHER_BRICK, 0, 3);
        BlockUtils.setBlock(world, x + 7, y + -1, z + 7, Blocks.NETHER_BRICK, 0, 3);
        BlockUtils.setBlock(world, x + 8, y + -1, z + 7, Blocks.NETHER_BRICK, 0, 3);
        BlockUtils.setBlock(world, x + 9, y + -1, z + 7, Blocks.NETHER_BRICK, 0, 3);
        BlockUtils.setBlock(world, x + 10, y + -1, z + 7, Blocks.NETHER_BRICK, 0, 3);
        BlockUtils.setBlock(world, x + 11, y + -1, z + 7, Blocks.NETHER_BRICK, 0, 3);
        BlockUtils.setBlock(world, x + 12, y + -1, z + 7, Blocks.NETHER_BRICK, 0, 3);
        BlockUtils.setBlock(world, x + 13, y + -1, z + 7, Blocks.NETHER_BRICK, 0, 3);
        BlockUtils.setBlock(world, x + 14, y + -1, z + 7, Blocks.NETHER_BRICK, 0, 3);
        BlockUtils.setBlock(world, x + 15, y + -1, z + 7, Blocks.NETHER_BRICK, 0, 3);
        BlockUtils.setBlock(world, x + 16, y + -1, z + 7, Blocks.NETHER_BRICK, 0, 3);
        BlockUtils.setBlock(world, x + 17, y + -1, z + 7, Blocks.NETHER_BRICK, 0, 3);
        BlockUtils.setBlock(world, x + 18, y + -1, z + 7, Blocks.NETHER_BRICK, 0, 3);
        BlockUtils.setBlock(world, x + 19, y + -1, z + 7, Blocks.NETHER_BRICK, 0, 3);
        BlockUtils.setBlock(world, x + 20, y + -1, z + 7, Blocks.NETHER_BRICK, 0, 3);
        BlockUtils.setBlock(world, x + 4, y, z + 2, Blocks.NETHER_BRICK, 0, 3);
        BlockUtils.setBlock(world, x + 5, y, z + 2, Blocks.NETHER_BRICK, 0, 3);
        BlockUtils.setBlock(world, x + 6, y, z + 2, Blocks.NETHER_BRICK, 0, 3);
        BlockUtils.setBlock(world, x + 7, y, z + 2, Blocks.NETHER_BRICK, 0, 3);
        BlockUtils.setBlock(world, x + 8, y, z + 2, Blocks.NETHER_BRICK, 0, 3);
        BlockUtils.setBlock(world, x + 9, y, z + 2, Blocks.NETHER_BRICK, 0, 3);
        BlockUtils.setBlock(world, x + 10, y, z + 2, Blocks.NETHER_BRICK, 0, 3);
        BlockUtils.setBlock(world, x + 11, y, z + 2, Blocks.NETHER_BRICK, 0, 3);
        BlockUtils.setBlock(world, x + 12, y, z + 2, Blocks.NETHER_BRICK, 0, 3);
        BlockUtils.setBlock(world, x + 13, y, z + 2, Blocks.NETHER_BRICK, 0, 3);
        BlockUtils.setBlock(world, x + 14, y, z + 2, Blocks.NETHER_BRICK, 0, 3);
        BlockUtils.setBlock(world, x + 15, y, z + 2, Blocks.NETHER_BRICK, 0, 3);
        BlockUtils.setBlock(world, x + 16, y, z + 2, Blocks.NETHER_BRICK, 0, 3);
        BlockUtils.setBlock(world, x + 17, y, z + 2, Blocks.NETHER_BRICK, 0, 3);
        BlockUtils.setBlock(world, x + 18, y, z + 2, Blocks.NETHER_BRICK, 0, 3);
        BlockUtils.setBlock(world, x + 19, y, z + 2, Blocks.NETHER_BRICK, 0, 3);
        BlockUtils.setBlock(world, x + 20, y, z + 2, Blocks.NETHER_BRICK, 0, 3);
        BlockUtils.setBlock(world, x + 3, y, z + 3, Blocks.NETHER_BRICK, 0, 3);
        BlockUtils.setBlock(world, x + 4, y, z + 3, Blocks.OBSIDIAN, 0, 3);
        BlockUtils.setBlock(world, x + 5, y, z + 3, Blocks.OBSIDIAN, 0, 3);
        BlockUtils.setBlock(world, x + 6, y, z + 3, Blocks.OBSIDIAN, 0, 3);
        BlockUtils.setBlock(world, x + 7, y, z + 3, Blocks.OBSIDIAN, 0, 3);
        BlockUtils.setBlock(world, x + 8, y, z + 3, Blocks.OBSIDIAN, 0, 3);
        BlockUtils.setBlock(world, x + 9, y, z + 3, Blocks.OBSIDIAN, 0, 3);
        BlockUtils.setBlock(world, x + 10, y, z + 3, Blocks.OBSIDIAN, 0, 3);
        BlockUtils.setBlock(world, x + 11, y, z + 3, Blocks.OBSIDIAN, 0, 3);
        BlockUtils.setBlock(world, x + 12, y, z + 3, Blocks.OBSIDIAN, 0, 3);
        BlockUtils.setBlock(world, x + 13, y, z + 3, Blocks.OBSIDIAN, 0, 3);
        BlockUtils.setBlock(world, x + 14, y, z + 3, Blocks.OBSIDIAN, 0, 3);
        BlockUtils.setBlock(world, x + 15, y, z + 3, Blocks.OBSIDIAN, 0, 3);
        BlockUtils.setBlock(world, x + 16, y, z + 3, Blocks.OBSIDIAN, 0, 3);
        BlockUtils.setBlock(world, x + 17, y, z + 3, Blocks.OBSIDIAN, 0, 3);
        BlockUtils.setBlock(world, x + 18, y, z + 3, Blocks.OBSIDIAN, 0, 3);
        BlockUtils.setBlock(world, x + 19, y, z + 3, Blocks.OBSIDIAN, 0, 3);
        BlockUtils.setBlock(world, x + 20, y, z + 3, Blocks.OBSIDIAN, 0, 3);
        BlockUtils.setBlock(world, x + 21, y, z + 3, Blocks.NETHER_BRICK, 0, 3);
        BlockUtils.setBlock(world, x + 2, y, z + 4, Blocks.NETHER_BRICK, 0, 3);
        BlockUtils.setBlock(world, x + 3, y, z + 4, Blocks.NETHER_BRICK, 0, 3);
        BlockUtils.setBlock(world, x + 4, y, z + 4, Blocks.OBSIDIAN, 0, 3);
        BlockUtils.setBlock(world, x + 5, y, z + 4, Blocks.OBSIDIAN, 0, 3);
        BlockUtils.setBlock(world, x + 6, y, z + 4, Blocks.OBSIDIAN, 0, 3);
        BlockUtils.setBlock(world, x + 7, y, z + 4, Blocks.OBSIDIAN, 0, 3);
        BlockUtils.setBlock(world, x + 8, y, z + 4, Blocks.OBSIDIAN, 0, 3);
        BlockUtils.setBlock(world, x + 9, y, z + 4, Blocks.OBSIDIAN, 0, 3);
        BlockUtils.setBlock(world, x + 10, y, z + 4, Blocks.OBSIDIAN, 0, 3);
        BlockUtils.setBlock(world, x + 11, y, z + 4, Blocks.OBSIDIAN, 0, 3);
        BlockUtils.setBlock(world, x + 12, y, z + 4, Blocks.OBSIDIAN, 0, 3);
        BlockUtils.setBlock(world, x + 13, y, z + 4, Blocks.OBSIDIAN, 0, 3);
        BlockUtils.setBlock(world, x + 14, y, z + 4, Blocks.OBSIDIAN, 0, 3);
        BlockUtils.setBlock(world, x + 15, y, z + 4, Blocks.OBSIDIAN, 0, 3);
        BlockUtils.setBlock(world, x + 16, y, z + 4, Blocks.OBSIDIAN, 0, 3);
        BlockUtils.setBlock(world, x + 17, y, z + 4, Blocks.OBSIDIAN, 0, 3);
        BlockUtils.setBlock(world, x + 18, y, z + 4, Blocks.OBSIDIAN, 0, 3);
        BlockUtils.setBlock(world, x + 19, y, z + 4, Blocks.OBSIDIAN, 0, 3);
        BlockUtils.setBlock(world, x + 20, y, z + 4, Blocks.OBSIDIAN, 0, 3);
        BlockUtils.setBlock(world, x + 21, y, z + 4, Blocks.NETHER_BRICK, 0, 3);
        BlockUtils.setBlock(world, x + 22, y, z + 4, Blocks.NETHER_BRICK, 0, 3);
        BlockUtils.setBlock(world, x + 1, y, z + 5, Blocks.NETHER_BRICK, 0, 3);
        BlockUtils.setBlock(world, x + 2, y, z + 5, Blocks.OBSIDIAN, 0, 3);
        BlockUtils.setBlock(world, x + 3, y, z + 5, Blocks.OBSIDIAN, 0, 3);
        BlockUtils.setBlock(world, x + 4, y, z + 5, Blocks.OBSIDIAN, 0, 3);
        BlockUtils.setBlock(world, x + 5, y, z + 5, Blocks.OBSIDIAN, 0, 3);
        BlockUtils.setBlock(world, x + 6, y, z + 5, Blocks.OBSIDIAN, 0, 3);
        BlockUtils.setBlock(world, x + 7, y, z + 5, Blocks.OBSIDIAN, 0, 3);
        BlockUtils.setBlock(world, x + 8, y, z + 5, Blocks.OBSIDIAN, 0, 3);
        BlockUtils.setBlock(world, x + 9, y, z + 5, Blocks.OBSIDIAN, 0, 3);
        BlockUtils.setBlock(world, x + 10, y, z + 5, Blocks.OBSIDIAN, 0, 3);
        BlockUtils.setBlock(world, x + 11, y, z + 5, Blocks.OBSIDIAN, 0, 3);
        BlockUtils.setBlock(world, x + 12, y, z + 5, Blocks.OBSIDIAN, 0, 3);
        BlockUtils.setBlock(world, x + 13, y, z + 5, Blocks.OBSIDIAN, 0, 3);
        BlockUtils.setBlock(world, x + 14, y, z + 5, Blocks.OBSIDIAN, 0, 3);
        BlockUtils.setBlock(world, x + 15, y, z + 5, Blocks.OBSIDIAN, 0, 3);
        BlockUtils.setBlock(world, x + 16, y, z + 5, Blocks.OBSIDIAN, 0, 3);
        BlockUtils.setBlock(world, x + 17, y, z + 5, Blocks.OBSIDIAN, 0, 3);
        BlockUtils.setBlock(world, x + 18, y, z + 5, Blocks.OBSIDIAN, 0, 3);
        BlockUtils.setBlock(world, x + 19, y, z + 5, Blocks.OBSIDIAN, 0, 3);
        BlockUtils.setBlock(world, x + 20, y, z + 5, Blocks.OBSIDIAN, 0, 3);
        BlockUtils.setBlock(world, x + 21, y, z + 5, Blocks.OBSIDIAN, 0, 3);
        BlockUtils.setBlock(world, x + 22, y, z + 5, Blocks.OBSIDIAN, 0, 3);
        BlockUtils.setBlock(world, x + 23, y, z + 5, Blocks.NETHER_BRICK, 0, 3);
        BlockUtils.setBlock(world, x + 24, y, z + 5, Blocks.NETHER_BRICK, 0, 3);
        BlockUtils.setBlock(world, x + 2, y, z + 6, Blocks.NETHER_BRICK, 0, 3);
        BlockUtils.setBlock(world, x + 3, y, z + 6, Blocks.NETHER_BRICK, 0, 3);
        BlockUtils.setBlock(world, x + 4, y, z + 6, Blocks.OBSIDIAN, 0, 3);
        BlockUtils.setBlock(world, x + 5, y, z + 6, Blocks.OBSIDIAN, 0, 3);
        BlockUtils.setBlock(world, x + 6, y, z + 6, Blocks.OBSIDIAN, 0, 3);
        BlockUtils.setBlock(world, x + 7, y, z + 6, Blocks.OBSIDIAN, 0, 3);
        BlockUtils.setBlock(world, x + 8, y, z + 6, Blocks.OBSIDIAN, 0, 3);
        BlockUtils.setBlock(world, x + 9, y, z + 6, Blocks.OBSIDIAN, 0, 3);
        BlockUtils.setBlock(world, x + 10, y, z + 6, Blocks.OBSIDIAN, 0, 3);
        BlockUtils.setBlock(world, x + 11, y, z + 6, Blocks.OBSIDIAN, 0, 3);
        BlockUtils.setBlock(world, x + 12, y, z + 6, Blocks.OBSIDIAN, 0, 3);
        BlockUtils.setBlock(world, x + 13, y, z + 6, Blocks.OBSIDIAN, 0, 3);
        BlockUtils.setBlock(world, x + 14, y, z + 6, Blocks.OBSIDIAN, 0, 3);
        BlockUtils.setBlock(world, x + 15, y, z + 6, Blocks.OBSIDIAN, 0, 3);
        BlockUtils.setBlock(world, x + 16, y, z + 6, Blocks.OBSIDIAN, 0, 3);
        BlockUtils.setBlock(world, x + 17, y, z + 6, Blocks.OBSIDIAN, 0, 3);
        BlockUtils.setBlock(world, x + 18, y, z + 6, Blocks.OBSIDIAN, 0, 3);
        BlockUtils.setBlock(world, x + 19, y, z + 6, Blocks.OBSIDIAN, 0, 3);
        BlockUtils.setBlock(world, x + 20, y, z + 6, Blocks.OBSIDIAN, 0, 3);
        BlockUtils.setBlock(world, x + 21, y, z + 6, Blocks.NETHER_BRICK, 0, 3);
        BlockUtils.setBlock(world, x + 22, y, z + 6, Blocks.NETHER_BRICK, 0, 3);
        BlockUtils.setBlock(world, x + 3, y, z + 7, Blocks.NETHER_BRICK, 0, 3);
        BlockUtils.setBlock(world, x + 4, y, z + 7, Blocks.OBSIDIAN, 0, 3);
        BlockUtils.setBlock(world, x + 5, y, z + 7, Blocks.OBSIDIAN, 0, 3);
        BlockUtils.setBlock(world, x + 6, y, z + 7, Blocks.OBSIDIAN, 0, 3);
        BlockUtils.setBlock(world, x + 7, y, z + 7, Blocks.OBSIDIAN, 0, 3);
        BlockUtils.setBlock(world, x + 8, y, z + 7, Blocks.OBSIDIAN, 0, 3);
        BlockUtils.setBlock(world, x + 9, y, z + 7, Blocks.OBSIDIAN, 0, 3);
        BlockUtils.setBlock(world, x + 10, y, z + 7, Blocks.OBSIDIAN, 0, 3);
        BlockUtils.setBlock(world, x + 11, y, z + 7, Blocks.OBSIDIAN, 0, 3);
        BlockUtils.setBlock(world, x + 12, y, z + 7, Blocks.OBSIDIAN, 0, 3);
        BlockUtils.setBlock(world, x + 13, y, z + 7, Blocks.OBSIDIAN, 0, 3);
        BlockUtils.setBlock(world, x + 14, y, z + 7, Blocks.OBSIDIAN, 0, 3);
        BlockUtils.setBlock(world, x + 15, y, z + 7, Blocks.OBSIDIAN, 0, 3);
        BlockUtils.setBlock(world, x + 16, y, z + 7, Blocks.OBSIDIAN, 0, 3);
        BlockUtils.setBlock(world, x + 17, y, z + 7, Blocks.OBSIDIAN, 0, 3);
        BlockUtils.setBlock(world, x + 18, y, z + 7, Blocks.OBSIDIAN, 0, 3);
        BlockUtils.setBlock(world, x + 19, y, z + 7, Blocks.OBSIDIAN, 0, 3);
        BlockUtils.setBlock(world, x + 20, y, z + 7, Blocks.OBSIDIAN, 0, 3);
        BlockUtils.setBlock(world, x + 21, y, z + 7, Blocks.NETHER_BRICK, 0, 3);
        BlockUtils.setBlock(world, x + 4, y, z + 8, Blocks.NETHER_BRICK, 0, 3);
        BlockUtils.setBlock(world, x + 5, y, z + 8, Blocks.NETHER_BRICK, 0, 3);
        BlockUtils.setBlock(world, x + 6, y, z + 8, Blocks.NETHER_BRICK, 0, 3);
        BlockUtils.setBlock(world, x + 7, y, z + 8, Blocks.NETHER_BRICK, 0, 3);
        BlockUtils.setBlock(world, x + 8, y, z + 8, Blocks.NETHER_BRICK, 0, 3);
        BlockUtils.setBlock(world, x + 9, y, z + 8, Blocks.NETHER_BRICK, 0, 3);
        BlockUtils.setBlock(world, x + 10, y, z + 8, Blocks.NETHER_BRICK, 0, 3);
        BlockUtils.setBlock(world, x + 11, y, z + 8, Blocks.NETHER_BRICK, 0, 3);
        BlockUtils.setBlock(world, x + 12, y, z + 8, Blocks.NETHER_BRICK, 0, 3);
        BlockUtils.setBlock(world, x + 13, y, z + 8, Blocks.NETHER_BRICK, 0, 3);
        BlockUtils.setBlock(world, x + 14, y, z + 8, Blocks.NETHER_BRICK, 0, 3);
        BlockUtils.setBlock(world, x + 15, y, z + 8, Blocks.NETHER_BRICK, 0, 3);
        BlockUtils.setBlock(world, x + 16, y, z + 8, Blocks.NETHER_BRICK, 0, 3);
        BlockUtils.setBlock(world, x + 17, y, z + 8, Blocks.NETHER_BRICK, 0, 3);
        BlockUtils.setBlock(world, x + 18, y, z + 8, Blocks.NETHER_BRICK, 0, 3);
        BlockUtils.setBlock(world, x + 19, y, z + 8, Blocks.NETHER_BRICK, 0, 3);
        BlockUtils.setBlock(world, x + 20, y, z + 8, Blocks.NETHER_BRICK, 0, 3);
        BlockUtils.setBlock(world, x + 4, y + 1, z + 1, Blocks.NETHER_BRICK, 0, 3);
        BlockUtils.setBlock(world, x + 5, y + 1, z + 1, Blocks.NETHER_BRICK, 0, 3);
        BlockUtils.setBlock(world, x + 6, y + 1, z + 1, Blocks.NETHER_BRICK, 0, 3);
        BlockUtils.setBlock(world, x + 7, y + 1, z + 1, Blocks.NETHER_BRICK, 0, 3);
        BlockUtils.setBlock(world, x + 8, y + 1, z + 1, Blocks.NETHER_BRICK, 0, 3);
        BlockUtils.setBlock(world, x + 9, y + 1, z + 1, Blocks.NETHER_BRICK, 0, 3);
        BlockUtils.setBlock(world, x + 10, y + 1, z + 1, Blocks.NETHER_BRICK, 0, 3);
        BlockUtils.setBlock(world, x + 11, y + 1, z + 1, Blocks.NETHER_BRICK, 0, 3);
        BlockUtils.setBlock(world, x + 12, y + 1, z + 1, Blocks.NETHER_BRICK, 0, 3);
        BlockUtils.setBlock(world, x + 13, y + 1, z + 1, Blocks.NETHER_BRICK, 0, 3);
        BlockUtils.setBlock(world, x + 14, y + 1, z + 1, Blocks.NETHER_BRICK, 0, 3);
        BlockUtils.setBlock(world, x + 15, y + 1, z + 1, Blocks.NETHER_BRICK, 0, 3);
        BlockUtils.setBlock(world, x + 16, y + 1, z + 1, Blocks.NETHER_BRICK, 0, 3);
        BlockUtils.setBlock(world, x + 17, y + 1, z + 1, Blocks.NETHER_BRICK, 0, 3);
        BlockUtils.setBlock(world, x + 18, y + 1, z + 1, Blocks.NETHER_BRICK, 0, 3);
        BlockUtils.setBlock(world, x + 19, y + 1, z + 1, Blocks.NETHER_BRICK, 0, 3);
        BlockUtils.setBlock(world, x + 20, y + 1, z + 1, Blocks.NETHER_BRICK, 0, 3);
        BlockUtils.setBlock(world, x + 3, y + 1, z + 2, Blocks.NETHER_BRICK, 0, 3);
        BlockUtils.setBlock(world, x + 4, y + 1, z + 2, FABlockRegistry.SKULL_BLOCK, 0, 3);
        BlockUtils.setBlock(world, x + 5, y + 1, z + 2, Blocks.AIR, 0, 3);
        BlockUtils.setBlock(world, x + 6, y + 1, z + 2, Blocks.AIR, 0, 3);
        BlockUtils.setBlock(world, x + 7, y + 1, z + 2, Blocks.AIR, 0, 3);
        BlockUtils.setBlock(world, x + 8, y + 1, z + 2, Blocks.AIR, 0, 3);
        BlockUtils.setBlock(world, x + 9, y + 1, z + 2, Blocks.FURNACE, 3, 3);
        BlockUtils.setBlock(world, x + 10, y + 1, z + 2, Blocks.FURNACE, 3, 3);
        BlockUtils.setBlock(world, x + 11, y + 1, z + 2, Blocks.JUKEBOX, 0, 3);
        BlockUtils.setBlock(world, x + 12, y + 1, z + 2, Blocks.AIR, 0, 3);
        BlockUtils.setBlock(world, x + 13, y + 1, z + 2, Blocks.AIR, 0, 3);
        BlockUtils.setBlock(world, x + 14, y + 1, z + 2, Blocks.WEB, 0, 3);
        BlockUtils.setBlock(world, x + 15, y + 1, z + 2, Blocks.IRON_BARS, 0, 3);
        BlockUtils.setBlock(world, x + 16, y + 1, z + 2, Blocks.AIR, 0, 3);
        BlockUtils.setBlock(world, x + 17, y + 1, z + 2, Blocks.AIR, 0, 3);
        BlockUtils.setBlock(world, x + 18, y + 1, z + 2, Blocks.CHEST, 4, 3);
        this.generateStructureCHESTContents(world, rand, x + 18, y + 1, z + 2, 2 + rand.nextInt(1));
        BlockUtils.setBlock(world, x + 19, y + 1, z + 2, Blocks.IRON_BARS, 0, 3);
        BlockUtils.setBlock(world, x + 20, y + 1, z + 2, Blocks.AIR, 0, 3);
        BlockUtils.setBlock(world, x + 21, y + 1, z + 2, Blocks.NETHER_BRICK, 0, 3);
        BlockUtils.setBlock(world, x + 2, y + 1, z + 3, Blocks.NETHER_BRICK, 0, 3);
        BlockUtils.setBlock(world, x + 3, y + 1, z + 3, Blocks.AIR, 0, 3);
        BlockUtils.setBlock(world, x + 4, y + 1, z + 3, Blocks.AIR, 0, 3);
        BlockUtils.setBlock(world, x + 5, y + 1, z + 3, Blocks.AIR, 0, 3);
        BlockUtils.setBlock(world, x + 6, y + 1, z + 3, Blocks.AIR, 0, 3);
        BlockUtils.setBlock(world, x + 7, y + 1, z + 3, Blocks.AIR, 0, 3);
        BlockUtils.setBlock(world, x + 8, y + 1, z + 3, Blocks.AIR, 0, 3);
        BlockUtils.setBlock(world, x + 9, y + 1, z + 3, Blocks.AIR, 0, 3);
        BlockUtils.setBlock(world, x + 10, y + 1, z + 3, Blocks.AIR, 0, 3);
        BlockUtils.setBlock(world, x + 11, y + 1, z + 3, Blocks.AIR, 0, 3);
        BlockUtils.setBlock(world, x + 12, y + 1, z + 3, Blocks.NETHER_BRICK_FENCE, 0, 3);
        BlockUtils.setBlock(world, x + 13, y + 1, z + 3, Blocks.AIR, 0, 3);
        BlockUtils.setBlock(world, x + 14, y + 1, z + 3, Blocks.AIR, 0, 3);
        BlockUtils.setBlock(world, x + 15, y + 1, z + 3, Blocks.IRON_BARS, 0, 3);
        BlockUtils.setBlock(world, x + 16, y + 1, z + 3, Blocks.AIR, 0, 3);
        BlockUtils.setBlock(world, x + 17, y + 1, z + 3, Blocks.AIR, 0, 3);
        BlockUtils.setBlock(world, x + 18, y + 1, z + 3, Blocks.CHEST, 4, 3);
        this.generateStructureCHESTContents(world, rand, x + 18, y + 1, z + 3, 2 + rand.nextInt(1));
        BlockUtils.setBlock(world, x + 19, y + 1, z + 3, Blocks.IRON_BARS, 0, 3);
        BlockUtils.setBlock(world, x + 20, y + 1, z + 3, Blocks.AIR, 0, 3);
        BlockUtils.setBlock(world, x + 21, y + 1, z + 3, Blocks.AIR, 0, 3);
        BlockUtils.setBlock(world, x + 22, y + 1, z + 3, Blocks.NETHER_BRICK, 0, 3);
        BlockUtils.setBlock(world, x + 1, y + 1, z + 4, Blocks.NETHER_BRICK, 0, 3);
        BlockUtils.setBlock(world, x + 2, y + 1, z + 4, Blocks.AIR, 0, 3);
        BlockUtils.setBlock(world, x + 3, y + 1, z + 4, Blocks.AIR, 0, 3);
        BlockUtils.setBlock(world, x + 4, y + 1, z + 4, Blocks.AIR, 0, 3);
        BlockUtils.setBlock(world, x + 5, y + 1, z + 4, Blocks.AIR, 0, 3);
        BlockUtils.setBlock(world, x + 6, y + 1, z + 4, Blocks.CHEST, 4, 3);
        this.generateStructureCHESTContents(world, rand, x + 6, y + 1, z + 4, 2 + rand.nextInt(1));
        BlockUtils.setBlock(world, x + 7, y + 1, z + 4, Blocks.NETHER_BRICK_STAIRS, 1, 3);
        BlockUtils.setBlock(world, x + 8, y + 1, z + 4, Blocks.AIR, 0, 3);
        BlockUtils.setBlock(world, x + 9, y + 1, z + 4, Blocks.AIR, 0, 3);
        BlockUtils.setBlock(world, x + 10, y + 1, z + 4, Blocks.AIR, 0, 3);
        BlockUtils.setBlock(world, x + 11, y + 1, z + 4, Blocks.AIR, 0, 3);
        BlockUtils.setBlock(world, x + 12, y + 1, z + 4, Blocks.AIR, 0, 3);
        BlockUtils.setBlock(world, x + 13, y + 1, z + 4, Blocks.AIR, 0, 3);
        BlockUtils.setBlock(world, x + 14, y + 1, z + 4, Blocks.AIR, 0, 3);
        BlockUtils.setBlock(world, x + 15, y + 1, z + 4, Blocks.DOUBLE_STONE_SLAB, 0, 3);
        // BlockUtils.setBlock(world, x + 16, y + 1, z + 4, Blocks.IRON_DOOR, 3, 3);
        ItemDoor.placeDoor(world, new BlockPos(x + 16, y + 1, z + 4), EnumFacing.SOUTH, Blocks.IRON_DOOR, false);
        BlockUtils.setBlock(world, x + 17, y + 1, z + 4, Blocks.DOUBLE_STONE_SLAB, 0, 3);
        BlockUtils.setBlock(world, x + 18, y + 1, z + 4, Blocks.IRON_BARS, 0, 3);
        BlockUtils.setBlock(world, x + 19, y + 1, z + 4, Blocks.IRON_BARS, 0, 3);
        BlockUtils.setBlock(world, x + 20, y + 1, z + 4, Blocks.AIR, 0, 3);
        BlockUtils.setBlock(world, x + 21, y + 1, z + 4, Blocks.AIR, 0, 3);
        BlockUtils.setBlock(world, x + 22, y + 1, z + 4, Blocks.AIR, 0, 3);
        BlockUtils.setBlock(world, x + 23, y + 1, z + 4, Blocks.NETHER_BRICK, 0, 3);
        BlockUtils.setBlock(world, x + 1, y + 1, z + 5, Blocks.NETHER_BRICK, 0, 3);
        BlockUtils.setBlock(world, x + 2, y + 1, z + 5, Blocks.AIR, 0, 3);
        BlockUtils.setBlock(world, x + 3, y + 1, z + 5, Blocks.AIR, 0, 3);
        BlockUtils.setBlock(world, x + 4, y + 1, z + 5, Blocks.AIR, 0, 3);
        BlockUtils.setBlock(world, x + 5, y + 1, z + 5, Blocks.AIR, 0, 3);
        BlockUtils.setBlock(world, x + 6, y + 1, z + 5, Blocks.NETHER_BRICK_STAIRS, 4, 3);
        BlockUtils.setBlock(world, x + 7, y + 1, z + 5, Blocks.NETHER_BRICK_STAIRS, 1, 3);
        BlockUtils.setBlock(world, x + 8, y + 1, z + 5, Blocks.AIR, 0, 3);
        BlockUtils.setBlock(world, x + 9, y + 1, z + 5, Blocks.AIR, 0, 3);
        BlockUtils.setBlock(world, x + 10, y + 1, z + 5, Blocks.AIR, 0, 3);
        BlockUtils.setBlock(world, x + 11, y + 1, z + 5, Blocks.AIR, 0, 3);
        BlockUtils.setBlock(world, x + 12, y + 1, z + 5, Blocks.AIR, 0, 3);
        BlockUtils.setBlock(world, x + 13, y + 1, z + 5, Blocks.AIR, 0, 3);
        BlockUtils.setBlock(world, x + 14, y + 1, z + 5, Blocks.AIR, 0, 3);
        BlockUtils.setBlock(world, x + 15, y + 1, z + 5, Blocks.AIR, 0, 3);
        BlockUtils.setBlock(world, x + 16, y + 1, z + 5, Blocks.AIR, 0, 3);
        BlockUtils.setBlock(world, x + 17, y + 1, z + 5, Blocks.AIR, 0, 3);
        BlockUtils.setBlock(world, x + 18, y + 1, z + 5, Blocks.AIR, 0, 3);
        BlockUtils.setBlock(world, x + 19, y + 1, z + 5, Blocks.AIR, 0, 3);
        BlockUtils.setBlock(world, x + 20, y + 1, z + 5, Blocks.AIR, 0, 3);
        BlockUtils.setBlock(world, x + 21, y + 1, z + 5, Blocks.AIR, 0, 3);
        BlockUtils.setBlock(world, x + 22, y + 1, z + 5, Blocks.AIR, 0, 3);
        BlockUtils.setBlock(world, x + 23, y + 1, z + 5, Blocks.NETHER_BRICK_FENCE, 0, 3);
        BlockUtils.setBlock(world, x + 24, y + 1, z + 5, Blocks.NETHER_BRICK, 0, 3);
        BlockUtils.setBlock(world, x + 25, y + 1, z + 5, Blocks.NETHER_BRICK, 0, 3);
        BlockUtils.setBlock(world, x + 1, y + 1, z + 6, Blocks.NETHER_BRICK, 0, 3);
        BlockUtils.setBlock(world, x + 2, y + 1, z + 6, Blocks.WEB, 0, 3);
        BlockUtils.setBlock(world, x + 3, y + 1, z + 6, Blocks.AIR, 0, 3);
        BlockUtils.setBlock(world, x + 4, y + 1, z + 6, Blocks.AIR, 0, 3);
        BlockUtils.setBlock(world, x + 5, y + 1, z + 6, Blocks.AIR, 0, 3);
        BlockUtils.setBlock(world, x + 6, y + 1, z + 6, Blocks.CHEST, 4, 3);
        this.generateStructureCHESTContents(world, rand, x + 6, y + 1, z + 6, 2 + rand.nextInt(1));
        BlockUtils.setBlock(world, x + 7, y + 1, z + 6, Blocks.NETHER_BRICK_STAIRS, 1, 3);
        BlockUtils.setBlock(world, x + 8, y + 1, z + 6, Blocks.AIR, 0, 3);
        BlockUtils.setBlock(world, x + 9, y + 1, z + 6, Blocks.AIR, 0, 3);
        BlockUtils.setBlock(world, x + 10, y + 1, z + 6, Blocks.AIR, 0, 3);
        BlockUtils.setBlock(world, x + 11, y + 1, z + 6, Blocks.AIR, 0, 3);
        BlockUtils.setBlock(world, x + 12, y + 1, z + 6, Blocks.NETHER_BRICK_FENCE, 0, 3);
        BlockUtils.setBlock(world, x + 13, y + 1, z + 6, Blocks.AIR, 0, 3);
        BlockUtils.setBlock(world, x + 14, y + 1, z + 6, Blocks.AIR, 0, 3);
        BlockUtils.setBlock(world, x + 15, y + 1, z + 6, Blocks.DOUBLE_STONE_SLAB, 0, 3);
        // BlockUtils.setBlock(world, x + 16, y + 1, z + 6, Blocks.IRON_DOOR, 1, 3);
        ItemDoor.placeDoor(world, new BlockPos(x + 16, y + 1, z + 6), EnumFacing.SOUTH, Blocks.IRON_DOOR, false);
        BlockUtils.setBlock(world, x + 17, y + 1, z + 6, Blocks.DOUBLE_STONE_SLAB, 0, 3);
        BlockUtils.setBlock(world, x + 18, y + 1, z + 6, Blocks.IRON_BARS, 0, 3);
        BlockUtils.setBlock(world, x + 19, y + 1, z + 6, Blocks.IRON_BARS, 0, 3);
        BlockUtils.setBlock(world, x + 20, y + 1, z + 6, Blocks.AIR, 0, 3);
        BlockUtils.setBlock(world, x + 21, y + 1, z + 6, Blocks.AIR, 0, 3);
        BlockUtils.setBlock(world, x + 22, y + 1, z + 6, Blocks.CHEST, 4, 3);//
        this.generateStructureCHESTContents(world, rand, x + 22, y + 1, z + 6, 2 + rand.nextInt(1));
        BlockUtils.setBlock(world, x + 23, y + 1, z + 6, Blocks.NETHER_BRICK, 0, 3);
        BlockUtils.setBlock(world, x + 2, y + 1, z + 7, Blocks.NETHER_BRICK, 0, 3);
        BlockUtils.setBlock(world, x + 3, y + 1, z + 7, Blocks.AIR, 0, 3);
        BlockUtils.setBlock(world, x + 4, y + 1, z + 7, Blocks.AIR, 0, 3);
        BlockUtils.setBlock(world, x + 5, y + 1, z + 7, Blocks.AIR, 0, 3);
        BlockUtils.setBlock(world, x + 6, y + 1, z + 7, Blocks.AIR, 0, 3);
        BlockUtils.setBlock(world, x + 7, y + 1, z + 7, Blocks.AIR, 0, 3);
        BlockUtils.setBlock(world, x + 8, y + 1, z + 7, Blocks.AIR, 0, 3);
        BlockUtils.setBlock(world, x + 9, y + 1, z + 7, Blocks.AIR, 0, 3);
        BlockUtils.setBlock(world, x + 10, y + 1, z + 7, Blocks.AIR, 0, 3);
        BlockUtils.setBlock(world, x + 12, y + 1, z + 7, Blocks.AIR, 0, 3);
        BlockUtils.setBlock(world, x + 13, y + 1, z + 7, Blocks.AIR, 0, 3);
        BlockUtils.setBlock(world, x + 14, y + 1, z + 7, Blocks.AIR, 0, 3);
        BlockUtils.setBlock(world, x + 15, y + 1, z + 7, Blocks.IRON_BARS, 0, 3);
        BlockUtils.setBlock(world, x + 16, y + 1, z + 7, Blocks.AIR, 0, 3);
        BlockUtils.setBlock(world, x + 17, y + 1, z + 7, Blocks.AIR, 0, 3);
        BlockUtils.setBlock(world, x + 19, y + 1, z + 7, Blocks.IRON_BARS, 0, 3);
        BlockUtils.setBlock(world, x + 20, y + 1, z + 7, Blocks.AIR, 0, 3);
        BlockUtils.setBlock(world, x + 21, y + 1, z + 7, Blocks.AIR, 0, 3);
        BlockUtils.setBlock(world, x + 22, y + 1, z + 7, Blocks.NETHER_BRICK, 0, 3);
        BlockUtils.setBlock(world, x + 3, y + 1, z + 8, Blocks.NETHER_BRICK, 0, 3);
        BlockUtils.setBlock(world, x + 4, y + 1, z + 8, Blocks.ANVIL, 4, 3);
        BlockUtils.setBlock(world, x + 5, y + 1, z + 8, Blocks.AIR, 0, 3);
        BlockUtils.setBlock(world, x + 6, y + 1, z + 8, Blocks.AIR, 0, 3);
        BlockUtils.setBlock(world, x + 7, y + 1, z + 8, Blocks.AIR, 0, 3);
        BlockUtils.setBlock(world, x + 8, y + 1, z + 8, Blocks.AIR, 0, 3);
        BlockUtils.setBlock(world, x + 9, y + 1, z + 8, Blocks.FURNACE, 2, 3);
        BlockUtils.setBlock(world, x + 10, y + 1, z + 8, Blocks.FURNACE, 2, 3);
        BlockUtils.setBlock(world, x + 11, y + 1, z + 8, Blocks.CHEST, 2, 3);//
        this.generateStructureCHESTContents(world, rand, x + 11, y + 1, z + 8, 2 + rand.nextInt(1));
        BlockUtils.setBlock(world, x + 11, y + 1, z + 7, Blocks.AIR, 2, 3);
        BlockUtils.setBlock(world, x + 12, y + 1, z + 8, Blocks.AIR, 0, 3);
        BlockUtils.setBlock(world, x + 13, y + 1, z + 8, Blocks.AIR, 0, 3);
        BlockUtils.setBlock(world, x + 14, y + 1, z + 8, Blocks.AIR, 0, 3);
        BlockUtils.setBlock(world, x + 15, y + 1, z + 8, Blocks.IRON_BARS, 0, 3);
        BlockUtils.setBlock(world, x + 16, y + 1, z + 8, Blocks.AIR, 0, 3);
        BlockUtils.setBlock(world, x + 17, y + 1, z + 8, Blocks.AIR, 0, 3);
        BlockUtils.setBlock(world, x + 18, y + 1, z + 8, Blocks.CHEST, 2, 3);
        this.generateStructureCHESTContents(world, rand, x + 18, y + 1, z + 8, 2 + rand.nextInt(1));
        BlockUtils.setBlock(world, x + 18, y + 1, z + 7, Blocks.AIR, 2, 3);
        BlockUtils.setBlock(world, x + 19, y + 1, z + 8, Blocks.IRON_BARS, 0, 3);
        BlockUtils.setBlock(world, x + 20, y + 1, z + 8, Blocks.WEB, 0, 3);
        BlockUtils.setBlock(world, x + 21, y + 1, z + 8, Blocks.NETHER_BRICK, 0, 3);
        BlockUtils.setBlock(world, x + 4, y + 1, z + 9, Blocks.NETHER_BRICK, 0, 3);
        BlockUtils.setBlock(world, x + 5, y + 1, z + 9, Blocks.NETHER_BRICK, 0, 3);
        BlockUtils.setBlock(world, x + 6, y + 1, z + 9, Blocks.NETHER_BRICK, 0, 3);
        BlockUtils.setBlock(world, x + 7, y + 1, z + 9, Blocks.NETHER_BRICK, 0, 3);
        BlockUtils.setBlock(world, x + 8, y + 1, z + 9, Blocks.NETHER_BRICK, 0, 3);
        BlockUtils.setBlock(world, x + 9, y + 1, z + 9, Blocks.NETHER_BRICK, 0, 3);
        BlockUtils.setBlock(world, x + 10, y + 1, z + 9, Blocks.NETHER_BRICK, 0, 3);
        BlockUtils.setBlock(world, x + 11, y + 1, z + 9, Blocks.NETHER_BRICK, 0, 3);
        BlockUtils.setBlock(world, x + 12, y + 1, z + 9, Blocks.NETHER_BRICK, 0, 3);
        BlockUtils.setBlock(world, x + 13, y + 1, z + 9, Blocks.NETHER_BRICK, 0, 3);
        BlockUtils.setBlock(world, x + 14, y + 1, z + 9, Blocks.NETHER_BRICK, 0, 3);
        BlockUtils.setBlock(world, x + 15, y + 1, z + 9, Blocks.NETHER_BRICK, 0, 3);
        BlockUtils.setBlock(world, x + 16, y + 1, z + 9, Blocks.NETHER_BRICK, 0, 3);
        BlockUtils.setBlock(world, x + 17, y + 1, z + 9, Blocks.NETHER_BRICK, 0, 3);
        BlockUtils.setBlock(world, x + 18, y + 1, z + 9, Blocks.NETHER_BRICK, 0, 3);
        BlockUtils.setBlock(world, x + 19, y + 1, z + 9, Blocks.NETHER_BRICK, 0, 3);
        BlockUtils.setBlock(world, x + 20, y + 1, z + 9, Blocks.NETHER_BRICK, 0, 3);
        BlockUtils.setBlock(world, x + 3, y + 2, z + 1, Blocks.NETHER_BRICK_STAIRS, 4, 3);
        BlockUtils.setBlock(world, x + 4, y + 2, z + 1, Blocks.NETHER_BRICK, 0, 3);
        BlockUtils.setBlock(world, x + 5, y + 2, z + 1, Blocks.NETHER_BRICK, 0, 3);
        BlockUtils.setBlock(world, x + 6, y + 2, z + 1, Blocks.NETHER_BRICK, 0, 3);
        BlockUtils.setBlock(world, x + 7, y + 2, z + 1, Blocks.NETHER_BRICK, 0, 3);
        BlockUtils.setBlock(world, x + 8, y + 2, z + 1, Blocks.NETHER_BRICK, 0, 3);
        BlockUtils.setBlock(world, x + 9, y + 2, z + 1, FABlockRegistry.ANCIENT_GLASS, 0, 3);
        BlockUtils.setBlock(world, x + 10, y + 2, z + 1, FABlockRegistry.ANCIENT_GLASS, 0, 3);
        BlockUtils.setBlock(world, x + 11, y + 2, z + 1, FABlockRegistry.ANCIENT_GLASS, 0, 3);
        BlockUtils.setBlock(world, x + 12, y + 2, z + 1, FABlockRegistry.ANCIENT_GLASS, 0, 3);
        BlockUtils.setBlock(world, x + 13, y + 2, z + 1, Blocks.NETHER_BRICK, 0, 3);
        BlockUtils.setBlock(world, x + 14, y + 2, z + 1, Blocks.NETHER_BRICK, 0, 3);
        BlockUtils.setBlock(world, x + 15, y + 2, z + 1, Blocks.NETHER_BRICK, 0, 3);
        BlockUtils.setBlock(world, x + 16, y + 2, z + 1, Blocks.NETHER_BRICK, 0, 3);
        BlockUtils.setBlock(world, x + 17, y + 2, z + 1, Blocks.NETHER_BRICK, 0, 3);
        BlockUtils.setBlock(world, x + 18, y + 2, z + 1, Blocks.NETHER_BRICK, 0, 3);
        BlockUtils.setBlock(world, x + 19, y + 2, z + 1, Blocks.NETHER_BRICK, 0, 3);
        BlockUtils.setBlock(world, x + 20, y + 2, z + 1, Blocks.NETHER_BRICK, 0, 3);
        BlockUtils.setBlock(world, x + 21, y + 2, z + 1, Blocks.NETHER_BRICK_STAIRS, 5, 3);
        BlockUtils.setBlock(world, x + 2, y + 2, z + 2, Blocks.NETHER_BRICK_STAIRS, 4, 3);
        BlockUtils.setBlock(world, x + 3, y + 2, z + 2, Blocks.NETHER_BRICK, 0, 3);
        BlockUtils.setBlock(world, x + 4, y + 2, z + 2, Blocks.AIR, 0, 3);
        BlockUtils.setBlock(world, x + 5, y + 2, z + 2, Blocks.AIR, 0, 3);
        BlockUtils.setBlock(world, x + 6, y + 2, z + 2, Blocks.AIR, 0, 3);
        BlockUtils.setBlock(world, x + 7, y + 2, z + 2, Blocks.AIR, 0, 3);
        BlockUtils.setBlock(world, x + 8, y + 2, z + 2, Blocks.AIR, 0, 3);
        BlockUtils.setBlock(world, x + 9, y + 2, z + 2, Blocks.AIR, 0, 3);
        BlockUtils.setBlock(world, x + 10, y + 2, z + 2, Blocks.AIR, 0, 3);
        BlockUtils.setBlock(world, x + 11, y + 2, z + 2, Blocks.AIR, 0, 3);
        BlockUtils.setBlock(world, x + 12, y + 2, z + 2, Blocks.AIR, 0, 3);
        BlockUtils.setBlock(world, x + 13, y + 2, z + 2, Blocks.AIR, 0, 3);
        BlockUtils.setBlock(world, x + 14, y + 2, z + 2, Blocks.AIR, 0, 3);
        BlockUtils.setBlock(world, x + 15, y + 2, z + 2, Blocks.IRON_BARS, 0, 3);
        BlockUtils.setBlock(world, x + 16, y + 2, z + 2, Blocks.AIR, 0, 3);
        BlockUtils.setBlock(world, x + 17, y + 2, z + 2, Blocks.AIR, 0, 3);
        BlockUtils.setBlock(world, x + 18, y + 2, z + 2, Blocks.AIR, 0, 3);
        BlockUtils.setBlock(world, x + 19, y + 2, z + 2, Blocks.IRON_BARS, 0, 3);
        BlockUtils.setBlock(world, x + 20, y + 2, z + 2, Blocks.AIR, 0, 3);
        BlockUtils.setBlock(world, x + 21, y + 2, z + 2, Blocks.NETHER_BRICK, 0, 3);
        BlockUtils.setBlock(world, x + 22, y + 2, z + 2, Blocks.NETHER_BRICK_STAIRS, 5, 3);
        BlockUtils.setBlock(world, x + 1, y + 2, z + 3, Blocks.NETHER_BRICK_STAIRS, 4, 3);
        BlockUtils.setBlock(world, x + 2, y + 2, z + 3, Blocks.NETHER_BRICK, 0, 3);
        BlockUtils.setBlock(world, x + 3, y + 2, z + 3, Blocks.AIR, 0, 3);
        BlockUtils.setBlock(world, x + 4, y + 2, z + 3, Blocks.AIR, 0, 3);
        BlockUtils.setBlock(world, x + 5, y + 2, z + 3, Blocks.AIR, 0, 3);
        BlockUtils.setBlock(world, x + 6, y + 2, z + 3, Blocks.AIR, 0, 3);
        BlockUtils.setBlock(world, x + 7, y + 2, z + 3, Blocks.AIR, 0, 3);
        BlockUtils.setBlock(world, x + 8, y + 2, z + 3, Blocks.AIR, 0, 3);
        BlockUtils.setBlock(world, x + 9, y + 2, z + 3, Blocks.AIR, 0, 3);
        BlockUtils.setBlock(world, x + 10, y + 2, z + 3, Blocks.AIR, 0, 3);
        BlockUtils.setBlock(world, x + 11, y + 2, z + 3, Blocks.AIR, 0, 3);
        BlockUtils.setBlock(world, x + 12, y + 2, z + 3, FABlockRegistry.SKULL_LANTERN, 1, 3);
        BlockUtils.setBlock(world, x + 13, y + 2, z + 3, Blocks.AIR, 0, 3);
        BlockUtils.setBlock(world, x + 14, y + 2, z + 3, Blocks.AIR, 0, 3);
        BlockUtils.setBlock(world, x + 15, y + 2, z + 3, Blocks.IRON_BARS, 0, 3);
        BlockUtils.setBlock(world, x + 16, y + 2, z + 3, Blocks.AIR, 0, 3);
        BlockUtils.setBlock(world, x + 17, y + 2, z + 3, Blocks.AIR, 0, 3);
        BlockUtils.setBlock(world, x + 18, y + 2, z + 3, Blocks.AIR, 0, 3);
        BlockUtils.setBlock(world, x + 19, y + 2, z + 3, Blocks.IRON_BARS, 0, 3);
        BlockUtils.setBlock(world, x + 20, y + 2, z + 3, Blocks.AIR, 0, 3);
        BlockUtils.setBlock(world, x + 21, y + 2, z + 3, Blocks.AIR, 0, 3);
        BlockUtils.setBlock(world, x + 22, y + 2, z + 3, Blocks.NETHER_BRICK, 0, 3);
        BlockUtils.setBlock(world, x + 23, y + 2, z + 3, Blocks.NETHER_BRICK_STAIRS, 5, 3);
        BlockUtils.setBlock(world, x + 1, y + 2, z + 4, Blocks.NETHER_BRICK, 0, 3);
        BlockUtils.setBlock(world, x + 3, y + 2, z + 4, Blocks.AIR, 0, 3);
        BlockUtils.setBlock(world, x + 4, y + 2, z + 4, Blocks.AIR, 0, 3);
        BlockUtils.setBlock(world, x + 5, y + 2, z + 4, Blocks.NETHER_BRICK_STAIRS, 4, 3);
        BlockUtils.setBlock(world, x + 6, y + 2, z + 4, Blocks.NETHER_BRICK_STAIRS, 1, 3);
        BlockUtils.setBlock(world, x + 7, y + 2, z + 4, Blocks.AIR, 0, 3);
        BlockUtils.setBlock(world, x + 8, y + 2, z + 4, Blocks.AIR, 0, 3);
        BlockUtils.setBlock(world, x + 9, y + 2, z + 4, Blocks.AIR, 0, 3);
        BlockUtils.setBlock(world, x + 10, y + 2, z + 4, Blocks.AIR, 0, 3);
        BlockUtils.setBlock(world, x + 11, y + 2, z + 4, Blocks.AIR, 0, 3);
        BlockUtils.setBlock(world, x + 12, y + 2, z + 4, Blocks.AIR, 0, 3);
        BlockUtils.setBlock(world, x + 13, y + 2, z + 4, Blocks.AIR, 0, 3);
        BlockUtils.setBlock(world, x + 14, y + 2, z + 4, Blocks.AIR, 0, 3);
        BlockUtils.setBlock(world, x + 15, y + 2, z + 4, Blocks.DOUBLE_STONE_SLAB, 0, 3);
        BlockUtils.setBlock(world, x + 17, y + 2, z + 4, Blocks.DOUBLE_STONE_SLAB, 0, 3);
        BlockUtils.setBlock(world, x + 18, y + 2, z + 4, Blocks.IRON_BARS, 0, 3);
        BlockUtils.setBlock(world, x + 19, y + 2, z + 4, Blocks.IRON_BARS, 0, 3);
        BlockUtils.setBlock(world, x + 20, y + 2, z + 4, Blocks.AIR, 0, 3);
        BlockUtils.setBlock(world, x + 21, y + 2, z + 4, Blocks.AIR, 0, 3);
        BlockUtils.setBlock(world, x + 22, y + 2, z + 4, Blocks.AIR, 0, 3);
        BlockUtils.setBlock(world, x + 23, y + 2, z + 4, Blocks.NETHER_BRICK, 0, 3);
        BlockUtils.setBlock(world, x + 24, y + 2, z + 4, Blocks.NETHER_BRICK_STAIRS, 5, 3);
        BlockUtils.setBlock(world, x + 1, y + 2, z + 5, Blocks.NETHER_BRICK, 0, 3);
        BlockUtils.setBlock(world, x + 2, y + 2, z + 5, Blocks.AIR, 0, 3);
        BlockUtils.setBlock(world, x + 3, y + 2, z + 5, Blocks.AIR, 0, 3);
        BlockUtils.setBlock(world, x + 4, y + 2, z + 5, Blocks.AIR, 0, 3);
        BlockUtils.setBlock(world, x + 5, y + 2, z + 5, Blocks.NETHER_BRICK_STAIRS, 4, 3);
        BlockUtils.setBlock(world, x + 6, y + 2, z + 5, Blocks.NETHER_BRICK_STAIRS, 1, 3);
        BlockUtils.setBlock(world, x + 7, y + 2, z + 5, Blocks.AIR, 0, 3);
        BlockUtils.setBlock(world, x + 8, y + 2, z + 5, Blocks.AIR, 0, 3);
        BlockUtils.setBlock(world, x + 9, y + 2, z + 5, Blocks.AIR, 0, 3);
        BlockUtils.setBlock(world, x + 10, y + 2, z + 5, Blocks.AIR, 0, 3);
        BlockUtils.setBlock(world, x + 11, y + 2, z + 5, Blocks.AIR, 0, 3);
        BlockUtils.setBlock(world, x + 12, y + 2, z + 5, Blocks.AIR, 0, 3);
        BlockUtils.setBlock(world, x + 13, y + 2, z + 5, Blocks.AIR, 0, 3);
        BlockUtils.setBlock(world, x + 14, y + 2, z + 5, Blocks.AIR, 0, 3);
        BlockUtils.setBlock(world, x + 15, y + 2, z + 5, Blocks.AIR, 0, 3);
        BlockUtils.setBlock(world, x + 16, y + 2, z + 5, Blocks.AIR, 0, 3);
        BlockUtils.setBlock(world, x + 17, y + 2, z + 5, Blocks.AIR, 0, 3);
        BlockUtils.setBlock(world, x + 18, y + 2, z + 5, Blocks.AIR, 0, 3);
        BlockUtils.setBlock(world, x + 19, y + 2, z + 5, Blocks.AIR, 0, 3);
        BlockUtils.setBlock(world, x + 20, y + 2, z + 5, Blocks.AIR, 0, 3);
        BlockUtils.setBlock(world, x + 21, y + 2, z + 5, Blocks.AIR, 0, 3);
        BlockUtils.setBlock(world, x + 22, y + 2, z + 5, Blocks.AIR, 0, 3);
        BlockUtils.setBlock(world, x + 23, y + 2, z + 5, FABlockRegistry.SKULL_LANTERN, 1, 3);
        BlockUtils.setBlock(world, x + 24, y + 2, z + 5, Blocks.NETHER_BRICK, 0, 3);
        BlockUtils.setBlock(world, x + 25, y + 2, z + 5, Blocks.NETHER_BRICK, 0, 3);
        BlockUtils.setBlock(world, x + 26, y + 2, z + 5, Blocks.NETHER_BRICK, 0, 3);
        BlockUtils.setBlock(world, x + 27, y + 2, z + 5, Blocks.NETHER_BRICK, 0, 3);
        BlockUtils.setBlock(world, x + 1, y + 2, z + 6, Blocks.NETHER_BRICK, 0, 3);
        BlockUtils.setBlock(world, x + 3, y + 2, z + 6, Blocks.AIR, 0, 3);
        BlockUtils.setBlock(world, x + 4, y + 2, z + 6, Blocks.AIR, 0, 3);
        BlockUtils.setBlock(world, x + 5, y + 2, z + 6, Blocks.NETHER_BRICK_STAIRS, 4, 3);
        BlockUtils.setBlock(world, x + 6, y + 2, z + 6, Blocks.NETHER_BRICK_STAIRS, 1, 3);
        BlockUtils.setBlock(world, x + 7, y + 2, z + 6, Blocks.AIR, 0, 3);
        BlockUtils.setBlock(world, x + 8, y + 2, z + 6, Blocks.AIR, 0, 3);
        BlockUtils.setBlock(world, x + 9, y + 2, z + 6, Blocks.AIR, 0, 3);
        BlockUtils.setBlock(world, x + 10, y + 2, z + 6, Blocks.AIR, 0, 3);
        BlockUtils.setBlock(world, x + 11, y + 2, z + 6, Blocks.AIR, 0, 3);
        BlockUtils.setBlock(world, x + 12, y + 2, z + 6, FABlockRegistry.SKULL_LANTERN, 1, 3);
        BlockUtils.setBlock(world, x + 13, y + 2, z + 6, Blocks.AIR, 0, 3);
        BlockUtils.setBlock(world, x + 14, y + 2, z + 6, Blocks.AIR, 0, 3);
        BlockUtils.setBlock(world, x + 15, y + 2, z + 6, Blocks.DOUBLE_STONE_SLAB, 0, 3);
        BlockUtils.setBlock(world, x + 17, y + 2, z + 6, Blocks.DOUBLE_STONE_SLAB, 0, 3);
        BlockUtils.setBlock(world, x + 18, y + 2, z + 6, Blocks.IRON_BARS, 0, 3);
        BlockUtils.setBlock(world, x + 19, y + 2, z + 6, Blocks.IRON_BARS, 0, 3);
        BlockUtils.setBlock(world, x + 20, y + 2, z + 6, Blocks.AIR, 0, 3);
        BlockUtils.setBlock(world, x + 21, y + 2, z + 6, Blocks.AIR, 0, 3);
        BlockUtils.setBlock(world, x + 22, y + 2, z + 6, Blocks.AIR, 0, 3);
        BlockUtils.setBlock(world, x + 23, y + 2, z + 6, Blocks.NETHER_BRICK, 0, 3);
        BlockUtils.setBlock(world, x + 24, y + 2, z + 6, Blocks.NETHER_BRICK_STAIRS, 5, 3);
        BlockUtils.setBlock(world, x + 1, y + 2, z + 7, Blocks.NETHER_BRICK_STAIRS, 4, 3);
        BlockUtils.setBlock(world, x + 2, y + 2, z + 7, Blocks.NETHER_BRICK, 0, 3);
        BlockUtils.setBlock(world, x + 3, y + 2, z + 7, Blocks.AIR, 0, 3);
        BlockUtils.setBlock(world, x + 4, y + 2, z + 7, Blocks.AIR, 0, 3);
        BlockUtils.setBlock(world, x + 5, y + 2, z + 7, Blocks.AIR, 0, 3);
        BlockUtils.setBlock(world, x + 6, y + 2, z + 7, Blocks.AIR, 0, 3);
        BlockUtils.setBlock(world, x + 7, y + 2, z + 7, Blocks.AIR, 0, 3);
        BlockUtils.setBlock(world, x + 8, y + 2, z + 7, Blocks.AIR, 0, 3);
        BlockUtils.setBlock(world, x + 9, y + 2, z + 7, Blocks.AIR, 0, 3);
        BlockUtils.setBlock(world, x + 10, y + 2, z + 7, Blocks.AIR, 0, 3);
        BlockUtils.setBlock(world, x + 11, y + 2, z + 7, Blocks.AIR, 0, 3);
        BlockUtils.setBlock(world, x + 12, y + 2, z + 7, Blocks.AIR, 0, 3);
        BlockUtils.setBlock(world, x + 13, y + 2, z + 7, Blocks.AIR, 0, 3);
        BlockUtils.setBlock(world, x + 14, y + 2, z + 7, Blocks.AIR, 0, 3);
        BlockUtils.setBlock(world, x + 15, y + 2, z + 7, Blocks.IRON_BARS, 0, 3);
        BlockUtils.setBlock(world, x + 16, y + 2, z + 7, Blocks.AIR, 0, 3);
        BlockUtils.setBlock(world, x + 17, y + 2, z + 7, Blocks.AIR, 0, 3);
        BlockUtils.setBlock(world, x + 18, y + 2, z + 7, Blocks.AIR, 0, 3);
        BlockUtils.setBlock(world, x + 19, y + 2, z + 7, Blocks.IRON_BARS, 0, 3);
        BlockUtils.setBlock(world, x + 20, y + 2, z + 7, Blocks.AIR, 0, 3);
        BlockUtils.setBlock(world, x + 21, y + 2, z + 7, Blocks.AIR, 0, 3);
        BlockUtils.setBlock(world, x + 22, y + 2, z + 7, Blocks.NETHER_BRICK, 0, 3);
        BlockUtils.setBlock(world, x + 23, y + 2, z + 7, Blocks.NETHER_BRICK_STAIRS, 5, 3);
        BlockUtils.setBlock(world, x + 2, y + 2, z + 8, Blocks.NETHER_BRICK_STAIRS, 4, 3);
        BlockUtils.setBlock(world, x + 3, y + 2, z + 8, Blocks.NETHER_BRICK, 0, 3);
        BlockUtils.setBlock(world, x + 4, y + 2, z + 8, Blocks.AIR, 0, 3);
        BlockUtils.setBlock(world, x + 5, y + 2, z + 8, Blocks.AIR, 0, 3);
        BlockUtils.setBlock(world, x + 6, y + 2, z + 8, Blocks.AIR, 0, 3);
        BlockUtils.setBlock(world, x + 7, y + 2, z + 8, Blocks.AIR, 0, 3);
        BlockUtils.setBlock(world, x + 8, y + 2, z + 8, Blocks.AIR, 0, 3);
        BlockUtils.setBlock(world, x + 9, y + 2, z + 8, Blocks.AIR, 0, 3);
        BlockUtils.setBlock(world, x + 10, y + 2, z + 8, Blocks.AIR, 0, 3);
        BlockUtils.setBlock(world, x + 11, y + 2, z + 8, Blocks.AIR, 0, 3);
        BlockUtils.setBlock(world, x + 12, y + 2, z + 8, Blocks.AIR, 0, 3);
        BlockUtils.setBlock(world, x + 13, y + 2, z + 8, Blocks.AIR, 0, 3);
        BlockUtils.setBlock(world, x + 14, y + 2, z + 8, Blocks.AIR, 0, 3);
        BlockUtils.setBlock(world, x + 15, y + 2, z + 8, Blocks.IRON_BARS, 0, 3);
        BlockUtils.setBlock(world, x + 16, y + 2, z + 8, Blocks.AIR, 0, 3);
        BlockUtils.setBlock(world, x + 17, y + 2, z + 8, Blocks.AIR, 0, 3);
        BlockUtils.setBlock(world, x + 18, y + 2, z + 8, Blocks.AIR, 0, 3);
        BlockUtils.setBlock(world, x + 19, y + 2, z + 8, Blocks.IRON_BARS, 0, 3);
        BlockUtils.setBlock(world, x + 20, y + 2, z + 8, Blocks.AIR, 0, 3);
        BlockUtils.setBlock(world, x + 21, y + 2, z + 8, Blocks.NETHER_BRICK, 0, 3);
        BlockUtils.setBlock(world, x + 22, y + 2, z + 8, Blocks.NETHER_BRICK_STAIRS, 5, 3);
        BlockUtils.setBlock(world, x + 3, y + 2, z + 9, Blocks.NETHER_BRICK_STAIRS, 4, 3);
        BlockUtils.setBlock(world, x + 4, y + 2, z + 9, Blocks.NETHER_BRICK, 0, 3);
        BlockUtils.setBlock(world, x + 5, y + 2, z + 9, Blocks.NETHER_BRICK, 0, 3);
        BlockUtils.setBlock(world, x + 6, y + 2, z + 9, Blocks.NETHER_BRICK, 0, 3);
        BlockUtils.setBlock(world, x + 7, y + 2, z + 9, Blocks.NETHER_BRICK, 0, 3);
        BlockUtils.setBlock(world, x + 8, y + 2, z + 9, Blocks.NETHER_BRICK, 0, 3);
        BlockUtils.setBlock(world, x + 9, y + 2, z + 9, FABlockRegistry.ANCIENT_GLASS, 0, 3);
        BlockUtils.setBlock(world, x + 10, y + 2, z + 9, FABlockRegistry.ANCIENT_GLASS, 0, 3);
        BlockUtils.setBlock(world, x + 11, y + 2, z + 9, FABlockRegistry.ANCIENT_GLASS, 0, 3);
        BlockUtils.setBlock(world, x + 12, y + 2, z + 9, FABlockRegistry.ANCIENT_GLASS, 0, 3);
        BlockUtils.setBlock(world, x + 13, y + 2, z + 9, Blocks.NETHER_BRICK, 0, 3);
        BlockUtils.setBlock(world, x + 14, y + 2, z + 9, Blocks.NETHER_BRICK, 0, 3);
        BlockUtils.setBlock(world, x + 15, y + 2, z + 9, Blocks.NETHER_BRICK, 0, 3);
        BlockUtils.setBlock(world, x + 16, y + 2, z + 9, Blocks.NETHER_BRICK, 0, 3);
        BlockUtils.setBlock(world, x + 17, y + 2, z + 9, Blocks.NETHER_BRICK, 0, 3);
        BlockUtils.setBlock(world, x + 18, y + 2, z + 9, Blocks.NETHER_BRICK, 0, 3);
        BlockUtils.setBlock(world, x + 19, y + 2, z + 9, Blocks.NETHER_BRICK, 0, 3);
        BlockUtils.setBlock(world, x + 20, y + 2, z + 9, Blocks.NETHER_BRICK, 0, 3);
        BlockUtils.setBlock(world, x + 21, y + 2, z + 9, Blocks.NETHER_BRICK_STAIRS, 5, 3);
        BlockUtils.setBlock(world, x + 3, y + 3, z + 1, Blocks.NETHER_BRICK_STAIRS, 0, 3);
        BlockUtils.setBlock(world, x + 4, y + 3, z + 1, Blocks.NETHER_BRICK_STAIRS, 2, 3);
        BlockUtils.setBlock(world, x + 5, y + 3, z + 1, Blocks.NETHER_BRICK_STAIRS, 2, 3);
        BlockUtils.setBlock(world, x + 6, y + 3, z + 1, Blocks.NETHER_BRICK_STAIRS, 2, 3);
        BlockUtils.setBlock(world, x + 7, y + 3, z + 1, Blocks.NETHER_BRICK_STAIRS, 2, 3);
        BlockUtils.setBlock(world, x + 8, y + 3, z + 1, Blocks.NETHER_BRICK_STAIRS, 2, 3);
        BlockUtils.setBlock(world, x + 9, y + 3, z + 1, Blocks.NETHER_BRICK_STAIRS, 2, 3);
        BlockUtils.setBlock(world, x + 10, y + 3, z + 1, Blocks.NETHER_BRICK_STAIRS, 2, 3);
        BlockUtils.setBlock(world, x + 11, y + 3, z + 1, Blocks.NETHER_BRICK_STAIRS, 2, 3);
        BlockUtils.setBlock(world, x + 12, y + 3, z + 1, Blocks.NETHER_BRICK_STAIRS, 2, 3);
        BlockUtils.setBlock(world, x + 13, y + 3, z + 1, Blocks.NETHER_BRICK_STAIRS, 2, 3);
        BlockUtils.setBlock(world, x + 14, y + 3, z + 1, Blocks.NETHER_BRICK_STAIRS, 2, 3);
        BlockUtils.setBlock(world, x + 15, y + 3, z + 1, Blocks.NETHER_BRICK_STAIRS, 2, 3);
        BlockUtils.setBlock(world, x + 16, y + 3, z + 1, Blocks.NETHER_BRICK_STAIRS, 2, 3);
        BlockUtils.setBlock(world, x + 17, y + 3, z + 1, Blocks.NETHER_BRICK_STAIRS, 2, 3);
        BlockUtils.setBlock(world, x + 18, y + 3, z + 1, Blocks.NETHER_BRICK_STAIRS, 2, 3);
        BlockUtils.setBlock(world, x + 19, y + 3, z + 1, Blocks.NETHER_BRICK_STAIRS, 2, 3);
        BlockUtils.setBlock(world, x + 20, y + 3, z + 1, Blocks.NETHER_BRICK_STAIRS, 2, 3);
        BlockUtils.setBlock(world, x + 21, y + 3, z + 1, Blocks.NETHER_BRICK_STAIRS, 2, 3);
        BlockUtils.setBlock(world, x + 2, y + 3, z + 2, Blocks.NETHER_BRICK_STAIRS, 0, 3);
        BlockUtils.setBlock(world, x + 3, y + 3, z + 2, Blocks.NETHER_BRICK_STAIRS, 2, 3);
        BlockUtils.setBlock(world, x + 4, y + 3, z + 2, Blocks.STONE_SLAB, 14, 3);
        BlockUtils.setBlock(world, x + 5, y + 3, z + 2, Blocks.STONE_SLAB, 14, 3);
        BlockUtils.setBlock(world, x + 6, y + 3, z + 2, Blocks.STONE_SLAB, 14, 3);
        BlockUtils.setBlock(world, x + 7, y + 3, z + 2, Blocks.STONE_SLAB, 14, 3);
        BlockUtils.setBlock(world, x + 8, y + 3, z + 2, Blocks.STONE_SLAB, 14, 3);
        BlockUtils.setBlock(world, x + 9, y + 3, z + 2, Blocks.STONE_SLAB, 14, 3);
        BlockUtils.setBlock(world, x + 10, y + 3, z + 2, Blocks.STONE_SLAB, 14, 3);
        BlockUtils.setBlock(world, x + 11, y + 3, z + 2, Blocks.STONE_SLAB, 14, 3);
        BlockUtils.setBlock(world, x + 12, y + 3, z + 2, Blocks.STONE_SLAB, 14, 3);
        BlockUtils.setBlock(world, x + 13, y + 3, z + 2, Blocks.STONE_SLAB, 14, 3);
        BlockUtils.setBlock(world, x + 14, y + 3, z + 2, Blocks.STONE_SLAB, 14, 3);
        BlockUtils.setBlock(world, x + 15, y + 3, z + 2, Blocks.NETHER_BRICK, 0, 3);
        BlockUtils.setBlock(world, x + 16, y + 3, z + 2, Blocks.STONE_SLAB, 14, 3);
        BlockUtils.setBlock(world, x + 17, y + 3, z + 2, Blocks.STONE_SLAB, 14, 3);
        BlockUtils.setBlock(world, x + 18, y + 3, z + 2, Blocks.STONE_SLAB, 14, 3);
        BlockUtils.setBlock(world, x + 19, y + 3, z + 2, Blocks.NETHER_BRICK, 0, 3);
        BlockUtils.setBlock(world, x + 20, y + 3, z + 2, Blocks.STONE_SLAB, 14, 3);
        BlockUtils.setBlock(world, x + 21, y + 3, z + 2, Blocks.NETHER_BRICK_STAIRS, 1, 3);
        BlockUtils.setBlock(world, x + 22, y + 3, z + 2, Blocks.NETHER_BRICK_STAIRS, 2, 3);
        BlockUtils.setBlock(world, x + 1, y + 3, z + 3, Blocks.NETHER_BRICK_STAIRS, 0, 3);
        BlockUtils.setBlock(world, x + 2, y + 3, z + 3, Blocks.NETHER_BRICK_STAIRS, 2, 3);
        BlockUtils.setBlock(world, x + 3, y + 3, z + 3, Blocks.STONE_SLAB, 14, 3);
        BlockUtils.setBlock(world, x + 4, y + 3, z + 3, Blocks.STONE_SLAB, 14, 3);
        BlockUtils.setBlock(world, x + 5, y + 3, z + 3, Blocks.STONE_SLAB, 14, 3);
        BlockUtils.setBlock(world, x + 6, y + 3, z + 3, Blocks.STONE_SLAB, 14, 3);
        BlockUtils.setBlock(world, x + 7, y + 3, z + 3, Blocks.STONE_SLAB, 14, 3);
        BlockUtils.setBlock(world, x + 8, y + 3, z + 3, Blocks.STONE_SLAB, 14, 3);
        BlockUtils.setBlock(world, x + 9, y + 3, z + 3, Blocks.STONE_SLAB, 14, 3);
        BlockUtils.setBlock(world, x + 10, y + 3, z + 3, Blocks.STONE_SLAB, 14, 3);
        BlockUtils.setBlock(world, x + 11, y + 3, z + 3, Blocks.STONE_SLAB, 14, 3);
        BlockUtils.setBlock(world, x + 12, y + 3, z + 3, Blocks.STONE_SLAB, 14, 3);
        BlockUtils.setBlock(world, x + 13, y + 3, z + 3, Blocks.STONE_SLAB, 14, 3);
        BlockUtils.setBlock(world, x + 14, y + 3, z + 3, Blocks.STONE_SLAB, 14, 3);
        BlockUtils.setBlock(world, x + 15, y + 3, z + 3, Blocks.NETHER_BRICK, 0, 3);
        BlockUtils.setBlock(world, x + 16, y + 3, z + 3, Blocks.STONE_SLAB, 14, 3);
        BlockUtils.setBlock(world, x + 17, y + 3, z + 3, Blocks.STONE_SLAB, 14, 3);
        BlockUtils.setBlock(world, x + 18, y + 3, z + 3, Blocks.STONE_SLAB, 14, 3);
        BlockUtils.setBlock(world, x + 19, y + 3, z + 3, Blocks.NETHER_BRICK, 0, 3);
        BlockUtils.setBlock(world, x + 20, y + 3, z + 3, Blocks.STONE_SLAB, 14, 3);
        BlockUtils.setBlock(world, x + 21, y + 3, z + 3, Blocks.STONE_SLAB, 14, 3);
        BlockUtils.setBlock(world, x + 22, y + 3, z + 3, Blocks.NETHER_BRICK_STAIRS, 1, 3);
        BlockUtils.setBlock(world, x + 23, y + 3, z + 3, Blocks.NETHER_BRICK_STAIRS, 2, 3);
        BlockUtils.setBlock(world, x + 1, y + 3, z + 4, Blocks.NETHER_BRICK_STAIRS, 0, 3);
        BlockUtils.setBlock(world, x + 2, y + 3, z + 4, Blocks.STONE_SLAB, 14, 3);
        BlockUtils.setBlock(world, x + 3, y + 3, z + 4, Blocks.STONE_SLAB, 14, 3);
        BlockUtils.setBlock(world, x + 4, y + 3, z + 4, Blocks.STONE_SLAB, 14, 3);
        BlockUtils.setBlock(world, x + 5, y + 3, z + 4, Blocks.NETHER_BRICK_STAIRS, 1, 3);
        BlockUtils.setBlock(world, x + 6, y + 3, z + 4, Blocks.AIR, 0, 3);
        BlockUtils.setBlock(world, x + 7, y + 3, z + 4, Blocks.AIR, 0, 3);
        BlockUtils.setBlock(world, x + 8, y + 3, z + 4, Blocks.AIR, 0, 3);
        BlockUtils.setBlock(world, x + 9, y + 3, z + 4, Blocks.STONE_SLAB, 14, 3);
        BlockUtils.setBlock(world, x + 10, y + 3, z + 4, Blocks.STONE_SLAB, 14, 3);
        BlockUtils.setBlock(world, x + 11, y + 3, z + 4, Blocks.STONE_SLAB, 14, 3);
        BlockUtils.setBlock(world, x + 12, y + 3, z + 4, Blocks.STONE_SLAB, 14, 3);
        BlockUtils.setBlock(world, x + 13, y + 3, z + 4, Blocks.STONE_SLAB, 14, 3);
        BlockUtils.setBlock(world, x + 14, y + 3, z + 4, Blocks.STONE_SLAB, 14, 3);
        BlockUtils.setBlock(world, x + 15, y + 3, z + 4, Blocks.NETHER_BRICK, 0, 3);
        BlockUtils.setBlock(world, x + 16, y + 3, z + 4, Blocks.NETHER_BRICK, 0, 3);
        BlockUtils.setBlock(world, x + 17, y + 3, z + 4, Blocks.NETHER_BRICK, 0, 3);
        BlockUtils.setBlock(world, x + 18, y + 3, z + 4, Blocks.NETHER_BRICK, 0, 3);
        BlockUtils.setBlock(world, x + 19, y + 3, z + 4, Blocks.NETHER_BRICK, 0, 3);
        BlockUtils.setBlock(world, x + 20, y + 3, z + 4, Blocks.STONE_SLAB, 14, 3);
        BlockUtils.setBlock(world, x + 21, y + 3, z + 4, Blocks.STONE_SLAB, 14, 3);
        BlockUtils.setBlock(world, x + 22, y + 3, z + 4, Blocks.STONE_SLAB, 14, 3);
        BlockUtils.setBlock(world, x + 23, y + 3, z + 4, Blocks.NETHER_BRICK_STAIRS, 1, 3);
        BlockUtils.setBlock(world, x + 24, y + 3, z + 4, Blocks.NETHER_BRICK_STAIRS, 2, 3);
        BlockUtils.setBlock(world, x + 1, y + 3, z + 5, Blocks.NETHER_BRICK_STAIRS, 0, 3);
        BlockUtils.setBlock(world, x + 2, y + 3, z + 5, Blocks.STONE_SLAB, 14, 3);
        BlockUtils.setBlock(world, x + 3, y + 3, z + 5, Blocks.STONE_SLAB, 14, 3);
        BlockUtils.setBlock(world, x + 4, y + 3, z + 5, Blocks.STONE_SLAB, 14, 3);
        BlockUtils.setBlock(world, x + 5, y + 3, z + 5, Blocks.NETHER_BRICK_STAIRS, 1, 3);
        BlockUtils.setBlock(world, x + 6, y + 3, z + 5, Blocks.AIR, 0, 3);
        BlockUtils.setBlock(world, x + 7, y + 3, z + 5, Blocks.AIR, 0, 3);
        BlockUtils.setBlock(world, x + 8, y + 3, z + 5, Blocks.AIR, 0, 3);
        BlockUtils.setBlock(world, x + 9, y + 3, z + 5, Blocks.STONE_SLAB, 14, 3);
        BlockUtils.setBlock(world, x + 10, y + 3, z + 5, Blocks.STONE_SLAB, 14, 3);
        BlockUtils.setBlock(world, x + 11, y + 3, z + 5, Blocks.STONE_SLAB, 14, 3);
        BlockUtils.setBlock(world, x + 12, y + 3, z + 5, Blocks.STONE_SLAB, 14, 3);
        BlockUtils.setBlock(world, x + 13, y + 3, z + 5, Blocks.STONE_SLAB, 14, 3);
        BlockUtils.setBlock(world, x + 14, y + 3, z + 5, Blocks.STONE_SLAB, 14, 3);
        BlockUtils.setBlock(world, x + 15, y + 3, z + 5, Blocks.STONE_SLAB, 14, 3);
        BlockUtils.setBlock(world, x + 16, y + 3, z + 5, Blocks.STONE_SLAB, 14, 3);
        BlockUtils.setBlock(world, x + 17, y + 3, z + 5, Blocks.STONE_SLAB, 14, 3);
        BlockUtils.setBlock(world, x + 18, y + 3, z + 5, Blocks.STONE_SLAB, 14, 3);
        BlockUtils.setBlock(world, x + 19, y + 3, z + 5, Blocks.STONE_SLAB, 14, 3);
        BlockUtils.setBlock(world, x + 20, y + 3, z + 5, Blocks.STONE_SLAB, 14, 3);
        BlockUtils.setBlock(world, x + 21, y + 3, z + 5, Blocks.STONE_SLAB, 14, 3);
        BlockUtils.setBlock(world, x + 22, y + 3, z + 5, Blocks.STONE_SLAB, 14, 3);
        BlockUtils.setBlock(world, x + 23, y + 3, z + 5, Blocks.NETHER_BRICK, 0, 3);
        BlockUtils.setBlock(world, x + 24, y + 3, z + 5, Blocks.NETHER_BRICK, 0, 3);
        BlockUtils.setBlock(world, x + 25, y + 3, z + 5, Blocks.NETHER_BRICK, 0, 3);
        BlockUtils.setBlock(world, x + 26, y + 3, z + 5, Blocks.NETHER_BRICK, 0, 3);
        BlockUtils.setBlock(world, x + 27, y + 3, z + 5, Blocks.NETHER_BRICK, 0, 3);
        BlockUtils.setBlock(world, x + 28, y + 3, z + 5, Blocks.NETHER_BRICK, 0, 3);
        BlockUtils.setBlock(world, x + 29, y + 3, z + 5, Blocks.NETHER_BRICK, 0, 3);
        BlockUtils.setBlock(world, x + 30, y + 3, z + 5, Blocks.NETHER_BRICK, 0, 3);
        BlockUtils.setBlock(world, x + 31, y + 3, z + 5, Blocks.NETHER_BRICK_STAIRS, 5, 3);
        BlockUtils.setBlock(world, x + 1, y + 3, z + 6, Blocks.NETHER_BRICK_STAIRS, 0, 3);
        BlockUtils.setBlock(world, x + 2, y + 3, z + 6, Blocks.STONE_SLAB, 14, 3);
        BlockUtils.setBlock(world, x + 3, y + 3, z + 6, Blocks.STONE_SLAB, 14, 3);
        BlockUtils.setBlock(world, x + 4, y + 3, z + 6, Blocks.STONE_SLAB, 14, 3);
        BlockUtils.setBlock(world, x + 5, y + 3, z + 6, Blocks.NETHER_BRICK_STAIRS, 1, 3);
        BlockUtils.setBlock(world, x + 6, y + 3, z + 6, Blocks.AIR, 0, 3);
        BlockUtils.setBlock(world, x + 7, y + 3, z + 6, Blocks.AIR, 0, 3);
        BlockUtils.setBlock(world, x + 8, y + 3, z + 6, Blocks.AIR, 0, 3);
        BlockUtils.setBlock(world, x + 9, y + 3, z + 6, Blocks.STONE_SLAB, 14, 3);
        BlockUtils.setBlock(world, x + 10, y + 3, z + 6, Blocks.STONE_SLAB, 14, 3);
        BlockUtils.setBlock(world, x + 11, y + 3, z + 6, Blocks.STONE_SLAB, 14, 3);
        BlockUtils.setBlock(world, x + 12, y + 3, z + 6, Blocks.STONE_SLAB, 14, 3);
        BlockUtils.setBlock(world, x + 13, y + 3, z + 6, Blocks.STONE_SLAB, 14, 3);
        BlockUtils.setBlock(world, x + 14, y + 3, z + 6, Blocks.STONE_SLAB, 14, 3);
        BlockUtils.setBlock(world, x + 15, y + 3, z + 6, Blocks.NETHER_BRICK, 0, 3);
        BlockUtils.setBlock(world, x + 16, y + 3, z + 6, Blocks.NETHER_BRICK, 0, 3);
        BlockUtils.setBlock(world, x + 17, y + 3, z + 6, Blocks.NETHER_BRICK, 0, 3);
        BlockUtils.setBlock(world, x + 18, y + 3, z + 6, Blocks.NETHER_BRICK, 0, 3);
        BlockUtils.setBlock(world, x + 19, y + 3, z + 6, Blocks.NETHER_BRICK, 0, 3);
        BlockUtils.setBlock(world, x + 20, y + 3, z + 6, Blocks.STONE_SLAB, 14, 3);
        BlockUtils.setBlock(world, x + 21, y + 3, z + 6, Blocks.STONE_SLAB, 14, 3);
        BlockUtils.setBlock(world, x + 22, y + 3, z + 6, Blocks.STONE_SLAB, 14, 3);
        BlockUtils.setBlock(world, x + 23, y + 3, z + 6, Blocks.NETHER_BRICK_STAIRS, 3, 3);
        BlockUtils.setBlock(world, x + 24, y + 3, z + 6, Blocks.NETHER_BRICK_STAIRS, 3, 3);
        BlockUtils.setBlock(world, x + 1, y + 3, z + 7, Blocks.NETHER_BRICK_STAIRS, 3, 3);
        BlockUtils.setBlock(world, x + 2, y + 3, z + 7, Blocks.NETHER_BRICK_STAIRS, 0, 3);
        BlockUtils.setBlock(world, x + 3, y + 3, z + 7, Blocks.STONE_SLAB, 14, 3);
        BlockUtils.setBlock(world, x + 4, y + 3, z + 7, Blocks.STONE_SLAB, 14, 3);
        BlockUtils.setBlock(world, x + 5, y + 3, z + 7, Blocks.STONE_SLAB, 14, 3);
        BlockUtils.setBlock(world, x + 6, y + 3, z + 7, Blocks.STONE_SLAB, 14, 3);
        BlockUtils.setBlock(world, x + 7, y + 3, z + 7, Blocks.STONE_SLAB, 14, 3);
        BlockUtils.setBlock(world, x + 8, y + 3, z + 7, Blocks.STONE_SLAB, 14, 3);
        BlockUtils.setBlock(world, x + 9, y + 3, z + 7, Blocks.STONE_SLAB, 14, 3);
        BlockUtils.setBlock(world, x + 10, y + 3, z + 7, Blocks.STONE_SLAB, 14, 3);
        BlockUtils.setBlock(world, x + 11, y + 3, z + 7, Blocks.STONE_SLAB, 14, 3);
        BlockUtils.setBlock(world, x + 12, y + 3, z + 7, Blocks.STONE_SLAB, 14, 3);
        BlockUtils.setBlock(world, x + 13, y + 3, z + 7, Blocks.STONE_SLAB, 14, 3);
        BlockUtils.setBlock(world, x + 14, y + 3, z + 7, Blocks.STONE_SLAB, 14, 3);
        BlockUtils.setBlock(world, x + 15, y + 3, z + 7, Blocks.NETHER_BRICK, 0, 3);
        BlockUtils.setBlock(world, x + 16, y + 3, z + 7, Blocks.STONE_SLAB, 14, 3);
        BlockUtils.setBlock(world, x + 17, y + 3, z + 7, Blocks.STONE_SLAB, 14, 3);
        BlockUtils.setBlock(world, x + 18, y + 3, z + 7, Blocks.STONE_SLAB, 14, 3);
        BlockUtils.setBlock(world, x + 19, y + 3, z + 7, Blocks.NETHER_BRICK, 0, 3);
        BlockUtils.setBlock(world, x + 20, y + 3, z + 7, Blocks.STONE_SLAB, 14, 3);
        BlockUtils.setBlock(world, x + 21, y + 3, z + 7, Blocks.STONE_SLAB, 14, 3);
        BlockUtils.setBlock(world, x + 22, y + 3, z + 7, Blocks.NETHER_BRICK_STAIRS, 3, 3);
        BlockUtils.setBlock(world, x + 23, y + 3, z + 7, Blocks.NETHER_BRICK_STAIRS, 1, 3);
        BlockUtils.setBlock(world, x + 2, y + 3, z + 8, Blocks.NETHER_BRICK_STAIRS, 3, 3);
        BlockUtils.setBlock(world, x + 3, y + 3, z + 8, Blocks.NETHER_BRICK_STAIRS, 3, 3);
        BlockUtils.setBlock(world, x + 4, y + 3, z + 8, Blocks.STONE_SLAB, 14, 3);
        BlockUtils.setBlock(world, x + 5, y + 3, z + 8, Blocks.STONE_SLAB, 14, 3);
        BlockUtils.setBlock(world, x + 6, y + 3, z + 8, Blocks.STONE_SLAB, 14, 3);
        BlockUtils.setBlock(world, x + 7, y + 3, z + 8, Blocks.STONE_SLAB, 14, 3);
        BlockUtils.setBlock(world, x + 8, y + 3, z + 8, Blocks.STONE_SLAB, 14, 3);
        BlockUtils.setBlock(world, x + 9, y + 3, z + 8, Blocks.STONE_SLAB, 14, 3);
        BlockUtils.setBlock(world, x + 10, y + 3, z + 8, Blocks.STONE_SLAB, 14, 3);
        BlockUtils.setBlock(world, x + 11, y + 3, z + 8, Blocks.STONE_SLAB, 14, 3);
        BlockUtils.setBlock(world, x + 12, y + 3, z + 8, Blocks.STONE_SLAB, 14, 3);
        BlockUtils.setBlock(world, x + 13, y + 3, z + 8, Blocks.STONE_SLAB, 14, 3);
        BlockUtils.setBlock(world, x + 14, y + 3, z + 8, Blocks.STONE_SLAB, 14, 3);
        BlockUtils.setBlock(world, x + 15, y + 3, z + 8, Blocks.NETHER_BRICK, 0, 3);
        BlockUtils.setBlock(world, x + 16, y + 3, z + 8, Blocks.STONE_SLAB, 14, 3);
        BlockUtils.setBlock(world, x + 17, y + 3, z + 8, Blocks.STONE_SLAB, 14, 3);
        BlockUtils.setBlock(world, x + 18, y + 3, z + 8, Blocks.STONE_SLAB, 14, 3);
        BlockUtils.setBlock(world, x + 19, y + 3, z + 8, Blocks.NETHER_BRICK, 0, 3);
        BlockUtils.setBlock(world, x + 20, y + 3, z + 8, Blocks.STONE_SLAB, 14, 3);
        BlockUtils.setBlock(world, x + 21, y + 3, z + 8, Blocks.NETHER_BRICK_STAIRS, 3, 3);
        BlockUtils.setBlock(world, x + 22, y + 3, z + 8, Blocks.NETHER_BRICK_STAIRS, 1, 3);
        BlockUtils.setBlock(world, x + 3, y + 3, z + 9, Blocks.NETHER_BRICK_STAIRS, 0, 3);
        BlockUtils.setBlock(world, x + 4, y + 3, z + 9, Blocks.NETHER_BRICK_STAIRS, 3, 3);
        BlockUtils.setBlock(world, x + 5, y + 3, z + 9, Blocks.NETHER_BRICK_STAIRS, 3, 3);
        BlockUtils.setBlock(world, x + 6, y + 3, z + 9, Blocks.NETHER_BRICK_STAIRS, 3, 3);
        BlockUtils.setBlock(world, x + 7, y + 3, z + 9, Blocks.NETHER_BRICK_STAIRS, 3, 3);
        BlockUtils.setBlock(world, x + 8, y + 3, z + 9, Blocks.NETHER_BRICK_STAIRS, 3, 3);
        BlockUtils.setBlock(world, x + 9, y + 3, z + 9, Blocks.NETHER_BRICK_STAIRS, 3, 3);
        BlockUtils.setBlock(world, x + 10, y + 3, z + 9, Blocks.NETHER_BRICK_STAIRS, 3, 3);
        BlockUtils.setBlock(world, x + 11, y + 3, z + 9, Blocks.NETHER_BRICK_STAIRS, 3, 3);
        BlockUtils.setBlock(world, x + 12, y + 3, z + 9, Blocks.NETHER_BRICK_STAIRS, 3, 3);
        BlockUtils.setBlock(world, x + 13, y + 3, z + 9, Blocks.NETHER_BRICK_STAIRS, 3, 3);
        BlockUtils.setBlock(world, x + 14, y + 3, z + 9, Blocks.NETHER_BRICK_STAIRS, 3, 3);
        BlockUtils.setBlock(world, x + 15, y + 3, z + 9, Blocks.NETHER_BRICK_STAIRS, 3, 3);
        BlockUtils.setBlock(world, x + 16, y + 3, z + 9, Blocks.NETHER_BRICK_STAIRS, 3, 3);
        BlockUtils.setBlock(world, x + 17, y + 3, z + 9, Blocks.NETHER_BRICK_STAIRS, 3, 3);
        BlockUtils.setBlock(world, x + 18, y + 3, z + 9, Blocks.NETHER_BRICK_STAIRS, 3, 3);
        BlockUtils.setBlock(world, x + 19, y + 3, z + 9, Blocks.NETHER_BRICK_STAIRS, 3, 3);
        BlockUtils.setBlock(world, x + 20, y + 3, z + 9, Blocks.NETHER_BRICK_STAIRS, 3, 3);
        BlockUtils.setBlock(world, x + 21, y + 3, z + 9, Blocks.NETHER_BRICK_STAIRS, 1, 3);
        BlockUtils.setBlock(world, x + 4, y + 4, z + 2, Blocks.OBSIDIAN, 0, 3);
        BlockUtils.setBlock(world, x + 5, y + 4, z + 2, Blocks.OBSIDIAN, 0, 3);
        BlockUtils.setBlock(world, x + 6, y + 4, z + 2, Blocks.OBSIDIAN, 0, 3);
        BlockUtils.setBlock(world, x + 7, y + 4, z + 2, Blocks.OBSIDIAN, 0, 3);
        BlockUtils.setBlock(world, x + 8, y + 4, z + 2, Blocks.OBSIDIAN, 0, 3);
        BlockUtils.setBlock(world, x + 9, y + 4, z + 2, Blocks.OBSIDIAN, 0, 3);
        BlockUtils.setBlock(world, x + 10, y + 4, z + 2, Blocks.OBSIDIAN, 0, 3);
        BlockUtils.setBlock(world, x + 11, y + 4, z + 2, Blocks.OBSIDIAN, 0, 3);
        BlockUtils.setBlock(world, x + 12, y + 4, z + 2, Blocks.OBSIDIAN, 0, 3);
        BlockUtils.setBlock(world, x + 13, y + 4, z + 2, Blocks.OBSIDIAN, 0, 3);
        BlockUtils.setBlock(world, x + 14, y + 4, z + 2, Blocks.OBSIDIAN, 0, 3);
        BlockUtils.setBlock(world, x + 15, y + 4, z + 2, Blocks.OBSIDIAN, 0, 3);
        BlockUtils.setBlock(world, x + 16, y + 4, z + 2, Blocks.OBSIDIAN, 0, 3);
        BlockUtils.setBlock(world, x + 17, y + 4, z + 2, Blocks.OBSIDIAN, 0, 3);
        BlockUtils.setBlock(world, x + 18, y + 4, z + 2, Blocks.OBSIDIAN, 0, 3);
        BlockUtils.setBlock(world, x + 19, y + 4, z + 2, Blocks.OBSIDIAN, 0, 3);
        BlockUtils.setBlock(world, x + 20, y + 4, z + 2, Blocks.OBSIDIAN, 0, 3);
        BlockUtils.setBlock(world, x + 3, y + 4, z + 3, Blocks.OBSIDIAN, 0, 3);
        BlockUtils.setBlock(world, x + 4, y + 4, z + 3, Blocks.OBSIDIAN, 0, 3);
        BlockUtils.setBlock(world, x + 20, y + 4, z + 3, Blocks.OBSIDIAN, 0, 3);
        BlockUtils.setBlock(world, x + 21, y + 4, z + 3, Blocks.OBSIDIAN, 0, 3);
        BlockUtils.setBlock(world, x + 2, y + 4, z + 4, Blocks.OBSIDIAN, 0, 3);
        BlockUtils.setBlock(world, x + 3, y + 4, z + 4, Blocks.OBSIDIAN, 0, 3);
        BlockUtils.setBlock(world, x + 21, y + 4, z + 4, Blocks.OBSIDIAN, 0, 3);
        BlockUtils.setBlock(world, x + 22, y + 4, z + 4, Blocks.OBSIDIAN, 0, 3);
        BlockUtils.setBlock(world, x + 2, y + 4, z + 5, Blocks.OBSIDIAN, 0, 3);
        BlockUtils.setBlock(world, x + 3, y + 4, z + 5, Blocks.OBSIDIAN, 0, 3);
        BlockUtils.setBlock(world, x + 11, y + 4, z + 5, FABlockRegistry.ANU_STATUE, 5, 3);
        BlockUtils.setBlock(world, x + 15, y + 4, z + 5, Blocks.OBSIDIAN, 0, 3);
        BlockUtils.setBlock(world, x + 22, y + 4, z + 5, Blocks.OBSIDIAN, 0, 3);
        BlockUtils.setBlock(world, x + 23, y + 4, z + 5, Blocks.OBSIDIAN, 0, 3);
        BlockUtils.setBlock(world, x + 2, y + 4, z + 6, Blocks.OBSIDIAN, 0, 3);
        BlockUtils.setBlock(world, x + 3, y + 4, z + 6, Blocks.OBSIDIAN, 0, 3);
        BlockUtils.setBlock(world, x + 21, y + 4, z + 6, Blocks.OBSIDIAN, 0, 3);
        BlockUtils.setBlock(world, x + 22, y + 4, z + 6, Blocks.OBSIDIAN, 0, 3);
        BlockUtils.setBlock(world, x + 3, y + 4, z + 7, Blocks.OBSIDIAN, 0, 3);
        BlockUtils.setBlock(world, x + 4, y + 4, z + 7, Blocks.OBSIDIAN, 0, 3);
        BlockUtils.setBlock(world, x + 20, y + 4, z + 7, Blocks.OBSIDIAN, 0, 3);
        BlockUtils.setBlock(world, x + 21, y + 4, z + 7, Blocks.OBSIDIAN, 0, 3);
        BlockUtils.setBlock(world, x + 4, y + 4, z + 8, Blocks.OBSIDIAN, 0, 3);
        BlockUtils.setBlock(world, x + 5, y + 4, z + 8, Blocks.OBSIDIAN, 0, 3);
        BlockUtils.setBlock(world, x + 6, y + 4, z + 8, Blocks.OBSIDIAN, 0, 3);
        BlockUtils.setBlock(world, x + 7, y + 4, z + 8, Blocks.OBSIDIAN, 0, 3);
        BlockUtils.setBlock(world, x + 8, y + 4, z + 8, Blocks.OBSIDIAN, 0, 3);
        BlockUtils.setBlock(world, x + 9, y + 4, z + 8, Blocks.OBSIDIAN, 0, 3);
        BlockUtils.setBlock(world, x + 10, y + 4, z + 8, Blocks.OBSIDIAN, 0, 3);
        BlockUtils.setBlock(world, x + 11, y + 4, z + 8, Blocks.OBSIDIAN, 0, 3);
        BlockUtils.setBlock(world, x + 12, y + 4, z + 8, Blocks.OBSIDIAN, 0, 3);
        BlockUtils.setBlock(world, x + 13, y + 4, z + 8, Blocks.OBSIDIAN, 0, 3);
        BlockUtils.setBlock(world, x + 14, y + 4, z + 8, Blocks.OBSIDIAN, 0, 3);
        BlockUtils.setBlock(world, x + 15, y + 4, z + 8, Blocks.OBSIDIAN, 0, 3);
        BlockUtils.setBlock(world, x + 16, y + 4, z + 8, Blocks.OBSIDIAN, 0, 3);
        BlockUtils.setBlock(world, x + 17, y + 4, z + 8, Blocks.OBSIDIAN, 0, 3);
        BlockUtils.setBlock(world, x + 18, y + 4, z + 8, Blocks.OBSIDIAN, 0, 3);
        BlockUtils.setBlock(world, x + 19, y + 4, z + 8, Blocks.OBSIDIAN, 0, 3);
        BlockUtils.setBlock(world, x + 20, y + 4, z + 8, Blocks.OBSIDIAN, 0, 3);
        BlockUtils.setBlock(world, x + 4, y + 5, z + 2, Blocks.NETHER_BRICK_FENCE, 0, 3);
        BlockUtils.setBlock(world, x + 5, y + 5, z + 2, Blocks.NETHER_BRICK_FENCE, 0, 3);
        BlockUtils.setBlock(world, x + 6, y + 5, z + 2, Blocks.NETHER_BRICK_FENCE, 0, 3);
        BlockUtils.setBlock(world, x + 7, y + 5, z + 2, Blocks.NETHER_BRICK_FENCE, 0, 3);
        BlockUtils.setBlock(world, x + 8, y + 5, z + 2, Blocks.NETHER_BRICK_FENCE, 0, 3);
        BlockUtils.setBlock(world, x + 9, y + 5, z + 2, Blocks.NETHER_BRICK_FENCE, 0, 3);
        BlockUtils.setBlock(world, x + 10, y + 5, z + 2, Blocks.NETHER_BRICK_FENCE, 0, 3);
        BlockUtils.setBlock(world, x + 11, y + 5, z + 2, Blocks.NETHER_BRICK_FENCE, 0, 3);
        BlockUtils.setBlock(world, x + 12, y + 5, z + 2, Blocks.NETHER_BRICK_FENCE, 0, 3);
        BlockUtils.setBlock(world, x + 13, y + 5, z + 2, Blocks.NETHER_BRICK_FENCE, 0, 3);
        BlockUtils.setBlock(world, x + 14, y + 5, z + 2, Blocks.NETHER_BRICK_FENCE, 0, 3);
        BlockUtils.setBlock(world, x + 15, y + 5, z + 2, Blocks.NETHER_BRICK_FENCE, 0, 3);
        BlockUtils.setBlock(world, x + 16, y + 5, z + 2, Blocks.NETHER_BRICK_FENCE, 0, 3);
        BlockUtils.setBlock(world, x + 17, y + 5, z + 2, Blocks.NETHER_BRICK_FENCE, 0, 3);
        BlockUtils.setBlock(world, x + 18, y + 5, z + 2, Blocks.NETHER_BRICK_FENCE, 0, 3);
        BlockUtils.setBlock(world, x + 19, y + 5, z + 2, Blocks.NETHER_BRICK_FENCE, 0, 3);
        BlockUtils.setBlock(world, x + 20, y + 5, z + 2, Blocks.NETHER_BRICK_FENCE, 0, 3);
        BlockUtils.setBlock(world, x + 3, y + 5, z + 3, Blocks.NETHER_BRICK_FENCE, 0, 3);
        BlockUtils.setBlock(world, x + 4, y + 5, z + 3, Blocks.NETHER_BRICK_FENCE, 0, 3);
        BlockUtils.setBlock(world, x + 20, y + 5, z + 3, Blocks.NETHER_BRICK_FENCE, 0, 3);
        BlockUtils.setBlock(world, x + 21, y + 5, z + 3, Blocks.NETHER_BRICK_FENCE, 0, 3);
        BlockUtils.setBlock(world, x + 2, y + 5, z + 4, Blocks.NETHER_BRICK_FENCE, 0, 3);
        BlockUtils.setBlock(world, x + 3, y + 5, z + 4, Blocks.NETHER_BRICK_FENCE, 0, 3);
        BlockUtils.setBlock(world, x + 21, y + 5, z + 4, Blocks.NETHER_BRICK_FENCE, 0, 3);
        BlockUtils.setBlock(world, x + 22, y + 5, z + 4, Blocks.NETHER_BRICK_FENCE, 0, 3);
        BlockUtils.setBlock(world, x + 2, y + 5, z + 5, Blocks.NETHER_BRICK_FENCE, 0, 3);
        BlockUtils.setBlock(world, x + 3, y + 5, z + 5, Blocks.OBSIDIAN, 0, 3);
        BlockUtils.setBlock(world, x + 15, y + 5, z + 5, Blocks.OBSIDIAN, 0, 3);
        BlockUtils.setBlock(world, x + 22, y + 5, z + 5, Blocks.NETHER_BRICK_FENCE, 0, 3);
        BlockUtils.setBlock(world, x + 23, y + 5, z + 5, Blocks.NETHER_BRICK_FENCE, 0, 3);
        BlockUtils.setBlock(world, x + 2, y + 5, z + 6, Blocks.NETHER_BRICK_FENCE, 0, 3);
        BlockUtils.setBlock(world, x + 3, y + 5, z + 6, Blocks.NETHER_BRICK_FENCE, 0, 3);
        BlockUtils.setBlock(world, x + 21, y + 5, z + 6, Blocks.NETHER_BRICK_FENCE, 0, 3);
        BlockUtils.setBlock(world, x + 22, y + 5, z + 6, Blocks.NETHER_BRICK_FENCE, 0, 3);
        BlockUtils.setBlock(world, x + 3, y + 5, z + 7, Blocks.NETHER_BRICK_FENCE, 0, 3);
        BlockUtils.setBlock(world, x + 4, y + 5, z + 7, Blocks.NETHER_BRICK_FENCE, 0, 3);
        BlockUtils.setBlock(world, x + 20, y + 5, z + 7, Blocks.NETHER_BRICK_FENCE, 0, 3);
        BlockUtils.setBlock(world, x + 21, y + 5, z + 7, Blocks.NETHER_BRICK_FENCE, 0, 3);
        BlockUtils.setBlock(world, x + 4, y + 5, z + 8, Blocks.NETHER_BRICK_FENCE, 0, 3);
        BlockUtils.setBlock(world, x + 5, y + 5, z + 8, Blocks.NETHER_BRICK_FENCE, 0, 3);
        BlockUtils.setBlock(world, x + 6, y + 5, z + 8, Blocks.NETHER_BRICK_FENCE, 0, 3);
        BlockUtils.setBlock(world, x + 7, y + 5, z + 8, Blocks.NETHER_BRICK_FENCE, 0, 3);
        BlockUtils.setBlock(world, x + 8, y + 5, z + 8, Blocks.NETHER_BRICK_FENCE, 0, 3);
        BlockUtils.setBlock(world, x + 9, y + 5, z + 8, Blocks.NETHER_BRICK_FENCE, 0, 3);
        BlockUtils.setBlock(world, x + 10, y + 5, z + 8, Blocks.NETHER_BRICK_FENCE, 0, 3);
        BlockUtils.setBlock(world, x + 11, y + 5, z + 8, Blocks.NETHER_BRICK_FENCE, 0, 3);
        BlockUtils.setBlock(world, x + 12, y + 5, z + 8, Blocks.NETHER_BRICK_FENCE, 0, 3);
        BlockUtils.setBlock(world, x + 13, y + 5, z + 8, Blocks.NETHER_BRICK_FENCE, 0, 3);
        BlockUtils.setBlock(world, x + 14, y + 5, z + 8, Blocks.NETHER_BRICK_FENCE, 0, 3);
        BlockUtils.setBlock(world, x + 15, y + 5, z + 8, Blocks.NETHER_BRICK_FENCE, 0, 3);
        BlockUtils.setBlock(world, x + 16, y + 5, z + 8, Blocks.NETHER_BRICK_FENCE, 0, 3);
        BlockUtils.setBlock(world, x + 17, y + 5, z + 8, Blocks.NETHER_BRICK_FENCE, 0, 3);
        BlockUtils.setBlock(world, x + 18, y + 5, z + 8, Blocks.NETHER_BRICK_FENCE, 0, 3);
        BlockUtils.setBlock(world, x + 19, y + 5, z + 8, Blocks.NETHER_BRICK_FENCE, 0, 3);
        BlockUtils.setBlock(world, x + 20, y + 5, z + 8, Blocks.NETHER_BRICK_FENCE, 0, 3);
        BlockUtils.setBlock(world, x + 3, y + 6, z + 5, Blocks.OBSIDIAN, 0, 3);
        BlockUtils.setBlock(world, x + 15, y + 6, z + 5, Blocks.OBSIDIAN, 0, 3);
        BlockUtils.setBlock(world, x + 3, y + 7, z + 5, Blocks.OBSIDIAN, 0, 3);
        BlockUtils.setBlock(world, x + 15, y + 7, z + 5, Blocks.OBSIDIAN, 0, 3);
        BlockUtils.setBlock(world, x + 3, y + 8, z + 5, Blocks.OBSIDIAN, 0, 3);
        BlockUtils.setBlock(world, x + 15, y + 8, z + 5, Blocks.OBSIDIAN, 0, 3);
        BlockUtils.setBlock(world, x + 15, y + 9, z + 3, Blocks.OBSIDIAN, 0, 3);
        BlockUtils.setBlock(world, x + 3, y + 9, z + 4, Blocks.OBSIDIAN, 0, 3);
        BlockUtils.setBlock(world, x + 15, y + 9, z + 4, Blocks.OBSIDIAN, 0, 3);
        BlockUtils.setBlock(world, x + 3, y + 9, z + 5, Blocks.OBSIDIAN, 0, 3);
        BlockUtils.setBlock(world, x + 15, y + 9, z + 5, Blocks.OBSIDIAN, 0, 3);
        BlockUtils.setBlock(world, x + 3, y + 9, z + 6, Blocks.OBSIDIAN, 0, 3);
        BlockUtils.setBlock(world, x + 15, y + 9, z + 6, Blocks.OBSIDIAN, 0, 3);
        BlockUtils.setBlock(world, x + 15, y + 9, z + 7, Blocks.OBSIDIAN, 0, 3);
        BlockUtils.setBlock(world, x + 3, y + 10, z + 5, Blocks.OBSIDIAN, 0, 3);
        BlockUtils.setBlock(world, x + 15, y + 10, z + 5, Blocks.OBSIDIAN, 0, 3);
        BlockUtils.setBlock(world, x + 3, y + 11, z + 5, Blocks.OBSIDIAN, 0, 3);
        BlockUtils.setBlock(world, x + 15, y + 11, z + 5, Blocks.OBSIDIAN, 0, 3);
        BlockUtils.setBlock(world, x + 3, y + 12, z + 5, Blocks.OBSIDIAN, 0, 3);
        BlockUtils.setBlock(world, x + 15, y + 12, z + 5, Blocks.OBSIDIAN, 0, 3);
        BlockUtils.setBlock(world, x + 3, y + 13, z + 5, Blocks.OBSIDIAN, 0, 3);
        BlockUtils.setBlock(world, x + 15, y + 13, z + 5, Blocks.OBSIDIAN, 0, 3);
        BlockUtils.setBlock(world, x + 15, y + 14, z, Blocks.OBSIDIAN, 0, 3);
        BlockUtils.setBlock(world, x + 3, y + 14, z + 1, Blocks.OBSIDIAN, 0, 3);
        BlockUtils.setBlock(world, x + 15, y + 14, z + 1, Blocks.OBSIDIAN, 0, 3);
        BlockUtils.setBlock(world, x + 3, y + 14, z + 2, Blocks.OBSIDIAN, 0, 3);
        BlockUtils.setBlock(world, x + 15, y + 14, z + 2, Blocks.OBSIDIAN, 0, 3);
        BlockUtils.setBlock(world, x + 3, y + 14, z + 3, Blocks.OBSIDIAN, 0, 3);
        BlockUtils.setBlock(world, x + 15, y + 14, z + 3, Blocks.OBSIDIAN, 0, 3);
        BlockUtils.setBlock(world, x + 3, y + 14, z + 4, Blocks.OBSIDIAN, 0, 3);
        BlockUtils.setBlock(world, x + 15, y + 14, z + 4, Blocks.OBSIDIAN, 0, 3);
        BlockUtils.setBlock(world, x + 3, y + 14, z + 5, Blocks.OBSIDIAN, 0, 3);
        BlockUtils.setBlock(world, x + 15, y + 14, z + 5, Blocks.OBSIDIAN, 0, 3);
        BlockUtils.setBlock(world, x + 3, y + 14, z + 6, Blocks.OBSIDIAN, 0, 3);
        BlockUtils.setBlock(world, x + 15, y + 14, z + 6, Blocks.OBSIDIAN, 0, 3);
        BlockUtils.setBlock(world, x + 3, y + 14, z + 7, Blocks.OBSIDIAN, 0, 3);
        BlockUtils.setBlock(world, x + 15, y + 14, z + 7, Blocks.OBSIDIAN, 0, 3);
        BlockUtils.setBlock(world, x + 3, y + 14, z + 8, Blocks.OBSIDIAN, 0, 3);
        BlockUtils.setBlock(world, x + 15, y + 14, z + 8, Blocks.OBSIDIAN, 0, 3);
        BlockUtils.setBlock(world, x + 3, y + 14, z + 9, Blocks.OBSIDIAN, 0, 3);
        BlockUtils.setBlock(world, x + 15, y + 14, z + 9, Blocks.OBSIDIAN, 0, 3);
        BlockUtils.setBlock(world, x + 15, y + 14, z + 10, Blocks.OBSIDIAN, 0, 3);
        BlockUtils.setBlock(world, x + 3, y + 15, z + 5, Blocks.OBSIDIAN, 0, 3);
        BlockUtils.setBlock(world, x + 15, y + 15, z + 5, Blocks.OBSIDIAN, 0, 3);
        BlockUtils.setBlock(world, x + 3, y + 16, z + 5, Blocks.OBSIDIAN, 0, 3);
        BlockUtils.setBlock(world, x + 15, y + 16, z + 5, Blocks.OBSIDIAN, 0, 3);
        BlockUtils.setBlock(world, x + 15, y + 17, z + 5, Blocks.OBSIDIAN, 0, 3);
        BlockUtils.setBlock(world, x + 15, y + 18, z + 5, Blocks.OBSIDIAN, 0, 3);
        BlockUtils.setBlock(world, x + 15, y + 19, z + 5, Blocks.OBSIDIAN, 0, 3);
        BlockUtils.setBlock(world, x + 14, y + 20, z + 4, Blocks.NETHER_BRICK_STAIRS, 4, 3);
        BlockUtils.setBlock(world, x + 15, y + 20, z + 4, Blocks.NETHER_BRICK_STAIRS, 6, 3);
        BlockUtils.setBlock(world, x + 16, y + 20, z + 4, Blocks.NETHER_BRICK_STAIRS, 6, 3);
        BlockUtils.setBlock(world, x + 15, y + 20, z + 5, Blocks.NETHER_BRICK, 0, 3);
        BlockUtils.setBlock(world, x + 16, y + 20, z + 5, Blocks.NETHER_BRICK_STAIRS, 5, 3);
        BlockUtils.setBlock(world, x + 14, y + 20, z + 6, Blocks.NETHER_BRICK_STAIRS, 4, 3);
        BlockUtils.setBlock(world, x + 15, y + 20, z + 6, Blocks.NETHER_BRICK_STAIRS, 7, 3);
        BlockUtils.setBlock(world, x + 16, y + 20, z + 6, Blocks.NETHER_BRICK_STAIRS, 7, 3);
        BlockUtils.setBlock(world, x + 14, y + 21, z + 4, Blocks.NETHER_BRICK_FENCE, 0, 3);
        BlockUtils.setBlock(world, x + 15, y + 21, z + 4, Blocks.NETHER_BRICK_FENCE, 0, 3);
        BlockUtils.setBlock(world, x + 16, y + 21, z + 4, Blocks.NETHER_BRICK_FENCE, 0, 3);
        BlockUtils.setBlock(world, x + 16, y + 21, z + 5, Blocks.NETHER_BRICK_FENCE, 0, 3);
        BlockUtils.setBlock(world, x + 14, y + 21, z + 6, Blocks.NETHER_BRICK_FENCE, 0, 3);
        BlockUtils.setBlock(world, x + 15, y + 21, z + 6, Blocks.NETHER_BRICK_FENCE, 0, 3);
        BlockUtils.setBlock(world, x + 16, y + 21, z + 6, Blocks.NETHER_BRICK_FENCE, 0, 3);

        generate_r02_last(world, rand, x, y, z);
        return true;

    }

    @SuppressWarnings("deprecation")
    public boolean generate_r02_last(World world, Random rand, int x, int y, int z) {
        BlockUtils.setBlock(world, x + 2, y + 2, z + 4, Blocks.REDSTONE_TORCH, 1, 3);
        BlockUtils.setBlock(world, x + 2, y + 2, z + 6, Blocks.REDSTONE_TORCH, 1, 3);
        BlockUtils.setBlock(world, x + 14, y + 4, z + 5, Blocks.LADDER, 4, 3);
        BlockUtils.setBlock(world, x + 14, y + 5, z + 5, Blocks.LADDER, 4, 3);
        BlockUtils.setBlock(world, x + 14, y + 6, z + 5, Blocks.LADDER, 4, 3);
        BlockUtils.setBlock(world, x + 14, y + 7, z + 5, Blocks.LADDER, 4, 3);
        BlockUtils.setBlock(world, x + 14, y + 8, z + 5, Blocks.LADDER, 4, 3);
        BlockUtils.setBlock(world, x + 14, y + 9, z + 5, Blocks.LADDER, 4, 3);
        BlockUtils.setBlock(world, x + 14, y + 10, z + 5, Blocks.LADDER, 4, 3);
        BlockUtils.setBlock(world, x + 14, y + 11, z + 5, Blocks.LADDER, 4, 3);
        BlockUtils.setBlock(world, x + 14, y + 12, z + 5, Blocks.LADDER, 4, 3);
        BlockUtils.setBlock(world, x + 14, y + 13, z + 5, Blocks.LADDER, 4, 3);
        BlockUtils.setBlock(world, x + 14, y + 14, z + 5, Blocks.LADDER, 4, 3);
        BlockUtils.setBlock(world, x + 14, y + 15, z + 5, Blocks.LADDER, 4, 3);
        BlockUtils.setBlock(world, x + 14, y + 16, z + 5, Blocks.LADDER, 4, 3);
        BlockUtils.setBlock(world, x + 14, y + 17, z + 5, Blocks.LADDER, 4, 3);
        BlockUtils.setBlock(world, x + 14, y + 18, z + 5, Blocks.LADDER, 4, 3);
        BlockUtils.setBlock(world, x + 14, y + 19, z + 5, Blocks.LADDER, 4, 3);
        BlockUtils.setBlock(world, x + 14, y + 20, z + 5, Blocks.LADDER, 4, 3);
        return true;

    }

    @SuppressWarnings("deprecation")
    protected void generateStructureCHESTContents(World world, Random rand, int i1, int j1, int k1, int i) {
        BlockUtils.setChest(world, i1, j1, k1, Blocks.CHEST, i, 3, FALoot.HELL_BOAT);
    }
}