package com.github.revival.common.gen.feature;

import com.github.revival.common.block.FABlockRegistry;
import net.minecraft.init.Blocks;
import net.minecraft.world.World;
import net.minecraft.world.gen.feature.WorldGenerator;

import java.util.Random;

public class WorldGenAncientChest extends WorldGenerator
{

    public boolean generate(World world, Random rand, int x, int y, int z)
    {
        world.setBlock(x + 0, y + -2, z + 0, Blocks.bedrock, 0, 3);
        world.setBlock(x + 1, y + -2, z + 0, Blocks.bedrock, 0, 3);
        world.setBlock(x + 2, y + -2, z + 0, Blocks.bedrock, 0, 3);
        world.setBlock(x + 3, y + -2, z + 0, Blocks.bedrock, 0, 3);
        world.setBlock(x + 4, y + -2, z + 0, Blocks.bedrock, 0, 3);
        world.setBlock(x + 5, y + -2, z + 0, Blocks.bedrock, 0, 3);
        world.setBlock(x + 6, y + -2, z + 0, Blocks.bedrock, 0, 3);
        world.setBlock(x + 7, y + -2, z + 0, Blocks.bedrock, 0, 3);
        world.setBlock(x + 8, y + -2, z + 0, Blocks.bedrock, 0, 3);
        world.setBlock(x + 9, y + -2, z + 0, Blocks.bedrock, 0, 3);
        world.setBlock(x + 10, y + -2, z + 0, Blocks.bedrock, 0, 3);
        world.setBlock(x + 0, y + -2, z + 1, Blocks.bedrock, 0, 3);
        world.setBlock(x + 1, y + -2, z + 1, Blocks.bedrock, 0, 3);
        world.setBlock(x + 2, y + -2, z + 1, Blocks.bedrock, 0, 3);
        world.setBlock(x + 3, y + -2, z + 1, Blocks.bedrock, 0, 3);
        world.setBlock(x + 4, y + -2, z + 1, Blocks.bedrock, 0, 3);
        world.setBlock(x + 5, y + -2, z + 1, Blocks.bedrock, 0, 3);
        world.setBlock(x + 6, y + -2, z + 1, Blocks.bedrock, 0, 3);
        world.setBlock(x + 7, y + -2, z + 1, Blocks.bedrock, 0, 3);
        world.setBlock(x + 8, y + -2, z + 1, Blocks.bedrock, 0, 3);
        world.setBlock(x + 9, y + -2, z + 1, Blocks.bedrock, 0, 3);
        world.setBlock(x + 10, y + -2, z + 1, Blocks.bedrock, 0, 3);
        world.setBlock(x + 0, y + -2, z + 2, Blocks.bedrock, 0, 3);
        world.setBlock(x + 1, y + -2, z + 2, Blocks.bedrock, 0, 3);
        world.setBlock(x + 2, y + -2, z + 2, Blocks.bedrock, 0, 3);
        world.setBlock(x + 3, y + -2, z + 2, Blocks.bedrock, 0, 3);
        world.setBlock(x + 4, y + -2, z + 2, Blocks.bedrock, 0, 3);
        world.setBlock(x + 5, y + -2, z + 2, Blocks.bedrock, 0, 3);
        world.setBlock(x + 6, y + -2, z + 2, Blocks.bedrock, 0, 3);
        world.setBlock(x + 7, y + -2, z + 2, Blocks.bedrock, 0, 3);
        world.setBlock(x + 8, y + -2, z + 2, Blocks.bedrock, 0, 3);
        world.setBlock(x + 9, y + -2, z + 2, Blocks.bedrock, 0, 3);
        world.setBlock(x + 10, y + -2, z + 2, Blocks.bedrock, 0, 3);
        world.setBlock(x + 0, y + -2, z + 3, Blocks.bedrock, 0, 3);
        world.setBlock(x + 1, y + -2, z + 3, Blocks.bedrock, 0, 3);
        world.setBlock(x + 2, y + -2, z + 3, Blocks.bedrock, 0, 3);
        world.setBlock(x + 3, y + -2, z + 3, Blocks.bedrock, 0, 3);
        world.setBlock(x + 4, y + -2, z + 3, Blocks.bedrock, 0, 3);
        world.setBlock(x + 5, y + -2, z + 3, Blocks.bedrock, 0, 3);
        world.setBlock(x + 6, y + -2, z + 3, Blocks.bedrock, 0, 3);
        world.setBlock(x + 7, y + -2, z + 3, Blocks.bedrock, 0, 3);
        world.setBlock(x + 8, y + -2, z + 3, Blocks.bedrock, 0, 3);
        world.setBlock(x + 9, y + -2, z + 3, Blocks.bedrock, 0, 3);
        world.setBlock(x + 10, y + -2, z + 3, Blocks.bedrock, 0, 3);
        world.setBlock(x + 0, y + -2, z + 4, Blocks.bedrock, 0, 3);
        world.setBlock(x + 1, y + -2, z + 4, Blocks.bedrock, 0, 3);
        world.setBlock(x + 2, y + -2, z + 4, Blocks.bedrock, 0, 3);
        world.setBlock(x + 3, y + -2, z + 4, Blocks.bedrock, 0, 3);
        world.setBlock(x + 4, y + -2, z + 4, Blocks.bedrock, 0, 3);
        world.setBlock(x + 5, y + -2, z + 4, Blocks.bedrock, 0, 3);
        world.setBlock(x + 6, y + -2, z + 4, Blocks.bedrock, 0, 3);
        world.setBlock(x + 7, y + -2, z + 4, Blocks.bedrock, 0, 3);
        world.setBlock(x + 8, y + -2, z + 4, Blocks.bedrock, 0, 3);
        world.setBlock(x + 9, y + -2, z + 4, Blocks.bedrock, 0, 3);
        world.setBlock(x + 10, y + -2, z + 4, Blocks.bedrock, 0, 3);
        world.setBlock(x + 0, y + -2, z + 5, Blocks.bedrock, 0, 3);
        world.setBlock(x + 1, y + -2, z + 5, Blocks.bedrock, 0, 3);
        world.setBlock(x + 2, y + -2, z + 5, Blocks.bedrock, 0, 3);
        world.setBlock(x + 3, y + -2, z + 5, Blocks.bedrock, 0, 3);
        world.setBlock(x + 4, y + -2, z + 5, Blocks.bedrock, 0, 3);
        world.setBlock(x + 5, y + -2, z + 5, Blocks.bedrock, 0, 3);
        world.setBlock(x + 6, y + -2, z + 5, Blocks.bedrock, 0, 3);
        world.setBlock(x + 7, y + -2, z + 5, Blocks.bedrock, 0, 3);
        world.setBlock(x + 8, y + -2, z + 5, Blocks.bedrock, 0, 3);
        world.setBlock(x + 9, y + -2, z + 5, Blocks.bedrock, 0, 3);
        world.setBlock(x + 10, y + -2, z + 5, Blocks.bedrock, 0, 3);
        world.setBlock(x + 0, y + -2, z + 6, Blocks.bedrock, 0, 3);
        world.setBlock(x + 1, y + -2, z + 6, Blocks.bedrock, 0, 3);
        world.setBlock(x + 2, y + -2, z + 6, Blocks.bedrock, 0, 3);
        world.setBlock(x + 3, y + -2, z + 6, Blocks.bedrock, 0, 3);
        world.setBlock(x + 4, y + -2, z + 6, Blocks.bedrock, 0, 3);
        world.setBlock(x + 5, y + -2, z + 6, Blocks.bedrock, 0, 3);
        world.setBlock(x + 6, y + -2, z + 6, Blocks.bedrock, 0, 3);
        world.setBlock(x + 7, y + -2, z + 6, Blocks.bedrock, 0, 3);
        world.setBlock(x + 8, y + -2, z + 6, Blocks.bedrock, 0, 3);
        world.setBlock(x + 9, y + -2, z + 6, Blocks.bedrock, 0, 3);
        world.setBlock(x + 10, y + -2, z + 6, Blocks.bedrock, 0, 3);
        world.setBlock(x + 0, y + -2, z + 7, Blocks.bedrock, 0, 3);
        world.setBlock(x + 1, y + -2, z + 7, Blocks.bedrock, 0, 3);
        world.setBlock(x + 2, y + -2, z + 7, Blocks.bedrock, 0, 3);
        world.setBlock(x + 3, y + -2, z + 7, Blocks.bedrock, 0, 3);
        world.setBlock(x + 4, y + -2, z + 7, Blocks.bedrock, 0, 3);
        world.setBlock(x + 5, y + -2, z + 7, Blocks.bedrock, 0, 3);
        world.setBlock(x + 6, y + -2, z + 7, Blocks.bedrock, 0, 3);
        world.setBlock(x + 7, y + -2, z + 7, Blocks.bedrock, 0, 3);
        world.setBlock(x + 8, y + -2, z + 7, Blocks.bedrock, 0, 3);
        world.setBlock(x + 9, y + -2, z + 7, Blocks.bedrock, 0, 3);
        world.setBlock(x + 10, y + -2, z + 7, Blocks.bedrock, 0, 3);
        world.setBlock(x + 0, y + -2, z + 8, Blocks.bedrock, 0, 3);
        world.setBlock(x + 1, y + -2, z + 8, Blocks.bedrock, 0, 3);
        world.setBlock(x + 2, y + -2, z + 8, Blocks.bedrock, 0, 3);
        world.setBlock(x + 3, y + -2, z + 8, Blocks.bedrock, 0, 3);
        world.setBlock(x + 4, y + -2, z + 8, Blocks.bedrock, 0, 3);
        world.setBlock(x + 5, y + -2, z + 8, Blocks.bedrock, 0, 3);
        world.setBlock(x + 6, y + -2, z + 8, Blocks.bedrock, 0, 3);
        world.setBlock(x + 7, y + -2, z + 8, Blocks.bedrock, 0, 3);
        world.setBlock(x + 8, y + -2, z + 8, Blocks.bedrock, 0, 3);
        world.setBlock(x + 9, y + -2, z + 8, Blocks.bedrock, 0, 3);
        world.setBlock(x + 10, y + -2, z + 8, Blocks.bedrock, 0, 3);
        world.setBlock(x + 0, y + -2, z + 9, Blocks.bedrock, 0, 3);
        world.setBlock(x + 1, y + -2, z + 9, Blocks.bedrock, 0, 3);
        world.setBlock(x + 2, y + -2, z + 9, Blocks.bedrock, 0, 3);
        world.setBlock(x + 3, y + -2, z + 9, Blocks.bedrock, 0, 3);
        world.setBlock(x + 4, y + -2, z + 9, Blocks.bedrock, 0, 3);
        world.setBlock(x + 5, y + -2, z + 9, Blocks.bedrock, 0, 3);
        world.setBlock(x + 6, y + -2, z + 9, Blocks.bedrock, 0, 3);
        world.setBlock(x + 7, y + -2, z + 9, Blocks.bedrock, 0, 3);
        world.setBlock(x + 8, y + -2, z + 9, Blocks.bedrock, 0, 3);
        world.setBlock(x + 9, y + -2, z + 9, Blocks.bedrock, 0, 3);
        world.setBlock(x + 10, y + -2, z + 9, Blocks.bedrock, 0, 3);
        world.setBlock(x + 0, y + -1, z + 0, Blocks.bedrock, 0, 3);
        world.setBlock(x + 1, y + -1, z + 0, Blocks.bedrock, 0, 3);
        world.setBlock(x + 2, y + -1, z + 0, Blocks.bedrock, 0, 3);
        world.setBlock(x + 3, y + -1, z + 0, Blocks.bedrock, 0, 3);
        world.setBlock(x + 4, y + -1, z + 0, Blocks.bedrock, 0, 3);
        world.setBlock(x + 5, y + -1, z + 0, Blocks.bedrock, 0, 3);
        world.setBlock(x + 6, y + -1, z + 0, Blocks.bedrock, 0, 3);
        world.setBlock(x + 7, y + -1, z + 0, Blocks.bedrock, 0, 3);
        world.setBlock(x + 8, y + -1, z + 0, Blocks.bedrock, 0, 3);
        world.setBlock(x + 9, y + -1, z + 0, Blocks.bedrock, 0, 3);
        world.setBlock(x + 10, y + -1, z + 0, Blocks.bedrock, 0, 3);
        world.setBlock(x + 0, y + -1, z + 1, Blocks.bedrock, 0, 3);
        world.setBlock(x + 1, y + -1, z + 1, Blocks.stonebrick, 0, 3);
        world.setBlock(x + 2, y + -1, z + 1, Blocks.stonebrick, 0, 3);
        world.setBlock(x + 3, y + -1, z + 1, Blocks.stonebrick, 0, 3);
        world.setBlock(x + 4, y + -1, z + 1, Blocks.stonebrick, 0, 3);
        world.setBlock(x + 5, y + -1, z + 1, Blocks.stonebrick, 0, 3);
        world.setBlock(x + 6, y + -1, z + 1, Blocks.stonebrick, 0, 3);
        world.setBlock(x + 7, y + -1, z + 1, Blocks.stonebrick, 0, 3);
        world.setBlock(x + 8, y + -1, z + 1, Blocks.stonebrick, 0, 3);
        world.setBlock(x + 9, y + -1, z + 1, Blocks.stonebrick, 0, 3);
        world.setBlock(x + 10, y + -1, z + 1, Blocks.bedrock, 0, 3);
        world.setBlock(x + 0, y + -1, z + 2, Blocks.bedrock, 0, 3);
        world.setBlock(x + 1, y + -1, z + 2, Blocks.stonebrick, 0, 3);
        world.setBlock(x + 2, y + -1, z + 2, Blocks.stonebrick, 0, 3);
        world.setBlock(x + 3, y + -1, z + 2, Blocks.stonebrick, 0, 3);
        world.setBlock(x + 4, y + -1, z + 2, Blocks.stonebrick, 0, 3);
        world.setBlock(x + 5, y + -1, z + 2, Blocks.stonebrick, 0, 3);
        world.setBlock(x + 6, y + -1, z + 2, Blocks.stonebrick, 0, 3);
        world.setBlock(x + 7, y + -1, z + 2, Blocks.stonebrick, 0, 3);
        world.setBlock(x + 8, y + -1, z + 2, Blocks.stonebrick, 0, 3);
        world.setBlock(x + 9, y + -1, z + 2, Blocks.stonebrick, 0, 3);
        world.setBlock(x + 10, y + -1, z + 2, Blocks.bedrock, 0, 3);
        world.setBlock(x + 0, y + -1, z + 3, Blocks.bedrock, 0, 3);
        world.setBlock(x + 1, y + -1, z + 3, Blocks.stonebrick, 0, 3);
        world.setBlock(x + 2, y + -1, z + 3, Blocks.stonebrick, 0, 3);
        world.setBlock(x + 3, y + -1, z + 3, Blocks.stonebrick, 0, 3);
        world.setBlock(x + 4, y + -1, z + 3, Blocks.stonebrick, 0, 3);
        world.setBlock(x + 5, y + -1, z + 3, Blocks.stonebrick, 0, 3);
        world.setBlock(x + 6, y + -1, z + 3, Blocks.stonebrick, 0, 3);
        world.setBlock(x + 7, y + -1, z + 3, Blocks.stonebrick, 0, 3);
        world.setBlock(x + 8, y + -1, z + 3, Blocks.stonebrick, 0, 3);
        world.setBlock(x + 9, y + -1, z + 3, Blocks.stonebrick, 0, 3);
        world.setBlock(x + 10, y + -1, z + 3, Blocks.bedrock, 0, 3);
        world.setBlock(x + 0, y + -1, z + 4, Blocks.bedrock, 0, 3);
        world.setBlock(x + 1, y + -1, z + 4, Blocks.stonebrick, 0, 3);
        world.setBlock(x + 2, y + -1, z + 4, Blocks.stonebrick, 0, 3);
        world.setBlock(x + 3, y + -1, z + 4, Blocks.stonebrick, 0, 3);
        world.setBlock(x + 4, y + -1, z + 4, Blocks.stonebrick, 0, 3);
        world.setBlock(x + 5, y + -1, z + 4, Blocks.stonebrick, 0, 3);
        world.setBlock(x + 6, y + -1, z + 4, Blocks.stonebrick, 0, 3);
        world.setBlock(x + 7, y + -1, z + 4, Blocks.stonebrick, 0, 3);
        world.setBlock(x + 8, y + -1, z + 4, Blocks.stonebrick, 0, 3);
        world.setBlock(x + 9, y + -1, z + 4, Blocks.stonebrick, 0, 3);
        world.setBlock(x + 10, y + -1, z + 4, Blocks.bedrock, 0, 3);
        world.setBlock(x + 0, y + -1, z + 5, Blocks.bedrock, 0, 3);
        world.setBlock(x + 1, y + -1, z + 5, Blocks.stonebrick, 0, 3);
        world.setBlock(x + 2, y + -1, z + 5, Blocks.stonebrick, 0, 3);
        world.setBlock(x + 3, y + -1, z + 5, Blocks.stonebrick, 0, 3);
        world.setBlock(x + 4, y + -1, z + 5, Blocks.stonebrick, 0, 3);
        world.setBlock(x + 5, y + -1, z + 5, Blocks.stonebrick, 0, 3);
        world.setBlock(x + 6, y + -1, z + 5, Blocks.stonebrick, 0, 3);
        world.setBlock(x + 7, y + -1, z + 5, Blocks.stonebrick, 0, 3);
        world.setBlock(x + 8, y + -1, z + 5, Blocks.stonebrick, 0, 3);
        world.setBlock(x + 9, y + -1, z + 5, Blocks.stonebrick, 0, 3);
        world.setBlock(x + 10, y + -1, z + 5, Blocks.bedrock, 0, 3);
        world.setBlock(x + 0, y + -1, z + 6, Blocks.bedrock, 0, 3);
        world.setBlock(x + 1, y + -1, z + 6, Blocks.stonebrick, 0, 3);
        world.setBlock(x + 2, y + -1, z + 6, Blocks.stonebrick, 0, 3);
        world.setBlock(x + 3, y + -1, z + 6, Blocks.stonebrick, 0, 3);
        world.setBlock(x + 4, y + -1, z + 6, Blocks.stonebrick, 0, 3);
        world.setBlock(x + 5, y + -1, z + 6, Blocks.stonebrick, 0, 3);
        world.setBlock(x + 6, y + -1, z + 6, Blocks.stonebrick, 0, 3);
        world.setBlock(x + 7, y + -1, z + 6, Blocks.stonebrick, 0, 3);
        world.setBlock(x + 8, y + -1, z + 6, Blocks.stonebrick, 0, 3);
        world.setBlock(x + 9, y + -1, z + 6, Blocks.stonebrick, 0, 3);
        world.setBlock(x + 10, y + -1, z + 6, Blocks.bedrock, 0, 3);
        world.setBlock(x + 0, y + -1, z + 7, Blocks.bedrock, 0, 3);
        world.setBlock(x + 1, y + -1, z + 7, Blocks.stonebrick, 0, 3);
        world.setBlock(x + 2, y + -1, z + 7, Blocks.stonebrick, 0, 3);
        world.setBlock(x + 3, y + -1, z + 7, Blocks.stonebrick, 0, 3);
        world.setBlock(x + 4, y + -1, z + 7, Blocks.stonebrick, 0, 3);
        world.setBlock(x + 5, y + -1, z + 7, Blocks.stonebrick, 0, 3);
        world.setBlock(x + 6, y + -1, z + 7, Blocks.stonebrick, 0, 3);
        world.setBlock(x + 7, y + -1, z + 7, Blocks.stonebrick, 0, 3);
        world.setBlock(x + 8, y + -1, z + 7, Blocks.stonebrick, 0, 3);
        world.setBlock(x + 9, y + -1, z + 7, Blocks.stonebrick, 0, 3);
        world.setBlock(x + 10, y + -1, z + 7, Blocks.bedrock, 0, 3);
        world.setBlock(x + 0, y + -1, z + 8, Blocks.bedrock, 0, 3);
        world.setBlock(x + 1, y + -1, z + 8, Blocks.stonebrick, 0, 3);
        world.setBlock(x + 2, y + -1, z + 8, Blocks.stonebrick, 0, 3);
        world.setBlock(x + 3, y + -1, z + 8, Blocks.stonebrick, 0, 3);
        world.setBlock(x + 4, y + -1, z + 8, Blocks.stonebrick, 0, 3);
        world.setBlock(x + 5, y + -1, z + 8, Blocks.stonebrick, 0, 3);
        world.setBlock(x + 6, y + -1, z + 8, Blocks.stonebrick, 0, 3);
        world.setBlock(x + 7, y + -1, z + 8, Blocks.stonebrick, 0, 3);
        world.setBlock(x + 8, y + -1, z + 8, Blocks.stonebrick, 0, 3);
        world.setBlock(x + 9, y + -1, z + 8, Blocks.stonebrick, 0, 3);
        world.setBlock(x + 10, y + -1, z + 8, Blocks.bedrock, 0, 3);
        world.setBlock(x + 0, y + -1, z + 9, Blocks.bedrock, 0, 3);
        world.setBlock(x + 1, y + -1, z + 9, Blocks.bedrock, 0, 3);
        world.setBlock(x + 2, y + -1, z + 9, Blocks.bedrock, 0, 3);
        world.setBlock(x + 3, y + -1, z + 9, Blocks.bedrock, 0, 3);
        world.setBlock(x + 4, y + -1, z + 9, Blocks.bedrock, 0, 3);
        world.setBlock(x + 5, y + -1, z + 9, Blocks.bedrock, 0, 3);
        world.setBlock(x + 6, y + -1, z + 9, Blocks.bedrock, 0, 3);
        world.setBlock(x + 7, y + -1, z + 9, Blocks.bedrock, 0, 3);
        world.setBlock(x + 8, y + -1, z + 9, Blocks.bedrock, 0, 3);
        world.setBlock(x + 9, y + -1, z + 9, Blocks.bedrock, 0, 3);
        world.setBlock(x + 10, y + -1, z + 9, Blocks.bedrock, 0, 3);
        world.setBlock(x + 0, y + 0, z + 0, Blocks.bedrock, 0, 3);
        world.setBlock(x + 1, y + 0, z + 0, Blocks.bedrock, 0, 3);
        world.setBlock(x + 2, y + 0, z + 0, Blocks.bedrock, 0, 3);
        world.setBlock(x + 3, y + 0, z + 0, Blocks.bedrock, 0, 3);
        world.setBlock(x + 4, y + 0, z + 0, Blocks.bedrock, 0, 3);
        world.setBlock(x + 5, y + 0, z + 0, Blocks.bedrock, 0, 3);
        world.setBlock(x + 6, y + 0, z + 0, Blocks.bedrock, 0, 3);
        world.setBlock(x + 7, y + 0, z + 0, Blocks.bedrock, 0, 3);
        world.setBlock(x + 8, y + 0, z + 0, Blocks.bedrock, 0, 3);
        world.setBlock(x + 9, y + 0, z + 0, Blocks.bedrock, 0, 3);
        world.setBlock(x + 10, y + 0, z + 0, Blocks.bedrock, 0, 3);
        world.setBlock(x + 0, y + 0, z + 1, Blocks.bedrock, 0, 3);
        world.setBlock(x + 1, y + 0, z + 1, Blocks.stonebrick, 3, 3);
        world.setBlock(x + 2, y + 0, z + 1, Blocks.stonebrick, 3, 3);
        world.setBlock(x + 3, y + 0, z + 1, Blocks.stonebrick, 3, 3);
        world.setBlock(x + 4, y + 0, z + 1, Blocks.stonebrick, 3, 3);
        world.setBlock(x + 5, y + 0, z + 1, Blocks.stonebrick, 3, 3);
        world.setBlock(x + 6, y + 0, z + 1, Blocks.stonebrick, 3, 3);
        world.setBlock(x + 7, y + 0, z + 1, Blocks.stonebrick, 3, 3);
        world.setBlock(x + 8, y + 0, z + 1, Blocks.stonebrick, 3, 3);
        world.setBlock(x + 9, y + 0, z + 1, Blocks.stonebrick, 3, 3);
        world.setBlock(x + 10, y + 0, z + 1, Blocks.bedrock, 0, 3);
        world.setBlock(x + 0, y + 0, z + 2, Blocks.bedrock, 0, 3);
        world.setBlock(x + 1, y + 0, z + 2, Blocks.stonebrick, 3, 3);
        world.setBlock(x + 5, y + 0, z + 2, FABlockRegistry.ancientChest, 3, 3);
        world.setBlock(x + 9, y + 0, z + 2, Blocks.stonebrick, 3, 3);
        world.setBlock(x + 10, y + 0, z + 2, Blocks.bedrock, 0, 3);
        world.setBlock(x + 0, y + 0, z + 3, Blocks.bedrock, 0, 3);
        world.setBlock(x + 1, y + 0, z + 3, Blocks.stonebrick, 3, 3);
        world.setBlock(x + 9, y + 0, z + 3, Blocks.stonebrick, 3, 3);
        world.setBlock(x + 10, y + 0, z + 3, Blocks.bedrock, 0, 3);
        world.setBlock(x + 0, y + 0, z + 4, Blocks.bedrock, 0, 3);
        world.setBlock(x + 1, y + 0, z + 4, Blocks.stonebrick, 3, 3);
        world.setBlock(x + 9, y + 0, z + 4, Blocks.stonebrick, 3, 3);
        world.setBlock(x + 10, y + 0, z + 4, Blocks.bedrock, 0, 3);
        world.setBlock(x + 0, y + 0, z + 5, Blocks.bedrock, 0, 3);
        world.setBlock(x + 1, y + 0, z + 5, Blocks.stonebrick, 3, 3);
        world.setBlock(x + 9, y + 0, z + 5, Blocks.stonebrick, 3, 3);
        world.setBlock(x + 10, y + 0, z + 5, Blocks.bedrock, 0, 3);
        world.setBlock(x + 0, y + 0, z + 6, Blocks.bedrock, 0, 3);
        world.setBlock(x + 1, y + 0, z + 6, Blocks.stonebrick, 3, 3);
        world.setBlock(x + 3, y + 0, z + 6, Blocks.stone_brick_stairs, 2, 3);
        world.setBlock(x + 4, y + 0, z + 6, Blocks.stone_brick_stairs, 2, 3);
        world.setBlock(x + 5, y + 0, z + 6, Blocks.stone_brick_stairs, 2, 3);
        world.setBlock(x + 6, y + 0, z + 6, Blocks.stone_brick_stairs, 2, 3);
        world.setBlock(x + 7, y + 0, z + 6, Blocks.stone_brick_stairs, 2, 3);
        world.setBlock(x + 9, y + 0, z + 6, Blocks.stonebrick, 3, 3);
        world.setBlock(x + 10, y + 0, z + 6, Blocks.bedrock, 0, 3);
        world.setBlock(x + 0, y + 0, z + 7, Blocks.bedrock, 0, 3);
        world.setBlock(x + 1, y + 0, z + 7, Blocks.stonebrick, 3, 3);
        world.setBlock(x + 3, y + 0, z + 7, Blocks.stone_brick_stairs, 0, 3);
        world.setBlock(x + 4, y + 0, z + 7, Blocks.stonebrick, 3, 3);
        world.setBlock(x + 5, y + 0, z + 7, Blocks.stonebrick, 3, 3);
        world.setBlock(x + 6, y + 0, z + 7, Blocks.stonebrick, 3, 3);
        world.setBlock(x + 7, y + 0, z + 7, Blocks.stone_brick_stairs, 1, 3);
        world.setBlock(x + 9, y + 0, z + 7, Blocks.stonebrick, 3, 3);
        world.setBlock(x + 10, y + 0, z + 7, Blocks.bedrock, 0, 3);
        world.setBlock(x + 0, y + 0, z + 8, Blocks.bedrock, 0, 3);
        world.setBlock(x + 1, y + 0, z + 8, Blocks.stonebrick, 3, 3);
        world.setBlock(x + 2, y + 0, z + 8, Blocks.stonebrick, 3, 3);
        world.setBlock(x + 3, y + 0, z + 8, Blocks.stonebrick, 3, 3);
        world.setBlock(x + 4, y + 0, z + 8, Blocks.stonebrick, 3, 3);
        world.setBlock(x + 5, y + 0, z + 8, Blocks.stonebrick, 3, 3);
        world.setBlock(x + 6, y + 0, z + 8, Blocks.stonebrick, 3, 3);
        world.setBlock(x + 7, y + 0, z + 8, Blocks.stonebrick, 3, 3);
        world.setBlock(x + 8, y + 0, z + 8, Blocks.stonebrick, 3, 3);
        world.setBlock(x + 9, y + 0, z + 8, Blocks.stonebrick, 3, 3);
        world.setBlock(x + 10, y + 0, z + 8, Blocks.bedrock, 0, 3);
        world.setBlock(x + 0, y + 0, z + 9, Blocks.bedrock, 0, 3);
        world.setBlock(x + 1, y + 0, z + 9, Blocks.bedrock, 0, 3);
        world.setBlock(x + 2, y + 0, z + 9, Blocks.bedrock, 0, 3);
        world.setBlock(x + 3, y + 0, z + 9, Blocks.bedrock, 0, 3);
        world.setBlock(x + 4, y + 0, z + 9, Blocks.bedrock, 0, 3);
        world.setBlock(x + 5, y + 0, z + 9, Blocks.bedrock, 0, 3);
        world.setBlock(x + 6, y + 0, z + 9, Blocks.bedrock, 0, 3);
        world.setBlock(x + 7, y + 0, z + 9, Blocks.bedrock, 0, 3);
        world.setBlock(x + 8, y + 0, z + 9, Blocks.bedrock, 0, 3);
        world.setBlock(x + 9, y + 0, z + 9, Blocks.bedrock, 0, 3);
        world.setBlock(x + 10, y + 0, z + 9, Blocks.bedrock, 0, 3);
        world.setBlock(x + 0, y + 1, z + 0, Blocks.bedrock, 0, 3);
        world.setBlock(x + 1, y + 1, z + 0, Blocks.bedrock, 0, 3);
        world.setBlock(x + 2, y + 1, z + 0, Blocks.bedrock, 0, 3);
        world.setBlock(x + 3, y + 1, z + 0, Blocks.bedrock, 0, 3);
        world.setBlock(x + 4, y + 1, z + 0, Blocks.bedrock, 0, 3);
        world.setBlock(x + 5, y + 1, z + 0, Blocks.bedrock, 0, 3);
        world.setBlock(x + 6, y + 1, z + 0, Blocks.bedrock, 0, 3);
        world.setBlock(x + 7, y + 1, z + 0, Blocks.bedrock, 0, 3);
        world.setBlock(x + 8, y + 1, z + 0, Blocks.bedrock, 0, 3);
        world.setBlock(x + 9, y + 1, z + 0, Blocks.bedrock, 0, 3);
        world.setBlock(x + 10, y + 1, z + 0, Blocks.bedrock, 0, 3);
        world.setBlock(x + 0, y + 1, z + 1, Blocks.bedrock, 0, 3);
        world.setBlock(x + 1, y + 1, z + 1, Blocks.stonebrick, 0, 3);
        world.setBlock(x + 2, y + 1, z + 1, Blocks.stonebrick, 0, 3);
        world.setBlock(x + 3, y + 1, z + 1, Blocks.stonebrick, 0, 3);
        world.setBlock(x + 4, y + 1, z + 1, Blocks.stonebrick, 0, 3);
        world.setBlock(x + 5, y + 1, z + 1, Blocks.stonebrick, 0, 3);
        world.setBlock(x + 6, y + 1, z + 1, Blocks.stonebrick, 0, 3);
        world.setBlock(x + 7, y + 1, z + 1, Blocks.stonebrick, 0, 3);
        world.setBlock(x + 8, y + 1, z + 1, Blocks.stonebrick, 0, 3);
        world.setBlock(x + 9, y + 1, z + 1, Blocks.stonebrick, 0, 3);
        world.setBlock(x + 10, y + 1, z + 1, Blocks.bedrock, 0, 3);
        world.setBlock(x + 0, y + 1, z + 2, Blocks.bedrock, 0, 3);
        world.setBlock(x + 1, y + 1, z + 2, Blocks.stonebrick, 0, 3);
        world.setBlock(x + 9, y + 1, z + 2, Blocks.stonebrick, 0, 3);
        world.setBlock(x + 10, y + 1, z + 2, Blocks.bedrock, 0, 3);
        world.setBlock(x + 0, y + 1, z + 3, Blocks.bedrock, 0, 3);
        world.setBlock(x + 1, y + 1, z + 3, Blocks.stonebrick, 0, 3);
        world.setBlock(x + 9, y + 1, z + 3, Blocks.stonebrick, 0, 3);
        world.setBlock(x + 10, y + 1, z + 3, Blocks.bedrock, 0, 3);
        world.setBlock(x + 0, y + 1, z + 4, Blocks.bedrock, 0, 3);
        world.setBlock(x + 1, y + 1, z + 4, Blocks.stonebrick, 0, 3);
        world.setBlock(x + 9, y + 1, z + 4, Blocks.stonebrick, 0, 3);
        world.setBlock(x + 10, y + 1, z + 4, Blocks.bedrock, 0, 3);
        world.setBlock(x + 0, y + 1, z + 5, Blocks.bedrock, 0, 3);
        world.setBlock(x + 1, y + 1, z + 5, Blocks.stonebrick, 0, 3);
        world.setBlock(x + 9, y + 1, z + 5, Blocks.stonebrick, 0, 3);
        world.setBlock(x + 10, y + 1, z + 5, Blocks.bedrock, 0, 3);
        world.setBlock(x + 0, y + 1, z + 6, Blocks.bedrock, 0, 3);
        world.setBlock(x + 1, y + 1, z + 6, Blocks.stonebrick, 0, 3);
        world.setBlock(x + 9, y + 1, z + 6, Blocks.stonebrick, 0, 3);
        world.setBlock(x + 10, y + 1, z + 6, Blocks.bedrock, 0, 3);
        world.setBlock(x + 0, y + 1, z + 7, Blocks.bedrock, 0, 3);
        world.setBlock(x + 1, y + 1, z + 7, Blocks.stonebrick, 0, 3);
        world.setBlock(x + 4, y + 1, z + 7, Blocks.stone_brick_stairs, 0, 3);
        world.setBlock(x + 5, y + 1, z + 7, Blocks.stone_brick_stairs, 2, 3);
        world.setBlock(x + 6, y + 1, z + 7, Blocks.stone_brick_stairs, 1, 3);
        world.setBlock(x + 9, y + 1, z + 7, Blocks.stonebrick, 0, 3);
        world.setBlock(x + 10, y + 1, z + 7, Blocks.bedrock, 0, 3);
        world.setBlock(x + 0, y + 1, z + 8, Blocks.bedrock, 0, 3);
        world.setBlock(x + 1, y + 1, z + 8, Blocks.stonebrick, 0, 3);
        world.setBlock(x + 2, y + 1, z + 8, Blocks.stonebrick, 0, 3);
        world.setBlock(x + 3, y + 1, z + 8, Blocks.stonebrick, 0, 3);
        world.setBlock(x + 4, y + 1, z + 8, Blocks.obsidian, 0, 3);
        world.setBlock(x + 5, y + 1, z + 8, Blocks.obsidian, 0, 3);
        world.setBlock(x + 6, y + 1, z + 8, Blocks.obsidian, 0, 3);
        world.setBlock(x + 7, y + 1, z + 8, Blocks.stonebrick, 0, 3);
        world.setBlock(x + 8, y + 1, z + 8, Blocks.stonebrick, 0, 3);
        world.setBlock(x + 9, y + 1, z + 8, Blocks.stonebrick, 0, 3);
        world.setBlock(x + 10, y + 1, z + 8, Blocks.bedrock, 0, 3);
        world.setBlock(x + 0, y + 1, z + 9, Blocks.bedrock, 0, 3);
        world.setBlock(x + 1, y + 1, z + 9, Blocks.bedrock, 0, 3);
        world.setBlock(x + 2, y + 1, z + 9, Blocks.bedrock, 0, 3);
        world.setBlock(x + 3, y + 1, z + 9, Blocks.bedrock, 0, 3);
        world.setBlock(x + 4, y + 1, z + 9, Blocks.bedrock, 0, 3);
        world.setBlock(x + 5, y + 1, z + 9, Blocks.bedrock, 0, 3);
        world.setBlock(x + 6, y + 1, z + 9, Blocks.bedrock, 0, 3);
        world.setBlock(x + 7, y + 1, z + 9, Blocks.bedrock, 0, 3);
        world.setBlock(x + 8, y + 1, z + 9, Blocks.bedrock, 0, 3);
        world.setBlock(x + 9, y + 1, z + 9, Blocks.bedrock, 0, 3);
        world.setBlock(x + 10, y + 1, z + 9, Blocks.bedrock, 0, 3);
        world.setBlock(x + 0, y + 2, z + 0, Blocks.bedrock, 0, 3);
        world.setBlock(x + 1, y + 2, z + 0, Blocks.bedrock, 0, 3);
        world.setBlock(x + 2, y + 2, z + 0, Blocks.bedrock, 0, 3);
        world.setBlock(x + 3, y + 2, z + 0, Blocks.bedrock, 0, 3);
        world.setBlock(x + 4, y + 2, z + 0, Blocks.bedrock, 0, 3);
        world.setBlock(x + 5, y + 2, z + 0, Blocks.bedrock, 0, 3);
        world.setBlock(x + 6, y + 2, z + 0, Blocks.bedrock, 0, 3);
        world.setBlock(x + 7, y + 2, z + 0, Blocks.bedrock, 0, 3);
        world.setBlock(x + 8, y + 2, z + 0, Blocks.bedrock, 0, 3);
        world.setBlock(x + 9, y + 2, z + 0, Blocks.bedrock, 0, 3);
        world.setBlock(x + 10, y + 2, z + 0, Blocks.bedrock, 0, 3);
        world.setBlock(x + 0, y + 2, z + 1, Blocks.bedrock, 0, 3);
        world.setBlock(x + 1, y + 2, z + 1, Blocks.stonebrick, 0, 3);
        world.setBlock(x + 2, y + 2, z + 1, Blocks.stonebrick, 0, 3);
        world.setBlock(x + 3, y + 2, z + 1, Blocks.stonebrick, 0, 3);
        world.setBlock(x + 4, y + 2, z + 1, Blocks.stonebrick, 0, 3);
        world.setBlock(x + 5, y + 2, z + 1, Blocks.stonebrick, 0, 3);
        world.setBlock(x + 6, y + 2, z + 1, Blocks.stonebrick, 0, 3);
        world.setBlock(x + 7, y + 2, z + 1, Blocks.stonebrick, 0, 3);
        world.setBlock(x + 8, y + 2, z + 1, Blocks.stonebrick, 0, 3);
        world.setBlock(x + 9, y + 2, z + 1, Blocks.stonebrick, 0, 3);
        world.setBlock(x + 10, y + 2, z + 1, Blocks.bedrock, 0, 3);
        world.setBlock(x + 0, y + 2, z + 2, Blocks.bedrock, 0, 3);
        world.setBlock(x + 1, y + 2, z + 2, Blocks.stonebrick, 0, 3);
        world.setBlock(x + 9, y + 2, z + 2, Blocks.stonebrick, 0, 3);
        world.setBlock(x + 10, y + 2, z + 2, Blocks.bedrock, 0, 3);
        world.setBlock(x + 0, y + 2, z + 3, Blocks.bedrock, 0, 3);
        world.setBlock(x + 1, y + 2, z + 3, Blocks.stonebrick, 0, 3);
        world.setBlock(x + 9, y + 2, z + 3, Blocks.stonebrick, 0, 3);
        world.setBlock(x + 10, y + 2, z + 3, Blocks.bedrock, 0, 3);
        world.setBlock(x + 0, y + 2, z + 4, Blocks.bedrock, 0, 3);
        world.setBlock(x + 1, y + 2, z + 4, Blocks.stonebrick, 0, 3);
        world.setBlock(x + 9, y + 2, z + 4, Blocks.stonebrick, 0, 3);
        world.setBlock(x + 10, y + 2, z + 4, Blocks.bedrock, 0, 3);
        world.setBlock(x + 0, y + 2, z + 5, Blocks.bedrock, 0, 3);
        world.setBlock(x + 1, y + 2, z + 5, Blocks.stonebrick, 0, 3);
        world.setBlock(x + 9, y + 2, z + 5, Blocks.stonebrick, 0, 3);
        world.setBlock(x + 10, y + 2, z + 5, Blocks.bedrock, 0, 3);
        world.setBlock(x + 0, y + 2, z + 6, Blocks.bedrock, 0, 3);
        world.setBlock(x + 1, y + 2, z + 6, Blocks.stonebrick, 0, 3);
        world.setBlock(x + 9, y + 2, z + 6, Blocks.stonebrick, 0, 3);
        world.setBlock(x + 10, y + 2, z + 6, Blocks.bedrock, 0, 3);
        world.setBlock(x + 0, y + 2, z + 7, Blocks.bedrock, 0, 3);
        world.setBlock(x + 1, y + 2, z + 7, Blocks.stonebrick, 0, 3);
        world.setBlock(x + 9, y + 2, z + 7, Blocks.stonebrick, 0, 3);
        world.setBlock(x + 10, y + 2, z + 7, Blocks.bedrock, 0, 3);
        world.setBlock(x + 0, y + 2, z + 8, Blocks.bedrock, 0, 3);
        world.setBlock(x + 1, y + 2, z + 8, Blocks.stonebrick, 0, 3);
        world.setBlock(x + 2, y + 2, z + 8, Blocks.stonebrick, 0, 3);
        world.setBlock(x + 3, y + 2, z + 8, Blocks.obsidian, 0, 3);
        world.setBlock(x + 4, y + 2, z + 8, FABlockRegistry.homePortal, 0, 3);
        world.setBlock(x + 5, y + 2, z + 8, FABlockRegistry.homePortal, 0, 3);
        world.setBlock(x + 6, y + 2, z + 8, FABlockRegistry.homePortal, 0, 3);
        world.setBlock(x + 7, y + 2, z + 8, Blocks.obsidian, 0, 3);
        world.setBlock(x + 8, y + 2, z + 8, Blocks.stonebrick, 0, 3);
        world.setBlock(x + 9, y + 2, z + 8, Blocks.stonebrick, 0, 3);
        world.setBlock(x + 10, y + 2, z + 8, Blocks.bedrock, 0, 3);
        world.setBlock(x + 0, y + 2, z + 9, Blocks.bedrock, 0, 3);
        world.setBlock(x + 1, y + 2, z + 9, Blocks.bedrock, 0, 3);
        world.setBlock(x + 2, y + 2, z + 9, Blocks.bedrock, 0, 3);
        world.setBlock(x + 3, y + 2, z + 9, Blocks.bedrock, 0, 3);
        world.setBlock(x + 4, y + 2, z + 9, Blocks.bedrock, 0, 3);
        world.setBlock(x + 5, y + 2, z + 9, Blocks.bedrock, 0, 3);
        world.setBlock(x + 6, y + 2, z + 9, Blocks.bedrock, 0, 3);
        world.setBlock(x + 7, y + 2, z + 9, Blocks.bedrock, 0, 3);
        world.setBlock(x + 8, y + 2, z + 9, Blocks.bedrock, 0, 3);
        world.setBlock(x + 9, y + 2, z + 9, Blocks.bedrock, 0, 3);
        world.setBlock(x + 10, y + 2, z + 9, Blocks.bedrock, 0, 3);
        world.setBlock(x + 0, y + 3, z + 0, Blocks.bedrock, 0, 3);
        world.setBlock(x + 1, y + 3, z + 0, Blocks.bedrock, 0, 3);
        world.setBlock(x + 2, y + 3, z + 0, Blocks.bedrock, 0, 3);
        world.setBlock(x + 3, y + 3, z + 0, Blocks.bedrock, 0, 3);
        world.setBlock(x + 4, y + 3, z + 0, Blocks.bedrock, 0, 3);
        world.setBlock(x + 5, y + 3, z + 0, Blocks.bedrock, 0, 3);
        world.setBlock(x + 6, y + 3, z + 0, Blocks.bedrock, 0, 3);
        world.setBlock(x + 7, y + 3, z + 0, Blocks.bedrock, 0, 3);
        world.setBlock(x + 8, y + 3, z + 0, Blocks.bedrock, 0, 3);
        world.setBlock(x + 9, y + 3, z + 0, Blocks.bedrock, 0, 3);
        world.setBlock(x + 10, y + 3, z + 0, Blocks.bedrock, 0, 3);
        world.setBlock(x + 0, y + 3, z + 1, Blocks.bedrock, 0, 3);
        world.setBlock(x + 1, y + 3, z + 1, Blocks.stonebrick, 3, 3);
        world.setBlock(x + 2, y + 3, z + 1, Blocks.stonebrick, 3, 3);
        world.setBlock(x + 3, y + 3, z + 1, Blocks.stonebrick, 3, 3);
        world.setBlock(x + 4, y + 3, z + 1, Blocks.stonebrick, 3, 3);
        world.setBlock(x + 5, y + 3, z + 1, Blocks.stonebrick, 3, 3);
        world.setBlock(x + 6, y + 3, z + 1, Blocks.stonebrick, 3, 3);
        world.setBlock(x + 7, y + 3, z + 1, Blocks.stonebrick, 3, 3);
        world.setBlock(x + 8, y + 3, z + 1, Blocks.stonebrick, 3, 3);
        world.setBlock(x + 9, y + 3, z + 1, Blocks.stonebrick, 3, 3);
        world.setBlock(x + 10, y + 3, z + 1, Blocks.bedrock, 0, 3);
        world.setBlock(x + 0, y + 3, z + 2, Blocks.bedrock, 0, 3);
        world.setBlock(x + 1, y + 3, z + 2, Blocks.stonebrick, 3, 3);
        world.setBlock(x + 9, y + 3, z + 2, Blocks.stonebrick, 3, 3);
        world.setBlock(x + 10, y + 3, z + 2, Blocks.bedrock, 0, 3);
        world.setBlock(x + 0, y + 3, z + 3, Blocks.bedrock, 0, 3);
        world.setBlock(x + 1, y + 3, z + 3, Blocks.stonebrick, 3, 3);
        world.setBlock(x + 9, y + 3, z + 3, Blocks.stonebrick, 3, 3);
        world.setBlock(x + 10, y + 3, z + 3, Blocks.bedrock, 0, 3);
        world.setBlock(x + 0, y + 3, z + 4, Blocks.bedrock, 0, 3);
        world.setBlock(x + 1, y + 3, z + 4, Blocks.stonebrick, 3, 3);
        world.setBlock(x + 9, y + 3, z + 4, Blocks.stonebrick, 3, 3);
        world.setBlock(x + 10, y + 3, z + 4, Blocks.bedrock, 0, 3);
        world.setBlock(x + 0, y + 3, z + 5, Blocks.bedrock, 0, 3);
        world.setBlock(x + 1, y + 3, z + 5, Blocks.stonebrick, 3, 3);
        world.setBlock(x + 9, y + 3, z + 5, Blocks.stonebrick, 3, 3);
        world.setBlock(x + 10, y + 3, z + 5, Blocks.bedrock, 0, 3);
        world.setBlock(x + 0, y + 3, z + 6, Blocks.bedrock, 0, 3);
        world.setBlock(x + 1, y + 3, z + 6, Blocks.stonebrick, 3, 3);
        world.setBlock(x + 9, y + 3, z + 6, Blocks.stonebrick, 3, 3);
        world.setBlock(x + 10, y + 3, z + 6, Blocks.bedrock, 0, 3);
        world.setBlock(x + 0, y + 3, z + 7, Blocks.bedrock, 0, 3);
        world.setBlock(x + 1, y + 3, z + 7, Blocks.stonebrick, 3, 3);
        world.setBlock(x + 9, y + 3, z + 7, Blocks.stonebrick, 3, 3);
        world.setBlock(x + 10, y + 3, z + 7, Blocks.bedrock, 0, 3);
        world.setBlock(x + 0, y + 3, z + 8, Blocks.bedrock, 0, 3);
        world.setBlock(x + 1, y + 3, z + 8, Blocks.stonebrick, 3, 3);
        world.setBlock(x + 2, y + 3, z + 8, Blocks.stonebrick, 3, 3);
        world.setBlock(x + 3, y + 3, z + 8, Blocks.obsidian, 0, 3);
        world.setBlock(x + 4, y + 3, z + 8, FABlockRegistry.homePortal, 0, 3);
        world.setBlock(x + 5, y + 3, z + 8, FABlockRegistry.homePortal, 0, 3);
        world.setBlock(x + 6, y + 3, z + 8, FABlockRegistry.homePortal, 0, 3);
        world.setBlock(x + 7, y + 3, z + 8, Blocks.obsidian, 0, 3);
        world.setBlock(x + 8, y + 3, z + 8, Blocks.stonebrick, 3, 3);
        world.setBlock(x + 9, y + 3, z + 8, Blocks.stonebrick, 3, 3);
        world.setBlock(x + 10, y + 3, z + 8, Blocks.bedrock, 0, 3);
        world.setBlock(x + 0, y + 3, z + 9, Blocks.bedrock, 0, 3);
        world.setBlock(x + 1, y + 3, z + 9, Blocks.bedrock, 0, 3);
        world.setBlock(x + 2, y + 3, z + 9, Blocks.bedrock, 0, 3);
        world.setBlock(x + 3, y + 3, z + 9, Blocks.bedrock, 0, 3);
        world.setBlock(x + 4, y + 3, z + 9, Blocks.bedrock, 0, 3);
        world.setBlock(x + 5, y + 3, z + 9, Blocks.bedrock, 0, 3);
        world.setBlock(x + 6, y + 3, z + 9, Blocks.bedrock, 0, 3);
        world.setBlock(x + 7, y + 3, z + 9, Blocks.bedrock, 0, 3);
        world.setBlock(x + 8, y + 3, z + 9, Blocks.bedrock, 0, 3);
        world.setBlock(x + 9, y + 3, z + 9, Blocks.bedrock, 0, 3);
        world.setBlock(x + 10, y + 3, z + 9, Blocks.bedrock, 0, 3);
        world.setBlock(x + 0, y + 4, z + 0, Blocks.bedrock, 0, 3);
        world.setBlock(x + 1, y + 4, z + 0, Blocks.bedrock, 0, 3);
        world.setBlock(x + 2, y + 4, z + 0, Blocks.bedrock, 0, 3);
        world.setBlock(x + 3, y + 4, z + 0, Blocks.bedrock, 0, 3);
        world.setBlock(x + 4, y + 4, z + 0, Blocks.bedrock, 0, 3);
        world.setBlock(x + 5, y + 4, z + 0, Blocks.bedrock, 0, 3);
        world.setBlock(x + 6, y + 4, z + 0, Blocks.bedrock, 0, 3);
        world.setBlock(x + 7, y + 4, z + 0, Blocks.bedrock, 0, 3);
        world.setBlock(x + 8, y + 4, z + 0, Blocks.bedrock, 0, 3);
        world.setBlock(x + 9, y + 4, z + 0, Blocks.bedrock, 0, 3);
        world.setBlock(x + 10, y + 4, z + 0, Blocks.bedrock, 0, 3);
        world.setBlock(x + 0, y + 4, z + 1, Blocks.bedrock, 0, 3);
        world.setBlock(x + 1, y + 4, z + 1, Blocks.stonebrick, 0, 3);
        world.setBlock(x + 2, y + 4, z + 1, Blocks.stonebrick, 0, 3);
        world.setBlock(x + 3, y + 4, z + 1, Blocks.stonebrick, 0, 3);
        world.setBlock(x + 4, y + 4, z + 1, Blocks.stonebrick, 0, 3);
        world.setBlock(x + 5, y + 4, z + 1, Blocks.stonebrick, 0, 3);
        world.setBlock(x + 6, y + 4, z + 1, Blocks.stonebrick, 0, 3);
        world.setBlock(x + 7, y + 4, z + 1, Blocks.stonebrick, 0, 3);
        world.setBlock(x + 8, y + 4, z + 1, Blocks.stonebrick, 0, 3);
        world.setBlock(x + 9, y + 4, z + 1, Blocks.stonebrick, 0, 3);
        world.setBlock(x + 10, y + 4, z + 1, Blocks.bedrock, 0, 3);
        world.setBlock(x + 0, y + 4, z + 2, Blocks.bedrock, 0, 3);
        world.setBlock(x + 1, y + 4, z + 2, Blocks.stonebrick, 0, 3);
        world.setBlock(x + 9, y + 4, z + 2, Blocks.stonebrick, 0, 3);
        world.setBlock(x + 10, y + 4, z + 2, Blocks.bedrock, 0, 3);
        world.setBlock(x + 0, y + 4, z + 3, Blocks.bedrock, 0, 3);
        world.setBlock(x + 1, y + 4, z + 3, Blocks.stonebrick, 0, 3);
        world.setBlock(x + 9, y + 4, z + 3, Blocks.stonebrick, 0, 3);
        world.setBlock(x + 10, y + 4, z + 3, Blocks.bedrock, 0, 3);
        world.setBlock(x + 0, y + 4, z + 4, Blocks.bedrock, 0, 3);
        world.setBlock(x + 1, y + 4, z + 4, Blocks.stonebrick, 0, 3);
        world.setBlock(x + 9, y + 4, z + 4, Blocks.stonebrick, 0, 3);
        world.setBlock(x + 10, y + 4, z + 4, Blocks.bedrock, 0, 3);
        world.setBlock(x + 0, y + 4, z + 5, Blocks.bedrock, 0, 3);
        world.setBlock(x + 1, y + 4, z + 5, Blocks.stonebrick, 0, 3);
        world.setBlock(x + 9, y + 4, z + 5, Blocks.stonebrick, 0, 3);
        world.setBlock(x + 10, y + 4, z + 5, Blocks.bedrock, 0, 3);
        world.setBlock(x + 0, y + 4, z + 6, Blocks.bedrock, 0, 3);
        world.setBlock(x + 1, y + 4, z + 6, Blocks.stonebrick, 0, 3);
        world.setBlock(x + 9, y + 4, z + 6, Blocks.stonebrick, 0, 3);
        world.setBlock(x + 10, y + 4, z + 6, Blocks.bedrock, 0, 3);
        world.setBlock(x + 0, y + 4, z + 7, Blocks.bedrock, 0, 3);
        world.setBlock(x + 1, y + 4, z + 7, Blocks.stonebrick, 0, 3);
        world.setBlock(x + 9, y + 4, z + 7, Blocks.stonebrick, 0, 3);
        world.setBlock(x + 10, y + 4, z + 7, Blocks.bedrock, 0, 3);
        world.setBlock(x + 0, y + 4, z + 8, Blocks.bedrock, 0, 3);
        world.setBlock(x + 1, y + 4, z + 8, Blocks.stonebrick, 0, 3);
        world.setBlock(x + 2, y + 4, z + 8, Blocks.stonebrick, 0, 3);
        world.setBlock(x + 3, y + 4, z + 8, Blocks.obsidian, 0, 3);
        world.setBlock(x + 4, y + 4, z + 8, FABlockRegistry.homePortal, 0, 3);
        world.setBlock(x + 5, y + 4, z + 8, FABlockRegistry.homePortal, 0, 3);
        world.setBlock(x + 6, y + 4, z + 8, FABlockRegistry.homePortal, 0, 3);
        world.setBlock(x + 7, y + 4, z + 8, Blocks.obsidian, 0, 3);
        world.setBlock(x + 8, y + 4, z + 8, Blocks.stonebrick, 0, 3);
        world.setBlock(x + 9, y + 4, z + 8, Blocks.stonebrick, 0, 3);
        world.setBlock(x + 10, y + 4, z + 8, Blocks.bedrock, 0, 3);
        world.setBlock(x + 0, y + 4, z + 9, Blocks.bedrock, 0, 3);
        world.setBlock(x + 1, y + 4, z + 9, Blocks.bedrock, 0, 3);
        world.setBlock(x + 2, y + 4, z + 9, Blocks.bedrock, 0, 3);
        world.setBlock(x + 3, y + 4, z + 9, Blocks.bedrock, 0, 3);
        world.setBlock(x + 4, y + 4, z + 9, Blocks.bedrock, 0, 3);
        world.setBlock(x + 5, y + 4, z + 9, Blocks.bedrock, 0, 3);
        world.setBlock(x + 6, y + 4, z + 9, Blocks.bedrock, 0, 3);
        world.setBlock(x + 7, y + 4, z + 9, Blocks.bedrock, 0, 3);
        world.setBlock(x + 8, y + 4, z + 9, Blocks.bedrock, 0, 3);
        world.setBlock(x + 9, y + 4, z + 9, Blocks.bedrock, 0, 3);
        world.setBlock(x + 10, y + 4, z + 9, Blocks.bedrock, 0, 3);
        world.setBlock(x + 0, y + 5, z + 0, Blocks.bedrock, 0, 3);
        world.setBlock(x + 1, y + 5, z + 0, Blocks.bedrock, 0, 3);
        world.setBlock(x + 2, y + 5, z + 0, Blocks.bedrock, 0, 3);
        world.setBlock(x + 3, y + 5, z + 0, Blocks.bedrock, 0, 3);
        world.setBlock(x + 4, y + 5, z + 0, Blocks.bedrock, 0, 3);
        world.setBlock(x + 5, y + 5, z + 0, Blocks.bedrock, 0, 3);
        world.setBlock(x + 6, y + 5, z + 0, Blocks.bedrock, 0, 3);
        world.setBlock(x + 7, y + 5, z + 0, Blocks.bedrock, 0, 3);
        world.setBlock(x + 8, y + 5, z + 0, Blocks.bedrock, 0, 3);
        world.setBlock(x + 9, y + 5, z + 0, Blocks.bedrock, 0, 3);
        world.setBlock(x + 10, y + 5, z + 0, Blocks.bedrock, 0, 3);
        world.setBlock(x + 0, y + 5, z + 1, Blocks.bedrock, 0, 3);
        world.setBlock(x + 1, y + 5, z + 1, Blocks.stonebrick, 0, 3);
        world.setBlock(x + 2, y + 5, z + 1, Blocks.stonebrick, 0, 3);
        world.setBlock(x + 3, y + 5, z + 1, Blocks.stonebrick, 0, 3);
        world.setBlock(x + 4, y + 5, z + 1, Blocks.stonebrick, 0, 3);
        world.setBlock(x + 5, y + 5, z + 1, Blocks.stonebrick, 0, 3);
        world.setBlock(x + 6, y + 5, z + 1, Blocks.stonebrick, 0, 3);
        world.setBlock(x + 7, y + 5, z + 1, Blocks.stonebrick, 0, 3);
        world.setBlock(x + 8, y + 5, z + 1, Blocks.stonebrick, 0, 3);
        world.setBlock(x + 9, y + 5, z + 1, Blocks.stonebrick, 0, 3);
        world.setBlock(x + 10, y + 5, z + 1, Blocks.bedrock, 0, 3);
        world.setBlock(x + 0, y + 5, z + 2, Blocks.bedrock, 0, 3);
        world.setBlock(x + 1, y + 5, z + 2, Blocks.stonebrick, 0, 3);
        world.setBlock(x + 9, y + 5, z + 2, Blocks.stonebrick, 0, 3);
        world.setBlock(x + 10, y + 5, z + 2, Blocks.bedrock, 0, 3);
        world.setBlock(x + 0, y + 5, z + 3, Blocks.bedrock, 0, 3);
        world.setBlock(x + 1, y + 5, z + 3, Blocks.stonebrick, 0, 3);
        world.setBlock(x + 9, y + 5, z + 3, Blocks.stonebrick, 0, 3);
        world.setBlock(x + 10, y + 5, z + 3, Blocks.bedrock, 0, 3);
        world.setBlock(x + 0, y + 5, z + 4, Blocks.bedrock, 0, 3);
        world.setBlock(x + 1, y + 5, z + 4, Blocks.stonebrick, 0, 3);
        world.setBlock(x + 9, y + 5, z + 4, Blocks.stonebrick, 0, 3);
        world.setBlock(x + 10, y + 5, z + 4, Blocks.bedrock, 0, 3);
        world.setBlock(x + 0, y + 5, z + 5, Blocks.bedrock, 0, 3);
        world.setBlock(x + 1, y + 5, z + 5, Blocks.stonebrick, 0, 3);
        world.setBlock(x + 9, y + 5, z + 5, Blocks.stonebrick, 0, 3);
        world.setBlock(x + 10, y + 5, z + 5, Blocks.bedrock, 0, 3);
        world.setBlock(x + 0, y + 5, z + 6, Blocks.bedrock, 0, 3);
        world.setBlock(x + 1, y + 5, z + 6, Blocks.stonebrick, 0, 3);
        world.setBlock(x + 9, y + 5, z + 6, Blocks.stonebrick, 0, 3);
        world.setBlock(x + 10, y + 5, z + 6, Blocks.bedrock, 0, 3);
        world.setBlock(x + 0, y + 5, z + 7, Blocks.bedrock, 0, 3);
        world.setBlock(x + 1, y + 5, z + 7, Blocks.stonebrick, 0, 3);
        world.setBlock(x + 9, y + 5, z + 7, Blocks.stonebrick, 0, 3);
        world.setBlock(x + 10, y + 5, z + 7, Blocks.bedrock, 0, 3);
        world.setBlock(x + 0, y + 5, z + 8, Blocks.bedrock, 0, 3);
        world.setBlock(x + 1, y + 5, z + 8, Blocks.stonebrick, 0, 3);
        world.setBlock(x + 2, y + 5, z + 8, Blocks.stonebrick, 0, 3);
        world.setBlock(x + 3, y + 5, z + 8, Blocks.stonebrick, 0, 3);
        world.setBlock(x + 4, y + 5, z + 8, Blocks.obsidian, 0, 3);
        world.setBlock(x + 5, y + 5, z + 8, Blocks.obsidian, 0, 3);
        world.setBlock(x + 6, y + 5, z + 8, Blocks.obsidian, 0, 3);
        world.setBlock(x + 7, y + 5, z + 8, Blocks.stonebrick, 0, 3);
        world.setBlock(x + 8, y + 5, z + 8, Blocks.stonebrick, 0, 3);
        world.setBlock(x + 9, y + 5, z + 8, Blocks.stonebrick, 0, 3);
        world.setBlock(x + 10, y + 5, z + 8, Blocks.bedrock, 0, 3);
        world.setBlock(x + 0, y + 5, z + 9, Blocks.bedrock, 0, 3);
        world.setBlock(x + 1, y + 5, z + 9, Blocks.bedrock, 0, 3);
        world.setBlock(x + 2, y + 5, z + 9, Blocks.bedrock, 0, 3);
        world.setBlock(x + 3, y + 5, z + 9, Blocks.bedrock, 0, 3);
        world.setBlock(x + 4, y + 5, z + 9, Blocks.bedrock, 0, 3);
        world.setBlock(x + 5, y + 5, z + 9, Blocks.bedrock, 0, 3);
        world.setBlock(x + 6, y + 5, z + 9, Blocks.bedrock, 0, 3);
        world.setBlock(x + 7, y + 5, z + 9, Blocks.bedrock, 0, 3);
        world.setBlock(x + 8, y + 5, z + 9, Blocks.bedrock, 0, 3);
        world.setBlock(x + 9, y + 5, z + 9, Blocks.bedrock, 0, 3);
        world.setBlock(x + 10, y + 5, z + 9, Blocks.bedrock, 0, 3);
        world.setBlock(x + 0, y + 6, z + 0, Blocks.bedrock, 0, 3);
        world.setBlock(x + 1, y + 6, z + 0, Blocks.bedrock, 0, 3);
        world.setBlock(x + 2, y + 6, z + 0, Blocks.bedrock, 0, 3);
        world.setBlock(x + 3, y + 6, z + 0, Blocks.bedrock, 0, 3);
        world.setBlock(x + 4, y + 6, z + 0, Blocks.bedrock, 0, 3);
        world.setBlock(x + 5, y + 6, z + 0, Blocks.bedrock, 0, 3);
        world.setBlock(x + 6, y + 6, z + 0, Blocks.bedrock, 0, 3);
        world.setBlock(x + 7, y + 6, z + 0, Blocks.bedrock, 0, 3);
        world.setBlock(x + 8, y + 6, z + 0, Blocks.bedrock, 0, 3);
        world.setBlock(x + 9, y + 6, z + 0, Blocks.bedrock, 0, 3);
        world.setBlock(x + 10, y + 6, z + 0, Blocks.bedrock, 0, 3);
        world.setBlock(x + 0, y + 6, z + 1, Blocks.bedrock, 0, 3);
        world.setBlock(x + 1, y + 6, z + 1, Blocks.stonebrick, 3, 3);
        world.setBlock(x + 2, y + 6, z + 1, Blocks.stonebrick, 3, 3);
        world.setBlock(x + 3, y + 6, z + 1, Blocks.stonebrick, 3, 3);
        world.setBlock(x + 4, y + 6, z + 1, Blocks.stonebrick, 3, 3);
        world.setBlock(x + 5, y + 6, z + 1, Blocks.stonebrick, 3, 3);
        world.setBlock(x + 6, y + 6, z + 1, Blocks.stonebrick, 3, 3);
        world.setBlock(x + 7, y + 6, z + 1, Blocks.stonebrick, 3, 3);
        world.setBlock(x + 8, y + 6, z + 1, Blocks.stonebrick, 3, 3);
        world.setBlock(x + 9, y + 6, z + 1, Blocks.stonebrick, 3, 3);
        world.setBlock(x + 10, y + 6, z + 1, Blocks.bedrock, 0, 3);
        world.setBlock(x + 0, y + 6, z + 2, Blocks.bedrock, 0, 3);
        world.setBlock(x + 1, y + 6, z + 2, Blocks.stonebrick, 3, 3);
        world.setBlock(x + 9, y + 6, z + 2, Blocks.stonebrick, 3, 3);
        world.setBlock(x + 10, y + 6, z + 2, Blocks.bedrock, 0, 3);
        world.setBlock(x + 0, y + 6, z + 3, Blocks.bedrock, 0, 3);
        world.setBlock(x + 1, y + 6, z + 3, Blocks.stonebrick, 3, 3);
        world.setBlock(x + 9, y + 6, z + 3, Blocks.stonebrick, 3, 3);
        world.setBlock(x + 10, y + 6, z + 3, Blocks.bedrock, 0, 3);
        world.setBlock(x + 0, y + 6, z + 4, Blocks.bedrock, 0, 3);
        world.setBlock(x + 1, y + 6, z + 4, Blocks.stonebrick, 3, 3);
        world.setBlock(x + 9, y + 6, z + 4, Blocks.stonebrick, 3, 3);
        world.setBlock(x + 10, y + 6, z + 4, Blocks.bedrock, 0, 3);
        world.setBlock(x + 0, y + 6, z + 5, Blocks.bedrock, 0, 3);
        world.setBlock(x + 1, y + 6, z + 5, Blocks.stonebrick, 3, 3);
        world.setBlock(x + 9, y + 6, z + 5, Blocks.stonebrick, 3, 3);
        world.setBlock(x + 10, y + 6, z + 5, Blocks.bedrock, 0, 3);
        world.setBlock(x + 0, y + 6, z + 6, Blocks.bedrock, 0, 3);
        world.setBlock(x + 1, y + 6, z + 6, Blocks.stonebrick, 3, 3);
        world.setBlock(x + 9, y + 6, z + 6, Blocks.stonebrick, 3, 3);
        world.setBlock(x + 10, y + 6, z + 6, Blocks.bedrock, 0, 3);
        world.setBlock(x + 0, y + 6, z + 7, Blocks.bedrock, 0, 3);
        world.setBlock(x + 1, y + 6, z + 7, Blocks.stonebrick, 3, 3);
        world.setBlock(x + 9, y + 6, z + 7, Blocks.stonebrick, 3, 3);
        world.setBlock(x + 10, y + 6, z + 7, Blocks.bedrock, 0, 3);
        world.setBlock(x + 0, y + 6, z + 8, Blocks.bedrock, 0, 3);
        world.setBlock(x + 1, y + 6, z + 8, Blocks.stonebrick, 3, 3);
        world.setBlock(x + 2, y + 6, z + 8, Blocks.stonebrick, 3, 3);
        world.setBlock(x + 3, y + 6, z + 8, Blocks.stonebrick, 3, 3);
        world.setBlock(x + 4, y + 6, z + 8, Blocks.stonebrick, 3, 3);
        world.setBlock(x + 5, y + 6, z + 8, Blocks.stonebrick, 3, 3);
        world.setBlock(x + 6, y + 6, z + 8, Blocks.stonebrick, 3, 3);
        world.setBlock(x + 7, y + 6, z + 8, Blocks.stonebrick, 3, 3);
        world.setBlock(x + 8, y + 6, z + 8, Blocks.stonebrick, 3, 3);
        world.setBlock(x + 9, y + 6, z + 8, Blocks.stonebrick, 3, 3);
        world.setBlock(x + 10, y + 6, z + 8, Blocks.bedrock, 0, 3);
        world.setBlock(x + 0, y + 6, z + 9, Blocks.bedrock, 0, 3);
        world.setBlock(x + 1, y + 6, z + 9, Blocks.bedrock, 0, 3);
        world.setBlock(x + 2, y + 6, z + 9, Blocks.bedrock, 0, 3);
        world.setBlock(x + 3, y + 6, z + 9, Blocks.bedrock, 0, 3);
        world.setBlock(x + 4, y + 6, z + 9, Blocks.bedrock, 0, 3);
        world.setBlock(x + 5, y + 6, z + 9, Blocks.bedrock, 0, 3);
        world.setBlock(x + 6, y + 6, z + 9, Blocks.bedrock, 0, 3);
        world.setBlock(x + 7, y + 6, z + 9, Blocks.bedrock, 0, 3);
        world.setBlock(x + 8, y + 6, z + 9, Blocks.bedrock, 0, 3);
        world.setBlock(x + 9, y + 6, z + 9, Blocks.bedrock, 0, 3);
        world.setBlock(x + 10, y + 6, z + 9, Blocks.bedrock, 0, 3);
        world.setBlock(x + 0, y + 7, z + 0, Blocks.bedrock, 0, 3);
        world.setBlock(x + 1, y + 7, z + 0, Blocks.bedrock, 0, 3);
        world.setBlock(x + 2, y + 7, z + 0, Blocks.bedrock, 0, 3);
        world.setBlock(x + 3, y + 7, z + 0, Blocks.bedrock, 0, 3);
        world.setBlock(x + 4, y + 7, z + 0, Blocks.bedrock, 0, 3);
        world.setBlock(x + 5, y + 7, z + 0, Blocks.bedrock, 0, 3);
        world.setBlock(x + 6, y + 7, z + 0, Blocks.bedrock, 0, 3);
        world.setBlock(x + 7, y + 7, z + 0, Blocks.bedrock, 0, 3);
        world.setBlock(x + 8, y + 7, z + 0, Blocks.bedrock, 0, 3);
        world.setBlock(x + 9, y + 7, z + 0, Blocks.bedrock, 0, 3);
        world.setBlock(x + 10, y + 7, z + 0, Blocks.bedrock, 0, 3);
        world.setBlock(x + 0, y + 7, z + 1, Blocks.bedrock, 0, 3);
        world.setBlock(x + 1, y + 7, z + 1, Blocks.stonebrick, 0, 3);
        world.setBlock(x + 2, y + 7, z + 1, Blocks.stonebrick, 0, 3);
        world.setBlock(x + 3, y + 7, z + 1, Blocks.stonebrick, 0, 3);
        world.setBlock(x + 4, y + 7, z + 1, Blocks.stonebrick, 0, 3);
        world.setBlock(x + 5, y + 7, z + 1, Blocks.stonebrick, 0, 3);
        world.setBlock(x + 6, y + 7, z + 1, Blocks.stonebrick, 0, 3);
        world.setBlock(x + 7, y + 7, z + 1, Blocks.stonebrick, 0, 3);
        world.setBlock(x + 8, y + 7, z + 1, Blocks.stonebrick, 0, 3);
        world.setBlock(x + 9, y + 7, z + 1, Blocks.stonebrick, 0, 3);
        world.setBlock(x + 10, y + 7, z + 1, Blocks.bedrock, 0, 3);
        world.setBlock(x + 0, y + 7, z + 2, Blocks.bedrock, 0, 3);
        world.setBlock(x + 1, y + 7, z + 2, Blocks.stonebrick, 0, 3);
        world.setBlock(x + 2, y + 7, z + 2, Blocks.stonebrick, 0, 3);
        world.setBlock(x + 3, y + 7, z + 2, Blocks.stonebrick, 0, 3);
        world.setBlock(x + 4, y + 7, z + 2, Blocks.stonebrick, 0, 3);
        world.setBlock(x + 5, y + 7, z + 2, Blocks.stonebrick, 0, 3);
        world.setBlock(x + 6, y + 7, z + 2, Blocks.stonebrick, 0, 3);
        world.setBlock(x + 7, y + 7, z + 2, Blocks.stonebrick, 0, 3);
        world.setBlock(x + 8, y + 7, z + 2, Blocks.stonebrick, 0, 3);
        world.setBlock(x + 9, y + 7, z + 2, Blocks.stonebrick, 0, 3);
        world.setBlock(x + 10, y + 7, z + 2, Blocks.bedrock, 0, 3);
        world.setBlock(x + 0, y + 7, z + 3, Blocks.bedrock, 0, 3);
        world.setBlock(x + 1, y + 7, z + 3, Blocks.stonebrick, 0, 3);
        world.setBlock(x + 2, y + 7, z + 3, Blocks.stonebrick, 0, 3);
        world.setBlock(x + 3, y + 7, z + 3, Blocks.stonebrick, 0, 3);
        world.setBlock(x + 4, y + 7, z + 3, Blocks.stonebrick, 0, 3);
        world.setBlock(x + 5, y + 7, z + 3, Blocks.stonebrick, 0, 3);
        world.setBlock(x + 6, y + 7, z + 3, Blocks.stonebrick, 0, 3);
        world.setBlock(x + 7, y + 7, z + 3, Blocks.stonebrick, 0, 3);
        world.setBlock(x + 8, y + 7, z + 3, Blocks.stonebrick, 0, 3);
        world.setBlock(x + 9, y + 7, z + 3, Blocks.stonebrick, 0, 3);
        world.setBlock(x + 10, y + 7, z + 3, Blocks.bedrock, 0, 3);
        world.setBlock(x + 0, y + 7, z + 4, Blocks.bedrock, 0, 3);
        world.setBlock(x + 1, y + 7, z + 4, Blocks.stonebrick, 0, 3);
        world.setBlock(x + 2, y + 7, z + 4, Blocks.stonebrick, 0, 3);
        world.setBlock(x + 3, y + 7, z + 4, Blocks.stonebrick, 0, 3);
        world.setBlock(x + 4, y + 7, z + 4, Blocks.stonebrick, 0, 3);
        world.setBlock(x + 5, y + 7, z + 4, Blocks.stonebrick, 0, 3);
        world.setBlock(x + 6, y + 7, z + 4, Blocks.stonebrick, 0, 3);
        world.setBlock(x + 7, y + 7, z + 4, Blocks.stonebrick, 0, 3);
        world.setBlock(x + 8, y + 7, z + 4, Blocks.stonebrick, 0, 3);
        world.setBlock(x + 9, y + 7, z + 4, Blocks.stonebrick, 0, 3);
        world.setBlock(x + 10, y + 7, z + 4, Blocks.bedrock, 0, 3);
        world.setBlock(x + 0, y + 7, z + 5, Blocks.bedrock, 0, 3);
        world.setBlock(x + 1, y + 7, z + 5, Blocks.stonebrick, 0, 3);
        world.setBlock(x + 2, y + 7, z + 5, Blocks.stonebrick, 0, 3);
        world.setBlock(x + 3, y + 7, z + 5, Blocks.stonebrick, 0, 3);
        world.setBlock(x + 4, y + 7, z + 5, Blocks.stonebrick, 0, 3);
        world.setBlock(x + 5, y + 7, z + 5, Blocks.stonebrick, 0, 3);
        world.setBlock(x + 6, y + 7, z + 5, Blocks.stonebrick, 0, 3);
        world.setBlock(x + 7, y + 7, z + 5, Blocks.stonebrick, 0, 3);
        world.setBlock(x + 8, y + 7, z + 5, Blocks.stonebrick, 0, 3);
        world.setBlock(x + 9, y + 7, z + 5, Blocks.stonebrick, 0, 3);
        world.setBlock(x + 10, y + 7, z + 5, Blocks.bedrock, 0, 3);
        world.setBlock(x + 0, y + 7, z + 6, Blocks.bedrock, 0, 3);
        world.setBlock(x + 1, y + 7, z + 6, Blocks.stonebrick, 0, 3);
        world.setBlock(x + 2, y + 7, z + 6, Blocks.stonebrick, 0, 3);
        world.setBlock(x + 3, y + 7, z + 6, Blocks.stonebrick, 0, 3);
        world.setBlock(x + 4, y + 7, z + 6, Blocks.stonebrick, 0, 3);
        world.setBlock(x + 5, y + 7, z + 6, Blocks.stonebrick, 0, 3);
        world.setBlock(x + 6, y + 7, z + 6, Blocks.stonebrick, 0, 3);
        world.setBlock(x + 7, y + 7, z + 6, Blocks.stonebrick, 0, 3);
        world.setBlock(x + 8, y + 7, z + 6, Blocks.stonebrick, 0, 3);
        world.setBlock(x + 9, y + 7, z + 6, Blocks.stonebrick, 0, 3);
        world.setBlock(x + 10, y + 7, z + 6, Blocks.bedrock, 0, 3);
        world.setBlock(x + 0, y + 7, z + 7, Blocks.bedrock, 0, 3);
        world.setBlock(x + 1, y + 7, z + 7, Blocks.stonebrick, 0, 3);
        world.setBlock(x + 2, y + 7, z + 7, Blocks.stonebrick, 0, 3);
        world.setBlock(x + 3, y + 7, z + 7, Blocks.stonebrick, 0, 3);
        world.setBlock(x + 4, y + 7, z + 7, Blocks.stonebrick, 0, 3);
        world.setBlock(x + 5, y + 7, z + 7, Blocks.stonebrick, 0, 3);
        world.setBlock(x + 6, y + 7, z + 7, Blocks.stonebrick, 0, 3);
        world.setBlock(x + 7, y + 7, z + 7, Blocks.stonebrick, 0, 3);
        world.setBlock(x + 8, y + 7, z + 7, Blocks.stonebrick, 0, 3);
        world.setBlock(x + 9, y + 7, z + 7, Blocks.stonebrick, 0, 3);
        world.setBlock(x + 10, y + 7, z + 7, Blocks.bedrock, 0, 3);
        world.setBlock(x + 0, y + 7, z + 8, Blocks.bedrock, 0, 3);
        world.setBlock(x + 1, y + 7, z + 8, Blocks.stonebrick, 0, 3);
        world.setBlock(x + 2, y + 7, z + 8, Blocks.stonebrick, 0, 3);
        world.setBlock(x + 3, y + 7, z + 8, Blocks.stonebrick, 0, 3);
        world.setBlock(x + 4, y + 7, z + 8, Blocks.stonebrick, 0, 3);
        world.setBlock(x + 5, y + 7, z + 8, Blocks.stonebrick, 0, 3);
        world.setBlock(x + 6, y + 7, z + 8, Blocks.stonebrick, 0, 3);
        world.setBlock(x + 7, y + 7, z + 8, Blocks.stonebrick, 0, 3);
        world.setBlock(x + 8, y + 7, z + 8, Blocks.stonebrick, 0, 3);
        world.setBlock(x + 9, y + 7, z + 8, Blocks.stonebrick, 0, 3);
        world.setBlock(x + 10, y + 7, z + 8, Blocks.bedrock, 0, 3);
        world.setBlock(x + 0, y + 7, z + 9, Blocks.bedrock, 0, 3);
        world.setBlock(x + 1, y + 7, z + 9, Blocks.bedrock, 0, 3);
        world.setBlock(x + 2, y + 7, z + 9, Blocks.bedrock, 0, 3);
        world.setBlock(x + 3, y + 7, z + 9, Blocks.bedrock, 0, 3);
        world.setBlock(x + 4, y + 7, z + 9, Blocks.bedrock, 0, 3);
        world.setBlock(x + 5, y + 7, z + 9, Blocks.bedrock, 0, 3);
        world.setBlock(x + 6, y + 7, z + 9, Blocks.bedrock, 0, 3);
        world.setBlock(x + 7, y + 7, z + 9, Blocks.bedrock, 0, 3);
        world.setBlock(x + 8, y + 7, z + 9, Blocks.bedrock, 0, 3);
        world.setBlock(x + 9, y + 7, z + 9, Blocks.bedrock, 0, 3);
        world.setBlock(x + 10, y + 7, z + 9, Blocks.bedrock, 0, 3);
        world.setBlock(x + 0, y + 8, z + 0, Blocks.bedrock, 0, 3);
        world.setBlock(x + 1, y + 8, z + 0, Blocks.bedrock, 0, 3);
        world.setBlock(x + 2, y + 8, z + 0, Blocks.bedrock, 0, 3);
        world.setBlock(x + 3, y + 8, z + 0, Blocks.bedrock, 0, 3);
        world.setBlock(x + 4, y + 8, z + 0, Blocks.bedrock, 0, 3);
        world.setBlock(x + 5, y + 8, z + 0, Blocks.bedrock, 0, 3);
        world.setBlock(x + 6, y + 8, z + 0, Blocks.bedrock, 0, 3);
        world.setBlock(x + 7, y + 8, z + 0, Blocks.bedrock, 0, 3);
        world.setBlock(x + 8, y + 8, z + 0, Blocks.bedrock, 0, 3);
        world.setBlock(x + 9, y + 8, z + 0, Blocks.bedrock, 0, 3);
        world.setBlock(x + 10, y + 8, z + 0, Blocks.bedrock, 0, 3);
        world.setBlock(x + 0, y + 8, z + 1, Blocks.bedrock, 0, 3);
        world.setBlock(x + 1, y + 8, z + 1, Blocks.bedrock, 0, 3);
        world.setBlock(x + 2, y + 8, z + 1, Blocks.bedrock, 0, 3);
        world.setBlock(x + 3, y + 8, z + 1, Blocks.bedrock, 0, 3);
        world.setBlock(x + 4, y + 8, z + 1, Blocks.bedrock, 0, 3);
        world.setBlock(x + 5, y + 8, z + 1, Blocks.bedrock, 0, 3);
        world.setBlock(x + 6, y + 8, z + 1, Blocks.bedrock, 0, 3);
        world.setBlock(x + 7, y + 8, z + 1, Blocks.bedrock, 0, 3);
        world.setBlock(x + 8, y + 8, z + 1, Blocks.bedrock, 0, 3);
        world.setBlock(x + 9, y + 8, z + 1, Blocks.bedrock, 0, 3);
        world.setBlock(x + 10, y + 8, z + 1, Blocks.bedrock, 0, 3);
        world.setBlock(x + 0, y + 8, z + 2, Blocks.bedrock, 0, 3);
        world.setBlock(x + 1, y + 8, z + 2, Blocks.bedrock, 0, 3);
        world.setBlock(x + 2, y + 8, z + 2, Blocks.bedrock, 0, 3);
        world.setBlock(x + 3, y + 8, z + 2, Blocks.bedrock, 0, 3);
        world.setBlock(x + 4, y + 8, z + 2, Blocks.bedrock, 0, 3);
        world.setBlock(x + 5, y + 8, z + 2, Blocks.bedrock, 0, 3);
        world.setBlock(x + 6, y + 8, z + 2, Blocks.bedrock, 0, 3);
        world.setBlock(x + 7, y + 8, z + 2, Blocks.bedrock, 0, 3);
        world.setBlock(x + 8, y + 8, z + 2, Blocks.bedrock, 0, 3);
        world.setBlock(x + 9, y + 8, z + 2, Blocks.bedrock, 0, 3);
        world.setBlock(x + 10, y + 8, z + 2, Blocks.bedrock, 0, 3);
        world.setBlock(x + 0, y + 8, z + 3, Blocks.bedrock, 0, 3);
        world.setBlock(x + 1, y + 8, z + 3, Blocks.bedrock, 0, 3);
        world.setBlock(x + 2, y + 8, z + 3, Blocks.bedrock, 0, 3);
        world.setBlock(x + 3, y + 8, z + 3, Blocks.bedrock, 0, 3);
        world.setBlock(x + 4, y + 8, z + 3, Blocks.bedrock, 0, 3);
        world.setBlock(x + 5, y + 8, z + 3, Blocks.bedrock, 0, 3);
        world.setBlock(x + 6, y + 8, z + 3, Blocks.bedrock, 0, 3);
        world.setBlock(x + 7, y + 8, z + 3, Blocks.bedrock, 0, 3);
        world.setBlock(x + 8, y + 8, z + 3, Blocks.bedrock, 0, 3);
        world.setBlock(x + 9, y + 8, z + 3, Blocks.bedrock, 0, 3);
        world.setBlock(x + 10, y + 8, z + 3, Blocks.bedrock, 0, 3);
        world.setBlock(x + 0, y + 8, z + 4, Blocks.bedrock, 0, 3);
        world.setBlock(x + 1, y + 8, z + 4, Blocks.bedrock, 0, 3);
        world.setBlock(x + 2, y + 8, z + 4, Blocks.bedrock, 0, 3);
        world.setBlock(x + 3, y + 8, z + 4, Blocks.bedrock, 0, 3);
        world.setBlock(x + 4, y + 8, z + 4, Blocks.bedrock, 0, 3);
        world.setBlock(x + 5, y + 8, z + 4, Blocks.bedrock, 0, 3);
        world.setBlock(x + 6, y + 8, z + 4, Blocks.bedrock, 0, 3);
        world.setBlock(x + 7, y + 8, z + 4, Blocks.bedrock, 0, 3);
        world.setBlock(x + 8, y + 8, z + 4, Blocks.bedrock, 0, 3);
        world.setBlock(x + 9, y + 8, z + 4, Blocks.bedrock, 0, 3);
        world.setBlock(x + 10, y + 8, z + 4, Blocks.bedrock, 0, 3);
        world.setBlock(x + 0, y + 8, z + 5, Blocks.bedrock, 0, 3);
        world.setBlock(x + 1, y + 8, z + 5, Blocks.bedrock, 0, 3);
        world.setBlock(x + 2, y + 8, z + 5, Blocks.bedrock, 0, 3);
        world.setBlock(x + 3, y + 8, z + 5, Blocks.bedrock, 0, 3);
        world.setBlock(x + 4, y + 8, z + 5, Blocks.bedrock, 0, 3);
        world.setBlock(x + 5, y + 8, z + 5, Blocks.bedrock, 0, 3);
        world.setBlock(x + 6, y + 8, z + 5, Blocks.bedrock, 0, 3);
        world.setBlock(x + 7, y + 8, z + 5, Blocks.bedrock, 0, 3);
        world.setBlock(x + 8, y + 8, z + 5, Blocks.bedrock, 0, 3);
        world.setBlock(x + 9, y + 8, z + 5, Blocks.bedrock, 0, 3);
        world.setBlock(x + 10, y + 8, z + 5, Blocks.bedrock, 0, 3);
        world.setBlock(x + 0, y + 8, z + 6, Blocks.bedrock, 0, 3);
        world.setBlock(x + 1, y + 8, z + 6, Blocks.bedrock, 0, 3);
        world.setBlock(x + 2, y + 8, z + 6, Blocks.bedrock, 0, 3);
        world.setBlock(x + 3, y + 8, z + 6, Blocks.bedrock, 0, 3);
        world.setBlock(x + 4, y + 8, z + 6, Blocks.bedrock, 0, 3);
        world.setBlock(x + 5, y + 8, z + 6, Blocks.bedrock, 0, 3);
        world.setBlock(x + 6, y + 8, z + 6, Blocks.bedrock, 0, 3);
        world.setBlock(x + 7, y + 8, z + 6, Blocks.bedrock, 0, 3);
        world.setBlock(x + 8, y + 8, z + 6, Blocks.bedrock, 0, 3);
        world.setBlock(x + 9, y + 8, z + 6, Blocks.bedrock, 0, 3);
        world.setBlock(x + 10, y + 8, z + 6, Blocks.bedrock, 0, 3);
        world.setBlock(x + 0, y + 8, z + 7, Blocks.bedrock, 0, 3);
        world.setBlock(x + 1, y + 8, z + 7, Blocks.bedrock, 0, 3);
        world.setBlock(x + 2, y + 8, z + 7, Blocks.bedrock, 0, 3);
        world.setBlock(x + 3, y + 8, z + 7, Blocks.bedrock, 0, 3);
        world.setBlock(x + 4, y + 8, z + 7, Blocks.bedrock, 0, 3);
        world.setBlock(x + 5, y + 8, z + 7, Blocks.bedrock, 0, 3);
        world.setBlock(x + 6, y + 8, z + 7, Blocks.bedrock, 0, 3);
        world.setBlock(x + 7, y + 8, z + 7, Blocks.bedrock, 0, 3);
        world.setBlock(x + 8, y + 8, z + 7, Blocks.bedrock, 0, 3);
        world.setBlock(x + 9, y + 8, z + 7, Blocks.bedrock, 0, 3);
        world.setBlock(x + 10, y + 8, z + 7, Blocks.bedrock, 0, 3);
        world.setBlock(x + 0, y + 8, z + 8, Blocks.bedrock, 0, 3);
        world.setBlock(x + 1, y + 8, z + 8, Blocks.bedrock, 0, 3);
        world.setBlock(x + 2, y + 8, z + 8, Blocks.bedrock, 0, 3);
        world.setBlock(x + 3, y + 8, z + 8, Blocks.bedrock, 0, 3);
        world.setBlock(x + 4, y + 8, z + 8, Blocks.bedrock, 0, 3);
        world.setBlock(x + 5, y + 8, z + 8, Blocks.bedrock, 0, 3);
        world.setBlock(x + 6, y + 8, z + 8, Blocks.bedrock, 0, 3);
        world.setBlock(x + 7, y + 8, z + 8, Blocks.bedrock, 0, 3);
        world.setBlock(x + 8, y + 8, z + 8, Blocks.bedrock, 0, 3);
        world.setBlock(x + 9, y + 8, z + 8, Blocks.bedrock, 0, 3);
        world.setBlock(x + 10, y + 8, z + 8, Blocks.bedrock, 0, 3);
        world.setBlock(x + 0, y + 8, z + 9, Blocks.bedrock, 0, 3);
        world.setBlock(x + 1, y + 8, z + 9, Blocks.bedrock, 0, 3);
        world.setBlock(x + 2, y + 8, z + 9, Blocks.bedrock, 0, 3);
        world.setBlock(x + 3, y + 8, z + 9, Blocks.bedrock, 0, 3);
        world.setBlock(x + 4, y + 8, z + 9, Blocks.bedrock, 0, 3);
        world.setBlock(x + 5, y + 8, z + 9, Blocks.bedrock, 0, 3);
        world.setBlock(x + 6, y + 8, z + 9, Blocks.bedrock, 0, 3);
        world.setBlock(x + 7, y + 8, z + 9, Blocks.bedrock, 0, 3);
        world.setBlock(x + 8, y + 8, z + 9, Blocks.bedrock, 0, 3);
        world.setBlock(x + 9, y + 8, z + 9, Blocks.bedrock, 0, 3);
        world.setBlock(x + 10, y + 8, z + 9, Blocks.bedrock, 0, 3);

        generate_r02_last(world, rand, x, y, z);
        return true;

    }

    public boolean generate_r02_last(World world, Random rand, int x, int y, int z)
    {

        world.setBlock(x + 3, y + 2, z + 2, Blocks.redstone_torch, 3, 3);
        world.setBlock(x + 7, y + 2, z + 2, Blocks.redstone_torch, 3, 3);
        world.setBlock(x + 2, y + 2, z + 3, Blocks.redstone_torch, 1, 3);
        world.setBlock(x + 8, y + 2, z + 3, Blocks.redstone_torch, 2, 3);
        world.setBlock(x + 2, y + 2, z + 6, Blocks.redstone_torch, 1, 3);
        world.setBlock(x + 8, y + 2, z + 6, Blocks.redstone_torch, 2, 3);
        world.setBlock(x + 3, y + 2, z + 7, Blocks.redstone_torch, 4, 3);
        world.setBlock(x + 7, y + 2, z + 7, Blocks.redstone_torch, 4, 3);
        return true;

    }

}