package fossilsarcheology.server.gen.feature;

import fossilsarcheology.server.block.FABlockRegistry;
import net.minecraft.init.Blocks;
import net.minecraft.world.World;
import net.minecraft.world.gen.feature.WorldGenerator;

import java.util.Random;

public class AncientChestWorldGen extends WorldGenerator {

    @Override
    public boolean generate(World world, Random rand, BlockPos pos) {
        world.setBlock(x, y + -2, z, Blocks.bedrock, 0, 3);
        world.setBlock(x + 1, y + -2, z, Blocks.bedrock, 0, 3);
        world.setBlock(x + 2, y + -2, z, Blocks.bedrock, 0, 3);
        world.setBlock(x + 3, y + -2, z, Blocks.bedrock, 0, 3);
        world.setBlock(x + 4, y + -2, z, Blocks.bedrock, 0, 3);
        world.setBlock(x + 5, y + -2, z, Blocks.bedrock, 0, 3);
        world.setBlock(x + 6, y + -2, z, Blocks.bedrock, 0, 3);
        world.setBlock(x + 7, y + -2, z, Blocks.bedrock, 0, 3);
        world.setBlock(x + 8, y + -2, z, Blocks.bedrock, 0, 3);
        world.setBlock(x + 9, y + -2, z, Blocks.bedrock, 0, 3);
        world.setBlock(x + 10, y + -2, z, Blocks.bedrock, 0, 3);
        world.setBlock(x, y + -2, z + 1, Blocks.bedrock, 0, 3);
        world.setBlock(x + 1, y + -2, z + 1, Blocks.bedrock, 0, 3);
        world.setBlock(x + 2, y + -2, z + 1, Blocks.bedrock, 0, 3);
        world.setBlock(x + 3, y + -2, z + 1, Blocks.bedrock, 0, 3);
        world.setBlock(x + 4, y + -2, z + 1, Blocks.bedrock, 0, 3);
        world.setBlock(x + 5, y + -2, z + 1, Blocks.bedrock, 0, 3);
        world.setBlock(x + 6, y + -2, z + 1, Blocks.bedrock, 0, 3);
        world.setBlock(x + 7, y + -2, z + 1, Blocks.bedrock, 0, 3);
        world.setBlock(x + 8, y + -2, z + 1, Blocks.bedrock, 0, 3);
        world.setBlock(x + 9, y + -2, z + 1, Blocks.bedrock, 0, 3);
        world.setBlock(x + 10, y + -2, z + 1, Blocks.bedrock, 0, 3);
        world.setBlock(x, y + -2, z + 2, Blocks.bedrock, 0, 3);
        world.setBlock(x + 1, y + -2, z + 2, Blocks.bedrock, 0, 3);
        world.setBlock(x + 2, y + -2, z + 2, Blocks.bedrock, 0, 3);
        world.setBlock(x + 3, y + -2, z + 2, Blocks.bedrock, 0, 3);
        world.setBlock(x + 4, y + -2, z + 2, Blocks.bedrock, 0, 3);
        world.setBlock(x + 5, y + -2, z + 2, Blocks.bedrock, 0, 3);
        world.setBlock(x + 6, y + -2, z + 2, Blocks.bedrock, 0, 3);
        world.setBlock(x + 7, y + -2, z + 2, Blocks.bedrock, 0, 3);
        world.setBlock(x + 8, y + -2, z + 2, Blocks.bedrock, 0, 3);
        world.setBlock(x + 9, y + -2, z + 2, Blocks.bedrock, 0, 3);
        world.setBlock(x + 10, y + -2, z + 2, Blocks.bedrock, 0, 3);
        world.setBlock(x, y + -2, z + 3, Blocks.bedrock, 0, 3);
        world.setBlock(x + 1, y + -2, z + 3, Blocks.bedrock, 0, 3);
        world.setBlock(x + 2, y + -2, z + 3, Blocks.bedrock, 0, 3);
        world.setBlock(x + 3, y + -2, z + 3, Blocks.bedrock, 0, 3);
        world.setBlock(x + 4, y + -2, z + 3, Blocks.bedrock, 0, 3);
        world.setBlock(x + 5, y + -2, z + 3, Blocks.bedrock, 0, 3);
        world.setBlock(x + 6, y + -2, z + 3, Blocks.bedrock, 0, 3);
        world.setBlock(x + 7, y + -2, z + 3, Blocks.bedrock, 0, 3);
        world.setBlock(x + 8, y + -2, z + 3, Blocks.bedrock, 0, 3);
        world.setBlock(x + 9, y + -2, z + 3, Blocks.bedrock, 0, 3);
        world.setBlock(x + 10, y + -2, z + 3, Blocks.bedrock, 0, 3);
        world.setBlock(x, y + -2, z + 4, Blocks.bedrock, 0, 3);
        world.setBlock(x + 1, y + -2, z + 4, Blocks.bedrock, 0, 3);
        world.setBlock(x + 2, y + -2, z + 4, Blocks.bedrock, 0, 3);
        world.setBlock(x + 3, y + -2, z + 4, Blocks.bedrock, 0, 3);
        world.setBlock(x + 4, y + -2, z + 4, Blocks.bedrock, 0, 3);
        world.setBlock(x + 5, y + -2, z + 4, Blocks.bedrock, 0, 3);
        world.setBlock(x + 6, y + -2, z + 4, Blocks.bedrock, 0, 3);
        world.setBlock(x + 7, y + -2, z + 4, Blocks.bedrock, 0, 3);
        world.setBlock(x + 8, y + -2, z + 4, Blocks.bedrock, 0, 3);
        world.setBlock(x + 9, y + -2, z + 4, Blocks.bedrock, 0, 3);
        world.setBlock(x + 10, y + -2, z + 4, Blocks.bedrock, 0, 3);
        world.setBlock(x, y + -2, z + 5, Blocks.bedrock, 0, 3);
        world.setBlock(x + 1, y + -2, z + 5, Blocks.bedrock, 0, 3);
        world.setBlock(x + 2, y + -2, z + 5, Blocks.bedrock, 0, 3);
        world.setBlock(x + 3, y + -2, z + 5, Blocks.bedrock, 0, 3);
        world.setBlock(x + 4, y + -2, z + 5, Blocks.bedrock, 0, 3);
        world.setBlock(x + 5, y + -2, z + 5, Blocks.bedrock, 0, 3);
        world.setBlock(x + 6, y + -2, z + 5, Blocks.bedrock, 0, 3);
        world.setBlock(x + 7, y + -2, z + 5, Blocks.bedrock, 0, 3);
        world.setBlock(x + 8, y + -2, z + 5, Blocks.bedrock, 0, 3);
        world.setBlock(x + 9, y + -2, z + 5, Blocks.bedrock, 0, 3);
        world.setBlock(x + 10, y + -2, z + 5, Blocks.bedrock, 0, 3);
        world.setBlock(x, y + -2, z + 6, Blocks.bedrock, 0, 3);
        world.setBlock(x + 1, y + -2, z + 6, Blocks.bedrock, 0, 3);
        world.setBlock(x + 2, y + -2, z + 6, Blocks.bedrock, 0, 3);
        world.setBlock(x + 3, y + -2, z + 6, Blocks.bedrock, 0, 3);
        world.setBlock(x + 4, y + -2, z + 6, Blocks.bedrock, 0, 3);
        world.setBlock(x + 5, y + -2, z + 6, Blocks.bedrock, 0, 3);
        world.setBlock(x + 6, y + -2, z + 6, Blocks.bedrock, 0, 3);
        world.setBlock(x + 7, y + -2, z + 6, Blocks.bedrock, 0, 3);
        world.setBlock(x + 8, y + -2, z + 6, Blocks.bedrock, 0, 3);
        world.setBlock(x + 9, y + -2, z + 6, Blocks.bedrock, 0, 3);
        world.setBlock(x + 10, y + -2, z + 6, Blocks.bedrock, 0, 3);
        world.setBlock(x, y + -2, z + 7, Blocks.bedrock, 0, 3);
        world.setBlock(x + 1, y + -2, z + 7, Blocks.bedrock, 0, 3);
        world.setBlock(x + 2, y + -2, z + 7, Blocks.bedrock, 0, 3);
        world.setBlock(x + 3, y + -2, z + 7, Blocks.bedrock, 0, 3);
        world.setBlock(x + 4, y + -2, z + 7, Blocks.bedrock, 0, 3);
        world.setBlock(x + 5, y + -2, z + 7, Blocks.bedrock, 0, 3);
        world.setBlock(x + 6, y + -2, z + 7, Blocks.bedrock, 0, 3);
        world.setBlock(x + 7, y + -2, z + 7, Blocks.bedrock, 0, 3);
        world.setBlock(x + 8, y + -2, z + 7, Blocks.bedrock, 0, 3);
        world.setBlock(x + 9, y + -2, z + 7, Blocks.bedrock, 0, 3);
        world.setBlock(x + 10, y + -2, z + 7, Blocks.bedrock, 0, 3);
        world.setBlock(x, y + -2, z + 8, Blocks.bedrock, 0, 3);
        world.setBlock(x + 1, y + -2, z + 8, Blocks.bedrock, 0, 3);
        world.setBlock(x + 2, y + -2, z + 8, Blocks.bedrock, 0, 3);
        world.setBlock(x + 3, y + -2, z + 8, Blocks.bedrock, 0, 3);
        world.setBlock(x + 4, y + -2, z + 8, Blocks.bedrock, 0, 3);
        world.setBlock(x + 5, y + -2, z + 8, Blocks.bedrock, 0, 3);
        world.setBlock(x + 6, y + -2, z + 8, Blocks.bedrock, 0, 3);
        world.setBlock(x + 7, y + -2, z + 8, Blocks.bedrock, 0, 3);
        world.setBlock(x + 8, y + -2, z + 8, Blocks.bedrock, 0, 3);
        world.setBlock(x + 9, y + -2, z + 8, Blocks.bedrock, 0, 3);
        world.setBlock(x + 10, y + -2, z + 8, Blocks.bedrock, 0, 3);
        world.setBlock(x, y + -2, z + 9, Blocks.bedrock, 0, 3);
        world.setBlock(x + 1, y + -2, z + 9, Blocks.bedrock, 0, 3);
        world.setBlock(x + 2, y + -2, z + 9, Blocks.bedrock, 0, 3);
        world.setBlock(x + 3, y + -2, z + 9, Blocks.bedrock, 0, 3);
        world.setBlock(x + 4, y + -2, z + 9, Blocks.bedrock, 0, 3);
        world.setBlock(x + 5, y + -2, z + 9, Blocks.bedrock, 0, 3);
        world.setBlock(x + 6, y + -2, z + 9, Blocks.bedrock, 0, 3);
        world.setBlock(x + 7, y + -2, z + 9, Blocks.bedrock, 0, 3);
        world.setBlock(x + 8, y + -2, z + 9, Blocks.bedrock, 0, 3);
        world.setBlock(x + 9, y + -2, z + 9, Blocks.bedrock, 0, 3);
        world.setBlock(x + 10, y + -2, z + 9, Blocks.bedrock, 0, 3);
        world.setBlock(x, y + -1, z, Blocks.bedrock, 0, 3);
        world.setBlock(x + 1, y + -1, z, Blocks.bedrock, 0, 3);
        world.setBlock(x + 2, y + -1, z, Blocks.bedrock, 0, 3);
        world.setBlock(x + 3, y + -1, z, Blocks.bedrock, 0, 3);
        world.setBlock(x + 4, y + -1, z, Blocks.bedrock, 0, 3);
        world.setBlock(x + 5, y + -1, z, Blocks.bedrock, 0, 3);
        world.setBlock(x + 6, y + -1, z, Blocks.bedrock, 0, 3);
        world.setBlock(x + 7, y + -1, z, Blocks.bedrock, 0, 3);
        world.setBlock(x + 8, y + -1, z, Blocks.bedrock, 0, 3);
        world.setBlock(x + 9, y + -1, z, Blocks.bedrock, 0, 3);
        world.setBlock(x + 10, y + -1, z, Blocks.bedrock, 0, 3);
        world.setBlock(x, y + -1, z + 1, Blocks.bedrock, 0, 3);
        world.setBlock(x + 1, y + -1, z + 1, Blocks.stonebrick, 0, 3);
        world.setBlock(x + 2, y + -1, z + 1, Blocks.stonebrick, 0, 3);
        world.setBlock(x + 3, y + -1, z + 1, Blocks.stonebrick, 0, 3);
        world.setBlock(x + 4, y + -1, z + 1, Blocks.stonebrick, 0, 3);
        world.setBlock(x + 5, y + -1, z + 1, Blocks.stonebrick, 0, 3);
        world.setBlock(x + 6, y + -1, z + 1, Blocks.stonebrick, 0, 3);
        world.setBlock(x + 7, y + -1, z + 1, Blocks.stonebrick, 0, 3);
        world.setBlock(x + 8, y + -1, z + 1, Blocks.stonebrick, 0, 3);
        world.setBlock(x + 9, y + -1, z + 1, Blocks.stonebrick, 0, 3);
        world.setBlock(x + 10, y + -1, z + 1, Blocks.bedrock, 0, 3);
        world.setBlock(x, y + -1, z + 2, Blocks.bedrock, 0, 3);
        world.setBlock(x + 1, y + -1, z + 2, Blocks.stonebrick, 0, 3);
        world.setBlock(x + 2, y + -1, z + 2, Blocks.stonebrick, 0, 3);
        world.setBlock(x + 3, y + -1, z + 2, Blocks.stonebrick, 0, 3);
        world.setBlock(x + 4, y + -1, z + 2, Blocks.stonebrick, 0, 3);
        world.setBlock(x + 5, y + -1, z + 2, Blocks.stonebrick, 0, 3);
        world.setBlock(x + 6, y + -1, z + 2, Blocks.stonebrick, 0, 3);
        world.setBlock(x + 7, y + -1, z + 2, Blocks.stonebrick, 0, 3);
        world.setBlock(x + 8, y + -1, z + 2, Blocks.stonebrick, 0, 3);
        world.setBlock(x + 9, y + -1, z + 2, Blocks.stonebrick, 0, 3);
        world.setBlock(x + 10, y + -1, z + 2, Blocks.bedrock, 0, 3);
        world.setBlock(x, y + -1, z + 3, Blocks.bedrock, 0, 3);
        world.setBlock(x + 1, y + -1, z + 3, Blocks.stonebrick, 0, 3);
        world.setBlock(x + 2, y + -1, z + 3, Blocks.stonebrick, 0, 3);
        world.setBlock(x + 3, y + -1, z + 3, Blocks.stonebrick, 0, 3);
        world.setBlock(x + 4, y + -1, z + 3, Blocks.stonebrick, 0, 3);
        world.setBlock(x + 5, y + -1, z + 3, Blocks.stonebrick, 0, 3);
        world.setBlock(x + 6, y + -1, z + 3, Blocks.stonebrick, 0, 3);
        world.setBlock(x + 7, y + -1, z + 3, Blocks.stonebrick, 0, 3);
        world.setBlock(x + 8, y + -1, z + 3, Blocks.stonebrick, 0, 3);
        world.setBlock(x + 9, y + -1, z + 3, Blocks.stonebrick, 0, 3);
        world.setBlock(x + 10, y + -1, z + 3, Blocks.bedrock, 0, 3);
        world.setBlock(x, y + -1, z + 4, Blocks.bedrock, 0, 3);
        world.setBlock(x + 1, y + -1, z + 4, Blocks.stonebrick, 0, 3);
        world.setBlock(x + 2, y + -1, z + 4, Blocks.stonebrick, 0, 3);
        world.setBlock(x + 3, y + -1, z + 4, Blocks.stonebrick, 0, 3);
        world.setBlock(x + 4, y + -1, z + 4, Blocks.stonebrick, 0, 3);
        world.setBlock(x + 5, y + -1, z + 4, Blocks.stonebrick, 0, 3);
        world.setBlock(x + 6, y + -1, z + 4, Blocks.stonebrick, 0, 3);
        world.setBlock(x + 7, y + -1, z + 4, Blocks.stonebrick, 0, 3);
        world.setBlock(x + 8, y + -1, z + 4, Blocks.stonebrick, 0, 3);
        world.setBlock(x + 9, y + -1, z + 4, Blocks.stonebrick, 0, 3);
        world.setBlock(x + 10, y + -1, z + 4, Blocks.bedrock, 0, 3);
        world.setBlock(x, y + -1, z + 5, Blocks.bedrock, 0, 3);
        world.setBlock(x + 1, y + -1, z + 5, Blocks.stonebrick, 0, 3);
        world.setBlock(x + 2, y + -1, z + 5, Blocks.stonebrick, 0, 3);
        world.setBlock(x + 3, y + -1, z + 5, Blocks.stonebrick, 0, 3);
        world.setBlock(x + 4, y + -1, z + 5, Blocks.stonebrick, 0, 3);
        world.setBlock(x + 5, y + -1, z + 5, Blocks.stonebrick, 0, 3);
        world.setBlock(x + 6, y + -1, z + 5, Blocks.stonebrick, 0, 3);
        world.setBlock(x + 7, y + -1, z + 5, Blocks.stonebrick, 0, 3);
        world.setBlock(x + 8, y + -1, z + 5, Blocks.stonebrick, 0, 3);
        world.setBlock(x + 9, y + -1, z + 5, Blocks.stonebrick, 0, 3);
        world.setBlock(x + 10, y + -1, z + 5, Blocks.bedrock, 0, 3);
        world.setBlock(x, y + -1, z + 6, Blocks.bedrock, 0, 3);
        world.setBlock(x + 1, y + -1, z + 6, Blocks.stonebrick, 0, 3);
        world.setBlock(x + 2, y + -1, z + 6, Blocks.stonebrick, 0, 3);
        world.setBlock(x + 3, y + -1, z + 6, Blocks.stonebrick, 0, 3);
        world.setBlock(x + 4, y + -1, z + 6, Blocks.stonebrick, 0, 3);
        world.setBlock(x + 5, y + -1, z + 6, Blocks.stonebrick, 0, 3);
        world.setBlock(x + 6, y + -1, z + 6, Blocks.stonebrick, 0, 3);
        world.setBlock(x + 7, y + -1, z + 6, Blocks.stonebrick, 0, 3);
        world.setBlock(x + 8, y + -1, z + 6, Blocks.stonebrick, 0, 3);
        world.setBlock(x + 9, y + -1, z + 6, Blocks.stonebrick, 0, 3);
        world.setBlock(x + 10, y + -1, z + 6, Blocks.bedrock, 0, 3);
        world.setBlock(x, y + -1, z + 7, Blocks.bedrock, 0, 3);
        world.setBlock(x + 1, y + -1, z + 7, Blocks.stonebrick, 0, 3);
        world.setBlock(x + 2, y + -1, z + 7, Blocks.stonebrick, 0, 3);
        world.setBlock(x + 3, y + -1, z + 7, Blocks.stonebrick, 0, 3);
        world.setBlock(x + 4, y + -1, z + 7, Blocks.stonebrick, 0, 3);
        world.setBlock(x + 5, y + -1, z + 7, Blocks.stonebrick, 0, 3);
        world.setBlock(x + 6, y + -1, z + 7, Blocks.stonebrick, 0, 3);
        world.setBlock(x + 7, y + -1, z + 7, Blocks.stonebrick, 0, 3);
        world.setBlock(x + 8, y + -1, z + 7, Blocks.stonebrick, 0, 3);
        world.setBlock(x + 9, y + -1, z + 7, Blocks.stonebrick, 0, 3);
        world.setBlock(x + 10, y + -1, z + 7, Blocks.bedrock, 0, 3);
        world.setBlock(x, y + -1, z + 8, Blocks.bedrock, 0, 3);
        world.setBlock(x + 1, y + -1, z + 8, Blocks.stonebrick, 0, 3);
        world.setBlock(x + 2, y + -1, z + 8, Blocks.stonebrick, 0, 3);
        world.setBlock(x + 3, y + -1, z + 8, Blocks.stonebrick, 0, 3);
        world.setBlock(x + 4, y + -1, z + 8, Blocks.stonebrick, 0, 3);
        world.setBlock(x + 5, y + -1, z + 8, Blocks.stonebrick, 0, 3);
        world.setBlock(x + 6, y + -1, z + 8, Blocks.stonebrick, 0, 3);
        world.setBlock(x + 7, y + -1, z + 8, Blocks.stonebrick, 0, 3);
        world.setBlock(x + 8, y + -1, z + 8, Blocks.stonebrick, 0, 3);
        world.setBlock(x + 9, y + -1, z + 8, Blocks.stonebrick, 0, 3);
        world.setBlock(x + 10, y + -1, z + 8, Blocks.bedrock, 0, 3);
        world.setBlock(x, y + -1, z + 9, Blocks.bedrock, 0, 3);
        world.setBlock(x + 1, y + -1, z + 9, Blocks.bedrock, 0, 3);
        world.setBlock(x + 2, y + -1, z + 9, Blocks.bedrock, 0, 3);
        world.setBlock(x + 3, y + -1, z + 9, Blocks.bedrock, 0, 3);
        world.setBlock(x + 4, y + -1, z + 9, Blocks.bedrock, 0, 3);
        world.setBlock(x + 5, y + -1, z + 9, Blocks.bedrock, 0, 3);
        world.setBlock(x + 6, y + -1, z + 9, Blocks.bedrock, 0, 3);
        world.setBlock(x + 7, y + -1, z + 9, Blocks.bedrock, 0, 3);
        world.setBlock(x + 8, y + -1, z + 9, Blocks.bedrock, 0, 3);
        world.setBlock(x + 9, y + -1, z + 9, Blocks.bedrock, 0, 3);
        world.setBlock(x + 10, y + -1, z + 9, Blocks.bedrock, 0, 3);
        world.setBlock(pos, Blocks.bedrock, 0, 3);
        world.setBlock(x + 1, y, z, Blocks.bedrock, 0, 3);
        world.setBlock(x + 2, y, z, Blocks.bedrock, 0, 3);
        world.setBlock(x + 3, y, z, Blocks.bedrock, 0, 3);
        world.setBlock(x + 4, y, z, Blocks.bedrock, 0, 3);
        world.setBlock(x + 5, y, z, Blocks.bedrock, 0, 3);
        world.setBlock(x + 6, y, z, Blocks.bedrock, 0, 3);
        world.setBlock(x + 7, y, z, Blocks.bedrock, 0, 3);
        world.setBlock(x + 8, y, z, Blocks.bedrock, 0, 3);
        world.setBlock(x + 9, y, z, Blocks.bedrock, 0, 3);
        world.setBlock(x + 10, y, z, Blocks.bedrock, 0, 3);
        world.setBlock(pos + 1, Blocks.bedrock, 0, 3);
        world.setBlock(x + 1, y, z + 1, Blocks.stonebrick, 3, 3);
        world.setBlock(x + 2, y, z + 1, Blocks.stonebrick, 3, 3);
        world.setBlock(x + 3, y, z + 1, Blocks.stonebrick, 3, 3);
        world.setBlock(x + 4, y, z + 1, Blocks.stonebrick, 3, 3);
        world.setBlock(x + 5, y, z + 1, Blocks.stonebrick, 3, 3);
        world.setBlock(x + 6, y, z + 1, Blocks.stonebrick, 3, 3);
        world.setBlock(x + 7, y, z + 1, Blocks.stonebrick, 3, 3);
        world.setBlock(x + 8, y, z + 1, Blocks.stonebrick, 3, 3);
        world.setBlock(x + 9, y, z + 1, Blocks.stonebrick, 3, 3);
        world.setBlock(x + 10, y, z + 1, Blocks.bedrock, 0, 3);
        world.setBlock(pos + 2, Blocks.bedrock, 0, 3);
        world.setBlock(x + 1, y, z + 2, Blocks.stonebrick, 3, 3);
        world.setBlock(x + 5, y, z + 2, FABlockRegistry.INSTANCE.ancientChest, 3, 3);
        world.setBlock(x + 9, y, z + 2, Blocks.stonebrick, 3, 3);
        world.setBlock(x + 10, y, z + 2, Blocks.bedrock, 0, 3);
        world.setBlock(pos + 3, Blocks.bedrock, 0, 3);
        world.setBlock(x + 1, y, z + 3, Blocks.stonebrick, 3, 3);
        world.setBlock(x + 9, y, z + 3, Blocks.stonebrick, 3, 3);
        world.setBlock(x + 10, y, z + 3, Blocks.bedrock, 0, 3);
        world.setBlock(pos + 4, Blocks.bedrock, 0, 3);
        world.setBlock(x + 1, y, z + 4, Blocks.stonebrick, 3, 3);
        world.setBlock(x + 9, y, z + 4, Blocks.stonebrick, 3, 3);
        world.setBlock(x + 10, y, z + 4, Blocks.bedrock, 0, 3);
        world.setBlock(pos + 5, Blocks.bedrock, 0, 3);
        world.setBlock(x + 1, y, z + 5, Blocks.stonebrick, 3, 3);
        world.setBlock(x + 9, y, z + 5, Blocks.stonebrick, 3, 3);
        world.setBlock(x + 10, y, z + 5, Blocks.bedrock, 0, 3);
        world.setBlock(pos + 6, Blocks.bedrock, 0, 3);
        world.setBlock(x + 1, y, z + 6, Blocks.stonebrick, 3, 3);
        world.setBlock(x + 3, y, z + 6, Blocks.stone_brick_stairs, 2, 3);
        world.setBlock(x + 4, y, z + 6, Blocks.stone_brick_stairs, 2, 3);
        world.setBlock(x + 5, y, z + 6, Blocks.stone_brick_stairs, 2, 3);
        world.setBlock(x + 6, y, z + 6, Blocks.stone_brick_stairs, 2, 3);
        world.setBlock(x + 7, y, z + 6, Blocks.stone_brick_stairs, 2, 3);
        world.setBlock(x + 9, y, z + 6, Blocks.stonebrick, 3, 3);
        world.setBlock(x + 10, y, z + 6, Blocks.bedrock, 0, 3);
        world.setBlock(pos + 7, Blocks.bedrock, 0, 3);
        world.setBlock(x + 1, y, z + 7, Blocks.stonebrick, 3, 3);
        world.setBlock(x + 3, y, z + 7, Blocks.stone_brick_stairs, 0, 3);
        world.setBlock(x + 4, y, z + 7, Blocks.stonebrick, 3, 3);
        world.setBlock(x + 5, y, z + 7, Blocks.stonebrick, 3, 3);
        world.setBlock(x + 6, y, z + 7, Blocks.stonebrick, 3, 3);
        world.setBlock(x + 7, y, z + 7, Blocks.stone_brick_stairs, 1, 3);
        world.setBlock(x + 9, y, z + 7, Blocks.stonebrick, 3, 3);
        world.setBlock(x + 10, y, z + 7, Blocks.bedrock, 0, 3);
        world.setBlock(pos + 8, Blocks.bedrock, 0, 3);
        world.setBlock(x + 1, y, z + 8, Blocks.stonebrick, 3, 3);
        world.setBlock(x + 2, y, z + 8, Blocks.stonebrick, 3, 3);
        world.setBlock(x + 3, y, z + 8, Blocks.stonebrick, 3, 3);
        world.setBlock(x + 4, y, z + 8, Blocks.stonebrick, 3, 3);
        world.setBlock(x + 5, y, z + 8, Blocks.stonebrick, 3, 3);
        world.setBlock(x + 6, y, z + 8, Blocks.stonebrick, 3, 3);
        world.setBlock(x + 7, y, z + 8, Blocks.stonebrick, 3, 3);
        world.setBlock(x + 8, y, z + 8, Blocks.stonebrick, 3, 3);
        world.setBlock(x + 9, y, z + 8, Blocks.stonebrick, 3, 3);
        world.setBlock(x + 10, y, z + 8, Blocks.bedrock, 0, 3);
        world.setBlock(pos + 9, Blocks.bedrock, 0, 3);
        world.setBlock(x + 1, y, z + 9, Blocks.bedrock, 0, 3);
        world.setBlock(x + 2, y, z + 9, Blocks.bedrock, 0, 3);
        world.setBlock(x + 3, y, z + 9, Blocks.bedrock, 0, 3);
        world.setBlock(x + 4, y, z + 9, Blocks.bedrock, 0, 3);
        world.setBlock(x + 5, y, z + 9, Blocks.bedrock, 0, 3);
        world.setBlock(x + 6, y, z + 9, Blocks.bedrock, 0, 3);
        world.setBlock(x + 7, y, z + 9, Blocks.bedrock, 0, 3);
        world.setBlock(x + 8, y, z + 9, Blocks.bedrock, 0, 3);
        world.setBlock(x + 9, y, z + 9, Blocks.bedrock, 0, 3);
        world.setBlock(x + 10, y, z + 9, Blocks.bedrock, 0, 3);
        world.setBlock(x, y + 1, z, Blocks.bedrock, 0, 3);
        world.setBlock(x + 1, y + 1, z, Blocks.bedrock, 0, 3);
        world.setBlock(x + 2, y + 1, z, Blocks.bedrock, 0, 3);
        world.setBlock(x + 3, y + 1, z, Blocks.bedrock, 0, 3);
        world.setBlock(x + 4, y + 1, z, Blocks.bedrock, 0, 3);
        world.setBlock(x + 5, y + 1, z, Blocks.bedrock, 0, 3);
        world.setBlock(x + 6, y + 1, z, Blocks.bedrock, 0, 3);
        world.setBlock(x + 7, y + 1, z, Blocks.bedrock, 0, 3);
        world.setBlock(x + 8, y + 1, z, Blocks.bedrock, 0, 3);
        world.setBlock(x + 9, y + 1, z, Blocks.bedrock, 0, 3);
        world.setBlock(x + 10, y + 1, z, Blocks.bedrock, 0, 3);
        world.setBlock(x, y + 1, z + 1, Blocks.bedrock, 0, 3);
        world.setBlock(x + 1, y + 1, z + 1, Blocks.stonebrick, 0, 3);
        world.setBlock(x + 2, y + 1, z + 1, Blocks.stonebrick, 0, 3);
        world.setBlock(x + 3, y + 1, z + 1, Blocks.stonebrick, 0, 3);
        world.setBlock(x + 4, y + 1, z + 1, Blocks.stonebrick, 0, 3);
        world.setBlock(x + 5, y + 1, z + 1, Blocks.stonebrick, 0, 3);
        world.setBlock(x + 6, y + 1, z + 1, Blocks.stonebrick, 0, 3);
        world.setBlock(x + 7, y + 1, z + 1, Blocks.stonebrick, 0, 3);
        world.setBlock(x + 8, y + 1, z + 1, Blocks.stonebrick, 0, 3);
        world.setBlock(x + 9, y + 1, z + 1, Blocks.stonebrick, 0, 3);
        world.setBlock(x + 10, y + 1, z + 1, Blocks.bedrock, 0, 3);
        world.setBlock(x, y + 1, z + 2, Blocks.bedrock, 0, 3);
        world.setBlock(x + 1, y + 1, z + 2, Blocks.stonebrick, 0, 3);
        world.setBlock(x + 9, y + 1, z + 2, Blocks.stonebrick, 0, 3);
        world.setBlock(x + 10, y + 1, z + 2, Blocks.bedrock, 0, 3);
        world.setBlock(x, y + 1, z + 3, Blocks.bedrock, 0, 3);
        world.setBlock(x + 1, y + 1, z + 3, Blocks.stonebrick, 0, 3);
        world.setBlock(x + 9, y + 1, z + 3, Blocks.stonebrick, 0, 3);
        world.setBlock(x + 10, y + 1, z + 3, Blocks.bedrock, 0, 3);
        world.setBlock(x, y + 1, z + 4, Blocks.bedrock, 0, 3);
        world.setBlock(x + 1, y + 1, z + 4, Blocks.stonebrick, 0, 3);
        world.setBlock(x + 9, y + 1, z + 4, Blocks.stonebrick, 0, 3);
        world.setBlock(x + 10, y + 1, z + 4, Blocks.bedrock, 0, 3);
        world.setBlock(x, y + 1, z + 5, Blocks.bedrock, 0, 3);
        world.setBlock(x + 1, y + 1, z + 5, Blocks.stonebrick, 0, 3);
        world.setBlock(x + 9, y + 1, z + 5, Blocks.stonebrick, 0, 3);
        world.setBlock(x + 10, y + 1, z + 5, Blocks.bedrock, 0, 3);
        world.setBlock(x, y + 1, z + 6, Blocks.bedrock, 0, 3);
        world.setBlock(x + 1, y + 1, z + 6, Blocks.stonebrick, 0, 3);
        world.setBlock(x + 9, y + 1, z + 6, Blocks.stonebrick, 0, 3);
        world.setBlock(x + 10, y + 1, z + 6, Blocks.bedrock, 0, 3);
        world.setBlock(x, y + 1, z + 7, Blocks.bedrock, 0, 3);
        world.setBlock(x + 1, y + 1, z + 7, Blocks.stonebrick, 0, 3);
        world.setBlock(x + 4, y + 1, z + 7, Blocks.stone_brick_stairs, 0, 3);
        world.setBlock(x + 5, y + 1, z + 7, Blocks.stone_brick_stairs, 2, 3);
        world.setBlock(x + 6, y + 1, z + 7, Blocks.stone_brick_stairs, 1, 3);
        world.setBlock(x + 9, y + 1, z + 7, Blocks.stonebrick, 0, 3);
        world.setBlock(x + 10, y + 1, z + 7, Blocks.bedrock, 0, 3);
        world.setBlock(x, y + 1, z + 8, Blocks.bedrock, 0, 3);
        world.setBlock(x + 1, y + 1, z + 8, Blocks.stonebrick, 0, 3);
        world.setBlock(x + 2, y + 1, z + 8, Blocks.stonebrick, 0, 3);
        world.setBlock(x + 3, y + 1, z + 8, Blocks.stonebrick, 0, 3);
        world.setBlock(x + 4, y + 1, z + 8, Blocks.obsidian, 0, 3);
        world.setBlock(x + 5, y + 1, z + 8, Blocks.obsidian, 0, 3);
        world.setBlock(x + 6, y + 1, z + 8, Blocks.obsidian, 0, 3);
        world.setBlock(x + 7, y + 1, z + 8, Blocks.stonebrick, 0, 3);
        world.setBlock(x + 8, y + 1, z + 8, Blocks.stonebrick, 0, 3);
        world.setBlock(x + 9, y + 1, z + 8, Blocks.stonebrick, 0, 3);
        world.setBlock(x + 10, y + 1, z + 8, Blocks.bedrock, 0, 3);
        world.setBlock(x, y + 1, z + 9, Blocks.bedrock, 0, 3);
        world.setBlock(x + 1, y + 1, z + 9, Blocks.bedrock, 0, 3);
        world.setBlock(x + 2, y + 1, z + 9, Blocks.bedrock, 0, 3);
        world.setBlock(x + 3, y + 1, z + 9, Blocks.bedrock, 0, 3);
        world.setBlock(x + 4, y + 1, z + 9, Blocks.bedrock, 0, 3);
        world.setBlock(x + 5, y + 1, z + 9, Blocks.bedrock, 0, 3);
        world.setBlock(x + 6, y + 1, z + 9, Blocks.bedrock, 0, 3);
        world.setBlock(x + 7, y + 1, z + 9, Blocks.bedrock, 0, 3);
        world.setBlock(x + 8, y + 1, z + 9, Blocks.bedrock, 0, 3);
        world.setBlock(x + 9, y + 1, z + 9, Blocks.bedrock, 0, 3);
        world.setBlock(x + 10, y + 1, z + 9, Blocks.bedrock, 0, 3);
        world.setBlock(x, y + 2, z, Blocks.bedrock, 0, 3);
        world.setBlock(x + 1, y + 2, z, Blocks.bedrock, 0, 3);
        world.setBlock(x + 2, y + 2, z, Blocks.bedrock, 0, 3);
        world.setBlock(x + 3, y + 2, z, Blocks.bedrock, 0, 3);
        world.setBlock(x + 4, y + 2, z, Blocks.bedrock, 0, 3);
        world.setBlock(x + 5, y + 2, z, Blocks.bedrock, 0, 3);
        world.setBlock(x + 6, y + 2, z, Blocks.bedrock, 0, 3);
        world.setBlock(x + 7, y + 2, z, Blocks.bedrock, 0, 3);
        world.setBlock(x + 8, y + 2, z, Blocks.bedrock, 0, 3);
        world.setBlock(x + 9, y + 2, z, Blocks.bedrock, 0, 3);
        world.setBlock(x + 10, y + 2, z, Blocks.bedrock, 0, 3);
        world.setBlock(x, y + 2, z + 1, Blocks.bedrock, 0, 3);
        world.setBlock(x + 1, y + 2, z + 1, Blocks.stonebrick, 0, 3);
        world.setBlock(x + 2, y + 2, z + 1, Blocks.stonebrick, 0, 3);
        world.setBlock(x + 3, y + 2, z + 1, Blocks.stonebrick, 0, 3);
        world.setBlock(x + 4, y + 2, z + 1, Blocks.stonebrick, 0, 3);
        world.setBlock(x + 5, y + 2, z + 1, Blocks.stonebrick, 0, 3);
        world.setBlock(x + 6, y + 2, z + 1, Blocks.stonebrick, 0, 3);
        world.setBlock(x + 7, y + 2, z + 1, Blocks.stonebrick, 0, 3);
        world.setBlock(x + 8, y + 2, z + 1, Blocks.stonebrick, 0, 3);
        world.setBlock(x + 9, y + 2, z + 1, Blocks.stonebrick, 0, 3);
        world.setBlock(x + 10, y + 2, z + 1, Blocks.bedrock, 0, 3);
        world.setBlock(x, y + 2, z + 2, Blocks.bedrock, 0, 3);
        world.setBlock(x + 1, y + 2, z + 2, Blocks.stonebrick, 0, 3);
        world.setBlock(x + 9, y + 2, z + 2, Blocks.stonebrick, 0, 3);
        world.setBlock(x + 10, y + 2, z + 2, Blocks.bedrock, 0, 3);
        world.setBlock(x, y + 2, z + 3, Blocks.bedrock, 0, 3);
        world.setBlock(x + 1, y + 2, z + 3, Blocks.stonebrick, 0, 3);
        world.setBlock(x + 9, y + 2, z + 3, Blocks.stonebrick, 0, 3);
        world.setBlock(x + 10, y + 2, z + 3, Blocks.bedrock, 0, 3);
        world.setBlock(x, y + 2, z + 4, Blocks.bedrock, 0, 3);
        world.setBlock(x + 1, y + 2, z + 4, Blocks.stonebrick, 0, 3);
        world.setBlock(x + 9, y + 2, z + 4, Blocks.stonebrick, 0, 3);
        world.setBlock(x + 10, y + 2, z + 4, Blocks.bedrock, 0, 3);
        world.setBlock(x, y + 2, z + 5, Blocks.bedrock, 0, 3);
        world.setBlock(x + 1, y + 2, z + 5, Blocks.stonebrick, 0, 3);
        world.setBlock(x + 9, y + 2, z + 5, Blocks.stonebrick, 0, 3);
        world.setBlock(x + 10, y + 2, z + 5, Blocks.bedrock, 0, 3);
        world.setBlock(x, y + 2, z + 6, Blocks.bedrock, 0, 3);
        world.setBlock(x + 1, y + 2, z + 6, Blocks.stonebrick, 0, 3);
        world.setBlock(x + 9, y + 2, z + 6, Blocks.stonebrick, 0, 3);
        world.setBlock(x + 10, y + 2, z + 6, Blocks.bedrock, 0, 3);
        world.setBlock(x, y + 2, z + 7, Blocks.bedrock, 0, 3);
        world.setBlock(x + 1, y + 2, z + 7, Blocks.stonebrick, 0, 3);
        world.setBlock(x + 9, y + 2, z + 7, Blocks.stonebrick, 0, 3);
        world.setBlock(x + 10, y + 2, z + 7, Blocks.bedrock, 0, 3);
        world.setBlock(x, y + 2, z + 8, Blocks.bedrock, 0, 3);
        world.setBlock(x + 1, y + 2, z + 8, Blocks.stonebrick, 0, 3);
        world.setBlock(x + 2, y + 2, z + 8, Blocks.stonebrick, 0, 3);
        world.setBlock(x + 3, y + 2, z + 8, Blocks.obsidian, 0, 3);
        world.setBlock(x + 4, y + 2, z + 8, FABlockRegistry.INSTANCE.homePortal, 0, 3);
        world.setBlock(x + 5, y + 2, z + 8, FABlockRegistry.INSTANCE.homePortal, 0, 3);
        world.setBlock(x + 6, y + 2, z + 8, FABlockRegistry.INSTANCE.homePortal, 0, 3);
        world.setBlock(x + 7, y + 2, z + 8, Blocks.obsidian, 0, 3);
        world.setBlock(x + 8, y + 2, z + 8, Blocks.stonebrick, 0, 3);
        world.setBlock(x + 9, y + 2, z + 8, Blocks.stonebrick, 0, 3);
        world.setBlock(x + 10, y + 2, z + 8, Blocks.bedrock, 0, 3);
        world.setBlock(x, y + 2, z + 9, Blocks.bedrock, 0, 3);
        world.setBlock(x + 1, y + 2, z + 9, Blocks.bedrock, 0, 3);
        world.setBlock(x + 2, y + 2, z + 9, Blocks.bedrock, 0, 3);
        world.setBlock(x + 3, y + 2, z + 9, Blocks.bedrock, 0, 3);
        world.setBlock(x + 4, y + 2, z + 9, Blocks.bedrock, 0, 3);
        world.setBlock(x + 5, y + 2, z + 9, Blocks.bedrock, 0, 3);
        world.setBlock(x + 6, y + 2, z + 9, Blocks.bedrock, 0, 3);
        world.setBlock(x + 7, y + 2, z + 9, Blocks.bedrock, 0, 3);
        world.setBlock(x + 8, y + 2, z + 9, Blocks.bedrock, 0, 3);
        world.setBlock(x + 9, y + 2, z + 9, Blocks.bedrock, 0, 3);
        world.setBlock(x + 10, y + 2, z + 9, Blocks.bedrock, 0, 3);
        world.setBlock(x, y + 3, z, Blocks.bedrock, 0, 3);
        world.setBlock(x + 1, y + 3, z, Blocks.bedrock, 0, 3);
        world.setBlock(x + 2, y + 3, z, Blocks.bedrock, 0, 3);
        world.setBlock(x + 3, y + 3, z, Blocks.bedrock, 0, 3);
        world.setBlock(x + 4, y + 3, z, Blocks.bedrock, 0, 3);
        world.setBlock(x + 5, y + 3, z, Blocks.bedrock, 0, 3);
        world.setBlock(x + 6, y + 3, z, Blocks.bedrock, 0, 3);
        world.setBlock(x + 7, y + 3, z, Blocks.bedrock, 0, 3);
        world.setBlock(x + 8, y + 3, z, Blocks.bedrock, 0, 3);
        world.setBlock(x + 9, y + 3, z, Blocks.bedrock, 0, 3);
        world.setBlock(x + 10, y + 3, z, Blocks.bedrock, 0, 3);
        world.setBlock(x, y + 3, z + 1, Blocks.bedrock, 0, 3);
        world.setBlock(x + 1, y + 3, z + 1, Blocks.stonebrick, 3, 3);
        world.setBlock(x + 2, y + 3, z + 1, Blocks.stonebrick, 3, 3);
        world.setBlock(x + 3, y + 3, z + 1, Blocks.stonebrick, 3, 3);
        world.setBlock(x + 4, y + 3, z + 1, Blocks.stonebrick, 3, 3);
        world.setBlock(x + 5, y + 3, z + 1, Blocks.stonebrick, 3, 3);
        world.setBlock(x + 6, y + 3, z + 1, Blocks.stonebrick, 3, 3);
        world.setBlock(x + 7, y + 3, z + 1, Blocks.stonebrick, 3, 3);
        world.setBlock(x + 8, y + 3, z + 1, Blocks.stonebrick, 3, 3);
        world.setBlock(x + 9, y + 3, z + 1, Blocks.stonebrick, 3, 3);
        world.setBlock(x + 10, y + 3, z + 1, Blocks.bedrock, 0, 3);
        world.setBlock(x, y + 3, z + 2, Blocks.bedrock, 0, 3);
        world.setBlock(x + 1, y + 3, z + 2, Blocks.stonebrick, 3, 3);
        world.setBlock(x + 9, y + 3, z + 2, Blocks.stonebrick, 3, 3);
        world.setBlock(x + 10, y + 3, z + 2, Blocks.bedrock, 0, 3);
        world.setBlock(x, y + 3, z + 3, Blocks.bedrock, 0, 3);
        world.setBlock(x + 1, y + 3, z + 3, Blocks.stonebrick, 3, 3);
        world.setBlock(x + 9, y + 3, z + 3, Blocks.stonebrick, 3, 3);
        world.setBlock(x + 10, y + 3, z + 3, Blocks.bedrock, 0, 3);
        world.setBlock(x, y + 3, z + 4, Blocks.bedrock, 0, 3);
        world.setBlock(x + 1, y + 3, z + 4, Blocks.stonebrick, 3, 3);
        world.setBlock(x + 9, y + 3, z + 4, Blocks.stonebrick, 3, 3);
        world.setBlock(x + 10, y + 3, z + 4, Blocks.bedrock, 0, 3);
        world.setBlock(x, y + 3, z + 5, Blocks.bedrock, 0, 3);
        world.setBlock(x + 1, y + 3, z + 5, Blocks.stonebrick, 3, 3);
        world.setBlock(x + 9, y + 3, z + 5, Blocks.stonebrick, 3, 3);
        world.setBlock(x + 10, y + 3, z + 5, Blocks.bedrock, 0, 3);
        world.setBlock(x, y + 3, z + 6, Blocks.bedrock, 0, 3);
        world.setBlock(x + 1, y + 3, z + 6, Blocks.stonebrick, 3, 3);
        world.setBlock(x + 9, y + 3, z + 6, Blocks.stonebrick, 3, 3);
        world.setBlock(x + 10, y + 3, z + 6, Blocks.bedrock, 0, 3);
        world.setBlock(x, y + 3, z + 7, Blocks.bedrock, 0, 3);
        world.setBlock(x + 1, y + 3, z + 7, Blocks.stonebrick, 3, 3);
        world.setBlock(x + 9, y + 3, z + 7, Blocks.stonebrick, 3, 3);
        world.setBlock(x + 10, y + 3, z + 7, Blocks.bedrock, 0, 3);
        world.setBlock(x, y + 3, z + 8, Blocks.bedrock, 0, 3);
        world.setBlock(x + 1, y + 3, z + 8, Blocks.stonebrick, 3, 3);
        world.setBlock(x + 2, y + 3, z + 8, Blocks.stonebrick, 3, 3);
        world.setBlock(x + 3, y + 3, z + 8, Blocks.obsidian, 0, 3);
        world.setBlock(x + 4, y + 3, z + 8, FABlockRegistry.INSTANCE.homePortal, 0, 3);
        world.setBlock(x + 5, y + 3, z + 8, FABlockRegistry.INSTANCE.homePortal, 0, 3);
        world.setBlock(x + 6, y + 3, z + 8, FABlockRegistry.INSTANCE.homePortal, 0, 3);
        world.setBlock(x + 7, y + 3, z + 8, Blocks.obsidian, 0, 3);
        world.setBlock(x + 8, y + 3, z + 8, Blocks.stonebrick, 3, 3);
        world.setBlock(x + 9, y + 3, z + 8, Blocks.stonebrick, 3, 3);
        world.setBlock(x + 10, y + 3, z + 8, Blocks.bedrock, 0, 3);
        world.setBlock(x, y + 3, z + 9, Blocks.bedrock, 0, 3);
        world.setBlock(x + 1, y + 3, z + 9, Blocks.bedrock, 0, 3);
        world.setBlock(x + 2, y + 3, z + 9, Blocks.bedrock, 0, 3);
        world.setBlock(x + 3, y + 3, z + 9, Blocks.bedrock, 0, 3);
        world.setBlock(x + 4, y + 3, z + 9, Blocks.bedrock, 0, 3);
        world.setBlock(x + 5, y + 3, z + 9, Blocks.bedrock, 0, 3);
        world.setBlock(x + 6, y + 3, z + 9, Blocks.bedrock, 0, 3);
        world.setBlock(x + 7, y + 3, z + 9, Blocks.bedrock, 0, 3);
        world.setBlock(x + 8, y + 3, z + 9, Blocks.bedrock, 0, 3);
        world.setBlock(x + 9, y + 3, z + 9, Blocks.bedrock, 0, 3);
        world.setBlock(x + 10, y + 3, z + 9, Blocks.bedrock, 0, 3);
        world.setBlock(x, y + 4, z, Blocks.bedrock, 0, 3);
        world.setBlock(x + 1, y + 4, z, Blocks.bedrock, 0, 3);
        world.setBlock(x + 2, y + 4, z, Blocks.bedrock, 0, 3);
        world.setBlock(x + 3, y + 4, z, Blocks.bedrock, 0, 3);
        world.setBlock(x + 4, y + 4, z, Blocks.bedrock, 0, 3);
        world.setBlock(x + 5, y + 4, z, Blocks.bedrock, 0, 3);
        world.setBlock(x + 6, y + 4, z, Blocks.bedrock, 0, 3);
        world.setBlock(x + 7, y + 4, z, Blocks.bedrock, 0, 3);
        world.setBlock(x + 8, y + 4, z, Blocks.bedrock, 0, 3);
        world.setBlock(x + 9, y + 4, z, Blocks.bedrock, 0, 3);
        world.setBlock(x + 10, y + 4, z, Blocks.bedrock, 0, 3);
        world.setBlock(x, y + 4, z + 1, Blocks.bedrock, 0, 3);
        world.setBlock(x + 1, y + 4, z + 1, Blocks.stonebrick, 0, 3);
        world.setBlock(x + 2, y + 4, z + 1, Blocks.stonebrick, 0, 3);
        world.setBlock(x + 3, y + 4, z + 1, Blocks.stonebrick, 0, 3);
        world.setBlock(x + 4, y + 4, z + 1, Blocks.stonebrick, 0, 3);
        world.setBlock(x + 5, y + 4, z + 1, Blocks.stonebrick, 0, 3);
        world.setBlock(x + 6, y + 4, z + 1, Blocks.stonebrick, 0, 3);
        world.setBlock(x + 7, y + 4, z + 1, Blocks.stonebrick, 0, 3);
        world.setBlock(x + 8, y + 4, z + 1, Blocks.stonebrick, 0, 3);
        world.setBlock(x + 9, y + 4, z + 1, Blocks.stonebrick, 0, 3);
        world.setBlock(x + 10, y + 4, z + 1, Blocks.bedrock, 0, 3);
        world.setBlock(x, y + 4, z + 2, Blocks.bedrock, 0, 3);
        world.setBlock(x + 1, y + 4, z + 2, Blocks.stonebrick, 0, 3);
        world.setBlock(x + 9, y + 4, z + 2, Blocks.stonebrick, 0, 3);
        world.setBlock(x + 10, y + 4, z + 2, Blocks.bedrock, 0, 3);
        world.setBlock(x, y + 4, z + 3, Blocks.bedrock, 0, 3);
        world.setBlock(x + 1, y + 4, z + 3, Blocks.stonebrick, 0, 3);
        world.setBlock(x + 9, y + 4, z + 3, Blocks.stonebrick, 0, 3);
        world.setBlock(x + 10, y + 4, z + 3, Blocks.bedrock, 0, 3);
        world.setBlock(x, y + 4, z + 4, Blocks.bedrock, 0, 3);
        world.setBlock(x + 1, y + 4, z + 4, Blocks.stonebrick, 0, 3);
        world.setBlock(x + 9, y + 4, z + 4, Blocks.stonebrick, 0, 3);
        world.setBlock(x + 10, y + 4, z + 4, Blocks.bedrock, 0, 3);
        world.setBlock(x, y + 4, z + 5, Blocks.bedrock, 0, 3);
        world.setBlock(x + 1, y + 4, z + 5, Blocks.stonebrick, 0, 3);
        world.setBlock(x + 9, y + 4, z + 5, Blocks.stonebrick, 0, 3);
        world.setBlock(x + 10, y + 4, z + 5, Blocks.bedrock, 0, 3);
        world.setBlock(x, y + 4, z + 6, Blocks.bedrock, 0, 3);
        world.setBlock(x + 1, y + 4, z + 6, Blocks.stonebrick, 0, 3);
        world.setBlock(x + 9, y + 4, z + 6, Blocks.stonebrick, 0, 3);
        world.setBlock(x + 10, y + 4, z + 6, Blocks.bedrock, 0, 3);
        world.setBlock(x, y + 4, z + 7, Blocks.bedrock, 0, 3);
        world.setBlock(x + 1, y + 4, z + 7, Blocks.stonebrick, 0, 3);
        world.setBlock(x + 9, y + 4, z + 7, Blocks.stonebrick, 0, 3);
        world.setBlock(x + 10, y + 4, z + 7, Blocks.bedrock, 0, 3);
        world.setBlock(x, y + 4, z + 8, Blocks.bedrock, 0, 3);
        world.setBlock(x + 1, y + 4, z + 8, Blocks.stonebrick, 0, 3);
        world.setBlock(x + 2, y + 4, z + 8, Blocks.stonebrick, 0, 3);
        world.setBlock(x + 3, y + 4, z + 8, Blocks.obsidian, 0, 3);
        world.setBlock(x + 4, y + 4, z + 8, FABlockRegistry.INSTANCE.homePortal, 0, 3);
        world.setBlock(x + 5, y + 4, z + 8, FABlockRegistry.INSTANCE.homePortal, 0, 3);
        world.setBlock(x + 6, y + 4, z + 8, FABlockRegistry.INSTANCE.homePortal, 0, 3);
        world.setBlock(x + 7, y + 4, z + 8, Blocks.obsidian, 0, 3);
        world.setBlock(x + 8, y + 4, z + 8, Blocks.stonebrick, 0, 3);
        world.setBlock(x + 9, y + 4, z + 8, Blocks.stonebrick, 0, 3);
        world.setBlock(x + 10, y + 4, z + 8, Blocks.bedrock, 0, 3);
        world.setBlock(x, y + 4, z + 9, Blocks.bedrock, 0, 3);
        world.setBlock(x + 1, y + 4, z + 9, Blocks.bedrock, 0, 3);
        world.setBlock(x + 2, y + 4, z + 9, Blocks.bedrock, 0, 3);
        world.setBlock(x + 3, y + 4, z + 9, Blocks.bedrock, 0, 3);
        world.setBlock(x + 4, y + 4, z + 9, Blocks.bedrock, 0, 3);
        world.setBlock(x + 5, y + 4, z + 9, Blocks.bedrock, 0, 3);
        world.setBlock(x + 6, y + 4, z + 9, Blocks.bedrock, 0, 3);
        world.setBlock(x + 7, y + 4, z + 9, Blocks.bedrock, 0, 3);
        world.setBlock(x + 8, y + 4, z + 9, Blocks.bedrock, 0, 3);
        world.setBlock(x + 9, y + 4, z + 9, Blocks.bedrock, 0, 3);
        world.setBlock(x + 10, y + 4, z + 9, Blocks.bedrock, 0, 3);
        world.setBlock(x, y + 5, z, Blocks.bedrock, 0, 3);
        world.setBlock(x + 1, y + 5, z, Blocks.bedrock, 0, 3);
        world.setBlock(x + 2, y + 5, z, Blocks.bedrock, 0, 3);
        world.setBlock(x + 3, y + 5, z, Blocks.bedrock, 0, 3);
        world.setBlock(x + 4, y + 5, z, Blocks.bedrock, 0, 3);
        world.setBlock(x + 5, y + 5, z, Blocks.bedrock, 0, 3);
        world.setBlock(x + 6, y + 5, z, Blocks.bedrock, 0, 3);
        world.setBlock(x + 7, y + 5, z, Blocks.bedrock, 0, 3);
        world.setBlock(x + 8, y + 5, z, Blocks.bedrock, 0, 3);
        world.setBlock(x + 9, y + 5, z, Blocks.bedrock, 0, 3);
        world.setBlock(x + 10, y + 5, z, Blocks.bedrock, 0, 3);
        world.setBlock(x, y + 5, z + 1, Blocks.bedrock, 0, 3);
        world.setBlock(x + 1, y + 5, z + 1, Blocks.stonebrick, 0, 3);
        world.setBlock(x + 2, y + 5, z + 1, Blocks.stonebrick, 0, 3);
        world.setBlock(x + 3, y + 5, z + 1, Blocks.stonebrick, 0, 3);
        world.setBlock(x + 4, y + 5, z + 1, Blocks.stonebrick, 0, 3);
        world.setBlock(x + 5, y + 5, z + 1, Blocks.stonebrick, 0, 3);
        world.setBlock(x + 6, y + 5, z + 1, Blocks.stonebrick, 0, 3);
        world.setBlock(x + 7, y + 5, z + 1, Blocks.stonebrick, 0, 3);
        world.setBlock(x + 8, y + 5, z + 1, Blocks.stonebrick, 0, 3);
        world.setBlock(x + 9, y + 5, z + 1, Blocks.stonebrick, 0, 3);
        world.setBlock(x + 10, y + 5, z + 1, Blocks.bedrock, 0, 3);
        world.setBlock(x, y + 5, z + 2, Blocks.bedrock, 0, 3);
        world.setBlock(x + 1, y + 5, z + 2, Blocks.stonebrick, 0, 3);
        world.setBlock(x + 9, y + 5, z + 2, Blocks.stonebrick, 0, 3);
        world.setBlock(x + 10, y + 5, z + 2, Blocks.bedrock, 0, 3);
        world.setBlock(x, y + 5, z + 3, Blocks.bedrock, 0, 3);
        world.setBlock(x + 1, y + 5, z + 3, Blocks.stonebrick, 0, 3);
        world.setBlock(x + 9, y + 5, z + 3, Blocks.stonebrick, 0, 3);
        world.setBlock(x + 10, y + 5, z + 3, Blocks.bedrock, 0, 3);
        world.setBlock(x, y + 5, z + 4, Blocks.bedrock, 0, 3);
        world.setBlock(x + 1, y + 5, z + 4, Blocks.stonebrick, 0, 3);
        world.setBlock(x + 9, y + 5, z + 4, Blocks.stonebrick, 0, 3);
        world.setBlock(x + 10, y + 5, z + 4, Blocks.bedrock, 0, 3);
        world.setBlock(x, y + 5, z + 5, Blocks.bedrock, 0, 3);
        world.setBlock(x + 1, y + 5, z + 5, Blocks.stonebrick, 0, 3);
        world.setBlock(x + 9, y + 5, z + 5, Blocks.stonebrick, 0, 3);
        world.setBlock(x + 10, y + 5, z + 5, Blocks.bedrock, 0, 3);
        world.setBlock(x, y + 5, z + 6, Blocks.bedrock, 0, 3);
        world.setBlock(x + 1, y + 5, z + 6, Blocks.stonebrick, 0, 3);
        world.setBlock(x + 9, y + 5, z + 6, Blocks.stonebrick, 0, 3);
        world.setBlock(x + 10, y + 5, z + 6, Blocks.bedrock, 0, 3);
        world.setBlock(x, y + 5, z + 7, Blocks.bedrock, 0, 3);
        world.setBlock(x + 1, y + 5, z + 7, Blocks.stonebrick, 0, 3);
        world.setBlock(x + 9, y + 5, z + 7, Blocks.stonebrick, 0, 3);
        world.setBlock(x + 10, y + 5, z + 7, Blocks.bedrock, 0, 3);
        world.setBlock(x, y + 5, z + 8, Blocks.bedrock, 0, 3);
        world.setBlock(x + 1, y + 5, z + 8, Blocks.stonebrick, 0, 3);
        world.setBlock(x + 2, y + 5, z + 8, Blocks.stonebrick, 0, 3);
        world.setBlock(x + 3, y + 5, z + 8, Blocks.stonebrick, 0, 3);
        world.setBlock(x + 4, y + 5, z + 8, Blocks.obsidian, 0, 3);
        world.setBlock(x + 5, y + 5, z + 8, Blocks.obsidian, 0, 3);
        world.setBlock(x + 6, y + 5, z + 8, Blocks.obsidian, 0, 3);
        world.setBlock(x + 7, y + 5, z + 8, Blocks.stonebrick, 0, 3);
        world.setBlock(x + 8, y + 5, z + 8, Blocks.stonebrick, 0, 3);
        world.setBlock(x + 9, y + 5, z + 8, Blocks.stonebrick, 0, 3);
        world.setBlock(x + 10, y + 5, z + 8, Blocks.bedrock, 0, 3);
        world.setBlock(x, y + 5, z + 9, Blocks.bedrock, 0, 3);
        world.setBlock(x + 1, y + 5, z + 9, Blocks.bedrock, 0, 3);
        world.setBlock(x + 2, y + 5, z + 9, Blocks.bedrock, 0, 3);
        world.setBlock(x + 3, y + 5, z + 9, Blocks.bedrock, 0, 3);
        world.setBlock(x + 4, y + 5, z + 9, Blocks.bedrock, 0, 3);
        world.setBlock(x + 5, y + 5, z + 9, Blocks.bedrock, 0, 3);
        world.setBlock(x + 6, y + 5, z + 9, Blocks.bedrock, 0, 3);
        world.setBlock(x + 7, y + 5, z + 9, Blocks.bedrock, 0, 3);
        world.setBlock(x + 8, y + 5, z + 9, Blocks.bedrock, 0, 3);
        world.setBlock(x + 9, y + 5, z + 9, Blocks.bedrock, 0, 3);
        world.setBlock(x + 10, y + 5, z + 9, Blocks.bedrock, 0, 3);
        world.setBlock(x, y + 6, z, Blocks.bedrock, 0, 3);
        world.setBlock(x + 1, y + 6, z, Blocks.bedrock, 0, 3);
        world.setBlock(x + 2, y + 6, z, Blocks.bedrock, 0, 3);
        world.setBlock(x + 3, y + 6, z, Blocks.bedrock, 0, 3);
        world.setBlock(x + 4, y + 6, z, Blocks.bedrock, 0, 3);
        world.setBlock(x + 5, y + 6, z, Blocks.bedrock, 0, 3);
        world.setBlock(x + 6, y + 6, z, Blocks.bedrock, 0, 3);
        world.setBlock(x + 7, y + 6, z, Blocks.bedrock, 0, 3);
        world.setBlock(x + 8, y + 6, z, Blocks.bedrock, 0, 3);
        world.setBlock(x + 9, y + 6, z, Blocks.bedrock, 0, 3);
        world.setBlock(x + 10, y + 6, z, Blocks.bedrock, 0, 3);
        world.setBlock(x, y + 6, z + 1, Blocks.bedrock, 0, 3);
        world.setBlock(x + 1, y + 6, z + 1, Blocks.stonebrick, 3, 3);
        world.setBlock(x + 2, y + 6, z + 1, Blocks.stonebrick, 3, 3);
        world.setBlock(x + 3, y + 6, z + 1, Blocks.stonebrick, 3, 3);
        world.setBlock(x + 4, y + 6, z + 1, Blocks.stonebrick, 3, 3);
        world.setBlock(x + 5, y + 6, z + 1, Blocks.stonebrick, 3, 3);
        world.setBlock(x + 6, y + 6, z + 1, Blocks.stonebrick, 3, 3);
        world.setBlock(x + 7, y + 6, z + 1, Blocks.stonebrick, 3, 3);
        world.setBlock(x + 8, y + 6, z + 1, Blocks.stonebrick, 3, 3);
        world.setBlock(x + 9, y + 6, z + 1, Blocks.stonebrick, 3, 3);
        world.setBlock(x + 10, y + 6, z + 1, Blocks.bedrock, 0, 3);
        world.setBlock(x, y + 6, z + 2, Blocks.bedrock, 0, 3);
        world.setBlock(x + 1, y + 6, z + 2, Blocks.stonebrick, 3, 3);
        world.setBlock(x + 9, y + 6, z + 2, Blocks.stonebrick, 3, 3);
        world.setBlock(x + 10, y + 6, z + 2, Blocks.bedrock, 0, 3);
        world.setBlock(x, y + 6, z + 3, Blocks.bedrock, 0, 3);
        world.setBlock(x + 1, y + 6, z + 3, Blocks.stonebrick, 3, 3);
        world.setBlock(x + 9, y + 6, z + 3, Blocks.stonebrick, 3, 3);
        world.setBlock(x + 10, y + 6, z + 3, Blocks.bedrock, 0, 3);
        world.setBlock(x, y + 6, z + 4, Blocks.bedrock, 0, 3);
        world.setBlock(x + 1, y + 6, z + 4, Blocks.stonebrick, 3, 3);
        world.setBlock(x + 9, y + 6, z + 4, Blocks.stonebrick, 3, 3);
        world.setBlock(x + 10, y + 6, z + 4, Blocks.bedrock, 0, 3);
        world.setBlock(x, y + 6, z + 5, Blocks.bedrock, 0, 3);
        world.setBlock(x + 1, y + 6, z + 5, Blocks.stonebrick, 3, 3);
        world.setBlock(x + 9, y + 6, z + 5, Blocks.stonebrick, 3, 3);
        world.setBlock(x + 10, y + 6, z + 5, Blocks.bedrock, 0, 3);
        world.setBlock(x, y + 6, z + 6, Blocks.bedrock, 0, 3);
        world.setBlock(x + 1, y + 6, z + 6, Blocks.stonebrick, 3, 3);
        world.setBlock(x + 9, y + 6, z + 6, Blocks.stonebrick, 3, 3);
        world.setBlock(x + 10, y + 6, z + 6, Blocks.bedrock, 0, 3);
        world.setBlock(x, y + 6, z + 7, Blocks.bedrock, 0, 3);
        world.setBlock(x + 1, y + 6, z + 7, Blocks.stonebrick, 3, 3);
        world.setBlock(x + 9, y + 6, z + 7, Blocks.stonebrick, 3, 3);
        world.setBlock(x + 10, y + 6, z + 7, Blocks.bedrock, 0, 3);
        world.setBlock(x, y + 6, z + 8, Blocks.bedrock, 0, 3);
        world.setBlock(x + 1, y + 6, z + 8, Blocks.stonebrick, 3, 3);
        world.setBlock(x + 2, y + 6, z + 8, Blocks.stonebrick, 3, 3);
        world.setBlock(x + 3, y + 6, z + 8, Blocks.stonebrick, 3, 3);
        world.setBlock(x + 4, y + 6, z + 8, Blocks.stonebrick, 3, 3);
        world.setBlock(x + 5, y + 6, z + 8, Blocks.stonebrick, 3, 3);
        world.setBlock(x + 6, y + 6, z + 8, Blocks.stonebrick, 3, 3);
        world.setBlock(x + 7, y + 6, z + 8, Blocks.stonebrick, 3, 3);
        world.setBlock(x + 8, y + 6, z + 8, Blocks.stonebrick, 3, 3);
        world.setBlock(x + 9, y + 6, z + 8, Blocks.stonebrick, 3, 3);
        world.setBlock(x + 10, y + 6, z + 8, Blocks.bedrock, 0, 3);
        world.setBlock(x, y + 6, z + 9, Blocks.bedrock, 0, 3);
        world.setBlock(x + 1, y + 6, z + 9, Blocks.bedrock, 0, 3);
        world.setBlock(x + 2, y + 6, z + 9, Blocks.bedrock, 0, 3);
        world.setBlock(x + 3, y + 6, z + 9, Blocks.bedrock, 0, 3);
        world.setBlock(x + 4, y + 6, z + 9, Blocks.bedrock, 0, 3);
        world.setBlock(x + 5, y + 6, z + 9, Blocks.bedrock, 0, 3);
        world.setBlock(x + 6, y + 6, z + 9, Blocks.bedrock, 0, 3);
        world.setBlock(x + 7, y + 6, z + 9, Blocks.bedrock, 0, 3);
        world.setBlock(x + 8, y + 6, z + 9, Blocks.bedrock, 0, 3);
        world.setBlock(x + 9, y + 6, z + 9, Blocks.bedrock, 0, 3);
        world.setBlock(x + 10, y + 6, z + 9, Blocks.bedrock, 0, 3);
        world.setBlock(x, y + 7, z, Blocks.bedrock, 0, 3);
        world.setBlock(x + 1, y + 7, z, Blocks.bedrock, 0, 3);
        world.setBlock(x + 2, y + 7, z, Blocks.bedrock, 0, 3);
        world.setBlock(x + 3, y + 7, z, Blocks.bedrock, 0, 3);
        world.setBlock(x + 4, y + 7, z, Blocks.bedrock, 0, 3);
        world.setBlock(x + 5, y + 7, z, Blocks.bedrock, 0, 3);
        world.setBlock(x + 6, y + 7, z, Blocks.bedrock, 0, 3);
        world.setBlock(x + 7, y + 7, z, Blocks.bedrock, 0, 3);
        world.setBlock(x + 8, y + 7, z, Blocks.bedrock, 0, 3);
        world.setBlock(x + 9, y + 7, z, Blocks.bedrock, 0, 3);
        world.setBlock(x + 10, y + 7, z, Blocks.bedrock, 0, 3);
        world.setBlock(x, y + 7, z + 1, Blocks.bedrock, 0, 3);
        world.setBlock(x + 1, y + 7, z + 1, Blocks.stonebrick, 0, 3);
        world.setBlock(x + 2, y + 7, z + 1, Blocks.stonebrick, 0, 3);
        world.setBlock(x + 3, y + 7, z + 1, Blocks.stonebrick, 0, 3);
        world.setBlock(x + 4, y + 7, z + 1, Blocks.stonebrick, 0, 3);
        world.setBlock(x + 5, y + 7, z + 1, Blocks.stonebrick, 0, 3);
        world.setBlock(x + 6, y + 7, z + 1, Blocks.stonebrick, 0, 3);
        world.setBlock(x + 7, y + 7, z + 1, Blocks.stonebrick, 0, 3);
        world.setBlock(x + 8, y + 7, z + 1, Blocks.stonebrick, 0, 3);
        world.setBlock(x + 9, y + 7, z + 1, Blocks.stonebrick, 0, 3);
        world.setBlock(x + 10, y + 7, z + 1, Blocks.bedrock, 0, 3);
        world.setBlock(x, y + 7, z + 2, Blocks.bedrock, 0, 3);
        world.setBlock(x + 1, y + 7, z + 2, Blocks.stonebrick, 0, 3);
        world.setBlock(x + 2, y + 7, z + 2, Blocks.stonebrick, 0, 3);
        world.setBlock(x + 3, y + 7, z + 2, Blocks.stonebrick, 0, 3);
        world.setBlock(x + 4, y + 7, z + 2, Blocks.stonebrick, 0, 3);
        world.setBlock(x + 5, y + 7, z + 2, Blocks.stonebrick, 0, 3);
        world.setBlock(x + 6, y + 7, z + 2, Blocks.stonebrick, 0, 3);
        world.setBlock(x + 7, y + 7, z + 2, Blocks.stonebrick, 0, 3);
        world.setBlock(x + 8, y + 7, z + 2, Blocks.stonebrick, 0, 3);
        world.setBlock(x + 9, y + 7, z + 2, Blocks.stonebrick, 0, 3);
        world.setBlock(x + 10, y + 7, z + 2, Blocks.bedrock, 0, 3);
        world.setBlock(x, y + 7, z + 3, Blocks.bedrock, 0, 3);
        world.setBlock(x + 1, y + 7, z + 3, Blocks.stonebrick, 0, 3);
        world.setBlock(x + 2, y + 7, z + 3, Blocks.stonebrick, 0, 3);
        world.setBlock(x + 3, y + 7, z + 3, Blocks.stonebrick, 0, 3);
        world.setBlock(x + 4, y + 7, z + 3, Blocks.stonebrick, 0, 3);
        world.setBlock(x + 5, y + 7, z + 3, Blocks.stonebrick, 0, 3);
        world.setBlock(x + 6, y + 7, z + 3, Blocks.stonebrick, 0, 3);
        world.setBlock(x + 7, y + 7, z + 3, Blocks.stonebrick, 0, 3);
        world.setBlock(x + 8, y + 7, z + 3, Blocks.stonebrick, 0, 3);
        world.setBlock(x + 9, y + 7, z + 3, Blocks.stonebrick, 0, 3);
        world.setBlock(x + 10, y + 7, z + 3, Blocks.bedrock, 0, 3);
        world.setBlock(x, y + 7, z + 4, Blocks.bedrock, 0, 3);
        world.setBlock(x + 1, y + 7, z + 4, Blocks.stonebrick, 0, 3);
        world.setBlock(x + 2, y + 7, z + 4, Blocks.stonebrick, 0, 3);
        world.setBlock(x + 3, y + 7, z + 4, Blocks.stonebrick, 0, 3);
        world.setBlock(x + 4, y + 7, z + 4, Blocks.stonebrick, 0, 3);
        world.setBlock(x + 5, y + 7, z + 4, Blocks.stonebrick, 0, 3);
        world.setBlock(x + 6, y + 7, z + 4, Blocks.stonebrick, 0, 3);
        world.setBlock(x + 7, y + 7, z + 4, Blocks.stonebrick, 0, 3);
        world.setBlock(x + 8, y + 7, z + 4, Blocks.stonebrick, 0, 3);
        world.setBlock(x + 9, y + 7, z + 4, Blocks.stonebrick, 0, 3);
        world.setBlock(x + 10, y + 7, z + 4, Blocks.bedrock, 0, 3);
        world.setBlock(x, y + 7, z + 5, Blocks.bedrock, 0, 3);
        world.setBlock(x + 1, y + 7, z + 5, Blocks.stonebrick, 0, 3);
        world.setBlock(x + 2, y + 7, z + 5, Blocks.stonebrick, 0, 3);
        world.setBlock(x + 3, y + 7, z + 5, Blocks.stonebrick, 0, 3);
        world.setBlock(x + 4, y + 7, z + 5, Blocks.stonebrick, 0, 3);
        world.setBlock(x + 5, y + 7, z + 5, Blocks.stonebrick, 0, 3);
        world.setBlock(x + 6, y + 7, z + 5, Blocks.stonebrick, 0, 3);
        world.setBlock(x + 7, y + 7, z + 5, Blocks.stonebrick, 0, 3);
        world.setBlock(x + 8, y + 7, z + 5, Blocks.stonebrick, 0, 3);
        world.setBlock(x + 9, y + 7, z + 5, Blocks.stonebrick, 0, 3);
        world.setBlock(x + 10, y + 7, z + 5, Blocks.bedrock, 0, 3);
        world.setBlock(x, y + 7, z + 6, Blocks.bedrock, 0, 3);
        world.setBlock(x + 1, y + 7, z + 6, Blocks.stonebrick, 0, 3);
        world.setBlock(x + 2, y + 7, z + 6, Blocks.stonebrick, 0, 3);
        world.setBlock(x + 3, y + 7, z + 6, Blocks.stonebrick, 0, 3);
        world.setBlock(x + 4, y + 7, z + 6, Blocks.stonebrick, 0, 3);
        world.setBlock(x + 5, y + 7, z + 6, Blocks.stonebrick, 0, 3);
        world.setBlock(x + 6, y + 7, z + 6, Blocks.stonebrick, 0, 3);
        world.setBlock(x + 7, y + 7, z + 6, Blocks.stonebrick, 0, 3);
        world.setBlock(x + 8, y + 7, z + 6, Blocks.stonebrick, 0, 3);
        world.setBlock(x + 9, y + 7, z + 6, Blocks.stonebrick, 0, 3);
        world.setBlock(x + 10, y + 7, z + 6, Blocks.bedrock, 0, 3);
        world.setBlock(x, y + 7, z + 7, Blocks.bedrock, 0, 3);
        world.setBlock(x + 1, y + 7, z + 7, Blocks.stonebrick, 0, 3);
        world.setBlock(x + 2, y + 7, z + 7, Blocks.stonebrick, 0, 3);
        world.setBlock(x + 3, y + 7, z + 7, Blocks.stonebrick, 0, 3);
        world.setBlock(x + 4, y + 7, z + 7, Blocks.stonebrick, 0, 3);
        world.setBlock(x + 5, y + 7, z + 7, Blocks.stonebrick, 0, 3);
        world.setBlock(x + 6, y + 7, z + 7, Blocks.stonebrick, 0, 3);
        world.setBlock(x + 7, y + 7, z + 7, Blocks.stonebrick, 0, 3);
        world.setBlock(x + 8, y + 7, z + 7, Blocks.stonebrick, 0, 3);
        world.setBlock(x + 9, y + 7, z + 7, Blocks.stonebrick, 0, 3);
        world.setBlock(x + 10, y + 7, z + 7, Blocks.bedrock, 0, 3);
        world.setBlock(x, y + 7, z + 8, Blocks.bedrock, 0, 3);
        world.setBlock(x + 1, y + 7, z + 8, Blocks.stonebrick, 0, 3);
        world.setBlock(x + 2, y + 7, z + 8, Blocks.stonebrick, 0, 3);
        world.setBlock(x + 3, y + 7, z + 8, Blocks.stonebrick, 0, 3);
        world.setBlock(x + 4, y + 7, z + 8, Blocks.stonebrick, 0, 3);
        world.setBlock(x + 5, y + 7, z + 8, Blocks.stonebrick, 0, 3);
        world.setBlock(x + 6, y + 7, z + 8, Blocks.stonebrick, 0, 3);
        world.setBlock(x + 7, y + 7, z + 8, Blocks.stonebrick, 0, 3);
        world.setBlock(x + 8, y + 7, z + 8, Blocks.stonebrick, 0, 3);
        world.setBlock(x + 9, y + 7, z + 8, Blocks.stonebrick, 0, 3);
        world.setBlock(x + 10, y + 7, z + 8, Blocks.bedrock, 0, 3);
        world.setBlock(x, y + 7, z + 9, Blocks.bedrock, 0, 3);
        world.setBlock(x + 1, y + 7, z + 9, Blocks.bedrock, 0, 3);
        world.setBlock(x + 2, y + 7, z + 9, Blocks.bedrock, 0, 3);
        world.setBlock(x + 3, y + 7, z + 9, Blocks.bedrock, 0, 3);
        world.setBlock(x + 4, y + 7, z + 9, Blocks.bedrock, 0, 3);
        world.setBlock(x + 5, y + 7, z + 9, Blocks.bedrock, 0, 3);
        world.setBlock(x + 6, y + 7, z + 9, Blocks.bedrock, 0, 3);
        world.setBlock(x + 7, y + 7, z + 9, Blocks.bedrock, 0, 3);
        world.setBlock(x + 8, y + 7, z + 9, Blocks.bedrock, 0, 3);
        world.setBlock(x + 9, y + 7, z + 9, Blocks.bedrock, 0, 3);
        world.setBlock(x + 10, y + 7, z + 9, Blocks.bedrock, 0, 3);
        world.setBlock(x, y + 8, z, Blocks.bedrock, 0, 3);
        world.setBlock(x + 1, y + 8, z, Blocks.bedrock, 0, 3);
        world.setBlock(x + 2, y + 8, z, Blocks.bedrock, 0, 3);
        world.setBlock(x + 3, y + 8, z, Blocks.bedrock, 0, 3);
        world.setBlock(x + 4, y + 8, z, Blocks.bedrock, 0, 3);
        world.setBlock(x + 5, y + 8, z, Blocks.bedrock, 0, 3);
        world.setBlock(x + 6, y + 8, z, Blocks.bedrock, 0, 3);
        world.setBlock(x + 7, y + 8, z, Blocks.bedrock, 0, 3);
        world.setBlock(x + 8, y + 8, z, Blocks.bedrock, 0, 3);
        world.setBlock(x + 9, y + 8, z, Blocks.bedrock, 0, 3);
        world.setBlock(x + 10, y + 8, z, Blocks.bedrock, 0, 3);
        world.setBlock(x, y + 8, z + 1, Blocks.bedrock, 0, 3);
        world.setBlock(x + 1, y + 8, z + 1, Blocks.bedrock, 0, 3);
        world.setBlock(x + 2, y + 8, z + 1, Blocks.bedrock, 0, 3);
        world.setBlock(x + 3, y + 8, z + 1, Blocks.bedrock, 0, 3);
        world.setBlock(x + 4, y + 8, z + 1, Blocks.bedrock, 0, 3);
        world.setBlock(x + 5, y + 8, z + 1, Blocks.bedrock, 0, 3);
        world.setBlock(x + 6, y + 8, z + 1, Blocks.bedrock, 0, 3);
        world.setBlock(x + 7, y + 8, z + 1, Blocks.bedrock, 0, 3);
        world.setBlock(x + 8, y + 8, z + 1, Blocks.bedrock, 0, 3);
        world.setBlock(x + 9, y + 8, z + 1, Blocks.bedrock, 0, 3);
        world.setBlock(x + 10, y + 8, z + 1, Blocks.bedrock, 0, 3);
        world.setBlock(x, y + 8, z + 2, Blocks.bedrock, 0, 3);
        world.setBlock(x + 1, y + 8, z + 2, Blocks.bedrock, 0, 3);
        world.setBlock(x + 2, y + 8, z + 2, Blocks.bedrock, 0, 3);
        world.setBlock(x + 3, y + 8, z + 2, Blocks.bedrock, 0, 3);
        world.setBlock(x + 4, y + 8, z + 2, Blocks.bedrock, 0, 3);
        world.setBlock(x + 5, y + 8, z + 2, Blocks.bedrock, 0, 3);
        world.setBlock(x + 6, y + 8, z + 2, Blocks.bedrock, 0, 3);
        world.setBlock(x + 7, y + 8, z + 2, Blocks.bedrock, 0, 3);
        world.setBlock(x + 8, y + 8, z + 2, Blocks.bedrock, 0, 3);
        world.setBlock(x + 9, y + 8, z + 2, Blocks.bedrock, 0, 3);
        world.setBlock(x + 10, y + 8, z + 2, Blocks.bedrock, 0, 3);
        world.setBlock(x, y + 8, z + 3, Blocks.bedrock, 0, 3);
        world.setBlock(x + 1, y + 8, z + 3, Blocks.bedrock, 0, 3);
        world.setBlock(x + 2, y + 8, z + 3, Blocks.bedrock, 0, 3);
        world.setBlock(x + 3, y + 8, z + 3, Blocks.bedrock, 0, 3);
        world.setBlock(x + 4, y + 8, z + 3, Blocks.bedrock, 0, 3);
        world.setBlock(x + 5, y + 8, z + 3, Blocks.bedrock, 0, 3);
        world.setBlock(x + 6, y + 8, z + 3, Blocks.bedrock, 0, 3);
        world.setBlock(x + 7, y + 8, z + 3, Blocks.bedrock, 0, 3);
        world.setBlock(x + 8, y + 8, z + 3, Blocks.bedrock, 0, 3);
        world.setBlock(x + 9, y + 8, z + 3, Blocks.bedrock, 0, 3);
        world.setBlock(x + 10, y + 8, z + 3, Blocks.bedrock, 0, 3);
        world.setBlock(x, y + 8, z + 4, Blocks.bedrock, 0, 3);
        world.setBlock(x + 1, y + 8, z + 4, Blocks.bedrock, 0, 3);
        world.setBlock(x + 2, y + 8, z + 4, Blocks.bedrock, 0, 3);
        world.setBlock(x + 3, y + 8, z + 4, Blocks.bedrock, 0, 3);
        world.setBlock(x + 4, y + 8, z + 4, Blocks.bedrock, 0, 3);
        world.setBlock(x + 5, y + 8, z + 4, Blocks.bedrock, 0, 3);
        world.setBlock(x + 6, y + 8, z + 4, Blocks.bedrock, 0, 3);
        world.setBlock(x + 7, y + 8, z + 4, Blocks.bedrock, 0, 3);
        world.setBlock(x + 8, y + 8, z + 4, Blocks.bedrock, 0, 3);
        world.setBlock(x + 9, y + 8, z + 4, Blocks.bedrock, 0, 3);
        world.setBlock(x + 10, y + 8, z + 4, Blocks.bedrock, 0, 3);
        world.setBlock(x, y + 8, z + 5, Blocks.bedrock, 0, 3);
        world.setBlock(x + 1, y + 8, z + 5, Blocks.bedrock, 0, 3);
        world.setBlock(x + 2, y + 8, z + 5, Blocks.bedrock, 0, 3);
        world.setBlock(x + 3, y + 8, z + 5, Blocks.bedrock, 0, 3);
        world.setBlock(x + 4, y + 8, z + 5, Blocks.bedrock, 0, 3);
        world.setBlock(x + 5, y + 8, z + 5, Blocks.bedrock, 0, 3);
        world.setBlock(x + 6, y + 8, z + 5, Blocks.bedrock, 0, 3);
        world.setBlock(x + 7, y + 8, z + 5, Blocks.bedrock, 0, 3);
        world.setBlock(x + 8, y + 8, z + 5, Blocks.bedrock, 0, 3);
        world.setBlock(x + 9, y + 8, z + 5, Blocks.bedrock, 0, 3);
        world.setBlock(x + 10, y + 8, z + 5, Blocks.bedrock, 0, 3);
        world.setBlock(x, y + 8, z + 6, Blocks.bedrock, 0, 3);
        world.setBlock(x + 1, y + 8, z + 6, Blocks.bedrock, 0, 3);
        world.setBlock(x + 2, y + 8, z + 6, Blocks.bedrock, 0, 3);
        world.setBlock(x + 3, y + 8, z + 6, Blocks.bedrock, 0, 3);
        world.setBlock(x + 4, y + 8, z + 6, Blocks.bedrock, 0, 3);
        world.setBlock(x + 5, y + 8, z + 6, Blocks.bedrock, 0, 3);
        world.setBlock(x + 6, y + 8, z + 6, Blocks.bedrock, 0, 3);
        world.setBlock(x + 7, y + 8, z + 6, Blocks.bedrock, 0, 3);
        world.setBlock(x + 8, y + 8, z + 6, Blocks.bedrock, 0, 3);
        world.setBlock(x + 9, y + 8, z + 6, Blocks.bedrock, 0, 3);
        world.setBlock(x + 10, y + 8, z + 6, Blocks.bedrock, 0, 3);
        world.setBlock(x, y + 8, z + 7, Blocks.bedrock, 0, 3);
        world.setBlock(x + 1, y + 8, z + 7, Blocks.bedrock, 0, 3);
        world.setBlock(x + 2, y + 8, z + 7, Blocks.bedrock, 0, 3);
        world.setBlock(x + 3, y + 8, z + 7, Blocks.bedrock, 0, 3);
        world.setBlock(x + 4, y + 8, z + 7, Blocks.bedrock, 0, 3);
        world.setBlock(x + 5, y + 8, z + 7, Blocks.bedrock, 0, 3);
        world.setBlock(x + 6, y + 8, z + 7, Blocks.bedrock, 0, 3);
        world.setBlock(x + 7, y + 8, z + 7, Blocks.bedrock, 0, 3);
        world.setBlock(x + 8, y + 8, z + 7, Blocks.bedrock, 0, 3);
        world.setBlock(x + 9, y + 8, z + 7, Blocks.bedrock, 0, 3);
        world.setBlock(x + 10, y + 8, z + 7, Blocks.bedrock, 0, 3);
        world.setBlock(x, y + 8, z + 8, Blocks.bedrock, 0, 3);
        world.setBlock(x + 1, y + 8, z + 8, Blocks.bedrock, 0, 3);
        world.setBlock(x + 2, y + 8, z + 8, Blocks.bedrock, 0, 3);
        world.setBlock(x + 3, y + 8, z + 8, Blocks.bedrock, 0, 3);
        world.setBlock(x + 4, y + 8, z + 8, Blocks.bedrock, 0, 3);
        world.setBlock(x + 5, y + 8, z + 8, Blocks.bedrock, 0, 3);
        world.setBlock(x + 6, y + 8, z + 8, Blocks.bedrock, 0, 3);
        world.setBlock(x + 7, y + 8, z + 8, Blocks.bedrock, 0, 3);
        world.setBlock(x + 8, y + 8, z + 8, Blocks.bedrock, 0, 3);
        world.setBlock(x + 9, y + 8, z + 8, Blocks.bedrock, 0, 3);
        world.setBlock(x + 10, y + 8, z + 8, Blocks.bedrock, 0, 3);
        world.setBlock(x, y + 8, z + 9, Blocks.bedrock, 0, 3);
        world.setBlock(x + 1, y + 8, z + 9, Blocks.bedrock, 0, 3);
        world.setBlock(x + 2, y + 8, z + 9, Blocks.bedrock, 0, 3);
        world.setBlock(x + 3, y + 8, z + 9, Blocks.bedrock, 0, 3);
        world.setBlock(x + 4, y + 8, z + 9, Blocks.bedrock, 0, 3);
        world.setBlock(x + 5, y + 8, z + 9, Blocks.bedrock, 0, 3);
        world.setBlock(x + 6, y + 8, z + 9, Blocks.bedrock, 0, 3);
        world.setBlock(x + 7, y + 8, z + 9, Blocks.bedrock, 0, 3);
        world.setBlock(x + 8, y + 8, z + 9, Blocks.bedrock, 0, 3);
        world.setBlock(x + 9, y + 8, z + 9, Blocks.bedrock, 0, 3);
        world.setBlock(x + 10, y + 8, z + 9, Blocks.bedrock, 0, 3);

        generate_r02_last(world, rand, pos);
        return true;

    }

    public boolean generate_r02_last(World world, Random rand, BlockPos pos) {

        world.setBlock(x + 3, y + 2, z + 2, Blocks.redstone_torch, 3, 3);
        world.setBlock(x + 7, y + 2, z + 2, Blocks.redstone_torch, 3, 3);
        world.setBlock(x + 2, y + 2, z + 3, Blocks.redstone_torch, 1, 3);
        world.setBlock(x + 8, y + 2, z + 3, Blocks.redstone_torch, 2, 3);
        world.setBlock(x + 2, y + 2, z + 6, Blocks.redstone_torch, 1, 3);
        world.setBlock(x + 8, y + 2, z + 6, Blocks.redstone_torch, 2, 3);
        world.setBlock(x + 3, y + 2, z + 7, Blocks.redstone_torch, 4, 3);
        world.setBlock(x + 7, y + 2, z + 7, Blocks.redstone_torch, 4, 3);
        return true;

    }

}