package fossilsarcheology.server.gen.feature;

import java.util.Random;

import fossilsarcheology.server.block.FABlockRegistry;
import net.minecraft.init.Blocks;
import net.minecraft.world.World;
import net.minecraft.world.gen.feature.WorldGenerator;

public class MoaiWorldGen extends WorldGenerator {
	private boolean generateHat;

	public boolean generate(World world, Random rand, int x, int y, int z) {
		int i = rand.nextInt(4);
		generateHat = rand.nextBoolean();
		if (i == 0) {
			generate_r0(world, rand, x, y, z);
		}

		if (i == 1) {
			generate_r1(world, rand, x, y, z);
		}

		if (i == 2) {
			generate_r2(world, rand, x, y, z);
		}

		if (i == 3) {
			generate_r3(world, rand, x, y, z);
		}

		return true;

	}

	public boolean generate_r0(World world, Random rand, int x, int y, int z) {
		world.setBlock(x + 0, y + 0, z + 0, FABlockRegistry.INSTANCE.ancientStone, 0, 3);
		world.setBlock(x + 1, y + 0, z + 0, FABlockRegistry.INSTANCE.ancientStone, 0, 3);
		world.setBlock(x + 2, y + 0, z + 0, FABlockRegistry.INSTANCE.ancientStone, 0, 3);
		world.setBlock(x + 3, y + 0, z + 0, FABlockRegistry.INSTANCE.ancientStone, 0, 3);
		world.setBlock(x + 4, y + 0, z + 0, FABlockRegistry.INSTANCE.ancientStone, 0, 3);
		world.setBlock(x + 0, y + 0, z + 1, FABlockRegistry.INSTANCE.ancientStone, 0, 3);
		world.setBlock(x + 1, y + 0, z + 1, FABlockRegistry.INSTANCE.ancientStone, 0, 3);
		world.setBlock(x + 2, y + 0, z + 1, FABlockRegistry.INSTANCE.ancientStone, 0, 3);
		world.setBlock(x + 3, y + 0, z + 1, FABlockRegistry.INSTANCE.ancientStone, 0, 3);
		world.setBlock(x + 4, y + 0, z + 1, FABlockRegistry.INSTANCE.ancientStone, 0, 3);
		world.setBlock(x + 0, y + 1, z + 0, FABlockRegistry.INSTANCE.ancientStone, 0, 3);
		world.setBlock(x + 1, y + 1, z + 0, FABlockRegistry.INSTANCE.ancientStonebrick, 0, 3);
		world.setBlock(x + 2, y + 1, z + 0, FABlockRegistry.INSTANCE.ancientStonebrick, 0, 3);
		world.setBlock(x + 3, y + 1, z + 0, FABlockRegistry.INSTANCE.ancientStonebrick, 0, 3);
		world.setBlock(x + 4, y + 1, z + 0, FABlockRegistry.INSTANCE.ancientStone, 0, 3);
		world.setBlock(x + 0, y + 1, z + 1, FABlockRegistry.INSTANCE.ancientStone, 0, 3);
		world.setBlock(x + 1, y + 1, z + 1, FABlockRegistry.INSTANCE.ancientStonebrick, 0, 3);
		world.setBlock(x + 2, y + 1, z + 1, FABlockRegistry.INSTANCE.ancientStone, 0, 3);
		world.setBlock(x + 3, y + 1, z + 1, FABlockRegistry.INSTANCE.ancientStonebrick, 0, 3);
		world.setBlock(x + 4, y + 1, z + 1, FABlockRegistry.INSTANCE.ancientStone, 0, 3);
		world.setBlock(x + 0, y + 2, z + 0, FABlockRegistry.INSTANCE.ancientStone, 0, 3);
		world.setBlock(x + 1, y + 2, z + 0, FABlockRegistry.INSTANCE.ancientStonebrick, 0, 3);
		world.setBlock(x + 2, y + 2, z + 0, FABlockRegistry.INSTANCE.ancientStone, 0, 3);
		world.setBlock(x + 3, y + 2, z + 0, FABlockRegistry.INSTANCE.ancientStonebrick, 0, 3);
		world.setBlock(x + 4, y + 2, z + 0, FABlockRegistry.INSTANCE.ancientStone, 0, 3);
		world.setBlock(x + 0, y + 2, z + 1, FABlockRegistry.INSTANCE.ancientStone, 0, 3);
		world.setBlock(x + 1, y + 2, z + 1, FABlockRegistry.INSTANCE.ancientStone, 0, 3);
		world.setBlock(x + 2, y + 2, z + 1, FABlockRegistry.INSTANCE.ancientStonebrick, 0, 3);
		world.setBlock(x + 3, y + 2, z + 1, FABlockRegistry.INSTANCE.ancientStone, 0, 3);
		world.setBlock(x + 4, y + 2, z + 1, FABlockRegistry.INSTANCE.ancientStone, 0, 3);
		world.setBlock(x + 0, y + 3, z + 0, FABlockRegistry.INSTANCE.ancientStone, 0, 3);
		world.setBlock(x + 1, y + 3, z + 0, FABlockRegistry.INSTANCE.ancientStone, 0, 3);
		world.setBlock(x + 2, y + 3, z + 0, FABlockRegistry.INSTANCE.ancientStonebrick, 0, 3);
		world.setBlock(x + 3, y + 3, z + 0, FABlockRegistry.INSTANCE.ancientStone, 0, 3);
		world.setBlock(x + 4, y + 3, z + 0, FABlockRegistry.INSTANCE.ancientStone, 0, 3);
		world.setBlock(x + 0, y + 3, z + 1, FABlockRegistry.INSTANCE.ancientStone, 0, 3);
		world.setBlock(x + 1, y + 3, z + 1, FABlockRegistry.INSTANCE.ancientStonebrick, 0, 3);
		world.setBlock(x + 2, y + 3, z + 1, FABlockRegistry.INSTANCE.ancientStonebrick, 0, 3);
		world.setBlock(x + 3, y + 3, z + 1, FABlockRegistry.INSTANCE.ancientStonebrick, 0, 3);
		world.setBlock(x + 4, y + 3, z + 1, FABlockRegistry.INSTANCE.ancientStone, 0, 3);
		world.setBlock(x + 0, y + 4, z + 0, FABlockRegistry.INSTANCE.ancientStone, 0, 3);
		world.setBlock(x + 1, y + 4, z + 0, FABlockRegistry.INSTANCE.ancientStone, 0, 3);
		world.setBlock(x + 2, y + 4, z + 0, FABlockRegistry.INSTANCE.ancientStonebrick, 0, 3);
		world.setBlock(x + 3, y + 4, z + 0, FABlockRegistry.INSTANCE.ancientStone, 0, 3);
		world.setBlock(x + 4, y + 4, z + 0, FABlockRegistry.INSTANCE.ancientStone, 0, 3);
		world.setBlock(x + 0, y + 4, z + 1, FABlockRegistry.INSTANCE.ancientStone, 0, 3);
		world.setBlock(x + 1, y + 4, z + 1, FABlockRegistry.INSTANCE.ancientStone, 0, 3);
		world.setBlock(x + 2, y + 4, z + 1, FABlockRegistry.INSTANCE.ancientStonebrick, 0, 3);
		world.setBlock(x + 3, y + 4, z + 1, FABlockRegistry.INSTANCE.ancientStone, 0, 3);
		world.setBlock(x + 4, y + 4, z + 1, FABlockRegistry.INSTANCE.ancientStone, 0, 3);
		world.setBlock(x + 1, y + 5, z + 0, FABlockRegistry.INSTANCE.ancientStone, 0, 3);
		world.setBlock(x + 2, y + 5, z + 0, FABlockRegistry.INSTANCE.ancientStonebrick, 0, 3);
		world.setBlock(x + 3, y + 5, z + 0, FABlockRegistry.INSTANCE.ancientStone, 0, 3);
		world.setBlock(x + 1, y + 5, z + 1, FABlockRegistry.INSTANCE.ancientStone, 0, 3);
		world.setBlock(x + 2, y + 5, z + 1, FABlockRegistry.INSTANCE.ancientStone, 0, 3);
		world.setBlock(x + 3, y + 5, z + 1, FABlockRegistry.INSTANCE.ancientStone, 0, 3);
		world.setBlock(x + 1, y + 6, z + 0, FABlockRegistry.INSTANCE.ancientStone, 0, 3);
		world.setBlock(x + 2, y + 6, z + 0, FABlockRegistry.INSTANCE.ancientStone, 0, 3);
		world.setBlock(x + 3, y + 6, z + 0, FABlockRegistry.INSTANCE.ancientStone, 0, 3);
		world.setBlock(x + 1, y + 6, z + 1, FABlockRegistry.INSTANCE.ancientStone, 0, 3);
		world.setBlock(x + 3, y + 6, z + 1, FABlockRegistry.INSTANCE.ancientStone, 0, 3);
		world.setBlock(x + 1, y + 6, z + 2, FABlockRegistry.INSTANCE.ancientStone, 0, 3);
		world.setBlock(x + 2, y + 6, z + 2, FABlockRegistry.INSTANCE.ancientStone, 0, 3);
		world.setBlock(x + 3, y + 6, z + 2, FABlockRegistry.INSTANCE.ancientStone, 0, 3);
		world.setBlock(x + 1, y + 7, z + 0, FABlockRegistry.INSTANCE.ancientStone, 0, 3);
		world.setBlock(x + 2, y + 7, z + 0, FABlockRegistry.INSTANCE.ancientStone, 0, 3);
		world.setBlock(x + 3, y + 7, z + 0, FABlockRegistry.INSTANCE.ancientStone, 0, 3);
		world.setBlock(x + 1, y + 7, z + 1, FABlockRegistry.INSTANCE.ancientStone, 0, 3);
		world.setBlock(x + 2, y + 7, z + 1, FABlockRegistry.INSTANCE.ancientStone, 0, 3);
		world.setBlock(x + 3, y + 7, z + 1, FABlockRegistry.INSTANCE.ancientStone, 0, 3);
		world.setBlock(x + 1, y + 7, z + 2, FABlockRegistry.INSTANCE.ancientStone, 0, 3);
		world.setBlock(x + 2, y + 7, z + 2, FABlockRegistry.INSTANCE.ancientStone, 0, 3);
		world.setBlock(x + 3, y + 7, z + 2, FABlockRegistry.INSTANCE.ancientStone, 0, 3);
		world.setBlock(x + 0, y + 8, z + 0, FABlockRegistry.INSTANCE.ancientStoneStairs, 4, 3);
		world.setBlock(x + 1, y + 8, z + 0, FABlockRegistry.INSTANCE.ancientStone, 0, 3);
		world.setBlock(x + 2, y + 8, z + 0, FABlockRegistry.INSTANCE.ancientStone, 0, 3);
		world.setBlock(x + 3, y + 8, z + 0, FABlockRegistry.INSTANCE.ancientStone, 0, 3);
		world.setBlock(x + 4, y + 8, z + 0, FABlockRegistry.INSTANCE.ancientStoneStairs, 5, 3);
		world.setBlock(x + 1, y + 8, z + 1, FABlockRegistry.INSTANCE.ancientStone, 0, 3);
		world.setBlock(x + 2, y + 8, z + 1, FABlockRegistry.INSTANCE.ancientStone, 0, 3);
		world.setBlock(x + 3, y + 8, z + 1, FABlockRegistry.INSTANCE.ancientStone, 0, 3);
		world.setBlock(x + 1, y + 8, z + 2, FABlockRegistry.INSTANCE.ancientStoneStairs, 7, 3);
		world.setBlock(x + 2, y + 8, z + 2, FABlockRegistry.INSTANCE.ancientStoneStairs, 7, 3);
		world.setBlock(x + 3, y + 8, z + 2, FABlockRegistry.INSTANCE.ancientStoneStairs, 7, 3);
		world.setBlock(x + 0, y + 9, z + 0, FABlockRegistry.INSTANCE.ancientStone, 0, 3);
		world.setBlock(x + 1, y + 9, z + 0, FABlockRegistry.INSTANCE.ancientStone, 0, 3);
		world.setBlock(x + 2, y + 9, z + 0, FABlockRegistry.INSTANCE.ancientStone, 0, 3);
		world.setBlock(x + 3, y + 9, z + 0, FABlockRegistry.INSTANCE.ancientStone, 0, 3);
		world.setBlock(x + 4, y + 9, z + 0, FABlockRegistry.INSTANCE.ancientStone, 0, 3);
		world.setBlock(x + 1, y + 9, z + 1, FABlockRegistry.INSTANCE.ancientStone, 0, 3);
		world.setBlock(x + 2, y + 9, z + 1, FABlockRegistry.INSTANCE.ancientStone, 0, 3);
		world.setBlock(x + 3, y + 9, z + 1, FABlockRegistry.INSTANCE.ancientStone, 0, 3);
		world.setBlock(x + 1, y + 9, z + 2, FABlockRegistry.INSTANCE.ancientStone, 0, 3);
		world.setBlock(x + 2, y + 9, z + 2, FABlockRegistry.INSTANCE.ancientStone, 0, 3);
		world.setBlock(x + 3, y + 9, z + 2, FABlockRegistry.INSTANCE.ancientStone, 0, 3);
		world.setBlock(x + 2, y + 9, z + 3, FABlockRegistry.INSTANCE.ancientStone, 0, 3);
		world.setBlock(x + 0, y + 10, z + 0, FABlockRegistry.INSTANCE.ancientStone, 0, 3);
		world.setBlock(x + 1, y + 10, z + 0, FABlockRegistry.INSTANCE.ancientStone, 0, 3);
		world.setBlock(x + 2, y + 10, z + 0, FABlockRegistry.INSTANCE.ancientStone, 0, 3);
		world.setBlock(x + 3, y + 10, z + 0, FABlockRegistry.INSTANCE.ancientStone, 0, 3);
		world.setBlock(x + 4, y + 10, z + 0, FABlockRegistry.INSTANCE.ancientStone, 0, 3);
		world.setBlock(x + 1, y + 10, z + 1, FABlockRegistry.INSTANCE.ancientStone, 0, 3);
		world.setBlock(x + 2, y + 10, z + 1, FABlockRegistry.INSTANCE.ancientStone, 0, 3);
		world.setBlock(x + 3, y + 10, z + 1, FABlockRegistry.INSTANCE.ancientStone, 0, 3);
		world.setBlock(x + 1, y + 10, z + 2, FABlockRegistry.INSTANCE.ancientStone, 0, 3);
		world.setBlock(x + 2, y + 10, z + 2, FABlockRegistry.INSTANCE.ancientStone, 0, 3);
		world.setBlock(x + 3, y + 10, z + 2, FABlockRegistry.INSTANCE.ancientStone, 0, 3);
		world.setBlock(x + 2, y + 10, z + 3, FABlockRegistry.INSTANCE.ancientStone, 0, 3);
		world.setBlock(x + 0, y + 11, z + 0, FABlockRegistry.INSTANCE.ancientStoneStairs, 0, 3);
		world.setBlock(x + 1, y + 11, z + 0, FABlockRegistry.INSTANCE.ancientStone, 0, 3);
		world.setBlock(x + 2, y + 11, z + 0, FABlockRegistry.INSTANCE.ancientStone, 0, 3);
		world.setBlock(x + 3, y + 11, z + 0, FABlockRegistry.INSTANCE.ancientStone, 0, 3);
		world.setBlock(x + 4, y + 11, z + 0, FABlockRegistry.INSTANCE.ancientStoneStairs, 1, 3);
		world.setBlock(x + 1, y + 11, z + 1, FABlockRegistry.INSTANCE.ancientStone, 0, 3);
		world.setBlock(x + 2, y + 11, z + 1, FABlockRegistry.INSTANCE.ancientStone, 0, 3);
		world.setBlock(x + 3, y + 11, z + 1, FABlockRegistry.INSTANCE.ancientStone, 0, 3);
		world.setBlock(x + 1, y + 11, z + 2, FABlockRegistry.INSTANCE.ancientStoneStairs, 3, 3);
		world.setBlock(x + 2, y + 11, z + 2, FABlockRegistry.INSTANCE.ancientStone, 0, 3);
		world.setBlock(x + 3, y + 11, z + 2, FABlockRegistry.INSTANCE.ancientStoneStairs, 3, 3);
		world.setBlock(x + 2, y + 11, z + 3, FABlockRegistry.INSTANCE.ancientStoneStairs, 3, 3);
		world.setBlock(x + 1, y + 12, z + 0, FABlockRegistry.INSTANCE.ancientStone, 0, 3);
		world.setBlock(x + 2, y + 12, z + 0, FABlockRegistry.INSTANCE.ancientStone, 0, 3);
		world.setBlock(x + 3, y + 12, z + 0, FABlockRegistry.INSTANCE.ancientStone, 0, 3);
		world.setBlock(x + 1, y + 12, z + 1, FABlockRegistry.INSTANCE.ancientStone, 0, 3);
		world.setBlock(x + 2, y + 12, z + 1, FABlockRegistry.INSTANCE.ancientStone, 0, 3);
		world.setBlock(x + 3, y + 12, z + 1, FABlockRegistry.INSTANCE.ancientStone, 0, 3);
		world.setBlock(x + 1, y + 12, z + 2, FABlockRegistry.INSTANCE.ancientStoneStairs, 7, 3);
		world.setBlock(x + 2, y + 12, z + 2, FABlockRegistry.INSTANCE.ancientStone, 0, 3);
		world.setBlock(x + 3, y + 12, z + 2, FABlockRegistry.INSTANCE.ancientStoneStairs, 7, 3);
		world.setBlock(x + 1, y + 13, z + 0, FABlockRegistry.INSTANCE.ancientStone, 0, 3);
		world.setBlock(x + 2, y + 13, z + 0, FABlockRegistry.INSTANCE.ancientStone, 0, 3);
		world.setBlock(x + 3, y + 13, z + 0, FABlockRegistry.INSTANCE.ancientStone, 0, 3);
		world.setBlock(x + 1, y + 13, z + 1, FABlockRegistry.INSTANCE.ancientStone, 0, 3);
		world.setBlock(x + 2, y + 13, z + 1, FABlockRegistry.INSTANCE.ancientStone, 0, 3);
		world.setBlock(x + 3, y + 13, z + 1, FABlockRegistry.INSTANCE.ancientStone, 0, 3);
		world.setBlock(x + 1, y + 13, z + 2, FABlockRegistry.INSTANCE.ancientStoneStairs, 3, 3);
		world.setBlock(x + 2, y + 13, z + 2, FABlockRegistry.INSTANCE.ancientStoneStairs, 3, 3);
		world.setBlock(x + 3, y + 13, z + 2, FABlockRegistry.INSTANCE.ancientStoneStairs, 3, 3);
		if (generateHat) {
			world.setBlock(x + 1, y + 14, z + 0, Blocks.hardened_clay, 0, 3);
			world.setBlock(x + 2, y + 14, z + 0, Blocks.hardened_clay, 0, 3);
			world.setBlock(x + 3, y + 14, z + 0, Blocks.hardened_clay, 0, 3);
			world.setBlock(x + 1, y + 14, z + 1, Blocks.hardened_clay, 0, 3);
			world.setBlock(x + 2, y + 14, z + 1, Blocks.hardened_clay, 0, 3);
			world.setBlock(x + 3, y + 14, z + 1, Blocks.hardened_clay, 0, 3);
			world.setBlock(x + 1, y + 14, z + 2, Blocks.hardened_clay, 0, 3);
			world.setBlock(x + 2, y + 14, z + 2, Blocks.hardened_clay, 0, 3);
			world.setBlock(x + 3, y + 14, z + 2, Blocks.hardened_clay, 0, 3);
			world.setBlock(x + 1, y + 15, z + 0, Blocks.hardened_clay, 0, 3);
			world.setBlock(x + 2, y + 15, z + 0, Blocks.hardened_clay, 0, 3);
			world.setBlock(x + 3, y + 15, z + 0, Blocks.hardened_clay, 0, 3);
			world.setBlock(x + 1, y + 15, z + 1, Blocks.hardened_clay, 0, 3);
			world.setBlock(x + 2, y + 15, z + 1, Blocks.hardened_clay, 0, 3);
			world.setBlock(x + 3, y + 15, z + 1, Blocks.hardened_clay, 0, 3);
			world.setBlock(x + 1, y + 15, z + 2, Blocks.hardened_clay, 0, 3);
			world.setBlock(x + 2, y + 15, z + 2, Blocks.hardened_clay, 0, 3);
			world.setBlock(x + 3, y + 15, z + 2, Blocks.hardened_clay, 0, 3);
			world.setBlock(x + 2, y + 16, z + 1, Blocks.hardened_clay, 0, 3);
		}
		return true;

	}

	public boolean generate_r1(World world, Random rand, int x, int y, int z) {
		world.setBlock(x + 0, y + 0, z + 4, FABlockRegistry.INSTANCE.ancientStone, 0, 3);
		world.setBlock(x + 0, y + 0, z + 3, FABlockRegistry.INSTANCE.ancientStone, 0, 3);
		world.setBlock(x + 0, y + 0, z + 2, FABlockRegistry.INSTANCE.ancientStone, 0, 3);
		world.setBlock(x + 0, y + 0, z + 1, FABlockRegistry.INSTANCE.ancientStone, 0, 3);
		world.setBlock(x + 0, y + 0, z + 0, FABlockRegistry.INSTANCE.ancientStone, 0, 3);
		world.setBlock(x + 1, y + 0, z + 4, FABlockRegistry.INSTANCE.ancientStone, 0, 3);
		world.setBlock(x + 1, y + 0, z + 3, FABlockRegistry.INSTANCE.ancientStone, 0, 3);
		world.setBlock(x + 1, y + 0, z + 2, FABlockRegistry.INSTANCE.ancientStone, 0, 3);
		world.setBlock(x + 1, y + 0, z + 1, FABlockRegistry.INSTANCE.ancientStone, 0, 3);
		world.setBlock(x + 1, y + 0, z + 0, FABlockRegistry.INSTANCE.ancientStone, 0, 3);
		world.setBlock(x + 0, y + 1, z + 4, FABlockRegistry.INSTANCE.ancientStone, 0, 3);
		world.setBlock(x + 0, y + 1, z + 3, FABlockRegistry.INSTANCE.ancientStonebrick, 0, 3);
		world.setBlock(x + 0, y + 1, z + 2, FABlockRegistry.INSTANCE.ancientStonebrick, 0, 3);
		world.setBlock(x + 0, y + 1, z + 1, FABlockRegistry.INSTANCE.ancientStonebrick, 0, 3);
		world.setBlock(x + 0, y + 1, z + 0, FABlockRegistry.INSTANCE.ancientStone, 0, 3);
		world.setBlock(x + 1, y + 1, z + 4, FABlockRegistry.INSTANCE.ancientStone, 0, 3);
		world.setBlock(x + 1, y + 1, z + 3, FABlockRegistry.INSTANCE.ancientStonebrick, 0, 3);
		world.setBlock(x + 1, y + 1, z + 2, FABlockRegistry.INSTANCE.ancientStone, 0, 3);
		world.setBlock(x + 1, y + 1, z + 1, FABlockRegistry.INSTANCE.ancientStonebrick, 0, 3);
		world.setBlock(x + 1, y + 1, z + 0, FABlockRegistry.INSTANCE.ancientStone, 0, 3);
		world.setBlock(x + 0, y + 2, z + 4, FABlockRegistry.INSTANCE.ancientStone, 0, 3);
		world.setBlock(x + 0, y + 2, z + 3, FABlockRegistry.INSTANCE.ancientStonebrick, 0, 3);
		world.setBlock(x + 0, y + 2, z + 2, FABlockRegistry.INSTANCE.ancientStone, 0, 3);
		world.setBlock(x + 0, y + 2, z + 1, FABlockRegistry.INSTANCE.ancientStonebrick, 0, 3);
		world.setBlock(x + 0, y + 2, z + 0, FABlockRegistry.INSTANCE.ancientStone, 0, 3);
		world.setBlock(x + 1, y + 2, z + 4, FABlockRegistry.INSTANCE.ancientStone, 0, 3);
		world.setBlock(x + 1, y + 2, z + 3, FABlockRegistry.INSTANCE.ancientStone, 0, 3);
		world.setBlock(x + 1, y + 2, z + 2, FABlockRegistry.INSTANCE.ancientStonebrick, 0, 3);
		world.setBlock(x + 1, y + 2, z + 1, FABlockRegistry.INSTANCE.ancientStone, 0, 3);
		world.setBlock(x + 1, y + 2, z + 0, FABlockRegistry.INSTANCE.ancientStone, 0, 3);
		world.setBlock(x + 0, y + 3, z + 4, FABlockRegistry.INSTANCE.ancientStone, 0, 3);
		world.setBlock(x + 0, y + 3, z + 3, FABlockRegistry.INSTANCE.ancientStone, 0, 3);
		world.setBlock(x + 0, y + 3, z + 2, FABlockRegistry.INSTANCE.ancientStonebrick, 0, 3);
		world.setBlock(x + 0, y + 3, z + 1, FABlockRegistry.INSTANCE.ancientStone, 0, 3);
		world.setBlock(x + 0, y + 3, z + 0, FABlockRegistry.INSTANCE.ancientStone, 0, 3);
		world.setBlock(x + 1, y + 3, z + 4, FABlockRegistry.INSTANCE.ancientStone, 0, 3);
		world.setBlock(x + 1, y + 3, z + 3, FABlockRegistry.INSTANCE.ancientStonebrick, 0, 3);
		world.setBlock(x + 1, y + 3, z + 2, FABlockRegistry.INSTANCE.ancientStonebrick, 0, 3);
		world.setBlock(x + 1, y + 3, z + 1, FABlockRegistry.INSTANCE.ancientStonebrick, 0, 3);
		world.setBlock(x + 1, y + 3, z + 0, FABlockRegistry.INSTANCE.ancientStone, 0, 3);
		world.setBlock(x + 0, y + 4, z + 4, FABlockRegistry.INSTANCE.ancientStone, 0, 3);
		world.setBlock(x + 0, y + 4, z + 3, FABlockRegistry.INSTANCE.ancientStone, 0, 3);
		world.setBlock(x + 0, y + 4, z + 2, FABlockRegistry.INSTANCE.ancientStonebrick, 0, 3);
		world.setBlock(x + 0, y + 4, z + 1, FABlockRegistry.INSTANCE.ancientStone, 0, 3);
		world.setBlock(x + 0, y + 4, z + 0, FABlockRegistry.INSTANCE.ancientStone, 0, 3);
		world.setBlock(x + 1, y + 4, z + 4, FABlockRegistry.INSTANCE.ancientStone, 0, 3);
		world.setBlock(x + 1, y + 4, z + 3, FABlockRegistry.INSTANCE.ancientStone, 0, 3);
		world.setBlock(x + 1, y + 4, z + 2, FABlockRegistry.INSTANCE.ancientStonebrick, 0, 3);
		world.setBlock(x + 1, y + 4, z + 1, FABlockRegistry.INSTANCE.ancientStone, 0, 3);
		world.setBlock(x + 1, y + 4, z + 0, FABlockRegistry.INSTANCE.ancientStone, 0, 3);
		world.setBlock(x + 0, y + 5, z + 3, FABlockRegistry.INSTANCE.ancientStone, 0, 3);
		world.setBlock(x + 0, y + 5, z + 2, FABlockRegistry.INSTANCE.ancientStonebrick, 0, 3);
		world.setBlock(x + 0, y + 5, z + 1, FABlockRegistry.INSTANCE.ancientStone, 0, 3);
		world.setBlock(x + 1, y + 5, z + 3, FABlockRegistry.INSTANCE.ancientStone, 0, 3);
		world.setBlock(x + 1, y + 5, z + 2, FABlockRegistry.INSTANCE.ancientStone, 0, 3);
		world.setBlock(x + 1, y + 5, z + 1, FABlockRegistry.INSTANCE.ancientStone, 0, 3);
		world.setBlock(x + 0, y + 6, z + 3, FABlockRegistry.INSTANCE.ancientStone, 0, 3);
		world.setBlock(x + 0, y + 6, z + 2, FABlockRegistry.INSTANCE.ancientStone, 0, 3);
		world.setBlock(x + 0, y + 6, z + 1, FABlockRegistry.INSTANCE.ancientStone, 0, 3);
		world.setBlock(x + 1, y + 6, z + 3, FABlockRegistry.INSTANCE.ancientStone, 0, 3);
		world.setBlock(x + 1, y + 6, z + 1, FABlockRegistry.INSTANCE.ancientStone, 0, 3);
		world.setBlock(x + 2, y + 6, z + 3, FABlockRegistry.INSTANCE.ancientStone, 0, 3);
		world.setBlock(x + 2, y + 6, z + 2, FABlockRegistry.INSTANCE.ancientStone, 0, 3);
		world.setBlock(x + 2, y + 6, z + 1, FABlockRegistry.INSTANCE.ancientStone, 0, 3);
		world.setBlock(x + 0, y + 7, z + 3, FABlockRegistry.INSTANCE.ancientStone, 0, 3);
		world.setBlock(x + 0, y + 7, z + 2, FABlockRegistry.INSTANCE.ancientStone, 0, 3);
		world.setBlock(x + 0, y + 7, z + 1, FABlockRegistry.INSTANCE.ancientStone, 0, 3);
		world.setBlock(x + 1, y + 7, z + 3, FABlockRegistry.INSTANCE.ancientStone, 0, 3);
		world.setBlock(x + 1, y + 7, z + 2, FABlockRegistry.INSTANCE.ancientStone, 0, 3);
		world.setBlock(x + 1, y + 7, z + 1, FABlockRegistry.INSTANCE.ancientStone, 0, 3);
		world.setBlock(x + 2, y + 7, z + 3, FABlockRegistry.INSTANCE.ancientStone, 0, 3);
		world.setBlock(x + 2, y + 7, z + 2, FABlockRegistry.INSTANCE.ancientStone, 0, 3);
		world.setBlock(x + 2, y + 7, z + 1, FABlockRegistry.INSTANCE.ancientStone, 0, 3);
		world.setBlock(x + 0, y + 8, z + 4, FABlockRegistry.INSTANCE.ancientStoneStairs, 7, 3);
		world.setBlock(x + 0, y + 8, z + 3, FABlockRegistry.INSTANCE.ancientStone, 0, 3);
		world.setBlock(x + 0, y + 8, z + 2, FABlockRegistry.INSTANCE.ancientStone, 0, 3);
		world.setBlock(x + 0, y + 8, z + 1, FABlockRegistry.INSTANCE.ancientStone, 0, 3);
		world.setBlock(x + 0, y + 8, z + 0, FABlockRegistry.INSTANCE.ancientStoneStairs, 6, 3);
		world.setBlock(x + 1, y + 8, z + 3, FABlockRegistry.INSTANCE.ancientStone, 0, 3);
		world.setBlock(x + 1, y + 8, z + 2, FABlockRegistry.INSTANCE.ancientStone, 0, 3);
		world.setBlock(x + 1, y + 8, z + 1, FABlockRegistry.INSTANCE.ancientStone, 0, 3);
		world.setBlock(x + 2, y + 8, z + 3, FABlockRegistry.INSTANCE.ancientStoneStairs, 5, 3);
		world.setBlock(x + 2, y + 8, z + 2, FABlockRegistry.INSTANCE.ancientStoneStairs, 5, 3);
		world.setBlock(x + 2, y + 8, z + 1, FABlockRegistry.INSTANCE.ancientStoneStairs, 5, 3);
		world.setBlock(x + 0, y + 9, z + 4, FABlockRegistry.INSTANCE.ancientStone, 0, 3);
		world.setBlock(x + 0, y + 9, z + 3, FABlockRegistry.INSTANCE.ancientStone, 0, 3);
		world.setBlock(x + 0, y + 9, z + 2, FABlockRegistry.INSTANCE.ancientStone, 0, 3);
		world.setBlock(x + 0, y + 9, z + 1, FABlockRegistry.INSTANCE.ancientStone, 0, 3);
		world.setBlock(x + 0, y + 9, z + 0, FABlockRegistry.INSTANCE.ancientStone, 0, 3);
		world.setBlock(x + 1, y + 9, z + 3, FABlockRegistry.INSTANCE.ancientStone, 0, 3);
		world.setBlock(x + 1, y + 9, z + 2, FABlockRegistry.INSTANCE.ancientStone, 0, 3);
		world.setBlock(x + 1, y + 9, z + 1, FABlockRegistry.INSTANCE.ancientStone, 0, 3);
		world.setBlock(x + 2, y + 9, z + 3, FABlockRegistry.INSTANCE.ancientStone, 0, 3);
		world.setBlock(x + 2, y + 9, z + 2, FABlockRegistry.INSTANCE.ancientStone, 0, 3);
		world.setBlock(x + 2, y + 9, z + 1, FABlockRegistry.INSTANCE.ancientStone, 0, 3);
		world.setBlock(x + 3, y + 9, z + 2, FABlockRegistry.INSTANCE.ancientStone, 0, 3);
		world.setBlock(x + 0, y + 10, z + 4, FABlockRegistry.INSTANCE.ancientStone, 0, 3);
		world.setBlock(x + 0, y + 10, z + 3, FABlockRegistry.INSTANCE.ancientStone, 0, 3);
		world.setBlock(x + 0, y + 10, z + 2, FABlockRegistry.INSTANCE.ancientStone, 0, 3);
		world.setBlock(x + 0, y + 10, z + 1, FABlockRegistry.INSTANCE.ancientStone, 0, 3);
		world.setBlock(x + 0, y + 10, z + 0, FABlockRegistry.INSTANCE.ancientStone, 0, 3);
		world.setBlock(x + 1, y + 10, z + 3, FABlockRegistry.INSTANCE.ancientStone, 0, 3);
		world.setBlock(x + 1, y + 10, z + 2, FABlockRegistry.INSTANCE.ancientStone, 0, 3);
		world.setBlock(x + 1, y + 10, z + 1, FABlockRegistry.INSTANCE.ancientStone, 0, 3);
		world.setBlock(x + 2, y + 10, z + 3, FABlockRegistry.INSTANCE.ancientStone, 0, 3);
		world.setBlock(x + 2, y + 10, z + 2, FABlockRegistry.INSTANCE.ancientStone, 0, 3);
		world.setBlock(x + 2, y + 10, z + 1, FABlockRegistry.INSTANCE.ancientStone, 0, 3);
		world.setBlock(x + 3, y + 10, z + 2, FABlockRegistry.INSTANCE.ancientStone, 0, 3);
		world.setBlock(x + 0, y + 11, z + 4, FABlockRegistry.INSTANCE.ancientStoneStairs, 3, 3);
		world.setBlock(x + 0, y + 11, z + 3, FABlockRegistry.INSTANCE.ancientStone, 0, 3);
		world.setBlock(x + 0, y + 11, z + 2, FABlockRegistry.INSTANCE.ancientStone, 0, 3);
		world.setBlock(x + 0, y + 11, z + 1, FABlockRegistry.INSTANCE.ancientStone, 0, 3);
		world.setBlock(x + 0, y + 11, z + 0, FABlockRegistry.INSTANCE.ancientStoneStairs, 2, 3);
		world.setBlock(x + 1, y + 11, z + 3, FABlockRegistry.INSTANCE.ancientStone, 0, 3);
		world.setBlock(x + 1, y + 11, z + 2, FABlockRegistry.INSTANCE.ancientStone, 0, 3);
		world.setBlock(x + 1, y + 11, z + 1, FABlockRegistry.INSTANCE.ancientStone, 0, 3);
		world.setBlock(x + 2, y + 11, z + 3, FABlockRegistry.INSTANCE.ancientStoneStairs, 1, 3);
		world.setBlock(x + 2, y + 11, z + 2, FABlockRegistry.INSTANCE.ancientStone, 0, 3);
		world.setBlock(x + 2, y + 11, z + 1, FABlockRegistry.INSTANCE.ancientStoneStairs, 1, 3);
		world.setBlock(x + 3, y + 11, z + 2, FABlockRegistry.INSTANCE.ancientStoneStairs, 1, 3);
		world.setBlock(x + 0, y + 12, z + 3, FABlockRegistry.INSTANCE.ancientStone, 0, 3);
		world.setBlock(x + 0, y + 12, z + 2, FABlockRegistry.INSTANCE.ancientStone, 0, 3);
		world.setBlock(x + 0, y + 12, z + 1, FABlockRegistry.INSTANCE.ancientStone, 0, 3);
		world.setBlock(x + 1, y + 12, z + 3, FABlockRegistry.INSTANCE.ancientStone, 0, 3);
		world.setBlock(x + 1, y + 12, z + 2, FABlockRegistry.INSTANCE.ancientStone, 0, 3);
		world.setBlock(x + 1, y + 12, z + 1, FABlockRegistry.INSTANCE.ancientStone, 0, 3);
		world.setBlock(x + 2, y + 12, z + 3, FABlockRegistry.INSTANCE.ancientStoneStairs, 5, 3);
		world.setBlock(x + 2, y + 12, z + 2, FABlockRegistry.INSTANCE.ancientStone, 0, 3);
		world.setBlock(x + 2, y + 12, z + 1, FABlockRegistry.INSTANCE.ancientStoneStairs, 5, 3);
		world.setBlock(x + 0, y + 13, z + 3, FABlockRegistry.INSTANCE.ancientStone, 0, 3);
		world.setBlock(x + 0, y + 13, z + 2, FABlockRegistry.INSTANCE.ancientStone, 0, 3);
		world.setBlock(x + 0, y + 13, z + 1, FABlockRegistry.INSTANCE.ancientStone, 0, 3);
		world.setBlock(x + 1, y + 13, z + 3, FABlockRegistry.INSTANCE.ancientStone, 0, 3);
		world.setBlock(x + 1, y + 13, z + 2, FABlockRegistry.INSTANCE.ancientStone, 0, 3);
		world.setBlock(x + 1, y + 13, z + 1, FABlockRegistry.INSTANCE.ancientStone, 0, 3);
		world.setBlock(x + 2, y + 13, z + 3, FABlockRegistry.INSTANCE.ancientStoneStairs, 1, 3);
		world.setBlock(x + 2, y + 13, z + 2, FABlockRegistry.INSTANCE.ancientStoneStairs, 1, 3);
		world.setBlock(x + 2, y + 13, z + 1, FABlockRegistry.INSTANCE.ancientStoneStairs, 1, 3);
		if (generateHat) {
			world.setBlock(x + 0, y + 14, z + 3, Blocks.hardened_clay, 0, 3);
			world.setBlock(x + 0, y + 14, z + 2, Blocks.hardened_clay, 0, 3);
			world.setBlock(x + 0, y + 14, z + 1, Blocks.hardened_clay, 0, 3);
			world.setBlock(x + 1, y + 14, z + 3, Blocks.hardened_clay, 0, 3);
			world.setBlock(x + 1, y + 14, z + 2, Blocks.hardened_clay, 0, 3);
			world.setBlock(x + 1, y + 14, z + 1, Blocks.hardened_clay, 0, 3);
			world.setBlock(x + 2, y + 14, z + 3, Blocks.hardened_clay, 0, 3);
			world.setBlock(x + 2, y + 14, z + 2, Blocks.hardened_clay, 0, 3);
			world.setBlock(x + 2, y + 14, z + 1, Blocks.hardened_clay, 0, 3);
			world.setBlock(x + 0, y + 15, z + 3, Blocks.hardened_clay, 0, 3);
			world.setBlock(x + 0, y + 15, z + 2, Blocks.hardened_clay, 0, 3);
			world.setBlock(x + 0, y + 15, z + 1, Blocks.hardened_clay, 0, 3);
			world.setBlock(x + 1, y + 15, z + 3, Blocks.hardened_clay, 0, 3);
			world.setBlock(x + 1, y + 15, z + 2, Blocks.hardened_clay, 0, 3);
			world.setBlock(x + 1, y + 15, z + 1, Blocks.hardened_clay, 0, 3);
			world.setBlock(x + 2, y + 15, z + 3, Blocks.hardened_clay, 0, 3);
			world.setBlock(x + 2, y + 15, z + 2, Blocks.hardened_clay, 0, 3);
			world.setBlock(x + 2, y + 15, z + 1, Blocks.hardened_clay, 0, 3);
			world.setBlock(x + 1, y + 16, z + 2, Blocks.hardened_clay, 0, 3);
		}
		return true;

	}

	public boolean generate_r2(World world, Random rand, int x, int y, int z) {
		world.setBlock(x + 4, y + 0, z + 3, FABlockRegistry.INSTANCE.ancientStone, 0, 3);
		world.setBlock(x + 3, y + 0, z + 3, FABlockRegistry.INSTANCE.ancientStone, 0, 3);
		world.setBlock(x + 2, y + 0, z + 3, FABlockRegistry.INSTANCE.ancientStone, 0, 3);
		world.setBlock(x + 1, y + 0, z + 3, FABlockRegistry.INSTANCE.ancientStone, 0, 3);
		world.setBlock(x + 0, y + 0, z + 3, FABlockRegistry.INSTANCE.ancientStone, 0, 3);
		world.setBlock(x + 4, y + 0, z + 2, FABlockRegistry.INSTANCE.ancientStone, 0, 3);
		world.setBlock(x + 3, y + 0, z + 2, FABlockRegistry.INSTANCE.ancientStone, 0, 3);
		world.setBlock(x + 2, y + 0, z + 2, FABlockRegistry.INSTANCE.ancientStone, 0, 3);
		world.setBlock(x + 1, y + 0, z + 2, FABlockRegistry.INSTANCE.ancientStone, 0, 3);
		world.setBlock(x + 0, y + 0, z + 2, FABlockRegistry.INSTANCE.ancientStone, 0, 3);
		world.setBlock(x + 4, y + 1, z + 3, FABlockRegistry.INSTANCE.ancientStone, 0, 3);
		world.setBlock(x + 3, y + 1, z + 3, FABlockRegistry.INSTANCE.ancientStonebrick, 0, 3);
		world.setBlock(x + 2, y + 1, z + 3, FABlockRegistry.INSTANCE.ancientStonebrick, 0, 3);
		world.setBlock(x + 1, y + 1, z + 3, FABlockRegistry.INSTANCE.ancientStonebrick, 0, 3);
		world.setBlock(x + 0, y + 1, z + 3, FABlockRegistry.INSTANCE.ancientStone, 0, 3);
		world.setBlock(x + 4, y + 1, z + 2, FABlockRegistry.INSTANCE.ancientStone, 0, 3);
		world.setBlock(x + 3, y + 1, z + 2, FABlockRegistry.INSTANCE.ancientStonebrick, 0, 3);
		world.setBlock(x + 2, y + 1, z + 2, FABlockRegistry.INSTANCE.ancientStone, 0, 3);
		world.setBlock(x + 1, y + 1, z + 2, FABlockRegistry.INSTANCE.ancientStonebrick, 0, 3);
		world.setBlock(x + 0, y + 1, z + 2, FABlockRegistry.INSTANCE.ancientStone, 0, 3);
		world.setBlock(x + 4, y + 2, z + 3, FABlockRegistry.INSTANCE.ancientStone, 0, 3);
		world.setBlock(x + 3, y + 2, z + 3, FABlockRegistry.INSTANCE.ancientStonebrick, 0, 3);
		world.setBlock(x + 2, y + 2, z + 3, FABlockRegistry.INSTANCE.ancientStone, 0, 3);
		world.setBlock(x + 1, y + 2, z + 3, FABlockRegistry.INSTANCE.ancientStonebrick, 0, 3);
		world.setBlock(x + 0, y + 2, z + 3, FABlockRegistry.INSTANCE.ancientStone, 0, 3);
		world.setBlock(x + 4, y + 2, z + 2, FABlockRegistry.INSTANCE.ancientStone, 0, 3);
		world.setBlock(x + 3, y + 2, z + 2, FABlockRegistry.INSTANCE.ancientStone, 0, 3);
		world.setBlock(x + 2, y + 2, z + 2, FABlockRegistry.INSTANCE.ancientStonebrick, 0, 3);
		world.setBlock(x + 1, y + 2, z + 2, FABlockRegistry.INSTANCE.ancientStone, 0, 3);
		world.setBlock(x + 0, y + 2, z + 2, FABlockRegistry.INSTANCE.ancientStone, 0, 3);
		world.setBlock(x + 4, y + 3, z + 3, FABlockRegistry.INSTANCE.ancientStone, 0, 3);
		world.setBlock(x + 3, y + 3, z + 3, FABlockRegistry.INSTANCE.ancientStone, 0, 3);
		world.setBlock(x + 2, y + 3, z + 3, FABlockRegistry.INSTANCE.ancientStonebrick, 0, 3);
		world.setBlock(x + 1, y + 3, z + 3, FABlockRegistry.INSTANCE.ancientStone, 0, 3);
		world.setBlock(x + 0, y + 3, z + 3, FABlockRegistry.INSTANCE.ancientStone, 0, 3);
		world.setBlock(x + 4, y + 3, z + 2, FABlockRegistry.INSTANCE.ancientStone, 0, 3);
		world.setBlock(x + 3, y + 3, z + 2, FABlockRegistry.INSTANCE.ancientStonebrick, 0, 3);
		world.setBlock(x + 2, y + 3, z + 2, FABlockRegistry.INSTANCE.ancientStonebrick, 0, 3);
		world.setBlock(x + 1, y + 3, z + 2, FABlockRegistry.INSTANCE.ancientStonebrick, 0, 3);
		world.setBlock(x + 0, y + 3, z + 2, FABlockRegistry.INSTANCE.ancientStone, 0, 3);
		world.setBlock(x + 4, y + 4, z + 3, FABlockRegistry.INSTANCE.ancientStone, 0, 3);
		world.setBlock(x + 3, y + 4, z + 3, FABlockRegistry.INSTANCE.ancientStone, 0, 3);
		world.setBlock(x + 2, y + 4, z + 3, FABlockRegistry.INSTANCE.ancientStonebrick, 0, 3);
		world.setBlock(x + 1, y + 4, z + 3, FABlockRegistry.INSTANCE.ancientStone, 0, 3);
		world.setBlock(x + 0, y + 4, z + 3, FABlockRegistry.INSTANCE.ancientStone, 0, 3);
		world.setBlock(x + 4, y + 4, z + 2, FABlockRegistry.INSTANCE.ancientStone, 0, 3);
		world.setBlock(x + 3, y + 4, z + 2, FABlockRegistry.INSTANCE.ancientStone, 0, 3);
		world.setBlock(x + 2, y + 4, z + 2, FABlockRegistry.INSTANCE.ancientStonebrick, 0, 3);
		world.setBlock(x + 1, y + 4, z + 2, FABlockRegistry.INSTANCE.ancientStone, 0, 3);
		world.setBlock(x + 0, y + 4, z + 2, FABlockRegistry.INSTANCE.ancientStone, 0, 3);
		world.setBlock(x + 3, y + 5, z + 3, FABlockRegistry.INSTANCE.ancientStone, 0, 3);
		world.setBlock(x + 2, y + 5, z + 3, FABlockRegistry.INSTANCE.ancientStonebrick, 0, 3);
		world.setBlock(x + 1, y + 5, z + 3, FABlockRegistry.INSTANCE.ancientStone, 0, 3);
		world.setBlock(x + 3, y + 5, z + 2, FABlockRegistry.INSTANCE.ancientStone, 0, 3);
		world.setBlock(x + 2, y + 5, z + 2, FABlockRegistry.INSTANCE.ancientStone, 0, 3);
		world.setBlock(x + 1, y + 5, z + 2, FABlockRegistry.INSTANCE.ancientStone, 0, 3);
		world.setBlock(x + 3, y + 6, z + 3, FABlockRegistry.INSTANCE.ancientStone, 0, 3);
		world.setBlock(x + 2, y + 6, z + 3, FABlockRegistry.INSTANCE.ancientStone, 0, 3);
		world.setBlock(x + 1, y + 6, z + 3, FABlockRegistry.INSTANCE.ancientStone, 0, 3);
		world.setBlock(x + 3, y + 6, z + 2, FABlockRegistry.INSTANCE.ancientStone, 0, 3);
		world.setBlock(x + 1, y + 6, z + 2, FABlockRegistry.INSTANCE.ancientStone, 0, 3);
		world.setBlock(x + 3, y + 6, z + 1, FABlockRegistry.INSTANCE.ancientStone, 0, 3);
		world.setBlock(x + 2, y + 6, z + 1, FABlockRegistry.INSTANCE.ancientStone, 0, 3);
		world.setBlock(x + 1, y + 6, z + 1, FABlockRegistry.INSTANCE.ancientStone, 0, 3);
		world.setBlock(x + 3, y + 7, z + 3, FABlockRegistry.INSTANCE.ancientStone, 0, 3);
		world.setBlock(x + 2, y + 7, z + 3, FABlockRegistry.INSTANCE.ancientStone, 0, 3);
		world.setBlock(x + 1, y + 7, z + 3, FABlockRegistry.INSTANCE.ancientStone, 0, 3);
		world.setBlock(x + 3, y + 7, z + 2, FABlockRegistry.INSTANCE.ancientStone, 0, 3);
		world.setBlock(x + 2, y + 7, z + 2, FABlockRegistry.INSTANCE.ancientStone, 0, 3);
		world.setBlock(x + 1, y + 7, z + 2, FABlockRegistry.INSTANCE.ancientStone, 0, 3);
		world.setBlock(x + 3, y + 7, z + 1, FABlockRegistry.INSTANCE.ancientStone, 0, 3);
		world.setBlock(x + 2, y + 7, z + 1, FABlockRegistry.INSTANCE.ancientStone, 0, 3);
		world.setBlock(x + 1, y + 7, z + 1, FABlockRegistry.INSTANCE.ancientStone, 0, 3);
		world.setBlock(x + 4, y + 8, z + 3, FABlockRegistry.INSTANCE.ancientStoneStairs, 5, 3);
		world.setBlock(x + 3, y + 8, z + 3, FABlockRegistry.INSTANCE.ancientStone, 0, 3);
		world.setBlock(x + 2, y + 8, z + 3, FABlockRegistry.INSTANCE.ancientStone, 0, 3);
		world.setBlock(x + 1, y + 8, z + 3, FABlockRegistry.INSTANCE.ancientStone, 0, 3);
		world.setBlock(x + 0, y + 8, z + 3, FABlockRegistry.INSTANCE.ancientStoneStairs, 4, 3);
		world.setBlock(x + 3, y + 8, z + 2, FABlockRegistry.INSTANCE.ancientStone, 0, 3);
		world.setBlock(x + 2, y + 8, z + 2, FABlockRegistry.INSTANCE.ancientStone, 0, 3);
		world.setBlock(x + 1, y + 8, z + 2, FABlockRegistry.INSTANCE.ancientStone, 0, 3);
		world.setBlock(x + 3, y + 8, z + 1, FABlockRegistry.INSTANCE.ancientStoneStairs, 6, 3);
		world.setBlock(x + 2, y + 8, z + 1, FABlockRegistry.INSTANCE.ancientStoneStairs, 6, 3);
		world.setBlock(x + 1, y + 8, z + 1, FABlockRegistry.INSTANCE.ancientStoneStairs, 6, 3);
		world.setBlock(x + 4, y + 9, z + 3, FABlockRegistry.INSTANCE.ancientStone, 0, 3);
		world.setBlock(x + 3, y + 9, z + 3, FABlockRegistry.INSTANCE.ancientStone, 0, 3);
		world.setBlock(x + 2, y + 9, z + 3, FABlockRegistry.INSTANCE.ancientStone, 0, 3);
		world.setBlock(x + 1, y + 9, z + 3, FABlockRegistry.INSTANCE.ancientStone, 0, 3);
		world.setBlock(x + 0, y + 9, z + 3, FABlockRegistry.INSTANCE.ancientStone, 0, 3);
		world.setBlock(x + 3, y + 9, z + 2, FABlockRegistry.INSTANCE.ancientStone, 0, 3);
		world.setBlock(x + 2, y + 9, z + 2, FABlockRegistry.INSTANCE.ancientStone, 0, 3);
		world.setBlock(x + 1, y + 9, z + 2, FABlockRegistry.INSTANCE.ancientStone, 0, 3);
		world.setBlock(x + 3, y + 9, z + 1, FABlockRegistry.INSTANCE.ancientStone, 0, 3);
		world.setBlock(x + 2, y + 9, z + 1, FABlockRegistry.INSTANCE.ancientStone, 0, 3);
		world.setBlock(x + 1, y + 9, z + 1, FABlockRegistry.INSTANCE.ancientStone, 0, 3);
		world.setBlock(x + 2, y + 9, z + 0, FABlockRegistry.INSTANCE.ancientStone, 0, 3);
		world.setBlock(x + 4, y + 10, z + 3, FABlockRegistry.INSTANCE.ancientStone, 0, 3);
		world.setBlock(x + 3, y + 10, z + 3, FABlockRegistry.INSTANCE.ancientStone, 0, 3);
		world.setBlock(x + 2, y + 10, z + 3, FABlockRegistry.INSTANCE.ancientStone, 0, 3);
		world.setBlock(x + 1, y + 10, z + 3, FABlockRegistry.INSTANCE.ancientStone, 0, 3);
		world.setBlock(x + 0, y + 10, z + 3, FABlockRegistry.INSTANCE.ancientStone, 0, 3);
		world.setBlock(x + 3, y + 10, z + 2, FABlockRegistry.INSTANCE.ancientStone, 0, 3);
		world.setBlock(x + 2, y + 10, z + 2, FABlockRegistry.INSTANCE.ancientStone, 0, 3);
		world.setBlock(x + 1, y + 10, z + 2, FABlockRegistry.INSTANCE.ancientStone, 0, 3);
		world.setBlock(x + 3, y + 10, z + 1, FABlockRegistry.INSTANCE.ancientStone, 0, 3);
		world.setBlock(x + 2, y + 10, z + 1, FABlockRegistry.INSTANCE.ancientStone, 0, 3);
		world.setBlock(x + 1, y + 10, z + 1, FABlockRegistry.INSTANCE.ancientStone, 0, 3);
		world.setBlock(x + 2, y + 10, z + 0, FABlockRegistry.INSTANCE.ancientStone, 0, 3);
		world.setBlock(x + 4, y + 11, z + 3, FABlockRegistry.INSTANCE.ancientStoneStairs, 1, 3);
		world.setBlock(x + 3, y + 11, z + 3, FABlockRegistry.INSTANCE.ancientStone, 0, 3);
		world.setBlock(x + 2, y + 11, z + 3, FABlockRegistry.INSTANCE.ancientStone, 0, 3);
		world.setBlock(x + 1, y + 11, z + 3, FABlockRegistry.INSTANCE.ancientStone, 0, 3);
		world.setBlock(x + 0, y + 11, z + 3, FABlockRegistry.INSTANCE.ancientStoneStairs, 0, 3);
		world.setBlock(x + 3, y + 11, z + 2, FABlockRegistry.INSTANCE.ancientStone, 0, 3);
		world.setBlock(x + 2, y + 11, z + 2, FABlockRegistry.INSTANCE.ancientStone, 0, 3);
		world.setBlock(x + 1, y + 11, z + 2, FABlockRegistry.INSTANCE.ancientStone, 0, 3);
		world.setBlock(x + 3, y + 11, z + 1, FABlockRegistry.INSTANCE.ancientStoneStairs, 2, 3);
		world.setBlock(x + 2, y + 11, z + 1, FABlockRegistry.INSTANCE.ancientStone, 0, 3);
		world.setBlock(x + 1, y + 11, z + 1, FABlockRegistry.INSTANCE.ancientStoneStairs, 2, 3);
		world.setBlock(x + 2, y + 11, z + 0, FABlockRegistry.INSTANCE.ancientStoneStairs, 2, 3);
		world.setBlock(x + 3, y + 12, z + 3, FABlockRegistry.INSTANCE.ancientStone, 0, 3);
		world.setBlock(x + 2, y + 12, z + 3, FABlockRegistry.INSTANCE.ancientStone, 0, 3);
		world.setBlock(x + 1, y + 12, z + 3, FABlockRegistry.INSTANCE.ancientStone, 0, 3);
		world.setBlock(x + 3, y + 12, z + 2, FABlockRegistry.INSTANCE.ancientStone, 0, 3);
		world.setBlock(x + 2, y + 12, z + 2, FABlockRegistry.INSTANCE.ancientStone, 0, 3);
		world.setBlock(x + 1, y + 12, z + 2, FABlockRegistry.INSTANCE.ancientStone, 0, 3);
		world.setBlock(x + 3, y + 12, z + 1, FABlockRegistry.INSTANCE.ancientStoneStairs, 6, 3);
		world.setBlock(x + 2, y + 12, z + 1, FABlockRegistry.INSTANCE.ancientStone, 0, 3);
		world.setBlock(x + 1, y + 12, z + 1, FABlockRegistry.INSTANCE.ancientStoneStairs, 6, 3);
		world.setBlock(x + 3, y + 13, z + 3, FABlockRegistry.INSTANCE.ancientStone, 0, 3);
		world.setBlock(x + 2, y + 13, z + 3, FABlockRegistry.INSTANCE.ancientStone, 0, 3);
		world.setBlock(x + 1, y + 13, z + 3, FABlockRegistry.INSTANCE.ancientStone, 0, 3);
		world.setBlock(x + 3, y + 13, z + 2, FABlockRegistry.INSTANCE.ancientStone, 0, 3);
		world.setBlock(x + 2, y + 13, z + 2, FABlockRegistry.INSTANCE.ancientStone, 0, 3);
		world.setBlock(x + 1, y + 13, z + 2, FABlockRegistry.INSTANCE.ancientStone, 0, 3);
		world.setBlock(x + 3, y + 13, z + 1, FABlockRegistry.INSTANCE.ancientStoneStairs, 2, 3);
		world.setBlock(x + 2, y + 13, z + 1, FABlockRegistry.INSTANCE.ancientStoneStairs, 2, 3);
		world.setBlock(x + 1, y + 13, z + 1, FABlockRegistry.INSTANCE.ancientStoneStairs, 2, 3);
		if (generateHat) {
			world.setBlock(x + 3, y + 14, z + 3, Blocks.hardened_clay, 0, 3);
			world.setBlock(x + 2, y + 14, z + 3, Blocks.hardened_clay, 0, 3);
			world.setBlock(x + 1, y + 14, z + 3, Blocks.hardened_clay, 0, 3);
			world.setBlock(x + 3, y + 14, z + 2, Blocks.hardened_clay, 0, 3);
			world.setBlock(x + 2, y + 14, z + 2, Blocks.hardened_clay, 0, 3);
			world.setBlock(x + 1, y + 14, z + 2, Blocks.hardened_clay, 0, 3);
			world.setBlock(x + 3, y + 14, z + 1, Blocks.hardened_clay, 0, 3);
			world.setBlock(x + 2, y + 14, z + 1, Blocks.hardened_clay, 0, 3);
			world.setBlock(x + 1, y + 14, z + 1, Blocks.hardened_clay, 0, 3);
			world.setBlock(x + 3, y + 15, z + 3, Blocks.hardened_clay, 0, 3);
			world.setBlock(x + 2, y + 15, z + 3, Blocks.hardened_clay, 0, 3);
			world.setBlock(x + 1, y + 15, z + 3, Blocks.hardened_clay, 0, 3);
			world.setBlock(x + 3, y + 15, z + 2, Blocks.hardened_clay, 0, 3);
			world.setBlock(x + 2, y + 15, z + 2, Blocks.hardened_clay, 0, 3);
			world.setBlock(x + 1, y + 15, z + 2, Blocks.hardened_clay, 0, 3);
			world.setBlock(x + 3, y + 15, z + 1, Blocks.hardened_clay, 0, 3);
			world.setBlock(x + 2, y + 15, z + 1, Blocks.hardened_clay, 0, 3);
			world.setBlock(x + 1, y + 15, z + 1, Blocks.hardened_clay, 0, 3);
			world.setBlock(x + 2, y + 16, z + 2, Blocks.hardened_clay, 0, 3);
		}
		return true;

	}

	public boolean generate_r3(World world, Random rand, int x, int y, int z) {
		world.setBlock(x + 3, y + 0, z + 0, FABlockRegistry.INSTANCE.ancientStone, 0, 3);
		world.setBlock(x + 3, y + 0, z + 1, FABlockRegistry.INSTANCE.ancientStone, 0, 3);
		world.setBlock(x + 3, y + 0, z + 2, FABlockRegistry.INSTANCE.ancientStone, 0, 3);
		world.setBlock(x + 3, y + 0, z + 3, FABlockRegistry.INSTANCE.ancientStone, 0, 3);
		world.setBlock(x + 3, y + 0, z + 4, FABlockRegistry.INSTANCE.ancientStone, 0, 3);
		world.setBlock(x + 2, y + 0, z + 0, FABlockRegistry.INSTANCE.ancientStone, 0, 3);
		world.setBlock(x + 2, y + 0, z + 1, FABlockRegistry.INSTANCE.ancientStone, 0, 3);
		world.setBlock(x + 2, y + 0, z + 2, FABlockRegistry.INSTANCE.ancientStone, 0, 3);
		world.setBlock(x + 2, y + 0, z + 3, FABlockRegistry.INSTANCE.ancientStone, 0, 3);
		world.setBlock(x + 2, y + 0, z + 4, FABlockRegistry.INSTANCE.ancientStone, 0, 3);
		world.setBlock(x + 3, y + 1, z + 0, FABlockRegistry.INSTANCE.ancientStone, 0, 3);
		world.setBlock(x + 3, y + 1, z + 1, FABlockRegistry.INSTANCE.ancientStonebrick, 0, 3);
		world.setBlock(x + 3, y + 1, z + 2, FABlockRegistry.INSTANCE.ancientStonebrick, 0, 3);
		world.setBlock(x + 3, y + 1, z + 3, FABlockRegistry.INSTANCE.ancientStonebrick, 0, 3);
		world.setBlock(x + 3, y + 1, z + 4, FABlockRegistry.INSTANCE.ancientStone, 0, 3);
		world.setBlock(x + 2, y + 1, z + 0, FABlockRegistry.INSTANCE.ancientStone, 0, 3);
		world.setBlock(x + 2, y + 1, z + 1, FABlockRegistry.INSTANCE.ancientStonebrick, 0, 3);
		world.setBlock(x + 2, y + 1, z + 2, FABlockRegistry.INSTANCE.ancientStone, 0, 3);
		world.setBlock(x + 2, y + 1, z + 3, FABlockRegistry.INSTANCE.ancientStonebrick, 0, 3);
		world.setBlock(x + 2, y + 1, z + 4, FABlockRegistry.INSTANCE.ancientStone, 0, 3);
		world.setBlock(x + 3, y + 2, z + 0, FABlockRegistry.INSTANCE.ancientStone, 0, 3);
		world.setBlock(x + 3, y + 2, z + 1, FABlockRegistry.INSTANCE.ancientStonebrick, 0, 3);
		world.setBlock(x + 3, y + 2, z + 2, FABlockRegistry.INSTANCE.ancientStone, 0, 3);
		world.setBlock(x + 3, y + 2, z + 3, FABlockRegistry.INSTANCE.ancientStonebrick, 0, 3);
		world.setBlock(x + 3, y + 2, z + 4, FABlockRegistry.INSTANCE.ancientStone, 0, 3);
		world.setBlock(x + 2, y + 2, z + 0, FABlockRegistry.INSTANCE.ancientStone, 0, 3);
		world.setBlock(x + 2, y + 2, z + 1, FABlockRegistry.INSTANCE.ancientStone, 0, 3);
		world.setBlock(x + 2, y + 2, z + 2, FABlockRegistry.INSTANCE.ancientStonebrick, 0, 3);
		world.setBlock(x + 2, y + 2, z + 3, FABlockRegistry.INSTANCE.ancientStone, 0, 3);
		world.setBlock(x + 2, y + 2, z + 4, FABlockRegistry.INSTANCE.ancientStone, 0, 3);
		world.setBlock(x + 3, y + 3, z + 0, FABlockRegistry.INSTANCE.ancientStone, 0, 3);
		world.setBlock(x + 3, y + 3, z + 1, FABlockRegistry.INSTANCE.ancientStone, 0, 3);
		world.setBlock(x + 3, y + 3, z + 2, FABlockRegistry.INSTANCE.ancientStonebrick, 0, 3);
		world.setBlock(x + 3, y + 3, z + 3, FABlockRegistry.INSTANCE.ancientStone, 0, 3);
		world.setBlock(x + 3, y + 3, z + 4, FABlockRegistry.INSTANCE.ancientStone, 0, 3);
		world.setBlock(x + 2, y + 3, z + 0, FABlockRegistry.INSTANCE.ancientStone, 0, 3);
		world.setBlock(x + 2, y + 3, z + 1, FABlockRegistry.INSTANCE.ancientStonebrick, 0, 3);
		world.setBlock(x + 2, y + 3, z + 2, FABlockRegistry.INSTANCE.ancientStonebrick, 0, 3);
		world.setBlock(x + 2, y + 3, z + 3, FABlockRegistry.INSTANCE.ancientStonebrick, 0, 3);
		world.setBlock(x + 2, y + 3, z + 4, FABlockRegistry.INSTANCE.ancientStone, 0, 3);
		world.setBlock(x + 3, y + 4, z + 0, FABlockRegistry.INSTANCE.ancientStone, 0, 3);
		world.setBlock(x + 3, y + 4, z + 1, FABlockRegistry.INSTANCE.ancientStone, 0, 3);
		world.setBlock(x + 3, y + 4, z + 2, FABlockRegistry.INSTANCE.ancientStonebrick, 0, 3);
		world.setBlock(x + 3, y + 4, z + 3, FABlockRegistry.INSTANCE.ancientStone, 0, 3);
		world.setBlock(x + 3, y + 4, z + 4, FABlockRegistry.INSTANCE.ancientStone, 0, 3);
		world.setBlock(x + 2, y + 4, z + 0, FABlockRegistry.INSTANCE.ancientStone, 0, 3);
		world.setBlock(x + 2, y + 4, z + 1, FABlockRegistry.INSTANCE.ancientStone, 0, 3);
		world.setBlock(x + 2, y + 4, z + 2, FABlockRegistry.INSTANCE.ancientStonebrick, 0, 3);
		world.setBlock(x + 2, y + 4, z + 3, FABlockRegistry.INSTANCE.ancientStone, 0, 3);
		world.setBlock(x + 2, y + 4, z + 4, FABlockRegistry.INSTANCE.ancientStone, 0, 3);
		world.setBlock(x + 3, y + 5, z + 1, FABlockRegistry.INSTANCE.ancientStone, 0, 3);
		world.setBlock(x + 3, y + 5, z + 2, FABlockRegistry.INSTANCE.ancientStonebrick, 0, 3);
		world.setBlock(x + 3, y + 5, z + 3, FABlockRegistry.INSTANCE.ancientStone, 0, 3);
		world.setBlock(x + 2, y + 5, z + 1, FABlockRegistry.INSTANCE.ancientStone, 0, 3);
		world.setBlock(x + 2, y + 5, z + 2, FABlockRegistry.INSTANCE.ancientStone, 0, 3);
		world.setBlock(x + 2, y + 5, z + 3, FABlockRegistry.INSTANCE.ancientStone, 0, 3);
		world.setBlock(x + 3, y + 6, z + 1, FABlockRegistry.INSTANCE.ancientStone, 0, 3);
		world.setBlock(x + 3, y + 6, z + 2, FABlockRegistry.INSTANCE.ancientStone, 0, 3);
		world.setBlock(x + 3, y + 6, z + 3, FABlockRegistry.INSTANCE.ancientStone, 0, 3);
		world.setBlock(x + 2, y + 6, z + 1, FABlockRegistry.INSTANCE.ancientStone, 0, 3);
		world.setBlock(x + 2, y + 6, z + 3, FABlockRegistry.INSTANCE.ancientStone, 0, 3);
		world.setBlock(x + 1, y + 6, z + 1, FABlockRegistry.INSTANCE.ancientStone, 0, 3);
		world.setBlock(x + 1, y + 6, z + 2, FABlockRegistry.INSTANCE.ancientStone, 0, 3);
		world.setBlock(x + 1, y + 6, z + 3, FABlockRegistry.INSTANCE.ancientStone, 0, 3);
		world.setBlock(x + 3, y + 7, z + 1, FABlockRegistry.INSTANCE.ancientStone, 0, 3);
		world.setBlock(x + 3, y + 7, z + 2, FABlockRegistry.INSTANCE.ancientStone, 0, 3);
		world.setBlock(x + 3, y + 7, z + 3, FABlockRegistry.INSTANCE.ancientStone, 0, 3);
		world.setBlock(x + 2, y + 7, z + 1, FABlockRegistry.INSTANCE.ancientStone, 0, 3);
		world.setBlock(x + 2, y + 7, z + 2, FABlockRegistry.INSTANCE.ancientStone, 0, 3);
		world.setBlock(x + 2, y + 7, z + 3, FABlockRegistry.INSTANCE.ancientStone, 0, 3);
		world.setBlock(x + 1, y + 7, z + 1, FABlockRegistry.INSTANCE.ancientStone, 0, 3);
		world.setBlock(x + 1, y + 7, z + 2, FABlockRegistry.INSTANCE.ancientStone, 0, 3);
		world.setBlock(x + 1, y + 7, z + 3, FABlockRegistry.INSTANCE.ancientStone, 0, 3);
		world.setBlock(x + 3, y + 8, z + 0, FABlockRegistry.INSTANCE.ancientStoneStairs, 6, 3);
		world.setBlock(x + 3, y + 8, z + 1, FABlockRegistry.INSTANCE.ancientStone, 0, 3);
		world.setBlock(x + 3, y + 8, z + 2, FABlockRegistry.INSTANCE.ancientStone, 0, 3);
		world.setBlock(x + 3, y + 8, z + 3, FABlockRegistry.INSTANCE.ancientStone, 0, 3);
		world.setBlock(x + 3, y + 8, z + 4, FABlockRegistry.INSTANCE.ancientStoneStairs, 7, 3);
		world.setBlock(x + 2, y + 8, z + 1, FABlockRegistry.INSTANCE.ancientStone, 0, 3);
		world.setBlock(x + 2, y + 8, z + 2, FABlockRegistry.INSTANCE.ancientStone, 0, 3);
		world.setBlock(x + 2, y + 8, z + 3, FABlockRegistry.INSTANCE.ancientStone, 0, 3);
		world.setBlock(x + 1, y + 8, z + 1, FABlockRegistry.INSTANCE.ancientStoneStairs, 4, 3);
		world.setBlock(x + 1, y + 8, z + 2, FABlockRegistry.INSTANCE.ancientStoneStairs, 4, 3);
		world.setBlock(x + 1, y + 8, z + 3, FABlockRegistry.INSTANCE.ancientStoneStairs, 4, 3);
		world.setBlock(x + 3, y + 9, z + 0, FABlockRegistry.INSTANCE.ancientStone, 0, 3);
		world.setBlock(x + 3, y + 9, z + 1, FABlockRegistry.INSTANCE.ancientStone, 0, 3);
		world.setBlock(x + 3, y + 9, z + 2, FABlockRegistry.INSTANCE.ancientStone, 0, 3);
		world.setBlock(x + 3, y + 9, z + 3, FABlockRegistry.INSTANCE.ancientStone, 0, 3);
		world.setBlock(x + 3, y + 9, z + 4, FABlockRegistry.INSTANCE.ancientStone, 0, 3);
		world.setBlock(x + 2, y + 9, z + 1, FABlockRegistry.INSTANCE.ancientStone, 0, 3);
		world.setBlock(x + 2, y + 9, z + 2, FABlockRegistry.INSTANCE.ancientStone, 0, 3);
		world.setBlock(x + 2, y + 9, z + 3, FABlockRegistry.INSTANCE.ancientStone, 0, 3);
		world.setBlock(x + 1, y + 9, z + 1, FABlockRegistry.INSTANCE.ancientStone, 0, 3);
		world.setBlock(x + 1, y + 9, z + 2, FABlockRegistry.INSTANCE.ancientStone, 0, 3);
		world.setBlock(x + 1, y + 9, z + 3, FABlockRegistry.INSTANCE.ancientStone, 0, 3);
		world.setBlock(x + 0, y + 9, z + 2, FABlockRegistry.INSTANCE.ancientStone, 0, 3);
		world.setBlock(x + 3, y + 10, z + 0, FABlockRegistry.INSTANCE.ancientStone, 0, 3);
		world.setBlock(x + 3, y + 10, z + 1, FABlockRegistry.INSTANCE.ancientStone, 0, 3);
		world.setBlock(x + 3, y + 10, z + 2, FABlockRegistry.INSTANCE.ancientStone, 0, 3);
		world.setBlock(x + 3, y + 10, z + 3, FABlockRegistry.INSTANCE.ancientStone, 0, 3);
		world.setBlock(x + 3, y + 10, z + 4, FABlockRegistry.INSTANCE.ancientStone, 0, 3);
		world.setBlock(x + 2, y + 10, z + 1, FABlockRegistry.INSTANCE.ancientStone, 0, 3);
		world.setBlock(x + 2, y + 10, z + 2, FABlockRegistry.INSTANCE.ancientStone, 0, 3);
		world.setBlock(x + 2, y + 10, z + 3, FABlockRegistry.INSTANCE.ancientStone, 0, 3);
		world.setBlock(x + 1, y + 10, z + 1, FABlockRegistry.INSTANCE.ancientStone, 0, 3);
		world.setBlock(x + 1, y + 10, z + 2, FABlockRegistry.INSTANCE.ancientStone, 0, 3);
		world.setBlock(x + 1, y + 10, z + 3, FABlockRegistry.INSTANCE.ancientStone, 0, 3);
		world.setBlock(x + 0, y + 10, z + 2, FABlockRegistry.INSTANCE.ancientStone, 0, 3);
		world.setBlock(x + 3, y + 11, z + 0, FABlockRegistry.INSTANCE.ancientStoneStairs, 2, 3);
		world.setBlock(x + 3, y + 11, z + 1, FABlockRegistry.INSTANCE.ancientStone, 0, 3);
		world.setBlock(x + 3, y + 11, z + 2, FABlockRegistry.INSTANCE.ancientStone, 0, 3);
		world.setBlock(x + 3, y + 11, z + 3, FABlockRegistry.INSTANCE.ancientStone, 0, 3);
		world.setBlock(x + 3, y + 11, z + 4, FABlockRegistry.INSTANCE.ancientStoneStairs, 3, 3);
		world.setBlock(x + 2, y + 11, z + 1, FABlockRegistry.INSTANCE.ancientStone, 0, 3);
		world.setBlock(x + 2, y + 11, z + 2, FABlockRegistry.INSTANCE.ancientStone, 0, 3);
		world.setBlock(x + 2, y + 11, z + 3, FABlockRegistry.INSTANCE.ancientStone, 0, 3);
		world.setBlock(x + 1, y + 11, z + 1, FABlockRegistry.INSTANCE.ancientStoneStairs, 0, 3);
		world.setBlock(x + 1, y + 11, z + 2, FABlockRegistry.INSTANCE.ancientStone, 0, 3);
		world.setBlock(x + 1, y + 11, z + 3, FABlockRegistry.INSTANCE.ancientStoneStairs, 0, 3);
		world.setBlock(x + 0, y + 11, z + 2, FABlockRegistry.INSTANCE.ancientStoneStairs, 0, 3);
		world.setBlock(x + 3, y + 12, z + 1, FABlockRegistry.INSTANCE.ancientStone, 0, 3);
		world.setBlock(x + 3, y + 12, z + 2, FABlockRegistry.INSTANCE.ancientStone, 0, 3);
		world.setBlock(x + 3, y + 12, z + 3, FABlockRegistry.INSTANCE.ancientStone, 0, 3);
		world.setBlock(x + 2, y + 12, z + 1, FABlockRegistry.INSTANCE.ancientStone, 0, 3);
		world.setBlock(x + 2, y + 12, z + 2, FABlockRegistry.INSTANCE.ancientStone, 0, 3);
		world.setBlock(x + 2, y + 12, z + 3, FABlockRegistry.INSTANCE.ancientStone, 0, 3);
		world.setBlock(x + 1, y + 12, z + 1, FABlockRegistry.INSTANCE.ancientStoneStairs, 4, 3);
		world.setBlock(x + 1, y + 12, z + 2, FABlockRegistry.INSTANCE.ancientStone, 0, 3);
		world.setBlock(x + 1, y + 12, z + 3, FABlockRegistry.INSTANCE.ancientStoneStairs, 4, 3);
		world.setBlock(x + 3, y + 13, z + 1, FABlockRegistry.INSTANCE.ancientStone, 0, 3);
		world.setBlock(x + 3, y + 13, z + 2, FABlockRegistry.INSTANCE.ancientStone, 0, 3);
		world.setBlock(x + 3, y + 13, z + 3, FABlockRegistry.INSTANCE.ancientStone, 0, 3);
		world.setBlock(x + 2, y + 13, z + 1, FABlockRegistry.INSTANCE.ancientStone, 0, 3);
		world.setBlock(x + 2, y + 13, z + 2, FABlockRegistry.INSTANCE.ancientStone, 0, 3);
		world.setBlock(x + 2, y + 13, z + 3, FABlockRegistry.INSTANCE.ancientStone, 0, 3);
		world.setBlock(x + 1, y + 13, z + 1, FABlockRegistry.INSTANCE.ancientStoneStairs, 0, 3);
		world.setBlock(x + 1, y + 13, z + 2, FABlockRegistry.INSTANCE.ancientStoneStairs, 0, 3);
		world.setBlock(x + 1, y + 13, z + 3, FABlockRegistry.INSTANCE.ancientStoneStairs, 0, 3);
		if (generateHat) {
			world.setBlock(x + 3, y + 14, z + 1, Blocks.hardened_clay, 0, 3);
			world.setBlock(x + 3, y + 14, z + 2, Blocks.hardened_clay, 0, 3);
			world.setBlock(x + 3, y + 14, z + 3, Blocks.hardened_clay, 0, 3);
			world.setBlock(x + 2, y + 14, z + 1, Blocks.hardened_clay, 0, 3);
			world.setBlock(x + 2, y + 14, z + 2, Blocks.hardened_clay, 0, 3);
			world.setBlock(x + 2, y + 14, z + 3, Blocks.hardened_clay, 0, 3);
			world.setBlock(x + 1, y + 14, z + 1, Blocks.hardened_clay, 0, 3);
			world.setBlock(x + 1, y + 14, z + 2, Blocks.hardened_clay, 0, 3);
			world.setBlock(x + 1, y + 14, z + 3, Blocks.hardened_clay, 0, 3);
			world.setBlock(x + 3, y + 15, z + 1, Blocks.hardened_clay, 0, 3);
			world.setBlock(x + 3, y + 15, z + 2, Blocks.hardened_clay, 0, 3);
			world.setBlock(x + 3, y + 15, z + 3, Blocks.hardened_clay, 0, 3);
			world.setBlock(x + 2, y + 15, z + 1, Blocks.hardened_clay, 0, 3);
			world.setBlock(x + 2, y + 15, z + 2, Blocks.hardened_clay, 0, 3);
			world.setBlock(x + 2, y + 15, z + 3, Blocks.hardened_clay, 0, 3);
			world.setBlock(x + 1, y + 15, z + 1, Blocks.hardened_clay, 0, 3);
			world.setBlock(x + 1, y + 15, z + 2, Blocks.hardened_clay, 0, 3);
			world.setBlock(x + 1, y + 15, z + 3, Blocks.hardened_clay, 0, 3);
			world.setBlock(x + 2, y + 16, z + 2, Blocks.hardened_clay, 0, 3);
		}
		return true;

	}

}