package fossilsarcheology.server.gen.feature;

import java.util.Random;

import net.minecraft.entity.passive.EntityVillager;
import net.minecraft.init.Blocks;
import net.minecraft.item.ItemDoor;
import net.minecraft.world.World;
import net.minecraft.world.gen.feature.WorldGenerator;
import fossilsarcheology.Revival;
import fossilsarcheology.server.block.FABlockRegistry;

public class TarSiteWorldGen extends WorldGenerator {

	public boolean generate(World world, Random rand, int x, int y, int z) {
		generate_r0(world, rand, x, y, z);
		return true;

	}
	public boolean generate_r0(World world, Random rand, int x, int y, int z) {
		world.setBlock(x + 0, y + 0, z + 0, Blocks.dirt, 0, 3);
		world.setBlock(x + 1, y + 0, z + 0, Blocks.dirt, 0, 3);
		world.setBlock(x + 2, y + 0, z + 0, Blocks.dirt, 0, 3);
		world.setBlock(x + 3, y + 0, z + 0, Blocks.dirt, 0, 3);
		world.setBlock(x + 4, y + 0, z + 0, Blocks.dirt, 0, 3);
		world.setBlock(x + 5, y + 0, z + 0, Blocks.dirt, 0, 3);
		world.setBlock(x + 6, y + 0, z + 0, Blocks.dirt, 0, 3);
		world.setBlock(x + 7, y + 0, z + 0, Blocks.dirt, 0, 3);
		world.setBlock(x + 8, y + 0, z + 0, Blocks.dirt, 0, 3);
		world.setBlock(x + 9, y + 0, z + 0, Blocks.dirt, 0, 3);
		world.setBlock(x + 10, y + 0, z + 0, Blocks.dirt, 0, 3);
		world.setBlock(x + 0, y + 0, z + 1, Blocks.dirt, 0, 3);
		world.setBlock(x + 1, y + 0, z + 1, Blocks.dirt, 0, 3);
		world.setBlock(x + 2, y + 0, z + 1, Blocks.dirt, 0, 3);
		world.setBlock(x + 3, y + 0, z + 1, Blocks.dirt, 0, 3);
		world.setBlock(x + 4, y + 0, z + 1, Blocks.dirt, 0, 3);
		world.setBlock(x + 5, y + 0, z + 1, Blocks.dirt, 0, 3);
		world.setBlock(x + 6, y + 0, z + 1, Blocks.dirt, 0, 3);
		world.setBlock(x + 7, y + 0, z + 1, Blocks.dirt, 0, 3);
		world.setBlock(x + 8, y + 0, z + 1, Blocks.dirt, 0, 3);
		world.setBlock(x + 9, y + 0, z + 1, Blocks.dirt, 0, 3);
		world.setBlock(x + 10, y + 0, z + 1, Blocks.dirt, 0, 3);
		world.setBlock(x + 0, y + 0, z + 2, Blocks.dirt, 0, 3);
		world.setBlock(x + 1, y + 0, z + 2, Blocks.dirt, 0, 3);
		world.setBlock(x + 2, y + 0, z + 2, Blocks.dirt, 0, 3);
		world.setBlock(x + 3, y + 0, z + 2, Blocks.dirt, 0, 3);
		world.setBlock(x + 4, y + 0, z + 2, Blocks.dirt, 0, 3);
		world.setBlock(x + 5, y + 0, z + 2, Blocks.dirt, 0, 3);
		world.setBlock(x + 6, y + 0, z + 2, Blocks.dirt, 0, 3);
		world.setBlock(x + 7, y + 0, z + 2, Blocks.dirt, 0, 3);
		world.setBlock(x + 8, y + 0, z + 2, Blocks.dirt, 0, 3);
		world.setBlock(x + 9, y + 0, z + 2, Blocks.dirt, 0, 3);
		world.setBlock(x + 10, y + 0, z + 2, Blocks.dirt, 0, 3);
		world.setBlock(x + 0, y + 0, z + 3, Blocks.dirt, 0, 3);
		world.setBlock(x + 1, y + 0, z + 3, Blocks.dirt, 0, 3);
		world.setBlock(x + 2, y + 0, z + 3, Blocks.dirt, 0, 3);
		world.setBlock(x + 3, y + 0, z + 3, Blocks.dirt, 0, 3);
		world.setBlock(x + 4, y + 0, z + 3, Blocks.dirt, 0, 3);
		world.setBlock(x + 5, y + 0, z + 3, Blocks.dirt, 0, 3);
		world.setBlock(x + 6, y + 0, z + 3, Blocks.dirt, 0, 3);
		world.setBlock(x + 7, y + 0, z + 3, Blocks.dirt, 0, 3);
		world.setBlock(x + 8, y + 0, z + 3, Blocks.dirt, 0, 3);
		world.setBlock(x + 9, y + 0, z + 3, Blocks.dirt, 0, 3);
		world.setBlock(x + 10, y + 0, z + 3, Blocks.dirt, 0, 3);
		world.setBlock(x + 0, y + 0, z + 4, Blocks.dirt, 0, 3);
		world.setBlock(x + 1, y + 0, z + 4, Blocks.dirt, 0, 3);
		world.setBlock(x + 2, y + 0, z + 4, Blocks.dirt, 0, 3);
		world.setBlock(x + 3, y + 0, z + 4, Blocks.dirt, 0, 3);
		world.setBlock(x + 4, y + 0, z + 4, Blocks.dirt, 0, 3);
		world.setBlock(x + 5, y + 0, z + 4, Blocks.dirt, 0, 3);
		world.setBlock(x + 6, y + 0, z + 4, Blocks.dirt, 0, 3);
		world.setBlock(x + 7, y + 0, z + 4, Blocks.dirt, 0, 3);
		world.setBlock(x + 8, y + 0, z + 4, Blocks.dirt, 0, 3);
		world.setBlock(x + 9, y + 0, z + 4, Blocks.dirt, 0, 3);
		world.setBlock(x + 10, y + 0, z + 4, Blocks.dirt, 0, 3);
		world.setBlock(x + 0, y + 0, z + 5, Blocks.dirt, 0, 3);
		world.setBlock(x + 1, y + 0, z + 5, Blocks.dirt, 0, 3);
		world.setBlock(x + 2, y + 0, z + 5, Blocks.dirt, 0, 3);
		world.setBlock(x + 3, y + 0, z + 5, Blocks.dirt, 0, 3);
		world.setBlock(x + 4, y + 0, z + 5, Blocks.dirt, 0, 3);
		world.setBlock(x + 5, y + 0, z + 5, Blocks.dirt, 0, 3);
		world.setBlock(x + 6, y + 0, z + 5, Blocks.dirt, 0, 3);
		world.setBlock(x + 7, y + 0, z + 5, Blocks.dirt, 0, 3);
		world.setBlock(x + 8, y + 0, z + 5, Blocks.dirt, 0, 3);
		world.setBlock(x + 9, y + 0, z + 5, Blocks.dirt, 0, 3);
		world.setBlock(x + 10, y + 0, z + 5, Blocks.dirt, 0, 3);
		world.setBlock(x + 0, y + 0, z + 6, Blocks.dirt, 0, 3);
		world.setBlock(x + 1, y + 0, z + 6, Blocks.dirt, 0, 3);
		world.setBlock(x + 2, y + 0, z + 6, Blocks.dirt, 0, 3);
		world.setBlock(x + 3, y + 0, z + 6, Blocks.dirt, 0, 3);
		world.setBlock(x + 4, y + 0, z + 6, Blocks.dirt, 0, 3);
		world.setBlock(x + 5, y + 0, z + 6, Blocks.dirt, 0, 3);
		world.setBlock(x + 6, y + 0, z + 6, Blocks.dirt, 0, 3);
		world.setBlock(x + 7, y + 0, z + 6, Blocks.dirt, 0, 3);
		world.setBlock(x + 8, y + 0, z + 6, Blocks.dirt, 0, 3);
		world.setBlock(x + 9, y + 0, z + 6, Blocks.dirt, 0, 3);
		world.setBlock(x + 10, y + 0, z + 6, Blocks.dirt, 0, 3);
		world.setBlock(x + 0, y + 0, z + 7, Blocks.dirt, 0, 3);
		world.setBlock(x + 1, y + 0, z + 7, Blocks.dirt, 0, 3);
		world.setBlock(x + 2, y + 0, z + 7, Blocks.dirt, 0, 3);
		world.setBlock(x + 3, y + 0, z + 7, Blocks.dirt, 0, 3);
		world.setBlock(x + 4, y + 0, z + 7, Blocks.dirt, 0, 3);
		world.setBlock(x + 5, y + 0, z + 7, Blocks.dirt, 0, 3);
		world.setBlock(x + 6, y + 0, z + 7, Blocks.dirt, 0, 3);
		world.setBlock(x + 7, y + 0, z + 7, Blocks.dirt, 0, 3);
		world.setBlock(x + 8, y + 0, z + 7, Blocks.dirt, 0, 3);
		world.setBlock(x + 9, y + 0, z + 7, Blocks.dirt, 0, 3);
		world.setBlock(x + 10, y + 0, z + 7, Blocks.dirt, 0, 3);
		world.setBlock(x + 0, y + 0, z + 8, Blocks.dirt, 0, 3);
		world.setBlock(x + 1, y + 0, z + 8, Blocks.dirt, 0, 3);
		world.setBlock(x + 2, y + 0, z + 8, Blocks.dirt, 0, 3);
		world.setBlock(x + 3, y + 0, z + 8, Blocks.dirt, 0, 3);
		world.setBlock(x + 4, y + 0, z + 8, Blocks.dirt, 0, 3);
		world.setBlock(x + 5, y + 0, z + 8, Blocks.dirt, 0, 3);
		world.setBlock(x + 6, y + 0, z + 8, Blocks.dirt, 0, 3);
		world.setBlock(x + 7, y + 0, z + 8, Blocks.dirt, 0, 3);
		world.setBlock(x + 8, y + 0, z + 8, Blocks.dirt, 0, 3);
		world.setBlock(x + 9, y + 0, z + 8, Blocks.dirt, 0, 3);
		world.setBlock(x + 10, y + 0, z + 8, Blocks.dirt, 0, 3);
		world.setBlock(x + 0, y + 0, z + 9, Blocks.dirt, 0, 3);
		world.setBlock(x + 1, y + 0, z + 9, Blocks.dirt, 0, 3);
		world.setBlock(x + 2, y + 0, z + 9, Blocks.dirt, 0, 3);
		world.setBlock(x + 3, y + 0, z + 9, Blocks.dirt, 0, 3);
		world.setBlock(x + 4, y + 0, z + 9, Blocks.dirt, 0, 3);
		world.setBlock(x + 5, y + 0, z + 9, Blocks.dirt, 0, 3);
		world.setBlock(x + 6, y + 0, z + 9, Blocks.dirt, 0, 3);
		world.setBlock(x + 7, y + 0, z + 9, Blocks.dirt, 0, 3);
		world.setBlock(x + 8, y + 0, z + 9, Blocks.dirt, 0, 3);
		world.setBlock(x + 9, y + 0, z + 9, Blocks.dirt, 0, 3);
		world.setBlock(x + 10, y + 0, z + 9, Blocks.dirt, 0, 3);
		world.setBlock(x + 0, y + 0, z + 10, Blocks.dirt, 0, 3);
		world.setBlock(x + 1, y + 0, z + 10, Blocks.dirt, 0, 3);
		world.setBlock(x + 2, y + 0, z + 10, Blocks.dirt, 0, 3);
		world.setBlock(x + 3, y + 0, z + 10, Blocks.dirt, 0, 3);
		world.setBlock(x + 4, y + 0, z + 10, Blocks.dirt, 0, 3);
		world.setBlock(x + 5, y + 0, z + 10, Blocks.dirt, 0, 3);
		world.setBlock(x + 6, y + 0, z + 10, Blocks.dirt, 0, 3);
		world.setBlock(x + 7, y + 0, z + 10, Blocks.dirt, 0, 3);
		world.setBlock(x + 8, y + 0, z + 10, Blocks.dirt, 0, 3);
		world.setBlock(x + 9, y + 0, z + 10, Blocks.dirt, 0, 3);
		world.setBlock(x + 10, y + 0, z + 10, Blocks.dirt, 0, 3);
		world.setBlock(x + 0, y + 0, z + 11, Blocks.dirt, 0, 3);
		world.setBlock(x + 1, y + 0, z + 11, Blocks.dirt, 0, 3);
		world.setBlock(x + 2, y + 0, z + 11, Blocks.dirt, 0, 3);
		world.setBlock(x + 3, y + 0, z + 11, Blocks.dirt, 0, 3);
		world.setBlock(x + 4, y + 0, z + 11, Blocks.dirt, 0, 3);
		world.setBlock(x + 5, y + 0, z + 11, Blocks.dirt, 0, 3);
		world.setBlock(x + 6, y + 0, z + 11, Blocks.dirt, 0, 3);
		world.setBlock(x + 7, y + 0, z + 11, Blocks.dirt, 0, 3);
		world.setBlock(x + 8, y + 0, z + 11, Blocks.dirt, 0, 3);
		world.setBlock(x + 9, y + 0, z + 11, Blocks.dirt, 0, 3);
		world.setBlock(x + 10, y + 0, z + 11, Blocks.dirt, 0, 3);
		world.setBlock(x + 0, y + 0, z + 12, Blocks.dirt, 0, 3);
		world.setBlock(x + 1, y + 0, z + 12, Blocks.dirt, 0, 3);
		world.setBlock(x + 2, y + 0, z + 12, Blocks.dirt, 0, 3);
		world.setBlock(x + 3, y + 0, z + 12, Blocks.dirt, 0, 3);
		world.setBlock(x + 4, y + 0, z + 12, Blocks.dirt, 0, 3);
		world.setBlock(x + 5, y + 0, z + 12, Blocks.dirt, 0, 3);
		world.setBlock(x + 6, y + 0, z + 12, Blocks.dirt, 0, 3);
		world.setBlock(x + 7, y + 0, z + 12, Blocks.dirt, 0, 3);
		world.setBlock(x + 8, y + 0, z + 12, Blocks.dirt, 0, 3);
		world.setBlock(x + 9, y + 0, z + 12, Blocks.dirt, 0, 3);
		world.setBlock(x + 10, y + 0, z + 12, Blocks.dirt, 0, 3);
		world.setBlock(x + 0, y + 0, z + 13, Blocks.dirt, 0, 3);
		world.setBlock(x + 1, y + 0, z + 13, Blocks.dirt, 0, 3);
		world.setBlock(x + 2, y + 0, z + 13, Blocks.dirt, 0, 3);
		world.setBlock(x + 3, y + 0, z + 13, Blocks.dirt, 0, 3);
		world.setBlock(x + 4, y + 0, z + 13, Blocks.dirt, 0, 3);
		world.setBlock(x + 5, y + 0, z + 13, Blocks.dirt, 0, 3);
		world.setBlock(x + 6, y + 0, z + 13, Blocks.dirt, 0, 3);
		world.setBlock(x + 7, y + 0, z + 13, Blocks.dirt, 0, 3);
		world.setBlock(x + 8, y + 0, z + 13, Blocks.dirt, 0, 3);
		world.setBlock(x + 9, y + 0, z + 13, Blocks.dirt, 0, 3);
		world.setBlock(x + 10, y + 0, z + 13, Blocks.dirt, 0, 3);
		world.setBlock(x + 0, y + 0, z + 14, Blocks.dirt, 0, 3);
		world.setBlock(x + 1, y + 0, z + 14, Blocks.dirt, 0, 3);
		world.setBlock(x + 2, y + 0, z + 14, Blocks.dirt, 0, 3);
		world.setBlock(x + 3, y + 0, z + 14, Blocks.dirt, 0, 3);
		world.setBlock(x + 4, y + 0, z + 14, Blocks.dirt, 0, 3);
		world.setBlock(x + 5, y + 0, z + 14, Blocks.dirt, 0, 3);
		world.setBlock(x + 6, y + 0, z + 14, Blocks.dirt, 0, 3);
		world.setBlock(x + 7, y + 0, z + 14, Blocks.dirt, 0, 3);
		world.setBlock(x + 8, y + 0, z + 14, Blocks.dirt, 0, 3);
		world.setBlock(x + 9, y + 0, z + 14, Blocks.dirt, 0, 3);
		world.setBlock(x + 10, y + 0, z + 14, Blocks.dirt, 0, 3);
		world.setBlock(x + 0, y + 0, z + 15, Blocks.dirt, 0, 3);
		world.setBlock(x + 1, y + 0, z + 15, Blocks.dirt, 0, 3);
		world.setBlock(x + 2, y + 0, z + 15, Blocks.dirt, 0, 3);
		world.setBlock(x + 3, y + 0, z + 15, Blocks.dirt, 0, 3);
		world.setBlock(x + 4, y + 0, z + 15, Blocks.dirt, 0, 3);
		world.setBlock(x + 5, y + 0, z + 15, Blocks.dirt, 0, 3);
		world.setBlock(x + 6, y + 0, z + 15, Blocks.dirt, 0, 3);
		world.setBlock(x + 7, y + 0, z + 15, Blocks.dirt, 0, 3);
		world.setBlock(x + 8, y + 0, z + 15, Blocks.dirt, 0, 3);
		world.setBlock(x + 9, y + 0, z + 15, Blocks.dirt, 0, 3);
		world.setBlock(x + 10, y + 0, z + 15, Blocks.dirt, 0, 3);
		world.setBlock(x + 0, y + 0, z + 16, Blocks.dirt, 0, 3);
		world.setBlock(x + 1, y + 0, z + 16, Blocks.dirt, 0, 3);
		world.setBlock(x + 2, y + 0, z + 16, Blocks.dirt, 0, 3);
		world.setBlock(x + 3, y + 0, z + 16, Blocks.dirt, 0, 3);
		world.setBlock(x + 4, y + 0, z + 16, Blocks.dirt, 0, 3);
		world.setBlock(x + 5, y + 0, z + 16, Blocks.dirt, 0, 3);
		world.setBlock(x + 6, y + 0, z + 16, Blocks.dirt, 0, 3);
		world.setBlock(x + 7, y + 0, z + 16, Blocks.dirt, 0, 3);
		world.setBlock(x + 8, y + 0, z + 16, Blocks.dirt, 0, 3);
		world.setBlock(x + 9, y + 0, z + 16, Blocks.dirt, 0, 3);
		world.setBlock(x + 10, y + 0, z + 16, Blocks.dirt, 0, 3);
		world.setBlock(x + 0, y + 0, z + 17, Blocks.dirt, 0, 3);
		world.setBlock(x + 1, y + 0, z + 17, Blocks.dirt, 0, 3);
		world.setBlock(x + 2, y + 0, z + 17, Blocks.dirt, 0, 3);
		world.setBlock(x + 3, y + 0, z + 17, Blocks.dirt, 0, 3);
		world.setBlock(x + 4, y + 0, z + 17, Blocks.dirt, 0, 3);
		world.setBlock(x + 5, y + 0, z + 17, Blocks.dirt, 0, 3);
		world.setBlock(x + 6, y + 0, z + 17, Blocks.dirt, 0, 3);
		world.setBlock(x + 7, y + 0, z + 17, Blocks.dirt, 0, 3);
		world.setBlock(x + 8, y + 0, z + 17, Blocks.dirt, 0, 3);
		world.setBlock(x + 9, y + 0, z + 17, Blocks.dirt, 0, 3);
		world.setBlock(x + 10, y + 0, z + 17, Blocks.dirt, 0, 3);
		world.setBlock(x + 0, y + 0, z + 18, Blocks.dirt, 0, 3);
		world.setBlock(x + 1, y + 0, z + 18, Blocks.dirt, 0, 3);
		world.setBlock(x + 2, y + 0, z + 18, Blocks.dirt, 0, 3);
		world.setBlock(x + 3, y + 0, z + 18, Blocks.dirt, 0, 3);
		world.setBlock(x + 4, y + 0, z + 18, Blocks.dirt, 0, 3);
		world.setBlock(x + 5, y + 0, z + 18, Blocks.dirt, 0, 3);
		world.setBlock(x + 6, y + 0, z + 18, Blocks.dirt, 0, 3);
		world.setBlock(x + 7, y + 0, z + 18, Blocks.dirt, 0, 3);
		world.setBlock(x + 8, y + 0, z + 18, Blocks.dirt, 0, 3);
		world.setBlock(x + 9, y + 0, z + 18, Blocks.dirt, 0, 3);
		world.setBlock(x + 10, y + 0, z + 18, Blocks.dirt, 0, 3);
		world.setBlock(x + 0, y + 1, z + 0, Blocks.dirt, 0, 3);
		world.setBlock(x + 1, y + 1, z + 0, Blocks.dirt, 0, 3);
		world.setBlock(x + 2, y + 1, z + 0, Blocks.dirt, 0, 3);
		world.setBlock(x + 3, y + 1, z + 0, Blocks.dirt, 0, 3);
		world.setBlock(x + 4, y + 1, z + 0, Blocks.dirt, 0, 3);
		world.setBlock(x + 5, y + 1, z + 0, Blocks.dirt, 0, 3);
		world.setBlock(x + 6, y + 1, z + 0, Blocks.dirt, 0, 3);
		world.setBlock(x + 7, y + 1, z + 0, Blocks.dirt, 0, 3);
		world.setBlock(x + 8, y + 1, z + 0, Blocks.dirt, 0, 3);
		world.setBlock(x + 9, y + 1, z + 0, Blocks.dirt, 0, 3);
		world.setBlock(x + 10, y + 1, z + 0, Blocks.dirt, 0, 3);
		world.setBlock(x + 0, y + 1, z + 1, Blocks.dirt, 0, 3);
		world.setBlock(x + 1, y + 1, z + 1, Blocks.dirt, 0, 3);
		world.setBlock(x + 2, y + 1, z + 1, Blocks.dirt, 0, 3);
		world.setBlock(x + 3, y + 1, z + 1, Blocks.dirt, 0, 3);
		world.setBlock(x + 4, y + 1, z + 1, Blocks.dirt, 0, 3);
		world.setBlock(x + 5, y + 1, z + 1, Blocks.dirt, 0, 3);
		world.setBlock(x + 6, y + 1, z + 1, Blocks.dirt, 0, 3);
		world.setBlock(x + 7, y + 1, z + 1, Blocks.dirt, 0, 3);
		world.setBlock(x + 8, y + 1, z + 1, Blocks.dirt, 0, 3);
		world.setBlock(x + 9, y + 1, z + 1, Blocks.dirt, 0, 3);
		world.setBlock(x + 10, y + 1, z + 1, Blocks.dirt, 0, 3);
		world.setBlock(x + 0, y + 1, z + 2, Blocks.dirt, 0, 3);
		world.setBlock(x + 1, y + 1, z + 2, Blocks.dirt, 0, 3);
		world.setBlock(x + 2, y + 1, z + 2, Blocks.dirt, 0, 3);
		world.setBlock(x + 3, y + 1, z + 2, Blocks.dirt, 0, 3);
		world.setBlock(x + 4, y + 1, z + 2, Blocks.dirt, 0, 3);
		world.setBlock(x + 5, y + 1, z + 2, Blocks.dirt, 0, 3);
		world.setBlock(x + 6, y + 1, z + 2, Blocks.dirt, 0, 3);
		world.setBlock(x + 7, y + 1, z + 2, Blocks.dirt, 0, 3);
		world.setBlock(x + 8, y + 1, z + 2, Blocks.dirt, 0, 3);
		world.setBlock(x + 9, y + 1, z + 2, Blocks.dirt, 0, 3);
		world.setBlock(x + 10, y + 1, z + 2, Blocks.dirt, 0, 3);
		world.setBlock(x + 0, y + 1, z + 3, Blocks.dirt, 0, 3);
		world.setBlock(x + 1, y + 1, z + 3, Blocks.dirt, 0, 3);
		world.setBlock(x + 2, y + 1, z + 3, Blocks.dirt, 0, 3);
		world.setBlock(x + 3, y + 1, z + 3, Blocks.dirt, 0, 3);
		world.setBlock(x + 4, y + 1, z + 3, Blocks.dirt, 0, 3);
		world.setBlock(x + 5, y + 1, z + 3, Blocks.dirt, 0, 3);
		world.setBlock(x + 6, y + 1, z + 3, Blocks.dirt, 0, 3);
		world.setBlock(x + 7, y + 1, z + 3, Blocks.dirt, 0, 3);
		world.setBlock(x + 8, y + 1, z + 3, Blocks.dirt, 0, 3);
		world.setBlock(x + 9, y + 1, z + 3, Blocks.dirt, 0, 3);
		world.setBlock(x + 10, y + 1, z + 3, Blocks.dirt, 0, 3);
		world.setBlock(x + 0, y + 1, z + 4, Blocks.dirt, 0, 3);
		world.setBlock(x + 1, y + 1, z + 4, Blocks.dirt, 0, 3);
		world.setBlock(x + 2, y + 1, z + 4, Blocks.dirt, 0, 3);
		world.setBlock(x + 3, y + 1, z + 4, Blocks.dirt, 0, 3);
		world.setBlock(x + 4, y + 1, z + 4, Blocks.dirt, 0, 3);
		world.setBlock(x + 5, y + 1, z + 4, Blocks.dirt, 0, 3);
		world.setBlock(x + 6, y + 1, z + 4, Blocks.dirt, 0, 3);
		world.setBlock(x + 7, y + 1, z + 4, Blocks.dirt, 0, 3);
		world.setBlock(x + 8, y + 1, z + 4, Blocks.dirt, 0, 3);
		world.setBlock(x + 9, y + 1, z + 4, Blocks.dirt, 0, 3);
		world.setBlock(x + 10, y + 1, z + 4, Blocks.dirt, 0, 3);
		world.setBlock(x + 0, y + 1, z + 5, Blocks.dirt, 0, 3);
		world.setBlock(x + 1, y + 1, z + 5, Blocks.dirt, 0, 3);
		world.setBlock(x + 2, y + 1, z + 5, Blocks.dirt, 0, 3);
		world.setBlock(x + 3, y + 1, z + 5, Blocks.dirt, 0, 3);
		world.setBlock(x + 4, y + 1, z + 5, Blocks.dirt, 0, 3);
		world.setBlock(x + 5, y + 1, z + 5, Blocks.dirt, 0, 3);
		world.setBlock(x + 6, y + 1, z + 5, Blocks.dirt, 0, 3);
		world.setBlock(x + 7, y + 1, z + 5, Blocks.dirt, 0, 3);
		world.setBlock(x + 8, y + 1, z + 5, Blocks.dirt, 0, 3);
		world.setBlock(x + 9, y + 1, z + 5, Blocks.dirt, 0, 3);
		world.setBlock(x + 10, y + 1, z + 5, Blocks.dirt, 0, 3);
		world.setBlock(x + 0, y + 1, z + 6, Blocks.dirt, 0, 3);
		world.setBlock(x + 1, y + 1, z + 6, Blocks.dirt, 0, 3);
		world.setBlock(x + 2, y + 1, z + 6, Blocks.dirt, 0, 3);
		world.setBlock(x + 3, y + 1, z + 6, Blocks.dirt, 0, 3);
		world.setBlock(x + 4, y + 1, z + 6, Blocks.dirt, 0, 3);
		world.setBlock(x + 5, y + 1, z + 6, Blocks.dirt, 0, 3);
		world.setBlock(x + 6, y + 1, z + 6, Blocks.dirt, 0, 3);
		world.setBlock(x + 7, y + 1, z + 6, Blocks.dirt, 0, 3);
		world.setBlock(x + 8, y + 1, z + 6, Blocks.dirt, 0, 3);
		world.setBlock(x + 9, y + 1, z + 6, Blocks.dirt, 0, 3);
		world.setBlock(x + 10, y + 1, z + 6, Blocks.dirt, 0, 3);
		world.setBlock(x + 0, y + 1, z + 7, Blocks.dirt, 0, 3);
		world.setBlock(x + 1, y + 1, z + 7, Blocks.dirt, 0, 3);
		world.setBlock(x + 2, y + 1, z + 7, Blocks.dirt, 0, 3);
		world.setBlock(x + 3, y + 1, z + 7, Blocks.dirt, 0, 3);
		world.setBlock(x + 4, y + 1, z + 7, Blocks.dirt, 0, 3);
		world.setBlock(x + 5, y + 1, z + 7, Blocks.dirt, 0, 3);
		world.setBlock(x + 6, y + 1, z + 7, Blocks.dirt, 0, 3);
		world.setBlock(x + 7, y + 1, z + 7, Blocks.dirt, 0, 3);
		world.setBlock(x + 8, y + 1, z + 7, Blocks.dirt, 0, 3);
		world.setBlock(x + 9, y + 1, z + 7, Blocks.dirt, 0, 3);
		world.setBlock(x + 10, y + 1, z + 7, Blocks.dirt, 0, 3);
		world.setBlock(x + 0, y + 1, z + 8, Blocks.dirt, 0, 3);
		world.setBlock(x + 1, y + 1, z + 8, Blocks.dirt, 0, 3);
		world.setBlock(x + 2, y + 1, z + 8, Blocks.dirt, 0, 3);
		world.setBlock(x + 3, y + 1, z + 8, Blocks.dirt, 0, 3);
		world.setBlock(x + 4, y + 1, z + 8, Blocks.dirt, 0, 3);
		world.setBlock(x + 5, y + 1, z + 8, Blocks.dirt, 0, 3);
		world.setBlock(x + 6, y + 1, z + 8, Blocks.dirt, 0, 3);
		world.setBlock(x + 7, y + 1, z + 8, Blocks.dirt, 0, 3);
		world.setBlock(x + 8, y + 1, z + 8, Blocks.dirt, 0, 3);
		world.setBlock(x + 9, y + 1, z + 8, Blocks.dirt, 0, 3);
		world.setBlock(x + 10, y + 1, z + 8, Blocks.dirt, 0, 3);
		world.setBlock(x + 0, y + 1, z + 9, Blocks.dirt, 0, 3);
		world.setBlock(x + 1, y + 1, z + 9, Blocks.dirt, 0, 3);
		world.setBlock(x + 2, y + 1, z + 9, Blocks.dirt, 0, 3);
		world.setBlock(x + 3, y + 1, z + 9, Blocks.dirt, 0, 3);
		world.setBlock(x + 4, y + 1, z + 9, Blocks.dirt, 0, 3);
		world.setBlock(x + 5, y + 1, z + 9, Blocks.dirt, 0, 3);
		world.setBlock(x + 6, y + 1, z + 9, Blocks.dirt, 0, 3);
		world.setBlock(x + 7, y + 1, z + 9, Blocks.dirt, 0, 3);
		world.setBlock(x + 8, y + 1, z + 9, Blocks.dirt, 0, 3);
		world.setBlock(x + 9, y + 1, z + 9, Blocks.dirt, 0, 3);
		world.setBlock(x + 10, y + 1, z + 9, Blocks.dirt, 0, 3);
		world.setBlock(x + 0, y + 1, z + 10, Blocks.dirt, 0, 3);
		world.setBlock(x + 1, y + 1, z + 10, Blocks.dirt, 0, 3);
		world.setBlock(x + 2, y + 1, z + 10, Blocks.dirt, 2, 3);
		world.setBlock(x + 3, y + 1, z + 10, Blocks.sand, 0, 3);
		world.setBlock(x + 4, y + 1, z + 10, Blocks.dirt, 0, 3);
		world.setBlock(x + 5, y + 1, z + 10, Blocks.dirt, 0, 3);
		world.setBlock(x + 6, y + 1, z + 10, Blocks.dirt, 0, 3);
		world.setBlock(x + 7, y + 1, z + 10, Blocks.dirt, 0, 3);
		world.setBlock(x + 8, y + 1, z + 10, Blocks.dirt, 0, 3);
		world.setBlock(x + 9, y + 1, z + 10, Blocks.dirt, 0, 3);
		world.setBlock(x + 10, y + 1, z + 10, Blocks.dirt, 0, 3);
		world.setBlock(x + 0, y + 1, z + 11, Blocks.dirt, 0, 3);
		world.setBlock(x + 1, y + 1, z + 11, Blocks.dirt, 0, 3);
		world.setBlock(x + 2, y + 1, z + 11, Blocks.sand, 0, 3);
		world.setBlock(x + 3, y + 1, z + 11, FABlockRegistry.INSTANCE.tar, 0, 3);
		world.setBlock(x + 4, y + 1, z + 11, FABlockRegistry.INSTANCE.tar, 0, 3);
		world.setBlock(x + 5, y + 1, z + 11, Blocks.dirt, 2, 3);
		world.setBlock(x + 6, y + 1, z + 11, Blocks.dirt, 0, 3);
		world.setBlock(x + 7, y + 1, z + 11, Blocks.dirt, 0, 3);
		world.setBlock(x + 8, y + 1, z + 11, Blocks.dirt, 0, 3);
		world.setBlock(x + 9, y + 1, z + 11, Blocks.dirt, 0, 3);
		world.setBlock(x + 10, y + 1, z + 11, Blocks.dirt, 0, 3);
		world.setBlock(x + 0, y + 1, z + 12, Blocks.dirt, 0, 3);
		world.setBlock(x + 1, y + 1, z + 12, Blocks.sand, 0, 3);
		world.setBlock(x + 2, y + 1, z + 12, FABlockRegistry.INSTANCE.tar, 0, 3);
		world.setBlock(x + 3, y + 1, z + 12, FABlockRegistry.INSTANCE.tar, 0, 3);
		world.setBlock(x + 4, y + 1, z + 12, FABlockRegistry.INSTANCE.tar, 0, 3);
		world.setBlock(x + 5, y + 1, z + 12, FABlockRegistry.INSTANCE.tar, 0, 3);
		world.setBlock(x + 6, y + 1, z + 12, Blocks.sand, 0, 3);
		world.setBlock(x + 7, y + 1, z + 12, Blocks.dirt, 0, 3);
		world.setBlock(x + 8, y + 1, z + 12, Blocks.dirt, 0, 3);
		world.setBlock(x + 9, y + 1, z + 12, Blocks.dirt, 0, 3);
		world.setBlock(x + 10, y + 1, z + 12, Blocks.dirt, 0, 3);
		world.setBlock(x + 0, y + 1, z + 13, Blocks.dirt, 0, 3);
		world.setBlock(x + 1, y + 1, z + 13, Blocks.dirt, 0, 3);
		world.setBlock(x + 2, y + 1, z + 13, Blocks.sand, 0, 3);
		world.setBlock(x + 3, y + 1, z + 13, Blocks.sand, 0, 3);
		world.setBlock(x + 4, y + 1, z + 13, FABlockRegistry.INSTANCE.tar, 0, 3);
		world.setBlock(x + 5, y + 1, z + 13, FABlockRegistry.INSTANCE.tar, 0, 3);
		world.setBlock(x + 6, y + 1, z + 13, FABlockRegistry.INSTANCE.tar, 0, 3);
		world.setBlock(x + 7, y + 1, z + 13, Blocks.sand, 0, 3);
		world.setBlock(x + 8, y + 1, z + 13, Blocks.dirt, 0, 3);
		world.setBlock(x + 9, y + 1, z + 13, Blocks.dirt, 0, 3);
		world.setBlock(x + 10, y + 1, z + 13, Blocks.dirt, 0, 3);
		world.setBlock(x + 0, y + 1, z + 14, Blocks.dirt, 0, 3);
		world.setBlock(x + 1, y + 1, z + 14, Blocks.dirt, 0, 3);
		world.setBlock(x + 2, y + 1, z + 14, Blocks.dirt, 0, 3);
		world.setBlock(x + 3, y + 1, z + 14, Blocks.dirt, 0, 3);
		world.setBlock(x + 4, y + 1, z + 14, Blocks.sand, 0, 3);
		world.setBlock(x + 5, y + 1, z + 14, FABlockRegistry.INSTANCE.tar, 0, 3);
		world.setBlock(x + 6, y + 1, z + 14, FABlockRegistry.INSTANCE.tar, 0, 3);
		world.setBlock(x + 7, y + 1, z + 14, Blocks.sand, 0, 3);
		world.setBlock(x + 8, y + 1, z + 14, Blocks.dirt, 0, 3);
		world.setBlock(x + 9, y + 1, z + 14, Blocks.dirt, 0, 3);
		world.setBlock(x + 10, y + 1, z + 14, Blocks.dirt, 0, 3);
		world.setBlock(x + 0, y + 1, z + 15, Blocks.dirt, 0, 3);
		world.setBlock(x + 1, y + 1, z + 15, Blocks.dirt, 0, 3);
		world.setBlock(x + 2, y + 1, z + 15, Blocks.dirt, 0, 3);
		world.setBlock(x + 3, y + 1, z + 15, Blocks.sand, 0, 3);
		world.setBlock(x + 4, y + 1, z + 15, FABlockRegistry.INSTANCE.tar, 0, 3);
		world.setBlock(x + 5, y + 1, z + 15, FABlockRegistry.INSTANCE.tar, 0, 3);
		world.setBlock(x + 6, y + 1, z + 15, Blocks.sand, 0, 3);
		world.setBlock(x + 7, y + 1, z + 15, Blocks.dirt, 0, 3);
		world.setBlock(x + 8, y + 1, z + 15, Blocks.dirt, 0, 3);
		world.setBlock(x + 9, y + 1, z + 15, Blocks.dirt, 0, 3);
		world.setBlock(x + 10, y + 1, z + 15, Blocks.dirt, 0, 3);
		world.setBlock(x + 0, y + 1, z + 16, Blocks.dirt, 0, 3);
		world.setBlock(x + 1, y + 1, z + 16, Blocks.dirt, 0, 3);
		world.setBlock(x + 2, y + 1, z + 16, Blocks.dirt, 0, 3);
		world.setBlock(x + 3, y + 1, z + 16, Blocks.dirt, 0, 3);
		world.setBlock(x + 4, y + 1, z + 16, Blocks.sand, 0, 3);
		world.setBlock(x + 5, y + 1, z + 16, Blocks.dirt, 2, 3);
		world.setBlock(x + 6, y + 1, z + 16, Blocks.dirt, 2, 3);
		world.setBlock(x + 7, y + 1, z + 16, Blocks.dirt, 0, 3);
		world.setBlock(x + 8, y + 1, z + 16, Blocks.dirt, 0, 3);
		world.setBlock(x + 9, y + 1, z + 16, Blocks.dirt, 0, 3);
		world.setBlock(x + 10, y + 1, z + 16, Blocks.dirt, 0, 3);
		world.setBlock(x + 0, y + 1, z + 17, Blocks.dirt, 0, 3);
		world.setBlock(x + 1, y + 1, z + 17, Blocks.dirt, 0, 3);
		world.setBlock(x + 2, y + 1, z + 17, Blocks.dirt, 0, 3);
		world.setBlock(x + 3, y + 1, z + 17, Blocks.dirt, 0, 3);
		world.setBlock(x + 4, y + 1, z + 17, Blocks.dirt, 0, 3);
		world.setBlock(x + 5, y + 1, z + 17, Blocks.dirt, 0, 3);
		world.setBlock(x + 6, y + 1, z + 17, Blocks.dirt, 0, 3);
		world.setBlock(x + 7, y + 1, z + 17, Blocks.dirt, 0, 3);
		world.setBlock(x + 8, y + 1, z + 17, Blocks.dirt, 0, 3);
		world.setBlock(x + 9, y + 1, z + 17, Blocks.dirt, 0, 3);
		world.setBlock(x + 10, y + 1, z + 17, Blocks.dirt, 0, 3);
		world.setBlock(x + 0, y + 1, z + 18, Blocks.dirt, 0, 3);
		world.setBlock(x + 1, y + 1, z + 18, Blocks.dirt, 0, 3);
		world.setBlock(x + 2, y + 1, z + 18, Blocks.dirt, 0, 3);
		world.setBlock(x + 3, y + 1, z + 18, Blocks.dirt, 0, 3);
		world.setBlock(x + 4, y + 1, z + 18, Blocks.dirt, 0, 3);
		world.setBlock(x + 5, y + 1, z + 18, Blocks.dirt, 0, 3);
		world.setBlock(x + 6, y + 1, z + 18, Blocks.dirt, 0, 3);
		world.setBlock(x + 7, y + 1, z + 18, Blocks.dirt, 0, 3);
		world.setBlock(x + 8, y + 1, z + 18, Blocks.dirt, 0, 3);
		world.setBlock(x + 9, y + 1, z + 18, Blocks.dirt, 0, 3);
		world.setBlock(x + 10, y + 1, z + 18, Blocks.dirt, 0, 3);
		world.setBlock(x + 0, y + 2, z + 0, Blocks.grass, 0, 3);
		world.setBlock(x + 1, y + 2, z + 0, Blocks.grass, 0, 3);
		world.setBlock(x + 2, y + 2, z + 0, Blocks.grass, 0, 3);
		world.setBlock(x + 3, y + 2, z + 0, Blocks.dirt, 0, 3);
		world.setBlock(x + 4, y + 2, z + 0, Blocks.dirt, 0, 3);
		world.setBlock(x + 5, y + 2, z + 0, Blocks.dirt, 0, 3);
		world.setBlock(x + 6, y + 2, z + 0, Blocks.grass, 0, 3);
		world.setBlock(x + 7, y + 2, z + 0, Blocks.grass, 0, 3);
		world.setBlock(x + 8, y + 2, z + 0, Blocks.grass, 0, 3);
		world.setBlock(x + 9, y + 2, z + 0, Blocks.grass, 0, 3);
		world.setBlock(x + 10, y + 2, z + 0, Blocks.grass, 0, 3);
		world.setBlock(x + 0, y + 2, z + 1, Blocks.grass, 0, 3);
		world.setBlock(x + 1, y + 2, z + 1, Blocks.grass, 0, 3);
		world.setBlock(x + 2, y + 2, z + 1, Blocks.dirt, 0, 3);
		world.setBlock(x + 3, y + 2, z + 1, Blocks.dirt, 1, 3);
		world.setBlock(x + 4, y + 2, z + 1, Blocks.dirt, 1, 3);
		world.setBlock(x + 5, y + 2, z + 1, Blocks.dirt, 1, 3);
		world.setBlock(x + 6, y + 2, z + 1, Blocks.dirt, 0, 3);
		world.setBlock(x + 7, y + 2, z + 1, Blocks.grass, 0, 3);
		world.setBlock(x + 8, y + 2, z + 1, Blocks.grass, 0, 3);
		world.setBlock(x + 9, y + 2, z + 1, Blocks.grass, 0, 3);
		world.setBlock(x + 10, y + 2, z + 1, Blocks.grass, 0, 3);
		world.setBlock(x + 0, y + 2, z + 2, Blocks.grass, 0, 3);
		world.setBlock(x + 1, y + 2, z + 2, Blocks.grass, 0, 3);
		world.setBlock(x + 2, y + 2, z + 2, Blocks.dirt, 0, 3);
		world.setBlock(x + 3, y + 2, z + 2, Blocks.dirt, 1, 3);
		world.setBlock(x + 4, y + 2, z + 2, Blocks.dirt, 1, 3);
		world.setBlock(x + 5, y + 2, z + 2, Blocks.dirt, 1, 3);
		world.setBlock(x + 6, y + 2, z + 2, Blocks.dirt, 0, 3);
		world.setBlock(x + 7, y + 2, z + 2, Blocks.grass, 0, 3);
		world.setBlock(x + 8, y + 2, z + 2, Blocks.grass, 0, 3);
		world.setBlock(x + 9, y + 2, z + 2, Blocks.grass, 0, 3);
		world.setBlock(x + 10, y + 2, z + 2, Blocks.grass, 0, 3);
		world.setBlock(x + 0, y + 2, z + 3, Blocks.grass, 0, 3);
		world.setBlock(x + 1, y + 2, z + 3, Blocks.grass, 0, 3);
		world.setBlock(x + 2, y + 2, z + 3, Blocks.dirt, 0, 3);
		world.setBlock(x + 3, y + 2, z + 3, Blocks.dirt, 1, 3);
		world.setBlock(x + 4, y + 2, z + 3, Blocks.dirt, 1, 3);
		world.setBlock(x + 5, y + 2, z + 3, Blocks.dirt, 1, 3);
		world.setBlock(x + 6, y + 2, z + 3, Blocks.dirt, 0, 3);
		world.setBlock(x + 7, y + 2, z + 3, Blocks.grass, 0, 3);
		world.setBlock(x + 8, y + 2, z + 3, Blocks.grass, 0, 3);
		world.setBlock(x + 9, y + 2, z + 3, Blocks.grass, 0, 3);
		world.setBlock(x + 10, y + 2, z + 3, Blocks.grass, 0, 3);
		world.setBlock(x + 0, y + 2, z + 4, Blocks.grass, 0, 3);
		world.setBlock(x + 1, y + 2, z + 4, Blocks.grass, 0, 3);
		world.setBlock(x + 2, y + 2, z + 4, Blocks.dirt, 0, 3);
		world.setBlock(x + 3, y + 2, z + 4, Blocks.dirt, 1, 3);
		world.setBlock(x + 4, y + 2, z + 4, Blocks.dirt, 1, 3);
		world.setBlock(x + 5, y + 2, z + 4, Blocks.dirt, 1, 3);
		world.setBlock(x + 6, y + 2, z + 4, Blocks.dirt, 0, 3);
		world.setBlock(x + 7, y + 2, z + 4, Blocks.grass, 0, 3);
		world.setBlock(x + 8, y + 2, z + 4, Blocks.grass, 0, 3);
		world.setBlock(x + 9, y + 2, z + 4, Blocks.grass, 0, 3);
		world.setBlock(x + 10, y + 2, z + 4, Blocks.grass, 0, 3);
		world.setBlock(x + 0, y + 2, z + 5, Blocks.grass, 0, 3);
		world.setBlock(x + 1, y + 2, z + 5, Blocks.grass, 0, 3);
		world.setBlock(x + 2, y + 2, z + 5, Blocks.grass, 0, 3);
		world.setBlock(x + 3, y + 2, z + 5, Blocks.dirt, 0, 3);
		world.setBlock(x + 4, y + 2, z + 5, Blocks.dirt, 1, 3);
		world.setBlock(x + 5, y + 2, z + 5, Blocks.dirt, 0, 3);
		world.setBlock(x + 6, y + 2, z + 5, Blocks.grass, 0, 3);
		world.setBlock(x + 7, y + 2, z + 5, Blocks.grass, 0, 3);
		world.setBlock(x + 8, y + 2, z + 5, Blocks.grass, 0, 3);
		world.setBlock(x + 9, y + 2, z + 5, Blocks.grass, 0, 3);
		world.setBlock(x + 10, y + 2, z + 5, Blocks.grass, 0, 3);
		world.setBlock(x + 0, y + 2, z + 6, Blocks.grass, 0, 3);
		world.setBlock(x + 1, y + 2, z + 6, Blocks.grass, 0, 3);
		world.setBlock(x + 2, y + 2, z + 6, Blocks.grass, 0, 3);
		world.setBlock(x + 3, y + 2, z + 6, Blocks.grass, 0, 3);
		world.setBlock(x + 4, y + 2, z + 6, Blocks.dirt, 2, 3);
		world.setBlock(x + 5, y + 2, z + 6, Blocks.grass, 0, 3);
		world.setBlock(x + 6, y + 2, z + 6, Blocks.grass, 0, 3);
		world.setBlock(x + 7, y + 2, z + 6, Blocks.grass, 0, 3);
		world.setBlock(x + 8, y + 2, z + 6, Blocks.grass, 0, 3);
		world.setBlock(x + 9, y + 2, z + 6, Blocks.grass, 0, 3);
		world.setBlock(x + 10, y + 2, z + 6, Blocks.grass, 0, 3);
		world.setBlock(x + 0, y + 2, z + 7, Blocks.grass, 0, 3);
		world.setBlock(x + 1, y + 2, z + 7, Blocks.grass, 0, 3);
		world.setBlock(x + 2, y + 2, z + 7, Blocks.grass, 0, 3);
		world.setBlock(x + 3, y + 2, z + 7, Blocks.dirt, 2, 3);
		world.setBlock(x + 4, y + 2, z + 7, Blocks.dirt, 2, 3);
		world.setBlock(x + 5, y + 2, z + 7, Blocks.dirt, 2, 3);
		world.setBlock(x + 6, y + 2, z + 7, Blocks.dirt, 2, 3);
		world.setBlock(x + 7, y + 2, z + 7, Blocks.dirt, 2, 3);
		world.setBlock(x + 8, y + 2, z + 7, Blocks.grass, 0, 3);
		world.setBlock(x + 9, y + 2, z + 7, Blocks.grass, 0, 3);
		world.setBlock(x + 10, y + 2, z + 7, Blocks.grass, 0, 3);
		world.setBlock(x + 0, y + 2, z + 8, Blocks.grass, 0, 3);
		world.setBlock(x + 1, y + 2, z + 8, Blocks.grass, 0, 3);
		world.setBlock(x + 2, y + 2, z + 8, Blocks.dirt, 2, 3);
		world.setBlock(x + 3, y + 2, z + 8, Blocks.grass, 0, 3);
		world.setBlock(x + 4, y + 2, z + 8, Blocks.dirt, 2, 3);
		world.setBlock(x + 5, y + 2, z + 8, Blocks.dirt, 2, 3);
		world.setBlock(x + 6, y + 2, z + 8, Blocks.soul_sand, 0, 3);
		world.setBlock(x + 7, y + 2, z + 8, Blocks.dirt, 2, 3);
		world.setBlock(x + 8, y + 2, z + 8, Blocks.dirt, 2, 3);
		world.setBlock(x + 9, y + 2, z + 8, Blocks.grass, 0, 3);
		world.setBlock(x + 10, y + 2, z + 8, Blocks.grass, 0, 3);
		world.setBlock(x + 0, y + 2, z + 9, Blocks.grass, 0, 3);
		world.setBlock(x + 1, y + 2, z + 9, Blocks.dirt, 2, 3);
		world.setBlock(x + 2, y + 2, z + 9, Blocks.dirt, 2, 3);
		world.setBlock(x + 3, y + 2, z + 9, Blocks.dirt, 2, 3);
		world.setBlock(x + 4, y + 2, z + 9, Blocks.dirt, 2, 3);
		world.setBlock(x + 5, y + 2, z + 9, Blocks.soul_sand, 0, 3);
		world.setBlock(x + 6, y + 2, z + 9, Blocks.soul_sand, 0, 3);
		world.setBlock(x + 7, y + 2, z + 9, Blocks.dirt, 2, 3);
		world.setBlock(x + 8, y + 2, z + 9, Blocks.dirt, 2, 3);
		world.setBlock(x + 9, y + 2, z + 9, Blocks.dirt, 2, 3);
		world.setBlock(x + 10, y + 2, z + 9, Blocks.grass, 0, 3);
		world.setBlock(x + 0, y + 2, z + 10, Blocks.grass, 0, 3);
		world.setBlock(x + 1, y + 2, z + 10, Blocks.dirt, 2, 3);
		world.setBlock(x + 2, y + 2, z + 10, Blocks.air, 0, 3);
		world.setBlock(x + 3, y + 2, z + 10, Blocks.air, 0, 3);
		world.setBlock(x + 4, y + 2, z + 10, Blocks.dirt, 2, 3);
		world.setBlock(x + 5, y + 2, z + 10, Blocks.dirt, 2, 3);
		world.setBlock(x + 6, y + 2, z + 10, Blocks.dirt, 2, 3);
		world.setBlock(x + 7, y + 2, z + 10, Blocks.soul_sand, 0, 3);
		world.setBlock(x + 8, y + 2, z + 10, Blocks.dirt, 2, 3);
		world.setBlock(x + 9, y + 2, z + 10, Blocks.dirt, 2, 3);
		world.setBlock(x + 10, y + 2, z + 10, Blocks.grass, 0, 3);
		world.setBlock(x + 0, y + 2, z + 11, Blocks.dirt, 2, 3);
		world.setBlock(x + 1, y + 2, z + 11, Blocks.dirt, 2, 3);
		world.setBlock(x + 2, y + 2, z + 11, Blocks.air, 0, 3);
		world.setBlock(x + 3, y + 2, z + 11, Blocks.air, 0, 3);
		world.setBlock(x + 4, y + 2, z + 11, Blocks.air, 0, 3);
		world.setBlock(x + 5, y + 2, z + 11, Blocks.air, 0, 3);
		world.setBlock(x + 6, y + 2, z + 11, Blocks.dirt, 2, 3);
		world.setBlock(x + 7, y + 2, z + 11, Blocks.dirt, 2, 3);
		world.setBlock(x + 8, y + 2, z + 11, Blocks.dirt, 2, 3);
		world.setBlock(x + 9, y + 2, z + 11, Blocks.dirt, 2, 3);
		world.setBlock(x + 10, y + 2, z + 11, Blocks.dirt, 2, 3);
		world.setBlock(x + 0, y + 2, z + 12, Blocks.dirt, 2, 3);
		world.setBlock(x + 1, y + 2, z + 12, Blocks.air, 0, 3);
		world.setBlock(x + 2, y + 2, z + 12, Blocks.air, 0, 3);
		world.setBlock(x + 3, y + 2, z + 12, Blocks.air, 0, 3);
		world.setBlock(x + 4, y + 2, z + 12, Blocks.air, 0, 3);
		world.setBlock(x + 5, y + 2, z + 12, Blocks.air, 0, 3);
		world.setBlock(x + 6, y + 2, z + 12, Blocks.air, 0, 3);
		world.setBlock(x + 7, y + 2, z + 12, Blocks.dirt, 2, 3);
		world.setBlock(x + 8, y + 2, z + 12, Blocks.sand, 0, 3);
		world.setBlock(x + 9, y + 2, z + 12, Blocks.grass, 0, 3);
		world.setBlock(x + 10, y + 2, z + 12, Blocks.dirt, 2, 3);
		world.setBlock(x + 0, y + 2, z + 13, Blocks.dirt, 2, 3);
		world.setBlock(x + 1, y + 2, z + 13, Blocks.dirt, 2, 3);
		world.setBlock(x + 2, y + 2, z + 13, Blocks.air, 0, 3);
		world.setBlock(x + 3, y + 2, z + 13, Blocks.air, 0, 3);
		world.setBlock(x + 4, y + 2, z + 13, Blocks.air, 0, 3);
		world.setBlock(x + 5, y + 2, z + 13, Blocks.air, 0, 3);
		world.setBlock(x + 6, y + 2, z + 13, Blocks.air, 0, 3);
		world.setBlock(x + 7, y + 2, z + 13, Blocks.air, 0, 3);
		world.setBlock(x + 8, y + 2, z + 13, Blocks.dirt, 2, 3);
		world.setBlock(x + 9, y + 2, z + 13, Blocks.grass, 0, 3);
		world.setBlock(x + 10, y + 2, z + 13, Blocks.dirt, 2, 3);
		world.setBlock(x + 0, y + 2, z + 14, Blocks.grass, 0, 3);
		world.setBlock(x + 1, y + 2, z + 14, Blocks.mycelium, 0, 3);
		world.setBlock(x + 2, y + 2, z + 14, Blocks.dirt, 2, 3);
		world.setBlock(x + 3, y + 2, z + 14, Blocks.dirt, 2, 3);
		world.setBlock(x + 4, y + 2, z + 14, Blocks.air, 0, 3);
		world.setBlock(x + 5, y + 2, z + 14, Blocks.air, 0, 3);
		world.setBlock(x + 6, y + 2, z + 14, Blocks.air, 0, 3);
		world.setBlock(x + 7, y + 2, z + 14, Blocks.air, 0, 3);
		world.setBlock(x + 8, y + 2, z + 14, Blocks.dirt, 2, 3);
		world.setBlock(x + 9, y + 2, z + 14, Blocks.sand, 0, 3);
		world.setBlock(x + 10, y + 2, z + 14, Blocks.dirt, 2, 3);
		world.setBlock(x + 0, y + 2, z + 15, Blocks.grass, 0, 3);
		world.setBlock(x + 1, y + 2, z + 15, Blocks.dirt, 2, 3);
		world.setBlock(x + 2, y + 2, z + 15, Blocks.dirt, 2, 3);
		world.setBlock(x + 3, y + 2, z + 15, Blocks.air, 0, 3);
		world.setBlock(x + 4, y + 2, z + 15, Blocks.air, 0, 3);
		world.setBlock(x + 5, y + 2, z + 15, Blocks.air, 0, 3);
		world.setBlock(x + 6, y + 2, z + 15, Blocks.air, 0, 3);
		world.setBlock(x + 7, y + 2, z + 15, Blocks.dirt, 2, 3);
		world.setBlock(x + 8, y + 2, z + 15, Blocks.dirt, 2, 3);
		world.setBlock(x + 9, y + 2, z + 15, Blocks.dirt, 2, 3);
		world.setBlock(x + 10, y + 2, z + 15, Blocks.grass, 0, 3);
		world.setBlock(x + 0, y + 2, z + 16, Blocks.grass, 0, 3);
		world.setBlock(x + 1, y + 2, z + 16, Blocks.dirt, 2, 3);
		world.setBlock(x + 2, y + 2, z + 16, Blocks.mycelium, 0, 3);
		world.setBlock(x + 3, y + 2, z + 16, Blocks.sand, 0, 3);
		world.setBlock(x + 4, y + 2, z + 16, Blocks.air, 0, 3);
		world.setBlock(x + 5, y + 2, z + 16, Blocks.air, 0, 3);
		world.setBlock(x + 6, y + 2, z + 16, Blocks.air, 0, 3);
		world.setBlock(x + 7, y + 2, z + 16, Blocks.grass, 0, 3);
		world.setBlock(x + 8, y + 2, z + 16, Blocks.dirt, 2, 3);
		world.setBlock(x + 9, y + 2, z + 16, Blocks.grass, 0, 3);
		world.setBlock(x + 10, y + 2, z + 16, Blocks.grass, 0, 3);
		world.setBlock(x + 0, y + 2, z + 17, Blocks.grass, 0, 3);
		world.setBlock(x + 1, y + 2, z + 17, Blocks.grass, 0, 3);
		world.setBlock(x + 2, y + 2, z + 17, Blocks.dirt, 2, 3);
		world.setBlock(x + 3, y + 2, z + 17, Blocks.mycelium, 0, 3);
		world.setBlock(x + 4, y + 2, z + 17, Blocks.dirt, 2, 3);
		world.setBlock(x + 5, y + 2, z + 17, Blocks.dirt, 2, 3);
		world.setBlock(x + 6, y + 2, z + 17, Blocks.dirt, 2, 3);
		world.setBlock(x + 7, y + 2, z + 17, Blocks.dirt, 2, 3);
		world.setBlock(x + 8, y + 2, z + 17, Blocks.grass, 0, 3);
		world.setBlock(x + 9, y + 2, z + 17, Blocks.grass, 0, 3);
		world.setBlock(x + 10, y + 2, z + 17, Blocks.grass, 0, 3);
		world.setBlock(x + 0, y + 2, z + 18, Blocks.grass, 0, 3);
		world.setBlock(x + 1, y + 2, z + 18, Blocks.grass, 0, 3);
		world.setBlock(x + 2, y + 2, z + 18, Blocks.grass, 0, 3);
		world.setBlock(x + 3, y + 2, z + 18, Blocks.dirt, 2, 3);
		world.setBlock(x + 4, y + 2, z + 18, Blocks.dirt, 2, 3);
		world.setBlock(x + 5, y + 2, z + 18, Blocks.grass, 0, 3);
		world.setBlock(x + 6, y + 2, z + 18, Blocks.grass, 0, 3);
		world.setBlock(x + 7, y + 2, z + 18, Blocks.grass, 0, 3);
		world.setBlock(x + 8, y + 2, z + 18, Blocks.grass, 0, 3);
		world.setBlock(x + 9, y + 2, z + 18, Blocks.grass, 0, 3);
		world.setBlock(x + 10, y + 2, z + 18, Blocks.grass, 0, 3);
		world.setBlock(x + 2, y + 3, z + 0, Blocks.fence, 0, 3);
		world.setBlock(x + 3, y + 3, z + 0, Blocks.wool, 0, 3);
		world.setBlock(x + 4, y + 3, z + 0, Blocks.wool, 0, 3);
		world.setBlock(x + 5, y + 3, z + 0, Blocks.wool, 0, 3);
		world.setBlock(x + 6, y + 3, z + 0, Blocks.fence, 0, 3);
		world.setBlock(x + 2, y + 3, z + 1, Blocks.wool, 0, 3);
		world.setBlock(x + 3, y + 3, z + 1, Blocks.wool, 0, 3);
		world.setBlock(x + 4, y + 3, z + 1, Blocks.fence, 0, 3);
		world.setBlock(x + 5, y + 3, z + 1, Blocks.wool, 0, 3);
		world.setBlock(x + 6, y + 3, z + 1, Blocks.wool, 0, 3);
		world.setBlock(x + 2, y + 3, z + 2, Blocks.wool, 0, 3);
		world.setBlock(x + 3, y + 3, z + 2, Blocks.bed, 10, 3);
		world.setBlock(x + 4, y + 3, z + 2, Blocks.air, 0, 3);
		world.setBlock(x + 5, y + 3, z + 2, FABlockRegistry.INSTANCE.blockworktableIdle, 0, 3);
		world.setBlock(x + 6, y + 3, z + 2, Blocks.wool, 0, 3);
		world.setBlock(x + 2, y + 3, z + 3, Blocks.wool, 0, 3);
		world.setBlock(x + 3, y + 3, z + 3, Blocks.bed, 2, 3);
		world.setBlock(x + 4, y + 3, z + 3, Blocks.air, 0, 3);
		world.setBlock(x + 5, y + 3, z + 3, FABlockRegistry.INSTANCE.blockanalyzerIdle, 0, 3);
		world.setBlock(x + 6, y + 3, z + 3, Blocks.wool, 0, 3);
		world.setBlock(x + 2, y + 3, z + 4, Blocks.wool, 0, 3);
		world.setBlock(x + 3, y + 3, z + 4, Blocks.fence, 0, 3);
		world.setBlock(x + 4, y + 3, z + 4, Blocks.air, 0, 3);
		world.setBlock(x + 5, y + 3, z + 4, Blocks.fence, 0, 3);
		world.setBlock(x + 6, y + 3, z + 4, Blocks.wool, 0, 3);
		world.setBlock(x + 2, y + 3, z + 5, Blocks.fence, 0, 3);
		world.setBlock(x + 3, y + 3, z + 5, Blocks.wool, 0, 3);
		world.setBlock(x + 5, y + 3, z + 5, Blocks.wool, 0, 3);
		world.setBlock(x + 6, y + 3, z + 5, Blocks.fence, 0, 3);
		world.setBlock(x + 3, y + 3, z + 7, Blocks.cobblestone_wall, 0, 3);
		world.setBlock(x + 4, y + 3, z + 7, Blocks.cobblestone_wall, 0, 3);
		world.setBlock(x + 8, y + 3, z + 8, Blocks.cobblestone_wall, 1, 3);
		world.setBlock(x + 8, y + 3, z + 9, Blocks.cobblestone_wall, 0, 3);
		world.setBlock(x + 9, y + 3, z + 9, Blocks.cobblestone_wall, 0, 3);
		world.setBlock(x + 9, y + 3, z + 12, Blocks.tallgrass, 1, 3);
		world.setBlock(x + 0, y + 3, z + 14, Blocks.double_plant, 2, 3);
		world.setBlock(x + 9, y + 3, z + 15, Blocks.cobblestone_wall, 1, 3);
		world.setBlock(x + 7, y + 3, z + 16, Blocks.tallgrass, 1, 3);
		world.setBlock(x + 2, y + 3, z + 17, Blocks.cobblestone_wall, 0, 3);
		world.setBlock(x + 3, y + 4, z + 0, Blocks.wool, 0, 3);
		world.setBlock(x + 4, y + 4, z + 0, Blocks.wool, 0, 3);
		world.setBlock(x + 5, y + 4, z + 0, Blocks.wool, 0, 3);
		world.setBlock(x + 2, y + 4, z + 1, Blocks.wool, 0, 3);
		world.setBlock(x + 3, y + 4, z + 1, Blocks.wool, 0, 3);
		world.setBlock(x + 4, y + 4, z + 1, Blocks.fence, 0, 3);
		world.setBlock(x + 5, y + 4, z + 1, Blocks.wool, 0, 3);
		world.setBlock(x + 6, y + 4, z + 1, Blocks.wool, 0, 3);
		world.setBlock(x + 2, y + 4, z + 2, Blocks.wool, 0, 3);
		world.setBlock(x + 3, y + 4, z + 2, Blocks.air, 0, 3);
		world.setBlock(x + 4, y + 4, z + 2, Blocks.air, 0, 3);
		world.setBlock(x + 5, y + 4, z + 2, Blocks.air, 0, 3);
		world.setBlock(x + 6, y + 4, z + 2, Blocks.wool, 0, 3);
		world.setBlock(x + 2, y + 4, z + 3, Blocks.wool, 0, 3);
		world.setBlock(x + 3, y + 4, z + 3, Blocks.air, 0, 3);
		world.setBlock(x + 4, y + 4, z + 3, Blocks.air, 0, 3);
		world.setBlock(x + 5, y + 4, z + 3, Blocks.air, 0, 3);
		world.setBlock(x + 6, y + 4, z + 3, Blocks.wool, 0, 3);
		world.setBlock(x + 2, y + 4, z + 4, Blocks.wool, 0, 3);
		world.setBlock(x + 3, y + 4, z + 4, Blocks.fence, 0, 3);
		world.setBlock(x + 4, y + 4, z + 4, Blocks.air, 0, 3);
		world.setBlock(x + 5, y + 4, z + 4, Blocks.fence, 0, 3);
		world.setBlock(x + 6, y + 4, z + 4, Blocks.wool, 0, 3);
		world.setBlock(x + 3, y + 4, z + 5, Blocks.wool, 0, 3);
		EntityVillager villager = new EntityVillager(world);
		villager.setPosition(x + 4.5D, y + 3.5D, z + 5.5D);
		if(!world.isRemote){
			world.spawnEntityInWorld(villager);
		}
		villager.setProfession(Revival.CONFIG.villagerId);
		world.setBlock(x + 5, y + 4, z + 5, Blocks.wool, 0, 3);
		world.setBlock(x + 3, y + 4, z + 8, Blocks.double_plant, 9, 3);
		world.setBlock(x + 8, y + 4, z + 8, Blocks.cobblestone_wall, 0, 3);
		world.setBlock(x + 9, y + 4, z + 13, Blocks.double_plant, 9, 3);
		world.setBlock(x + 0, y + 4, z + 14, Blocks.double_plant, 8, 3);
		world.setBlock(x + 9, y + 4, z + 15, Blocks.cobblestone_wall, 0, 3);
		world.setBlock(x + 4, y + 5, z + 0, Blocks.wool, 0, 3);
		world.setBlock(x + 3, y + 5, z + 1, Blocks.wool, 0, 3);
		world.setBlock(x + 4, y + 5, z + 1, Blocks.wool, 0, 3);
		world.setBlock(x + 5, y + 5, z + 1, Blocks.wool, 0, 3);
		world.setBlock(x + 3, y + 5, z + 2, Blocks.wool, 0, 3);
		world.setBlock(x + 4, y + 5, z + 2, Blocks.air, 0, 3);
		world.setBlock(x + 5, y + 5, z + 2, Blocks.wool, 0, 3);
		world.setBlock(x + 3, y + 5, z + 3, Blocks.wool, 0, 3);
		world.setBlock(x + 4, y + 5, z + 3, Blocks.air, 0, 3);
		world.setBlock(x + 5, y + 5, z + 3, Blocks.wool, 0, 3);
		world.setBlock(x + 3, y + 5, z + 4, Blocks.wool, 0, 3);
		world.setBlock(x + 4, y + 5, z + 4, Blocks.air, 0, 3);
		world.setBlock(x + 5, y + 5, z + 4, Blocks.wool, 0, 3);
		world.setBlock(x + 4, y + 5, z + 5, Blocks.wool, 0, 3);
		world.setBlock(x + 8, y + 5, z + 8, Blocks.cobblestone_wall, 0, 3);
		world.setBlock(x + 4, y + 6, z + 1, Blocks.wool, 0, 3);
		world.setBlock(x + 4, y + 6, z + 2, Blocks.wool, 0, 3);
		world.setBlock(x + 4, y + 6, z + 3, Blocks.wool, 0, 3);
		world.setBlock(x + 4, y + 6, z + 4, Blocks.wool, 0, 3);
		ItemDoor.placeDoorBlock(world, x + 4, y + 3, z + 5, 3, Blocks.wooden_door);
		//ItemDoor.placeDoorBlock(world, x + 4, y + 4, z + 5, 3, Blocks.wooden_door);
		return true;
	}

}